Workbook

Sheet Main
A1: Prada
A2: numbers in mio EUR | G2: Price HKD | H2: 43.26
G3: Price EUR | H3: =+H2*H10 -> 5.1912
B4: 1913.HK | G4: Shares | H4: 2558.824 | I4: Q226
B5: IR | G5: MC | H5: =+H3*H4 -> 13283.367
G6: Cash | H6: 1020.558 | I6: Q226
B7: Busines Model | G7: Debt | H7: =124.16+1595.655 -> 1719.815 | I7: Q226
B8: Brands | C8: Products | D8: Costumers | G8: EV | H8: =+H5-H6+H7 -> 13982.624
B9: Prada | C9: leather products, clothing, shoes | D9: men & woman
B10: Miu Miu | C10: clothing | D10: woman | G10: HKD/EUR | H10: 0.12
B11: Chruchs | C11: shpes
B12: Car Shoe | C12: loafers and other shoes | G12: CEO: Andrea Guerra
B13: Marchesi 1824 | C13: patisserie | G13: Creative Director Miuccia Prada & Co Crative Director. Raf Simon
B14: Luna Rossa | C14: Italian sailing team | G14: CFO: Andrea Bonini
B16: Notes | G16: Founded 1913 by Mario Prada
B17: Close to a deal with Capri to acquire Versace for 1.6 Billion USD | G17: Emplyoe Count: 14.876
B18: 10-04-25: Acquistion of Versace for 1.25 Billion EUR | G18: Factories: 26 (23 in italy)
B21: History
B22: 1913 founded by Mario Prada -> store selling leather goodsin Milans Galleria Vitoorie Emanuele II.
B23: 1919 Prada obtained title of Official supplier to the Italian Royal Family
B24: 1975 Mario Prada's granddaughter Miuccia Prada began collobaration with the entrepreneur Patrizio Bertelli
B25: 1977 Bertelli founded IPI S.p.A. ->distributed Prada leather goods
B26: 1979 First women's footwear collection
B27: 1983 Second Store in Milan -> showcasing a special shade of light green "Prada Green"
B28: 1988 Prada's fist woman clothing collection in Milan
B29: 1993 debut in menswear and established a new women's brand Miu Miu
B30: 1997 foundation of Prada sailing team and ist Linea Rossa activewear collection
B31: 1999 Prada group acquired the class English footwear brand Church's
B32: 2003 licensing agreement with Luxottica to produce Prada and Miu Miu eyewear
... B37: 2023 entrance in cosmetic industy in collaboration with L´Oréal

Sheet Quarters
A1: Main
C2: Q124 | D2: Q224 | E2: Q324 | F2: Q424 | G2: Q125 | H2: Q225 | I2: Q325 | J2: Q425 | K2: Q126 | L2: Q226 | M2: Q326 | N2: Q426
B3: Prada | C3: 826 | D3: =+Model!G12-Quarters!C3 -> 882 | E3: =2533.606-Model!G12 -> 825.606 | F3: =+Model!H12-Quarters!E3 -> 1029.77 | G3: 827 | H3: =+Model!I12-Quarters!G3 -> 819.788 | I3: =2428.359-Model!I12 -> 781.571 | J3: =+Model!J12-Quarters!I3 -> 964.502 | K3: 771.408 | L3: =+Model!K12-Quarters!K3 -> 849.55
B4: MiuMiu | C4: 233 | D4: =+Model!G13-Quarters!C4 -> 297 | E4: =854.339-Model!G13 -> 324.339 | F4: =+Model!H13-Quarters!E4 -> 373.714 | G4: 377 | H4: =+Model!I13-Quarters!G4 -> 403.14 | I4: =1178.237-Model!I13 -> 398.097 | J4: =+Model!J13-Quarters!I4 -> 416.344 | K4: 358.088 | L4: =+Model!K13-Quarters!K4 -> 405.188
B5: Versace | C5: 0 | D5: 0 | E5: 0 | F5: 0 | G5: 0 | H5: =+Model!I14-Quarters!G5 -> 0 | I5: 0 | J5: =+Model!J14-Quarters!I5 -> 51.343 | K5: 101.945 | L5: =+Model!K14-Quarters!K5 -> 117.552
B6: Chuchs | C6: 7 | D6: =+Model!G15-Quarters!C6 -> 8 | E6: =21.513-Model!G15 -> 6.513 | F6: =+Model!H15-Quarters!E6 -> 10.146 | G6: 7 | H6: =+Model!I15-Quarters!G6 -> 8.37 | I6: =22.823-Model!I15 -> 7.453 | J6: =+Model!J15-Quarters!I6 -> 10.865 | K6: 7.175 | L6: =+Model!K15-Quarters!K6 -> 8.591
B7: Other | C7: 5 | D7: =+Model!G16-Quarters!C7 -> 5 | E7: =15.281-Model!G16 -> 5.281 | F7: =+Model!H16-Quarters!E7 -> 10.839 | G7: 5 | H7: =+Model!I16-Quarters!G7 -> 6.083 | I7: =17.108-Model!I16 -> 6.025 | J7: =+Model!J16-Quarters!I7 -> 12.209 | K7: 6.02 | L7: =+Model!K16-Quarters!K7 -> 7.001
B8: APAC Retail | C8: 396 | D8: =+Model!G17-Quarters!C8 -> 378.435 | E8: =1139.067-Model!G17 -> 364.632 | F8: =+Model!H17-Quarters!E8 -> 465.346 | G8: 438 | H8: =+Model!I17-Quarters!G8 -> 400.371 | I8: =1216.493-Model!I17 -> 378.122 | J8: =+Model!J17-Quarters!I8 -> 482.955 | K8: 461 | L8: =+Model!K17-Quarters!K8 -> 461.283
B9: Europe Retail | C9: 295 | D9: =+Model!G18-Quarters!C9 -> 387.192 | E9: =1089.344-Model!G18 -> 407.152 | F9: =+Model!H18-Quarters!E9 -> 442.278 | G9: 334 | H9: =+Model!I18-Quarters!G9 -> 393.562 | I9: =1137.093-Model!I18 -> 409.531 | J9: =+Model!J18-Quarters!I9 -> 425.704 | K9: 333 | L9: =+Model!K18-Quarters!K9 -> 419.146
B10: Americas Retail | C10: 181 | D10: =+Model!G19-Quarters!C10 -> 205.961 | E10: =575.567-Model!G19 -> 188.606 | F10: =+Model!H19-Quarters!E10 -> 254.242 | G10: 201 | H10: =+Model!I19-Quarters!G10 -> 223.09 | I10: =636.754-Model!I19 -> 212.664 | J10: =+Model!J19-Quarters!I10 -> 295.293 | K10: 256 | L10: =+Model!K19-Quarters!K10 -> 215.99
B11: Japan Retail | C11: 145 | D11: =+Model!G20-Quarters!C11 -> 163.612 | E11: =466.361-Model!G20 -> 157.749 | F11: =+Model!H20-Quarters!E11 -> 190.07 | G11: 172 | H11: =+Model!I20-Quarters!G11 -> 153.945 | I11: =474.16-Model!I20 -> 148.215 | J11: =+Model!J20-Quarters!I11 -> 181.941 | K11: 145 | L11: =+Model!K20-Quarters!K11 -> 143.307
B12: Middle East Retail | C12: 54 | D12: =+Model!G21-Quarters!C12 -> 56.391 | E12: =154.4-Model!F21 -> 66.614 | F12: =+Model!H21-Quarters!E12 -> 49.928 | G12: 70 | H12: =+Model!I21-Quarters!G12 -> 67.413 | I12: =182.027-Model!I21 -> 44.614 | J12: =+Model!J21-Quarters!I12 -> 69.37 | K12: 49 | L12: =+Model!K21-Quarters!K12 -> 48.792
B13: Retail Sales | C13: 1071 | D13: =+Model!G22-Quarters!C13 -> 1191.591 | E13: =3424.739-Model!G22 -> 1162.148 | F13: =+Model!H22-Quarters!E13 -> 1424.469 | G13: 1216 | H13: =+Model!I22-Quarters!G13 -> 1237.381 | I13: =3646.527-Model!I22 -> 1193.146 | J13: =+Model!J22-Quarters!I13 -> 1455.263 | K13: 1244.636 | L13: =+Model!K22-Quarters!K13 -> 1387.882
B14: Wholesale Sales | C14: 90 | D14: =+Model!G23-Quarters!C14 -> 135.213 | E14: =313.851-Model!G23 -> 88.638 | F14: =+Model!H23-Quarters!E14 -> 146.967 | G14: 96 | H14: =+Model!I23-Quarters!G14 -> 123.762 | I14: =322.329-Model!I23 -> 102.567 | J14: =+Model!J23-Quarters!I14 -> 148.393 | K14: 129.397 | L14: =+Model!K23-Quarters!K14 -> 170.056
B15: Royalties | C15: 25 | D15: =+Model!G24-Quarters!C15 -> 35.83 | E15: =90.547-Model!G24 -> 29.717 | F15: =+Model!H24-Quarters!E15 -> 30.984 | G15: 29 | H15: =+Model!I24-Quarters!G15 -> 37.892 | I15: =100.884-Model!I24 -> 33.992 | J15: =+Model!J24-Quarters!I15 -> 44.215 | K15: 53.666 | L15: =+Model!K24-Quarters!K15 -> 62.377
B16: Revenue | C16: =+SUM(C13:C15) -> 1186 | D16: =+SUM(D13:D15) -> 1362.634 | E16: =+SUM(E13:E15) -> 1280.503 | F16: =+SUM(F13:F15) -> 1602.42 | G16: =+SUM(G13:G15) -> 1341 | H16: =+SUM(H13:H15) -> 1399.035 | I16: =+SUM(I13:I15) -> 1329.705 | J16: =+SUM(J13:J15) -> 1647.871 | K16: 1427.699 | L16: =+Model!K25-Quarters!K16 -> 1620.315
B18: Prada Growth | G18: =+G3/C3-1 -> 0.0012106538 | H18: =+H3/D3-1 -> -0.070535147 | I18: =+I3/E3-1 -> -0.053336579 | J18: =+J3/F3-1 -> -0.063381143 | K18: =+K3/G3-1 -> -0.067221282 | L18: =+L3/H3-1 -> 0.036304508
B19: MiuMiu Growth | G19: =+G4/C4-1 -> 0.61802575 | H19: =+H4/D4-1 -> 0.35737374 | I19: =+I4/E4-1 -> 0.22741021 | J19: =+J4/F4-1 -> 0.11407119 | K19: =+K4/G4-1 -> -0.050164456 | L19: =+L4/H4-1 -> 0.005080121
B20: Versace Growth | G20: n.a. | H20: n.a. | I20: n.a. | J20: n.a. | K20: n.a. | L20: n.a.
B21: Chuchs Growth | G21: =+G6/C6-1 -> 0 | H21: =+H6/D6-1 -> 0.04625 | I21: =+I6/E6-1 -> 0.14432673 | J21: =+J6/F6-1 -> 0.070865366 | K21: =+K6/G6-1 -> 0.025 | L21: =+L6/H6-1 -> 0.026403823
B22: Other Growth | G22: =+G7/C7-1 -> 0 | H22: =+H7/D7-1 -> 0.2166 | I22: =+I7/E7-1 -> 0.14088241 | J22: =+J7/F7-1 -> 0.12639542 | K22: =+K7/G7-1 -> 0.204 | L22: =+L7/H7-1 -> 0.15091238
B23: Revenue Growth | G23: =+G16/C16-1 -> 0.1306914 | H23: =+H16/D16-1 -> 0.026713703 | I23: =+I16/E16-1 -> 0.038423963 | J23: =+J16/F16-1 -> 0.028363974 | K23: =+K16/G16-1 -> 0.064652498 | L23: =+L16/H16-1 -> 0.15816616

Sheet Model
A1: Main
C2: H122 | D2: H222 | E2: H123 | F2: H223 | G2: H124 | H2: H224 | I2: H125 | J2: H225 | K2: H126 | L2: H226 | N2: FY18 | O2: FY19 | P2: FY20 | Q2: FY21 | R2: FY22 | S2: FY23 | T2: FY24 | U2: FY25
B3: Prada Stores | D3: =+R3 -> 422 | E3: 428 | F3: =+S3 -> 428 | G3: 417 | H3: =+T3 -> 425 | I3: 426 | J3: =+U3 -> 423 | K3: 416 | N3: 398 | O3: 410 | P3: 410 | Q3: 420 | R3: 422 | S3: 428 | T3: 425 | U3: 423
B4: Versace | C4: 0 | D4: 0 | E4: 0 | F4: 0 | G4: 0 | H4: 0 | I4: 0 | J4: =+U4 -> 220 | K4: 210 | N4: 0 | O4: 0 | P4: 0 | Q4: 0 | R4: 0 | S4: 0 | T4: 0 | U4: 220
B5: Miu Miu Stores | D5: =+R5 -> 145 | E5: 141 | F5: =+S5 -> 141 | G5: 139 | H5: =+T5 -> 147 | I5: 156 | J5: =+U5 -> 162 | K5: 168 | N5: 166 | O5: 160 | P5: 152 | Q5: 146 | R5: 145 | S5: 141 | T5: 147 | U5: 162
B6: Church's Stores | D6: =+R6 -> 37 | E6: 28 | F6: =+S6 -> 28 | G6: 28 | H6: =+T6 -> 28 | I6: 28 | J6: =+U6 -> 27 | K6: 26 | N6: 63 | O6: 62 | P6: 62 | Q6: 61 | R6: 37 | S6: 28 | T6: 28 | U6: 27
B7: Car Shoe Stores | D7: =+R7 -> 2 | E7: 2 | F7: =+S7 -> 2 | G7: 2 | H7: =+T7 -> 2 | I7: 2 | J7: =+U7 -> 2 | K7: 2 | N7: 4 | O7: 3 | P7: 3 | Q7: 2 | R7: 2 | S7: 2 | T7: 2 | U7: 2
B8: Marchesi 1824 Stores | D8: =+R8 -> 6 | E8: 7 | F8: =+S8 -> 7 | G8: 7 | H8: =+T8 -> 7 | I8: 8 | J8: =+U8 -> 9 | K8: 10 | N8: 5 | O8: 6 | P8: 6 | Q8: 6 | R8: 6 | S8: 7 | T8: 7 | U8: 9
B9: Total Stores | C9: =+SUM(C3:C8) -> 0 | D9: =+SUM(D3:D8) -> 612 | E9: =+SUM(E3:E8) -> 606 | F9: =+SUM(F3:F8) -> 606 | G9: =+SUM(G3:G8) -> 593 | H9: =+SUM(H3:H8) -> 609 | I9: =+SUM(I3:I8) -> 620 | J9: =+SUM(J3:J8) -> 843 | K9: =+SUM(K3:K8) -> 832 | N9: =+SUM(N3:N8) -> 636 | O9: =+SUM(O3:O8) -> 641 | P9: =+SUM(P3:P8) -> 633 | Q9: =+SUM(Q3:Q8) -> 635 | R9: =+SUM(R3:R8) -> 612 | S9: =+SUM(S3:S8) -> 606 | T9: =+SUM(T3:T8) -> 609 | U9: =+SUM(U3:U8) -> 843
B10: Franchises | D10: =+R10 -> 26 | E10: 25 | F10: =+S10 -> 25 | G10: 24 | H10: =+T10 -> 23 | I10: 22 | J10: =+U10 -> 22 | K10: 22 | N10: 34 | O10: 25 | P10: 26 | Q10: 26 | R10: 26 | S10: 25 | T10: 23 | U10: 22
B12: Prada | E12: 1668 | F12: =+S12-E12 -> 2244.309 | G12: 1708 | H12: =+T12-G12 -> 1855.376 | I12: 1646.788 | J12: =+U12-I12 -> 1746.073 | K12: 1620.958 | N12: 2558.108 | O12: 2643.348 | P12: 2012.62 | Q12: 2857.693 | R12: 3647.805 | S12: 3912.309 | T12: 3563.376 | U12: 3392.861
B13: Miu Miu | E13: 285 | F13: =+S13-E13 -> 468.234 | G13: 530 | H13: =+T13-G13 -> 698.053 | I13: 780.14 | J13: =+U13-I13 -> 814.441 | K13: 763.276 | N13: 453.476 | O13: 450.491 | P13: 329.497 | Q13: 401.219 | R13: 488.952 | S13: 753.234 | T13: 1228.053 | U13: 1594.581
B14: Versace | C14: 0 | D14: 0 | E14: 0 | F14: 0 | G14: 0 | H14: 0 | I14: 0 | J14: =+U14-I14 -> 51.343 | K14: 219.497 | N14: 0 | O14: 0 | P14: 0 | Q14: 0 | R14: 0 | S14: 0 | T14: 0 | U14: 51.343
B15: Church's | E15: 13 | F15: =+S15-E15 -> 22.791 | G15: 15 | H15: =+T15-G15 -> 16.659 | I15: 15.37 | J15: =+U15-I15 -> 18.318 | K15: 15.766 | N15: 69.079 | O15: 69.801 | P15: 36.964 | Q15: 39.551 | R15: 41.971 | S15: 35.791 | T15: 31.659 | U15: 33.688
B16: Other | E16: 9 | F16: =+S16-E16 -> 16.077 | G16: 10 | H16: =+T16-G16 -> 16.12 | I16: 11.083 | J16: =+U16-I16 -> 18.234 | K16: 13.021 | N16: 17.405 | O16: 19.699 | P16: 11.785 | Q16: 18.157 | R16: 21.946 | S16: 25.077 | T16: 26.12 | U16: 29.317
B17: Asia Pacific | E17: 715.724 | F17: =+S17-E17 -> 730.276 | G17: 774.435 | H17: =+T17-G17 -> 829.978 | I17: 838.371 | J17: =+U17-I17 -> 861.077 | K17: 922.283 | N17: 1189.827 | O17: 1228.437 | P17: 741.131 | Q17: 970.636 | R17: 1232 | S17: 1446 | T17: 1604.413 | U17: 1699.448
B18: Europe | E18: 582.112 | F18: =+S18-E18 -> 729.888 | G18: 682.192 | H18: =+T18-G18 -> 849.43 | I18: 727.562 | J18: =+U18-I18 -> 835.235 | K18: 752.146 | N18: 1035.061 | O18: 1017.593 | P18: 963.845 | Q18: 1272.534 | R18: 1187 | S18: 1312 | T18: 1531.622 | U18: 1562.797
B19: America | E19: 361.073 | F19: =+S19-E19 -> 405.927 | G19: 386.961 | H19: =+T19-G19 -> 442.848 | I19: 424.09 | J19: =+U19-I19 -> 507.957 | K19: 471.99 | N19: 426.184 | O19: 455.402 | P19: 324.479 | Q19: 636.963 | R19: 782 | S19: 767 | T19: 829.809 | U19: 932.047
B20: Japan | E20: 223.587 | F20: =+S20-E20 -> 260.413 | G20: 308.612 | H20: =+T20-G20 -> 347.819 | I20: 325.945 | J20: =+U20-I20 -> 330.156 | K20: 288.307 | N20: 350.313 | O20: 386.055 | P20: 280.232 | Q20: 309.704 | R20: 369 | S20: 484 | T20: 656.431 | U20: 656.101
B21: Middle East | E21: 92.214 | F21: =+S21-E21 -> 87.786 | G21: 110.391 | H21: =+T21-G21 -> 116.542 | I21: 137.413 | J21: =+U21-I21 -> 113.984 | K21: 97.792 | N21: =95.601+1.082 -> 96.683 | O21: 95.481 | P21: 81.179 | Q21: 126.782 | R21: 167 | S21: 180 | T21: 226.933 | U21: 251.397
B22: Retail Revenue | E22: 1974.71 | F22: =+S22-E22 -> 2214.966 | G22: 2262.591 | H22: =+T22-G22 -> 2586.617 | I22: 2453.381 | J22: =+U22-I22 -> 2648.409 | K22: 2632.518 | N22: 2532.004 | O22: 2636.097 | P22: 2115.37 | Q22: 2930.856 | R22: 3736.971 | S22: 4189.676 | T22: 4849.208 | U22: 5101.79
B23: Wholesale Revenue | E23: 210.186 | F23: =+S23-E23 -> 223.02 | G23: 225.213 | H23: =+T23-G23 -> 235.605 | I23: 219.762 | J23: =+U23-I23 -> 250.96 | K23: 299.453 | N23: 566.064 | O23: 547.242 | P23: 275.496 | Q23: 385.764 | R23: 387.621 | S23: 433.206 | T23: 460.818 | U23: 470.722
B24: Royalties Revenue | E24: 47.483 | F24: =+S24-E24 -> 56.046 | G24: 60.83 | H24: =+T24-G24 -> 60.701 | I24: 66.892 | J24: =+U24-I24 -> 78.207 | K24: 116.043 | N24: 44.08 | O24: 42.255 | P24: 31.873 | Q24: 49.047 | R24: 76.082 | S24: 103.529 | T24: 121.531 | U24: 145.099
B25: Revenue | C25: =+SUM(C22:C24) -> 0 | D25: =+SUM(D22:D24) -> 0 | E25: =+SUM(E22:E24) -> 2232.379 | F25: =+SUM(F22:F24) -> 2494.032 | G25: =+SUM(G22:G24) -> 2548.634 | H25: =+SUM(H22:H24) -> 2882.923 | I25: =+SUM(I22:I24) -> 2740.035 | J25: =+SUM(J22:J24) -> 2977.576 | K25: 3048.014 | N25: =+SUM(N22:N24) -> 3142.148 | O25: =+SUM(O22:O24) -> 3225.594 | P25: =+SUM(P22:P24) -> 2422.739 | Q25: =+SUM(Q22:Q24) -> 3365.667 | R25: =+SUM(R22:R24) -> 4200.674 | S25: =+SUM(S22:S24) -> 4726.411 | T25: =+SUM(T22:T24) -> 5431.557 | U25: 5717.521
B26: COGS | E26: 438.984 | F26: =+S26-E26 -> 485.656 | G26: 514.673 | H26: =+T26-G26 -> 580.192 | I26: 545.453 | J26: =+U26-I26 -> 579.991 | K26: 660.298 | N26: 879.568 | O26: 905.982 | P26: 679.361 | Q26: 818.309 | R26: 888.58 | S26: 924.64 | T26: 1094.865 | U26: 1125.444
B27: Gross Profit | C27: =C25-C26 -> 0 | D27: =D25-D26 -> 0 | E27: =E25-E26 -> 1793.395 | F27: =F25-F26 -> 2008.376 | G27: =G25-G26 -> 2033.961 | H27: =H25-H26 -> 2302.731 | I27: =I25-I26 -> 2194.582 | J27: =J25-J26 -> 2397.585 | ... L27: =L25-L26 -> 0 | N27: =+N25-N26 -> 2262.58 | O27: =+O25-O26 -> 2319.612 | P27: =+P25-P26 -> 1743.378 | Q27: =+Q25-Q26 -> 2547.358 | R27: =+R25-R26 -> 3312.094 | S27: =+S25-S26 -> 3801.771 | T27: =+T25-T26 -> 4336.692 | U27: =+U25-U26 -> 4592.077
B28: Selling | E28: 894.587 | F28: =+S28-E28 -> 978.039 | G28: 978.47 | H28: =+T28-G28 -> 1104.282 | I28: 1064.293 | J28: =+U28-I28 -> 1141.897 | K28: 1242.125 | N28: 1414.153 | O28: 1470.101 | P28: 1259.827 | Q28: 1421.169 | R28: 1704.363 | S28: 1872.626 | T28: 2082.752 | U28: 2206.19
B29: Marketing | E29: 187.274 | F29: =+S29-E29 -> 233.014 | G29: 219.25 | H29: =+T29-G29 -> 253.845 | I29: 254.359 | J29: =+U29-I29 -> 282.839 | K29: 307.322 | N29: 207.278 | O29: 231.011 | P29: 206.848 | Q29: 294.251 | R29: 359.114 | S29: 420.288 | T29: 473.095 | U29: 537.198
B30: Product Development | E30: 72.489 | F30: =+S30-E30 -> 78.127 | G30: 81.659 | H30: =+T30-G30 -> 76.425 | I30: 79.895 | J30: =+U30-I30 -> 80.366 | K30: 90.946 | N30: 125.179 | O30: 127.378 | P30: 102.232 | Q30: 115.319 | R30: 137.469 | S30: 150.616 | T30: 158.084 | U30: 160.261
B31: G&A | E31: 147.626 | F31: =+S31-E31 -> 148.923 | G31: 179.463 | H31: =+T31-G31 -> 163.748 | I31: =177.49+11.251 -> 188.741 | J31: =+U31-I31 -> 200.647 | K31: =217.171+7.153 -> 224.324 | N31: 192.138 | O31: 184.343 | P31: 154.41 | Q31: 227.135 | R31: 265.972 | S31: 296.549 | T31: 343.211 | U31: =364.782+24.606 -> 389.388
B32: Operating Income | C32: =+C27-SUM(C28:C31) -> 0 | D32: =+D27-SUM(D28:D31) -> 0 | E32: =+E27-SUM(E28:E31) -> 491.419 | F32: =+F27-SUM(F28:F31) -> 570.273 | G32: =+G27-SUM(G28:G31) -> 575.119 | H32: =+H27-SUM(H28:H31) -> 704.431 | I32: =+I27-SUM(I28:I31) -> 607.294 | J32: =+J27-SUM(J28:J31) -> 691.836 | K32: =+K27-SUM(K28:K31) -> 522.999 | N32: =+N27-SUM(N28:N31) -> 323.832 | O32: =+O27-SUM(O28:O31) -> 306.779 | P32: =+P27-SUM(P28:P31) -> 20.061 | Q32: =+Q27-SUM(Q28:Q31) -> 489.484 | R32: =+R27-SUM(R28:R31) -> 845.176 | S32: =+S27-SUM(S28:S31) -> 1061.692 | T32: =+T27-SUM(T28:T31) -> 1279.55 | U32: =+U27-SUM(U28:U31) -> 1299.04
B33: Interest Income | E33: -46.408 | F33: =+S33-E33 -> -43.821 | G33: -38.09 | H33: =+T33-G33 -> -52.737 | I33: =-7.397-41.982 -> -49.379 | J33: =+U33-I33 -> -48.377 | K33: -37.637 | N33: -21.308 | O33: -72.019 | P33: -71.873 | Q33: -67.829 | R33: -65.015 | S33: -90.229 | T33: -90.827 | U33: =-87.764-34.531+24.539 -> -97.756
B34: Other Income | E34: 0 | F34: =+S34-E34 -> 0 | G34: 0 | H34: =+T34-G34 -> 0 | I34: 0 | J34: =+U34-I34 -> 0 | K34: =15.957-52.018 -> -36.061 | N34: 0 | O34: 0 | P34: 0 | Q34: 0 | R34: -69.186 | S34: 0 | T34: 0 | U34: 0
B35: Pretax Income | C35: =+C32+C33+C34 -> 0 | D35: =+D32+D33+D34 -> 0 | E35: =+E32+E33+E34 -> 445.011 | F35: =+F32+F33+F34 -> 526.452 | G35: =+G32+G33+G34 -> 537.029 | H35: =+H32+H33+H34 -> 651.694 | I35: =+I32+I33+I34 -> 557.915 | J35: =+J32+J33+J34 -> 643.459 | K35: =+K32+K33+K34 -> 449.301 | N35: =+N32+N33+N34 -> 302.524 | O35: =+O32+O33+O34 -> 234.76 | P35: =+P32+P33+P34 -> -51.812 | Q35: =+Q32+Q33+Q34 -> 421.655 | R35: =+R32+R33+R34 -> 710.975 | S35: =+S32+S33+S34 -> 971.463 | T35: =+T32+T33+T34 -> 1188.723 | U35: =+U32+U33+U34 -> 1201.284
B36: Income Tax Expense | E36: 138.381 | F36: =+S36-E36 -> 159.69 | G36: 151.316 | H36: =+T36-G36 -> 194.007 | I36: 170.923 | J36: =+U36-I36 -> 175.439 | K36: 121.269 | N36: 94.356 | O36: -22.964 | P36: 2.556 | Q36: 126.552 | R36: 241.82 | S36: 298.071 | T36: 345.323 | U36: 346.362
B37: Net Income | C37: =+C35-C36 -> 0 | D37: =+D35-D36 -> 0 | E37: =+E35-E36 -> 306.63 | F37: =+F35-F36 -> 366.762 | G37: =+G35-G36 -> 385.713 | H37: =+H35-H36 -> 457.687 | I37: =+I35-I36 -> 386.992 | J37: =+J35-J36 -> 468.02 | K37: =+K35-K36 -> 328.032 | N37: =+N35-N36 -> 208.168 | O37: =+O35-O36 -> 257.724 | P37: =+P35-P36 -> -54.368 | Q37: =+Q35-Q36 -> 295.103 | R37: =+R35-R36 -> 469.155 | S37: =+S35-S36 -> 673.392 | T37: =+T35-T36 -> 843.4 | U37: =+U35-U36 -> 854.922
B38: Minorities | E38: 1.462 | F38: =+S38-E38 -> 0.904 | G38: 2.214 | H38: =+T38-G38 -> 2.279 | I38: 1.109 | J38: =+U38-I38 -> 1.877 | K38: 1.175 | N38: 2.739 | O38: 1.936 | P38: -0.229 | Q38: 0.849 | R38: 3.962 | S38: 2.366 | T38: 4.493 | U38: 2.986
B39: Net Income to Group | C39: =+C37-C38 -> 0 | D39: =+D37-D38 -> 0 | E39: =+E37-E38 -> 305.168 | F39: =+F37-F38 -> 365.858 | G39: =+G37-G38 -> 383.499 | H39: =+H37-H38 -> 455.408 | I39: =+I37-I38 -> 385.883 | J39: =+J37-J38 -> 466.143 | K39: =+K37-K38 -> 326.857 | N39: =+N37-N38 -> 205.429 | O39: =+O37-O38 -> 255.788 | P39: =+P37-P38 -> -54.139 | Q39: =+Q37-Q38 -> 294.254 | R39: =+R37-R38 -> 465.193 | S39: =+S37-S38 -> 671.026 | T39: =+T37-T38 -> 838.907 | U39: =+U37-U38 -> 851.936
B41: Shares | C41: =+C39/C42 -> 0 | D41: =+D39/D42 -> 0 | E41: =+E39/E42 -> 0.11926104 | F41: =+F39/F42 -> 0.14297896 | G41: =+G39/G42 -> 0.14987314 | H41: =+H39/H42 -> 0.17797551 | I41: =+I39/I42 -> 0.15080482 | J41: =+J39/J42 -> 0.18217079 | K41: =+K39/K42 -> 0.12773719 | N41: =+N39/N42 -> 0.080282583 | O41: =+O39/O42 -> 0.099963108 | P41: =+P39/P42 -> -0.021157766 | Q41: =+Q39/Q42 -> 0.11499579 | R41: =+R39/R42 -> 0.18179953 | S41: =+S39/S42 -> 0.26224 | T41: =+T39/T42 -> 0.32784865 | U41: =+U39/U42 -> 0.33294044
B42: EPS | C42: 2558.824 | D42: 2558.824 | E42: 2558.824 | F42: 2558.824 | G42: 2558.824 | H42: 2558.824 | I42: 2558.824 | J42: =+U42 -> 2558.824 | K42: 2558.824 | N42: 2558.824 | O42: 2558.824 | P42: 2558.824 | Q42: 2558.824 | R42: 2558.824 | S42: 2558.824 | T42: 2558.824 | U42: 2558.824
...

Sheet Ratios
A1: Main
B2: Ratios | C2: 18 | D2: =+C2+1 -> 19 | E2: =+D2+1 -> 20 | F2: =+E2+1 -> 21 | G2: =+F2+1 -> 22 | H2: =+G2+1 -> 23 | I2: =+H2+1 -> 24 | J2: =+I2+1 -> 25
B3: Price HKD | C3: 27.75 | D3: 25.25 | E3: 31.85 | F3: 49.7 | G3: 48.25 | H3: 45.5 | I3: 44.05 | J3: 40.88
B4: Price EUR | C4: =+C3*Main!$H$10 -> 3.33 | D4: =+D3*Main!$H$10 -> 3.03 | E4: =+E3*Main!$H$10 -> 3.822 | F4: =+F3*Main!$H$10 -> 5.964 | G4: =+G3*Main!$H$10 -> 5.79 | H4: =+H3*Main!$H$10 -> 5.46 | I4: =+I3*Main!$H$10 -> 5.286 | J4: =+J3*Main!$H$10 -> 4.9056
B5: Shares o/s | C5: =+Model!N42 -> 2558.824 | D5: =+Model!O42 -> 2558.824 | E5: =+Model!P42 -> 2558.824 | F5: =+Model!Q42 -> 2558.824 | G5: =+Model!R42 -> 2558.824 | H5: =+Model!S42 -> 2558.824 | I5: =+Model!T42 -> 2558.824 | J5: =+Model!U42 -> 2558.824
B6: Market Cap | C6: =+C4*C5 -> 8520.8839 | D6: =+D4*D5 -> 7753.2367 | E6: =+E4*E5 -> 9779.8253 | F6: =+F4*F5 -> 15260.826 | G6: =+G4*G5 -> 14815.591 | H6: =+H4*H5 -> 13971.179 | I6: =+I4*I5 -> 13525.944 | J6: =+J4*J5 -> 12552.567
B7: Net Debt | F7: =+Model!Q83+Model!Q91-Model!Q65 -> -239.882 | G7: =+Model!R83+Model!R91-Model!R65 -> -535.119 | H7: =+Model!S83+Model!S91-Model!S65 -> -202.759 | I7: =+Model!T83+Model!T91-Model!T65 -> -607.375 | J7: =+Model!U83+Model!U91-Model!U65 -> 470.69
B8: EV | F8: =+F6+F7 -> 15020.944 | G8: =+G6+G7 -> 14280.472 | H8: =+H6+H7 -> 13768.42 | I8: =+I6+I7 -> 12918.569 | J8: =+J6+J7 -> 13023.257
A10: x | B10: Value Driver
B11: Capital Emloyed | F11: =+Model!Q80+SUM(Model!Q66:Q70)-Model!Q85-Model!Q84 -> 5578.702 | G11: =+Model!R80+SUM(Model!R66:R70)-Model!R85-Model!R84 -> 5880.589 | H11: =+Model!S80+SUM(Model!S66:S70)-Model!S85-Model!S84 -> 6466.287 | I11: =+Model!T80+SUM(Model!T66:T70)-Model!T85-Model!T84 -> 7048.502 | J11: =+Model!U80+SUM(Model!U66:U70)-Model!U85-Model!U84 -> 9123.074 | L11: =Long Term Assets + Working Capital (Exclusive of cash)-Accounts Payables
B12: Invested Capital | F12: =+SUM(Model!Q66:Q70)+Model!Q72+Model!Q73-SUM(Model!Q84:Q88) -> 2829.894 | G12: =+SUM(Model!R66:R70)+Model!R72+Model!R73-SUM(Model!R84:R88) -> 2791.185 | H12: =+SUM(Model!S66:S70)+Model!S72+Model!S73-SUM(Model!S84:S88) -> 3461.375 | I12: =+SUM(Model!T66:T70)+Model!T72+Model!T73-SUM(Model!T84:T88) -> 3604.75 | J12: =+SUM(Model!U66:U70)+Model!U72+Model!U73-SUM(Model!U84:U88) -> 4904.835 | L12: =Net Working Capital + PP&E + Other Net Operating Assets (net of Liabilties) + (Intangibles)
B13: Invested Capital (exl. Intangibles) | F13: =+SUM(Model!Q66:Q70)+Model!Q72-SUM(Model!Q84:Q88) -> 2000.489 | G13: =+SUM(Model!R66:R70)+Model!R72-SUM(Model!R84:R88) -> 1973.376 | H13: =+SUM(Model!S66:S70)+Model!S72-SUM(Model!S84:S88) -> 2615.351 | I13: =+SUM(Model!T66:T70)+Model!T72-SUM(Model!T84:T88) -> 2736.83 | J13: =+SUM(Model!U66:U70)+Model!U72-SUM(Model!U84:U88) -> 3004.848
B14: Total Funds Invested | F14: =+F13+Model!Q65+SUM(Model!Q74:Q79) -> 5377.193 | G14: =+G13+Model!R65+SUM(Model!R74:R79) -> 5622.875 | H14: =+H13+Model!S65+SUM(Model!S74:S79) -> 5878.273 | I14: =+I13+Model!T65+SUM(Model!T74:T79) -> 6615.969 | J14: =+J13+Model!U65+SUM(Model!U74:U79) -> 7878.069 | L14: Invested Capital + Non-Operating Assets
B15: NOPAT | D15: =+Model!O32*(1-Model!O62) -> 336.78783 | E15: =+Model!P32*(1-Model!P62) -> 21.050653 | F15: =+Model!Q32*(1-Model!Q62) -> 342.57437 | G15: =+Model!R32*(1-Model!R62) -> 557.71096 | H15: =+Model!S32*(1-Model!S62) -> 735.93631 | I15: =+Model!T32*(1-Model!T62) -> 907.84184 | J15: =+Model!U32*(1-Model!U62) -> 924.49236 | L15: EBITA * (1-Marginal Tax Rate)
B16: Net Investment | G16: =+G12-F12 -> -38.709 | H16: =+H12-G12 -> 670.19 | I16: =+I12-H12 -> 143.375 | J16: =+J12-I12 -> 1300.085 | L16: =Invested Capital (t+1)-Invested Capital (t)
B17: FCF | G17: =+G15-G16 -> 596.41996 | H17: =+H15-H16 -> 65.746314 | I17: =+I15-I16 -> 764.46684 | J17: =+J15-J16 -> -375.59264 | L17: =NOPAT + non-cash Expenses - Investments in Invested Capital
B18: Investment Rate | G18: =+G16/G15 -> -0.069406921 | H18: =+H16/H15 -> 0.91066304 | I18: =+I16/I15 -> 0.15792949 | J18: =+J16/J15 -> 1.4062691 | L18: =Net Investment/NOPAT
B19: Economic Profit | L19: =Invested Capital *(ROIC-WACC)
A21: x | B21: Efficency-Ratios
B22: Capital Turnover | C22: =+Model!N25/Model!N99 -> #DIV/0! | D22: =+Model!O25/Model!O99 -> #DIV/0! | E22: =+Model!P25/Model!P99 -> #DIV/0! | F22: =+Model!Q25/Model!Q99 -> 1.0757594 | G22: =+Model!R25/Model!R99 -> 1.1998422 | H22: =+Model!S25/Model!S99 -> 1.2191498 | I22: =+Model!T25/Model!T99 -> 1.2290175 | J22: =+Model!U25/Model!U99 -> 1.2254219 | L22: Revenue / Equity
B23: Return on Equity (ROE) | E23: =+Model!P39/Model!P99 -> #DIV/0! | F23: =+Model!Q39/Model!Q99 -> 0.094051638 | G23: =+Model!R39/Model!R99 -> 0.13287349 | H23: =+Model!S39/Model!S99 -> 0.1730872 | I23: =+Model!T39/Model!T99 -> 0.18982244 | J23: =+Model!U39/Model!U99 -> 0.18259331 | L23: =Net Income/Book Value of Equity
B24: Return on Capital Employed (ROCE) | C24: =+Model!N32/Ratios!C11 -> #DIV/0! | D24: =+Model!O32/Ratios!D11 -> #DIV/0! | E24: =+Model!P32/Ratios!E11 -> #DIV/0! | F24: =+Model!Q32/Ratios!F11 -> 0.087741557 | G24: =+Model!R32/Ratios!G11 -> 0.14372302 | H24: =+Model!S32/Ratios!H11 -> 0.16418882 | I24: =+Model!T32/Ratios!I11 -> 0.18153503 | J24: =+Model!U32/Ratios!J11 -> 0.1423906 | L24: =EBIT/Capital Employed
B25: Return on Capital Invested (ROIC) | F25: =+F15/F12 -> 0.12105555 | G25: =+G15/G12 -> 0.19981153 | H25: =+H15/H12 -> 0.21261386 | I25: =+I15/I12 -> 0.25184599 | J25: =+J15/J12 -> 0.18848592 | L25: =NOPAT/Invested Capital
B26: ROIC without Intangibles | L26: =NOPAT/(Invested Capital exclusive of Intangibles)
B27: Decomposed ROIC | L27: = ROIC = (1-operating cash tax)* (EBITA/Revenues) * (Revenue/Invested Capital)
B29: Retention Rate | L29: =1 - Dividends/Net Income
B30: Reinvestment Rate | L30: =Net CapEx + Change in WC / EBIT * (1-t)
B31: Epected Growth in Net Income | L31: =ROE * Retention Rate
B32: Expected Growth in NOPAT | L32: =ROIC * Reinvestment Rate
A34: x | B34: Finacial Stability Ratios
B35: Equity/Debt Ratio | L35: =Book Value of Equtiy/Book Value of Debt
B36: Gearing | L36: =(Debt - Cash (Net Debt))/Book Value of Equity
B37: Interest Coverage Ratio | L37: =EBIT/Interest Expenses
B38: Net Debt / EBITDA | L38: =Net Debt/EBITDA
B39: Cash Burn Rate | L39: =Book Value of Equity/Absolute value of Loss
A41: x | B41: WC-Managment Ratios
B42: Debitor-Duration | F42: =+Model!Q66/Model!Q25*360 -> 35.249156 | G42: =+Model!R66/Model!R25*360 -> 28.445292 | H42: =+Model!S66/Model!S25*360 -> 30.859432 | I42: =+Model!T66/Model!T25*360 -> 28.084743 | J42: =+Model!U66/Model!U25*360 -> 29.496658 | L42: =Accounts Receivables/Revenue*360
B43: Creditor-Duration | F43: =+Model!Q85/Model!Q25*360 -> 41.732792 | G43: =+Model!R85/Model!R25*360 -> 34.434388 | H43: =+Model!S85/Model!S25*360 -> 34.533459 | I43: =+Model!T85/Model!T25*360 -> 31.921123 | J43: =+Model!U85/Model!U25*360 -> 39.552065 | L43: =Accounts Payable/Revenue*360
B44: Inventory Intensity | F44: =+Model!Q67/Model!Q100 -> 0.095222439 | G44: =+Model!R67/Model!R100 -> 0.10307678 | H44: =+Model!S67/Model!S100 -> 0.1028198 | I44: =+Model!T67/Model!T100 -> 0.10130575 | J44: =+Model!U67/Model!U100 -> 0.096163536 | L44: =Inventory/Balance Sheet Total
B45: Invetory Turnover | F45: =+Model!Q26/Model!Q67 -> 1.2348963 | G45: =+Model!R26/Model!R67 -> 1.1684816 | H45: =+Model!S26/Model!S67 -> 1.1809272 | I45: =+Model!T26/Model!T67 -> 1.2640447 | J45: =+Model!U26/Model!U67 -> 1.0627001 | L45: =Cogs/Inventory
...

Sheet DCF
A1: Main | B1: DCF
B3: Ticker | G3: Share Price | L3: Share Price | O3: =+J3 -> 0
B4: Date | E4: =+TODAY() -> 46234 | G4: Fair Share Price | J4: =V62 -> #DIV/0! | L4: Scneario DCF Price | O4: =+J15+O15+T15 -> 0
B5: End of FY | G5: Implied Upside | J5: =J4/J3-1 -> #DIV/0! | L5: Implied Upside | O5: =O4/O3-1 -> #DIV/0!
A7: x | B7: Assumptions
B9: Switches | G9: Conservative Case | L9: Base Case | Q9: Optimistic Case
B10: Assuptions | G10: Assuptions | I10: Year | J10: Metic | L10: Assuptions | N10: Year | O10: Metic | Q10: Assuptions | S10: Year | T10: Metic
B11: Revenue | E11: 2 | G11: Revenue | L11: Revenue | Q11: Revenue
B12: EBIT | E12: 2 | G12: EBIT | L12: EBIT | Q12: EBIT
B13: WACC | E13: 2 | G13: Implied Share Price
B14: TGR | E14: 2 | G14: Probability | L14: Probability | Q14: Probability
B15: ROIC | E15: 2 | G15: Implied Share Price * p | L15: Implied Share Price * p | Q15: Implied Share Price * p
B17: Valuation
B18: WACC | E18: =CHOOSE(E13,J18,O18,T18) -> 0 | G18: WACC | L18: WACC | Q18: WACC
B19: TGR | E19: =CHOOSE(E14,J19,O19,T19) -> 0 | G19: TGR | L19: TGR | Q19: TGR
B20: RONIC | E20: =CHOOSE(E15,J20,O20,T20) -> 0 | G20: RONIC | L20: RONIC | Q20: RONIC
A24: x | B24: Model | G24: 19 | H24: =G24+1 -> 20 | I24: =H24+1 -> 21 | J24: =I24+1 -> 22 | K24: =J24+1 -> 23 | L24: =K24+1 -> 24 | M24: =L24+1 -> 25 | N24: =M24+1 -> 26 | O24: =N24+1 -> 27 | ... V24: =U24+1 -> 34
B25: Revenue | M25: =L25*(1+M26) -> 0 | N25: =M25*(1+N26) -> 0 | O25: =N25*(1+O26) -> 0 | P25: =O25*(1+P26) -> 0 | Q25: =P25*(1+Q26) -> 0 | R25: =Q25*(1+R26) -> 0 | S25: =R25*(1+S26) -> 0 | T25: =S25*(1+T26) -> 0 | ... V25: =U25*(1+V26) -> 0
B26: Growth (%) | H26: =H25/G25-1 -> #DIV/0! | I26: =I25/H25-1 -> #DIV/0! | J26: =J25/I25-1 -> #DIV/0! | K26: =K25/J25-1 -> #DIV/0! | L26: =L25/K25-1 -> #DIV/0! | M26: {=OFFSET(M26,$E$11,,)} -> 0 | N26: {=OFFSET(N26,$E$11,,)} -> 0 | O26: {=OFFSET(O26,$E$11,,)} -> 0 | P26: {=OFFSET(P26,$E$11,,)} -> 0 | Q26: {=OFFSET(Q26,$E$11,,)} -> 0 | R26: {=OFFSET(R26,$E$11,,)} -> 0 | S26: {=OFFSET(S26,$E$11,,)} -> 0 | T26: {=OFFSET(T26,$E$11,,)} -> 0 | ... V26: {=OFFSET(V26,$E$11,,)} -> 0
B27: Conservative Case
B28: Base Case
B29: Optimisitic Case
B31: EBIT | M31: =M32*M25 -> 0 | N31: =N32*N25 -> 0 | O31: =O32*O25 -> 0 | P31: =P32*P25 -> 0 | Q31: =Q32*Q25 -> 0 | R31: =R32*R25 -> 0 | S31: =S32*S25 -> 0 | T31: =T32*T25 -> 0 | ... V31: =V32*V25 -> 0
B32: % of Sales | G32: =G31/G25 -> #DIV/0! | H32: =H31/H25 -> #DIV/0! | I32: =I31/I25 -> #DIV/0! | J32: =J31/J25 -> #DIV/0! | K32: =K31/K25 -> #DIV/0! | L32: =L31/L25 -> #DIV/0! | M32: {=OFFSET(M32,$E$12,,)} -> 0 | N32: {=OFFSET(N32,$E$12,,)} -> 0 | O32: {=OFFSET(O32,$E$12,,)} -> 0 | P32: {=OFFSET(P32,$E$12,,)} -> 0 | Q32: {=OFFSET(Q32,$E$12,,)} -> 0 | R32: {=OFFSET(R32,$E$12,,)} -> 0 | S32: {=OFFSET(S32,$E$12,,)} -> 0 | T32: {=OFFSET(T32,$E$12,,)} -> 0 | ... V32: {=OFFSET(V32,$E$12,,)} -> 0
B33: Conservative Case
B34: Base Case
B35: Optimisitic Case
B37: Taxes | M37: =M38*M31 -> 0 | N37: =N38*N31 -> 0 | O37: =O38*O31 -> 0 | P37: =P38*P31 -> 0 | Q37: =Q38*Q31 -> 0 | R37: =R38*R31 -> 0 | S37: =S38*S31 -> 0 | T37: =T38*T31 -> 0 | ... V37: =V38*V31 -> 0
B38: Tax Rate (%) | G38: =G37/G31 -> #DIV/0! | H38: =H37/H31 -> #DIV/0! | I38: =I37/I31 -> #DIV/0! | J38: =J37/J31 -> #DIV/0! | K38: =K37/K31 -> #DIV/0! | L38: =L37/L31 -> #DIV/0!
B40: Nopat | G40: =G31-G37 -> 0 | H40: =H31-H37 -> 0 | I40: =I31-I37 -> 0 | J40: =J31-J37 -> 0 | K40: =K31-K37 -> 0 | L40: =L31-L37 -> 0 | M40: =M31-M37 -> 0 | N40: =N31-N37 -> 0 | ... V40: =V31-V37 -> 0
B42: D&A and other non-cash Expenses | M42: =M43*M25 -> 0 | N42: =N43*N25 -> 0 | O42: =O43*O25 -> 0 | P42: =P43*P25 -> 0 | Q42: =Q43*Q25 -> 0 | R42: =R43*R25 -> 0 | S42: =S43*S25 -> 0 | T42: =T43*T25 -> 0 | ... V42: =V43*V25 -> 0
B43: % of Sales | G43: =G42/G25 -> #DIV/0! | H43: =H42/H25 -> #DIV/0! | I43: =I42/I25 -> #DIV/0! | J43: =J42/J25 -> #DIV/0! | K43: =K42/K25 -> #DIV/0! | L43: =L42/L25 -> #DIV/0!
B45: CapEx | M45: =M46*M25 -> 0 | N45: =N46*N25 -> 0 | O45: =O46*O25 -> 0 | P45: =P46*P25 -> 0 | Q45: =Q46*Q25 -> 0 | R45: =R46*R25 -> 0 | S45: =S46*S25 -> 0 | T45: =T46*T25 -> 0 | ... V45: =V46*V25 -> 0
B46: % of Sales | G46: =G45/G25 -> #DIV/0! | H46: =H45/H25 -> #DIV/0! | I46: =I45/I25 -> #DIV/0! | J46: =J45/J25 -> #DIV/0! | K46: =K45/K25 -> #DIV/0! | L46: =L45/L25 -> #DIV/0!
B48: Change in WC | M48: =M49*M25 -> 0 | N48: =N49*N25 -> 0 | O48: =O49*O25 -> 0 | P48: =P49*P25 -> 0 | Q48: =Q49*Q25 -> 0 | R48: =R49*R25 -> 0 | S48: =S49*S25 -> 0 | T48: =T49*T25 -> 0 | ... V48: =V49*V25 -> 0
B49: % of Sales | G49: =G48/G25 -> #DIV/0! | H49: =H48/H25 -> #DIV/0! | I49: =I48/I25 -> #DIV/0! | J49: =J48/J25 -> #DIV/0! | K49: =K48/K25 -> #DIV/0! | L49: =L48/L25 -> #DIV/0!
B51: Unlevered Free Cashflow | G51: =G40+G42+G45+G48 -> 0 | H51: =H40+H42+H45+H48 -> 0 | I51: =I40+I42+I45+I48 -> 0 | J51: =J40+J42+J45+J48 -> 0 | K51: =K40+K42+K45+K48 -> 0 | L51: =L40+L42+L45+L48 -> 0 | M51: =M40+M42+M45+M48 -> 0 | N51: =N40+N42+N45+N48 -> 0 | ... V51: =V40+V42+V45+V48 -> 0
B52: Present Value of unlevered FC | M52: =(M51/(1+$E$18)^M53)*M53 -> 0 | N52: =N51/(1+$E$18)^N53 -> 0 | O52: =O51/(1+$E$18)^O53 -> 0 | P52: =P51/(1+$E$18)^P53 -> 0 | Q52: =Q51/(1+$E$18)^Q53 -> 0 | R52: =R51/(1+$E$18)^R53 -> 0 | S52: =S51/(1+$E$18)^S53 -> 0 | T52: =T51/(1+$E$18)^T53 -> 0 | U52: =U51/(1+$E$18)^U53 -> 0 | V52: =V51/(1+$E$18)^V53 -> 0
B53: Discount Period | M53: =YEARFRAC(E4,E5) -> 126.58611 | N53: =M53+1 -> 127.58611 | O53: =N53+1 -> 128.58611 | P53: =O53+1 -> 129.58611 | Q53: =P53+1 -> 130.58611 | R53: =Q53+1 -> 131.58611 | S53: =R53+1 -> 132.58611 | T53: =S53+1 -> 133.58611 | U53: =T53+1 -> 134.58611 | V53: =U53+1 -> 135.58611
B54: Sum of Present Value | V54: =SUM(M52:V52) -> 0
...

Sheet WACC
A1: Main
B3: Cost of Capital
A4: x | B4: Cost of Equity (CAPM)
B5: Riskfree Rate
B6: Expected Inflation | H6: =(1+Nominal Rate)/(1+Real Rate)-1
B7: Average Real Interest Rate | H7: = Average Interest Rate of the Past
B8: Riskfree Rate | F8: =F6+F7 -> 0 | H8: =Goverment Bond or Expected Inflation + Average Real Interest Rate
A10: x | B10: Adjustments for Industry/Company Risk
B11: Raw Beta | H11: =Raw beta slope of regression line aginst total market -> Ri= alpha + beta*Rm + standard error
B12: Debt to Value Ratio | H12: Value of Debt/Enterpries Value
B13: Unlevered Beta | H13: = Raw Beta* Debt-to-Equity Ratio (Book Value)
B14: Unlevered Industry Beta | H14: =Median of Peer Group
B15: Levered Industry Beta | H15: =Unlevered Industry Beta * Market Value of Debt to Market Value of Equity
A17: x | B17: Expected Equity Risk Premium
B18: Estimated Future Market Return | H18: = 1/P/E * (1.g/ROE) + g , g = real growth in GDP, P/E => P/E ratio for S&P500 or MSCI World Index, ROE = Average ROE in S&P500 or MSCI World
B19: Riskfree Rate
B20: Expected Equity Risk Premium | F20: =F18-F19 -> 0
A22: x | B22: Cost of Equity (CAPM) | F22: =F8+F15*F20 -> 0 | H22: => ER(i)=rf+beta(i)*(Er(m)-rf)
A25: x | B25: Cost of Debt
B26: Yield to Maturity on Trading Bonds | H26: => Price = Coupon/(1+YTM)+Coupon(1+YTM)^2 + … + (Face Value + Coupon)/(1+YTM)^n => solve for YTM
B27: or
B28: Riskfree Rate
B29: Credit Default Spread
B30: Country Rsik Premium
A32: x | B32: Cost of Debt | F32: =F28+F29+F30 -> 0
A34: x | B34: Capital Structure
B35: Market Value of Debt
B36: Market Value of Equity
B37: Total Enterprise Value | F37: =F35+F36 -> 0
B39: Marginal Tax Rate
A41: x | B41: WACC | F41: =(F32*(F35/F37)*(1-F39))+((F36/F38)*F22) -> #DIV/0! | H41: => WACC = (D/D+E)*kd * (1-t) + (E/D+E) * ke
I47: =SLOPE(H48:H52,K48:K52) -> #DIV/0!
H48: Change
