Workbook

Sheet Main
A1: British American Tobacco
A2: in m GBP | G2: Price USD | H2: 60.8
G3: Price GBP | H3: 46.15
B4: TICKR | C4: BATS.L | G4: Shares | H4: 2187 | I4: Q425
B5: Investors | C5: IR | G5: MC | H5: =+H3*H4 -> 100930.05
B6: Chart | C6: BAT | G6: Cash | H6: 3827 | I6: Q425
G7: Debt | H7: =31708+3362 -> 35070 | I7: Q425
A8: x | B8: Busines Model | G8: EV | H8: =H5-H6+H7 -> 132173.05
B9: Segments | C9: % of Rev | D9: Brands/Products | E9: Category
B10: Smoke-Free | C10: =SUM(C11:C14) -> 0.17 | G10: GBP/USD | H10: 1.27
B11: Vapors | C11: 0.07 | D11: Vuse -> Biggest Vape Brand globally -> 35,9% Market Share 11,5 mio Customers | G11: GBP/EUR | H11: 1.16
B12: HP-Sticks | C12: 0.04 | D12: Glo -> handheld device with lithium-ion battery -> powers a heating chamber
B13: Modern Oral | C13: 0.02 | D13: Velo -> Gloabl leading Brand Snooze 3,3 Mio Customers
B14: Traditional Oral | C14: 0.04 | D14: Grizzly -> Snuff Tobacco
B15: Combustibles | C15: =C16+C17 -> 0.83
B16: Cigarettes | C16: 0.81 | D16: Camel, Dunhill, Kent, Lucky Strike, Pall Mall, Rothmans, Newport, American Spirit | E16: Cashcow
B17: Other | C17: 0.02 | D17: Local Tobacco Brands like Vogue, Viceroy etc
A19: x | B19: Region | C19: % of NI
B20: U.S. | C20: =1775/4258 -> 0.41686238 | E20: Management
B21: AME | C21: =1473/4258 -> 0.34593706 | E21: CEO | F21: Tadeu Marroco
B22: APMEA | C22: =1010/4258 -> 0.23720056 | E22: CFO | F22: Soraya Benchikh
B23: Total | C23: =SUM(C20:C22) -> 1 | E23: Legal Director | F23: Jerome Abelman
E24: Business Develop. | F24: James Barret
E25: Marketing Director | F25: Luaciano Comin
E26: Regional Director | F26: Miachael Dijanosic
D27: Guidance for FY25: 1% Revenue Growth | E27: Digital Director | F27: Javed Iqbal
B28: 46.000 Employees | D28: CAGR for nicotine value growth 2024-2035: 4,6% | E28: Operations Director | F28: Zafar Khan
D29: 2026: 3-6% revenue Growth | E29: CPO | F29: Dr. Cora Koppen-Stahrenberg
A30: x | B30: 5. Forces Model | E30: Corporate Director | F30: Paul McCrory
B31: 1. Competity Rivaliry | D31: Only real Threat is Phil Morris | E31: Regional Director | F31: Fred Monteiro
B32: 2. Threat of New Entrants | D32: No real threat -> very consolidated market -> High Moats due to Regulatory | E32: Research a. Science | F32: Dr James Murphy
B33: 3. Bargain Power of Supplier | D33: Low According to Creditors Metric | E33: COO | F33: Johan Vandermeulen
B34: 4. Bargain Power of Costumers | D34: Very low, Cigarrete Prices have been rising for years | E34: Ceo Reynolds | F34: David Waterfield
B35: 5. Threat of Substitutes | D35: Elfbar Vapes (illegal), Decling TAM | E35: CCO | F35: Kingsley Wheaton
E37: SWOT Analysis
A38: x | B38: Notes | F38: Opportunities | G38: Threats
B39: Founded 1902 | E39: Strength
B40: BTI Bond US05526DAZ87 | D40: 3,22% Coupon | E40: Weakness
B41: Global Volume exp. To be down 2% 2024
B42: FY23 Amortization and Impairment Charge of 23,202 Bn GBP
...

Sheet Products
A1: Main
A3: x | B3: Nicotine
B4: Belongs to the family of alkaloids and occurs naturally in a variety of plants as a neurotxin (tomatoes, potatoes, highest concentration on tobacco)
B5: Nicotine can cause acute increase in heart rate and blood pressure, a low dosis is not dangerous
B6: Consuming Nicotine doesnt cause harm, but is addicitive (pure nocotine is not very addictive)
B7: Toxicants that are produced while tobacco is burned is way more harmful than nicotine
B9: Smokefree Products
C11: Vapours
C12: Products:
C13: battery powered Devices that heat a e-liquid to produce an inhalble aerosol
C14: E-Liquid usually contains nicotine origanilly derived from Tobacco -> there is no Tobacco in Vapours products
C15: The Atomiser - the part that produces the vapour - contains a littel electric heater combined wiht a wick
C16: made from absorbant materials such as glass fibre, cotton or ceramic
C17: E-Liquid is drawn in the wick a tank -> heated to a form of vapour when the costumers puffs on the product
C18: Classified in open and closed systems
C19: Open systems can be costumized -> using a refillable tank -> Costumers can choose from a wide range of e-liquids
C20: Closed systems work with disposable pre-filled with e-liquid
C21: Closed sytems products Vuse e-Pod and Vuse e-Pen 3
C22: Scientific Evidence:
... C26: Vapour user had favorauble differences in biomarkers of exposure (boe) and biomarkers of potential harm (boph) compared to smokers
B28: Oral Tobacco
B30: Heatstick
B35: Cigarettes
B37: Brands: | C37: Dunhill, Kent, Lucky Strike, Pall Mall, Rothmans
B38: US: | C38: Camel, American Spirit, Newport
B39: International and local cigarette brands -> not part of portfolio
B40: Vogue, Viceroy, Kool, Peter Stuyvesant, Craven A, State Express 555, Shuang Xi
B42: Components:
B43: Tobacco rod, Cigarette paper, tipping paper, filter
B45: 8,6 Billion Tones Market Size in 2023
B46: 9,7 Billion until 2032
B47: -> 1,3% CAGR

Sheet Model
A1: Main
C2: H123 | D2: H223 | E2: H124 | F2: H224 | G2: H125 | H2: H225 | I2: H126 | J2: H226 | L2: FY14 | M2: FY15 | N2: FY16 | O2: FY17 | P2: FY18 | Q2: FY19 | R2: FY20 | S2: FY21 | T2: FY22 | U2: FY23 | V2: FY24 | W2: FY25 | X2: FY26 | Y2: FY27 | Z2: FY28 | AA2: FY29 | AB2: FY30 | AC2: FY31 | AD2: FY32 | AE2: FY33 | AF2: FY34
B3: Population | P3: 7732.989 | Q3: 7811.1 | R3: 7890 | S3: 7968.9 | T3: 8020 | U3: 8090 | V3: 8160 | W3: =V3*(1+0.8%) -> 8225.28 | X3: =W3*(1+0.8%) -> 8291.0822 | Y3: =X3*(1+0.8%) -> 8357.4109 | Z3: =Y3*(1+0.8%) -> 8424.2702 | AA3: =Z3*(1+0.8%) -> 8491.6643 | AB3: =AA3*(1+0.8%) -> 8559.5977 | AC3: =AB3*(1+0.8%) -> 8628.0744 | AD3: =AC3*(1+0.8%) -> 8697.099 | ... AF3: =AE3*(1+0.8%) -> 8836.8092
B4: Total Smokers | T4: 1254 | U4: =T4*0.98 -> 1228.92 | V4: =U4*0.98 -> 1204.3416 | W4: 1197 | X4: =W4*1.002 -> 1199.394 | Y4: =X4*1.002 -> 1201.7928 | Z4: =Y4*1.002 -> 1204.1964 | AA4: =Z4*1.002 -> 1206.6048 | AB4: 1227 | AC4: =AB4*1.002 -> 1229.454 | AD4: =AC4*1.002 -> 1231.9129 | AE4: =AD4*1.002 -> 1234.3767 | AF4: =AE4*1.002 -> 1236.8455
B5: Total Smokefree | T5: 259 | U5: =T5*1.03 -> 266.77 | V5: =U5*1.03 -> 274.7731 | W5: =V5*1.03 -> 283.01629 | X5: =W5*1.03 -> 291.50678 | Y5: =X5*1.03 -> 300.25199 | Z5: =Y5*1.03 -> 309.25954 | AA5: =Z5*1.03 -> 318.53733 | AB5: =AA5*1.03 -> 328.09345 | ... AF5: =AE5*1.03 -> 369.27207
B6: Smokefree Customers | E6: 26.4 | G6: 30.5 | P6: n.a. | Q6: n.a. | R6: 13.5 | S6: 18.3 | T6: 22.5 | U6: 23.9 | V6: =V5*9% -> 24.729579 | W6: 35 | X6: =X5*9% -> 26.23561 | Y6: =Y5*9% -> 27.022679 | Z6: =Z5*9% -> 27.833359 | AA6: =AA5*9% -> 28.66836 | AB6: =AB5*9% -> 29.528411 | AC6: =AC5*9% -> 30.414263 | AD6: =AD5*9% -> 31.326691 | AE6: =AE5*9% -> 32.266492 | AF6: =AF5*9% -> 33.234486
B7: Revenue per Costumer | R7: =SUM(R22:R25)/R6 -> 192.81481 | S7: =SUM(S22:S25)/S6 -> 173.33333 | T7: =SUM(T22:T25)/T6 -> 182.35556 | U7: =SUM(U22:U25)/U6 -> 188.70293 | V7: =SUM(V22:V25)/V6 -> 182.93882 | W7: =SUM(W22:W25)/W6 -> 133.25714 | X7: =W7*(1+1.5%) -> 135.256 | Y7: =X7*(1+1.5%) -> 137.28484 | Z7: =Y7*(1+1.5%) -> 139.34411 | AA7: =Z7*(1+1.5%) -> 141.43427 | AB7: =AA7*(1+1.5%) -> 143.55579 | AC7: =AB7*(1+1.5%) -> 145.70913 | AD7: =200 -> 200 | AE7: 200 | AF7: 200
B9: Volume in bn
B10: Vapours | C10: 0.319 | D10: =U10-C10 -> 0.335 | E10: 0.29 | F10: =+V10-E10 -> 0.3261 | G10: 0.253 | H10: =+W10-G10 -> 0.285 | P10: 0.189 | Q10: 0.226 | R10: 0.344 | S10: 0.535 | T10: 0.612 | U10: 0.654 | V10: 0.6161 | W10: 0.538
B11: THP | C11: 12.1 | D11: =U11-C11 -> 11.6 | E11: 9.9 | F11: =+V11-E11 -> 11 | G11: 10.1 | H11: =+W11-G11 -> 9.9 | P11: 7 | Q11: 9 | R11: 11 | S11: 19.1 | T11: 24 | U11: 23.7 | V11: 20.9 | W11: 20
B12: Modern Oral | C12: 2.348 | D12: =U12-C12 -> 3.012 | E12: 3.522 | F12: =+V12-E12 -> 4.778 | G12: 5 | H12: =+W12-G12 -> 7.2 | P12: n.a. | Q12: 1.194 | R12: 1.934 | S12: 3.296 | T12: 4.01 | U12: 5.36 | V12: 8.3 | W12: 12.2
B13: Traditional Oral | C13: 3 | D13: =U13-C13 -> 3.6 | E13: 3.1 | F13: =+V13-E13 -> 3 | G13: 2.9 | H13: =+W13-G13 -> 2.6 | P13: 3.9 | Q13: 8 | R13: 8 | S13: 8 | T13: 7.4 | U13: 6.6 | V13: 6.1 | W13: 5.5
B14: Combustibles | C14: 298.2 | D14: =U14-C14 -> 271.8 | E14: 256 | F14: =+V14-E14 -> 262 | G14: 234.1 | H14: =+W14-G14 -> 242.9 | P14: 701 | Q14: 668 | R14: 658 | S14: 655 | T14: 629 | U14: 570 | V14: 518 | W14: 477
B15: Total | C15: =SUM(C10:C14) -> 315.967 | D15: =SUM(D10:D14) -> 290.347 | E15: =SUM(E10:E14) -> 272.812 | F15: =SUM(F10:F14) -> 281.1041 | G15: =SUM(G10:G14) -> 252.353 | H15: =+W15-G15 -> 262.885 | L15: 694 | M15: 689 | N15: 689 | O15: 714 | P15: =SUM(P10:P14) -> 712.089 | Q15: =SUM(Q10:Q14) -> 686.42 | R15: =SUM(R10:R14) -> 679.278 | S15: =SUM(S10:S14) -> 685.931 | T15: =SUM(T10:T14) -> 665.022 | U15: =SUM(U10:U14) -> 606.314 | V15: =SUM(V10:V14) -> 553.9161 | W15: =SUM(W10:W14) -> 515.238 | ... AE15: =SUM(AE10:AE14) -> 0
B17: Total Industry (in billions) | U17: 8600 | V17: =U17*(1+1.3%) -> 8711.8 | W17: =V17*(1+1.3%) -> 8825.0534 | X17: =W17*(1+1.3%) -> 8939.7791 | Y17: =X17*(1+1.3%) -> 9055.9962 | Z17: =Y17*(1+1.3%) -> 9173.7242 | AA17: =Z17*(1+1.3%) -> 9292.9826 | AB17: =AA17*(1+1.3%) -> 9413.7914 | AC17: =AB17*(1+1.3%) -> 9536.1706 | ... AF17: =AE17*(1+1.3%) -> 9912.9371
A19: x | B19: US Revenue | E19: 5378 | F19: =+V19-E19 -> 5900 | G19: 5432 | H19: =+W19-G19 -> 6102 | L19: 0 | M19: 0 | N19: 0 | O19: 4221 | P19: 9495 | Q19: 10373 | R19: 11473 | S19: 11691 | T19: 12639 | U19: 11592 | V19: 11278 | W19: 11534
B20: AME Revenue | E20: 4376 | F20: =+V20-E20 -> 4865 | G20: 4281 | H20: =+W20-G20 -> 5028 | L20: =2720+3203+3408 -> 9331 | M20: =3340+3476+4030 -> 10846 | N20: =2868+3867+3750 -> 10485 | O20: =3125+4532+3915 -> 11572 | P20: =4111+6004 -> 10115 | Q20: =4261+6090 -> 10351 | R20: =3772+5994 -> 9766 | S20: =3801+6001 -> 9802 | T20: =4203+6346 -> 10549 | U20: 9764 | V20: 9241 | W20: 9309
B21: APMEA Revenue | E21: 2586 | F21: =+V21-E21 -> 2762 | G21: 2356 | H21: =+W21-G21 -> 2411 | L21: 3873 | M21: 3773 | N21: 4266 | O21: 4509 | P21: 4882 | Q21: 5153 | R21: 4537 | S21: 4191 | T21: 4467 | U21: 5795 | V21: 5348 | W21: 4767
B22: Vapours | C22: 866 | D22: =U22-C22 -> 946 | E22: 869 | F22: =+V22-E22 -> 852 | G22: 737 | H22: =+W22-G22 -> 805 | P22: 318 | Q22: 401 | R22: 611 | S22: 927 | T22: 1436 | U22: 1812 | V22: 1721 | W22: 1542
B23: THP | C23: 550 | D23: =U23-C23 -> 446 | E23: 441 | F23: =+V23-E23 -> 480 | G23: 444 | H23: =+W23-G23 -> 470 | P23: 565 | Q23: 728 | R23: 634 | S23: 853 | T23: 1060 | U23: 996 | V23: 921 | W23: 914
B24: Modern Oral | C24: 240 | D24: =U24-C24 -> 299 | E24: 341 | F24: =+V24-E24 -> 449 | G24: 470 | H24: =+W24-G24 -> 695 | P24: 34 | Q24: 126 | R24: 198 | S24: 274 | T24: 398 | U24: 539 | V24: 790 | W24: 1165
B25: Traditional Oral | C25: 571 | D25: =U25-C25 -> 592 | E25: 555 | F25: =+V25-E25 -> 537 | G25: 542 | H25: =+W25-G25 -> 501 | P25: 883 | Q25: 1081 | R25: 1160 | S25: 1118 | T25: 1209 | U25: 1163 | V25: 1092 | W25: 1043
B26: Smoke Free | C26: =SUM(C22:C25) -> 2227 | D26: =SUM(D22:D25) -> 2283 | E26: =SUM(E22:E25) -> 2206 | F26: =+V26-E26 -> 2318 | G26: 2193 | H26: =+W26-G26 -> 2471 | P26: =SUM(P22:P25) -> 1800 | Q26: =SUM(Q22:Q25) -> 2336 | R26: =SUM(R22:R25) -> 2603 | S26: =SUM(S22:S25) -> 3172 | T26: =SUM(T22:T25) -> 4103 | U26: =SUM(U22:U25) -> 4510 | V26: =SUM(V22:V25) -> 4524 | W26: =3621+1043 -> 4664 | X26: =X7*X6 -> 3548.5237 | Y26: =Y7*Y6 -> 3709.8041 | Z26: =Z7*Z6 -> 3878.4147 | AA26: =AA7*AA6 -> 4054.6887 | AB26: =AB7*AB6 -> 4238.9743 | AC26: =AC7*AC6 -> 4431.6356 | AD26: =AD7*AD6 -> 6265.3382 | AE26: =AE7*AE6 -> 6453.2983 | AF26: =AF7*AF6 -> 6646.8973
B27: Total Combustibles | C27: 10967 | D27: =U27-C27 -> 11141 | E27: 9856 | F27: =+V27-E27 -> 10829 | G27: 9515 | H27: =+W27-G27 -> 10686 | P27: 15457 | Q27: 23001 | R27: 22752 | S27: 22029 | T27: 23030 | U27: 22108 | V27: 20685 | W27: 20201 | X27: =W27*(1-1%) -> 19998.99 | Y27: =X27*(1-1%) -> 19799 | Z27: =Y27*(1-1%) -> 19601.01 | AA27: =Z27*(1-1%) -> 19405 | AB27: =AA27*(1-1%) -> 19210.95 | AC27: =AB27*(1-1%) -> 19018.84 | AD27: =AC27*(1-2%) -> 18638.464 | AE27: =AD27*(1-2%) -> 18265.694 | AF27: =AE27*(1-2%) -> 17900.381
B28: Other | C28: 247 | D28: =U28-C28 -> 418 | E28: 278 | F28: =+V28-E28 -> 380 | G28: 361 | H28: =+W28-G28 -> 395 | P28: 7235 | Q28: 540 | R28: 421 | S28: 483 | T28: 522 | U28: 665 | V28: 658 | W28: 756 | X28: =W28*(1+1%) -> 763.56 | Y28: =X28*(1+1%) -> 771.1956 | Z28: =Y28*(1+1%) -> 778.90756 | AA28: =Z28*(1+1%) -> 786.69663 | AB28: =AA28*(1+1%) -> 794.5636 | AC28: =AB28*(1+1%) -> 802.50923 | AD28: =AC28*(1+1%) -> 810.53433 | AE28: =AD28*(1+1%) -> 818.63967 | AF28: =AE28*(1+1%) -> 826.82607
B29: Revenue | C29: 13441 | D29: =U29-C29 -> 13842 | E29: 12340 | F29: =+V29-E29 -> 13527 | G29: 12069 | H29: =+W29-G29 -> 13541 | L29: 13971 | M29: 13104 | N29: 14751 | O29: 20292 | P29: 24492 | Q29: 25877 | R29: 25776 | S29: 25684 | T29: 27655 | U29: 27283 | V29: =SUM(V26:V28) -> 25867 | W29: 25610 | X29: =SUM(X22:X28) -> 24311.074 | Y29: =SUM(Y22:Y28) -> 24280 | Z29: =SUM(Z22:Z28) -> 24258.332 | AA29: =SUM(AA22:AA28) -> 24246.385 | AB29: =SUM(AB22:AB28) -> 24244.488 | AC29: =SUM(AC22:AC28) -> 24252.985 | AD29: =SUM(AD22:AD28) -> 25714.336 | AE29: =SUM(AE22:AE28) -> 25537.632 | AF29: =SUM(AF22:AF28) -> 25374.104
B30: Cost of Materials | C30: 2251 | D30: =U30-C30 -> 2294 | E30: 2304 | F30: =+V30-E30 -> 2261 | G30: 2166 | H30: =+W30-G30 -> 2299 | L30: 3088 | M30: 3217 | N30: 3777 | O30: 4520 | P30: 4664 | Q30: 4599 | R30: 4583 | S30: 4542 | T30: 4781 | U30: 4545 | V30: 4565 | W30: 4465 | X30: =W30*(1-0.1%) -> 4460.535 | Y30: =X30*(1-0.1%) -> 4456.0745 | Z30: =Y30*(1-0.1%) -> 4451.6184 | AA30: =Z30*(1-0.1%) -> 4447.1668 | AB30: =AA30*(1-0.1%) -> 4442.7196 | AC30: =AB30*(1-0.1%) -> 4438.2769 | AD30: =AC30*(1-0.1%) -> 4433.8386 | AE30: =AD30*(1-0.1%) -> 4429.4048 | AF30: =AE30*(1-0.1%) -> 4424.9754
B31: Changes in inventories of finished goods | C31: 7 | D31: =U31-C31 -> -103 | E31: 140 | F31: =+V31-E31 -> -11 | G31: 185 | H31: =+W31-G31 -> 54 | L31: 58 | M31: 184 | N31: 44 | O31: -513 | P31: 114 | Q31: 162 | R31: 445 | S31: 160 | T31: 227 | U31: -96 | V31: 129 | W31: 239 | X31: =W31*(1-0.1%) -> 238.761 | Y31: =X31*(1-0.1%) -> 238.52224 | Z31: =Y31*(1-0.1%) -> 238.28372 | AA31: =Z31*(1-0.1%) -> 238.04543 | AB31: =AA31*(1-0.1%) -> 237.80739 | AC31: =AB31*(1-0.1%) -> 237.56958 | AD31: =AC31*(1-0.1%) -> 237.33201 | AE31: =AD31*(1-0.1%) -> 237.09468 | AF31: =AE31*(1-0.1%) -> 236.85758
B32: Employee benefit cost | C32: 1389 | D32: =U32-C32 -> 1275 | E32: 1375 | F32: =+V32-E32 -> 1456 | G32: 1463 | H32: =+W32-G32 -> 1662 | L32: 2194 | M32: 2039 | N32: 2274 | O32: 2679 | P32: 3005 | Q32: 3221 | R32: 2744 | S32: 2717 | T32: 2972 | U32: 2664 | V32: 2831 | W32: 3125 | X32: =W32*(1-0.1%) -> 3121.875 | Y32: =X32*(1-0.1%) -> 3118.7531 | Z32: =Y32*(1-0.1%) -> 3115.6344 | AA32: =Z32*(1-0.1%) -> 3112.5187 | AB32: =AA32*(1-0.1%) -> 3109.4062 | AC32: =AB32*(1-0.1%) -> 3106.2968 | AD32: =AC32*(1-0.1%) -> 3103.1905 | AE32: =AD32*(1-0.1%) -> 3100.0873 | AF32: =AE32*(1-0.1%) -> 3096.9872
B33: Gross Profit | C33: =C29-C30+C31-C32 -> 9808 | D33: =D29-D30+D31-D32 -> 10170 | E33: =E29-E30+E31-E32 -> 8801 | F33: =F29-F30+F31-F32 -> 9799 | G33: =G29-G30+G31-G32 -> 8625 | H33: =H29-H30+H31-H32 -> 9634 | L33: =L29-L30+L31-L32 -> 8747 | M33: =M29-M30+M31-M32 -> 8032 | N33: =N29-N30+N31-N32 -> 8744 | O33: =O29-O30+O31-O32 -> 12580 | P33: =P29-P30+P31-P32 -> 16937 | Q33: =Q29-Q30+Q31-Q32 -> 18219 | R33: =R29-R30+R31-R32 -> 18894 | S33: =S29-S30+S31-S32 -> 18585 | ... AF33: =AF29-AF30+AF31-AF32 -> 18088.999
B34: D&A | C34: 480 | D34: =U34-C34 -> 28134 | E34: 1620 | F34: =+V34-E34 -> 1481 | G34: 1192 | H34: =+W34-G34 -> 1355 | L34: 523 | M34: 428 | N34: 607 | O34: 902 | P34: 1038 | Q34: 1512 | R34: 1450 | S34: 1076 | T34: 1305 | U34: 28614 | V34: 3101 | W34: 2547 | X34: =W34*(1-0.1%) -> 2544.453 | Y34: =X34*(1-0.1%) -> 2541.9085 | Z34: =Y34*(1-0.1%) -> 2539.3666 | AA34: =Z34*(1-0.1%) -> 2536.8273 | AB34: =AA34*(1-0.1%) -> 2534.2904 | AC34: =AB34*(1-0.1%) -> 2531.7562 | AD34: =AC34*(1-0.1%) -> 2529.2244 | AE34: =AD34*(1-0.1%) -> 2526.6952 | AF34: =AE34*(1-0.1%) -> 2524.1685
B35: Other Operating Income | C35: 239 | D35: =U35-C35 -> 193 | E35: 223 | F35: =+V35-E35 -> 117 | G35: 54 | H35: =+W35-G35 -> 138 | L35: 178 | M35: 225 | N35: 176 | O35: 144 | P35: 85 | Q35: 163 | R35: 188 | S35: 196 | T35: 722 | U35: 432 | V35: 340 | W35: 192 | X35: =W35*(1-0.1%) -> 191.808 | Y35: =X35*(1-0.1%) -> 191.61619 | Z35: =Y35*(1-0.1%) -> 191.42458 | AA35: =Z35*(1-0.1%) -> 191.23315 | AB35: =AA35*(1-0.1%) -> 191.04192 | AC35: =AB35*(1-0.1%) -> 190.85088 | AD35: =AC35*(1-0.1%) -> 190.66003 | AE35: =AD35*(1-0.1%) -> 190.46937 | AF35: =AE35*(1-0.1%) -> 190.2789
B36: Loss on Impairment of Assets | C36: 3 | D36: =U36-C36 -> 6 | E36: 4 | F36: =+V36-E36 -> 6 | G36: 5 | H36: =+W36-G36 -> 7 | L36: 0 | M36: 0 | N36: 0 | O36: 0 | P36: 3 | Q36: 3 | R36: 3 | S36: 3 | T36: 5 | U36: 9 | V36: 10 | W36: 12 | X36: =W36*(1-0.1%) -> 11.988 | Y36: =X36*(1-0.1%) -> 11.976012 | Z36: =Y36*(1-0.1%) -> 11.964036 | AA36: =Z36*(1-0.1%) -> 11.952072 | AB36: =AA36*(1-0.1%) -> 11.94012 | AC36: =AB36*(1-0.1%) -> 11.92818 | AD36: =AC36*(1-0.1%) -> 11.916252 | AE36: =AD36*(1-0.1%) -> 11.904335 | AF36: =AE36*(1-0.1%) -> 11.892431
B37: Other Operating Expenses | C37: 3629 | D37: =U37-C37 -> 3909 | E37: 3142 | F37: =+V37-E37 -> 9951 | G37: 2413 | H37: =+W37-G37 -> 3482 | L37: 3856 | M37: 3272 | N37: 3658 | O37: 5346 | P37: 6668 | Q37: 7851 | R37: 7667 | S37: 7468 | T37: 9018 | U37: 7538 | V37: 13093 | W37: 5895 | X37: =W37*(1-0.1%) -> 5889.105 | Y37: =X37*(1-0.1%) -> 5883.2159 | Z37: =Y37*(1-0.1%) -> 5877.3327 | AA37: =Z37*(1-0.1%) -> 5871.4553 | AB37: =AA37*(1-0.1%) -> 5865.5839 | AC37: =AB37*(1-0.1%) -> 5859.7183 | AD37: =AC37*(1-0.1%) -> 5853.8586 | AE37: =AD37*(1-0.1%) -> 5848.0047 | AF37: =AE37*(1-0.1%) -> 5842.1567
B38: Operating Profit | C38: =C33-C34+C35-C36-C37 -> 5935 | D38: =D33-D34+D35-D36-D37 -> -21686 | E38: =E33-E34+E35-E36-E37 -> 4258 | F38: =F33-F34+F35-F36-F37 -> -1522 | G38: =G33-G34+G35-G36-G37 -> 5069 | H38: =H33-H34+H35-H36-H37 -> 4928 | L38: =L33-L34+L35-L36-L37 -> 4546 | M38: =M33-M34+M35-M36-M37 -> 4557 | N38: =N33-N34+N35-N36-N37 -> 4655 | O38: =O33-O34+O35-O36-O37 -> 6476 | P38: =P33-P34+P35-P36-P37 -> 9313 | Q38: =Q33-Q34+Q35-Q36-Q37 -> 9016 | R38: =R33-R34+R35-R36-R37 -> 9962 | S38: =S33-S34+S35-S36-S37 -> 10234 | ... W38: =W33-W34+W35-W36-W37 -> 9997 | X38: =39%*X29 -> 9481.3187 | Y38: =39%*Y29 -> 9469.1999 | Z38: =39%*Z29 -> 9460.7496 | AA38: =39%*AA29 -> 9456.0903 | AB38: =39%*AB29 -> 9455.3503 | AC38: =39%*AC29 -> 9458.6643 | AD38: =39%*AD29 -> 10028.591 | AE38: =39%*AE29 -> 9959.6766 | AF38: =39%*AF29 -> 9895.9005
B39: Financial Result | C39: -921 | D39: =U39-C39 -> -974 | E39: -305 | F39: =+V39-E39 -> -793 | G39: -969 | H39: =+W39-G39 -> -850 | L39: -417 | M39: 62 | N39: -637 | O39: -1094 | P39: -1381 | Q39: -1602 | R39: -1745 | S39: -1486 | T39: -1641 | U39: -1895 | V39: -1098 | W39: -1819 | X39: =W39*(1-0.1%) -> -1817.181 | Y39: =X39*(1-0.1%) -> -1815.3638 | Z39: =Y39*(1-0.1%) -> -1813.5485 | AA39: =Z39*(1-0.1%) -> -1811.7349 | AB39: =AA39*(1-0.1%) -> -1809.9232 | AC39: =AB39*(1-0.1%) -> -1808.1132 | AD39: =AC39*(1-0.1%) -> -1806.3051 | AE39: =AD39*(1-0.1%) -> -1804.4988 | AF39: =AE39*(1-0.1%) -> -1802.6943
B40: Post Tax Income of Asscociates/Joint Ventures | C40: 289 | D40: =U40-C40 -> 296 | E40: 1647 | F40: =+V40-E40 -> 253 | G40: 1474 | H40: =+W40-G40 -> 207 | L40: 719 | M40: 1236 | N40: 2227 | O40: 24209 | P40: 419 | Q40: 498 | R40: 455 | S40: 415 | T40: 442 | U40: 585 | V40: 1900 | W40: 1681 | X40: =W40*(1-0.1%) -> 1679.319 | Y40: =X40*(1-0.1%) -> 1677.6397 | Z40: =Y40*(1-0.1%) -> 1675.962 | AA40: =Z40*(1-0.1%) -> 1674.2861 | AB40: =AA40*(1-0.1%) -> 1672.6118 | AC40: =AB40*(1-0.1%) -> 1670.9392 | AD40: =AC40*(1-0.1%) -> 1669.2682 | AE40: =AD40*(1-0.1%) -> 1667.599 | AF40: =AE40*(1-0.1%) -> 1665.9314
B41: Pretax Income | C41: =C38+SUM(C39:C40) -> 5303 | D41: =D38+SUM(D39:D40) -> -22364 | E41: =E38+SUM(E39:E40) -> 5600 | F41: =F38+SUM(F39:F40) -> -2062 | G41: =G38+SUM(G39:G40) -> 5574 | H41: =H38+SUM(H39:H40) -> 4285 | L41: =L38+SUM(L39:L40) -> 4848 | M41: =M38+SUM(M39:M40) -> 5855 | N41: =N38+SUM(N39:N40) -> 6245 | O41: =O38+SUM(O39:O40) -> 29591 | P41: =P38+SUM(P39:P40) -> 8351 | Q41: =Q38+SUM(Q39:Q40) -> 7912 | R41: =R38+SUM(R39:R40) -> 8672 | S41: =S38+SUM(S39:S40) -> 9163 | ... AF41: =AF38+SUM(AF39:AF40) -> 9759.1375
B42: Income Tax | C42: 1268 | D42: =U42-C42 -> -4140 | E42: 1041 | F42: =+V42-E42 -> -684 | G42: 1009 | H42: =+W42-G42 -> 1085 | L42: 1455 | M42: 1333 | N42: 1406 | O42: 8113 | P42: 2141 | Q42: 2063 | R42: 2108 | S42: 2189 | T42: 2478 | U42: -2872 | V42: 357 | W42: 2094 | X42: =X41*X64 -> 2024.1913 | Y42: =Y41*Y64 -> 2062.0277 | Z42: =Z41*Z64 -> 2101.3946 | AA42: =AA41*AA64 -> 2142.3829 | AB42: =AB41*AB64 -> 2185.0893 | AC42: =AC41*AC64 -> 2229.6166 | AD42: =AD41*AD64 -> 2413.2902 | AE42: =AE41*AE64 -> 2444.4404 | AF42: =AF41*AF64 -> 2477.1756
B43: Net Income | C43: =C41-C42 -> 4035 | D43: =D41-D42 -> -18224 | E43: =E41-E42 -> 4559 | F43: =F41-F42 -> -1378 | G43: =G41-G42 -> 4565 | H43: =H41-H42 -> 3200 | L43: =L41-L42 -> 3393 | M43: =M41-M42 -> 4522 | N43: =N41-N42 -> 4839 | O43: =O41-O42 -> 21478 | P43: =P41-P42 -> 6210 | Q43: =Q41-Q42 -> 5849 | R43: =R41-R42 -> 6564 | S43: =S41-S42 -> 6974 | ... AF43: =AF41-AF42 -> 7281.9619
...

Sheet Ratios
A1: Main
B2: Ratios | D2: FY14 | E2: FY15 | F2: FY16 | G2: FY17 | H2: 18 | I2: =H2+1 -> 19 | J2: =I2+1 -> 20 | K2: =J2+1 -> 21 | L2: =K2+1 -> 22 | M2: =L2+1 -> 23 | N2: =M2+1 -> 24 | P2: Average | Q2: Median
A3: x | B3: Efficieny
B4: Return on Equity (ROE) | D4: =Model!L43/AVERAGE(Model!L91,Model!#REF!) -> #REF! | E4: =Model!M43/AVERAGE(Model!M91,Model!L91) -> 0.8338558 | F4: =Model!N43/AVERAGE(Model!N91,Model!M91) -> 0.72019646 | G4: =Model!O43/AVERAGE(Model!O91,Model!N91) -> 0.61867727 | H4: =Model!P43/AVERAGE(Model!P91,Model!O91) -> 0.098016005 | I4: =Model!Q43/AVERAGE(Model!Q91,Model!P91) -> 0.090089951 | J4: =Model!R43/AVERAGE(Model!R91,Model!Q91) -> 0.10327656 | K4: =Model!S43/AVERAGE(Model!S91,Model!R91) -> 0.10699929 | L4: =Model!T43/AVERAGE(Model!T91,Model!S91) -> 0.095673987 | ... N4: =Model!V43/AVERAGE(Model!V91,Model!U91) -> 0.061809597 | P4: =AVERAGE(C4:L4) -> #REF! | Q4: =MEDIAN(C4:L4) -> #REF!
B5: Return on Capital Employed (ROCE) | D5: =Model!L38/AVERAGE(Model!L74+Model!L75+Model!L76+Model!L77-Model!L102-Model!L96,Model!#REF!+Model!#REF!+Model!#REF!+Model!#REF!-Model!#REF!-Model!#REF!) -> #REF! | E5: =Model!M38/AVERAGE(Model!M74+Model!M75+Model!M76+Model!M77-Model!M102-Model!M96,Model!L74+Model!L75+Model!L76+Model!L77-Model!L96-Model!L102) -> 0.22413496 | F5: =Model!N38/AVERAGE(Model!N74+Model!N75+Model!N76+Model!N77-Model!N102-Model!N96,Model!M74+Model!M75+Model!M76+Model!M77-Model!M96-Model!M102) -> 0.18216683 | G5: =Model!O38/AVERAGE(Model!O74+Model!O75+Model!O76+Model!O77-Model!O102-Model!O96,Model!N74+Model!N75+Model!N76+Model!N77-Model!N96-Model!N102) -> 0.082850911 | H5: =Model!P38/AVERAGE(Model!P74+Model!P75+Model!P76+Model!P77-Model!P102-Model!P96,Model!O74+Model!O75+Model!O76+Model!O77-Model!O96-Model!O102) -> 0.071849589 | I5: =Model!Q38/AVERAGE(Model!Q74+Model!Q75+Model!Q76+Model!Q77-Model!Q102-Model!Q96,Model!P74+Model!P75+Model!P76+Model!P77-Model!P96-Model!P102) -> 0.069629418 | J5: =Model!R38/AVERAGE(Model!R74+Model!R75+Model!R76+Model!R77-Model!R102-Model!R96,Model!Q74+Model!Q75+Model!Q76+Model!Q77-Model!Q96-Model!Q102) -> 0.079569326 | K5: =Model!S38/AVERAGE(Model!S74+Model!S75+Model!S76+Model!S77-Model!S102-Model!S96,Model!R74+Model!R75+Model!R76+Model!R77-Model!R96-Model!R102) -> 0.083046274 | L5: =Model!T38/AVERAGE(Model!T74+Model!T75+Model!T76+Model!T77-Model!T102-Model!T96,Model!S74+Model!S75+Model!S76+Model!S77-Model!S96-Model!S102) -> 0.080860007 | ... N5: =Model!V38/AVERAGE(Model!V74+Model!V75+Model!V76+Model!V77-Model!V102-Model!V96,Model!U74+Model!U75+Model!U76+Model!U77-Model!U96-Model!U102) -> 0.026650432 | P5: =AVERAGE(C5:L5) -> #REF! | Q5: =MEDIAN(C5:L5) -> #REF!
B6: Return on Capital Invested (ROIC) | D6: =(Model!L38*(1-Model!L64))/AVERAGE(Model!L91+Model!L92+Model!L99+Model!L103+Model!L97-Model!L80,Model!#REF!+Model!#REF!+Model!#REF!+Model!#REF!+Model!#REF!-Model!#REF!) -> #REF! | E6: =(Model!M38*(1-Model!M64))/AVERAGE(Model!M91+Model!M92+Model!M99+Model!M103+Model!M97-Model!M80,Model!L91+Model!L92+Model!L97+Model!L99+Model!L103-Model!L80) -> 0.19081127 | F6: =(Model!N38*(1-Model!N64))/AVERAGE(Model!N91+Model!N92+Model!N99+Model!N103+Model!N97-Model!N80,Model!M91+Model!M92+Model!M97+Model!M99+Model!M103-Model!M80) -> 0.15430239 | G6: =(Model!O38*(1-Model!O64))/AVERAGE(Model!O91+Model!O92+Model!O99+Model!O103+Model!O97-Model!O80,Model!N91+Model!N92+Model!N97+Model!N99+Model!N103-Model!N80) -> 0.070269499 | H6: =(Model!P38*(1-Model!P64))/AVERAGE(Model!P91+Model!P92+Model!P99+Model!P103+Model!P97-Model!P80,Model!O91+Model!O92+Model!O97+Model!O99+Model!O103-Model!O80) -> 0.063381374 | I6: =(Model!Q38*(1-Model!Q64))/AVERAGE(Model!Q91+Model!Q92+Model!Q99+Model!Q103+Model!Q97-Model!Q80,Model!P91+Model!P92+Model!P97+Model!P99+Model!P103-Model!P80) -> 0.060986092 | J6: =(Model!R38*(1-Model!R64))/AVERAGE(Model!R91+Model!R92+Model!R99+Model!R103+Model!R97-Model!R80,Model!Q91+Model!Q92+Model!Q97+Model!Q99+Model!Q103-Model!Q80) -> 0.071280329 | K6: =(Model!S38*(1-Model!S64))/AVERAGE(Model!S91+Model!S92+Model!S99+Model!S103+Model!S97-Model!S80,Model!R91+Model!R92+Model!R97+Model!R99+Model!R103-Model!R80) -> 0.074656202 | L6: =(Model!T38*(1-Model!T64))/AVERAGE(Model!T91+Model!T92+Model!T99+Model!T103+Model!T97-Model!T80,Model!S91+Model!S92+Model!S97+Model!S99+Model!S103-Model!S80) -> 0.069954611 | ... N6: =(Model!V38*(1-Model!V64))/AVERAGE(Model!V91+Model!V92+Model!V99+Model!V103+Model!V97-Model!V80,Model!U91+Model!U92+Model!U97+Model!U99+Model!U103-Model!U80) -> 0.028860169 | P6: =AVERAGE(C6:L6) -> #REF! | Q6: =MEDIAN(C6:L6) -> #REF!
B7: Retention Rate | D7: =1-(-1*((Model!L142+Model!L144))/Model!L43) -> 0.12732095 | E7: =1-(-1*((Model!M142+Model!M144))/Model!M43) -> 0.33547103 | F7: =1-(-1*((Model!N142+Model!N144))/Model!N43) -> 0.3682579 | G7: =1-(-1*((Model!O142+Model!O144))/Model!O43) -> 0.83089673 | H7: =1-(-1*((Model!P142+Model!P144))/Model!P43) -> 0.27713366 | I7: =1-(-1*((Model!Q142+Model!Q144))/Model!Q43) -> 0.18704052 | J7: =1-(-1*((Model!R142+Model!R144))/Model!R43) -> 0.25639854 | K7: =1-(-1*((Model!S142+Model!S144))/Model!S43) -> 0.27530829 | ... N7: =1-(-1*((Model!V142+Model!V144))/Model!V43) -> -0.67683119 | P7: =AVERAGE(C7:L7) -> 0.32409011 | Q7: =MEDIAN(C7:L7) -> 0.27530829
B8: Expected Growth | D8: =D7*D4 -> #REF! | E8: =E7*E4 -> 0.27973446 | F8: =F7*F4 -> 0.26521804 | G8: =G7*G4 -> 0.51405692 | H8: =H7*H4 -> 0.027163534 | I8: =I7*I4 -> 0.016850471 | J8: =J7*J4 -> 0.026479959 | K8: =K7*K4 -> 0.029457793 | ... N8: =N7*N4 -> -0.041834663 | P8: =AVERAGE(C8:L8) -> #REF! | Q8: =MEDIAN(C8:L8) -> #REF!
B9: Reinvestment Rate | D9: =(-1*(Model!L117-Model!L123))/(Model!L38*(1-Model!L64)) -> -0.014143661 | E9: =(-1*(Model!M117-Model!M123))/(Model!M38*(1-Model!M64)) -> -0.25770604 | F9: =(-1*(Model!N117-Model!N123))/(Model!N38*(1-Model!N64)) -> -0.060161252 | G9: =(-1*(Model!O117-Model!O123))/(Model!O38*(1-Model!O64)) -> 0.11786062 | H9: =(-1*(Model!P117-Model!P123))/(Model!P38*(1-Model!P64)) -> -0.33904346 | I9: =(-1*(Model!Q117-Model!Q123))/(Model!Q38*(1-Model!Q64)) -> -0.14673361 | J9: =(-1*(Model!R117-Model!R123))/(Model!R38*(1-Model!R64)) -> -0.082223479 | K9: =(-1*(Model!S117-Model!S123))/(Model!S38*(1-Model!S64)) -> -0.059698481 | ... N9: =(-1*(Model!V117-Model!V123))/(Model!V38*(1-Model!V64)) -> -2.5456057 | P9: =AVERAGE(C9:L9) -> -0.1025412 | Q9: =MEDIAN(C9:L9) -> -0.081021473
B10: Expected Growth | D10: =D9*D6 -> #REF! | E10: =E9*E6 -> -0.049173218 | F10: =F9*F6 -> -0.0092830253 | G10: =G9*G6 -> 0.0082820068 | H10: =H9*H6 -> -0.02148904 | I10: =I9*I6 -> -0.0089487096 | J10: =J9*J6 -> -0.0058609167 | K10: =K9*K6 -> -0.0044568619 | ... N10: =N9*N6 -> -0.07346661 | P10: =AVERAGE(C10:L10) -> #REF! | Q10: =MEDIAN(C10:L10) -> #REF!
A13: x | B13: Financial Stability
B14: EK-Quote | D14: =Model!L91/Model!L106 -> 0.22218825 | E14: =Model!M91/Model!M106 -> 0.15967 | F14: =Model!N91/Model!N106 -> 0.21134941 | G14: =Model!O91/Model!O106 -> 0.4326919 | H14: =Model!P91/Model!P106 -> 0.44886635 | I14: =Model!Q91/Model!Q106 -> 0.45501933 | J14: =Model!R91/Model!R106 -> 0.45722275 | K14: =Model!S91/Model!S106 -> 0.49067084 | ... N14: =Model!V91/Model!V106 -> 0.42048293 | P14: =AVERAGE(C14:M14) -> 0.38166435 | Q14: =MEDIAN(C14:M14) -> 0.44737701
B15: Gearing | D15: =D32/Model!L91 -> 1.7901617 | E15: =E32/Model!M91 -> 2.9844992 | F15: =F32/Model!N91 -> 2.0547228 | G15: =G32/Model!O91 -> 0.75630059 | H15: =H32/Model!P91 -> 0.68356473 | I15: =I32/Model!Q91 -> 0.66765898 | J15: =J32/Model!R91 -> 0.64849496 | K15: =K32/Model!S91 -> 0.54652008 | ... N15: =N32/Model!V91 -> 0.62492249 | P15: =AVERAGE(C15:M15) -> 1.1308347 | Q15: =MEDIAN(C15:M15) -> 0.67561185
B16: Interest Coverage Ratio | D16: =Model!L38/((Model!L132+Model!L133)*-1) -> 7.9614711 | E16: =Model!M38/((Model!M132+Model!M133)*-1) -> 7.6331658 | F16: =Model!N38/((Model!N132+Model!N133)*-1) -> 7.2620905 | G16: =Model!O38/((Model!O132+Model!O133)*-1) -> 5.8132855 | H16: =Model!P38/((Model!P132+Model!P133)*-1) -> 5.9737011 | I16: =Model!Q38/((Model!Q132+Model!Q133)*-1) -> 5.5211268 | J16: =Model!R38/((Model!R132+Model!R133)*-1) -> 5.6505956 | K16: =Model!S38/((Model!S132+Model!S133)*-1) -> 6.8135819 | ... N16: =Model!V38/((Model!V132+Model!V133)*-1) -> 1.5724138 | P16: =AVERAGE(C16:M16) -> 4.9993234 | Q16: =AVERAGE(C16:M16) -> 4.9993234
B17: Net Debt / EBITDA | D17: =D32/(Model!L38+Model!L109) -> 2.0532649 | E17: =E32/(Model!M38+Model!M109) -> 3.0126379 | F17: =F32/(Model!N38+Model!N109) -> 3.2824021 | G17: =G32/(Model!O38+Model!O109) -> 6.2556248 | H17: =H32/(Model!P38+Model!P109) -> 4.3379384 | I17: =I32/(Model!Q38+Model!Q109) -> 4.068864 | J17: =J32/(Model!R38+Model!R109) -> 3.5774623 | K17: =K32/(Model!S38+Model!S109) -> 3.2569408 | ... N17: =N32/(Model!V38+Model!V109) -> 5.3525784 | P17: =AVERAGE(C17:M17) -> 3.5861554 | Q17: =MEDIAN(C17:M17) -> 3.2867033
B18: Goodwill-Anteil | D18: =Model!L66/Model!L83 -> 0.41288646 | E18: =Model!M66/Model!M83 -> 0.3311439 | F18: =Model!N66/Model!N83 -> 0.30465391 | G18: =Model!O66/Model!O83 -> 0.83512954 | H18: =Model!P66/Model!P83 -> 0.84741906 | I18: =Model!Q66/Model!Q83 -> 0.84243112 | J18: =Model!R66/Model!R83 -> 0.83770063 | K18: =Model!S66/Model!S83 -> 0.84173552 | ... N18: =Model!V66/Model!V83 -> 0.79290827 | P18: =AVERAGE(C18:M18) -> 0.68986908 | Q18: =MEDIAN(C18:M18) -> 0.83641509
A20: x | B20: WC Management
B21: Debitorenlaufzeit | D21: =Model!L77/Model!L29*360 -> 71.324887 | E21: =Model!M77/Model!M29*360 -> 89.725275 | F21: =Model!N77/Model!N29*360 -> 94.789506 | G21: =Model!O77/Model!O29*360 -> 71.904199 | H21: =Model!P77/Model!P29*360 -> 52.738854 | I21: =Model!Q77/Model!Q29*360 -> 56.941686 | J21: =Model!R77/Model!R29*360 -> 51.969274 | K21: =Model!S77/Model!S29*360 -> 55.379224 | ... N21: =Model!V77/Model!V29*360 -> 50.158117 | P21: =AVERAGE(C21:M21) -> 64.939969 | Q21: =MEDIAN(C21:M21) -> 56.894636
B22: Kreditorenlaufzeit | D22: =Model!L102/Model!L29*360 -> 142.34056 | E22: =Model!M102/Model!M29*360 -> 163.1044 | F22: =Model!N102/Model!N29*360 -> 179.01159 | G22: =Model!O102/Model!O29*360 -> 156.95446 | H22: =Model!P102/Model!P29*360 -> 156.26164 | I22: =Model!Q102/Model!Q29*360 -> 135.32171 | J22: =Model!R102/Model!R29*360 -> 135.37709 | K22: =Model!S102/Model!S29*360 -> 134.2361 | ... N22: =Model!V102/Model!V29*360 -> 132.91066 | P22: =AVERAGE(C22:M22) -> 146.66196 | Q22: =MEDIAN(C22:M22) -> 139.18041
B23: Vorratsintensität | D23: =Model!L75/Model!L83 -> 0.15794703 | E23: =Model!M75/Model!M83 -> 0.13476122 | F23: =Model!N75/Model!N83 -> 0.14565157 | G23: =Model!O75/Model!O83 -> 0.041577447 | H23: =Model!P75/Model!P83 -> 0.041198016 | I23: =Model!Q75/Model!Q83 -> 0.043218326 | J23: =Model!R75/Model!R83 -> 0.043561624 | K23: =Model!S75/Model!S83 -> 0.038430459 | ... N23: =Model!V75/Model!V83 -> 0.038822866 | P23: =AVERAGE(C23:M23) -> 0.072487433 | Q23: =MEDIAN(C23:M23) -> 0.042406696
B24: Umschlaghäufigkeit der Vorräte | D24: =SUM(Model!L30:L32)/Model!L75 -> 1.2920397 | E24: =SUM(Model!M30:M32)/Model!M75 -> 1.2809042 | F24: =SUM(Model!N30:N32)/Model!N75 -> 1.0521319 | G24: =SUM(Model!O30:O32)/Model!O75 -> 1.1401774 | H24: =SUM(Model!P30:P32)/Model!P75 -> 1.2909272 | I24: =SUM(Model!Q30:Q32)/Model!Q75 -> 1.3098129 | J24: =SUM(Model!R30:R32)/Model!R75 -> 1.2957653 | K24: =SUM(Model!S30:S32)/Model!S75 -> 1.4053798 | ... N24: =SUM(Model!V30:V32)/Model!V75 -> 1.6301993 | P24: =AVERAGE(C24:M24) -> 1.2914759 | Q24: =MEDIAN(C24:M24) -> 1.2939025
B25: Lagedauer | D25: =360/D24 -> 278.62921 | E25: =360/E24 -> 281.05147 | F25: =360/F24 -> 342.16243 | G25: =360/G24 -> 315.74035 | H25: =360/H24 -> 278.86933 | I25: =360/I24 -> 274.84841 | J25: =360/J24 -> 277.8281 | K25: =360/K24 -> 256.15851 | ... N25: =360/N24 -> 220.83189 | P25: =AVERAGE(C25:M25) -> 281.10423 | Q25: =MEDIAN(C25:M25) -> 278.22866
B26: Cash Conversion Cycle | D26: =D25+D21-D22 -> 207.61354 | E26: =E25+E21-E22 -> 207.67235 | F26: =F25+F21-F22 -> 257.94034 | G26: =G25+G21-G22 -> 230.69009 | H26: =H25+H21-H22 -> 175.34655 | I26: =I25+I21-I22 -> 196.46838 | J26: =J25+J21-J22 -> 194.42028 | K26: =K25+K21-K22 -> 177.30164 | ... N26: =N25+N21-N22 -> 138.07935 | P26: =AVERAGE(C26:M26) -> 199.38224 | Q26: =MEDIAN(C26:M26) -> 195.44433
A28: x | B28: Multiples
B29: Price | D29: 53.06 | E29: 54.28 | F29: 56.49 | G29: 66.99 | H29: 24.79 | I29: 32.65 | J29: 27.53 | K29: 27.86 | L29: 33.42 | M29: 23.33 | N29: =Main!H3 -> 46.15
B30: Shares | D30: =Model!L48 -> 2030.5206 | E30: =Model!M48 -> 1863 | F30: =Model!N48 -> 1865 | G30: =Model!O48 -> 2044 | H30: =Model!P48 -> 2285 | I30: =Model!Q48 -> 2291 | J30: =Model!R48 -> 2295 | K30: =Model!S48 -> 2287 | ... M30: =Model!U48 -> 2229 | N30: =Main!H4 -> 2187
B31: Market Cap | D31: =D30*D29 -> 107739.43 | E31: =E30*E29 -> 101123.64 | F31: =F30*F29 -> 105353.85 | G31: =G30*G29 -> 136927.56 | H31: =H30*H29 -> 56645.15 | I31: =I30*I29 -> 74801.15 | J31: =J30*J29 -> 63181.35 | K31: =K30*K29 -> 63715.82 | ... N31: =N30*N29 -> 100930.05
B32: Net Debt | D32: =Model!L92+Model!L99-Model!L80-Model!L81 -> 10408 | E32: =Model!M92+Model!M99-Model!M80-Model!M81 -> 15018 | F32: =Model!N92+Model!N99-Model!N80-Model!N81 -> 17272 | G32: =Model!O92+Model!O99-Model!O80-Model!O81 -> 46154 | H32: =Model!P92+Model!P99-Model!P80-Model!P81 -> 44902 | I32: =Model!Q92+Model!Q99-Model!Q80-Model!Q81 -> 42837 | J32: =Model!R92+Model!R99-Model!R80-Model!R81 -> 40826 | K32: =Model!S92+Model!S99-Model!S80-Model!S81 -> 36836 | ... M32: =Model!U92+Model!U99-Model!U80-Model!U81 -> 35057 | N32: =Main!H7-Main!H6 -> 31243
B33: EV | D33: =D31+D32 -> 118147.43 | E33: =E31+E32 -> 116141.64 | F33: =F31+F32 -> 122625.85 | G33: =G31+G32 -> 183081.56 | H33: =H31+H32 -> 101547.15 | I33: =I31+I32 -> 117638.15 | J33: =J31+J32 -> 104007.35 | K33: =K31+K32 -> 100551.82 | ... N33: =N31+N32 -> 132173.05
B35: Equity-Multiples
B36: P/E Ratio | D36: =D31/Model!L43 -> 31.753441 | E36: =E31/Model!M43 -> 22.362592 | F36: =F31/Model!N43 -> 21.771823 | G36: =G31/Model!O43 -> 6.3752472 | H36: =H31/Model!P43 -> 9.1216023 | I36: =I31/Model!Q43 -> 12.788707 | J36: =J31/Model!R43 -> 9.6254342 | K36: =K31/Model!S43 -> 9.1361944 | ... N36: =N31/Model!V43 -> 31.729032 | P36: =AVERAGE(N36,C36:L36) -> 16.567715 | Q36: =MEDIAN(N36,C36:L36) -> 11.900892
B37: PEG Ratio | E37: =E36/((Model!M38/Model!L38-1)*100) -> 92.418493 | F37: =F36/((Model!N38/Model!M38-1)*100) -> 10.123898 | G37: =G36/((Model!O38/Model!N38-1)*100) -> 0.16296966 | H37: =H36/((Model!P38/Model!O38-1)*100) -> 0.20821817 | I37: =I36/((Model!Q38/Model!P38-1)*100) -> -4.0101425 | J37: =J36/((Model!R38/Model!Q38-1)*100) -> 0.91736696 | K37: =K36/((Model!S38/Model!R38-1)*100) -> 3.3461312 | L37: =L36/((Model!T38/Model!S38-1)*100) -> 3.8999246 | M37: =M36/((Model!U38/Model!T38-1)*100) -> 0.014678659 | N37: =N32/Model!V44 -> 276.48673 | P37: =AVERAGE(N37,C37:L37) -> 42.617065 | Q37: =MEDIAN(N37,C37:L37) -> 3.3461312
B38: P/B Ratio | E38: =F31/Model!M91 -> 20.936775 | F38: =G31/Model!N91 -> 16.289265 | G38: =H31/Model!O91 -> 0.92821338 | H38: =I31/Model!P91 -> 1.1387339 | I38: =J31/Model!Q91 -> 0.98474673 | J38: =K31/Model!R91 -> 1.0120851 | K38: =L31/Model!S91 -> 1.1186113 | L38: =M31/Model!T91 -> 0.68686528 | ... N38: =O31/Model!V91 -> 0 | P38: =AVERAGE(N38,C38:L38) -> 4.7883661 | Q38: =MEDIAN(N38,C38:L38) -> 1.0120851
B39: Entity-Multiples
B40: EV/EBITDA
B41: EV/EBIT | D41: =D33/(Model!L38+Model!L109) -> 23.307837 | E41: =E33/(Model!M38+Model!M109) -> 23.298223 | F41: =F33/(Model!N38+Model!N109) -> 23.304038 | G41: =G33/(Model!O38+Model!O109) -> 24.814524 | H41: =H33/(Model!P38+Model!P109) -> 9.810371 | I41: =I33/(Model!Q38+Model!Q109) -> 11.173836 | J41: =J33/(Model!R38+Model!R109) -> 9.1138582 | K41: =K33/(Model!S38+Model!S109) -> 8.8905234 | ... N41: =N33/(Model!V38+Model!V109) -> 22.644004 | P41: =AVERAGE(C41:N41) -> 15.708251 | Q41: =MEDIAN(C41:N41) -> 11.173836
B42: EV/FCF | D42: =D33/Model!L38 -> 25.989315 | E42: =E33/Model!M38 -> 25.486425 | F42: =F33/Model!N38 -> 26.342825 | G42: =G33/Model!O38 -> 28.270778 | H42: =H33/Model!P38 -> 10.903807 | I42: =I33/Model!Q38 -> 13.04771 | J42: =J33/Model!R38 -> 10.440409 | K42: =K33/Model!S38 -> 9.8252707 | ... N42: =N33/Model!V38 -> 48.308863 | P42: =AVERAGE(C42:N42) -> 18.541103 | Q42: =MEDIAN(C42:N42) -> 13.04771
B43: EV/Sales | D43: n.a | E43: n.a | F43: n.a | G43: n.a | H43: =H33/#REF! -> #REF! | I43: =I33/#REF! -> #REF! | J43: =J33/#REF! -> #REF! | K43: =K33/#REF! -> #REF! | L43: =L33/#REF! -> #REF! | M43: =M33/#REF! -> #REF! | N43: =N33/#REF! -> #REF! | P43: =AVERAGE(C43:N43) -> #REF! | Q43: =MEDIAN(C43:N43) -> #REF!
D44: =D33/Model!L29 -> 8.4566191 | E44: =E33/Model!M29 -> 8.8630678 | F44: =F33/Model!N29 -> 8.3130534 | G44: =G33/Model!O29 -> 9.0223517 | H44: =H33/Model!P29 -> 4.1461355 | I44: =I33/Model!Q29 -> 4.5460505 | J44: =J33/Model!R29 -> 4.0350462 | K44: =K33/Model!S29 -> 3.9149595 | ... N44: =N33/Model!V29 -> 5.109717 | P44: =AVERAGE(C44:N44) -> 5.7938027 | Q44: =MEDIAN(C44:N44) -> 4.5460505
B46: Dividend Yield | D46: =(-1*Model!L142)/D31 -> 0.025171844 | E46: =(-1*Model!M142)/E31 -> 0.02739221 | F46: =(-1*Model!N142)/F31 -> 0.027621202 | G46: =(-1*Model!O142)/G31 -> 0.025305351 | H46: =(-1*Model!P142)/H31 -> 0.076740904 | I46: =(-1*Model!Q142)/I31 -> 0.061469643 | J46: =(-1*Model!R142)/J31 -> 0.075101276 | K46: =(-1*Model!S142)/K31 -> 0.076966756 | ... N46: =(-1*Model!V142)/N31 -> 0.051649633 | P46: =AVERAGE(C46:M46) -> 0.055816547 | Q46: =MEDIAN(C46:M46) -> 0.063329596

Sheet DCF
A1: Main | B1: British American Tobacco DCF
B3: Ticker | E3: BTI | G3: Share Price | J3: =+Main!H3 -> 46.15 | L3: Share Price | O3: =+J3 -> 46.15
B4: Date | E4: =+TODAY() -> 46226 | G4: Fair Share Price | J4: =V62 -> 42.245377 | L4: Scneario DCF Price | O4: =+J15+O15+T15 -> 0
B5: End of FY | E5: 46022 | G5: Implied Upside | J5: =J4/J3-1 -> -0.084607205 | L5: Implied Upside | O5: =O4/O3-1 -> -1
A7: x | B7: Assumptions
B9: Switches | G9: Conservative Case | L9: Base Case | Q9: Optimistic Case
B10: Assuptions | G10: Assuptions | I10: Year | J10: Metic | L10: Assuptions | N10: Year | O10: Metic | Q10: Assuptions | S10: Year | T10: Metic
B11: Revenue | E11: 3 | G11: Revenue | L11: Revenue | Q11: Revenue
B12: EBIT | E12: 2 | G12: EBIT | L12: EBIT | Q12: EBIT
B13: WACC | E13: 2 | G13: Implied Share Price
B14: TGR | E14: 2 | G14: Probability | L14: Probability | Q14: Probability
B15: ROIC | E15: 2 | G15: Implied Share Price * p | L15: Implied Share Price * p | Q15: Implied Share Price * p
B17: Valuation
B18: WACC | E18: =CHOOSE(E13,J18,O18,T18) -> 0.07 | G18: WACC | J18: 0.08 | L18: WACC | O18: 0.07 | Q18: WACC | T18: 0.06
B19: TGR | E19: =CHOOSE(E14,J19,O19,T19) -> 0.01 | G19: TGR | J19: 0.005 | L19: TGR | O19: 0.01 | Q19: TGR | T19: 0.02
B20: RONIC | E20: =CHOOSE(E15,J20,O20,T20) -> 0.09 | G20: RONIC | J20: 0.08 | L20: RONIC | O20: 0.09 | Q20: RONIC | T20: 0.1
A24: x | B24: Model | G24: 19 | H24: =G24+1 -> 20 | I24: =H24+1 -> 21 | J24: =I24+1 -> 22 | K24: =J24+1 -> 23 | L24: =K24+1 -> 24 | M24: =L24+1 -> 25 | N24: =M24+1 -> 26 | O24: =N24+1 -> 27 | ... V24: =U24+1 -> 34
B25: Revenue | G25: =+Model!Q29 -> 25877 | H25: =+Model!R29 -> 25776 | I25: =+Model!S29 -> 25684 | J25: =+Model!T29 -> 27655 | K25: =+Model!U29 -> 27283 | L25: =+Model!V29 -> 25867 | M25: =L25*(1+M26) -> 25868.67 | N25: =M25*(1+N26) -> 24815.311 | O25: =N25*(1+O26) -> 25031.746 | P25: =O25*(1+P26) -> 25259.725 | Q25: =P25*(1+Q26) -> 25499.882 | R25: =Q25*(1+R26) -> 25752.885 | S25: =R25*(1+S26) -> 26019.44 | T25: =S25*(1+T26) -> 27847.422 | ... V25: =U25*(1+V26) -> 28035.003
B26: Growth (%) | H26: =H25/G25-1 -> -0.00390308 | I26: =I25/H25-1 -> -0.0035692117 | J26: =J25/I25-1 -> 0.076740383 | K26: =K25/J25-1 -> -0.013451455 | L26: =L25/K25-1 -> -0.051900451 | M26: {=OFFSET(M26,$E$11,,)} -> 6.4561024e-05 | N26: {=OFFSET(N26,$E$11,,)} -> -0.040719496 | O26: {=OFFSET(O26,$E$11,,)} -> 0.0087218213 | P26: {=OFFSET(P26,$E$11,,)} -> 0.009107601 | Q26: {=OFFSET(Q26,$E$11,,)} -> 0.0095075063 | R26: {=OFFSET(R26,$E$11,,)} -> 0.0099217436 | S26: {=OFFSET(S26,$E$11,,)} -> 0.010350493 | T26: {=OFFSET(T26,$E$11,,)} -> 0.070254471 | ... V26: {=OFFSET(V26,$E$11,,)} -> 0.003596566
B27: Conservative Case | M27: =+M28-1% -> -0.019935439 | N27: =+N28-1% -> -0.060719496 | O27: =+O28-1% -> -0.011278179 | P27: =+P28-1% -> -0.010892399 | Q27: =+Q28-1% -> -0.010492494 | R27: =+R28-1% -> -0.010078256 | S27: =+S28-1% -> -0.0096495073 | T27: =+T28-1% -> 0.050254471 | ... V27: =+V28-1% -> -0.016403434
B28: Base Case | M28: =+Model!W60 -> -0.009935439 | N28: =+Model!X60 -> -0.050719496 | O28: =+Model!Y60 -> -0.0012781787 | P28: =+Model!Z60 -> -0.00089239901 | Q28: =+Model!AA60 -> -0.00049249373 | R28: =+Model!AB60 -> -7.8256362e-05 | S28: =+Model!AC60 -> 0.00035049271 | T28: =+Model!AD60 -> 0.060254471 | ... V28: =+Model!AF60 -> -0.006403434
B29: Optimisitic Case | M29: =+M28+1% -> 6.4561024e-05 | N29: =+N28+1% -> -0.040719496 | O29: =+O28+1% -> 0.0087218213 | P29: =+P28+1% -> 0.009107601 | Q29: =+Q28+1% -> 0.0095075063 | R29: =+R28+1% -> 0.0099217436 | S29: =+S28+1% -> 0.010350493 | T29: =+T28+1% -> 0.070254471 | ... V29: =+V28+1% -> 0.003596566
B31: EBIT | G31: =+Model!Q38 -> 9016 | H31: =+Model!R38 -> 9962 | I31: =+Model!S38 -> 10234 | J31: =+Model!T38 -> 10523 | K31: =+Model!U38 -> -15751 | L31: =+Model!V38 -> 2736 | M31: =M32*M25 -> 10097.973 | N31: =N32*N25 -> 9677.9712 | O31: =O32*O25 -> 9762.3807 | P31: =P32*P25 -> 9851.2926 | Q31: =Q32*Q25 -> 9944.9538 | R31: =R32*R25 -> 10043.625 | S31: =S32*S25 -> 10147.582 | T31: =T32*T25 -> 10860.495 | ... V31: =V32*V25 -> 10933.651
B32: % of Sales | G32: =G31/G25 -> 0.34841751 | H32: =H31/H25 -> 0.38648355 | I32: =I31/I25 -> 0.39845818 | J32: =J31/J25 -> 0.38050985 | K32: =K31/K25 -> -0.57731921 | L32: =L31/L25 -> 0.10577183 | M32: {=OFFSET(M32,$E$12,,)} -> 0.39035533 | N32: {=OFFSET(N32,$E$12,,)} -> 0.39 | O32: {=OFFSET(O32,$E$12,,)} -> 0.39 | P32: {=OFFSET(P32,$E$12,,)} -> 0.39 | Q32: {=OFFSET(Q32,$E$12,,)} -> 0.39 | R32: {=OFFSET(R32,$E$12,,)} -> 0.39 | S32: {=OFFSET(S32,$E$12,,)} -> 0.39 | T32: {=OFFSET(T32,$E$12,,)} -> 0.39 | ... V32: {=OFFSET(V32,$E$12,,)} -> 0.39
B33: Conservative Case | M33: =+M34-2% -> 0.37035533 | N33: =+N34-2% -> 0.37 | O33: =+O34-2% -> 0.37 | P33: =+P34-2% -> 0.37 | Q33: =+Q34-2% -> 0.37 | R33: =+R34-2% -> 0.37 | S33: =+S34-2% -> 0.37 | T33: =+T34-2% -> 0.37 | ... V33: =+V34-2% -> 0.37
B34: Base Case | M34: =+Model!W62 -> 0.39035533 | N34: =+Model!X62 -> 0.39 | O34: =+Model!Y62 -> 0.39 | P34: =+Model!Z62 -> 0.39 | Q34: =+Model!AA62 -> 0.39 | R34: =+Model!AB62 -> 0.39 | S34: =+Model!AC62 -> 0.39 | T34: =+Model!AD62 -> 0.39 | ... V34: =+Model!AF62 -> 0.39
B35: Optimisitic Case | M35: =+M34+2% -> 0.41035533 | N35: =+N34+2% -> 0.41 | O35: =+O34+2% -> 0.41 | P35: =+P34+2% -> 0.41 | Q35: =+Q34+2% -> 0.41 | R35: =+R34+2% -> 0.41 | S35: =+S34+2% -> 0.41 | T35: =+T34+2% -> 0.41 | ... V35: =+V34+2% -> 0.41
B37: Taxes | G37: =+Model!Q42 -> 2063 | H37: =+Model!R42 -> 2108 | I37: =+Model!S42 -> 2189 | J37: =+Model!T42 -> 2478 | K37: =+Model!U42 -> -2872 | L37: =+Model!V42 -> 357 | M37: =M38*M31 -> 2144.7567 | N37: =N38*N31 -> 2096.6614 | O37: =O38*O31 -> 2157.2471 | P37: =P38*P31 -> 2220.4323 | Q37: =Q38*Q31 -> 2286.374 | R37: =R38*R31 -> 2355.24 | S37: =S38*S31 -> 2427.2102 | T37: =T38*T31 -> 2649.6872 | ... V37: =V38*V31 -> 2775.304
B38: Tax Rate (%) | G38: =G37/G31 -> 0.22881544 | H38: =H37/H31 -> 0.2116041 | I38: =I37/I31 -> 0.21389486 | J38: =J37/J31 -> 0.23548418 | K38: =K37/K31 -> 0.18233763 | L38: =L37/L31 -> 0.13048246 | M38: =+Model!W64 -> 0.21239477 | N38: =+Model!X64 -> 0.21664266 | O38: =+Model!Y64 -> 0.22097551 | P38: =+Model!Z64 -> 0.22539503 | Q38: =+Model!AA64 -> 0.22990293 | R38: =+Model!AB64 -> 0.23450098 | S38: =+Model!AC64 -> 0.239191 | T38: =+Model!AD64 -> 0.24397482 | ... V38: =+Model!AF64 -> 0.25383141
B40: Nopat | G40: =G31-G37 -> 6953 | H40: =H31-H37 -> 7854 | I40: =I31-I37 -> 8045 | J40: =J31-J37 -> 8045 | K40: =K31-K37 -> -12879 | L40: =L31-L37 -> 2379 | M40: =M31-M37 -> 7953.2166 | N40: =N31-N37 -> 7581.3098 | ... V40: =V31-V37 -> 8158.347
B42: D&A and other non-cash Expenses | G42: =Model!Q109 -> 1512 | H42: =Model!R109 -> 1450 | I42: =Model!S109 -> 1076 | J42: =Model!T109 -> 1305 | K42: =Model!U109 -> 28614 | L42: =Model!V109 -> 3101 | M42: =M43*M25 -> 1448.6455 | N42: =N43*N25 -> 1389.6574 | O42: =O43*O25 -> 1401.7777 | P42: =P43*P25 -> 1414.5446 | Q42: =Q43*Q25 -> 1427.9934 | R42: =R43*R25 -> 1442.1616 | S42: =S43*S25 -> 1457.0886 | T42: =T43*T25 -> 1559.4556 | ... V42: =V43*V25 -> 1569.9601
B43: % of Sales | G43: =G42/G25 -> 0.058430266 | H43: =H42/H25 -> 0.05625388 | I43: =I42/I25 -> 0.041893786 | J43: =J42/J25 -> 0.047188573 | K43: =K42/K25 -> 1.048785 | L43: =L42/L25 -> 0.11988248 | M43: 0.056 | N43: 0.056 | O43: 0.056 | P43: 0.056 | Q43: 0.056 | R43: 0.056 | S43: 0.056 | T43: 0.056 | U43: 0.056 | V43: 0.056
B45: CapEx | G45: =+Model!Q123+Model!Q124+Model!Q125+Model!Q126 -> -781 | H45: =+Model!R123+Model!R124+Model!R125+Model!R126 -> -711 | I45: =+Model!S123+Model!S124+Model!S125+Model!S126 -> -714 | J45: =+Model!T123+Model!T124+Model!T125+Model!T126 -> -622 | K45: =+Model!U123+Model!U124+Model!U125+Model!U126 -> -520 | L45: =+Model!V123+Model!V124+Model!V125+Model!V126 -> -424 | M45: =M46*M25 -> -517.3734 | N45: =N46*N25 -> -496.30622 | O45: =O46*O25 -> -500.63491 | P45: =P46*P25 -> -505.19449 | Q45: =Q46*Q25 -> -509.99763 | R45: =R46*R25 -> -515.0577 | S45: =S46*S25 -> -520.3888 | T45: =T46*T25 -> -556.94844 | ... V45: =V46*V25 -> -560.70005
B46: % of Sales | G46: =G45/G25 -> -0.030181242 | H46: =H45/H25 -> -0.027583799 | I46: =I45/I25 -> -0.027799408 | J46: =J45/J25 -> -0.022491412 | K46: =K45/K25 -> -0.019059488 | L46: =L45/L25 -> -0.016391541 | M46: -0.02 | N46: -0.02 | O46: -0.02 | P46: -0.02 | Q46: -0.02 | R46: -0.02 | S46: -0.02 | T46: -0.02 | U46: -0.02 | V46: -0.02
B48: Change in WC | G48: =+Model!Q117 -> 314 | H48: =+Model!R117 -> 109 | I48: =+Model!S117 -> -62 | J48: =+Model!T117 -> 103 | K48: =+Model!U117 -> -469 | L48: =+Model!V117 -> 5776 | M48: =M49*M25 -> 25.86867 | N48: =N49*N25 -> 24.815311 | O48: =O49*O25 -> 25.031746 | P48: =P49*P25 -> 25.259725 | Q48: =Q49*Q25 -> 25.499882 | R48: =R49*R25 -> 25.752885 | S48: =S49*S25 -> 26.01944 | T48: =T49*T25 -> 27.847422 | ... V48: =V49*V25 -> 28.035003
B49: % of Sales | G49: =G48/G25 -> 0.012134328 | H49: =H48/H25 -> 0.0042287399 | I49: =I48/I25 -> -0.0024139542 | J49: =J48/J25 -> 0.0037244621 | K49: =K48/K25 -> -0.017190192 | L49: =L48/L25 -> 0.22329609 | M49: 0.001 | N49: 0.001 | O49: 0.001 | P49: 0.001 | Q49: 0.001 | R49: 0.001 | S49: 0.001 | T49: 0.001 | U49: 0.001 | V49: 0.001
B51: Unlevered Free Cashflow | G51: =G40+G42+G45+G48 -> 7998 | H51: =H40+H42+H45+H48 -> 8702 | I51: =I40+I42+I45+I48 -> 8345 | J51: =J40+J42+J45+J48 -> 8831 | K51: =K40+K42+K45+K48 -> 14746 | L51: =L40+L42+L45+L48 -> 10832 | M51: =M40+M42+M45+M48 -> 8910.3573 | N51: =N40+N42+N45+N48 -> 8499.4763 | ... V51: =V40+V42+V45+V48 -> 9195.6421
B52: Present Value of unlevered FC | M52: =(M51/(1+$E$18)^M53)*M53 -> 4836.3695 | N52: =N51/(1+$E$18)^N53 -> 7646.0864 | O52: =O51/(1+$E$18)^O53 -> 7172.6376 | P52: =P51/(1+$E$18)^P53 -> 6730.2421 | Q52: =Q51/(1+$E$18)^Q53 -> 6316.8266 | R52: =R51/(1+$E$18)^R53 -> 5930.456 | S52: =S51/(1+$E$18)^S53 -> 5569.324 | T52: =T51/(1+$E$18)^T53 -> 5539.5049 | U52: =U51/(1+$E$18)^U53 -> 5163.5212 | V52: =V51/(1+$E$18)^V53 -> 4814.5852
B53: Discount Period | M53: =YEARFRAC(E4,E5) -> 0.56388889 | N53: =M53+1 -> 1.5638889 | O53: =N53+1 -> 2.5638889 | P53: =O53+1 -> 3.5638889 | Q53: =P53+1 -> 4.5638889 | R53: =Q53+1 -> 5.5638889 | S53: =R53+1 -> 6.5638889 | T53: =S53+1 -> 7.5638889 | U53: =T53+1 -> 8.5638889 | V53: =U53+1 -> 9.5638889
B54: Sum of Present Value | V54: =SUM(M52:V52) -> 59719.553
...
