Workbook

Sheet Main
A1: Crocs Inc.
A2: numbers in mio USD | G2: Price | H2: 136.34
G3: Shares | H3: 49.689648 | I3: Q126
B4: Crox | G4: MC | H4: =H3*H2 -> 6774.6866
B5: IR | G5: Cash | H5: 130.881 | I5: Q126
G6: Debt | H6: =1330.271+5.55 -> 1335.821 | I6: Q126
B7: Segments | C7: % of Rev | D7: Products | E7: Stores | G7: EV | H7: =H4+H6-H5 -> 7979.6266
B8: Crocs | C8: 0.7990933 | D8: Clogs, other shoes, Accessoires | E8: 390
B9: Heydude | C9: 0.2009067 | D9: Casual Shoes & other, Accessoires | E9: 52 | G9: Founded: | H9: 2002
G10: Employees: 7.910
A12: x | B12: Notes | G12: Management
B13: Acquistion of Heydude in 2021 for 2.5 billion USD | G13: CEO | H13: Andrew Rees
B14: TAM 160 billion USD -> Market Share of 3% | G14: CFO | H14: Susan Healy
B15: Crocs: Mostly Clogs; jibbitz and sandals; | G15: CBO | H15: Terence Reilly
B16: collabs with other brands like Crocs X Birkenstock | G16: CBO | H16: Anne Mehlman
B17: First Clog introduced in 2002 in six different colours | G17: DFO | H17: Adam Michaels
B18: Heydude: Most important models: Wally, Wendy and sandals | G18: CPO | H18: Shanoon Sisler
B19: Competitors: Nike, Sketchers, Underarmor, Adidas, Deckers etc. | G19: CIO | H19: Tom Britt
B20: Outlook for 2025 canceled
B21: Heydude: Sydney Sweeney new Brand Ambassador
B22: Impact of tariffs: around 45 to 130 mio USD
B23: Crocs number one brand on Tik Tok shops
B24: Guidance: Revenues for Q3 down to be down between 9-11%
C25: Operating Margin of approximately 18 to 19%
B28: https://web.quartr.com/articles/c73151dc-7087-46ee-8927-68817e7948a0

Sheet Model
A1: Main
C2: Q123 | D2: Q223 | E2: Q323 | F2: Q423 | G2: Q124 | H2: Q224 | I2: Q324 | J2: Q424 | K2: Q125 | L2: Q225 | M2: Q325 | N2: Q425 | O2: Q126 | P2: Q226 | Q2: Q326 | R2: Q426 | T2: FY18 | U2: FY19 | V2: FY20 | W2: FY21 | X2: FY22 | Y2: FY23 | Z2: FY24 | AA2: FY25
B3: Corcs Stores | T3: 383 | U3: 367 | V3: 351 | W3: 340 | X3: 373 | Y3: 349 | Z3: 390
B4: HEYDUDE Stores | T4: 0 | U4: 0 | V4: 0 | W4: 0 | X4: 0 | Y4: 14 | Z4: 52
B5: Total Stores | T5: =+T3+T4 -> 383 | U5: =+U3+U4 -> 367 | V5: =+V3+V4 -> 351 | W5: =+W3+W4 -> 340 | X5: =+X3+X4 -> 373 | Y5: =+Y3+Y4 -> 363 | Z5: =+Z3+Z4 -> 442 | AA5: 429
B7: Unit Sales Crocs | T7: 59.815 | U7: 67.051 | V7: 69.087 | W7: 102.962 | X7: 115.558 | Y7: 119.577 | Z7: 127
B8: Unit Sales HEYDUDE | T8: n.a. | U8: n.a. | V8: n.a. | W8: n.a. | X8: 30.519 | Y8: 32.969 | Z8: 26.95
B9: Avergae Price Crocs | T9: 17.71 | U9: 18.21 | V9: 19.91 | W9: 22.27 | X9: 22.72 | Y9: 24.92 | Z9: 25.52
B10: Avergae Price HEYDUDE | T10: n.a. | U10: n.a. | V10: n.a. | W10: n.a. | X10: 29.35 | Y10: 28.8 | Z10: 30.54
B12: North America Crocs | C12: 351.309 | D12: 474.558 | E12: 480.744 | F12: =+Y12-SUM(C12:E12) -> 471.274 | G12: 382.913 | H12: 488.715 | I12: 490.817 | J12: =+Z12-SUM(G12:I12) -> 470.977 | K12: 368.517 | L12: 457.13 | M12: 447.705 | N12: =+AA12-SUM(K12:M12) -> 436.283 | O12: 345.926 | T12: =216.797+204.806+98.589 -> 520.192 | U12: =275.284+241.694+123.537 -> 640.515 | V12: =390.93+249.238+223.445 -> 863.613 | W12: 1553.891 | X12: 1644.656 | Y12: 1777.885 | Z12: 1833.422 | AA12: 1709.635
B13: International Crocs | C13: 297.469 | D13: 358.392 | E13: 318.025 | F13: =+Y13-SUM(C13:E13) -> 261.183 | G13: 360.903 | H13: 425.274 | I13: 367.281 | J13: =+Z13-SUM(G13:I13) -> 291.087 | K13: 393.091 | L13: 502.46 | M13: 388.524 | N13: =+AA13-SUM(K13:M13) -> 332.097 | O13: 421.49 | T13: 568.013 | U13: 590.078 | V13: 522.338 | W13: =350.16+409.278+0.087 -> 759.525 | X13: 1014.469 | Y13: 1235.069 | Z13: 1444.545 | AA13: 1616.172
B14: Crocs Revenue | C14: 743.816 | D14: 832.95 | E14: 798.769 | F14: =+Y14-SUM(C14:E14) -> 637.419 | G14: 648.778 | H14: 913.989 | I14: 858.098 | J14: =+Z14-SUM(G14:I14) -> 857.102 | K14: 761.608 | L14: =+L12+L13 -> 959.59 | M14: 836.229 | N14: =+AA14-SUM(K14:M14) -> 768.38 | O14: 767.416 | T14: 1088.205 | U14: 1230.593 | V14: 1385.951 | W14: =+W18 -> 2313.416 | X14: 2659.125 | Y14: 3012.954 | Z14: 3277.967 | AA14: 3325.807
B15: HEYDUDE Revenue | C15: 194.817 | D15: 239.417 | E15: 246.948 | F15: =+Y15-SUM(C15:E15) -> 268.211 | G15: 235.388 | H15: 197.513 | I15: 204.102 | J15: =+Z15-SUM(G15:I15) -> 187.138 | K15: 175.725 | L15: 189.783 | M15: 160.072 | N15: =+AA15-SUM(K15:M15) -> 189.26 | O15: 154.041 | T15: n.a. | U15: n.a. | V15: n.a. | W15: n.a. | X15: 895.86 | Y15: 949.393 | Z15: 824.141 | AA15: 714.84
B16: Wholesale Revenue | C16: =462.002+134.753 -> 596.755 | D16: =407.342+148.825 -> 556.167 | E16: =369.177+146.501 -> 515.678 | F16: =+Y16-SUM(C16:E16) -> 391.874 | G16: =410.563+167.863 -> 578.426 | H16: =435.281+113.829 -> 549.11 | I16: =395.564+113.018 -> 508.582 | J16: =+Z16-SUM(G16:I16) -> 427.9 | K16: =476.804+110.693 -> 587.497 | L16: =464.679+99.76 -> 564.439 | M16: =364.356+69.402 -> 433.758 | N16: =+AA16-SUM(K16:M16) -> 350.005 | O16: =445.822+83.402 -> 529.224 | T16: 578.044 | U16: 656.227 | V16: 629.919 | W16: 1174.081 | X16: =1377.302+574.14 -> 1951.442 | Y16: =1493.537+566.937 -> 2060.474 | Z16: =1607.546+456.472 -> 2064.018 | AA16: =1599.374+336.325 -> 1935.699
B17: DTC Revenue | C17: =281.814+60.064 -> 341.878 | D17: =425.608+90.592 -> 516.2 | E17: =429.592+100.447 -> 530.039 | F17: =+Y17-SUM(C17:E17) -> 513.756 | G17: =238.215+67.525 -> 305.74 | H17: =478.708+83.684 -> 562.392 | I17: =462.534+91.084 -> 553.618 | J17: =+Z17-SUM(G17:I17) -> 616.34 | K17: =284.804+65.032 -> 349.836 | L17: =494.911+90.023 -> 584.934 | M17: =471.873+90.67 -> 562.543 | N17: =+AA17-SUM(K17:M17) -> 607.635 | O17: =321.594+70.639 -> 392.233 | T17: 510.161 | U17: =347.362+226.004 -> 573.366 | V17: =334.016+359.016 -> 693.032 | W17: 1139.335 | X17: =1291.823+321.72 -> 1613.543 | Y17: =1519.417+382.456 -> 1901.873 | Z17: =1670.421+367.669 -> 2038.09 | AA17: =1726.433+378.515 -> 2104.948
B18: Revenue | C18: 884.166 | D18: 1072.367 | E18: 1045.717 | F18: =+Y18-SUM(C18:E18) -> 960.097 | G18: 938.633 | H18: 1111.502 | I18: 1062.2 | J18: =+Z18-SUM(G18:I18) -> 989.773 | K18: 937.333 | L18: 1149.373 | M18: 996.301 | N18: 957.64 | O18: 921.457 | T18: 1088.205 | U18: 1230.593 | V18: 1385.951 | W18: 2313.416 | X18: 3554.985 | Y18: 3962.347 | Z18: 4102.108 | AA18: 4040.647
B19: COGS | C19: 407.796 | D19: 451.06 | E19: 464.081 | F19: =+Y19-SUM(C19:E19) -> 429.4 | G19: 416.556 | H19: 429.586 | I19: 428.861 | J19: =+Z19-SUM(G19:I19) -> 416.847 | K19: 395.784 | L19: 440.537 | M19: 413.293 | N19: 433.978 | O19: 398.512 | T19: 528.051 | U19: 613.537 | V19: 636.003 | W19: 893.196 | X19: 1694.703 | Y19: 1752.337 | Z19: 1691.85 | AA19: 1683.592
B20: Gross Profit | C20: =C18-C19 -> 476.37 | D20: =D18-D19 -> 621.307 | E20: =E18-E19 -> 581.636 | F20: =F18-F19 -> 530.697 | G20: =G18-G19 -> 522.077 | H20: =H18-H19 -> 681.916 | I20: =I18-I19 -> 633.339 | J20: =J18-J19 -> 572.926 | ... O20: =O18-O19 -> 522.945 | T20: =+T18-T19 -> 560.154 | U20: =+U18-U19 -> 617.056 | V20: =+V18-V19 -> 749.948 | W20: =+W18-W19 -> 1420.22 | X20: =+X18-X19 -> 1860.282 | Y20: =+Y18-Y19 -> 2210.01 | Z20: =+Z18-Z19 -> 2410.258 | AA20: =+AA18-AA19 -> 2357.055
B21: SG&A | C21: 241.442 | D21: 302.818 | E21: 307.784 | F21: =+Y21-SUM(C21:E21) -> 321.183 | G21: 295.648 | H21: 356.178 | I21: 363.51 | J21: =+Z21-SUM(G21:I21) -> 373.011 | K21: 318.575 | L21: 1136.352 | M21: 375.348 | N21: 377.265 | O21: 322.101 | T21: =495.028+2.182 -> 497.21 | U21: 488.407 | V21: =514.753+21.071 -> 535.824 | W21: 737.156 | X21: 1009.526 | Y21: 1173.227 | Z21: 1388.347 | AA21: 2207.54
B22: Operating Profit | C22: =C20-C21 -> 234.928 | D22: =D20-D21 -> 318.489 | E22: =E20-E21 -> 273.852 | F22: =F20-F21 -> 209.514 | G22: =G20-G21 -> 226.429 | H22: =H20-H21 -> 325.738 | I22: =I20-I21 -> 269.829 | J22: =J20-J21 -> 199.915 | ... O22: =O20-O21 -> 200.844 | T22: =+T20-T21 -> 62.944 | U22: =+U20-U21 -> 128.649 | V22: =+V20-V21 -> 214.124 | W22: =+W20-W21 -> 683.064 | X22: =+X20-X21 -> 850.756 | Y22: =+Y20-Y21 -> 1036.783 | Z22: =+Z20-Z21 -> 1021.911 | AA22: =+AA20-AA21 -> 149.515
B23: Loss on Foreign Currency | C23: 0.403 | D23: -0.551 | E23: 1.77 | F23: =+Y23-SUM(C23:E23) -> -0.382 | G23: 2.273 | H23: 1.323 | I23: 0.332 | J23: =+Z23-SUM(G23:I23) -> 2.849 | K23: -4.873 | L23: -0.434 | M23: -2.957 | N23: -1.579 | O23: 1.625 | T23: -1.318 | U23: 1.323 | V23: 1.128 | W23: 0.14 | X23: -3.228 | Y23: 1.24 | Z23: 6.777 | AA23: -9.843
B24: Interest Income | C24: 0.171 | D24: 0.548 | E24: 0.506 | F24: =+Y24-SUM(C24:E24) -> 1.181 | G24: 0.416 | H24: 1.126 | I24: 1.366 | J24: =+Z24-SUM(G24:I24) -> 0.576 | K24: 0.333 | L24: 0.371 | M24: 0.531 | N24: 0.609 | O24: 0.335 | T24: 1.281 | U24: 0.601 | V24: 0.215 | W24: 0.775 | X24: 1.02 | Y24: 2.406 | Z24: 3.484 | AA24: 1.844
B25: Interest Expense | C25: 42.637 | D25: 43.063 | E25: 39.207 | F25: =+Y25-SUM(C25:E25) -> 36.444 | G25: 30.563 | H25: 29.161 | I25: 26.2304 | J25: =+Z25-SUM(G25:I25) -> 23.3096 | K25: 22.766 | L25: 22.523 | M25: 21.711 | N25: 21.287 | O25: 20.459 | T25: 0.955 | U25: 8.636 | V25: 6.742 | W25: 21.647 | X25: 136.158 | Y25: 161.351 | Z25: 109.264 | AA25: 88.287
B26: Other Income | C26: -0.293 | D26: 0.717 | E26: 0.024 | F26: =+Y26-SUM(C26:E26) -> -0.774 | G26: 0.02 | H26: 0.045 | I26: 0.237 | J26: =+Z26-SUM(G26:I26) -> 0.929 | K26: -0.475 | L26: 0.627 | M26: 0.009 | N26: -0.08 | O26: -0.251 | T26: 0.569 | U26: 0.031 | V26: 0.51 | W26: 1.797 | X26: -0.338 | Y26: -0.326 | Z26: 1.231 | AA26: 0.063
B27: Pretax Income | C27: =C22-C23+C24-C25+C26 -> 191.766 | D27: =D22-D23+D24-D25+D26 -> 277.242 | E27: =E22-E23+E24-E25+E26 -> 233.405 | F27: =F22-F23+F24-F25+F26 -> 173.859 | G27: =G22-G23+G24-G25+G26 -> 194.029 | H27: =H22-H23+H24-H25+H26 -> 296.425 | I27: =I22-I23+I24-I25+I26 -> 244.8696 | J27: =J22-J23+J24-J25+J26 -> 175.2614 | ... O27: =O22-O23+O24-O25+O26 -> 178.844 | T27: =T22-T23+T24-T25+T26 -> 65.157 | U27: =U22-U23+U24-U25+U26 -> 119.322 | V27: =V22-V23+V24-V25+V26 -> 206.979 | W27: =W22-W23+W24-W25+W26 -> 663.849 | X27: =X22-X23+X24-X25+X26 -> 718.508 | Y27: =Y22-Y23+Y24-Y25+Y26 -> 876.272 | Z27: =Z22-Z23+Z24-Z25+Z26 -> 910.585 | AA27: =AA22-AA23+AA24-AA25+AA26 -> 72.978
B28: Income Tax Expense | C28: 42.223 | D28: 64.83 | E28: 56.38 | F28: =+Y28-SUM(C28:E28) -> -79.727 | G28: 41.575 | H28: 67.518 | I28: 45.096 | J28: =+Z28-SUM(G28:I28) -> -193.675 | K28: 44.836 | L28: 43.675 | M28: 43.612 | N28: 22.053 | O28: 41.288 | T28: =14.72+108.224+11.429 -> 134.373 | U28: -0.175 | V28: -105.882 | W28: -61.845 | X28: 178.349 | Y28: 83.706 | Z28: -39.486 | AA28: 154.176
B29: Net Income | C29: =C27-C28 -> 149.543 | D29: =D27-D28 -> 212.412 | E29: =E27-E28 -> 177.025 | F29: =F27-F28 -> 253.586 | G29: =G27-G28 -> 152.454 | H29: =H27-H28 -> 228.907 | I29: =I27-I28 -> 199.7736 | J29: =J27-J28 -> 368.9364 | ... O29: =O27-O28 -> 137.556 | T29: =+T27-T28 -> -69.216 | U29: =+U27-U28 -> 119.497 | V29: =+V27-V28 -> 312.861 | W29: =+W27-W28 -> 725.694 | X29: =+X27-X28 -> 540.159 | Y29: =+Y27-Y28 -> 792.566 | Z29: =+Z27-Z28 -> 950.071 | AA29: =+AA27-AA28 -> -81.198
B31: EPS | C31: =C29/C32 -> 2.4183809 | D31: =D29/D32 -> 3.4239567 | E31: =E29/E32 -> 2.8952619 | F31: =F29/F32 -> 4.1422084 | G31: =G29/G32 -> 2.517238 | H31: =+H29/H32 -> 3.7948773 | I31: =+I29/I32 -> 3.3833554 | J31: =+J29/J32 -> 6.2130378 | K31: =+K29/K32 -> 2.8533773 | L31: =+L29/L32 -> -8.8249467 | M31: =+M29/M32 -> 2.718704 | N31: =+N29/N32 -> 2.0477646 | O31: =+O29/O32 -> 2.7356907 | T31: =+T29/T32 -> -1.0116192 | U31: =+U29/U32 -> 1.698438 | V31: =+V29/V32 -> 4.642819 | W31: =+W29/W32 -> 11.617796 | X31: =+X29/X32 -> 8.823244 | Y31: =+Y29/Y32 -> 12.911185 | Z31: =+Z29/Z32 -> 15.999579 | AA31: =+AA29/AA32 -> -1.497897
B32: Shares | C32: 61.836 | D32: 62.037 | E32: 61.143 | F32: 61.22 | G32: 60.564 | H32: 60.32 | I32: 59.046 | J32: 59.381 | K32: 56.11 | L32: 55.783 | M32: 53.641 | N32: 51.356 | O32: 50.282 | T32: 68.421 | U32: 70.357 | V32: 67.386 | W32: 62.464 | X32: 61.22 | Y32: 61.386 | Z32: 59.381 | AA32: 54.208
B34: Crocs Store Growth | T34: n.a. | U34: =+U3/T3-1 -> -0.041775457 | V34: =+V3/U3-1 -> -0.04359673 | W34: =+W3/V3-1 -> -0.031339031 | X34: =+X3/W3-1 -> 0.097058824 | Y34: =+Y3/X3-1 -> -0.064343164 | Z34: =+Z3/Y3-1 -> 0.11747851 | AA34: =+AA3/Z3-1 -> -1
B35: HEYDUDE Store Growth | T35: n.a. | U35: n.a. | V35: n.a. | W35: n.a. | X35: n.a. | Y35: =+Y4/X4-1 -> #DIV/0! | Z35: =+Z4/Y4-1 -> 2.7142857 | AA35: =+AA4/Z4-1 -> -1
B36: Units Crocs Growth | T36: n.a. | U36: =+U7/T7-1 -> 0.120973 | V36: =+V7/U7-1 -> 0.030364946 | W36: =+W7/V7-1 -> 0.49032379 | X36: =+X7/W7-1 -> 0.1223364 | Y36: =+Y7/X7-1 -> 0.034779072 | Z36: =+Z7/Y7-1 -> 0.062077155 | AA36: =+AA7/Z7-1 -> -1
B37: Units HEYDUDE Growth | T37: n.a. | U37: n.a. | V37: n.a. | W37: n.a. | X37: n.a. | Y37: =+Y8/X8-1 -> 0.08027786 | Z37: =+Z8/Y8-1 -> -0.18256544 | AA37: =+AA8/Z8-1 -> -1
B38: Crocs Revenue Growth | G38: =+G14/C14-1 -> -0.12777085 | H38: =+H14/D14-1 -> 0.097291554 | I38: =+I14/E14-1 -> 0.074275541 | J38: =+J14/F14-1 -> 0.34464457 | K38: =+K14/G14-1 -> 0.17391157 | L38: =+L14/H14-1 -> 0.049892285 | M38: =+M14/I14-1 -> -0.025485434 | N38: =+N14/J14-1 -> -0.10351393 | O38: =+O14/K14-1 -> 0.0076259703 | T38: n.a. | U38: =+U14/T14-1 -> 0.13084667 | V38: =+V14/U14-1 -> 0.12624645 | W38: =+W14/V14-1 -> 0.66919032 | X38: =+X14/W14-1 -> 0.14943659 | Y38: =+Y14/X14-1 -> 0.13306219 | Z38: =+Z14/Y14-1 -> 0.087957865 | AA38: =+AA14/Z14-1 -> 0.014594412
B39: HEYDUDE Revenue Growth | G39: =+G15/C15-1 -> 0.20825185 | H39: =+H15/D15-1 -> -0.17502517 | I39: =+I15/E15-1 -> -0.17350211 | J39: =+J15/F15-1 -> -0.30227321 | K39: =+K15/G15-1 -> -0.25346662 | L39: =+L15/H15-1 -> -0.039136664 | M39: =+M15/I15-1 -> -0.21572547 | N39: =+N15/J15-1 -> 0.011339226 | O39: =+O15/K15-1 -> -0.12339735 | T39: n.a. | U39: n.a. | V39: n.a. | W39: n.a. | X39: n.a. | Y39: =+Y15/X15-1 -> 0.059755989 | Z39: =+Z15/Y15-1 -> -0.13192851 | AA39: =+AA15/Z15-1 -> -0.13262415
B40: Wholesale Growth | G40: =+G16/C16-1 -> -0.030714447 | H40: =+H16/D16-1 -> -0.012688635 | I40: =+I16/E16-1 -> -0.013760525 | J40: =+J16/F16-1 -> 0.091932611 | K40: =+K16/G16-1 -> 0.015682213 | L40: =+L16/H16-1 -> 0.027916082 | M40: =+M16/I16-1 -> -0.14712278 | N40: =+N16/J16-1 -> -0.1820402 | O40: =+O16/K16-1 -> -0.099188592 | T40: n.a. | U40: =+U16/T16-1 -> 0.13525441 | V40: =+V16/U16-1 -> -0.040089786 | W40: =+W16/V16-1 -> 0.86386027 | X40: =+X16/W16-1 -> 0.66210168 | Y40: =+Y16/X16-1 -> 0.055872529 | Z40: =+Z16/Y16-1 -> 0.0017199926 | AA40: =+AA16/Z16-1 -> -0.062169516
B41: DTC Growth | G41: =+G17/C17-1 -> -0.10570437 | H41: =+H17/D17-1 -> 0.089484696 | I41: =+I17/E17-1 -> 0.044485406 | J41: =+J17/F17-1 -> 0.19967455 | K41: =+K17/G17-1 -> 0.14422712 | L41: =+L17/H17-1 -> 0.040082362 | M41: =+M17/I17-1 -> 0.016121224 | N41: =+N17/J17-1 -> -0.014123698 | O41: =+O17/K17-1 -> 0.12119107 | T41: n.a. | U41: =+U17/T17-1 -> 0.12389226 | V41: =+V17/U17-1 -> 0.20870788 | W41: =+W17/V17-1 -> 0.64398614 | X41: =+X17/W17-1 -> 0.41621472 | Y41: =+Y17/X17-1 -> 0.17869372 | Z41: =+Z17/Y17-1 -> 0.071622553 | AA41: =+AA17/Z17-1 -> 0.032804243
B42: Revenue Growth | G42: =G18/C18-1 -> 0.061602685 | H42: =H18/D18-1 -> 0.036494036 | I42: =I18/E18-1 -> 0.015762391 | J42: =J18/F18-1 -> 0.030909377 | K42: =K18/G18-1 -> -0.0013849929 | L42: =L18/H18-1 -> 0.034071914 | M42: =M18/I18-1 -> -0.062040105 | N42: =N18/J18-1 -> -0.03246502 | O42: =O18/K18-1 -> -0.016937417 | T42: n.a. | U42: =+U18/T18-1 -> 0.13084667 | V42: =+V18/U18-1 -> 0.12624645 | W42: =+W18/V18-1 -> 0.66919032 | X42: =+X18/W18-1 -> 0.53668212 | Y42: =+Y18/X18-1 -> 0.11458895 | Z42: =+Z18/Y18-1 -> 0.035272277 | AA42: =+AA18/Z18-1 -> -0.014982784
B43: Gross Margin | C43: =C20/C18 -> 0.53877892 | D43: =D20/D18 -> 0.57937907 | E43: =E20/E18 -> 0.55620785 | F43: =F20/F18 -> 0.55275352 | G43: =G20/G18 -> 0.55620994 | H43: =H20/H18 -> 0.61350857 | I43: =I20/I18 -> 0.59625212 | J43: =J20/J18 -> 0.57884586 | ... O43: =O20/O18 -> 0.5675197 | T43: =T20/T18 -> 0.51475044 | U43: =U20/U18 -> 0.5014298 | V43: =V20/V18 -> 0.54110715 | W43: =W20/W18 -> 0.61390602 | X43: =X20/X18 -> 0.52328828 | Y43: =Y20/Y18 -> 0.55775277 | Z43: =Z20/Z18 -> 0.58756571 | AA43: =AA20/AA18 -> 0.58333604
B44: Operating Margin | C44: =C22/C18 -> 0.26570576 | D44: =D22/D18 -> 0.29699627 | E44: =E22/E18 -> 0.26187965 | F44: =F22/F18 -> 0.2182217 | G44: =G22/G18 -> 0.24123273 | H44: =H22/H18 -> 0.2930611 | I44: =I22/I18 -> 0.25402843 | J44: =J22/J18 -> 0.20198066 | ... O44: =O22/O18 -> 0.21796351 | T44: =T22/T18 -> 0.057842043 | U44: =U22/U18 -> 0.10454228 | V44: =V22/V18 -> 0.15449608 | W44: =W22/W18 -> 0.29526207 | X44: =X22/X18 -> 0.23931353 | Y44: =Y22/Y18 -> 0.26165881 | Z44: =Z22/Z18 -> 0.2491185 | AA44: =AA22/AA18 -> 0.037002737
...

Sheet Ratios
A1: Main
B2: Ratios | C2: 18 | D2: =+C2+1 -> 19 | E2: =+D2+1 -> 20 | F2: =+E2+1 -> 21 | G2: =+F2+1 -> 22 | H2: =+G2+1 -> 23 | I2: =+H2+1 -> 24 | J2: =+I2+1 -> 25
B3: Price | C3: 27.6 | D3: 41.89 | E3: 62.66 | F3: 128.22 | G3: 106.81 | H3: 93.77 | I3: 110.3 | J3: 99.2
B4: Shares o/s | C4: =+Model!T32 -> 68.421 | D4: =+Model!U32 -> 70.357 | E4: =+Model!V32 -> 67.386 | F4: =+Model!W32 -> 62.464 | G4: =+Model!X32 -> 61.22 | H4: =+Model!Y32 -> 61.386 | I4: =+Model!Z32 -> 59.381 | J4: =+Model!AA32 -> 54.208
B5: Market Cap | C5: =+C3*C4 -> 1888.4196 | D5: =+D3*D4 -> 2947.2547 | E5: =+E3*E4 -> 4222.4068 | F5: =+F3*F4 -> 8009.1341 | G5: =+G3*G4 -> 6538.9082 | H5: =+H3*H4 -> 5756.1652 | I5: =+I3*I4 -> 6549.7243 | J5: =+J3*J4 -> 5377.4336
B6: Net Debt | C6: =+Model!T69+Model!T74-Model!T48-Model!T49 -> -100.994 | D6: =+Model!U69+Model!U74-Model!U48-Model!U49 -> 95.247 | E6: =+Model!V69+Model!V74-Model!V48-Model!V49 -> 42.656 | F6: =+Model!W69+Model!W74-Model!W48-Model!W49 -> 558.128 | G6: =+Model!X69+Model!X74-Model!X48-Model!X49 -> 2130.758 | H6: =+Model!Y69+Model!Y74-Model!Y48-Model!Y49 -> 1515.034 | I6: =+Model!Z69+Model!Z74-Model!Z48-Model!Z49 -> 1168.854 | J6: =+Model!AA69+Model!AA74-Model!AA48-Model!AA49 -> 1100.531
B7: EV | C7: =+C5+C6 -> 1787.4256 | D7: =+D5+D6 -> 3042.5017 | E7: =+E5+E6 -> 4265.0628 | F7: =+F5+F6 -> 8567.2621 | G7: =+G5+G6 -> 8669.6662 | H7: =+H5+H6 -> 7271.1992 | I7: =+I5+I6 -> 7718.5783 | J7: =+J5+J6 -> 6477.9646
A9: x | B9: Value Driver
B10: Capital Emloyed | L10: =Long Term Assets + Working Capital (Exclusive of cash)-Accounts Payables
B11: Invested Capital | L11: =Net Working Capital + PP&E + Other Net Operating Assets (net of Liabilties) + (Intangibles)
B12: Invested Capital (exl. Intangibles)
B13: Total Funds Invested | L13: Invested Capital + Non-Operating Assets
B14: NOPAT | L14: EBITA * (1-Marginal Tax Rate)
B15: Net Investment | L15: =Invested Capital (t+1)-Invested Capital (t)
B16: FCF | L16: =NOPAT + non-cash Expenses - Investments in Invested Capital
B17: Investment Rate | L17: =Net Investment/NOPAT
B18: Economic Profit | L18: =Invested Capital *(ROIC-WACC)
A20: x | B20: Efficency-Ratios
B21: Capital Turnover | L21: =Revenue/Equity
B22: Return on Equity (ROE) | L22: =Net Income/Book Value of Equity
B23: Return on Capital Employed (ROCE) | L23: =EBIT/Capital Employed
B24: Return on Capital Invested (ROIC) | L24: =NOPAT/Invested Capital
B25: ROIC without Intangibles | L25: =NOPAT/(Invested Capital exclusive of Intangibles)
B26: Decomposed ROIC | L26: = ROIC = (1-operating cash tax)* (EBITA/Revenues) * (Revenue/Invested Capital)
B28: Retention Rate | L28: =1 - Dividends/Net Income
B29: Reinvestment Rate | L29: =Net CapEx + Change in WC / EBIT * (1-t)
B30: Epected Growth in Net Income | L30: =ROE * Retention Rate
B31: Expected Growth in NOPAT | L31: =ROIC * Reinvestment Rate
A33: x | B33: Finacial Stability Ratios
B34: Equity/Debt Ratio | L34: =Book Value of Equtiy/Book Value of Debt
B35: Gearing | L35: =(Debt - Cash (Net Debt))/Book Value of Equity
B36: Interest Coverage Ratio | L36: =EBIT/Interest Expenses
B37: Net Debt / EBITDA | L37: =Net Debt/EBITDA
B38: Cash Burn Rate | L38: =Book Value of Equity/Absolute value of Loss
A40: x | B40: WC-Managment Ratios
B41: Debitor-Duration | L41: =Accounts Receivables/Revenue*360
B42: Creditor-Duration | L42: =Accounts Payable/Revenue*360
B43: Inventory Intensity | L43: =Inventory/Balance Sheet Total
B44: Invetory Turnover | L44: =Cogs/Inventory
B45: Storage-Duration | L45: =360/Inventory Turnover
...

Sheet Coc
A1: Main
B3: Cost of Capital
A4: x | B4: Cost of Equity (CAPM)
B5: Riskfree Rate
B6: Expected Inflation | F6: =+(1+4.283%)/(1+1.855%)-1 -> 0.023837809 | H6: =(1+Nominal Rate)/(1+Real Rate)-1
B7: Average Real Interest Rate | F7: 0.04283 | H7: = Average Interest Rate of the Past
B8: Riskfree Rate | F8: =F6+F7 -> 0.066667809 | H8: =Goverment Bond or Expected Inflation + Average Real Interest Rate
A10: x | B10: Adjustments for Industry/Company Risk
B11: Raw Beta | F11: =+Data!J3 -> 1.633734 | H11: =Raw beta slope of regression line aginst total market -> Ri= alpha + beta*Rm + standard error
B12: Debt to Value Ratio | H12: Value of Debt/Enterpries Value
B13: Unlevered Beta | H13: = Raw Beta* Debt-to-Equity Ratio (Book Value)
B14: Unlevered Industry Beta | H14: =Median of Peer Group
B15: Levered Industry Beta | F15: =+Data!J7 -> 1.633734 | H15: =Unlevered Industry Beta * Market Value of Debt to Market Value of Equity
A17: x | B17: Expected Equity Risk Premium
B18: Estimated Future Market Return | F18: 0.11 | H18: = 1/P/E * (1.g/ROE) + g , g = real growth in GDP, P/E => P/E ratio for S&P500 or MSCI World Index, ROE = Average ROE in S&P500 or MSCI World
B19: Riskfree Rate | F19: =+F8 -> 0.066667809
B20: Expected Equity Risk Premium | F20: =F18-F19 -> 0.043332191
A22: x | B22: Cost of Equity (CAPM) | F22: =F8+F15*F20 -> 0.13746108 | H22: => ER(i)=rf+beta(i)*(Er(m)-rf)
A25: x | B25: Cost of Debt
B26: Yield to Maturity on Trading Bonds | F26: 0.0425 | H26: => Price = Coupon/(1+YTM)+Coupon(1+YTM)^2 + … + (Face Value + Coupon)/(1+YTM)^n => solve for YTM
B27: or
B28: Riskfree Rate
B29: Credit Default Spread | H29: BB-Rating
B30: Country Rsik Premium | F30: 0
A32: x | B32: Cost of Debt | F32: =+F26 -> 0.0425
A34: x | B34: Capital Structure
B35: Market Value of Debt | F35: =+Main!H6 -> 1335.821
B36: Market Value of Equity | F36: =+Main!H4 -> 6774.6866
B37: Total Enterprise Value | F37: =F35+F36 -> 8110.5076
B39: Marginal Tax Rate | F39: 0.21
A41: x | B41: WACC | F41: =+((F35/F37)*F32*(1-F39))+(F36/F37)*F22 -> 0.12035078 | H41: => WACC = (D/D+E)*kd * (1-t) + (E/D+E) * ke

Sheet DCF
A1: Main | B1: CROCS DCF
B3: Ticker | E3: CROX | G3: Share Price | J3: =+Main!H2 -> 136.34 | L3: Share Price | O3: =+J3 -> 136.34
B4: Date | E4: =+TODAY() -> 46226 | G4: Fair Share Price | J4: =V62 -> 149.81273 | L4: Scneario DCF Price | O4: =+J15+O15+T15 -> 0
B5: End of FY | E5: 46022 | G5: Implied Upside | J5: =J4/J3-1 -> 0.098817119 | L5: Implied Upside | O5: =O4/O3-1 -> -1
A7: x | B7: Assumptions
B9: Switches | G9: Conservative Case | L9: Base Case | Q9: Optimistic Case
B10: Assuptions | G10: Assuptions | I10: Year | J10: Metic | L10: Assuptions | N10: Year | O10: Metic | Q10: Assuptions | S10: Year | T10: Metic
B11: Revenue | E11: 2 | G11: Revenue | L11: Revenue | Q11: Revenue
B12: EBIT | E12: 2 | G12: EBIT | L12: EBIT | Q12: EBIT
B13: WACC | E13: 2 | G13: Implied Share Price
B14: TGR | E14: 2 | G14: Probability | L14: Probability | Q14: Probability
B15: ROIC | E15: 2 | G15: Implied Share Price * p | L15: Implied Share Price * p | Q15: Implied Share Price * p
B17: Valuation
B18: WACC | E18: =CHOOSE(E13,J18,O18,T18) -> 0.105 | G18: WACC | J18: 0.12 | L18: WACC | O18: 0.105 | Q18: WACC | T18: 0.09
B19: TGR | E19: =CHOOSE(E14,J19,O19,T19) -> 0.025 | G19: TGR | J19: 1.5% | L19: TGR | O19: 0.025 | Q19: TGR | T19: 0.03
B20: RONIC | E20: =CHOOSE(E15,J20,O20,T20) -> 0.12 | G20: RONIC | J20: 0.11 | L20: RONIC | O20: 0.12 | Q20: RONIC | T20: 0.13
A24: x | B24: Model | G24: 19 | H24: =G24+1 -> 20 | I24: =H24+1 -> 21 | J24: =I24+1 -> 22 | K24: =J24+1 -> 23 | L24: =K24+1 -> 24 | M24: =L24+1 -> 25 | N24: =M24+1 -> 26 | O24: =N24+1 -> 27 | ... V24: =U24+1 -> 34
B25: Revenue | G25: =+Model!U18 -> 1230.593 | H25: =+Model!V18 -> 1385.951 | I25: =+Model!W18 -> 2313.416 | J25: =+Model!X18 -> 3554.985 | K25: =+Model!Y18 -> 3962.347 | L25: =+Model!Z18 -> 4102.108 | M25: =L25*(1+M26) -> 4143.1291 | N25: =M25*(1+N26) -> 4254.9936 | O25: =N25*(1+O26) -> 4365.283 | P25: =O25*(1+P26) -> 4473.9052 | Q25: =P25*(1+Q26) -> 4580.7773 | R25: =Q25*(1+R26) -> 4685.8253 | S25: =R25*(1+S26) -> 4788.984 | T25: =S25*(1+T26) -> 4890.1966 | ... V25: =U25*(1+V26) -> 5086.5956
B26: Growth (%) | H26: =H25/G25-1 -> 0.12624645 | I26: =I25/H25-1 -> 0.66919032 | J26: =J25/I25-1 -> 0.53668212 | K26: =K25/J25-1 -> 0.11458895 | L26: =L25/K25-1 -> 0.035272277 | M26: {=OFFSET(M26,$E$11,,)} -> 0.01 | N26: {=OFFSET(N26,$E$11,,)} -> 0.027 | O26: {=OFFSET(O26,$E$11,,)} -> 0.02592 | P26: {=OFFSET(P26,$E$11,,)} -> 0.0248832 | Q26: {=OFFSET(Q26,$E$11,,)} -> 0.023887872 | R26: {=OFFSET(R26,$E$11,,)} -> 0.022932357 | S26: {=OFFSET(S26,$E$11,,)} -> 0.022015063 | T26: {=OFFSET(T26,$E$11,,)} -> 0.02113446 | ... V26: {=OFFSET(V26,$E$11,,)} -> 0.019477519
B27: Conservative Case | M27: =+M28-2% -> -0.01 | N27: =+N28-2% -> 0.007 | O27: =+O28-2% -> 0.00592 | P27: =+P28-2% -> 0.0048832 | Q27: =+Q28-2% -> 0.003887872 | R27: =+R28-2% -> 0.0029323571 | S27: =+S28-2% -> 0.0020150628 | T27: =+T28-2% -> 0.0011344603 | ... V27: =+V28-2% -> -0.00052248137
B28: Base Case | M28: 0.01 | N28: 0.027 | O28: =+N28*(1-4%) -> 0.02592 | P28: =+O28*(1-4%) -> 0.0248832 | Q28: =+P28*(1-4%) -> 0.023887872 | R28: =+Q28*(1-4%) -> 0.022932357 | S28: =+R28*(1-4%) -> 0.022015063 | T28: =+S28*(1-4%) -> 0.02113446 | U28: =+T28*(1-4%) -> 0.020289082 | V28: =+U28*(1-4%) -> 0.019477519
B29: Optimisitic Case | M29: =+M28+1% -> 0.02 | N29: =+N28+1% -> 0.037 | O29: =+O28+1% -> 0.03592 | P29: =+P28+1% -> 0.0348832 | Q29: =+Q28+1% -> 0.033887872 | R29: =+R28+1% -> 0.032932357 | S29: =+S28+1% -> 0.032015063 | T29: =+T28+1% -> 0.03113446 | ... V29: =+V28+1% -> 0.029477519
B31: EBIT | G31: =+Model!U22 -> 128.649 | H31: =+Model!V22 -> 214.124 | I31: =+Model!W22 -> 683.064 | J31: =+Model!X22 -> 850.756 | K31: =+Model!Y22 -> 1036.783 | L31: =+Model!Z22 -> 1021.911 | M31: =M32*M25 -> 952.91969 | N31: =N32*N25 -> 988.43501 | O31: =O32*O25 -> 1024.1958 | P31: =P32*P25 -> 1060.1779 | Q31: =Q32*Q25 -> 1096.3583 | R31: =R32*R25 -> 1132.7154 | S31: =S32*S25 -> 1169.2287 | T31: =T32*T25 -> 1205.8791 | ... V31: =V32*V25 -> 1279.521
B32: % of Sales | G32: =G31/G25 -> 0.10454228 | H32: =H31/H25 -> 0.15449608 | I32: =I31/I25 -> 0.29526207 | J32: =J31/J25 -> 0.23931353 | K32: =K31/K25 -> 0.26165881 | L32: =L31/L25 -> 0.2491185 | M32: {=OFFSET(M32,$E$12,,)} -> 0.23 | N32: {=OFFSET(N32,$E$12,,)} -> 0.2323 | O32: {=OFFSET(O32,$E$12,,)} -> 0.234623 | P32: {=OFFSET(P32,$E$12,,)} -> 0.23696923 | Q32: {=OFFSET(Q32,$E$12,,)} -> 0.23933892 | R32: {=OFFSET(R32,$E$12,,)} -> 0.24173231 | S32: {=OFFSET(S32,$E$12,,)} -> 0.24414963 | T32: {=OFFSET(T32,$E$12,,)} -> 0.24659113 | ... V32: {=OFFSET(V32,$E$12,,)} -> 0.25154761
B33: Conservative Case | M33: =+M34-2% -> 0.21 | N33: =+N34-2% -> 0.2123 | O33: =+O34-2% -> 0.214623 | P33: =+P34-2% -> 0.21696923 | Q33: =+Q34-2% -> 0.21933892 | R33: =+R34-2% -> 0.22173231 | S33: =+S34-2% -> 0.22414963 | T33: =+T34-2% -> 0.22659113 | ... V33: =+V34-2% -> 0.23154761
B34: Base Case | M34: 0.23 | N34: =+M34*(1+1%) -> 0.2323 | O34: =+N34*(1+1%) -> 0.234623 | P34: =+O34*(1+1%) -> 0.23696923 | Q34: =+P34*(1+1%) -> 0.23933892 | R34: =+Q34*(1+1%) -> 0.24173231 | S34: =+R34*(1+1%) -> 0.24414963 | T34: =+S34*(1+1%) -> 0.24659113 | U34: =+T34*(1+1%) -> 0.24905704 | V34: =+U34*(1+1%) -> 0.25154761
B35: Optimisitic Case | M35: =+M34+1% -> 0.24 | N35: =+N34+1% -> 0.2423 | O35: =+O34+1% -> 0.244623 | P35: =+P34+1% -> 0.24696923 | Q35: =+Q34+1% -> 0.24933892 | R35: =+R34+1% -> 0.25173231 | S35: =+S34+1% -> 0.25414963 | T35: =+T34+1% -> 0.25659113 | ... V35: =+V34+1% -> 0.26154761
B37: Taxes | G37: =+Model!U28 -> -0.175 | H37: =+Model!V28 -> -105.882 | I37: =+Model!W28 -> -61.845 | J37: =+Model!X28 -> 178.349 | K37: =+Model!Y28 -> 83.706 | L37: =+Model!Z28 -> -39.486 | M37: =M38*M31 -> 200.11313 | N37: =N38*N31 -> 207.57135 | O37: =O38*O31 -> 215.08112 | P37: =P38*P31 -> 222.63735 | Q37: =Q38*Q31 -> 230.23524 | R37: =R38*R31 -> 237.87023 | S37: =S38*S31 -> 245.53803 | T37: =T38*T31 -> 253.23462 | ... V37: =V38*V31 -> 268.69941
B38: Tax Rate (%) | G38: =G37/G31 -> -0.0013602904 | H38: =H37/H31 -> -0.49448917 | I38: =I37/I31 -> -0.090540564 | J38: =J37/J31 -> 0.2096359 | K38: =K37/K31 -> 0.080736278 | L38: =L37/L31 -> -0.038639373 | M38: 0.21 | N38: 0.21 | O38: 0.21 | P38: 0.21 | Q38: 0.21 | R38: 0.21 | S38: 0.21 | T38: 0.21 | U38: 0.21 | V38: 0.21
B40: Nopat | G40: =G31-G37 -> 128.824 | H40: =H31-H37 -> 320.006 | I40: =I31-I37 -> 744.909 | J40: =J31-J37 -> 672.407 | K40: =K31-K37 -> 953.077 | L40: =L31-L37 -> 1061.397 | M40: =M31-M37 -> 752.80655 | N40: =N31-N37 -> 780.86365 | ... V40: =V31-V37 -> 1010.8216
B42: D&A and other non-cash Expenses | G42: =+Model!U83+Model!U88 -> 38.625 | H42: =+Model!V83+Model!V88 -> 43.98 | I42: =+Model!W83+Model!W88 -> 70.098 | J42: =+Model!X83+Model!X88 -> 70.532 | K42: =+Model!Y83+Model!Y88 -> 83.376 | L42: =+Model!Z83+Model!Z88 -> 102.893 | M42: =M43*M25 -> 107.72136 | N42: =N43*N25 -> 110.62983 | O42: =O43*O25 -> 113.49736 | P42: =P43*P25 -> 116.32154 | Q42: =Q43*Q25 -> 119.10021 | R42: =R43*R25 -> 121.83146 | S42: =S43*S25 -> 124.51359 | T42: =T43*T25 -> 127.14511 | ... V42: =V43*V25 -> 132.25149
B43: % of Sales | G43: =G42/G25 -> 0.031387307 | H43: =H42/H25 -> 0.031732724 | I43: =I42/I25 -> 0.030300646 | J43: =J42/J25 -> 0.019840309 | K43: =K42/K25 -> 0.021042074 | L43: =L42/L25 -> 0.025082957 | M43: 0.026 | N43: 0.026 | O43: 0.026 | P43: 0.026 | Q43: 0.026 | R43: 0.026 | S43: 0.026 | T43: 0.026 | U43: 0.026 | V43: 0.026
B45: CapEx | G45: =+Model!U101 -> -35.96 | H45: =+Model!V101 -> -41.597 | I45: =+Model!W101 -> -55.916 | J45: =+Model!X101 -> -104.19 | K45: =+Model!Y101 -> -115.625 | L45: =+Model!Z101 -> -69.347 | M45: =M46*M25 -> -116.00761 | N45: =N46*N25 -> -119.13982 | O45: =O46*O25 -> -122.22792 | P45: =P46*P25 -> -125.26935 | Q45: =Q46*Q25 -> -128.26176 | R45: =R46*R25 -> -131.20311 | S45: =S46*S25 -> -134.09155 | T45: =T46*T25 -> -136.92551 | ... V45: =V46*V25 -> -142.42468
B46: % of Sales | G46: =G45/G25 -> -0.029221684 | H46: =H45/H25 -> -0.030013327 | I46: =I45/I25 -> -0.024170318 | J46: =J45/J25 -> -0.029308141 | K46: =K45/K25 -> -0.029180937 | L46: =L45/L25 -> -0.016905211 | M46: -0.028 | N46: -0.028 | O46: -0.028 | P46: -0.028 | Q46: -0.028 | R46: -0.028 | S46: -0.028 | T46: -0.028 | U46: -0.028 | V46: -0.028
B48: Change in WC | G48: =+Model!U99 -> -111.297 | H48: =+Model!V99 -> 132.388 | I48: =+Model!W99 -> -44.526 | J48: =+Model!X99 -> -91.682 | K48: =+Model!Y99 -> 366.525 | L48: =+Model!Z99 -> 68.43 | M48: =M49*M25 -> -49.717549 | N48: =N49*N25 -> -51.059923 | O48: =O49*O25 -> -52.383396 | P48: =P49*P25 -> -53.686862 | Q48: =Q49*Q25 -> -54.969327 | R48: =R49*R25 -> -56.229904 | S48: =S49*S25 -> -57.467809 | T48: =T49*T25 -> -58.68236 | ... V48: =V49*V25 -> -61.039148
B49: % of Sales | G49: =G48/G25 -> -0.090441763 | H49: =H48/H25 -> 0.095521415 | I49: =I48/I25 -> -0.019246863 | J49: =J48/J25 -> -0.025789701 | K49: =K48/K25 -> 0.092501994 | L49: =L48/L25 -> 0.016681667 | M49: -0.012 | N49: -0.012 | O49: -0.012 | P49: -0.012 | Q49: -0.012 | R49: -0.012 | S49: -0.012 | T49: -0.012 | U49: -0.012 | V49: -0.012
B51: Unlevered Free Cashflow | G51: =G40+G42+G45+G48 -> 20.192 | H51: =H40+H42+H45+H48 -> 454.777 | I51: =I40+I42+I45+I48 -> 714.565 | J51: =J40+J42+J45+J48 -> 547.067 | K51: =K40+K42+K45+K48 -> 1287.353 | L51: =L40+L42+L45+L48 -> 1163.373 | M51: =M40+M42+M45+M48 -> 694.80275 | N51: =N40+N42+N45+N48 -> 721.29374 | ... V51: =V40+V42+V45+V48 -> 939.60924
B52: Present Value of unlevered FC | M52: =(M51/(1+$E$18)^M53)*M53 -> 370.3425 | N52: =N51/(1+$E$18)^N53 -> 617.01878 | O52: =O51/(1+$E$18)^O53 -> 579.06318 | P52: =P51/(1+$E$18)^P53 -> 542.88844 | Q52: =Q51/(1+$E$18)^Q53 -> 508.47489 | R52: =R51/(1+$E$18)^R53 -> 475.79429 | S52: =S51/(1+$E$18)^S53 -> 444.81114 | T52: =T51/(1+$E$18)^T53 -> 415.4838 | U52: =U51/(1+$E$18)^U53 -> 387.76557 | V52: =V51/(1+$E$18)^V53 -> 361.6057
B53: Discount Period | M53: =YEARFRAC(E4,E5) -> 0.56388889 | N53: =M53+1 -> 1.5638889 | O53: =N53+1 -> 2.5638889 | P53: =O53+1 -> 3.5638889 | Q53: =P53+1 -> 4.5638889 | R53: =Q53+1 -> 5.5638889 | S53: =R53+1 -> 6.5638889 | T53: =S53+1 -> 7.5638889 | U53: =T53+1 -> 8.5638889 | V53: =U53+1 -> 9.5638889
B54: Sum of Present Value | V54: =SUM(M52:V52) -> 4703.2483
...

Sheet Data
A1: Main
B2: Computation of Beta | L2: CROX Close Prices | P2: Lulu Close Prices | T2: SPX Close Prices
B3: Regression Slope | J3: =+SLOPE(N5:N1006,V5:V1006) -> 1.633734 | L3: UTC Date | M3: Close | N3: Change | P3: UTC Date | Q3: Close | R3: Change | T3: UTC Date | U3: Close | V3: Change
L4: Wed, 25 Aug 2021 00:00:00 GMT | M4: 143.81 | P4: Wed, 25 Aug 2021 00:00:00 GMT | Q4: 408.32 | T4: Wed, 25 Aug 2021 00:00:00 GMT | U4: 4496.1899
B5: Covariance | J5: =+_xlfn.COVARIANCE.P(N5:N1006,V5:V1006) -> 0.00020875767 | L5: Thu, 26 Aug 2021 00:00:00 GMT | M5: 143.1 | N5: =+M5/M4-1 -> -0.0049370697 | P5: Thu, 26 Aug 2021 00:00:00 GMT | Q5: 404.44 | R5: =+Q5/Q4-1 -> -0.0095023511 | T5: Thu, 26 Aug 2021 00:00:00 GMT | U5: 4470 | V5: =+U5/U4-1 -> -0.0058249188
B6: Variance | J6: =+_xlfn.VAR.P(V5:V1006) -> 0.00012777947 | L6: Fri, 27 Aug 2021 00:00:00 GMT | M6: 146.09 | N6: =+M6/M5-1 -> 0.020894479 | P6: Fri, 27 Aug 2021 00:00:00 GMT | Q6: 405.97 | R6: =+Q6/Q5-1 -> 0.0037830086 | T6: Fri, 27 Aug 2021 00:00:00 GMT | U6: 4509.3701 | V6: =+U6/U5-1 -> 0.0088076325
B7: Beta | J7: =+J5/J6 -> 1.633734 | L7: Mon, 30 Aug 2021 00:00:00 GMT | M7: 146.4 | N7: =+M7/M6-1 -> 0.0021219796 | P7: Mon, 30 Aug 2021 00:00:00 GMT | Q7: 414.52 | R7: =+Q7/Q6-1 -> 0.02106067 | T7: Mon, 30 Aug 2021 00:00:00 GMT | U7: 4528.79 | V7: =+U7/U6-1 -> 0.0043065708
L8: Tue, 31 Aug 2021 00:00:00 GMT | M8: 142.82 | N8: =+M8/M7-1 -> -0.024453552 | P8: Tue, 31 Aug 2021 00:00:00 GMT | Q8: 400.17 | R8: =+Q8/Q7-1 -> -0.034618354 | T8: Tue, 31 Aug 2021 00:00:00 GMT | U8: 4522.6802 | V8: =+U8/U7-1 -> -0.001349116
B9: Regression Statistics | L9: Wed, 01 Sep 2021 00:00:00 GMT | M9: 143.36 | N9: =+M9/M8-1 -> 0.0037809831 | P9: Wed, 01 Sep 2021 00:00:00 GMT | Q9: 395.53 | R9: =+Q9/Q8-1 -> -0.011595072 | T9: Wed, 01 Sep 2021 00:00:00 GMT | U9: 4524.0898 | V9: =+U9/U8-1 -> 0.00031168863
B10: Multiple R | C10: 0.50794566 | L10: Thu, 02 Sep 2021 00:00:00 GMT | M10: 138.57 | N10: =+M10/M9-1 -> -0.033412388 | P10: Thu, 02 Sep 2021 00:00:00 GMT | Q10: 388.37 | R10: =+Q10/Q9-1 -> -0.018102293 | T10: Thu, 02 Sep 2021 00:00:00 GMT | U10: 4536.9502 | V10: =+U10/U9-1 -> 0.0028426384
B11: R Square | C11: 0.25800879 | L11: Fri, 03 Sep 2021 00:00:00 GMT | M11: 139.69 | N11: =+M11/M10-1 -> 0.0080825576 | P11: Fri, 03 Sep 2021 00:00:00 GMT | Q11: 388.33 | R11: =+Q11/Q10-1 -> -0.00010299457 | T11: Fri, 03 Sep 2021 00:00:00 GMT | U11: 4535.4302 | V11: =+U11/U10-1 -> -0.00033503113
B12: Adjusted R Square | C12: 0.2572668 | L12: Tue, 07 Sep 2021 00:00:00 GMT | M12: 136.28 | N12: =+M12/M11-1 -> -0.024411196 | P12: Tue, 07 Sep 2021 00:00:00 GMT | Q12: 386.46 | R12: =+Q12/Q11-1 -> -0.004815492 | T12: Tue, 07 Sep 2021 00:00:00 GMT | U12: 4520.0298 | V12: =+U12/U11-1 -> -0.0033955744
B13: Standard Error | C13: 0.031349302 | L13: Wed, 08 Sep 2021 00:00:00 GMT | M13: 138.96 | N13: =+M13/M12-1 -> 0.019665395 | P13: Wed, 08 Sep 2021 00:00:00 GMT | Q13: 380.85 | R13: =+Q13/Q12-1 -> -0.014516379 | T13: Wed, 08 Sep 2021 00:00:00 GMT | U13: 4514.0698 | V13: =+U13/U12-1 -> -0.0013185667
B14: Observations | C14: 1002 | L14: Thu, 09 Sep 2021 00:00:00 GMT | M14: 141.53 | N14: =+M14/M13-1 -> 0.018494531 | P14: Thu, 09 Sep 2021 00:00:00 GMT | Q14: 420.71 | R14: =+Q14/Q13-1 -> 0.10466063 | T14: Thu, 09 Sep 2021 00:00:00 GMT | U14: 4493.2798 | V14: =+U14/U13-1 -> -0.0046056087
L15: Fri, 10 Sep 2021 00:00:00 GMT | M15: 144.11 | N15: =+M15/M14-1 -> 0.018229351 | P15: Fri, 10 Sep 2021 00:00:00 GMT | Q15: 425.58 | R15: =+Q15/Q14-1 -> 0.01157567 | T15: Fri, 10 Sep 2021 00:00:00 GMT | U15: 4458.5801 | V15: =+U15/U14-1 -> -0.0077225788
B16: ANOVA | L16: Mon, 13 Sep 2021 00:00:00 GMT | M16: 137.72 | N16: =+M16/M15-1 -> -0.044341128 | P16: Mon, 13 Sep 2021 00:00:00 GMT | Q16: 425.12 | R16: =+Q16/Q15-1 -> -0.0010808779 | T16: Mon, 13 Sep 2021 00:00:00 GMT | U16: 4468.73 | V16: =+U16/U15-1 -> 0.0022764876
C17: df | D17: SS | E17: MS | F17: F | G17: Significance F | L17: Tue, 14 Sep 2021 00:00:00 GMT | M17: 149.38 | N17: =+M17/M16-1 -> 0.084664537 | P17: Tue, 14 Sep 2021 00:00:00 GMT | Q17: 420.5 | R17: =+Q17/Q16-1 -> -0.01086752 | T17: Tue, 14 Sep 2021 00:00:00 GMT | U17: 4443.0498 | V17: =+U17/U16-1 -> -0.0057466385
B18: Regression | C18: 1 | D18: 0.3417366 | E18: 0.3417366 | F18: 347.72486 | G18: 7.837118e-67 | L18: Wed, 15 Sep 2021 00:00:00 GMT | M18: 153.68 | N18: =+M18/M17-1 -> 0.028785647 | P18: Wed, 15 Sep 2021 00:00:00 GMT | Q18: 418.95 | R18: =+Q18/Q17-1 -> -0.003686088 | T18: Wed, 15 Sep 2021 00:00:00 GMT | U18: 4480.7002 | V18: =+U18/U17-1 -> 0.008473997
B19: Residual | C19: 1000 | D19: 0.98277874 | E19: 0.00098277874 | L19: Thu, 16 Sep 2021 00:00:00 GMT | M19: 157.82 | N19: =+M19/M18-1 -> 0.026939094 | P19: Thu, 16 Sep 2021 00:00:00 GMT | Q19: 426.44 | R19: =+Q19/Q18-1 -> 0.017878028 | T19: Thu, 16 Sep 2021 00:00:00 GMT | U19: 4473.75 | V19: =+U19/U18-1 -> -0.0015511404
B20: Total | C20: 1001 | D20: 1.3245153 | L20: Fri, 17 Sep 2021 00:00:00 GMT | M20: 155.18 | N20: =+M20/M19-1 -> -0.016727918 | P20: Fri, 17 Sep 2021 00:00:00 GMT | Q20: 426.55 | R20: =+Q20/Q19-1 -> 0.00025794954 | T20: Fri, 17 Sep 2021 00:00:00 GMT | U20: 4432.9902 | V20: =+U20/U19-1 -> -0.0091108725
L21: Mon, 20 Sep 2021 00:00:00 GMT | M21: 151.72 | N21: =+M21/M20-1 -> -0.022296688 | P21: Mon, 20 Sep 2021 00:00:00 GMT | Q21: 419.53 | R21: =+Q21/Q20-1 -> -0.016457625 | T21: Mon, 20 Sep 2021 00:00:00 GMT | U21: 4357.73 | V21: =+U21/U20-1 -> -0.016977311
C22: Coefficients | D22: Standard Error | E22: t Stat | F22: P-value | G22: Lower 95% | H22: Upper 95% | I22: Lower 95,0% | J22: Upper 95,0% | L22: Tue, 21 Sep 2021 00:00:00 GMT | M22: 152.47 | N22: =+M22/M21-1 -> 0.0049433166 | P22: Tue, 21 Sep 2021 00:00:00 GMT | Q22: 424.19 | R22: =+Q22/Q21-1 -> 0.011107668 | T22: Tue, 21 Sep 2021 00:00:00 GMT | U22: 4354.1899 | V22: =+U22/U21-1 -> -0.00081235852
B23: Intercept | C23: -0.00053410231 | D23: 0.00099106715 | E23: -0.53891637 | F23: 0.59006451 | G23: -0.0024789121 | H23: 0.0014107075 | I23: -0.0024789121 | J23: 0.0014107075 | L23: Wed, 22 Sep 2021 00:00:00 GMT | M23: 155.73 | N23: =+M23/M22-1 -> 0.021381255 | P23: Wed, 22 Sep 2021 00:00:00 GMT | Q23: 431.18 | R23: =+Q23/Q22-1 -> 0.016478465 | T23: Wed, 22 Sep 2021 00:00:00 GMT | U23: 4395.6401 | V23: =+U23/U22-1 -> 0.0095196112
B24: X Variable 1 | C24: 1.633734 | D24: 0.087611975 | E24: 18.647382 | F24: 7.837118e-67 | G24: 1.4618096 | H24: 1.8056584 | I24: 1.4618096 | J24: 1.8056584 | L24: Thu, 23 Sep 2021 00:00:00 GMT | M24: 163 | N24: =+M24/M23-1 -> 0.046683362 | P24: Thu, 23 Sep 2021 00:00:00 GMT | Q24: 431.91 | R24: =+Q24/Q23-1 -> 0.0016930284 | T24: Thu, 23 Sep 2021 00:00:00 GMT | U24: 4448.98 | V24: =+U24/U23-1 -> 0.012134716
L25: Fri, 24 Sep 2021 00:00:00 GMT | M25: 156.3 | N25: =+M25/M24-1 -> -0.041104294 | P25: Fri, 24 Sep 2021 00:00:00 GMT | Q25: 432.61 | R25: =+Q25/Q24-1 -> 0.001620708 | T25: Fri, 24 Sep 2021 00:00:00 GMT | U25: 4455.48 | V25: =+U25/U24-1 -> 0.001461009
B26: CORX-LULU Analysis | L26: Mon, 27 Sep 2021 00:00:00 GMT | M26: 153.59 | N26: =+M26/M25-1 -> -0.017338452 | P26: Mon, 27 Sep 2021 00:00:00 GMT | Q26: 430.72 | R26: =+Q26/Q25-1 -> -0.004368831 | T26: Mon, 27 Sep 2021 00:00:00 GMT | U26: 4443.1099 | V26: =+U26/U25-1 -> -0.0027763826
L27: Tue, 28 Sep 2021 00:00:00 GMT | M27: 150.63 | N27: =+M27/M26-1 -> -0.019272088 | P27: Tue, 28 Sep 2021 00:00:00 GMT | Q27: 414.54 | R27: =+Q27/Q26-1 -> -0.037565007 | T27: Tue, 28 Sep 2021 00:00:00 GMT | U27: 4352.6299 | V27: =+U27/U26-1 -> -0.020364111
B28: Slope | D28: =+SLOPE(N5:N1006,R5:R1006) -> 0.62818043 | L28: Wed, 29 Sep 2021 00:00:00 GMT | M28: 149.81 | N28: =+M28/M27-1 -> -0.0054438027 | P28: Wed, 29 Sep 2021 00:00:00 GMT | Q28: 410.22 | R28: =+Q28/Q27-1 -> -0.01042119 | T28: Wed, 29 Sep 2021 00:00:00 GMT | U28: 4359.46 | V28: =+U28/U27-1 -> 0.0015691842
L29: Thu, 30 Sep 2021 00:00:00 GMT | M29: 143.48 | N29: =+M29/M28-1 -> -0.042253521 | P29: Thu, 30 Sep 2021 00:00:00 GMT | Q29: 404.7 | R29: =+Q29/Q28-1 -> -0.013456194 | T29: Thu, 30 Sep 2021 00:00:00 GMT | U29: 4307.54 | V29: =+U29/U28-1 -> -0.011909714
B30: COV.S | D30: =+_xlfn.COVARIANCE.S(R5:R1006,N5:N1006) -> 0.00044223662 | L30: Fri, 01 Oct 2021 00:00:00 GMT | M30: 141.13 | N30: =+M30/M29-1 -> -0.016378589 | P30: Fri, 01 Oct 2021 00:00:00 GMT | Q30: 401.37 | R30: =+Q30/Q29-1 -> -0.0082283173 | T30: Fri, 01 Oct 2021 00:00:00 GMT | U30: 4357.04 | V30: =+U30/U29-1 -> 0.011491478
B31: VAR.S | D31: =+_xlfn.VAR.S(N5:N1006) -> 0.0013231921 | L31: Mon, 04 Oct 2021 00:00:00 GMT | M31: 136.07 | N31: =+M31/M30-1 -> -0.035853468 | P31: Mon, 04 Oct 2021 00:00:00 GMT | Q31: 392.57 | R31: =+Q31/Q30-1 -> -0.021924907 | T31: Mon, 04 Oct 2021 00:00:00 GMT | U31: 4300.46 | V31: =+U31/U30-1 -> -0.012985898
B32: Beta | D32: =+D30/D31 -> 0.3342195 | L32: Tue, 05 Oct 2021 00:00:00 GMT | M32: 136.92 | N32: =+M32/M31-1 -> 0.0062467847 | P32: Tue, 05 Oct 2021 00:00:00 GMT | Q32: 397.12 | R32: =+Q32/Q31-1 -> 0.01159029 | T32: Tue, 05 Oct 2021 00:00:00 GMT | U32: 4345.7202 | V32: =+U32/U31-1 -> 0.010524515
L33: Wed, 06 Oct 2021 00:00:00 GMT | M33: 138.31 | N33: =+M33/M32-1 -> 0.010151914 | P33: Wed, 06 Oct 2021 00:00:00 GMT | Q33: 398.13 | R33: =+Q33/Q32-1 -> 0.0025433118 | T33: Wed, 06 Oct 2021 00:00:00 GMT | U33: 4363.5498 | V33: =+U33/U32-1 -> 0.0041027929
B34: Regression Statistics | L34: Thu, 07 Oct 2021 00:00:00 GMT | M34: 139.54 | N34: =+M34/M33-1 -> 0.0088930663 | P34: Thu, 07 Oct 2021 00:00:00 GMT | Q34: 399.72 | R34: =+Q34/Q33-1 -> 0.0039936704 | T34: Thu, 07 Oct 2021 00:00:00 GMT | U34: 4399.7598 | V34: =+U34/U33-1 -> 0.0082982807
B35: Multiple R | C35: 0.45820318 | L35: Fri, 08 Oct 2021 00:00:00 GMT | M35: 130.4 | N35: =+M35/M34-1 -> -0.065500932 | P35: Fri, 08 Oct 2021 00:00:00 GMT | Q35: 397.22 | R35: =+Q35/Q34-1 -> -0.0062543781 | T35: Fri, 08 Oct 2021 00:00:00 GMT | U35: 4391.3398 | V35: =+U35/U34-1 -> -0.0019137231
B36: R Square | C36: 0.20995015 | L36: Mon, 11 Oct 2021 00:00:00 GMT | M36: 125.62 | N36: =+M36/M35-1 -> -0.036656442 | P36: Mon, 11 Oct 2021 00:00:00 GMT | Q36: 386.04 | R36: =+Q36/Q35-1 -> -0.028145612 | T36: Mon, 11 Oct 2021 00:00:00 GMT | U36: 4361.1899 | V36: =+U36/U35-1 -> -0.0068657638
B37: Adjusted R Square | C37: 0.2091601 | L37: Tue, 12 Oct 2021 00:00:00 GMT | M37: 130.09 | N37: =+M37/M36-1 -> 0.035583506 | P37: Tue, 12 Oct 2021 00:00:00 GMT | Q37: 384.57 | R37: =+Q37/Q36-1 -> -0.0038078956 | T37: Tue, 12 Oct 2021 00:00:00 GMT | U37: 4350.6499 | V37: =+U37/U36-1 -> -0.0024167806
B38: Standard Error | C38: 0.023595514 | L38: Wed, 13 Oct 2021 00:00:00 GMT | M38: 132.47 | N38: =+M38/M37-1 -> 0.018295027 | P38: Wed, 13 Oct 2021 00:00:00 GMT | Q38: 400.71 | R38: =+Q38/Q37-1 -> 0.041968952 | T38: Wed, 13 Oct 2021 00:00:00 GMT | U38: 4363.7998 | V38: =+U38/U37-1 -> 0.0030225145
B39: Observations | C39: 1002 | L39: Thu, 14 Oct 2021 00:00:00 GMT | M39: 136.62 | N39: =+M39/M38-1 -> 0.031327848 | P39: Thu, 14 Oct 2021 00:00:00 GMT | Q39: 406.99 | R39: =+Q39/Q38-1 -> 0.015672182 | T39: Thu, 14 Oct 2021 00:00:00 GMT | U39: 4438.2598 | V39: =+U39/U38-1 -> 0.017063102
L40: Fri, 15 Oct 2021 00:00:00 GMT | M40: 137.19 | N40: =+M40/M39-1 -> 0.0041721563 | P40: Fri, 15 Oct 2021 00:00:00 GMT | Q40: 403.51 | R40: =+Q40/Q39-1 -> -0.0085505786 | T40: Fri, 15 Oct 2021 00:00:00 GMT | U40: 4471.3701 | V40: =+U40/U39-1 -> 0.0074602104
...
