Workbook
Name WACC: DCF!$E$18

Sheet Main
A1: Kering
A2: numbers in mio EUR | G2: Price | H2: 245.3
G3: Shares out. | H3: 122.60481 | I3: Q126
B4: KER.PA | G4: MC | H4: =H3*H2 -> 30074.96
B5: Investors | G5: Cash | H5: 4313 | I5: Q126
G6: Debt | H6: =10306+2046+170+40 -> 12562 | I6: Q126
B7: Brands | C7: % of Rev | D7: Products | E7: Competitors | G7: EV | H7: =H4+H6-H5 -> 38323.96
B8: Gucci | C8: =1-SUM(C9:C12) -> 0.44 | D8: Leather Goods, Shoes, Appereal
B9: Yves Saint Laurent | C9: 0.16 | D9: Leather Goods, Shoes, Appereal
B10: Bottega Veneta | C10: 0.09 | D10: Leather Goods, Shoes, Appereal | G10: Founded: 1963
B11: Kering Eyewear and Corporate | C11: 0.19 | D11: Eyeware | G11: Employees | H11: 46930
B12: Other Houeses: | C12: 0.12
B13: Balenciaga | D13: Appereal and other | G13: Management
B14: Alexander Mcqueen | D14: Appereal and other | G14: CEO: Luca de Meo
B15: Brioni | D15: Appereal and other | G15: CFO: Armelle Poulou | L15: Supply Chain
B16: Boucheron | D16: Fregrance and Jewelery | G16: Brand Development: Francessca Bellettini
B17: Pomellato | D17: Jewelery | G17: COO: Jean-Marc Duplaix
B18: Dodo | D18: Jewelery
B19: Qeelin | D19: Jewelery | G19: EUR/USD | H19: 1.07
J31: Strategy
J32: 4 Pillars:
J33: 1.Brand Building: Convey brand narrative
J34: 2.Product Strategy: covering relevant range
J35: 3.Distribution and Client Experience: Increase exclusivity
B36: Revenue Stores & E-Com | C36: 0.78 | J36: 4. Excellence in Execution: Improving organization
B37: Revenue Wholesale | C37: 0.22 | J37: Focus on direclty operated online stores, lower wholesale penetration, close outlets and stores with low profitability
B39: Notes: | J39: Equity Investments
B40: Disposal of Girard-Perregaux and Ulysse Nardin in 2022 (Watch-Makers) | J40: Valentino | K40: 1768
B41: Jan. 2024 -> Acquistion of strategic Real Estate in New York 10.700 sqm for 885 mio EUR 715-175 Fith Evenue | J41: Other | K41: 75
B42: April 2024 -> Acquistion of company that ownes real estate in at 8 Via 11,800 sqm for 1,3 bil EUR Montenapoleone in Milan | J42: Valentino will be incoporated in the group within 3 years
B43: Dual Tranche Bond: 1 bil EUR for 8-year matuiry 3,375% Coupon, 750 Mil for 12 year maturity 3,625% Coupon
B44: November 2024: 750mio EUR bond 10 year maturity 3,625% coupon
B45: Q324: Ewa Abrams appointed President of Kering Americas
B46: Boucheron fist Store in NY
B47: Bottega Venetta first Parfume collection through Kering Beautue
B48: 15-01-25: Real Estate Deal with Adrian for these properties: Hôtel de Nocé, located 26, place Vendôme, and two buildings located on avenue Montaigne, at 35-37 and 56, Kerings investment amounts to 837 mio EUR
B49: 29-01-25: Patnership with 0-93. Lab
B50: 07-02-25: Gucci endes collaboration with Sabato de Sarno
B51: Kering Beaute: Launch of Bottega and Balenciaga fragrances in H2.24
B52: 13-03-25: Demna new creative director of Gucci
...

Sheet Brands
A1: Main
B2: Kering
B3: CEO: Luca de Meo | D3: was former CEO of Renault -> a lot of experience in the automotive industry (Fiat, Volkswagen etc.)
T4: Latest drop: Primavera
T5: https://www.businessoffashion.com/articles/luxury/gucci-demna-pricing-strategy/?utm_source=newsletter_daily_digest&utm_medium=email&utm_campaign=Daily_Digest_180326&cid=587aba24-4127-469f-8d2d-6bf7a31b470b&did=69ba3f805900d1b23aaac8f231f99758&uid=2360165579082&utm_content=intro
B7: GUCCI | J7: Products:
B8: CEO: Francesca Bellettini (Former CEOs: Stefano Cantino, Jean Franqouis Palus) | J8: 50% Leather Goods
B9: Creative Director: Demna Gvasalia | J9: 21% Shoes
B10: Former: Sabato de Sano, Alessandro Michele | J10: 17% Ready-to-Wear
B11: 90% of Revenue in driectly operated stores | J11: 4% Wathches & Jewelery
B12: 10% of Revenue in Wholesale | J12: 8% other
B14: GUCCI Design Idea
B15: Demna Gvasalia: Founder of Vetments, former creative director of Balenciaga
B17: Red -> New main colour of GUCCI
B18: Contrast to Allesandro Michele -> less loud
B20: https://www.gq-magazin.de/artikel/gucci-sabato-de-sarno-spring-summer-2025
B21: https://www.vogue.de/artikel/gucci-kreativdirektor-sabato-de-sarno-interview
B22: https://bellevue.nzz.ch/mode-beauty/wer-ist-sabato-de-sarno-gucci-zeigt-film-ueber-neuen-chefdesigner-ld.1822928
B24: Gucci Collections: | D24: https://www.vogue.com/fashion-shows/designer/gucci | T24: created surge in Website traffic: jumped to 316.000 (average 180-210.000) visitors per day
B25: next Collection
B27: Yves Saint Laurent
B28: CEO: Cedric Charbit (former: Francesca Bellettini) | I28: Products: | J28: 70% Leather Goods
B29: Creative Director: Anthony Vaccarello | J29: 7% Shoes
B30: 81% of Revenue in driectly operated stores | J30: 12% Ready-to-Wear
B31: 19% of Revenue in Wholesale | J31: 11% other
B34: Bottega Venetta | I34: Products: | J34: 79% Leather Goods
B35: CEO: Bartolomeo Rongone | J35: 9% Shoes
B36: Creative Director: Louise Trotter (former: Matthieu Blazy) | J36: 9% Ready-to-Wear
B37: 84% of Revenue in driectly operated stores | J37: 3% other
B38: 16% of Revenue in Wholesale
B41: Other Houses | I41: Products: | J41: 17% Leather Goods
B42: 73% of Revenue in driectly operated stores | J42: 25% Shoes
B43: 27% of Revenue in Wholesale | J43: 26% Ready-to-Wear
J44: 28% Wathches & Jewelery
B45: Balenciaga | J45: 4% other
B46: CEO: Gianfranco Gianangeli (former: Cedric Charbit, now at YSL) | I46: Products:
B47: Creative Director: | D47: Peirpaolo Piccioli | I47: Ready-to-Wear, Shoes, Leather Goods etc
B49: Alexander McQueen | G49: Products:
B50: CEO: Gianfilippo Testa | G50: Ready-to-Wear, Shoes, Leather Goods etc
B51: Creative Director: Sean McGirr
...

Sheet Macro
A1: Main
B18: Revenue vs. Operating Income since 2007 | J18: Revenue by houses since 2011
B60: https://www.statista.com/outlook/cmo/luxury-goods/worldwide#revenue

Sheet Model
A1: Main
C2: H123 | D2: H223 | E2: H124 | F2: H224 | G2: H125 | H2: H225 | J2: 2007 | K2: 2008 | L2: 2009 | M2: 2010 | N2: FY11 | O2: FY12 | P2: FY13 | Q2: FY14 | R2: FY15 | S2: FY16 | T2: FY17 | U2: FY18 | V2: FY19 | W2: FY20 | X2: FY21 | Y2: FY22 | Z2: FY23 | AA2: FY24 | AB2: FY25 | AC2: FY26 | AD2: FY27 | AE2: FY28 | AF2: FY29 | AG2: FY30
B3: Luxury Eyewear Global Revenue | U3: 26740 | V3: 27550 | W3: 21940 | X3: 24870 | Y3: 26470 | Z3: 29180 | AA3: 29830 | AB3: 30520 | AC3: 31190 | AD3: 31870 | AE3: 32530 | AF3: 33190
B4: Luxury Fashion Global Revenue | U4: 117900 | V4: 124700 | W4: 110900 | X4: 120000 | Y4: 125500 | Z4: 142100 | AA4: 145400 | AB4: 150400 | AC4: 155300 | AD4: 160200 | AE4: 165000 | AF4: 169800
B5: Luxury Leather Goods Global Revenue | U5: 50860 | V5: 55900 | W5: 46490 | X5: 55990 | Y5: 59620 | Z5: 69130 | AA5: 72350 | AB5: 76130 | AC5: 79840 | AD5: 83520 | AE5: 87170 | AF5: 90780
B6: Luxury Watches & Jewelery Global Revenue | U6: 122000 | V6: 129300 | W6: 106800 | X6: 122300 | Y6: 129900 | Z6: 150600 | AA6: 157600 | AB6: 166400 | AC6: 175200 | AD6: 183900 | AE6: 192400 | AF6: 200900
B7: Luxury Beauty Products Global Revenue | U7: 58240 | V7: 62100 | W7: 52010 | X7: 59010 | Y7: 64430 | Z7: 63300 | AA7: 68750 | AB7: 71700 | AC7: 74590 | AD7: 77450 | AE7: 80280 | AF7: 83080
B8: Total Market | S8: 249000 | U8: =+SUM(U3:U7) -> 375740 | V8: =+SUM(V3:V7) -> 399550 | W8: =+SUM(W3:W7) -> 338140 | X8: =+SUM(X3:X7) -> 382170 | Y8: =+SUM(Y3:Y7) -> 405920 | Z8: =+SUM(Z3:Z7) -> 454310 | AA8: =+SUM(AA3:AA7) -> 473930 | AB8: =+SUM(AB3:AB7) -> 495150 | ... AF8: =+SUM(AF3:AF7) -> 577750
B9: Kering Revenue in USD | U9: =+U44*Main!$H$19 -> 14621.764 | V9: =+V44*Main!$H$19 -> 16995.345 | W9: =+W44*Main!$H$19 -> 14017.214 | X9: =+X44*Main!$H$19 -> 18880.15 | Y9: =+Y44*Main!$H$19 -> 21775.57 | Z9: =+Z44*Main!$H$19 -> 20935.62 | AA9: =+AA44*Main!$H$19 -> 18397.58 | AB9: =+AB8*AB10 -> 15349.65 | AC9: =+AC8*AC10 -> 17031.96 | AD9: =+AD8*AD10 -> 19866.78 | AE9: =+AE8*AE10 -> 22295.2 | AF9: =+AF8*AF10 -> 26576.5
B10: Market Share in % | U10: =+U9/U8 -> 0.038914579 | V10: =+V9/V8 -> 0.042536216 | W10: =+W9/W8 -> 0.041453877 | X10: =+X9/X8 -> 0.049402491 | Y10: =+Y9/Y8 -> 0.053644979 | Z10: =+Z9/Z8 -> 0.046082235 | AA10: =+AA9/AA8 -> 0.038819193 | AB10: 0.031 | AC10: 0.033 | AD10: 0.037 | AE10: 0.04 | AF10: 0.046
B12: Europe Stores | C12: 349 | D12: =Z12 -> 367 | E12: 378 | F12: =+AA12 -> 379 | G12: 373 | H12: =+AB12 -> 361 | N12: =192+52 -> 244 | O12: =245+83 -> 328 | P12: 288 | Q12: 312 | R12: 326 | S12: 338 | T12: 367 | U12: 305 | V12: 324 | W12: 313 | X12: 330 | Y12: 347 | Z12: 367 | AA12: 379 | AB12: 361 | AC12: 428 | AD12: 448 | AE12: 468 | AF12: 488
B13: North America Stores | C13: 293 | D13: =Z13 -> 316 | E13: 326 | F13: =+AA13 -> 329 | G13: 324 | H13: =+AB13 -> 308 | N13: =142+16 -> 158 | O13: =161+25 -> 186 | P13: 195 | Q13: 206 | R13: 210 | S13: 213 | T13: 219 | U13: 212 | V13: 228 | W13: 229 | X13: 251 | Y13: 278 | Z13: 316 | AA13: 329 | AB13: 308 | AC13: 363 | AD13: 376 | AE13: 393 | AF13: 408
B14: Japan Stores | C14: 238 | D14: =Z14 -> 238 | E14: 232 | F14: =+AA14 -> 241 | G14: 232 | H14: =+AB14 -> 225 | N14: =214+78 -> 292 | O14: =237+94 -> 331 | P14: 224 | Q14: 226 | R14: 237 | S14: 248 | T14: 260 | U14: 213 | V14: 220 | W14: 228 | X14: 233 | Y14: 239 | Z14: 238 | AA14: 241 | AB14: 225 | AC14: 218 | AD14: 214 | AE14: 213 | AF14: 212
B15: Asia Stores (excl. Japan) | C15: 672 | D15: =Z15 -> 698 | E15: 706 | F15: =+AA15 -> 708 | G15: 701 | H15: =+AB15 -> 666 | N15: 0 | O15: 0 | P15: 0 | Q15: 0 | R15: 0 | S15: 0 | T15: 0 | U15: 0 | V15: 0 | W15: 0 | X15: 625 | Y15: 662 | Z15: 698 | AA15: 708 | AB15: 666 | AC15: 751 | AD15: 779 | AE15: 799 | AF15: 819
B16: Rest of World | C16: 142 | D16: =Z16 -> 152 | E16: 159 | F16: =+AA16 -> 156 | G16: 159 | H16: =+AB16 -> 159 | N16: =253+26 -> 279 | O16: =315+42 -> 357 | P16: 389 | Q16: 442 | R16: 491 | S16: 506 | T16: 542 | U16: 548 | V16: 609 | W16: 663 | X16: 120 | Y16: 137 | Z16: 152 | AA16: 156 | AB16: 159 | AC16: 194 | AD16: 209 | AE16: 221 | AF16: 236
B17: Total Stores | C17: =+SUM(C12:C16) -> 1694 | D17: =+SUM(D12:D16) -> 1771 | E17: 1801 | F17: =+AA17 -> 1813 | G17: =+SUM(G12:G16) -> 1789 | H17: =+AB17 -> 1719 | L17: =+SUM(L12:L16) -> 0 | M17: =+SUM(M12:M16) -> 0 | N17: =+SUM(N12:N16) -> 973 | O17: =+SUM(O12:O16) -> 1202 | P17: =+SUM(P12:P16) -> 1096 | Q17: =+SUM(Q12:Q16) -> 1186 | R17: =+SUM(R12:R16) -> 1264 | S17: =+SUM(S12:S16) -> 1305 | ... AF17: =+SUM(AF12:AF16) -> 2163
B18: RPS | C18: =C26/C17 -> 4.6068182 | D18: =D26/D17 -> 4.3151045 | E18: =E26/E17 -> 3.7053415 | F18: =F26/F17 -> 3.5268174 | G18: =G26/G17 -> 3.0958692 | H18: =H26/H17 -> 3.2661373 | L18: =L26/L17 -> #DIV/0! | M18: =M26/M17 -> #DIV/0! | N18: =N26/N17 -> 0 | O18: =O26/O17 -> 0 | P18: =P26/P17 -> 0 | Q18: =Q26/Q17 -> 0 | R18: =R26/R17 -> 6.8735364 | S18: =S26/S17 -> 7.1177586 | ... AF18: =AF26/AF17 -> 9.1864449
B20: Asia Revenue | C20: 3710 | D20: =Z20-C20 -> 3138 | E20: 2897 | F20: =+AA20-E20 -> 2261.2 | G20: 2237 | H20: =+AB20-G20 -> 1967 | N20: 1962 | O20: 2439.9 | P20: 2449.4 | Q20: 2582.8 | R20: 2956.2 | S20: 3203.6 | T20: 4184.8 | U20: 4420.3 | V20: 5421.6 | W20: 4975.7 | X20: 6695.4 | Y20: 6568 | Z20: 6848 | AA20: =30%*AA44 -> 5158.2 | AB20: 4204 | AC20: =38%*AC44 -> 6048.7335 | AD20: =38%*AD44 -> 7055.492 | AE20: =39%*AE44 -> 8126.2879 | AF20: =40%*AF44 -> 9935.1402
B21: Western Europe Revenue | C21: 2739 | D21: =Z21-C21 -> 2666 | E21: 2555 | F21: =+AA21-E21 -> 2431.26 | G21: 2232 | H21: =+AB21-G21 -> 2183 | N21: 2611.8 | O21: 2937.5 | P21: 3022 | Q21: 3125.3 | R21: 3562.4 | S21: 3885.9 | T21: 5077.1 | U21: 4471.5 | V21: 5120.2 | W21: 3657.1 | X21: 4945 | Y21: 5566 | Z21: 5405 | AA21: =29%*AA44 -> 4986.26 | AB21: 4415 | AC21: =26%*AC44 -> 4138.6071 | AD21: =26%*AD44 -> 4827.4419 | AE21: =26%*AE44 -> 5417.5252 | AF21: =26%*AF44 -> 6457.8411
B22: North America Revenue | C22: 2266 | D22: =Z22-C22 -> 2234 | E22: 2057 | F22: =+AA22-E22 -> 2069.56 | G22: 1784 | H22: =+AB22-G22 -> 1765 | N22: 1496.8 | O22: 1983.1 | P22: 2031.6 | Q22: 2146.7 | R22: 2652 | S22: 2740.5 | T22: 3306 | U22: 2704.7 | V22: 3039.7 | W22: 2742.4 | X22: 4685.3 | Y22: 5547 | Z22: 4500 | AA22: =24%*AA44 -> 4126.56 | AB22: 3549 | AC22: =23%*AC44 -> 3661.0755 | AD22: =23%*AD44 -> 4270.4293 | AE22: =23%*AE44 -> 4792.4262 | AF22: =22%*AF44 -> 5464.3271
B23: Japan Revenue | C23: 683 | D23: =Z23-C23 -> 717 | E23: 737 | F23: =+AA23-E23 -> 638.52 | G23: 599 | H23: =+AB23-G23 -> 558 | N23: 983.5 | O23: 1158.4 | P23: 967.8 | Q23: 962.5 | R23: 1101.1 | S23: 1226.3 | T23: 1291.2 | U23: 1157.5 | V23: 1309.8 | W23: 931.1 | X23: 1059.4 | Y23: 1244 | Z23: 1400 | AA23: =8%*AA44 -> 1375.52 | AB23: 1157 | AC23: =5%*AC44 -> 795.88598 | AD23: =5%*AD44 -> 928.35421 | AE23: =5%*AE44 -> 1041.8318 | AF23: =5%*AF44 -> 1241.8925
B24: Rest of the World Revenue | C24: 737 | D24: =Z24-C24 -> 676 | E24: 772 | F24: =+AA24-E24 -> 775.46 | G24: 735 | H24: =+AB24-G24 -> 614 | N24: =540.5+467.9 -> 1008.4 | O24: =685.2+532.2 -> 1217.4 | P24: =709.6+475.3 -> 1184.9 | Q24: =728.5+464.7 -> 1193.2 | R24: =773.7+538.8 -> 1312.5 | S24: =514.3+814.3 -> 1328.6 | T24: =1032.9+594.7 -> 1627.6 | U24: =725.1+186.1 -> 911.2 | V24: =770.2+222.1 -> 992.3 | W24: 793.9 | X24: 1160.1 | Y24: 1425 | Z24: 1413 | AA24: =9%*AA44 -> 1547.46 | AB24: 1349 | AC24: =8%*AC44 -> 1273.4176 | AD24: =8%*AD44 -> 1485.3667 | AE24: =8%*AE44 -> 1666.9308 | AF24: =8%*AF44 -> 1987.028
B26: Store Revenue | C26: =0.77*C44 -> 7803.95 | D26: =Z26-C26 -> 7642.05 | E26: =0.74*E44 -> 6673.32 | F26: =+AA26-E26 -> 6394.12 | G26: =73%*G44 -> 5538.51 | H26: =+AB26-G26 -> 5614.49 | R26: =0.75*R44 -> 8688.15 | S26: =0.75*S44 -> 9288.675 | T26: =0.75*T44 -> 11608.275 | U26: =0.77*U44 -> 10522.204 | V26: =0.78*V44 -> 12389.13 | W26: 9926.8 | X26: 13781.9 | Y26: 16007 | Z26: 15446 | AA26: =76%*AA44 -> 13067.44 | AB26: =76%*AB44 -> 11153 | AC26: =80%*AC44 -> 12734.176 | AD26: =80%*AD44 -> 14853.667 | AE26: =80%*AE44 -> 16669.308 | AF26: =80%*AF44 -> 19870.28
B27: Wholesale Revenue | C27: =0.23*C44 -> 2331.05 | D27: =Z27-C27 -> 1788.95 | E27: =0.26*E44 -> 2344.68 | F27: =+AA27-E27 -> 1781.88 | G27: =27%*G44 -> 2048.49 | H27: =+AB27-G27 -> 1473.51 | R27: =0.75*R45 -> 3382.5 | S27: =0.75*S45 -> 3446.475 | T27: =0.75*T45 -> 4008.525 | U27: =0.23*U44 -> 3142.996 | V27: =0.22*V44 -> 3494.37 | W27: 3173.4 | X27: 3863.3 | Y27: 4344 | Z27: 4120 | AA27: =+AA44-AA26 -> 4126.56 | AB27: =+AB44*0.24 -> 3522 | AC27: =+AC44-AC26 -> 3183.5439 | AD27: =+AD44-AD26 -> 3713.4168 | AE27: =+AE44-AE26 -> 4167.3271 | AF27: =+AF44-AF26 -> 4967.5701
B29: Gucci Stores | C29: 536 | D29: =Z29 -> 538 | E29: 536 | F29: =+AA29 -> 529 | G29: 511 | H29: =+AB29 -> 497 | K29: 258 | M29: 317 | O29: 429 | Q29: 505 | S29: 520 | T29: 529 | U29: 469 | V29: 487 | W29: 483 | X29: 501 | Y29: 528 | Z29: 538 | AA29: 529 | AB29: 497 | AC29: 550 | AD29: 560 | AE29: 570 | AF29: 580
B30: Gucci RPS | C30: =C38*0.91/C29 -> 8.7061194 | D30: =D38*0.91/D29 -> 8.0259294 | E30: =E38*0.9/E29 -> 6.8591418 | F30: =0.85*F38/F29 -> 5.7282609 | G30: =0.91*G38/G29 -> 5.3905479 | H30: =0.91*H38/H29 -> 5.4288732 | N30: =0.85*N38/N29 -> #DIV/0! | O30: =0.85*O38/O29 -> 7.2101399 | P30: =0.85*P38/P29 -> #DIV/0! | Q30: =0.85*Q38/Q29 -> 5.8863762 | R30: =0.85*R38/R29 -> #DIV/0! | S30: =0.85*S38/S29 -> 7.1568365 | T30: =0.85*T38/T29 -> 9.9798677 | U30: =0.85*U38/U29 -> 15.015458 | V30: =0.85*V38/V29 -> 16.805216 | W30: =0.87*W38/W29 -> 13.402323 | X30: =0.91*X38/X29 -> 17.67507 | Y30: =0.91*Y38/Y29 -> 18.074186 | Z30: =0.91*Z38/Z29 -> 16.699684 | AA30: =0.91*AA38/AA29 -> 13.159735 | AB30: =0.92*AB38/AB29 -> 11.091831 | AC30: =0.91*AC38/AC29 -> 12.114832 | AD30: =0.91*AD38/AD29 -> 13.275465 | AE30: =0.91*AE38/AE29 -> 13.971512 | AF30: =0.91*AF38/AF29 -> 15.97759
B31: Saint Laurent Stores | C31: 288 | D31: =Z31 -> 308 | E31: 320 | F31: =+AA31 -> 318 | G31: 317 | H31: =+AB31 -> 312 | K31: 64 | M31: 78 | O31: 89 | Q31: 128 | S31: 159 | T31: 184 | U31: 194 | V31: 222 | W31: 239 | X31: 268 | Y31: 280 | Z31: 308 | AA31: 318 | AB31: 312 | AC31: 350 | AD31: 367 | AE31: 386 | AF31: 405
B32: Saint Laurent RPS | C32: =+C39*0.8/C31 -> 4.3777778 | D32: =+D39*0.81/D31 -> 4.2156818 | E32: =+E39*0.81/E31 -> 3.6475313 | F32: =0.69*F39/F31 -> 3.1245283 | G32: =0.8*G39/G31 -> 3.2504732 | H32: =0.8*H39/H31 -> 3.474359 | N32: =0.69*N39/N31 -> #DIV/0! | O32: =0.69*O39/O31 -> 3.6670787 | P32: =0.69*P39/P31 -> #DIV/0! | Q32: =0.69*Q39/Q31 -> 3.8127891 | R32: =0.69*R39/R31 -> #DIV/0! | S32: =0.69*S39/S31 -> 5.2952075 | T32: =0.69*T39/T31 -> 5.6325 | U32: =0.68*U39/U31 -> 6.1129897 | V32: =0.69*V39/V31 -> 6.3688243 | W32: =0.69*W39/W31 -> 5.0361339 | X32: =0.74*X39/X31 -> 6.9609701 | Y32: =0.77*Y39/Y31 -> 9.075 | Z32: =0.81*Z39/Z31 -> 8.3603571 | AA32: =0.82*AA39/AA31 -> 7.4289937 | AB32: =0.81*AB39/AB31 -> 6.8616346 | AC32: =0.81*AC39/AC31 -> 6.2624857 | AD32: =0.81*AD39/AD31 -> 6.9664509 | AE32: =0.81*AE39/AE31 -> 7.4331728 | AF32: =0.81*AF39/AF31 -> 8.9416262
B33: Bottega Stores | C33: 279 | D33: 288 | E33: 301 | F33: =+AA33 -> 307 | G33: 302 | H33: =+AB33 -> 297 | K33: 121 | M33: 148 | O33: 196 | Q33: 236 | S33: 255 | T33: 270 | U33: 255 | V33: 268 | W33: 261 | X33: 263 | Y33: 271 | Z33: 288 | AA33: 307 | AB33: 297 | AC33: 330 | AD33: 342 | AE33: 354 | AF33: 364
B34: Bottega RPS | C34: =+C40*0.8/C33 -> 2.3885305 | D34: =+D40*0.84/D33 -> 2.3683333 | E34: =+E40*0.84/E33 -> 2.3330233 | F34: =0.83*F40/F33 -> 2.3710423 | G34: =0.85*G40/G33 -> 2.3811258 | H34: =0.85*H40/H33 -> 2.4612795 | N34: =0.83*N40/N33 -> #DIV/0! | O34: =0.83*O40/O33 -> 4.0017857 | P34: =0.83*P40/P33 -> #DIV/0! | Q34: =0.83*Q40/Q33 -> 3.975911 | R34: =0.83*R40/R33 -> #DIV/0! | S34: =0.83*S40/S33 -> 3.819302 | T34: =0.83*T40/T33 -> 3.6151111 | U34: =0.82*U40/U33 -> 3.5661961 | V34: =0.81*V40/V33 -> 3.5289403 | W34: =0.73*W40/W33 -> 3.3851303 | X34: =0.75*X40/X33 -> 4.2861217 | Y34: =0.78*Y40/Y33 -> 5.0081181 | Z34: =0.82*Z40/Z33 -> 4.6836806 | AA34: =0.85*AA40/AA33 -> 4.7428339 | AB34: =0.86*AB40/AB33 -> 4.9399327 | AC34: =0.82*AC40/AC33 -> 2.7687185 | AD34: =0.82*AD40/AD33 -> 3.1162299 | AE34: =0.82*AE40/AE33 -> 2.8959392 | AF34: =0.82*AF40/AF33 -> 3.357204
B35: Other Houes Stores | C35: 591 | D35: 618 | E35: 625 | F35: =+AA35 -> 640 | G35: 622 | H35: =+AB35 -> 613 | K35: 117 | M35: 141 | O35: 244 | Q35: 317 | S35: 371 | T35: 405 | U35: 360 | V35: 404 | W35: 450 | X35: 533 | Y35: 584 | Z35: 618 | AA35: 640 | AB35: 613 | AC35: 680 | AD35: 705 | AE35: 730 | AF35: 755
B36: Other Houes RPS | C36: =C41*0.68/C35 -> 2.1354992 | D36: =D41*0.73/D35 -> 1.958479 | E36: =E41*0.73/E35 -> 2.005456 | F36: =F41*0.73/F35 -> 1.7155 | G36: =G41*0.76/G35 -> 1.782701 | H36: =H41*0.76/H35 -> 1.7865579 | N36: =0.45*N41/N35 -> #DIV/0! | O36: =0.45*O41/O35 -> 2.1319672 | P36: =0.45*P41/P35 -> #DIV/0! | Q36: =0.45*Q41/Q35 -> 2.0208833 | R36: =0.45*R41/R35 -> #DIV/0! | S36: =0.45*S41/S35 -> 2.0589623 | T36: =0.45*T41/T35 -> 1.8044444 | U36: =0.51*U41/U35 -> 2.98775 | V36: =0.56*V41/V35 -> 3.5173267 | W36: =0.58*W41/W35 -> 2.9403422 | X36: =0.59*X41/X35 -> 3.6363039 | Y36: =0.66*Y41/Y35 -> 4.3781507 | Z36: =0.72*Z41/Z35 -> 4.0939806 | AA36: =0.75*AA41/AA35 -> 3.7746094 | AB36: =0.77*AB41/AB35 -> 3.6427406 | AC36: =0.72*AC41/AC35 -> 3.3708112 | AD36: =0.72*AD41/AD35 -> 3.7924257 | AE36: =0.72*AE41/AE35 -> 4.1102404 | AF36: =0.72*AF41/AF35 -> 4.7372854
B38: Gucci | C38: 5128 | D38: =Z38-C38 -> 4745 | E38: 4085 | F38: =+AA38-E38 -> 3565 | G38: 3027 | H38: =+AB38-G38 -> 2965 | K38: 2206 | M38: 2666 | N38: 3143.2 | O38: 3639 | P38: 3560.8 | Q38: 3497.2 | R38: 3898 | S38: 4378.3 | T38: 6211 | U38: 8285 | V38: 9628.4 | W38: 7440.6 | X38: 9731 | Y38: 10487 | Z38: 9873 | AA38: 7650 | AB38: 5992 | AC38: =+AC44*46% -> 7322.151 | AD38: =+AD44*44% -> 8169.517 | AE38: =+AE44*42% -> 8751.3869 | AF38: =+AF44*41% -> 10183.519
B39: Yves Saint Laurent | C39: 1576 | D39: =Z39-C39 -> 1603 | E39: 1441 | F39: =+AA39-E39 -> 1440 | G39: 1288 | H39: =+AB39-G39 -> 1355 | K39: 263 | M39: 269 | N39: 682.6 | O39: 473 | P39: 1015.8 | Q39: 707.3 | R39: 973.6 | S39: 1220.2 | T39: 1502 | U39: 1744 | V39: 2049.1 | W39: 1744.4 | X39: 2521 | Y39: 3300 | Z39: 3179 | AA39: 2881 | AB39: 2643 | AC39: =+AC44*17% -> 2706.0123 | AD39: =+AD44*17% -> 3156.4043 | AE39: =+AE44*17% -> 3542.228 | AF39: =+AF44*18% -> 4470.8131
B40: Bottega Veneta | C40: 833 | D40: =Z40-C40 -> 812 | E40: 836 | F40: =+AA40-E40 -> 877 | G40: 846 | H40: =+AB40-G40 -> 860 | K40: 402 | M40: 511 | N40: 353.7 | O40: 945 | P40: 556.9 | Q40: 1130.5 | R40: 1285.8 | S40: 1173.4 | T40: 1176 | U40: 1109 | V40: 1167.6 | W40: 1210.3 | X40: 1503 | Y40: 1740 | Z40: 1645 | AA40: 1713 | AB40: 1706 | AC40: =+AC44*7% -> 1114.2404 | AD40: =+AD44*7% -> 1299.6959 | AE40: =+AE44*6% -> 1250.1981 | AF40: =+AF44*6% -> 1490.271
B41: Other Houeses | C41: 1856 | D41: =Z41-C41 -> 1658 | E41: 1717 | F41: =+AA41-E41 -> 1504 | G41: 1459 | H41: =+AB41-G41 -> 1441 | K41: 509 | M41: 565 | N41: 737.5 | O41: 1156 | P41: 1244 | Q41: 1423.6 | R41: 1707.9 | S41: 1697.5 | T41: 1624 | U41: 2109 | V41: 2537.5 | W41: 2281.3 | X41: 3285 | Y41: 3874 | Z41: 3514 | AA41: 3221 | AB41: 2900 | AC41: =20%*AC44 -> 3183.5439 | AD41: =20%*AD44 -> 3713.4168 | AE41: =20%*AE44 -> 4167.3271 | AF41: =20%*AF44 -> 4967.5701
B42: Kering Eyewear and Corporate | C42: 869 | D42: =Z42-C42 -> 699 | E42: 1067 | F42: =+AA42-E42 -> 874 | G42: 1092 | H42: =+AB42-G42 -> 539 | N42: 3155.7 | O42: =3532+261 -> 3793 | P42: =3001.9+245.1+31.2 -> 3278.2 | Q42: =3245.1+33.8 -> 3278.9 | R42: =3403.4+279.1+36.4 -> 3718.9 | S42: =3883.7+31.8 -> 3915.5 | T42: 302.1 | U42: 418.2 | V42: 500.9 | W42: 423.6 | X42: 733 | Y42: 1139 | Z42: 1568 | AA42: 1941 | AB42: 1631 | AC42: =+AC44*15% -> 2387.6579 | AD42: =+AD44*16% -> 2970.7335 | AE42: =+AE44*16% -> 3333.8617 | AF42: =+AF44*16% -> 3974.0561
B43: Elminations | C43: -127 | D43: =Z43-C43 -> -86 | E43: -128 | F43: =+AA43-E43 -> -84 | G43: -125 | H43: =+AB43-G43 -> -72 | N43: -10.4 | O43: -7.9 | P43: 0 | Q43: 0 | R43: 0 | S43: 0 | T43: 0 | U43: 0 | V43: 0 | W43: 0 | X43: -128 | Y43: -189 | Z43: -213 | AA43: -212 | AB43: -197 | AC43: =-1%*AC44 -> -159.1772 | AD43: =-1%*AD44 -> -185.67084 | AE43: =-1%*AE44 -> -208.36636 | AF43: =-1%*AF44 -> -248.3785
B44: Total Revenue | C44: =SUM(C38:C43) -> 10135 | D44: =SUM(D38:D43) -> 9431 | E44: =SUM(E38:E43) -> 9018 | F44: =SUM(F38:F43) -> 8176 | G44: 7587 | H44: =SUM(H38:H43) -> 7088 | J44: 19098.2 | K44: 20201.2 | L44: 13584.3 | M44: 14605.1 | N44: 8062.3 | O44: 9736.3 | P44: 9655.7 | Q44: 10037.5 | R44: 11584.2 | S44: 12384.9 | T44: 15477.7 | U44: =SUM(U38:U43) -> 13665.2 | V44: =SUM(V38:V43) -> 15883.5 | W44: =SUM(W38:W43) -> 13100.2 | X44: =SUM(X38:X43) -> 17645 | Y44: =SUM(Y38:Y43) -> 20351 | Z44: =SUM(Z38:Z43) -> 19566 | AA44: =SUM(AA38:AA43) -> 17194 | AB44: 14675 | AC44: =+AC9/Main!$H$19 -> 15917.72 | AD44: =+AD9/Main!$H$19 -> 18567.084 | AE44: =+AE9/Main!$H$19 -> 20836.636 | AF44: =+AF9/Main!$H$19 -> 24837.85
B45: COGS | C45: 2405 | D45: =Z45-C45 -> 2234 | E45: 2310 | F45: =+AA45-E45 -> 2203 | G45: 2048 | H45: =+AB45-G45 -> 1967 | J45: 10792.8 | K45: 11385.9 | L45: 6900.7 | M45: 7175.9 | N45: 3086.5 | O45: 3776.2 | P45: 3615.2 | Q45: 3741.7 | R45: 4510 | S45: 4595.3 | T45: 5344.7 | U45: 3467 | V45: 4108.5 | W45: 3590.6 | X45: 4577 | Y45: 5153 | Z45: 4639 | AA45: 4513 | AB45: 4015
...

Sheet Quart
A1: Main
C2: Q122 | D2: Q222 | E2: Q322 | F2: Q422 | G2: Q123 | H2: Q223 | I2: Q323 | J2: Q423 | K2: Q124 | L2: Q224 | M2: Q324 | N2: Q424 | O2: Q125 | P2: Q225 | Q2: Q325 | R2: Q425 | S2: Q126 | T2: Q226 | U2: Q326 | V2: Q426
A3: x | B3: Revenues:
B4: Gucci | C4: 2591 | D4: 2582 | E4: 2581 | F4: =+Model!Y38-SUM(Quart!C4:E4) -> 2733 | G4: 2616 | H4: 2512 | I4: 2217 | J4: =+Model!Z38-SUM(Quart!G4:I4) -> 2528 | K4: 2079 | L4: 2006 | M4: 1641 | N4: 1924 | O4: 1571 | P4: =+Model!G38-Quart!O4 -> 1456 | Q4: 1343 | R4: =+Model!AB38-SUM(O4:Q4) -> 1622 | S4: 1347
B5: Saint Laurent | C5: 739 | D5: 742 | E5: 916 | F5: =+Model!Y39-SUM(Quart!C5:E5) -> 903 | G5: 806 | H5: 770 | I5: 768 | J5: =+Model!Z39-SUM(Quart!G5:I5) -> 835 | K5: 740 | L5: 701 | M5: 670 | N5: 770 | O5: 679 | P5: =+Model!G39-Quart!O5 -> 609 | Q5: 620 | R5: =+Model!AB39-SUM(O5:Q5) -> 735 | S5: n.a.
B6: Bottega Venetta | C6: 396 | D6: 438 | E6: 437 | F6: =+Model!Y40-SUM(Quart!C6:E6) -> 469 | G6: 395 | H6: 438 | I6: 381 | J6: =+Model!Z40-SUM(Quart!G6:I6) -> 431 | K6: 388 | L6: 448 | M6: 397 | N6: 480 | O6: 405 | P6: =+Model!G40-Quart!O6 -> 441 | Q6: 393 | R6: =+Model!AB40-SUM(O6:Q6) -> 467 | S6: n.a.
B7: Other Houses | C7: 973 | D7: 982 | E7: 995 | F7: =+Model!Y41-SUM(Quart!C7:E7) -> 924 | G7: 890 | H7: 966 | I7: 805 | J7: =+Model!Z41-SUM(Quart!G7:I7) -> 853 | K7: 824 | L7: 893 | M7: 686 | N7: 818 | O7: 733 | P7: =+Model!G41-Quart!O7 -> 726 | Q7: 652 | R7: =+Model!AB41-SUM(O7:Q7) -> 789 | S7: n.a.
B8: Kering Eyewear | C8: 308 | D8: 283 | E8: 253 | F8: =+Model!Y42-SUM(Quart!C8:E8) -> 295 | G8: 433 | H8: 436 | I8: 333 | J8: =+Model!Z42-SUM(Quart!G8:I8) -> 366 | K8: 536 | L8: 531 | M8: 440 | N8: 434 | O8: 558 | P8: =+Model!G42-Quart!O8 -> 534 | Q8: 448 | R8: =+Model!AB42-SUM(O8:Q8) -> 91 | S8: 489
B9: Eliminations | C9: -51 | D9: -53 | E9: -45 | F9: =+Model!Y43-SUM(Quart!C9:E9) -> -40 | G9: -63 | H9: -64 | I9: -40 | J9: =+Model!Z43-SUM(Quart!G9:I9) -> -46 | K9: -63 | L9: -65 | M9: -48 | N9: -36 | O9: -63 | P9: =+Model!G43-Quart!O9 -> -62 | Q9: -41 | R9: =+Model!AB43-SUM(O9:Q9) -> -31 | S9: -72
B10: Revenue | C10: =+SUM(C4:C9) -> 4956 | D10: =+SUM(D4:D9) -> 4974 | E10: =+SUM(E4:E9) -> 5137 | F10: =+SUM(F4:F9) -> 5284 | G10: =+SUM(G4:G9) -> 5077 | H10: =+SUM(H4:H9) -> 5058 | I10: =+SUM(I4:I9) -> 4464 | J10: =+SUM(J4:J9) -> 4967 | ... O10: =+SUM(O4:O9) -> 3883 | P10: 3704 | Q10: 3415 | R10: =+SUM(R4:R9) -> 3673 | S10: 3568
A12: x | B12: Growth | G12: =+G4/C4-1 -> 0.0096487843 | H12: =+H4/D4-1 -> -0.027110767 | I12: =+I4/E4-1 -> -0.14103061 | J12: =+J4/F4-1 -> -0.075009147 | K12: =+K4/G4-1 -> -0.20527523 | L12: =+L4/H4-1 -> -0.20143312 | M12: =+M4/I4-1 -> -0.25981055 | N12: =+N4/J4-1 -> -0.23892405 | ... S12: =+S4/O4-1 -> -0.14258434
B13: Gucci | G13: =+G5/C5-1 -> 0.090663058 | H13: =+H5/D5-1 -> 0.037735849 | I13: =+I5/E5-1 -> -0.16157205 | J13: =+J5/F5-1 -> -0.07530454 | K13: =+K5/G5-1 -> -0.081885856 | L13: =+L5/H5-1 -> -0.08961039 | M13: =+M5/I5-1 -> -0.12760417 | N13: =+N5/J5-1 -> -0.077844311 | ... R13: =+R5/N5-1 -> -0.045454545 | S13: n.a.
B14: Saint Laurent | G14: =+G6/C6-1 -> -0.0025252525 | H14: =+H6/D6-1 -> 0 | I14: =+I6/E6-1 -> -0.12814645 | J14: =+J6/F6-1 -> -0.081023454 | K14: =+K6/G6-1 -> -0.017721519 | L14: =+L6/H6-1 -> 0.02283105 | M14: =+M6/I6-1 -> 0.041994751 | N14: =+N6/J6-1 -> 0.1136891 | ... R14: =+R6/N6-1 -> -0.027083333 | S14: n.a.
B15: Bottega Venetta | G15: =+G7/C7-1 -> -0.085303186 | H15: =+H7/D7-1 -> -0.016293279 | I15: =+I7/E7-1 -> -0.19095477 | J15: =+J7/F7-1 -> -0.076839827 | K15: =+K7/G7-1 -> -0.074157303 | L15: =+L7/H7-1 -> -0.075569358 | M15: =+M7/I7-1 -> -0.14782609 | N15: =+N7/J7-1 -> -0.041031653 | ... R15: =+R7/N7-1 -> -0.035452323 | S15: n.a.
B16: Other Houses | G16: =+G8/C8-1 -> 0.40584416 | H16: =+H8/D8-1 -> 0.54063604 | I16: =+I8/E8-1 -> 0.31620553 | J16: =+J8/F8-1 -> 0.24067797 | K16: =+K8/G8-1 -> 0.23787529 | L16: =+L8/H8-1 -> 0.21788991 | M16: =+M8/I8-1 -> 0.32132132 | N16: =+N8/J8-1 -> 0.18579235 | ... S16: =+S8/O8-1 -> -0.12365591
B17: Kering Eyewear | G17: =+G9/C9-1 -> 0.23529412 | H17: =+H9/D9-1 -> 0.20754717 | I17: =+I9/E9-1 -> -0.11111111 | J17: =+J9/F9-1 -> 0.15 | K17: =+K9/G9-1 -> 0 | L17: =+L9/H9-1 -> 0.015625 | M17: =+M9/I9-1 -> 0.2 | N17: =+N9/J9-1 -> -0.2173913 | ... S17: =+S9/O9-1 -> 0.14285714
B18: Revenue | G18: =+G10/C10-1 -> 0.024414851 | H18: =+H10/D10-1 -> 0.016887817 | I18: =+I10/E10-1 -> -0.13101032 | J18: =+J10/F10-1 -> -0.05999243 | K18: =+K10/G10-1 -> -0.11286193 | L18: =+L10/H10-1 -> -0.10755239 | M18: =+M10/I10-1 -> -0.15188172 | N18: =+N10/J10-1 -> -0.1161667 | ... S18: =+S10/O10-1 -> -0.081122843

Sheet Ratios
A1: Main
B2: Ratios | C2: 17 | D2: 18 | E2: =+D2+1 -> 19 | F2: =+E2+1 -> 20 | G2: =+F2+1 -> 21 | H2: =+G2+1 -> 22 | I2: =+H2+1 -> 23 | J2: =+I2+1 -> 24 | K2: =+J2+1 -> 25 | N2: Average | O2: Median
B3: Price | C3: 364.34 | D3: 400.8 | E3: 585.7 | F3: 587.9 | G3: 706.9 | H3: 480 | I3: 400.1 | J3: 230.2 | K3: 284.8 | N3: =+AVERAGE(C3:J3) -> 469.4925 | O3: =+MEDIAN(C3:J3) -> 440.4
B4: Shares o/s | C4: =Model!T69 -> 125.99951 | D4: =Model!U69 -> 125.95604 | E4: =Model!V69 -> 125.49877 | F4: =Model!W69 -> 125.01194 | G4: =Model!X69 -> 124.58451 | H4: =Model!Y69 -> 122.38293 | I4: =Model!Z69 -> 122.34649 | J4: 122.58444 | K4: =+Model!AB69 -> 122.60481 | N4: =+AVERAGE(C4:J4) -> 124.29558 | O4: =+MEDIAN(C4:J4) -> 124.79823
B5: Market Cap | C5: =+C3*C4 -> 45906.662 | D5: =+D3*D4 -> 50483.18 | E5: =+E3*E4 -> 73504.627 | F5: =+F3*F4 -> 73494.522 | G5: =+G3*G4 -> 88068.789 | H5: =+H3*H4 -> 58743.806 | I5: =+I3*I4 -> 48950.832 | J5: =+J3*J4 -> 28218.937 | K5: =+K3*K4 -> 34917.85 | N5: =+AVERAGE(C5:J5) -> 58421.42 | O5: =+MEDIAN(C5:J5) -> 54613.493
B6: Net Debt | C6: =+Model!T110+Model!T112+Model!T118+Model!T120-Model!T103-Model!T101 -> 3261.3 | D6: =+Model!U110+Model!U112+Model!U118+Model!U120-Model!U103-Model!U101 -> 1667.6 | E6: =+Model!V110+Model!V112+Model!V118+Model!V120-Model!V103-Model!V101 -> 3318.8 | F6: =+Model!W110+Model!W112+Model!W118+Model!W120-Model!W103-Model!W101 -> 2408.2 | G6: =+Model!X110+Model!X112+Model!X118+Model!X120-Model!X103-Model!X101 -> 871 | H6: =+Model!Y110+Model!Y112+Model!Y118+Model!Y120-Model!Y103-Model!Y101 -> 2802 | I6: =+Model!Z110+Model!Z112+Model!Z118+Model!Z120-Model!Z103-Model!Z101 -> 8969 | J6: =+Main!H6-Main!H5 -> 8249 | K6: =+Model!AB110+Model!AB112+Model!AB118+Model!AB120-Model!AB103-Model!AB101 -> 8147 | N6: =+AVERAGE(C6:J6) -> 3943.3625 | O6: =+MEDIAN(C6:J6) -> 3031.65
B7: EV | C7: =+C6+C5 -> 49167.962 | D7: =+D6+D5 -> 52150.78 | E7: =+E6+E5 -> 76823.427 | F7: =+F6+F5 -> 75902.722 | G7: =+G6+G5 -> 88939.789 | H7: =+H6+H5 -> 61545.806 | I7: =+I6+I5 -> 57919.832 | J7: =+J6+J5 -> 36467.937 | K7: =+K6+K5 -> 43064.85 | N7: =+AVERAGE(C7:J7) -> 62364.782 | O7: =+MEDIAN(C7:J7) -> 59732.819
A9: x | B9: Value Driver
B10: Capital Emloyed | C10: =+Model!T97+SUM(Model!T98:T102)-Model!T121-SUM(Model!T119,Model!T121:T125) -> 17744.8 | D10: =+Model!U97+SUM(Model!U98:U102)-Model!U121-SUM(Model!U119,Model!U121:U125) -> 12765.1 | E10: =+Model!V97+SUM(Model!V98:V102)-Model!V121-SUM(Model!V119,Model!V121:V125) -> 18379.1 | F10: =+Model!W97+SUM(Model!W98:W102)-Model!W121-SUM(Model!W119,Model!W121:W125) -> 19275.6 | G10: =+Model!X97+SUM(Model!X98:X102)-Model!X121-SUM(Model!X119,Model!X121:X125) -> 18468 | H10: =+Model!Y97+SUM(Model!Y98:Y102)-Model!Y121-SUM(Model!Y119,Model!Y121:Y125) -> 21794 | I10: =+Model!Z97+SUM(Model!Z98:Z102)-Model!Z121-SUM(Model!Z119,Model!Z121:Z125) -> 29602 | J10: =+Model!AA97+SUM(Model!AA98:AA102)-Model!AA121-SUM(Model!AA119,Model!AA121:AA125) -> 30885 | K10: =+Model!AB97+SUM(Model!AB98:AB102)-Model!AB121-SUM(Model!AB119,Model!AB121:AB125) -> 24208 | N10: =+AVERAGE(C10:I10) -> 19718.371 | O10: =+MEDIAN(C10:I10) -> 18468 | Q10: =Long Term Assets + Working Capital (Exclusive of cash)-Accounts Payables
B11: Invested Capital | C11: =+Model!T92+Model!T89+Model!T90+Model!T95+SUM(Model!T98:T102)-SUM(Model!T121:T125) -> 18537.2 | D11: =+Model!U92+Model!U89+Model!U90+Model!U95+SUM(Model!U98:U102)-SUM(Model!U121:U125) -> 12065.7 | E11: =+Model!V92+Model!V89+Model!V90+Model!V95+SUM(Model!V98:V102)-SUM(Model!V121:V125) -> 14078.6 | F11: =+Model!W92+Model!W89+Model!W90+Model!W95+SUM(Model!W98:W102)-SUM(Model!W121:W125) -> 14780.6 | G11: =+Model!X92+Model!X89+Model!X90+Model!X95+SUM(Model!X98:X102)-SUM(Model!X121:X125) -> 15492 | H11: =+Model!Y92+Model!Y89+Model!Y90+Model!Y95+SUM(Model!Y98:Y102)-SUM(Model!Y121:Y125) -> 19028 | I11: =+Model!Z92+Model!Z89+Model!Z90+Model!Z95+SUM(Model!Z98:Z102)-SUM(Model!Z121:Z125) -> 25400 | J11: =+Model!AA92+Model!AA89+Model!AA90+Model!AA95+SUM(Model!AA98:AA102)-SUM(Model!AA121:AA125) -> 26138 | K11: =+Model!AB92+Model!AB89+Model!AB90+Model!AB95+SUM(Model!AB98:AB102)-SUM(Model!AB121:AB125) -> 19014 | N11: =+AVERAGE(C11:I11) -> 17054.586 | O11: =+MEDIAN(C11:I11) -> 15492 | Q11: =Net Working Capital + PP&E + Other Net Operating Assets (net of Liabilties) + (Intangibles)
B12: Invested Capital (excl. Intangibles) | C12: =+Model!T92+Model!T95+SUM(Model!T98:T102)-SUM(Model!T121:T125) -> 3957 | D12: =+Model!U92+Model!U95+SUM(Model!U98:U102)-SUM(Model!U121:U125) -> 2272.9 | E12: =+Model!V92+Model!V95+SUM(Model!V98:V102)-SUM(Model!V121:V125) -> 4292.2 | F12: =+Model!W92+Model!W95+SUM(Model!W98:W102)-SUM(Model!W121:W125) -> 5342.6 | G12: =+Model!X92+Model!X95+SUM(Model!X98:X102)-SUM(Model!X121:X125) -> 5569 | H12: =+Model!Y92+Model!Y95+SUM(Model!Y98:Y102)-SUM(Model!Y121:Y125) -> 7618 | I12: =+Model!Z92+Model!Z95+SUM(Model!Z98:Z102)-SUM(Model!Z121:Z125) -> 10110 | J12: =+Model!AA92+Model!AA95+SUM(Model!AA98:AA102)-SUM(Model!AA121:AA125) -> 10574 | K12: =+Model!AB92+Model!AB95+SUM(Model!AB98:AB102)-SUM(Model!AB121:AB125) -> 7386 | N12: =+AVERAGE(C12:I12) -> 5594.5286 | O12: =+MEDIAN(C12:I12) -> 5342.6
B13: Total Funds Invested | C13: =+C11+Model!T91+Model!T93+Model!T96+Model!T103 -> 20757.8 | D13: =+D11+Model!U91+Model!U93+Model!U96+Model!U103 -> 15930.3 | E13: =+E11+Model!V91+Model!V93+Model!V96+Model!V103 -> 21741.4 | F13: =+F11+Model!W91+Model!W93+Model!W96+Model!W103 -> 22234.5 | G13: =+G11+Model!X91+Model!X93+Model!X96+Model!X103 -> 25099 | H13: =+H11+Model!Y91+Model!Y93+Model!Y96+Model!Y103 -> 28350 | I13: =+I11+Model!Z91+Model!Z93+Model!Z96+Model!Z103 -> 36072 | J13: =+J11+Model!AA91+Model!AA93+Model!AA96+Model!AA103 -> 37060 | K13: =+K11+Model!AB91+Model!AB93+Model!AB96+Model!AB103 -> 31066 | N13: =+AVERAGE(C13:I13) -> 24312.143 | O13: =+MEDIAN(C13:I13) -> 22234.5 | Q13: Invested Capital + Non-Operating Assets
B14: NOPAT | C14: =+Model!T56*(1-Model!T86) -> 2240.8246 | D14: =+Model!U56*(1-Model!U86) -> 2969.9987 | E14: =+Model!V56*(1-Model!V86) -> 2407.4285 | F14: =+Model!W56*(1-Model!W86) -> 2330.1116 | G14: =+Model!X56*(1-Model!X86) -> 3597.0692 | H14: =+Model!Y56*(1-Model!Y86) -> 4043.4537 | I14: =+Model!Z56*(1-Model!Z86) -> 3442.0553 | J14: =+Model!AA56*(1-Model!AA86) -> 1860.5995 | K14: =+Model!AB56*(1-Model!AB86) -> 356.44371 | N14: =+AVERAGE(C14:I14) -> 3004.4202 | O14: =+MEDIAN(C14:I14) -> 2969.9987 | Q14: EBITA * (1-Marginal Tax Rate)
B15: Net Investment | D15: =+D12-C12 -> -1684.1 | E15: =+E12-D12 -> 2019.3 | F15: =+F12-E12 -> 1050.4 | G15: =+G12-F12 -> 226.4 | H15: =+H12-G12 -> 2049 | I15: =+I12-H12 -> 2492 | J15: =+J12-I12 -> 464 | K15: =+K12-J12 -> -3188 | N15: =+AVERAGE(C15:I15) -> 1025.5 | O15: =+MEDIAN(C15:I15) -> 1534.85 | Q15: =Invested Capital (t+1)-Invested Capital (t)
B16: FCF | D16: =+D14-D15+Model!U132+Model!U133 -> 5139.3987 | E16: =+E14-E15+Model!V132+Model!V133 -> 1241.0285 | F16: =+F14-F15+Model!W132+Model!W133 -> 2435.9116 | G16: =+G14-G15+Model!X132+Model!X133 -> 4841.6692 | H16: =+H14-H15+Model!Y132+Model!Y133 -> 3326.4537 | I16: =+I14-I15+Model!Z132+Model!Z133 -> 2867.0553 | J16: =+J14-J15+Model!AA132+Model!AA133 -> 3566.5995 | K16: =+K14-K15+Model!AB132+Model!AB133 -> 5725.4437 | N16: =+AVERAGE(C16:I16) -> 3308.5862 | O16: =+MEDIAN(C16:I16) -> 3096.7545 | Q16: =NOPAT + non-cash Expenses - Investments in Invested Capital
B17: Investment Rate | C17: =C15/C14 -> 0 | D17: =D15/D14 -> -0.56703729 | E17: =E15/E14 -> 0.8387788 | F17: =F15/F14 -> 0.45079386 | G17: =G15/G14 -> 0.062940129 | H17: =H15/H14 -> 0.50674501 | I17: =I15/I14 -> 0.72398605 | J17: =J15/J14 -> 0.24938198 | K17: =K15/K14 -> -8.9439087 | N17: =+AVERAGE(C17:I17) -> 0.28802951 | O17: =+MEDIAN(C17:I17) -> 0.45079386 | Q17: =Net Investment/NOPAT
B18: Economic Profit | E18: =+E11*(E24-DCF!$O$18) -> 1325.7071 | F18: =+F11*(F24-DCF!$O$18) -> 1056.5376 | G18: =+G11*(G24-DCF!$O$18) -> 2287.3196 | H18: =+H11*(H24-DCF!$O$18) -> 2745.1184 | I18: =+I11*(I24-DCF!$O$18) -> 1649.7254 | J18: =+J11*(J24-DCF!$O$18) -> -465.17756 | K18: =+K11*(K24-DCF!$O$18) -> -1411.0553 | N18: =+AVERAGE(C18:I18) -> 1812.8816 | O18: =+MEDIAN(C18:I18) -> 1649.7254 | Q18: =Invested Capital *(ROIC-WACC)
A20: x | B20: Efficency-Ratios
B21: Capital Turnover | C21: =+Model!T44/Model!T128 -> 0.60513187 | D21: =+Model!U44/Model!U128 -> 0.639532 | E21: =+Model!V44/Model!V128 -> 0.58506641 | F21: =+Model!W44/Model!W128 -> 0.46777407 | G21: =+Model!X44/Model!X128 -> 0.56794773 | H21: =+Model!Y44/Model!Y128 -> 0.5995993 | I21: =+Model!Z44/Model!Z128 -> 0.47298571 | J21: =+Model!AA44/Model!AA128 -> 0.39666867 | K21: =+Model!AB44/Model!AB128 -> 0.35634501 | N21: =+AVERAGE(C21:I21) -> 0.56257673 | O21: =+MEDIAN(C21:I21) -> 0.58506641 | Q21: =Revenue/Total Assets
B22: Return on Equity (ROE) | D22: =+Model!U66/AVERAGE(Model!T107:U107) -> 0.33997282 | E22: =+Model!V66/AVERAGE(Model!U107:V107) -> 0.22875545 | F22: =+Model!W66/AVERAGE(Model!V107:W107) -> 0.19461514 | G22: =+Model!X66/AVERAGE(Model!W107:X107) -> 0.25236909 | H22: =+Model!Y66/AVERAGE(Model!X107:Y107) -> 0.2643262 | I22: =+Model!Z66/AVERAGE(Model!Y107:Z107) -> 0.20424512 | J22: =+Model!AA66/AVERAGE(Model!Z107:AA107) -> 0.075242396 | K22: =+Model!AB66/AVERAGE(Model!AA107:AB107) -> 0.0045930429 | N22: =+AVERAGE(D22:I22) -> 0.24738064 | O22: =+MEDIAN(D22:I22) -> 0.24056227 | Q22: =Net Income/Book Value of Equity
B23: Return on Capital Employed (ROCE) | D23: =+Model!U58/AVERAGE(Ratios!C10:D10) -> 0.24394705 | E23: =+Model!V58/AVERAGE(Ratios!D10:E10) -> 0.29602944 | F23: =+Model!W58/AVERAGE(Ratios!E10:F10) -> 0.17518132 | G23: =+Model!X58/AVERAGE(Ratios!F10:G10) -> 0.25418879 | H23: =+Model!Y58/AVERAGE(Ratios!G10:H10) -> 0.26799464 | I23: =+Model!Z58/AVERAGE(Ratios!H10:I10) -> 0.18067554 | J23: =+Model!AA58/AVERAGE(Ratios!I10:J10) -> 0.076446179 | K23: =+Model!AB58/AVERAGE(Ratios!J10:K10) -> 0.038008458 | N23: =+AVERAGE(D23:I23) -> 0.23633613 | O23: =+MEDIAN(D23:I23) -> 0.24906792 | Q23: =EBIT/Capital Employed
B24: Return on Capital Invested (ROIC) | D24: =+D14/AVERAGE(C11:D11) -> 0.19409916 | E24: =+E14/AVERAGE(D11:E11) -> 0.18416469 | F24: =+F14/AVERAGE(E11:F11) -> 0.16148137 | G24: =+G14/AVERAGE(F11:G11) -> 0.23764521 | H24: =+H14/AVERAGE(G11:H11) -> 0.23426731 | I24: =+I14/AVERAGE(H11:I11) -> 0.15494982 | J24: =+J14/AVERAGE(I11:J11) -> 0.072203016 | K24: =+K14/AVERAGE(J11:K11) -> 0.015788612 | N24: =+AVERAGE(D24:I24) -> 0.1944346 | O24: =+MEDIAN(D24:I24) -> 0.18913193 | Q24: =NOPAT/Invested Capital
B25: ROIC without Intangibles | D25: =+D14/AVERAGE(C12:D12) -> 0.95346592 | E25: =+E14/AVERAGE(D12:E12) -> 0.73340193 | F25: =+F14/AVERAGE(E12:F12) -> 0.48368655 | G25: =+G14/AVERAGE(F12:G12) -> 0.65931105 | H25: =+H14/AVERAGE(G12:H12) -> 0.61324846 | I25: =+I14/AVERAGE(H12:I12) -> 0.38831851 | J25: =+J14/AVERAGE(I12:J12) -> 0.17990713 | K25: =+K14/AVERAGE(J12:K12) -> 0.039693063 | N25: =+AVERAGE(D25:I25) -> 0.63857207 | O25: =+MEDIAN(D25:I25) -> 0.63627976 | Q25: =NOPAT/(Invested Capital exclusive of Intangibles)
B26: Decomposed ROIC | Q26: = ROIC = (1-operating cash tax)* (EBITA/Revenues) * (Revenue/Invested Capital)
B28: Retention Rate | D28: =1-(-Model!U146)/Model!U66 -> 0.78992705 | E28: =1-(-Model!V146)/Model!V66 -> 0.41869531 | F28: =1-(-Model!W146)/Model!W66 -> 0.53059896 | G28: =1-(-Model!X146)/Model!X66 -> 0.67724668 | H28: =1-(-Model!Y146)/Model!Y66 -> 0.57719978 | I28: =1-(-Model!Z146)/Model!Z66 -> 0.41200134 | J28: =1-(-Model!AA146)/Model!AA66 -> -0.53574581 | K28: =1-(-Model!AB146)/Model!AB66 -> -9.8235294 | N28: =+AVERAGE(D28:I28) -> 0.56761152 | O28: =+MEDIAN(D28:I28) -> 0.55389937 | Q28: =1 - Dividends/Net Income
B29: Reinvestment Rate | D29: =-(Model!U137+Model!U140)/Ratios!D14 -> 0.29441091 | E29: =-(Model!V137+Model!V140)/Ratios!E14 -> 0.62809757 | F29: =-(Model!W137+Model!W140)/Ratios!F14 -> 0.31740969 | G29: =-(Model!X137+Model!X140)/Ratios!G14 -> 0.26855196 | H29: =-(Model!Y137+Model!Y140)/Ratios!H14 -> 0.48770188 | I29: =-(Model!Z137+Model!Z140)/Ratios!I14 -> 0.8343852 | J29: =-(Model!AA137+Model!AA140)/Ratios!J14 -> 1.4027737 | K29: =-(Model!AB137+Model!AB140)/Ratios!K14 -> -3.9220779 | N29: =+AVERAGE(D29:I29) -> 0.47175954 | O29: =+MEDIAN(D29:I29) -> 0.40255579 | Q29: =Net CapEx + Change in WC / EBIT * (1-t)
B30: Epected Growth in Net Income | D30: =+D28*D22 -> 0.26855373 | E30: =+E28*E22 -> 0.095778835 | F30: =+F28*F22 -> 0.10326259 | G30: =+G28*G22 -> 0.17091613 | H30: =+H28*H22 -> 0.15256903 | I30: =+I28*I22 -> 0.084149264 | J30: =+J28*J22 -> -0.040310798 | K30: =+K28*K22 -> -0.045119892 | N30: =+AVERAGE(D30:I30) -> 0.14587159 | O30: =+MEDIAN(D30:I30) -> 0.12791581 | Q30: =ROE * Retention Rate
B31: Expected Growth in NOPAT | D31: =+D29*D24 -> 0.057144911 | E31: =+E29*E24 -> 0.1156734 | F31: =+F29*F24 -> 0.051255752 | G31: =+G29*G24 -> 0.063820088 | H31: =+H29*H24 -> 0.11425261 | I31: =+I29*I24 -> 0.12928784 | J31: =+J29*J24 -> 0.10128449 | K31: =+K29*K24 -> -0.061924167 | N31: =+AVERAGE(D31:I31) -> 0.088572432 | O31: =+MEDIAN(D31:I31) -> 0.089036348 | Q31: =ROIC * Reinvestment Rate
B32: Expected Growth in NOPAT (excl. Int) | D32: =+D29*D25 -> 0.28071077 | E32: =+E29*E25 -> 0.46064797 | F32: =+F29*F25 -> 0.1535268 | G32: =+G29*G25 -> 0.17705928 | H32: =+H29*H25 -> 0.29908243 | I32: =+I29*I25 -> 0.32400722 | J32: =+J29*J25 -> 0.25236898 | K32: =+K29*K25 -> -0.15567929 | N32: =+AVERAGE(D32:I32) -> 0.28250574 | O32: =+MEDIAN(D32:I32) -> 0.2898966
A34: x | B34: Finacial Stability Ratios
B35: Equity/Debt Ratio | C35: =+Model!T109/SUM(Model!T118,Model!T120,Model!T110,Model!T112) -> 2.2735932 | D35: =+Model!U109/SUM(Model!U118,Model!U120,Model!U110,Model!U112) -> 2.2437893 | E35: =+Model!V109/SUM(Model!V118,Model!V120,Model!V110,Model!V112) -> 1.8478015 | F35: =+Model!W109/SUM(Model!W118,Model!W120,Model!W110,Model!W112) -> 2.0025958 | G35: =+Model!X109/SUM(Model!X118,Model!X120,Model!X110,Model!X112) -> 2.2295082 | H35: =+Model!Y109/SUM(Model!Y118,Model!Y120,Model!Y110,Model!Y112) -> 2.0236824 | I35: =+Model!Z109/SUM(Model!Z118,Model!Z120,Model!Z110,Model!Z112) -> 1.228986 | J35: =+Model!AA109/SUM(Model!AA118,Model!AA120,Model!AA110,Model!AA112) -> 1.0930443 | K35: =+Model!AB109/SUM(Model!AB118,Model!AB120,Model!AB110,Model!AB112) -> 1.235074 | N35: =+AVERAGE(C35:I35) -> 1.9785652 | O35: =+MEDIAN(C35:I35) -> 2.0236824 | Q35: =Book Value of Equtiy/Book Value of Debt
B36: Gearing | C36: =+C6/Model!T109 -> 0.25829215 | D36: =+D6/Model!U109 -> 0.16573905 | E36: =+E6/Model!V109 -> 0.31793536 | F36: =+F6/Model!W109 -> 0.20009971 | G36: =+G6/Model!X109 -> 0.063410017 | H36: =+H6/Model!Y109 -> 0.18954204 | I36: =+I6/Model!Z109 -> 0.56021237 | J36: =+J6/Model!AA109 -> 0.52441195 | K36: =+K6/Model!AB109 -> 0.52510474 | N36: =+AVERAGE(C36:I36) -> 0.25074724 | O36: =+MEDIAN(C36:I36) -> 0.20009971 | Q36: =(Debt - Cash (Net Debt))/Book Value of Equity
B37: Interest Coverage Ratio | C37: =+Model!T58/(-Model!T59) -> 11.1554 | D37: =+Model!U58/(-Model!U59) -> 17.951761 | E37: =+Model!V58/(-Model!V59) -> 14.894346 | F37: =+Model!W58/(-Model!W59) -> 9.6523266 | G37: =+Model!X58/(-Model!X59) -> 17.571429 | H37: =+Model!Y58/(-Model!Y59) -> 20.75 | I37: =+Model!Z58/(-Model!Z59) -> 11.32439 | J37: =+Model!AA58/(-Model!AA59) -> 3.7654723 | K37: =+Model!AB58/(-Model!AB59) -> 1.7626263 | N37: =+AVERAGE(C37:I37) -> 14.757093 | O37: =+MEDIAN(C37:I37) -> 14.894346 | Q37: =EBIT/Interest Expenses
B38: Net Debt / EBITDA | C38: =+C6/(Model!T58+Model!T132) -> 1.0391601 | D38: =+D6/(Model!U58+Model!U132) -> 0.39579427 | E38: =+E6/(Model!V58+Model!V132) -> 0.56682209 | F38: =+F6/(Model!W58+Model!W132) -> 0.50835937 | G38: =+G6/(Model!X58+Model!X132) -> 0.13936 | H38: =+H6/(Model!Y58+Model!Y132) -> 0.39682764 | I38: =+I6/(Model!Z58+Model!Z132) -> 1.3871018 | J38: =+J6/(Model!AA58+Model!AA132) -> 1.8641808 | K38: =+K6/(Model!AB58+Model!AB132) -> 2.6357166 | N38: =+AVERAGE(C38:I38) -> 0.63334646 | O38: =+MEDIAN(C38:I38) -> 0.50835937 | Q38: =Net Debt/EBITDA
B39: Cash Burn Rate | C39: 0 | D39: 0 | E39: 0 | F39: 0 | G39: 0 | H39: 0 | I39: 0 | J39: 0 | K39: 0 | N39: =+AVERAGE(C39:I39) -> 0 | O39: =+MEDIAN(C39:I39) -> 0 | Q39: =Book Value of Equity/Absolute value of Loss
A41: x | B41: WC-Managment Ratios
B42: Debitor-Duration | C42: =+Model!T99/Model!T44*360 -> 31.783792 | D42: =+Model!U99/Model!U44*360 -> 22.379475 | E42: =+Model!V99/Model!V44*360 -> 22.57437 | F42: =+Model!W99/Model!W44*360 -> 22.649425 | G42: =+Model!X99/Model!X44*360 -> 19.933126 | H42: =+Model!Y99/Model!Y44*360 -> 20.873667 | I42: =+Model!Z99/Model!Z44*360 -> 21.177553 | J42: =+Model!AA99/Model!AA44*360 -> 21.000349 | K42: =+Model!AB99/Model!AB44*360 -> 20.213969 | N42: =+AVERAGE(C42:I42) -> 23.053058 | O42: =+MEDIAN(C42:I42) -> 22.379475 | Q42: =Accounts Receivables/Revenue*360
B43: Creditor-Duration | C43: =+Model!T121/Model!T44*360 -> 28.857776 | D43: =+Model!U121/Model!U44*360 -> 19.647572 | E43: =+Model!V121/Model!V44*360 -> 18.32921 | F43: =+Model!W121/Model!W44*360 -> 18.302011 | G43: =+Model!X121/Model!X44*360 -> 35.540946 | H43: =+Model!Y121/Model!Y44*360 -> 40.031448 | I43: =+Model!Z121/Model!Z44*360 -> 40.478381 | J43: =+Model!AA121/Model!AA44*360 -> 43.926951 | K43: =+Model!AB121/Model!AB44*360 -> 46.560818 | N43: =+AVERAGE(C43:I43) -> 28.741049 | O43: =+MEDIAN(C43:I43) -> 28.857776 | Q43: =Accounts Payable/Revenue*360
B44: Inventory Intensity | C44: =+Model!T98/Model!T106 -> 0.10552675 | D44: =+Model!U98/Model!U106 -> 0.11300807 | E44: =+Model!V98/Model!V106 -> 0.1090017 | F44: =+Model!W98/Model!W106 -> 0.1016054 | G44: =+Model!X98/Model!X106 -> 0.10843955 | H44: =+Model!Y98/Model!Y106 -> 0.13155181 | I44: =+Model!Z98/Model!Z106 -> 0.10999106 | J44: =+Model!AA98/Model!AA106 -> 0.092096157 | K44: =+Model!AB98/Model!AB106 -> 0.089286582 | N44: =+AVERAGE(C44:I44) -> 0.11130348 | O44: =+MEDIAN(C44:I44) -> 0.1090017 | Q44: =Inventory/Balance Sheet Total
B45: Invetory Turnover | C45: =+Model!T45/Model!T98 -> 1.9801786 | D45: =+Model!U45/Model!U98 -> 1.4357891 | E45: =+Model!V45/Model!V98 -> 1.388382 | F45: =+Model!W45/Model!W98 -> 1.261852 | G45: =+Model!X45/Model!X98 -> 1.3585634 | H45: =+Model!Y45/Model!Y98 -> 1.1540873 | I45: =+Model!Z45/Model!Z98 -> 1.0195604 | J45: =+Model!AA45/Model!AA98 -> 1.130511 | K45: =+Model!AB45/Model!AB98 -> 1.0919228 | N45: =+AVERAGE(C45:I45) -> 1.3712018 | O45: =+MEDIAN(C45:I45) -> 1.3585634 | Q45: =Cogs/Inventory
...

Sheet DCF
A1: Main | B1: Kering DCF
B3: Ticker | E3: KER.PA | G3: Share Price | J3: =+Main!H2 -> 245.3 | L3: Share Price | O3: =+J3 -> 245.3
B4: Date | E4: =+TODAY() -> 46226 | G4: Fair Share Price | J4: =V62 -> 339.64482 | L4: Scneario DCF Price | O4: =+J15+O15+T15 -> 0
B5: End of FY | E5: 46022 | G5: Implied Upside | J5: =J4/J3-1 -> 0.38460993 | L5: Implied Upside | O5: =O4/O3-1 -> -1
A7: x | B7: Assumptions
B9: Switches | G9: Conservative Case | L9: Base Case | Q9: Optimistic Case
B10: Assuptions | G10: Assuptions | I10: Year | J10: Metic | L10: Assuptions | N10: Year | O10: Metic | Q10: Assuptions | S10: Year | T10: Metic
B11: Revenue | E11: 2 | G11: Revenue | L11: Revenue | Q11: Revenue
B12: EBIT | E12: 2 | G12: EBIT | L12: EBIT | Q12: EBIT
B13: WACC | E13: 2 | G13: Implied Share Price
B14: TGR | E14: 2 | G14: Probability | L14: Probability | Q14: Probability
B15: ROIC | E15: 2 | G15: Implied Share Price * p | L15: Implied Share Price * p | Q15: Implied Share Price * p
B17: Valuation
B18: WACC | E18: =CHOOSE(E13,J18,O18,T18) -> 0.09 | G18: WACC | J18: 0.11 | L18: WACC | O18: 0.09 | Q18: WACC | T18: 0.08
B19: TGR | E19: =CHOOSE(E14,J19,O19,T19) -> 0.02 | G19: TGR | J19: 0.01 | L19: TGR | O19: 0.02 | Q19: TGR | T19: 0.03
B20: RONIC | E20: =CHOOSE(E15,J20,O20,T20) -> 0.1 | G20: RONIC | J20: 0.09 | L20: RONIC | O20: 0.1 | Q20: RONIC | T20: 0.11
A24: x | B24: Model | G24: 19 | H24: =G24+1 -> 20 | I24: =H24+1 -> 21 | J24: =I24+1 -> 22 | K24: =J24+1 -> 23 | L24: =K24+1 -> 24 | M24: =L24+1 -> 25 | N24: =M24+1 -> 26 | O24: =N24+1 -> 27 | ... V24: =U24+1 -> 34
B25: Revenue | G25: =+Model!V44 -> 15883.5 | H25: =+Model!W44 -> 13100.2 | I25: =+Model!X44 -> 17645 | J25: =+Model!Y44 -> 20351 | K25: =+Model!Z44 -> 19566 | L25: =+Model!AA44 -> 17194 | M25: =L25*(1+M26) -> 14675 | N25: =M25*(1+N26) -> 15917.72 | O25: =N25*(1+O26) -> 18567.084 | P25: =O25*(1+P26) -> 20836.636 | Q25: =P25*(1+Q26) -> 24837.85 | R25: =Q25*(1+R26) -> 24837.85 | S25: =R25*(1+S26) -> 24837.85 | T25: =S25*(1+T26) -> 24837.85 | ... V25: =U25*(1+V26) -> 24837.85
B26: Growth (%) | H26: =H25/G25-1 -> -0.17523216 | I26: =I25/H25-1 -> 0.346926 | J26: =J25/I25-1 -> 0.15335789 | K26: =K25/J25-1 -> -0.038573043 | L26: =L25/K25-1 -> -0.12123071 | M26: {=OFFSET(M26,$E$11,,)} -> -0.14650459 | N26: {=OFFSET(N26,$E$11,,)} -> 0.084682768 | O26: {=OFFSET(O26,$E$11,,)} -> 0.16644121 | P26: {=OFFSET(P26,$E$11,,)} -> 0.12223521 | Q26: {=OFFSET(Q26,$E$11,,)} -> 0.19202788 | R26: {=OFFSET(R26,$E$11,,)} -> 0 | S26: {=OFFSET(S26,$E$11,,)} -> 0 | T26: {=OFFSET(T26,$E$11,,)} -> 0 | ... V26: {=OFFSET(V26,$E$11,,)} -> 0
B27: Conservative Case | M27: =+M28-3% -> -0.17650459 | N27: =+N28-3% -> 0.054682768 | O27: =+O28-3% -> 0.13644121 | P27: =+P28-3% -> 0.092235209 | Q27: =+Q28-3% -> 0.16202788 | R27: =+R28-3% -> -0.03 | S27: =+S28-3% -> -0.03 | T27: =+T28-3% -> -0.03 | ... V27: =+V28-3% -> -0.03
B28: Base Case | M28: =+Model!AB78 -> -0.14650459 | N28: =+Model!AC78 -> 0.084682768 | O28: =+Model!AD78 -> 0.16644121 | P28: =+Model!AE78 -> 0.12223521 | Q28: =+Model!AF78 -> 0.19202788 | R28: =+Model!AG78 -> 0 | S28: =+Model!AH78 -> 0 | T28: =+Model!AI78 -> 0 | ... V28: =+Model!AK78 -> 0
B29: Optimisitic Case | M29: =+M28+2% -> -0.12650459 | N29: =+N28+2% -> 0.10468277 | O29: =+O28+2% -> 0.18644121 | P29: =+P28+2% -> 0.14223521 | Q29: =+Q28+2% -> 0.21202788 | R29: =+R28+2% -> 0.02 | S29: =+S28+2% -> 0.02 | T29: =+T28+2% -> 0.02 | ... V29: =+V28+2% -> 0.02
B31: EBIT | G31: =+Model!V58 -> 4609.8 | H31: =+Model!W58 -> 3298.2 | I31: =+Model!X58 -> 4797 | J31: =+Model!Y58 -> 5395 | K31: =+Model!Z58 -> 4643 | L31: =+Model!AA58 -> 2312 | M31: =M32*M25 -> 2201.25 | N31: =N32*N25 -> 2626.4237 | O31: =O32*O25 -> 3369.9258 | P31: =P32*P25 -> 4160.0343 | Q31: =Q32*Q25 -> 5454.7645 | R31: =R32*R25 -> 6000.241 | S31: =S32*S25 -> 6600.2651 | T31: =T32*T25 -> 6954.5981 | ... V31: =V32*V25 -> 6954.5981
B32: % of Sales | G32: =G31/G25 -> 0.29022571 | H32: =H31/H25 -> 0.25176715 | I32: =I31/I25 -> 0.27186172 | J32: =J31/J25 -> 0.26509754 | K32: =K31/K25 -> 0.2372994 | L32: =L31/L25 -> 0.13446551 | M32: {=OFFSET(M32,$E$12,,)} -> 0.15 | N32: {=OFFSET(N32,$E$12,,)} -> 0.165 | O32: {=OFFSET(O32,$E$12,,)} -> 0.1815 | P32: {=OFFSET(P32,$E$12,,)} -> 0.19965 | Q32: {=OFFSET(Q32,$E$12,,)} -> 0.219615 | R32: {=OFFSET(R32,$E$12,,)} -> 0.2415765 | S32: {=OFFSET(S32,$E$12,,)} -> 0.26573415 | T32: {=OFFSET(T32,$E$12,,)} -> 0.28 | ... V32: {=OFFSET(V32,$E$12,,)} -> 0.28
B33: Conservative Case | M33: =+M34-2% -> 0.13 | N33: =+N34-2% -> 0.145 | O33: =+O34-2% -> 0.1615 | P33: =+P34-2% -> 0.17965 | Q33: =+Q34-2% -> 0.199615 | R33: =+R34-2% -> 0.2215765 | S33: =+S34-2% -> 0.24573415 | T33: =+T34-2% -> 0.26 | ... V33: =+V34-2% -> 0.26
B34: Base Case | M34: =+Model!AB85 -> 0.15 | N34: =+Model!AC85 -> 0.165 | O34: =+Model!AD85 -> 0.1815 | P34: =+Model!AE85 -> 0.19965 | Q34: =+Model!AF85 -> 0.219615 | R34: =+Model!AG85 -> 0.2415765 | S34: =+Model!AH85 -> 0.26573415 | T34: =+Model!AI85 -> 0.28 | ... V34: =+Model!AK85 -> 0.28
B35: Optimisitic Case | M35: =+M34+1% -> 0.16 | N35: =+N34+1% -> 0.175 | O35: =+O34+1% -> 0.1915 | P35: =+P34+1% -> 0.20965 | Q35: =+Q34+1% -> 0.229615 | R35: =+R34+1% -> 0.2515765 | S35: =+S34+1% -> 0.27573415 | T35: =+T34+1% -> 0.29 | ... V35: =+V34+1% -> 0.29
B37: Taxes | G37: =+Model!V61 -> 2133.7 | H37: =+Model!W61 -> 759.2 | I37: =+Model!X61 -> 1280.4 | J37: =+Model!Y61 -> 1420 | K37: =+Model!Z61 -> 1163 | L37: =+Model!AA61 -> 461 | M37: =M38*M31 -> 440.25 | N37: =N38*N31 -> 525.28475 | O37: =O38*O31 -> 673.98515 | P37: =P38*P31 -> 832.00686 | Q37: =Q38*Q31 -> 1090.9529 | R37: =R38*R31 -> 1200.0482 | S37: =S38*S31 -> 1320.053 | T37: =T38*T31 -> 1390.9196 | ... V37: =V38*V31 -> 1390.9196
B38: Tax Rate (%) | G38: =G37/G31 -> 0.46286173 | H38: =H37/H31 -> 0.23018616 | I38: =I37/I31 -> 0.26691682 | J38: =J37/J31 -> 0.26320667 | K38: =K37/K31 -> 0.2504846 | L38: =L37/L31 -> 0.19939446 | M38: 0.2 | N38: 0.2 | O38: 0.2 | P38: 0.2 | Q38: 0.2 | R38: 0.2 | S38: 0.2 | T38: 0.2 | U38: 0.2 | V38: 0.2
B40: Nopat | G40: =G31-G37 -> 2476.1 | H40: =H31-H37 -> 2539 | I40: =I31-I37 -> 3516.6 | J40: =J31-J37 -> 3975 | K40: =K31-K37 -> 3480 | L40: =L31-L37 -> 1851 | M40: =M31-M37 -> 1761 | N40: =N31-N37 -> 2101.139 | ... V40: =V31-V37 -> 5563.6785
B42: D&A and other non-cash Expenses | G42: =+Model!V132 -> 1245.3 | H42: =+Model!W132 -> 1439 | I42: =+Model!X132 -> 1453 | J42: =+Model!Y132 -> 1666 | K42: =+Model!Z132 -> 1823 | L42: =+Model!AA132 -> 2113 | M42: =M43*M25 -> 1467.5 | N42: =N43*N25 -> 1544.0188 | O42: =O43*O25 -> 1746.9769 | P42: =P43*P25 -> 1901.7035 | Q42: =Q43*Q25 -> 2198.877 | R42: =R43*R25 -> 2132.9107 | S42: =S43*S25 -> 2068.9234 | T42: =T43*T25 -> 2006.8557 | ... V42: =V43*V25 -> 1888.2505
B43: % of Sales | G43: =G42/G25 -> 0.078402115 | H43: =H42/H25 -> 0.10984565 | I43: =I42/I25 -> 0.082346274 | J43: =J42/J25 -> 0.081863299 | K43: =K42/K25 -> 0.093171829 | L43: =L42/L25 -> 0.12289171 | M43: 0.1 | N43: =+M43*(1-3%) -> 0.097 | O43: =+N43*(1-3%) -> 0.09409 | P43: =+O43*(1-3%) -> 0.0912673 | Q43: =+P43*(1-3%) -> 0.088529281 | R43: =+Q43*(1-3%) -> 0.085873403 | S43: =+R43*(1-3%) -> 0.0832972 | T43: =+S43*(1-3%) -> 0.080798284 | U43: =+T43*(1-3%) -> 0.078374336 | V43: =+U43*(1-3%) -> 0.076023106
B45: CapEx | G45: =+Model!V140 -> -954.6 | H45: =+Model!W140 -> -784 | I45: =+Model!X140 -> -928 | J45: =+Model!Y140 -> -1070 | K45: =+Model!Z140 -> -2476 | L45: =+Model!AA140 -> -3277 | M45: =M46*M25 -> -1761 | N45: =N46*N25 -> -1795.5188 | O45: =O46*O25 -> -1968.7051 | P45: =P46*P25 -> -2076.7891 | Q45: =Q46*Q25 -> -2327.0551 | R45: =R46*R25 -> -2187.4318 | S45: =S46*S25 -> -2056.1859 | T45: =T46*T25 -> -1932.8147 | ... V45: =V46*V25 -> -1707.8351
B46: % of Sales | G46: =G45/G25 -> -0.060100104 | H46: =H45/H25 -> -0.059846415 | I46: =I45/I25 -> -0.052592802 | J46: =J45/J25 -> -0.052577269 | K46: =K45/K25 -> -0.12654605 | L46: =L45/L25 -> -0.19058974 | M46: -0.12 | N46: =+M46*(1-6%) -> -0.1128 | O46: =+N46*(1-6%) -> -0.106032 | P46: =+O46*(1-6%) -> -0.09967008 | Q46: =+P46*(1-6%) -> -0.093689875 | R46: =+Q46*(1-6%) -> -0.088068483 | S46: =+R46*(1-6%) -> -0.082784374 | T46: =+S46*(1-6%) -> -0.077817311 | U46: =+T46*(1-6%) -> -0.073148273 | V46: =+U46*(1-6%) -> -0.068759376
B48: Change in WC | G48: =+Model!V137 -> -557.5 | H48: =+Model!W137 -> 44.4 | I48: =+Model!X137 -> -38 | J48: =+Model!Y137 -> -902 | K48: =+Model!Z137 -> -396 | L48: =+Model!AA137 -> 667 | M48: =M49*M25 -> -293.5 | N48: =N49*N25 -> -305.62022 | O48: =O49*O25 -> -342.22849 | P48: =P49*P25 -> -368.69843 | Q48: =Q49*Q25 -> -421.91886 | R48: =R49*R25 -> -405.0421 | S48: =S49*S25 -> -388.84042 | T48: =T49*T25 -> -373.2868 | ... V48: =V49*V25 -> -344.02112
B49: % of Sales | G49: =G48/G25 -> -0.035099317 | H49: =H48/H25 -> 0.0033892612 | I49: =I48/I25 -> -0.0021535846 | J49: =J48/J25 -> -0.044322146 | K49: =K48/K25 -> -0.02023919 | L49: =L48/L25 -> 0.038792602 | M49: -0.02 | N49: =+M49*(1-4%) -> -0.0192 | O49: =+N49*(1-4%) -> -0.018432 | P49: =+O49*(1-4%) -> -0.01769472 | Q49: =+P49*(1-4%) -> -0.016986931 | R49: =+Q49*(1-4%) -> -0.016307454 | S49: =+R49*(1-4%) -> -0.015655156 | T49: =+S49*(1-4%) -> -0.01502895 | U49: =+T49*(1-4%) -> -0.014427792 | V49: =+U49*(1-4%) -> -0.01385068
B51: Unlevered Free Cashflow | G51: =G40+G42+G45+G48 -> 2209.3 | H51: =H40+H42+H45+H48 -> 3238.4 | I51: =I40+I42+I45+I48 -> 4003.6 | J51: =J40+J42+J45+J48 -> 3669 | K51: =K40+K42+K45+K48 -> 2431 | L51: =L40+L42+L45+L48 -> 1354 | M51: =M40+M42+M45+M48 -> 1174 | N51: =N40+N42+N45+N48 -> 1544.0188 | ... V51: =V40+V42+V45+V48 -> 5400.0728
B52: Present Value of unlevered FC | M52: =(M51/(1+$E$18)^M53)*M53 -> 630.60476 | N52: =N51/(1+$E$18)^N53 -> 1349.341 | O52: =O51/(1+$E$18)^O53 -> 1709.3325 | P52: =P51/(1+$E$18)^P53 -> 2047.9687 | Q52: =Q51/(1+$E$18)^Q53 -> 2573.5809 | R52: =R51/(1+$E$18)^R53 -> 2687.2981 | S52: =S51/(1+$E$18)^S53 -> 2785.4589 | T52: =T51/(1+$E$18)^T53 -> 2743.2267 | U52: =U51/(1+$E$18)^U53 -> 2550.5182 | V52: =V51/(1+$E$18)^V53 -> 2368.4092
B53: Discount Period | M53: =YEARFRAC(E4,E5) -> 0.56388889 | N53: =M53+1 -> 1.5638889 | O53: =N53+1 -> 2.5638889 | P53: =O53+1 -> 3.5638889 | Q53: =P53+1 -> 4.5638889 | R53: =Q53+1 -> 5.5638889 | S53: =R53+1 -> 6.5638889 | T53: =S53+1 -> 7.5638889 | U53: =T53+1 -> 8.5638889 | V53: =U53+1 -> 9.5638889
B54: Sum of Present Value | V54: =SUM(M52:V52) -> 21445.739
...

Sheet CoC
A1: Main
B3: Cost of Capital
A4: x | B4: Cost of Equity (CAPM)
B5: Riskfree Rate
B6: Expected Inflation | H6: =(1+Nominal Rate)/(1+Real Rate)-1
B7: Average Real Interest Rate | F7: 0.0227 | H7: = Average Interest Rate of the Past
B8: Riskfree Rate | F8: =F6+F7 -> 0.0227 | H8: =Goverment Bond or Expected Inflation + Average Real Interest Rate
A10: x | B10: Adjustments for Industry/Company Risk
B11: Raw Beta | H11: =Raw beta slope of regression line aginst total market -> Ri= alpha + beta*Rm + standard error
B12: Debt to Value Ratio | H12: Value of Debt/Enterpries Value
B13: Unlevered Beta | H13: = Raw Beta* Debt-to-Equity Ratio (Book Value)
B14: Unlevered Industry Beta | H14: =Median of Peer Group
B15: Levered Industry Beta | H15: =Unlevered Industry Beta * Market Value of Debt to Market Value of Equity
A17: x | B17: Expected Equity Risk Premium
B18: Estimated Future Market Return | H18: = 1/P/E * (1.g/ROE) + g , g = real growth in GDP, P/E => P/E ratio for S&P500 or MSCI World Index, ROE = Average ROE in S&P500 or MSCI World
B19: Riskfree Rate
B20: Expected Equity Risk Premium | F20: =F18-F19 -> 0
A22: x | B22: Cost of Equity (CAPM) | F22: =F8+F15*F20 -> 0.0227 | H22: => ER(i)=rf+beta(i)*(Er(m)-rf)
A25: x | B25: Cost of Debt
B26: Yield to Maturity on Trading Bonds | F26: 0.03625 | H26: => Price = Coupon/(1+YTM)+Coupon(1+YTM)^2 + … + (Face Value + Coupon)/(1+YTM)^n => solve for YTM
B27: or
B28: Riskfree Rate
B29: Credit Default Spread
B30: Country Rsik Premium
A32: x | B32: Cost of Debt | F32: =+F26 -> 0.03625
A34: x | B34: Capital Structure
B35: Market Value of Debt | F35: =+Main!H4 -> 30074.96
B36: Market Value of Equity | F36: =+Main!H6 -> 12562
B37: Total Enterprise Value | F37: =F35+F36 -> 42636.96
B39: Marginal Tax Rate | F39: 0.27
A41: x | B41: WACC | F41: =+(F36/F37*F32*(1-F40))+(F35/F37*F22) -> 0.026692196 | H41: => WACC = (D/D+E)*kd * (1-t) + (E/D+E) * ke

Sheet TradingComps
A1: Main
C3: Company | J3: Multiples
A5: x | B5: Name | C5: MC | D5: EV | E5: Debt Ratio | F5: Revenue | G5: EBIT | H5: Dividende | I5: ROC | J5: P/R | K5: P/E | L5: PEG | M5: P/B | N5: P/CF | O5: EV/EBIT
B6: LVMH | C6: 339520 | D6: 413940 | E6: 1.318 | F6: 97200 | G6: 21400 | H6: 0.0176 | I6: 0.1074 | J6: 4.29 | K6: 24.24 | L6: 1.89 | M6: 6.18 | N6: 19.15 | O6: =D6/G6 -> 19.342991
B7: Hermés | C7: 151050 | D7: 149400 | E7: 0.4 | F7: 11600 | G7: =F7*(39.74%) -> 4609.84 | H7: 0.0075 | I7: 0.1953 | J7: 13.02 | K7: 44.88 | L7: 2.28 | M7: 12.14 | N7: 35.67 | O7: =D7/G7 -> 32.408934
B8: Richemont | C8: 66780 | D8: 76740 | E8: 1.143 | F8: 19830 | G8: 3390 | H8: 0.0213 | I8: 0.1035 | J8: =C8/F8 -> 3.3676248 | K8: 2145.34 | L8: 0.17 | M8: 3.56 | N8: 13.52 | O8: =D8/G8 -> 22.637168
B9: Pandora | C9: 5830 | D9: 7600 | E9: 2.0714 | F9: =C9/J9 -> 3554.878 | G9: =F9*25.87% -> 919.64695 | H9: 0.0203 | I9: 0.243 | J9: 1.64 | K9: 9.01 | L9: 1.78 | M9: 6.09 | N9: 10.31 | O9: =D9/G9 -> 8.2640409
B10: Capri Holdings (vormals Michael Kors) | C10: 5310 | D10: =C10-249+5+1822 -> 6888 | E10: 2.942 | F10: 5610 | G10: 376 | H10: 0 | I10: 0.0877 | J10: 1 | K10: 10.55 | L10: 0.9 | M10: 3.08 | N10: 8.44 | O10: =D10/G10 -> 18.319149
B11: Moncler | C11: 14650 | D11: 13150 | E11: 0.5984 | F11: 2600 | G11: =39.76%*C11 -> 5824.84 | H11: 0.0195 | I11: 0.1364 | J11: =C11/F11 -> 5.6346154 | K11: 24.49 | L11: 2.28 | M11: 4.59 | N11: 20.09 | O11: =D11/G11 -> 2.2575727
B12: Hugo Boss | C12: 4660 | D12: 5228 | E12: 1.7 | F12: 3650 | G12: =F12*0.084 -> 306.6 | H12: 0.0199 | I12: 0.0746 | J12: =C12/F12 -> 1.2767123 | K12: 18.26 | L12: 0.79 | M12: 3.35 | N12: 11.12 | O12: =D12/G12 -> 17.051533
