Workbook

Sheet Main
A1: LuluLemon
A2: numbers in mio USD | H2: Price | I2: 99.65
H3: Shares | I3: 105.59406 | J3: Q226
B4: SEC | C4: BFY | D4: 45323 | H4: MC | I4: =I3*I2 -> 10522.448
B5: Investors | C5: EFY | D5: 45322 | H5: Cash | I5: 189.737 | J5: Q226
H6: Debt | I6: 0 | J6: Q226
B7: FX | H7: EV | I7: =I4+I6-I5 -> 10332.711
B8: EUR/USD | C8: 1.15
B9: RMB/USD | C9: 0.15 | H9: P/E | I9: =+I2/9.73 -> 10.241521
H10: EV/EBIT | I10: =+I7/Model!Z32 -> 4.1236875
B12: Notes | H12: CEO: | I12: Heidi O'Neill | K12: (pior at Nike Consumer, Product & Brand, joins 09.09)
B13: May 2026, settlement with Chip Wilson: | H13: CFO | I13: Meghan Frank
B14: Two of his nominees are appointed to board
B15: of Directors | H15: Founded: | I15: 1998 | J15: by Chip Wilson in Vancouver
B16: In exchange he agreed to stop critizing the company's
B17: management publicly
B19: Q226:
B20: Weak leggins -> down 20%
B21: China weakens, brand problems rather than macro
B22: Outlook
B23: For full year: Revenue down 5-7% (10.35-10,5)
B24: EPS: 9,48-9,73

Sheet Model
A1: Main
C2: Q123 | D2: Q223 | E2: Q323 | F2: Q423 | G2: Q124 | H2: Q224 | I2: Q324 | J2: Q424 | K2: Q125 | L2: Q225 | M2: Q325 | N2: Q425 | O2: Q126 | P2: Q226 | Q2: Q326 | R2: Q426 | T2: FY18 | U2: FY19 | V2: FY20 | W2: FY21 | X2: FY22 | Y2: FY23 | Z2: FY24 | AA2: FY25 | AB2: FY26 | AC2: FY27 | AD2: FY28 | AE2: FY29 | AF2: FY30 | AG2: FY31 | AH2: FY32
B3: Nike Sports Apparel | T3: 10733 | U3: 11550 | V3: 10953 | W3: 12865 | X3: 13567 | Y3: 13843 | Z3: 13775 | AA3: 12965 | AB3: 13449
B4: Adidas Sports Apparel | Y4: 9034.4 | Z4: 9448.4 | AA4: 10078.6
B5: Anta Sports Apparel | W5: 4294.8 | X5: 4428.45 | Y5: 5260.05 | Z5: 5907.75 | AA5: 6872.1
B6: Puma Sports Apparel | Y6: =2763*Main!C8 -> 3177.45 | Z6: =2813.9*Main!C8 -> 3235.985 | AA6: =2328.5*Main!C8 -> 2677.775
B7: Sports Apparel Market | T7: =+U7*(1-5.4%) -> 150281.56 | U7: =+V7*(1-5.4%) -> 158860 | V7: =+W7*(1-5.4%) -> 167928.12 | W7: =+X7*(1-5.4%) -> 177513.87 | X7: =+Y7*(1-5.4%) -> 187646.79 | Y7: =+Z7*(1-5.4%) -> 198358.13 | Z7: =+AA7*(1-5.4%) -> 209680.9 | AA7: 221650 | AB7: 233810 | AC7: =+AB7*(1+5.4%) -> 246435.74 | AD7: =+AC7*(1+5.4%) -> 259743.27 | AE7: =+AD7*(1+5.4%) -> 273769.41 | AF7: =+AE7*(1+5.4%) -> 288552.95 | AG7: =+AF7*(1+5.4%) -> 304134.81 | AH7: =+AG7*(1+5.4%) -> 320558.09
B8: LULU Market Share | T8: =+T27/T7 -> 0.021881055 | U8: =+U27/U7 -> 0.025049075 | V8: =+V27/V7 -> 0.026212877 | W8: =+W27/W7 -> 0.035245793 | X8: =+X27/X7 -> 0.043222258 | Y8: =+Y27/Y7 -> 0.048494498 | Z8: =+Z27/Z7 -> 0.050496378 | AA8: =+AA27/AA7 -> 0.050090684 | AB8: =+AB27/AB7 -> 0.048910132 | AC8: =+AB8*(1-4%) -> 0.046953727 | AD8: =+AC8*(1-4%) -> 0.045075578 | AE8: =+AD8*(1-4%) -> 0.043272555 | AF8: =+AE8*(1-4%) -> 0.041541652 | AG8: =+AF8*(1-4%) -> 0.039879986 | AH8: =+AG8*(1-4%) -> 0.038284787
B11: Americas Stores | C11: 438 | D11: 438 | E11: 438 | F11: 438 | G11: 440 | H11: 441 | I11: 459 | J11: 462 | K11: 462 | L11: 467 | M11: 470 | N11: 476 | O11: 476 | P11: 483 | T11: =285+64 -> 349 | U11: =306+63 -> 369 | V11: =315+62 -> 377 | W11: =324+63 -> 387 | X11: 419 | Y11: 438 | Z11: 462 | AA11: 476
B12: China-Mainland Stores | C12: 127 | D12: 127 | E12: 127 | F12: 127 | G12: 127 | H12: 132 | I12: 138 | J12: 151 | K12: 154 | L12: 159 | M12: 165 | N12: 172 | O12: 173 | P12: 174 | T12: 22 | U12: 38 | V12: 55 | W12: 86 | X12: 99 | Y12: 127 | Z12: 151 | AA12: 172
B13: APAC Stores | C13: 98 | D13: 98 | E13: 98 | F13: 98 | G13: 97 | H13: 101 | I13: 105 | J13: 107 | K13: 107 | L13: 109 | M13: 112 | N13: 114 | O13: 117 | P13: 117 | T13: =29+5+7+4+3 -> 48 | U13: =31+7+7+5+4+2 -> 56 | V13: =31+7+7+6+4+2 -> 57 | W13: =31+12+7+6+6+2 -> 64 | X13: 91 | Y13: 98 | Z13: 107 | AA13: 114
B14: EMEA Stores | C14: 48 | D14: 48 | E14: 48 | F14: 48 | G14: 47 | H14: 47 | I14: 47 | J14: 47 | K14: 47 | L14: 49 | M14: 49 | N14: 49 | O14: 50 | P14: 51 | T14: =12+5+1+1+1+1 -> 21 | U14: =14+6+3+2+1+1+1 -> 28 | V14: =16+7+3+1+2+1+1+1 -> 32 | W14: =17+9+3+3+2+1+1+1 -> 37 | X14: 46 | Y14: 48 | Z14: 47 | AA14: 49
B15: Total Stores | C15: =+SUM(C11:C14) -> 711 | D15: =+SUM(D11:D14) -> 711 | E15: =+SUM(E11:E14) -> 711 | F15: =+SUM(F11:F14) -> 711 | G15: =+SUM(G11:G14) -> 711 | H15: =+SUM(H11:H14) -> 721 | I15: =+SUM(I11:I14) -> 749 | J15: =+SUM(J11:J14) -> 767 | ... P15: =+SUM(P11:P14) -> 825 | T15: =+SUM(T11:T14) -> 440 | U15: =+SUM(U11:U14) -> 491 | V15: =+SUM(V11:V14) -> 521 | W15: =+SUM(W11:W14) -> 574 | X15: =+SUM(X11:X14) -> 655 | Y15: =+SUM(Y11:Y14) -> 711 | Z15: =+SUM(Z11:Z14) -> 767 | AA15: =+SUM(AA11:AA14) -> 811 | AB15: =+AA15*(1+5%) -> 851.55 | AC15: =+AB15*(1+5%) -> 894.1275 | AD15: =+AC15*(1+2%) -> 912.01005 | AE15: =+AD15*(1+2%) -> 930.25025 | AF15: =+AE15*(1+2%) -> 948.85526 | AG15: =+AF15*(1+2%) -> 967.83236 | AH15: =+AG15*(1+2%) -> 987.18901
B16: ARPS | C16: =+C25/C15 -> 1.1743207 | D16: =+D25/D15 -> 1.2569241 | E16: =+E25/E15 -> 1.2772532 | F16: =+F25/F15 -> 2.354948 | G16: =+G25/G15 -> 1.273962 | H16: =+H25/H15 -> 1.2630194 | I16: =+I25/I15 -> 1.2613845 | J16: =+J25/J15 -> 2.3588592 | ... M16: =+M25/M15 -> 1.3401382 | N16: =+N24/N15 -> 1.7695771 | O16: =+O24/O15 -> 1.4618137 | P16: =+P24/P15 -> 1.4227236 | T16: =+T24/T15 -> 4.8326432 | U16: =+U24/U15 -> 2.3173564 | V16: =+V24/V15 -> 3.1831228 | W16: =+W24/W15 -> 4.9155 | X16: =+X24/X15 -> 5.5696595 | Y16: =+Y24/Y15 -> 6.2038762 | Z16: =+Z24/Z15 -> 6.5291682 | AA16: =+AA24/AA15 -> 6.2265647 | ... AH16: =+AH24/AH15 -> 4.9086252
B18: Americas Revenue | C18: 1567.738 | D18: 1719.773 | E18: 1732.398 | F18: =+Y18-SUM(C18:E18) -> 2611.738 | G18: 1622.264 | H18: 1741.433 | I18: 1770.382 | J18: =+Z18-SUM(G18:I18) -> 2794.077 | K18: 1674.558 | L18: 1758.217 | M18: 1733.382 | N18: =+AA18-SUM(K18:M18) -> 2680.887 | O18: 1621.21 | P18: 1616.772 | T18: =2363.374+565.105 -> 2928.479 | U18: =2854.364+649.114 -> 3503.478 | V18: =3015.133+672.607 -> 3687.74 | W18: =4345.687+954.219 -> 5299.906 | X18: 6817.454 | Y18: 7631.647 | Z18: 7928.156 | AA18: 7847.044
B19: China-Mainland Revenue | C19: 210.068 | D19: 234.445 | E19: 228.595 | F19: =+Y19-SUM(C19:E19) -> 290.652 | G19: 303.786 | H19: 314.189 | I19: 318.338 | J19: =+Z19-SUM(G19:I19) -> 425.024 | K19: 412.205 | L19: 392.898 | M19: 465.362 | N19: =+AA19-SUM(K19:M19) -> 484.334 | O19: 529.803 | P19: 458.514 | T19: 0 | U19: 0 | V19: 0 | W19: 0 | X19: 576.503 | Y19: 963.76 | Z19: 1361.337 | AA19: 1754.799
B20: ROW Revenue | C20: 222.986 | D20: 254.947 | E20: 243.225 | F20: =+Y20-SUM(C20:E20) -> 302.713 | G20: 282.841 | H20: 315.456 | I20: 307.94 | J20: =+Z20-SUM(G20:I20) -> 392.396 | K20: 283.897 | L20: 374.104 | M20: 367.176 | N20: =+AA20-SUM(K20:M20) -> 475.58 | O20: 320.59 | P20: 340.345 | T20: 359.84 | U20: 475.818 | V20: 624.139 | W20: 956.711 | X20: 716.561 | Y20: 1023.871 | Z20: 1298.633 | AA20: 1500.757
B21: Women Products | C21: 1308.828 | D21: 1396.327 | E21: 1433.927 | F21: =+Y21-SUM(C21:E21) -> 2008.29 | G21: 1435.241 | H21: 1476.121 | I21: 1555.686 | J21: =+Z21-SUM(G21:I21) -> 2225.582 | K21: 1535.172 | L21: 1547.321 | M21: 1644.952 | N21: =+AA21-SUM(K21:M21) -> 2267.92 | O21: 1602.985 | P21: 1488.241 | T21: 2352.788 | U21: 2790.997 | V21: 3049.906 | W21: 4171.762 | X21: 5259.803 | Y21: 6147.372 | Z21: 6692.63 | AA21: 6995.365
B22: Men Products | C22: 438.165 | D22: 530.723 | E22: 504.828 | F22: =+Y22-SUM(C22:E22) -> 779.037 | G22: 505.698 | H22: 587.525 | I22: 551.43 | J22: =+Z22-SUM(G22:I22) -> 913.727 | K22: 544.788 | L22: 624.598 | M22: 596.241 | N22: =+AA22-SUM(K22:M22) -> 901.359 | O22: 581.878 | P22: 621.38 | T22: 694.921 | U22: 933.767 | V22: 953.183 | W22: 1535.85 | X22: 1956.602 | Y22: 2252.753 | Z22: 2558.38 | AA22: 2666.986
B23: Other | C23: 253.799 | D23: 282.115 | E23: 265.463 | F23: =+Y23-SUM(C23:E23) -> 417.776 | G23: 267.952 | H23: 307.432 | I23: 289.544 | J23: =+Z23-SUM(G23:I23) -> 472.188 | K23: 290.7 | L23: 353.3 | M23: 324.727 | N23: =+AA23-SUM(K23:M23) -> 474.522 | O23: 286.74 | P23: 306.01 | T23: 240.61 | U23: 254.532 | V23: 398.79 | W23: 549.005 | X23: 894.113 | Y23: 1219.153 | Z23: 1337.116 | AA23: 1443.249
B24: Store Revenue | C24: 958.087 | D24: 1096.939 | E24: 1073.973 | F24: =+Y24-SUM(C24:E24) -> 1281.957 | G24: 1170.525 | H24: 1215.613 | I24: 1210.523 | J24: =+Z24-SUM(G24:I24) -> 1411.211 | K24: 1153.107 | L24: 1254.952 | M24: 1206.558 | N24: =+AA24-SUM(K24:M24) -> 1435.127 | O24: 1192.84 | P24: 1173.747 | T24: 2126.363 | U24: 1137.822 | V24: 1658.407 | W24: 2821.497 | X24: 3648.127 | Y24: 4410.956 | Z24: 5007.872 | AA24: 5049.744 | AB24: =+AB27*AB45 -> 5097.2116 | AC24: =+AC27*AC45 -> 5054.4113 | AD24: =+AD27*AD45 -> 5011.9704 | AE24: =+AE27*AE45 -> 4969.8859 | AF24: =+AF27*AF45 -> 4928.1548 | AG24: =+AG27*AG45 -> 4886.7741 | AH24: =+AH27*AH45 -> 4845.7408
B25: E-commerce Revenue | C25: 834.942 | D25: 893.673 | E25: 908.127 | F25: =+Y25-SUM(C25:E25) -> 1674.368 | G25: 905.787 | H25: 910.637 | I25: 944.777 | J25: =+Z25-SUM(G25:I25) -> 1809.245 | K25: 960.89 | L25: 993.093 | M25: 1066.75 | N25: =+AA25-SUM(K25:M25) -> 1897.964 | O25: 997.442 | P25: 934.63 | T25: 858.856 | U25: 2501.067 | V25: 2284.068 | W25: 2777.944 | X25: 3699.791 | Y25: 4311.11 | Z25: 4570.446 | AA25: 4918.697 | AB25: =+AB27*AB44 -> 5167.5831 | AC25: =+AC27*AC44 -> 5333.3426 | AD25: =+AD27*AD44 -> 5504.4192 | AE25: =+AE27*AE44 -> 5680.9833 | AF25: =+AF27*AF44 -> 5863.2111 | AG25: =+AG27*AG44 -> 6051.2841 | AH25: =+AH27*AH44 -> 6245.39
B26: Other channels | C26: 207.763 | D26: 218.553 | E26: 222.118 | F26: =+Y26-SUM(C26:E26) -> 248.778 | G26: 232.579 | H26: 244.828 | I26: 241.36 | J26: =+Z26-SUM(G26:I26) -> 291.041 | K26: 256.663 | L26: 277.174 | M26: 292.612 | N26: =+AA26-SUM(K26:M26) -> 307.71 | O26: 281.321 | P26: 307.254 | T26: 303.1 | U26: 340.407 | V26: 459.004 | W26: 657.176 | X26: 762.6 | Y26: 897.212 | Z26: 1009.808 | AA26: 1134.159 | AB26: =+AB27-AB24-AB25 -> 1170.8833 | AC26: =+AC27-AC24-AC25 -> 1183.3225 | AD26: =+AD27-AD24-AD25 -> 1191.6884 | AE26: =+AE27-AE24-AE25 -> 1195.8324 | AF26: =+AF27-AF24-AF25 -> 1195.6007 | AG26: =+AG27-AG24-AG25 -> 1190.8341 | AH26: =+AH27-AH24-AH25 -> 1181.3676
B27: Reveues | C27: 2000.792 | D27: 2209.165 | E27: 2204.218 | F27: 3205.103 | G27: 2208.891 | H27: 2371.078 | I27: 2396.66 | J27: 3611.497 | K27: 2370.66 | L27: 2525.219 | M27: 2565.92 | N27: =+AA27-SUM(K27:M27) -> 3640.801 | O27: 2471.603 | P27: 2415.631 | T27: 3288.319 | U27: 3979.296 | V27: 4401.879 | W27: 6256.617 | X27: 8110.518 | Y27: 9619.278 | Z27: 10588.126 | AA27: 11102.6 | AB27: =+AA27*(1+3%) -> 11435.678 | AC27: =+AC7*AC8 -> 11571.076 | AD27: =+AD7*AD8 -> 11708.078 | AE27: =+AE7*AE8 -> 11846.702 | AF27: =+AF7*AF8 -> 11986.967 | AG27: =+AG7*AG8 -> 12128.892 | AH27: =+AH7*AH8 -> 12272.498
B28: COGS | C28: 849.987 | D28: 910.654 | E28: 947.554 | F28: 1301.678 | G28: 933.823 | H28: 958.893 | I28: 995.054 | J28: 1429.545 | K28: 987.534 | L28: 1048.017 | M28: 1140.004 | N28: =+AA28-SUM(K28:M28) -> 1642.913 | O28: 1132.785 | P28: 953.753 | T28: 1472.031 | U28: 1755.91 | V28: 1937.888 | W28: 2648.052 | X28: 3618.178 | Y28: 4009.873 | Z28: 4317.315 | AA28: 4818.468
B29: Gross Profit | C29: =C27-C28 -> 1150.805 | D29: =D27-D28 -> 1298.511 | E29: =E27-E28 -> 1256.664 | F29: =F27-F28 -> 1903.425 | G29: =G27-G28 -> 1275.068 | H29: =H27-H28 -> 1412.185 | I29: =I27-I28 -> 1401.606 | J29: =J27-J28 -> 2181.952 | ... P29: =P27-P28 -> 1461.878 | T29: =T27-T28 -> 1816.288 | U29: =U27-U28 -> 2223.386 | V29: =V27-V28 -> 2463.991 | W29: =W27-W28 -> 3608.565 | X29: =X27-X28 -> 4492.34 | Y29: =Y27-Y28 -> 5609.405 | Z29: =Z27-Z28 -> 6270.811 | AA29: =AA27-AA28 -> 6284.132
B30: SGA | C30: 747.513 | D30: 817.375 | E30: 842.795 | F30: 989.535 | G30: 842.426 | H30: 871.959 | I30: 909.827 | J30: 1138.167 | K30: 942.871 | L30: 951.658 | M30: 988.254 | N30: =+AA30-SUM(K30:M30) -> 1183.773 | O30: 1059.988 | P30: 1006.332 | T30: 1100.379 | U30: 1334.247 | V30: 1609.003 | W30: 2225.034 | X30: 2757.447 | Y30: 3397.218 | Z30: 3762.379 | AA30: 4066.556
B31: Other Expenses | C31: 1.878 | D31: 1.879 | E31: =74.501+1.253 -> 75.754 | F31: 0 | G31: 0 | H31: 0 | I31: 1.118 | J31: 1.617 | K31: 1.63 | L31: 1.73 | M31: 1.776 | N31: =+AA31-SUM(K31:M31) -> 1.825 | O31: 1.884 | P31: 1.893 | T31: 0.072 | U31: 0.029 | V31: =5.16+29.842 -> 35.002 | W31: =8.782+41.394 -> 50.176 | X31: =407.913+8.752-10.18 -> 406.485 | Y31: =74.501+5.01 -> 79.511 | Z31: 2.735 | AA31: 6.961
B32: Operating Income | C32: =C29-SUM(C30:C31) -> 401.414 | D32: =D29-SUM(D30:D31) -> 479.257 | E32: =E29-SUM(E30:E31) -> 338.115 | F32: =F29-SUM(F30:F31) -> 913.89 | G32: =G29-SUM(G30:G31) -> 432.642 | H32: =H29-SUM(H30:H31) -> 540.226 | I32: =I29-SUM(I30:I31) -> 490.661 | J32: =J29-SUM(J30:J31) -> 1042.168 | ... P32: =P29-SUM(P30:P31) -> 453.653 | T32: =T29-SUM(T30:T31) -> 715.837 | U32: =U29-SUM(U30:U31) -> 889.11 | V32: =V29-SUM(V30:V31) -> 819.986 | W32: =W29-SUM(W30:W31) -> 1333.355 | X32: =X29-SUM(X30:X31) -> 1328.408 | Y32: =Y29-SUM(Y30:Y31) -> 2132.676 | Z32: =Z29-SUM(Z30:Z31) -> 2505.697 | AA32: =AA29-SUM(AA30:AA31) -> 2210.615
B33: Other Income | C33: 8.025 | D33: 7.362 | E33: 9.842 | F33: 17.83 | G33: 23.283 | H33: 17.994 | I33: 13.743 | J33: 15.36 | K33: 11.786 | L33: 9.737 | M33: 5.854 | N33: =+AA33-SUM(K33:M33) -> 0.975 | O33: 9.131 | P33: 13.698 | T33: 9.414 | U33: 8.283 | V33: -0.636 | W33: 0.514 | X33: 4.163 | Y33: 43.059 | Z33: 70.38 | AA33: 28.352
B34: Pretax Income | C34: =C32+C33 -> 409.439 | D34: =D32+D33 -> 486.619 | E34: =E32+E33 -> 347.957 | F34: =F32+F33 -> 931.72 | G34: =G32+G33 -> 455.925 | H34: =H32+H33 -> 558.22 | I34: =I32+I33 -> 504.404 | J34: =J32+J33 -> 1057.528 | ... P34: =P32+P33 -> 467.351 | T34: =T32+T33 -> 725.251 | U34: =U32+U33 -> 897.393 | V34: =V32+V33 -> 819.35 | W34: =W32+W33 -> 1333.869 | X34: =X32+X33 -> 1332.571 | Y34: =Y32+Y33 -> 2175.735 | Z34: =Z32+Z33 -> 2576.077 | AA34: =AA32+AA33 -> 2238.967
B35: Income Tax Expense | C35: 119.034 | D35: 145.016 | E35: 99.243 | F35: 262.252 | G35: 134.504 | H35: 165.298 | I35: 152.534 | J35: 309.125 | K35: 135.839 | L35: 162.646 | M35: 134.905 | N35: =+AA35-SUM(K35:M35) -> 226.394 | O35: 91.029 | P35: 138.128 | T35: 231.449 | U35: 251.797 | V35: 230.437 | W35: 358.547 | X35: 477.771 | Y35: 625.545 | Z35: 761.461 | AA35: 659.784
B36: Net Income | C36: =C34-C35 -> 290.405 | D36: =D34-D35 -> 341.603 | E36: =E34-E35 -> 248.714 | F36: =F34-F35 -> 669.468 | G36: =G34-G35 -> 321.421 | H36: =H34-H35 -> 392.922 | I36: =I34-I35 -> 351.87 | J36: =J34-J35 -> 748.403 | ... P36: =P34-P35 -> 329.223 | T36: =T34-T35 -> 493.802 | U36: =U34-U35 -> 645.596 | V36: =V34-V35 -> 588.913 | W36: =W34-W35 -> 975.322 | X36: =X34-X35 -> 854.8 | Y36: =Y34-Y35 -> 1550.19 | Z36: =Z34-Z35 -> 1814.616 | AA36: =AA34-AA35 -> 1579.183
B38: EPS | C38: =C36/C39 -> 2.2822328 | D38: =D36/D39 -> 2.6904441 | E38: =E36/E39 -> 1.9667405 | F38: =F36/F39 -> 5.303641 | G38: =G36/G39 -> 2.5530271 | H38: =H36/H39 -> 3.1504077 | I38: =I36/I39 -> 2.8677963 | J38: =J36/J39 -> 6.1504319 | ... P38: =P36/P39 -> 2.9161101 | T38: =+T36/T39 -> 3.7013035 | U38: =+U36/U39 -> 4.9511554 | V38: =+V36/V39 -> 4.5200516 | W38: =+W36/W39 -> 7.5158899 | X38: =+X36/X39 -> 6.6955963 | Y38: =+Y36/Y39 -> 12.232612 | Z38: =+Z36/Z39 -> 14.665341 | AA38: =+AA36/AA39 -> 13.272565
B39: Shares | C39: 127.246 | D39: 126.969 | E39: 126.46 | F39: 126.228 | G39: 125.898 | H39: 124.721 | I39: 122.697 | J39: 121.683 | K39: 120.632 | L39: 119.6 | M39: 118.535 | N39: 118.981 | O39: 115.414 | P39: 112.898 | T39: 133.413 | U39: 130.393 | V39: 130.289 | W39: 129.768 | X39: 127.666 | Y39: 126.726 | Z39: 123.735 | AA39: 118.981
B42: Market Share | T42: =+T8 -> 0.021881055 | U42: =+U8 -> 0.025049075 | V42: =+V8 -> 0.026212877 | W42: =+W8 -> 0.035245793 | X42: =+X8 -> 0.043222258 | Y42: =+Y8 -> 0.048494498 | Z42: =+Z8 -> 0.050496378 | AA42: =+AA8 -> 0.050090684 | ... AH42: =+AH8 -> 0.038284787
B43: Store Growth | O43: =+O15/K15-1 -> 0.05974026 | P43: =+P15/L15-1 -> 0.052295918 | U43: =+U15/T15-1 -> 0.11590909 | V43: =+V15/U15-1 -> 0.061099796 | W43: =+W15/V15-1 -> 0.10172745 | X43: =+X15/W15-1 -> 0.14111498 | Y43: =+Y15/X15-1 -> 0.085496183 | Z43: =+Z15/Y15-1 -> 0.078762307 | AA43: =+AA15/Z15-1 -> 0.057366362 | AB43: =+AB15/AA15-1 -> 0.05 | ... AH43: =+AH15/AG15-1 -> 0.02
B44: % Ecommerce | T44: =+T25/T27 -> 0.26118391 | U44: =+U25/U27 -> 0.62851997 | V44: =+V25/V27 -> 0.51888478 | W44: =+W25/W27 -> 0.44400097 | X44: =+X25/X27 -> 0.45617197 | Y44: =+Y25/Y27 -> 0.44817397 | Z44: =+Z25/Z27 -> 0.43165769 | AA44: =+AA25/AA27 -> 0.44302208 | AB44: =+AA44*(1+2%) -> 0.45188253 | AC44: =+AB44*(1+2%) -> 0.46092018 | AD44: =+AC44*(1+2%) -> 0.47013858 | AE44: =+AD44*(1+2%) -> 0.47954135 | AF44: =+AE44*(1+2%) -> 0.48913218 | AG44: =+AF44*(1+2%) -> 0.49891482 | AH44: =+AG44*(1+2%) -> 0.50889312
B45: % Store Sales | T45: =+T24/T27 -> 0.64664134 | U45: =+U24/U27 -> 0.2859355 | V45: =+V24/V27 -> 0.37674979 | W45: =+W24/W27 -> 0.45096208 | X45: =+X24/X27 -> 0.44980197 | Y45: =+Y24/Y27 -> 0.45855375 | Z45: =+Z24/Z27 -> 0.47297057 | AA45: =+AA24/AA27 -> 0.45482536 | AB45: =+AA45*(1-2%) -> 0.44572885 | AC45: =+AB45*(1-2%) -> 0.43681427 | AD45: =+AC45*(1-2%) -> 0.42807799 | AE45: =+AD45*(1-2%) -> 0.41951643 | AF45: =+AE45*(1-2%) -> 0.4111261 | AG45: =+AF45*(1-2%) -> 0.40290358 | AH45: =+AG45*(1-2%) -> 0.3948455
B46: Revenue Growth | G46: =G27/C27-1 -> 0.10400831 | H46: =H27/D27-1 -> 0.073291492 | I46: =I27/E27-1 -> 0.087306246 | J46: =J27/F27-1 -> 0.12679593 | K46: =K27/G27-1 -> 0.073235393 | L46: =L27/H27-1 -> 0.065008827 | M46: =M27/I27-1 -> 0.070623284 | N46: =N27/J27-1 -> 0.0081140868 | ... P46: =P27/L27-1 -> -0.043397424 | U46: =U27/T27-1 -> 0.21013077 | V46: =V27/U27-1 -> 0.10619542 | W46: =W27/V27-1 -> 0.42135143 | X46: =X27/W27-1 -> 0.29631045 | Y46: =Y27/X27-1 -> 0.18602511 | Z46: =Z27/Y27-1 -> 0.10071941 | AA46: =AA27/Z27-1 -> 0.048589713 | AB46: =AB27/AA27-1 -> 0.03 | ... AH46: =AH27/AG27-1 -> 0.01184
...

Sheet Ratios
A1: Main
B2: Ratios | C2: 18 | D2: =+C2+1 -> 19 | E2: =+D2+1 -> 20 | F2: =+E2+1 -> 21 | G2: =+F2+1 -> 22 | H2: =+G2+1 -> 23 | I2: =+H2+1 -> 24 | J2: =+I2+1 -> 25 | K2: FY26
B3: Price | C3: 148.61 | D3: 239.39 | E3: 333.4 | F3: 333.8 | G3: 306.88 | H3: 453.82 | I3: 414.2 | J3: 179.08 | K3: =+Main!I2 -> 99.65
B4: Shares o/s | C4: =+Model!T39 -> 133.413 | D4: =+Model!U39 -> 130.393 | E4: =+Model!V39 -> 130.289 | F4: =+Model!W39 -> 129.768 | G4: =+Model!X39 -> 127.666 | H4: =+Model!Y39 -> 126.726 | I4: =+Model!Z39 -> 123.735 | J4: =+Model!AA39 -> 118.981 | K4: =+Main!I3 -> 105.59406
B5: Market Cap | C5: =+C3*C4 -> 19826.506 | D5: =+D3*D4 -> 31214.78 | E5: =+E3*E4 -> 43438.353 | F5: =+F3*F4 -> 43316.558 | G5: =+G3*G4 -> 39178.142 | H5: =+H3*H4 -> 57510.793 | I5: =+I3*I4 -> 51251.037 | J5: =+J3*J4 -> 21307.117 | K5: =+K3*K4 -> 10522.448
B6: Net Debt | C6: =-Model!T52 -> -881.32 | D6: =-Model!U52 -> -1093.505 | E6: =-Model!V52 -> -1150.517 | F6: =-Model!W52 -> -1259.871 | G6: =-Model!X52 -> -1154.867 | H6: =-Model!Y52 -> -2243.971 | I6: =-Model!Z52 -> -1984.336 | J6: =-Model!AA52 -> -1807.202 | K6: =+Main!I6-Main!I5 -> -189.737
B7: EV | C7: =+C5+C6 -> 18945.186 | D7: =+D5+D6 -> 30121.275 | E7: =+E5+E6 -> 42287.836 | F7: =+F5+F6 -> 42056.687 | G7: =+G5+G6 -> 38023.275 | H7: =+H5+H6 -> 55266.822 | I7: =+I5+I6 -> 49266.701 | J7: =+J5+J6 -> 19499.915 | K7: =+K5+K6 -> 10332.711
A9: x | B9: Value Driver
B10: Capital Emloyed | C10: =+Model!T58+Model!T59+Model!T53+Model!T54+Model!T61+Model!T60-Model!T66 -> 936.571 | D10: =+Model!U58+Model!U59+Model!U53+Model!U54+Model!U61+Model!U60-Model!U66 -> 1864.515 | E10: =+Model!V58+Model!V59+Model!V53+Model!V54+Model!V61+Model!V60-Model!V66 -> 2484.862 | F10: =+Model!W58+Model!W59+Model!W53+Model!W54+Model!W61+Model!W60-Model!W66 -> 2943.186 | G10: =+Model!X58+Model!X59+Model!X53+Model!X54+Model!X61+Model!X60-Model!X66 -> 3692.679 | H10: =+Model!Y58+Model!Y59+Model!Y53+Model!Y54+Model!Y61+Model!Y60-Model!Y66 -> 3935.434 | I10: =+Model!Z58+Model!Z59+Model!Z53+Model!Z54+Model!Z61+Model!Z60-Model!Z66 -> 4658.912 | J10: =+Model!AA58+Model!AA59+Model!AA53+Model!AA54+Model!AA61+Model!AA60-Model!AA66 -> 5415.084 | L10: =Long Term Assets + Working Capital (Exclusive of cash)-Accounts Payables
B11: Invested Capital | C11: =+Model!T53+Model!T54+Model!T55+Model!T56-Model!T66-Model!T67-Model!T68+Model!T58+Model!T60+Model!T61+Model!T59-Model!T74 -> 918.483 | D11: =+Model!U53+Model!U54+Model!U55+Model!U56-Model!U66-Model!U67-Model!U68+Model!U58+Model!U60+Model!U61+Model!U59-Model!U74 -> 1156.079 | E11: =+Model!V53+Model!V54+Model!V55+Model!V56-Model!V66-Model!V67-Model!V68+Model!V58+Model!V60+Model!V61+Model!V59-Model!V74 -> 1759.467 | F11: =+Model!W53+Model!W54+Model!W55+Model!W56-Model!W66-Model!W67-Model!W68+Model!W58+Model!W60+Model!W61+Model!W59-Model!W74 -> 2026.909 | G11: =+Model!X53+Model!X54+Model!X55+Model!X56-Model!X66-Model!X67-Model!X68+Model!X58+Model!X60+Model!X61+Model!X59-Model!X74 -> 2607.24 | H11: =+Model!Y53+Model!Y54+Model!Y55+Model!Y56-Model!Y66-Model!Y67-Model!Y68+Model!Y58+Model!Y60+Model!Y61+Model!Y59-Model!Y74 -> 2474.992 | I11: =+Model!Z53+Model!Z54+Model!Z55+Model!Z56-Model!Z66-Model!Z67-Model!Z68+Model!Z58+Model!Z60+Model!Z61+Model!Z59-Model!Z74 -> 3027.981 | J11: =+Model!AA53+Model!AA54+Model!AA55+Model!AA56-Model!AA66-Model!AA67-Model!AA68+Model!AA58+Model!AA60+Model!AA61+Model!AA59-Model!AA74 -> 3628.587 | L11: =Net Working Capital + PP&E + Other Net Operating Assets (net of Liabilties) + (Intangibles)
B12: Invested Capital (exl. Intangibles)
B13: Total Funds Invested | L13: Invested Capital + Non-Operating Assets
B14: NOPAT | C14: =+(Model!T32+Model!T83)*(1-Model!T50) -> 570.78803 | D14: =+(Model!U32+Model!U83)*(1-Model!U50) -> 756.13377 | E14: =+(Model!V32+Model!V83)*(1-Model!V50) -> 722.68362 | F14: =+(Model!W32+Model!W83)*(1-Model!W50) -> 1138.8851 | G14: =+(Model!X32+Model!X83)*(1-Model!X50) -> 1039.3038 | H14: =+(Model!Y32+Model!Y83)*(1-Model!Y50) -> 1789.8183 | I14: =+(Model!Z32+Model!Z83)*(1-Model!Z50) -> 2079.5758 | J14: =+(Model!AA32+Model!AA83)*(1-Model!AA50) -> 1909.1842 | L14: EBITA * (1-Marginal Tax Rate)
B15: Net Investment | C15: =+D11-C11 -> 237.596 | D15: =+E11-D11 -> 603.388 | E15: =+F11-E11 -> 267.442 | F15: =+G11-F11 -> 580.331 | G15: =+H11-G11 -> -132.248 | H15: =+I11-H11 -> 552.989 | I15: =+J11-I11 -> 600.606 | L15: =Invested Capital (t+1)-Invested Capital (t)
B16: FCF | L16: =NOPAT + non-cash Expenses - Investments in Invested Capital
B17: Investment Rate | C17: =+C15/C14 -> 0.41625961 | D17: =+D15/D14 -> 0.79799107 | E17: =+E15/E14 -> 0.37006789 | F17: =+F15/F14 -> 0.50956063 | G17: =+G15/G14 -> -0.12724672 | H17: =+H15/H14 -> 0.30896377 | I17: =+I15/I14 -> 0.28881178 | L17: =Net Investment/NOPAT
B18: Economic Profit | L18: =Invested Capital *(ROIC-WACC)
A20: x | B20: Efficency-Ratios
B21: Capital Turnover | C21: =+Model!T27/Model!T79 -> 2.2741188 | D21: =+Model!U27/Model!U79 -> 2.0383461 | E21: =+Model!V27/Model!V79 -> 1.7204477 | F21: =+Model!W27/Model!W79 -> 2.2833985 | G21: =+Model!X27/Model!X79 -> 2.5757497 | H21: =+Model!Y27/Model!Y79 -> 2.2729428 | I21: =+Model!Z27/Model!Z79 -> 2.4486612 | J21: =+Model!AA27/Model!AA79 -> 2.2375973 | L21: =Revenue/Equity
B22: Return on Equity (ROE) | C22: =+Model!T36/Model!T79 -> 0.34150106 | D22: =+Model!U36/Model!U79 -> 0.33069872 | E22: =+Model!V36/Model!V79 -> 0.23017307 | F22: =+Model!W36/Model!W79 -> 0.35595096 | G22: =+Model!X36/Model!X79 -> 0.27146858 | H22: =+Model!Y36/Model!Y79 -> 0.36629497 | I22: =+Model!Z36/Model!Z79 -> 0.41965686 | J22: =+Model!AA36/Model!AA79 -> 0.3182656 | L22: =Net Income/Book Value of Equity
B23: Return on Capital Employed (ROCE) | C23: =+Model!T32/Ratios!C10 -> 0.76431685 | D23: =+Model!U32/Ratios!D10 -> 0.47685859 | E23: =+Model!V32/Ratios!E10 -> 0.32999257 | F23: =+Model!W32/Ratios!F10 -> 0.45303117 | G23: =+Model!X32/Ratios!G10 -> 0.35974099 | H23: =+Model!Y32/Ratios!H10 -> 0.54191634 | I23: =+Model!Z32/Ratios!I10 -> 0.53782879 | J23: =+Model!AA32/Ratios!J10 -> 0.40823282 | L23: =EBIT/Capital Employed
B24: Return on Capital Invested (ROIC) | C24: =+C14/C11 -> 0.62144648 | D24: =+D14/D11 -> 0.65405026 | E24: =+E14/E11 -> 0.41074008 | F24: =+F14/F11 -> 0.56188269 | G24: =+G14/G11 -> 0.39862222 | H24: =+H14/H11 -> 0.72316124 | I24: =+I14/I11 -> 0.68678629 | J24: =+J14/J11 -> 0.52615087 | L24: =NOPAT/Invested Capital
B25: Decomposed ROIC | L25: = ROIC = (1-operating cash tax)* (EBITA/Revenues) * (Revenue/Invested Capital)
B27: Retention Rate | L27: =1 - Dividends/Net Income
B28: Reinvestment Rate | L28: =Net CapEx + Change in WC / EBIT * (1-t)
B29: Epected Growth in Net Income | L29: =ROE * Retention Rate
B30: Expected Growth in NOPAT | C30: =+C24*C17 -> 0.25868307 | D30: =+D24*D17 -> 0.52192627 | E30: =+E24*E17 -> 0.15200171 | F30: =+F24*F17 -> 0.2863133 | G30: =+G24*G17 -> -0.05072337 | H30: =+H24*H17 -> 0.22343062 | I30: =+I24*I17 -> 0.19835197 | J30: =+J24*J17 -> 0 | L30: =ROIC * Reinvestment Rate
A32: x | B32: Finacial Stability Ratios
B33: Equity/Debt Ratio | L33: =Book Value of Equtiy/Book Value of Debt
B34: Gearing | L34: =(Debt - Cash (Net Debt))/Book Value of Equity
B35: Interest Coverage Ratio | L35: =EBIT/Interest Expenses
B36: Net Debt / EBITDA | L36: =Net Debt/EBITDA
B37: Cash Burn Rate | L37: =Book Value of Equity/Absolute value of Loss
A39: x | B39: WC-Managment Ratios
B40: Debitor-Duration | L40: =Accounts Receivables/Revenue*360
B41: Creditor-Duration | L41: =Accounts Payable/Revenue*360
B42: Inventory Intensity | L42: =Inventory/Balance Sheet Total
B43: Invetory Turnover | L43: =Cogs/Inventory
B44: Storage-Duration | L44: =360/Inventory Turnover
B45: Cash Conversion Cycle | L45: =Debitor Duration + Storage Duration - Creditor Duration
...

Sheet DCF
A1: Main | B1: DCF
B3: Ticker | E3: LULU | G3: Share Price | J3: =+Main!I2 -> 99.65 | L3: Share Price | O3: =+J3 -> 99.65
B4: Date | E4: =+TODAY() -> 46269 | G4: Fair Share Price | J4: =V62 -> 185.21581 | L4: Scneario DCF Price | O4: =+J15+O15+T15 -> 0
B5: End of FY | E5: 46417 | G5: Implied Upside | J5: =J4/J3-1 -> 0.85866344 | L5: Implied Upside | O5: =O4/O3-1 -> -1
A7: x | B7: Assumptions
B9: Switches | G9: Market Case | L9: Base Case | Q9: Optimistic Case
B10: Assumptions | G10: Assumptions | I10: Year | J10: Metic | L10: Assumptions | N10: Year | O10: Metic | Q10: Assumptions | S10: Year | T10: Metic
B11: Revenue | E11: 1 | G11: Revenue | L11: Revenue | Q11: Revenue
B12: EBIT | E12: 2 | G12: EBIT | L12: EBIT | Q12: EBIT
B13: WACC | E13: 2 | G13: Implied Share Price
B14: TGR | E14: 2 | G14: Probability | L14: Probability | Q14: Probability
B15: ROIC | E15: 2 | G15: Implied Share Price * p | L15: Implied Share Price * p | Q15: Implied Share Price * p
B17: Valuation
B18: WACC | E18: =CHOOSE(E13,J18,O18,T18) -> 0.08 | G18: WACC | J18: 0.09 | L18: WACC | O18: 0.08 | Q18: WACC
B19: TGR | E19: =CHOOSE(E14,J19,O19,T19) -> 0.015 | G19: TGR | J19: 0.01 | L19: TGR | O19: 0.015 | Q19: TGR
B20: RONIC | E20: =CHOOSE(E15,J20,O20,T20) -> 0.1 | G20: RONIC | J20: 0.1 | L20: RONIC | O20: 0.1 | Q20: RONIC
A24: x | B24: Model | G24: 20 | H24: =G24+1 -> 21 | I24: =H24+1 -> 22 | J24: =I24+1 -> 23 | K24: =J24+1 -> 24 | L24: =K24+1 -> 25 | M24: =L24+1 -> 26 | N24: =M24+1 -> 27 | O24: =N24+1 -> 28 | ... V24: =U24+1 -> 35
B25: Revenue | G25: =+Model!V27 -> 4401.879 | H25: =+Model!W27 -> 6256.617 | I25: =+Model!X27 -> 8110.518 | J25: =+Model!Y27 -> 9619.278 | K25: =+Model!Z27 -> 10588.126 | L25: =+Model!AA27 -> 11102.6 | M25: =L25*(1+M26) -> 11102.6 | N25: =M25*(1+N26) -> 11102.6 | O25: =N25*(1+O26) -> 11102.6 | P25: =O25*(1+P26) -> 11102.6 | Q25: =P25*(1+Q26) -> 11102.6 | R25: =Q25*(1+R26) -> 11102.6 | S25: =R25*(1+S26) -> 11102.6 | T25: =S25*(1+T26) -> 11102.6 | ... V25: =U25*(1+V26) -> 11102.6
B26: Growth (%) | H26: =H25/G25-1 -> 0.42135143 | I26: =I25/H25-1 -> 0.29631045 | J26: =J25/I25-1 -> 0.18602511 | K26: =K25/J25-1 -> 0.10071941 | L26: =L25/K25-1 -> 0.048589713 | M26: {=OFFSET(M26,$E$11,,)} -> 0 | N26: {=OFFSET(N26,$E$11,,)} -> 0 | O26: {=OFFSET(O26,$E$11,,)} -> 0 | P26: {=OFFSET(P26,$E$11,,)} -> 0 | Q26: {=OFFSET(Q26,$E$11,,)} -> 0 | R26: {=OFFSET(R26,$E$11,,)} -> 0 | S26: {=OFFSET(S26,$E$11,,)} -> 0 | T26: {=OFFSET(T26,$E$11,,)} -> 0 | ... V26: {=OFFSET(V26,$E$11,,)} -> 0
B27: Conservative Case | M27: 0 | N27: 0 | O27: 0 | P27: 0 | Q27: 0 | R27: 0 | S27: 0 | T27: 0 | U27: 0 | V27: 0
B28: Base Case | M28: =+Model!AB46 -> 0.03 | N28: =+Model!AC46 -> 0.01184 | O28: =+Model!AD46 -> 0.01184 | P28: =+Model!AE46 -> 0.01184 | Q28: =+Model!AF46 -> 0.01184 | R28: =+Model!AG46 -> 0.01184 | S28: =+Model!AH46 -> 0.01184 | T28: 0.012 | U28: 0.012 | V28: 0.012
B29: Optimisitic Case
B31: EBIT | G31: =+Model!V32 -> 819.986 | H31: =+Model!W32 -> 1333.355 | I31: =+Model!X32 -> 1328.408 | J31: =+Model!Y32 -> 2132.676 | K31: =+Model!Z32 -> 2505.697 | L31: =+Model!AA32 -> 2210.615 | M31: =M32*M25 -> 1443.338 | N31: =N32*N25 -> 1998.468 | O31: =O32*O25 -> 2109.494 | P31: =P32*P25 -> 2220.52 | Q31: =Q32*Q25 -> 2331.546 | R31: =R32*R25 -> 2442.572 | S31: =S32*S25 -> 2553.598 | T31: =T32*T25 -> 2664.624 | ... V31: =V32*V25 -> 2775.65
B32: % of Sales | G32: =G31/G25 -> 0.1862809 | H32: =H31/H25 -> 0.21311117 | I32: =I31/I25 -> 0.16378831 | J32: =J31/J25 -> 0.22170853 | K32: =K31/K25 -> 0.2366516 | L32: =L31/L25 -> 0.19910787 | M32: {=OFFSET(M32,$E$12,,)} -> 0.13 | N32: {=OFFSET(N32,$E$12,,)} -> 0.18 | O32: {=OFFSET(O32,$E$12,,)} -> 0.19 | P32: {=OFFSET(P32,$E$12,,)} -> 0.2 | Q32: {=OFFSET(Q32,$E$12,,)} -> 0.21 | R32: {=OFFSET(R32,$E$12,,)} -> 0.22 | S32: {=OFFSET(S32,$E$12,,)} -> 0.23 | T32: {=OFFSET(T32,$E$12,,)} -> 0.24 | ... V32: {=OFFSET(V32,$E$12,,)} -> 0.25
B33: Conservative Case | M33: 0.11 | N33: 0.15 | O33: 0.16 | P33: 0.16 | Q33: 0.16 | R33: 0.16 | S33: 0.16 | T33: 0.16 | U33: 0.16 | V33: 0.16
B34: Base Case | M34: 0.13 | N34: 0.18 | O34: 0.19 | P34: 0.2 | Q34: 0.21 | R34: 0.22 | S34: 0.23 | T34: 0.24 | U34: 0.25 | V34: 0.25
B35: Optimisitic Case
B37: Taxes | G37: =+Model!V35 -> 230.437 | H37: =+Model!W35 -> 358.547 | I37: =+Model!X35 -> 477.771 | J37: =+Model!Y35 -> 625.545 | K37: =+Model!Z35 -> 761.461 | L37: =+Model!AA35 -> 659.784 | M37: =M38*M31 -> 418.56802 | N37: =N38*N31 -> 579.55572 | O37: =O38*O31 -> 611.75326 | P37: =P38*P31 -> 643.9508 | Q37: =Q38*Q31 -> 676.14834 | R37: =R38*R31 -> 708.34588 | S37: =S38*S31 -> 740.54342 | T37: =T38*T31 -> 772.74096 | ... V37: =V38*V31 -> 804.9385
B38: Tax Rate (%) | G38: =G37/G31 -> 0.28102553 | H38: =H37/H31 -> 0.26890588 | I38: =I37/I31 -> 0.35965682 | J38: =J37/J31 -> 0.2933146 | K38: =K37/K31 -> 0.30389189 | L38: =L37/L31 -> 0.29846174 | M38: 0.29 | N38: 0.29 | O38: 0.29 | P38: 0.29 | Q38: 0.29 | R38: 0.29 | S38: 0.29 | T38: 0.29 | U38: 0.29 | V38: 0.29
B40: Nopat | G40: =G31-G37 -> 589.549 | H40: =H31-H37 -> 974.808 | I40: =I31-I37 -> 850.637 | J40: =J31-J37 -> 1507.131 | K40: =K31-K37 -> 1744.236 | L40: =L31-L37 -> 1550.831 | M40: =M31-M37 -> 1024.77 | N40: =N31-N37 -> 1418.9123 | ... V40: =V31-V37 -> 1970.7115
B42: D&A and other non-cash Expenses | G42: =+Model!V83 -> 185.478 | H42: =+Model!W83 -> 224.206 | I42: =+Model!X83 -> 291.791 | J42: =+Model!Y83 -> 379.384 | K42: =+Model!Z83 -> 446.524 | L42: =+Model!AA83 -> 496.228 | M42: =M43*M25 -> 499.617 | N42: =N43*N25 -> 499.617 | O42: =O43*O25 -> 499.617 | P42: =P43*P25 -> 499.617 | Q42: =Q43*Q25 -> 499.617 | R42: =R43*R25 -> 499.617 | S42: =S43*S25 -> 499.617 | T42: =T43*T25 -> 499.617 | ... V42: =V43*V25 -> 499.617
B43: % of Sales | G43: =G42/G25 -> 0.042136097 | H43: =H42/H25 -> 0.035835021 | I43: =I42/I25 -> 0.035976864 | J43: =J42/J25 -> 0.039439966 | K43: =K42/K25 -> 0.042172146 | L43: =L42/L25 -> 0.044694756 | M43: 0.045 | N43: 0.045 | O43: 0.045 | P43: 0.045 | Q43: 0.045 | R43: 0.045 | S43: 0.045 | T43: 0.045 | U43: 0.045 | V43: 0.045
B45: CapEx | G45: =+Model!V103 -> -229.226 | H45: =+Model!W103 -> -394.502 | I45: =+Model!X103 -> -638.657 | J45: =+Model!Y103 -> -651.865 | K45: =+Model!Z103 -> -689.232 | L45: =+Model!AA103 -> -680.802 | M45: =M46*M25 -> -777.182 | N45: =N46*N25 -> -777.182 | O45: =O46*O25 -> -777.182 | P45: =P46*P25 -> -777.182 | Q45: =Q46*Q25 -> -777.182 | R45: =R46*R25 -> -777.182 | S45: =S46*S25 -> -777.182 | T45: =T46*T25 -> -777.182 | ... V45: =V46*V25 -> -777.182
B46: % of Sales | G46: =G45/G25 -> -0.05207458 | H46: =H45/H25 -> -0.063053564 | I46: =I45/I25 -> -0.078744292 | J46: =J45/J25 -> -0.067766521 | K46: =K45/K25 -> -0.065094805 | L46: =L45/L25 -> -0.06131915 | M46: -0.07 | N46: -0.07 | O46: -0.07 | P46: -0.07 | Q46: -0.07 | R46: -0.07 | S46: -0.07 | T46: -0.07 | U46: -0.07 | V46: -0.07
B48: Change in WC | G48: =+Model!V101 -> -47.549 | H48: =+Model!W101 -> 129.131 | I48: =+Model!X101 -> -659.92 | J48: =+Model!Y101 -> 199.223 | K48: =+Model!Z101 -> -51.895 | L48: =+Model!AA101 -> -409.43 | M48: =M49*M25 -> -333.078 | N48: =N49*N25 -> -333.078 | O48: =O49*O25 -> -333.078 | P48: =P49*P25 -> -333.078 | Q48: =Q49*Q25 -> -333.078 | R48: =R49*R25 -> -333.078 | S48: =S49*S25 -> -333.078 | T48: =T49*T25 -> -333.078 | ... V48: =V49*V25 -> -333.078
B49: % of Sales | G49: =G48/G25 -> -0.010801978 | H49: =H48/H25 -> 0.020639109 | I49: =I48/I25 -> -0.08136595 | J49: =J48/J25 -> 0.020710806 | K49: =K48/K25 -> -0.004901245 | L49: =L48/L25 -> -0.036876948 | M49: -0.03 | N49: -0.03 | O49: -0.03 | P49: -0.03 | Q49: -0.03 | R49: -0.03 | S49: -0.03 | T49: -0.03 | U49: -0.03 | V49: -0.03
B51: Unlevered Free Cashflow | G51: =G40+G42+G45+G48 -> 498.252 | H51: =H40+H42+H45+H48 -> 933.643 | I51: =I40+I42+I45+I48 -> -156.149 | J51: =J40+J42+J45+J48 -> 1433.873 | K51: =K40+K42+K45+K48 -> 1449.633 | L51: =L40+L42+L45+L48 -> 956.827 | M51: =M40+M42+M45+M48 -> 414.12698 | N51: =N40+N42+N45+N48 -> 808.26928 | ... V51: =V40+V42+V45+V48 -> 1360.0685
B52: Present Value of unlevered FC | M52: =(M51/(1+$E$18)^M53)*M53 -> 162.79036 | N52: =N51/(1+$E$18)^N53 -> 725.39929 | O52: =O51/(1+$E$18)^O53 -> 737.1719 | P52: =P51/(1+$E$18)^P53 -> 743.22017 | Q52: =Q51/(1+$E$18)^Q53 -> 744.32757 | R52: =R51/(1+$E$18)^R53 -> 741.19288 | S52: =S51/(1+$E$18)^S53 -> 734.43849 | T52: =T51/(1+$E$18)^T53 -> 724.61784 | U52: =U51/(1+$E$18)^U53 -> 712.22227 | V52: =V51/(1+$E$18)^V53 -> 659.46506
B53: Discount Period | M53: =YEARFRAC(E4,E5) -> 0.40555556 | N53: =M53+1 -> 1.4055556 | O53: =N53+1 -> 2.4055556 | P53: =O53+1 -> 3.4055556 | Q53: =P53+1 -> 4.4055556 | R53: =Q53+1 -> 5.4055556 | S53: =R53+1 -> 6.4055556 | T53: =S53+1 -> 7.4055556 | U53: =T53+1 -> 8.4055556 | V53: =U53+1 -> 9.4055556
B54: Sum of Present Value | V54: =SUM(M52:V52) -> 6684.8458
...
