Workbook

Sheet Main
A1: LVMH
A2: numbers in mio EUR
B4: Investors | H4: Price | I4: 459.1
B5: MC.PA | H5: Shares | I5: 495.81108 | J5: Q226
H6: MC | I6: =I5*I4 -> 227626.87
B7: Segments | C7: % of Rev | D7: Brands/Products | E7: Competition | H7: Cash | I7: 6803 | J7: Q226
B8: Wines & Spirits | C8: 0.07 | D8: Hennessy, Moet & Chandon, Dom Perignon, Vueve Clicqout, Krug etc. | H8: Debt | I8: =13041+7444 -> 20485 | J8: Q226
B9: Fashion & Leather Goods | C9: 0.51 | D9: Louis Vuitton, Givenchy, Rimowa, Kenzo, Loro Piana, Fendi, Celine, Loewe etc. | E9: Hermes, Kering | H9: EV | I9: =I6+I8-I7 -> 241308.87
B10: Perfumes & Cosmetics | C10: 0.11 | D10: Parfums Christian Dior, LV, Guerlain, Aqua de Parma, Stella McCartney etc.
B11: Watches & Jevelery | C11: 0.12 | D11: Tiffany & Co, Bulgari, TAG Heuer, Hublot, Zenith, Chaumet, Repossi etc. | E11: Richemont | H11: Founded 1987
B12: Selective Retailing | C12: 0.2 | D12: Sephora, Le Bon Marche, 24S, DFS, La Grande Ecipiere de Paris | H12: Employee Count: 213.618
H13: Management
A14: x | B14: Notes | H14: CEO and Chairman | J14: Bernard Arnault
B15: 75 Maisons (2025) | H15: CFO | J15: Cecile Cabanis
H16: CEO Dior | J16: Delphine Arnault
B17: Increased stake in Loro Piana Q425 | H17: Group Manager | J17: Stephane Bianchi
B18: Sale of Marc Jacob | H18: Fashion Group | J18: Michael Burke
H19: CEO Wines & Spirits | J19: Jean-Jacques Guiony
B24: History:
B25: Founded 1987 through a merger of Louis Vuitton, Moet & Chandon and Hennessy -> orechestrated by Bernard Arnault
B26: Louis Vuitton founded 1854 in France, on of Frenchs first fashion labels that concentrated on selling to royals and elites
B27: Moet & Chandon founded in 1743, Hennesy founded in 1765 -> merged in 1971 to Moet Hennesy
B28: Bernard Arnault -> after University joined the construction company of his father Ferret-Savinel
B29: 1984: Arnault acquired Boussac Saint-Fères -> struggling textile company (owned Dior) through an LBO with Lazard for 80 mio EUR
B30: Arnault restructured the company, sold off many segments -> only kept Dior and Le Bon Marché -> turned it around, gained 400 mio EUR
B31: Before the Acqusition famous cab ride in NY -> the cab driver didn't know the French President -> said: "No, but I know Christian Dior".
B32: After the Cration LVMH -> aggressive expansion: Givenchy (1989), Celine (1996), Tag Heuer (1999),
B46: https://quartr.com/insights/company-research/lvmh-guardians-of-tradition-engineers-of-desirability

Sheet Quarters
A1: Main
C2: Q124 | D2: Q224 | E2: Q324 | F2: Q424 | G2: Q125 | H2: Q225 | I2: Q325 | J2: Q425 | K2: Q126 | L2: Q226 | M2: Q326 | N2: Q426
B3: United States | C3: =23%*$C$15 -> 4759.62 | G3: =24%*$G$15 -> 4874.64
B4: France | C4: =7%*$C$15 -> 1448.58 | G4: =8%*$G$15 -> 1624.88
B5: Euorpe | C5: =15%*$C$15 -> 3104.1 | G5: =15%*$G$15 -> 3046.65
B6: Asia | C6: =33%*$C$15 -> 6829.02 | G6: =30%*$G$15 -> 6093.3
B7: Japan | C7: =9%*$C$15 -> 1862.46 | G7: =9%*$G$15 -> 1827.99
B8: Other Markets | C8: =13%*$C$15 -> 2690.22 | G8: =14%*$G$15 -> 2843.54
B9: Wines & Spirits | C9: 1417 | D9: 1391 | E9: 1386 | G9: 1305 | H9: 1283 | I9: 1330 | J9: =+Model!S13-SUM(Quarters!G9:I9) -> 1440 | K9: 1273
B10: Fashion & Leather Goods | C10: 10490 | D10: 10281 | E10: 9151 | G10: 10108 | H10: 9006 | I10: 8497 | J10: =+Model!S14-SUM(Quarters!G10:I10) -> 10159 | K10: 9247
B11: Perfumes & Cosmetics | C11: 2182 | D11: 1953 | E11: 2012 | G11: 2178 | H11: 1904 | I11: 1958 | J11: =+Model!S15-SUM(Quarters!G11:I11) -> 2134 | K11: 2038
B12: Watches & Jevelery | C12: 2466 | D12: 2685 | E12: 2386 | G12: 2482 | H12: 2608 | I12: 2319 | J12: =+Model!S16-SUM(Quarters!G12:I12) -> 3077 | K12: 2443
B13: Selective Retailing | C13: 4175 | D13: 4457 | E13: 3927 | G13: 4189 | H13: 4431 | I13: 3992 | J13: =+Model!S17-SUM(Quarters!G13:I13) -> 5736 | K13: 4048
B14: Other | C14: -36 | D14: =552-336 -> 216 | E14: 214 | G14: 49 | H14: =609-341 -> 268 | I14: 185 | J14: =+Model!S18-SUM(Quarters!G14:I14) -> 169 | K14: 72
B15: Revenue | C15: =+SUM(C9:C14) -> 20694 | D15: =+SUM(D9:D14) -> 20983 | E15: =+SUM(E9:E14) -> 19076 | G15: =+SUM(G9:G14) -> 20311 | H15: =+SUM(H9:H14) -> 19500 | I15: =+SUM(I9:I14) -> 18281 | J15: =+Model!S19-SUM(Quarters!G15:I15) -> 22715 | K15: 19121
B17: US Growth | G17: =+G3/C3-1 -> 0.024165795 | H17: =+H3/D3-1 -> #DIV/0! | I17: =+I3/E3-1 -> #DIV/0! | J17: =+J3/F3-1 -> #DIV/0! | K17: =+K3/G3-1 -> -1
B18: France Growth | G18: =+G4/C4-1 -> 0.12170539 | H18: =+H4/D4-1 -> #DIV/0! | I18: =+I4/E4-1 -> #DIV/0! | J18: =+J4/F4-1 -> #DIV/0! | K18: =+K4/G4-1 -> -1
B19: Europe Growth | G19: =+G5/C5-1 -> -0.01850778 | H19: =+H5/D5-1 -> #DIV/0! | I19: =+I5/E5-1 -> #DIV/0! | J19: =+J5/F5-1 -> #DIV/0! | K19: =+K5/G5-1 -> -1
B20: Asia Growth | G20: =+G6/C6-1 -> -0.10773435 | H20: =+H6/D6-1 -> #DIV/0! | I20: =+I6/E6-1 -> #DIV/0! | J20: =+J6/F6-1 -> #DIV/0! | K20: =+K6/G6-1 -> -1
B21: Japan Growth | G21: =+G7/C7-1 -> -0.01850778 | H21: =+H7/D7-1 -> #DIV/0! | I21: =+I7/E7-1 -> #DIV/0! | J21: =+J7/F7-1 -> #DIV/0! | K21: =+K7/G7-1 -> -1
B22: Others Growth | G22: =+G8/C8-1 -> 0.056991622 | H22: =+H8/D8-1 -> #DIV/0! | I22: =+I8/E8-1 -> #DIV/0! | J22: =+J8/F8-1 -> #DIV/0! | K22: =+K8/G8-1 -> -1
B23: Wines Growth | G23: =+G9/C9-1 -> -0.079040226 | H23: =+H9/D9-1 -> -0.077641984 | I23: =+I9/E9-1 -> -0.04040404 | J23: =+J9/F9-1 -> #DIV/0! | K23: =+K9/G9-1 -> -0.024521073
B24: Fashion Growth | G24: =+G10/C10-1 -> -0.036415634 | H24: =+H10/D10-1 -> -0.12401517 | I24: =+I10/E10-1 -> -0.071467599 | J24: =+J10/F10-1 -> #DIV/0! | K24: =+K10/G10-1 -> -0.085180055
B25: Cosmetics Growth | G25: =+G11/C11-1 -> -0.0018331806 | H25: =+H11/D11-1 -> -0.025089606 | I25: =+I11/E11-1 -> -0.026838966 | J25: =+J11/F11-1 -> #DIV/0! | K25: =+K11/G11-1 -> -0.064279155
B26: Jewelery Groth | G26: =+G12/C12-1 -> 0.0064882401 | H26: =+H12/D12-1 -> -0.02867784 | I26: =+I12/E12-1 -> -0.028080469 | J26: =+J12/F12-1 -> #DIV/0! | K26: =+K12/G12-1 -> -0.015713135
B27: Selective Retail Growth | G27: =+G13/C13-1 -> 0.0033532934 | H27: =+H13/D13-1 -> -0.0058335203 | I27: =+I13/E13-1 -> 0.016552075 | J27: =+J13/F13-1 -> #DIV/0! | K27: =+K13/G13-1 -> -0.033659585
B28: Revenue Growth | G28: =+G15/C15-1 -> -0.01850778 | H28: =+H15/D15-1 -> -0.070676262 | I28: =+I15/E15-1 -> -0.041675404 | J28: =+J15/F15-1 -> #DIV/0! | K28: =+K15/G15-1 -> -0.058588942

Sheet Model
A1: Main
C2: H123 | D2: H223 | E2: H124 | F2: H224 | G2: H125 | H2: H225 | I2: H126 | J2: H226 | L2: FY18 | M2: FY19 | N2: FY20 | O2: FY21 | P2: FY22 | Q2: FY23 | R2: FY24 | S2: FY25 | T2: FY26 | U2: FY27 | V2: FY28 | W2: FY29 | X2: FY30 | Y2: FY31 | Z2: FY32 | AA2: FY33 | AB2: FY34
B3: Stores Europe | F3: 1254 | G3: 1245 | H3: 1255 | I3: 1253 | P3: 1108 | Q3: 1213 | R3: 1254 | S3: 1255 | T3: =+S3*(1+4%) -> 1305.2 | U3: =+T3*(1+4%) -> 1357.408 | V3: =+U3*(1+4%) -> 1411.7043 | W3: =+V3*(1+4%) -> 1468.1725 | X3: =+W3*(1+4%) -> 1526.8994 | Y3: =+X3*(1+4%) -> 1587.9754 | Z3: =+Y3*(1+4%) -> 1651.4944 | AA3: =+Z3*(1+4%) -> 1717.5542 | AB3: =+AA3*(1+4%) -> 1786.2563
B4: Stores France | F4: 553 | G4: 543 | H4: 539 | I4: 533 | P4: 518 | Q4: 550 | R4: 553 | S4: 539 | T4: =+S4*(1+2%) -> 549.78 | U4: =+T4*(1+2%) -> 560.7756 | V4: =+U4*(1+2%) -> 571.99111 | W4: =+V4*(1+2%) -> 583.43093 | X4: =+W4*(1+2%) -> 595.09955 | Y4: =+X4*(1+2%) -> 607.00154 | Z4: =+Y4*(1+2%) -> 619.14157 | AA4: =+Z4*(1+2%) -> 631.52441 | AB4: =+AA4*(1+2%) -> 644.15489
B5: Stores Asia | F5: 2019 | G5: 1991 | H5: 1905 | I5: 1832 | P5: 1829 | Q5: 2003 | R5: 2019 | S5: 1905 | T5: =+S5*(1+3%) -> 1962.15 | U5: =+T5*(1+3%) -> 2021.0145 | V5: =+U5*(1+3%) -> 2081.6449 | W5: =+V5*(1+3%) -> 2144.0943 | X5: =+W5*(1+3%) -> 2208.4171 | Y5: =+X5*(1+3%) -> 2274.6696 | Z5: =+Y5*(1+3%) -> 2342.9097 | AA5: =+Z5*(1+3%) -> 2413.197 | AB5: =+AA5*(1+3%) -> 2485.5929
B6: Stores Japan | F6: 510 | G6: 508 | H6: 520 | I6: 511 | P6: 496 | Q6: 497 | R6: 510 | S6: 520 | T6: =+S6*(1+1%) -> 525.2 | U6: =+T6*(1+1%) -> 530.452 | V6: =+U6*(1+1%) -> 535.75652 | W6: =+V6*(1+1%) -> 541.11409 | X6: =+W6*(1+1%) -> 546.52523 | Y6: =+X6*(1+1%) -> 551.99048 | Z6: =+Y6*(1+1%) -> 557.51038 | AA6: =+Z6*(1+1%) -> 563.08549 | AB6: =+AA6*(1+1%) -> 568.71634
B7: Stores USA | F7: 1193 | G7: 1222 | H7: 1232 | I7: 1237 | P7: 1054 | Q7: 1128 | R7: 1193 | S7: 1232 | T7: =+S7*(1+2%) -> 1256.64 | U7: =+T7*(1+2%) -> 1281.7728 | V7: =+U7*(1+2%) -> 1307.4083 | W7: =+V7*(1+2%) -> 1333.5564 | X7: =+W7*(1+2%) -> 1360.2275 | Y7: =+X7*(1+2%) -> 1387.4321 | Z7: =+Y7*(1+2%) -> 1415.1807 | AA7: =+Z7*(1+2%) -> 1443.4844 | AB7: =+AA7*(1+2%) -> 1472.354
B8: Stores Other Markets | F8: 778 | G8: 804 | H8: 832 | I8: 851 | P8: 659 | Q8: 706 | R8: 778 | S8: 832 | T8: =+S8*(1+2%) -> 848.64 | U8: =+T8*(1+2%) -> 865.6128 | V8: =+U8*(1+2%) -> 882.92506 | W8: =+V8*(1+2%) -> 900.58356 | X8: =+W8*(1+2%) -> 918.59523 | Y8: =+X8*(1+2%) -> 936.96713 | Z8: =+Y8*(1+2%) -> 955.70648 | AA8: =+Z8*(1+2%) -> 974.8206 | AB8: =+AA8*(1+2%) -> 994.31702
B9: Total Stores | F9: =+SUM(F3:F8) -> 6307 | G9: =+SUM(G3:G8) -> 6313 | H9: =+SUM(H3:H8) -> 6283 | I9: =+SUM(I3:I8) -> 6217 | P9: 5664 | Q9: 6097 | R9: 6307 | S9: 6307 | T9: =+SUM(T3:T8) -> 6447.61 | U9: =+SUM(U3:U8) -> 6617.0357 | V9: =+SUM(V3:V8) -> 6791.4302 | W9: =+SUM(W3:W8) -> 6970.9518 | X9: =+SUM(X3:X8) -> 7155.7641 | Y9: =+SUM(Y3:Y8) -> 7346.0362 | Z9: =+SUM(Z3:Z8) -> 7541.9433 | AA9: =+SUM(AA3:AA8) -> 7743.666 | AB9: =+SUM(AB3:AB8) -> 7951.3915
B10: ARPS | F10: =+F19/F9 -> 6.8187728 | G10: =+G19/G9 -> 6.3060352 | H10: =+H19/H9 -> 6.5250676 | I10: =+I19/I9 -> 6.2158597 | L10: =+L19/L9 -> #DIV/0! | M10: =+M19/M9 -> #DIV/0! | N10: =+N19/N9 -> #DIV/0! | O10: =+O19/O9 -> #DIV/0! | P10: =+P19/P9 -> 13.980226 | Q10: =+Q19/Q9 -> 14.130392 | R10: =+R19/R9 -> 13.426827 | S10: =+S19/S9 -> 12.812272 | T10: 13 | U10: 13.4 | V10: 13.8 | W10: 14.2 | X10: 14.6 | Y10: 15 | Z10: 15 | AA10: 15 | AB10: 15
A12: x | B12: Income Statement
B13: Wines & Spirits | C13: 3181 | D13: =Q13-C13 -> 3421 | E13: 2807 | F13: =+R13-SUM(E13) -> 3055 | G13: 2588 | H13: =+S13-G13 -> 2770 | I13: 2598 | L13: 5143 | M13: 5576 | N13: 4755 | O13: 5974 | P13: 7099 | Q13: 6602 | R13: 5862 | S13: 5358
B14: Fashion & Leather Goods | C14: 21162 | D14: =Q14-C14 -> 21007 | E14: 20771 | F14: =+R14-SUM(E14) -> 20289 | G14: 19115 | H14: =+S14-G14 -> 18655 | I14: 18146 | L14: 18455 | M14: 22237 | N14: 21207 | O14: 30896 | P14: 38648 | Q14: 42169 | R14: 41060 | S14: 37770
B15: Perfumes & Cosmetics | C15: 4028 | D15: =Q15-C15 -> 4243 | E15: 4136 | F15: =+R15-SUM(E15) -> 4282 | G15: 4082 | H15: =+S15-G15 -> 4092 | I15: 3914 | L15: 6092 | M15: 6835 | N15: 5248 | O15: 6608 | P15: 7722 | Q15: 8271 | R15: 8418 | S15: 8174
B16: Watches & Jewelery | C16: 5427 | D16: =Q16-C16 -> 5475 | E16: 5150 | F16: =+R16-SUM(E16) -> 5427 | G16: 5090 | H16: =+S16-G16 -> 5396 | I16: 5225 | L16: 4123 | M16: 4405 | N16: 3356 | O16: 8694 | P16: 10581 | Q16: 10902 | R16: 10577 | S16: 10486
B17: Selective Retailing | C17: 8355 | D17: =Q17-C17 -> 9530 | E17: 8632 | F17: =+R17-SUM(E17) -> 9630 | G17: 8620 | H17: =+S17-G17 -> 9728 | I17: 8406 | L17: 13646 | M17: 14791 | N17: 10155 | O17: 11754 | P17: 14852 | Q17: 17885 | R17: 18262 | S17: 18348
B18: Other | C18: 87 | D18: =Q18-C18 -> 237 | E18: 181 | F18: =+R18-SUM(E18) -> 323 | G18: 315 | H18: =+S18-G18 -> 356 | I18: 356 | L18: -633 | M18: -174 | N18: -70 | O18: 0 | P18: 0 | Q18: 324 | R18: 504 | S18: 671
B19: Revenue | C19: =SUM(C13:C18) -> 42240 | D19: =SUM(D13:D18) -> 43913 | E19: =SUM(E13:E18) -> 41677 | F19: =SUM(F13:F18) -> 43006 | G19: =SUM(G13:G18) -> 39810 | H19: =+S19-G19 -> 40997 | I19: 38644 | L19: 46826 | M19: 53670 | N19: 44651 | O19: 64215 | P19: 79184 | Q19: 86153 | R19: 84683 | S19: =+SUM(S13:S18) -> 80807 | T19: =+T9*T10 -> 83818.93 | U19: =+U9*U10 -> 88668.278 | V19: =+V9*V10 -> 93721.737 | W19: =+W9*W10 -> 98987.515 | X19: =+X9*X10 -> 104474.16 | Y19: =+Y9*Y10 -> 110190.54 | Z19: =+Z9*Z10 -> 113129.15 | AA19: =+AA9*AA10 -> 116154.99 | AB19: =+AB9*AB10 -> 119270.87
B20: COGS | C20: 12923 | D20: =Q20-C20 -> 13953 | E20: 12984 | F20: =+R20-SUM(E20) -> 14934 | G20: 13200 | H20: =+S20-G20 -> 14079 | I20: 12708 | L20: 15625 | M20: 18123 | N20: 15871 | O20: 20355 | P20: 24988 | Q20: 26876 | R20: 27918 | S20: 27279
B21: Gross Profit | C21: =C19-C20 -> 29317 | D21: =D19-D20 -> 29960 | E21: =E19-E20 -> 28693 | F21: =F19-F20 -> 28072 | G21: =G19-G20 -> 26610 | H21: =H19-H20 -> 26918 | I21: =I19-I20 -> 25936 | L21: =L19-L20 -> 31201 | M21: =M19-M20 -> 35547 | N21: =N19-N20 -> 28780 | O21: =O19-O20 -> 43860 | P21: =P19-P20 -> 54196 | Q21: =Q19-Q20 -> 59277 | R21: =R19-R20 -> 56765 | S21: =S19-S20 -> 53528
B22: Marketing and Sales | C22: 14915 | D22: =Q22-C22 -> 15853 | E22: 14999 | F22: =+R22-SUM(E22) -> 16003 | G22: 14732 | H22: =+S22-G22 -> 15182 | I22: 14392 | L22: 17755 | M22: 20207 | N22: 16792 | O22: 22308 | P22: 28151 | Q22: 30768 | R22: 31002 | S22: 29914
B23: General & Admminstrative Expenses | C23: 2823 | D23: =Q23-C23 -> 2891 | E23: 3035 | F23: =+R23-SUM(E23) -> 3185 | G23: 2889 | H23: =+S23-G23 -> 3045 | I23: 2876 | L23: 3466 | M23: 3864 | N23: 3641 | O23: 4414 | P23: 5027 | Q23: 5714 | R23: 6220 | S23: 5934
B24: Income from Joint Ventures | C24: -5 | D24: =Q24-C24 -> 12 | E24: -6 | F24: =+R24-SUM(E24) -> 34 | G24: 23 | H24: =+S24-G24 -> 52 | I24: 23 | L24: 23 | M24: 28 | N24: -42 | O24: 13 | P24: 37 | Q24: 7 | R24: 28 | S24: 75
B25: Other Operating Income | C25: -10 | D25: =Q25-C25 -> -232 | E25: -29 | F25: =+R25-SUM(E25) -> -635 | G25: -14 | H25: =+S25-G25 -> -642 | I25: 23 | L25: -126 | M25: -231 | N25: -333 | O25: 4 | P25: -54 | Q25: -242 | R25: -664 | S25: -656
B26: Operating Income | C26: =C21-C22-C23+C24+C25 -> 11564 | D26: =D21-D22-D23+D24+D25 -> 10996 | E26: =E21-E22-E23+E24+E25 -> 10624 | F26: =F21-F22-F23+F24+F25 -> 8283 | G26: =G21-G22-G23+G24+G25 -> 8998 | H26: =H21-H22-H23+H24+H25 -> 8101 | I26: =I21-I22-I23+I24+I25 -> 8714 | L26: =L21-L22-L23+L24+L25 -> 9877 | M26: =M21-M22-M23+M24+M25 -> 11273 | N26: =N21-N22-N23+N24+N25 -> 7972 | O26: =O21-O22-O23+O24+O25 -> 17155 | P26: =P21-P22-P23+P24+P25 -> 21001 | Q26: =Q21-Q22-Q23+Q24+Q25 -> 22560 | R26: =R21-R22-R23+R24+R25 -> 18907 | S26: =S21-S22-S23+S24+S25 -> 17099
B27: Cost of financial debt | C27: 171 | D27: =Q27-C27 -> 196 | E27: 235 | F27: =+R27-SUM(E27) -> 207 | G27: 211 | H27: =+S27-G27 -> 137 | I27: 192 | L27: 117 | M27: 107 | N27: 35 | O27: -41 | P27: 17 | Q27: 367 | R27: 442 | S27: 348
B28: Interest Expenses on Leases | C28: 160 | D28: =Q28-C28 -> 233 | E28: 241 | F28: =+R28-SUM(E28) -> 269 | G28: 278 | H28: =+S28-G28 -> 275 | I28: 261 | L28: 0 | M28: 290 | N28: 281 | O28: 242 | P28: 254 | Q28: 393 | R28: 510 | S28: 553
B29: Other financial Income | C29: 798 | D29: =Q29-C29 -> -973 | E29: 221 | F29: =+R29-SUM(E29) -> -61 | G29: 54 | H29: =+S29-G29 -> 446 | I29: 341 | L29: -271 | M29: -162 | N29: -292 | O29: 254 | P29: -617 | Q29: -175 | R29: 160 | S29: 500
B30: Pretax Income | C30: =C26-C27-C28+C29 -> 12031 | D30: =D26-D27-D28+D29 -> 9594 | E30: =E26-E27-E28+E29 -> 10369 | F30: =F26-F27-F28+F29 -> 7746 | G30: =G26-G27-G28+G29 -> 8563 | H30: =H26-H27-H28+H29 -> 8135 | I30: =I26-I27-I28+I29 -> 8602 | L30: =L26-L27-L28+L29 -> 9489 | M30: =M26-M27-M28+M29 -> 10714 | N30: =N26-N27-N28+N29 -> 7364 | O30: =O26-O27-O28+O29 -> 17208 | P30: =P26-P27-P28+P29 -> 20113 | Q30: =Q26-Q27-Q28+Q29 -> 21625 | R30: =R26-R27-R28+R29 -> 18115 | S30: =S26-S27-S28+S29 -> 16698
B31: Income Tax | C31: 3129 | D31: =Q31-C31 -> 2544 | E31: 2805 | F31: =+R31-SUM(E31) -> 2352 | G31: 2648 | H31: =+S31-G31 -> 2828 | I31: 2583 | L31: 2499 | M31: 2932 | N31: 2409 | O31: 4510 | P31: 5362 | Q31: 5673 | R31: 5157 | S31: 5476
B32: Net Income | C32: =C30-C31 -> 8902 | D32: =D30-D31 -> 7050 | E32: =E30-E31 -> 7564 | F32: =F30-F31 -> 5394 | G32: =G30-G31 -> 5915 | H32: =H30-H31 -> 5307 | I32: =I30-I31 -> 6019 | L32: =L30-L31 -> 6990 | M32: =M30-M31 -> 7782 | N32: =N30-N31 -> 4955 | O32: =O30-O31 -> 12698 | P32: =P30-P31 -> 14751 | Q32: =Q30-Q31 -> 15952 | R32: =R30-R31 -> 12958 | S32: =S30-S31 -> 11222
B33: Minority Interest | C33: 421 | D33: =Q33-C33 -> 357 | E33: 297 | F33: =+R33-SUM(E33) -> 111 | G33: 217 | H33: =+S33-G33 -> 127 | I33: 322 | L33: 636 | M33: 611 | N33: 253 | O33: 662 | P33: 667 | Q33: 778 | R33: 408 | S33: 344
B34: Net Income to Group | C34: =C32-C33 -> 8481 | D34: =D32-D33 -> 6693 | E34: =E32-E33 -> 7267 | F34: =F32-F33 -> 5283 | G34: =G32-G33 -> 5698 | H34: =H32-H33 -> 5180 | I34: =I32-I33 -> 5697 | L34: =L32-L33 -> 6354 | M34: =M32-M33 -> 7171 | N34: =N32-N33 -> 4702 | O34: =O32-O33 -> 12036 | P34: =P32-P33 -> 14084 | Q34: =Q32-Q33 -> 15174 | R34: =R32-R33 -> 12550 | S34: =S32-S33 -> 10878
B36: EPS | C36: =C34/C37 -> 16.946498 | D36: =D34/D37 -> 13.384485 | E36: =E34/E37 -> 14.54699 | F36: =F34/F37 -> 10.578429 | G36: =G34/G37 -> 11.431684 | H36: =H34/H37 -> 10.408149 | I36: =I34/I37 -> 11.518698 | L36: =L34/L37 -> 12.636587 | M36: =M34/M37 -> 14.250261 | N36: =N34/N37 -> 9.3353057 | O36: =O34/O37 -> 23.898606 | P36: =P34/P37 -> 28.049033 | Q36: =Q34/Q37 -> 30.344567 | R36: =R34/R37 -> 25.129526 | S36: =S34/S37 -> 21.857114
B37: Shares | C37: 500.45737 | D37: 500.05659 | E37: 499.5535 | F37: 499.41251 | G37: 498.43927 | H37: 497.68694 | I37: 494.58715 | L37: 502.82564 | M37: 503.21885 | N37: 503.67927 | O37: 503.62771 | P37: 502.12069 | Q37: 500.05657 | R37: 499.41251 | S37: 497.68694
B39: Wines & Spirits | E39: =+E13/C13-1 -> -0.11757309 | F39: =+F13/D13-1 -> -0.10698626 | G39: =+G13/E13-1 -> -0.078019238 | H39: =+H13/F13-1 -> -0.093289689 | I39: =+I13/G13-1 -> 0.0038639876 | J39: =+J13/H13-1 -> -1 | M39: =+M13/L13-1 -> 0.084192106 | N39: =+N13/M13-1 -> -0.14723816 | O39: =+O13/N13-1 -> 0.25636172 | P39: =+P13/O13-1 -> 0.18831604 | Q39: =+Q13/P13-1 -> -0.070009861 | R39: =+R13/Q13-1 -> -0.11208725 | S39: =+S13/R13-1 -> -0.085977482
B40: Fashion & Leather Goods | E40: =+E14/C14-1 -> -0.018476515 | F40: =+F14/D14-1 -> -0.034179083 | G40: =+G14/E14-1 -> -0.079726542 | H40: =+H14/F14-1 -> -0.080536251 | I40: =+I14/G14-1 -> -0.050693173 | J40: =+J14/H14-1 -> -1 | M40: =+M14/L14-1 -> 0.20493091 | N40: =+N14/M14-1 -> -0.046319198 | O40: =+O14/N14-1 -> 0.45687745 | P40: =+P14/O14-1 -> 0.25090627 | Q40: =+Q14/P14-1 -> 0.091104326 | R40: =+R14/Q14-1 -> -0.02629894 | S40: =+S14/R14-1 -> -0.080126644
B41: Perfumes & Cosmetics | E41: =+E15/C15-1 -> 0.026812314 | F41: =+F15/D15-1 -> 0.0091916097 | G41: =+G15/E15-1 -> -0.013056093 | H41: =+H15/F15-1 -> -0.044371789 | I41: =+I15/G15-1 -> -0.041156296 | J41: =+J15/H15-1 -> -1 | M41: =+M15/L15-1 -> 0.12196323 | N41: =+N15/M15-1 -> -0.23218727 | O41: =+O15/N15-1 -> 0.25914634 | P41: =+P15/O15-1 -> 0.16858354 | Q41: =+Q15/P15-1 -> 0.071095571 | R41: =+R15/Q15-1 -> 0.017772942 | S41: =+S15/R15-1 -> -0.028985507
B42: Watches & Jewelery | E42: =+E16/C16-1 -> -0.051041091 | F42: =+F16/D16-1 -> -0.0087671233 | G42: =+G16/E16-1 -> -0.011650485 | H42: =+H16/F16-1 -> -0.0057121798 | I42: =+I16/G16-1 -> 0.026522593 | J42: =+J16/H16-1 -> -1 | M42: =+M16/L16-1 -> 0.068396798 | N42: =+N16/M16-1 -> -0.23813848 | O42: =+O16/N16-1 -> 1.590584 | P42: =+P16/O16-1 -> 0.21704624 | Q42: =+Q16/P16-1 -> 0.030337397 | R42: =+R16/Q16-1 -> -0.029811044 | S42: =+S16/R16-1 -> -0.0086035738
B43: Selective Retailing | E43: =+E17/C17-1 -> 0.0331538 | F43: =+F17/D17-1 -> 0.010493179 | G43: =+G17/E17-1 -> -0.0013901761 | H43: =+H17/F17-1 -> 0.010176532 | I43: =+I17/G17-1 -> -0.024825986 | J43: =+J17/H17-1 -> -1 | M43: =+M17/L17-1 -> 0.083907372 | N43: =+N17/M17-1 -> -0.31343384 | O43: =+O17/N17-1 -> 0.15745938 | P43: =+P17/O17-1 -> 0.26356985 | Q43: =+Q17/P17-1 -> 0.20421492 | R43: =+R17/Q17-1 -> 0.021079117 | S43: =+S17/R17-1 -> 0.0047092323
...

Sheet Ratios
D2: FY18 | E2: FY19 | F2: FY20 | G2: FY21 | H2: FY22 | I2: FY23 | J2: FY24 | K2: FY25 | M2: Average
A3: x | B3: Profitabilty
B4: ROE | D4: =Model!L34/Model!L69 -> 0.187119 | E4: =Model!M34/Model!M69 -> 0.18691516 | F4: =Model!N34/Model!N69 -> 0.12109506 | G4: =Model!O34/Model!O69 -> 0.24608968 | H4: =Model!P34/Model!P69 -> 0.24881634 | I4: =Model!Q34/Model!Q69 -> 0.24200571 | J4: =Model!R34/Model!R69 -> 0.18113066 | K4: =Model!S34/Model!S69 -> 0.15776879 | M4: =AVERAGE(G4:I4,D4:E4) -> 0.22218918
B5: ROC | D5: =Model!L26/Model!L66 -> 0.13293405 | E5: =Model!M26/Model!M66 -> 0.11681018 | F5: =Model!N26/Model!N66 -> 0.073359038 | G5: =Model!O26/Model!O66 -> 0.13689939 | H5: =Model!P26/Model!P66 -> 0.15597196 | I5: =Model!Q26/Model!Q66 -> 0.15700029 | J5: =Model!R26/Model!R66 -> 0.12673101 | K5: =Model!S26/Model!S66 -> 0.12038413 | M5: =AVERAGE(G5:I5,D5:E5) -> 0.13992317
B6: ROIC | D6: =(Model!L26*(1-Model!L48))/(Model!L69+Model!L70+Model!L71+Model!L76+Model!L77-Model!L64-Model!L55-Model!L56) -> 0.18829268 | E6: =(Model!M26*(1-Model!M48))/(Model!M69+Model!M70+Model!M71+Model!M76+Model!M77-Model!M64-Model!M55-Model!M56) -> 0.14632184 | F6: =(Model!N26*(1-Model!N48))/(Model!N69+Model!N70+Model!N71+Model!N76+Model!N77-Model!N64-Model!N55-Model!N56) -> 0.098121456 | G6: =(Model!O26*(1-Model!O48))/(Model!O69+Model!O70+Model!O71+Model!O76+Model!O77-Model!O64-Model!O55-Model!O56) -> 0.17351642 | H6: =(Model!P26*(1-Model!P48))/(Model!P69+Model!P70+Model!P71+Model!P76+Model!P77-Model!P64-Model!P55-Model!P56) -> 0.1872024 | I6: =(Model!Q26*(1-Model!Q48))/(Model!Q69+Model!Q70+Model!Q71+Model!Q76+Model!Q77-Model!Q64-Model!Q55-Model!Q56) -> 0.18283984 | J6: =(Model!R26*(1-Model!R48))/(Model!R69+Model!R70+Model!R71+Model!R76+Model!R77-Model!R64-Model!R55-Model!R56) -> 0.1387772 | K6: =(Model!S26*(1-Model!S48))/(Model!S69+Model!S70+Model!S71+Model!S76+Model!S77-Model!S64-Model!S55-Model!S56) -> 0.12996639 | M6: =AVERAGE(G6:I6,D6:E6) -> 0.17563464
B7: ROCE | D7: =Model!L26/(Model!L59+Model!L60+Model!L61+Model!L62+Model!L63-Model!L57-Model!L55-Model!L78) -> 0.15739737 | E7: =Model!M26/(Model!M59+Model!M60+Model!M61+Model!M62+Model!M63-Model!M57-Model!M55-Model!M78) -> 0.13680825 | F7: =Model!N26/(Model!N59+Model!N60+Model!N61+Model!N62+Model!N63-Model!N57-Model!N55-Model!N78) -> 0.097487007 | G7: =Model!O26/(Model!O59+Model!O60+Model!O61+Model!O62+Model!O63-Model!O57-Model!O55-Model!O78) -> 0.15874558 | H7: =Model!P26/(Model!P59+Model!P60+Model!P61+Model!P62+Model!P63-Model!P57-Model!P55-Model!P78) -> 0.18056678 | I7: =Model!Q26/(Model!Q59+Model!Q60+Model!Q61+Model!Q62+Model!Q63-Model!Q57-Model!Q55-Model!Q78) -> 0.18067802 | J7: =Model!R26/(Model!R59+Model!R60+Model!R61+Model!R62+Model!R63-Model!R57-Model!R55-Model!R78) -> 0.14715909 | K7: =Model!S26/(Model!S59+Model!S60+Model!S61+Model!S62+Model!S63-Model!S57-Model!S55-Model!S78) -> 0.1392166 | M7: =AVERAGE(G7:I7,D7:E7) -> 0.1628392
B9: Retention Rate | D9: =1-(-Model!L101/Model!L34) -> 0.51369216 | E9: =1-(-Model!M101/Model!M34) -> 0.48710082 | F9: =1-(-Model!N101/Model!N34) -> 0.4047214 | G9: =1-(-Model!O101/Model!O34) -> 0.65428714 | H9: =1-(-Model!P101/Model!P34) -> 0.51902869 | I9: =1-(-Model!Q101/Model!Q34) -> 0.52820614 | J9: =1-(-Model!R101/Model!R34) -> 0.41657371 | K9: =1-(-Model!S101/Model!S34) -> 0.34519213 | M9: =AVERAGE(G9:I9,D9:E9) -> 0.54046299
B10: Expected Growth | D10: =D9*D4 -> 0.096121566 | E10: =E9*E4 -> 0.091046527 | F10: =F9*F4 -> 0.049009761 | G10: =G9*G4 -> 0.16101331 | H10: =H9*H4 -> 0.12914282 | I10: =I9*I4 -> 0.1278289 | J10: =J9*J4 -> 0.07545427 | K10: =K9*K4 -> 0.054460543 | M10: =AVERAGE(G10:I10,D10:E10) -> 0.12103062
B11: Reinvestment Rate | D11: =(-Model!L94-Model!L96)/(Model!L26*(1-Model!L48)) -> 0.56694662 | E11: =(-Model!M94-Model!M96)/(Model!M26*(1-Model!M48)) -> 0.54323243 | F11: =(-Model!N94-Model!N96)/(Model!N26*(1-Model!N48)) -> 0.53037751 | G11: =(-Model!O94-Model!O96)/(Model!O26*(1-Model!O48)) -> 0.17679274 | H11: =(-Model!P94-Model!P96)/(Model!P26*(1-Model!P48)) -> 0.51862503 | I11: =(-Model!Q94-Model!Q96)/(Model!Q26*(1-Model!Q48)) -> 0.72438441 | J11: =(-Model!R94-Model!R96)/(Model!R26*(1-Model!R48)) -> 0.55129447 | K11: =(-Model!S94-Model!S96)/(Model!S26*(1-Model!S48)) -> 0.42363074 | M11: =AVERAGE(G11:I11,D11:E11) -> 0.50599625
B12: Expected Growth | D12: =D11*D6 -> 0.1067519 | E12: =E11*E6 -> 0.079486767 | F12: =F11*F6 -> 0.052041414 | G12: =G11*G6 -> 0.030676444 | H12: =H11*H6 -> 0.097087851 | I12: =I11*I6 -> 0.13244633 | J12: =J11*J6 -> 0.076507106 | K12: =K11*K6 -> 0.055057756 | M12: =AVERAGE(G12:I12,D12:E12) -> 0.089289857
A14: x | B14: Financial Stabiltiy
B15: Gearing | D15: =D32/Model!L69 -> 0.13793916 | E15: =E32/Model!M69 -> 0.45859507 | F15: =F32/Model!N69 -> 0.40791676 | G15: =G32/Model!O69 -> 0.49164775 | H15: =H32/Model!P69 -> 0.45353685 | I15: =I32/Model!Q69 -> 0.45161959 | J15: =J32/Model!R69 -> 0.40654091 | K15: =K32/Model!S69 -> 0.35478397 | M15: =AVERAGE(G15:I15,D15:E15) -> 0.39866769
B16: Net Debt/EBITDA | D16: =D32/(Model!L26+Model!L88) -> 0.38459644 | E16: =E32/(Model!M26+Model!M88) -> 1.2591426 | F16: =F32/(Model!N26+Model!N88) -> 1.3833188 | G16: =G32/(Model!O26+Model!O88) -> 1.1848822 | H16: =H32/(Model!P26+Model!P88) -> 1.0599505 | I16: =I32/(Model!Q26+Model!Q88) -> 1.0603235 | J16: =J32/(Model!R26+Model!R88) -> 1.1999148 | K16: =K32/(Model!S26+Model!S88) -> 1.1140866 | M16: =AVERAGE(G16:I16,D16:E16) -> 0.98977906
A19: x | B19: WC Managment
B20: Debitors | D20: =Model!L61/Model!L19*360 -> 24.770854 | E20: =Model!M61/Model!M19*360 -> 23.14142 | F20: =Model!N61/Model!N19*360 -> 22.220331 | G20: =Model!O61/Model!O19*360 -> 21.230554 | H20: =Model!P61/Model!P19*360 -> 19.358456 | I20: =Model!Q61/Model!Q19*360 -> 19.75648 | J20: =Model!R61/Model!R19*360 -> 20.107932 | K20: =Model!S61/Model!S19*360 -> 19.299318 | M20: =AVERAGE(G20:I20,D20:F20) -> 21.746349
B21: Creditors | D21: =Model!L78/Model!L19*360 -> 40.854226 | E21: =Model!M78/Model!M19*360 -> 38.998323 | F21: =Model!N78/Model!N19*360 -> 41.102775 | G21: =Model!O78/Model!O19*360 -> 39.725298 | H21: =Model!P78/Model!P19*360 -> 39.953526 | I21: =Model!Q78/Model!Q19*360 -> 37.812264 | J21: =Model!R78/Model!R19*360 -> 36.687411 | K21: =Model!S78/Model!S19*360 -> 36.633955 | M21: =AVERAGE(G21:I21,D21:F21) -> 39.741069
B22: Inventory-Intensity | D22: =Model!L60/Model!L66 -> 0.16803499 | E22: =Model!M60/Model!M66 -> 0.14213477 | F22: =Model!N60/Model!N66 -> 0.11977436 | G22: =Model!O60/Model!O66 -> 0.13206343 | H22: =Model!P60/Model!P66 -> 0.15090682 | I22: =Model!Q60/Model!Q66 -> 0.15972831 | J22: =Model!R60/Model!R66 -> 0.15865004 | K22: =Model!S60/Model!S66 -> 0.15952886 | M22: =AVERAGE(D22:I22) -> 0.14544045
B23: Inventory Turnover | D23: =Model!L20/Model!L60 -> 1.2515018 | E23: =Model!M20/Model!M60 -> 1.3212073 | F23: =Model!N20/Model!N60 -> 1.2193454 | G23: =Model!O20/Model!O60 -> 1.2299837 | H23: =Model!P20/Model!P60 -> 1.2297849 | I23: =Model!Q20/Model!Q60 -> 1.1709655 | J23: =Model!R20/Model!R60 -> 1.1795175 | K23: =Model!S20/Model!S60 -> 1.2038925 | M23: =AVERAGE(G23:I23,D23:F23) -> 1.2371314
B24: Storage Duration | D24: =360/D23 -> 287.6544 | E24: =360/E23 -> 272.47807 | F24: =360/F23 -> 295.24038 | G24: =360/G23 -> 292.68681 | H24: =360/H23 -> 292.73411 | I24: =360/I23 -> 307.43861 | J24: =360/J23 -> 305.20954 | K24: =360/K23 -> 299.03002 | M24: =AVERAGE(G24:I24,D24:F24) -> 291.37206
B25: Cash Conversion Cycle | D25: =D24+D20-D21 -> 271.57103 | E25: =E24+E20-E21 -> 256.62116 | F25: =F24+F20-F21 -> 276.35793 | G25: =G24+G20-G21 -> 274.19206 | H25: =H24+H20-H21 -> 272.13904 | I25: =I24+I20-I21 -> 289.38282 | J25: =J24+J20-J21 -> 288.63006 | K25: =K24+K20-K21 -> 281.69539 | M25: =AVERAGE(G25:I25,D25:F25) -> 273.37734
A28: x | B28: Multiples
B29: Price | D29: 258.2 | E29: 414.6 | F29: 510.9 | G29: 730 | H29: 679.9 | I29: 733.6 | J29: 635.4 | K29: 641.8
B30: Shares | D30: =Model!L37 -> 502.82564 | E30: =Model!M37 -> 503.21885 | F30: =Model!N37 -> 503.67927 | G30: =Model!O37 -> 503.62771 | H30: =Model!P37 -> 502.12069 | I30: =Model!Q37 -> 500.05657 | J30: =Model!R37 -> 499.41251 | K30: =Model!S37 -> 497.68694
B31: MC | D31: =D30*D29 -> 129829.58 | E31: =E30*E29 -> 208634.54 | F31: =F30*F29 -> 257329.74 | G31: =G30*G29 -> 367648.23 | H31: =H30*H29 -> 341391.86 | I31: =I30*I29 -> 366841.5 | J31: =J30*J29 -> 317326.71 | K31: =K30*K29 -> 319415.48
B32: Net Debt | D32: =(Model!L76+Model!L77+Model!L70+Model!L71-Model!L64-Model!L55-Model!L56) -> 4684 | E32: =(Model!M76+Model!M77+Model!M70+Model!M71-Model!M64-Model!M55-Model!M56) -> 17594 | F32: =(Model!N76+Model!N77+Model!N70+Model!N71-Model!N64-Model!N55-Model!N56) -> 15839 | G32: =(Model!O76+Model!O77+Model!O70+Model!O71-Model!O64-Model!O55-Model!O56) -> 24046 | H32: =(Model!P76+Model!P77+Model!P70+Model!P71-Model!P64-Model!P55-Model!P56) -> 25672 | I32: =(Model!Q76+Model!Q77+Model!Q70+Model!Q71-Model!Q64-Model!Q55-Model!Q56) -> 28317 | J32: =(Model!R76+Model!R77+Model!R70+Model!R71-Model!R64-Model!R55-Model!R56) -> 28168 | K32: =(Model!S76+Model!S77+Model!S70+Model!S71-Model!S64-Model!S55-Model!S56) -> 24462
B33: EV | D33: =D31+D32 -> 134513.58 | E33: =E31+E32 -> 226228.54 | F33: =F31+F32 -> 273168.74 | G33: =G31+G32 -> 391694.23 | H33: =H31+H32 -> 367063.86 | I33: =I31+I32 -> 395158.5 | J33: =J31+J32 -> 345494.71 | K33: =K31+K32 -> 343877.48
B34: Free Cashflow | D34: =Model!L26*(1-Model!L46)+Model!L88+Model!L94+Model!L96+Model!L89 -> 5970.6461 | E34: =Model!M26*(1-Model!M46)+Model!M88+Model!M94+Model!M96+Model!M89 -> 9565.1869 | F34: =Model!N26*(1-Model!N46)+Model!N88+Model!N94+Model!N96+Model!N89 -> 9753.6773 | G34: =Model!O26*(1-Model!O46)+Model!O88+Model!O94+Model!O96+Model!O89 -> 16164.052 | H34: =Model!P26*(1-Model!P46)+Model!P88+Model!P94+Model!P96+Model!P89 -> 13669.163 | I34: =Model!Q26*(1-Model!Q46)+Model!Q88+Model!Q94+Model!Q96+Model!Q89 -> 11774.445 | J34: =Model!R26*(1-Model!R46)+Model!R88+Model!R94+Model!R96+Model!R89 -> 15025.673 | K34: =Model!S26*(1-Model!S46)+Model!S88+Model!S94+Model!S96+Model!S89 -> 16024.23
B35: Equity-Multiples
B36: P/E | D36: =D31/Model!L34 -> 20.432732 | E36: =E31/Model!M34 -> 29.094204 | F36: =F31/Model!N34 -> 54.72772 | G36: =G31/Model!O34 -> 30.545715 | H36: =H31/Model!P34 -> 24.239695 | I36: =I31/Model!Q34 -> 24.175662 | J36: =Main!I6/Model!R34 -> 18.137599 | K36: =Main!J6/Model!S34 -> 0 | M36: =AVERAGE(G36:I36,D36:E36) -> 25.697602
B37: PEG | E37: =E36/((Model!M34/Model!L34-1)*100) -> 2.2627242 | F37: =F36/((Model!N34/Model!M34-1)*100) -> -1.58952 | G37: =G36/((Model!O34/Model!N34-1)*100) -> 0.19583577 | H37: =H36/((Model!P34/Model!O34-1)*100) -> 1.4245555 | I37: =I36/((Model!Q34/Model!P34-1)*100) -> 3.1237617 | J37: =J36/-2 -> -9.0687995 | K37: =K36/-2 -> 0 | M37: =AVERAGE(G37:I37,E37) -> 1.7517193
B38: P/B | D38: =D31/Model!L69 -> 3.8233525 | E38: =E31/Model!M69 -> 5.4381477 | F38: =F31/Model!N69 -> 6.6272564 | G38: =G31/Model!O69 -> 7.5169852 | H38: =H31/Model!P69 -> 6.0312321 | I38: =I31/Model!Q69 -> 5.8506483 | J38: =J31/Model!R69 -> 4.5798882 | K38: =K31/Model!S69 -> 4.6326339 | M38: =AVERAGE(G38:I38,D38:E38) -> 5.7320731
B39: Entity -Multiples
B40: EV/Sales | D40: =D33/Model!L19 -> 2.8726259 | E40: =E33/Model!M19 -> 4.2151767 | F40: =F33/Model!N19 -> 6.1178639 | G40: =G33/Model!O19 -> 6.099731 | H40: =H33/Model!P19 -> 4.6355812 | I40: =I33/Model!Q19 -> 4.5867062 | J40: =J33/Model!R19 -> 4.0798591 | M40: =AVERAGE(G40:I40,D40:E40) -> 4.4819642
B41: EV/EBITDA | D41: =Ratios!D33/(Model!L26+Model!L88+Model!L89) -> 11.044715 | E41: =Ratios!E33/(Model!M26+Model!M88+Model!M89) -> 13.810423 | F41: =Ratios!F33/(Model!N26+Model!N88+Model!N89) -> 19.481439 | G41: =Ratios!G33/(Model!O26+Model!O88+Model!O89) -> 17.041298 | H41: =Ratios!H33/(Model!P26+Model!P88+Model!P89) -> 13.481612 | I41: =Ratios!I33/(Model!Q26+Model!Q88+Model!Q89) -> 13.288445 | J41: =Ratios!J33/(Model!R26+Model!R88+Model!R89) -> 12.938423 | M41: =AVERAGE(G41:I41,D41:E41) -> 13.733299
B42: EV/EBIT | D42: =D33/Model!L26 -> 13.61887 | E42: =E33/Model!M26 -> 20.068175 | F42: =F33/Model!N26 -> 34.266024 | G42: =G33/Model!O26 -> 22.832657 | H42: =H33/Model!P26 -> 17.478399 | I42: =I33/Model!Q26 -> 17.515891 | J42: =J33/Model!R26 -> 18.273376 | M42: =AVERAGE(G42:I42,D42:E42) -> 18.302798

Sheet DCF
A1: Main | B1: LVMH DCF
B3: Ticker | E3: MC.PA | G3: Share Price | J3: =+Main!I4 -> 459.1 | L3: Share Price | O3: =+J3 -> 459.1
B4: Date | E4: =+TODAY() -> 46231 | G4: Fair Share Price | J4: =V62 -> 463.48604 | L4: Scneario DCF Price | O4: =+J15+O15+T15 -> 0
B5: End of FY | E5: 46022 | G5: Implied Upside | J5: =J4/J3-1 -> 0.0095535512 | L5: Implied Upside | O5: =O4/O3-1 -> -1
A7: x | B7: Assumptions
B9: Switches | G9: Conservative Case | L9: Base Case | Q9: Optimistic Case
B10: Assuptions | G10: Assuptions | I10: Year | J10: Metic | L10: Assuptions | N10: Year | O10: Metic | Q10: Assuptions | S10: Year | T10: Metic
B11: Revenue | E11: 2 | G11: Revenue | L11: Revenue | Q11: Revenue
B12: EBIT | E12: 2 | G12: EBIT | L12: EBIT | Q12: EBIT
B13: WACC | E13: 2 | G13: Implied Share Price
B14: TGR | E14: 2 | G14: Probability | L14: Probability | Q14: Probability
B15: ROIC | E15: 2 | G15: Implied Share Price * p | L15: Implied Share Price * p | Q15: Implied Share Price * p
B17: Valuation
B18: WACC | E18: =CHOOSE(E13,J18,O18,T18) -> 0.09 | G18: WACC | J18: 0.1 | L18: WACC | O18: 0.09 | Q18: WACC | T18: 0.08
B19: TGR | E19: =CHOOSE(E14,J19,O19,T19) -> 0.02 | G19: TGR | J19: 0.01 | L19: TGR | O19: 0.02 | Q19: TGR | T19: 0.03
B20: RONIC | E20: =CHOOSE(E15,J20,O20,T20) -> 0.11 | G20: RONIC | J20: 0.1 | L20: RONIC | O20: 0.11 | Q20: RONIC | T20: 0.12
A24: x | B24: Model | G24: 19 | H24: =G24+1 -> 20 | I24: =H24+1 -> 21 | J24: =I24+1 -> 22 | K24: =J24+1 -> 23 | L24: =K24+1 -> 24 | M24: =L24+1 -> 25 | N24: =M24+1 -> 26 | O24: =N24+1 -> 27 | ... V24: =U24+1 -> 34
B25: Revenue | G25: =+Model!M19 -> 53670 | H25: =+Model!N19 -> 44651 | I25: =+Model!O19 -> 64215 | J25: =+Model!P19 -> 79184 | K25: =+Model!Q19 -> 86153 | L25: =+Model!R19 -> 84683 | M25: =L25*(1+M26) -> 80807 | N25: =M25*(1+N26) -> 83818.93 | O25: =N25*(1+O26) -> 88668.278 | P25: =O25*(1+P26) -> 93721.737 | Q25: =P25*(1+Q26) -> 98987.515 | R25: =Q25*(1+R26) -> 104474.16 | S25: =R25*(1+S26) -> 110190.54 | T25: =S25*(1+T26) -> 113129.15 | ... V25: =U25*(1+V26) -> 119270.87
B26: Growth (%) | H26: =H25/G25-1 -> -0.16804546 | I26: =I25/H25-1 -> 0.43815368 | J26: =J25/I25-1 -> 0.23310753 | K26: =K25/J25-1 -> 0.088010204 | L26: =L25/K25-1 -> -0.017062668 | M26: {=OFFSET(M26,$E$11,,)} -> -0.045770698 | N26: {=OFFSET(N26,$E$11,,)} -> 0.037273132 | O26: {=OFFSET(O26,$E$11,,)} -> 0.05785505 | P26: {=OFFSET(P26,$E$11,,)} -> 0.056992855 | Q26: {=OFFSET(Q26,$E$11,,)} -> 0.056185242 | R26: {=OFFSET(R26,$E$11,,)} -> 0.055427597 | S26: {=OFFSET(S26,$E$11,,)} -> 0.054715814 | T26: {=OFFSET(T26,$E$11,,)} -> 0.026668399 | ... V26: {=OFFSET(V26,$E$11,,)} -> 0.026825217
B27: Conservative Case | M27: =+M28-2% -> -0.065770698 | N27: =+N28-2% -> 0.017273132 | O27: =+O28-2% -> 0.03785505 | P27: =+P28-2% -> 0.036992855 | Q27: =+Q28-2% -> 0.036185242 | R27: =+R28-2% -> 0.035427597 | S27: =+S28-2% -> 0.034715814 | T27: =+T28-2% -> 0.0066683987 | ... V27: =+V28-2% -> 0.0068252167
B28: Base Case | M28: =+Model!S44 -> -0.045770698 | N28: =+Model!T44 -> 0.037273132 | O28: =+Model!U44 -> 0.05785505 | P28: =+Model!V44 -> 0.056992855 | Q28: =+Model!W44 -> 0.056185242 | R28: =+Model!X44 -> 0.055427597 | S28: =+Model!Y44 -> 0.054715814 | T28: =+Model!Z44 -> 0.026668399 | ... V28: =+Model!AB44 -> 0.026825217
B29: Optimisitic Case | M29: =+M28+2% -> -0.025770698 | N29: =+N28+2% -> 0.057273132 | O29: =+O28+2% -> 0.07785505 | P29: =+P28+2% -> 0.076992855 | Q29: =+Q28+2% -> 0.076185242 | R29: =+R28+2% -> 0.075427597 | S29: =+S28+2% -> 0.074715814 | T29: =+T28+2% -> 0.046668399 | ... V29: =+V28+2% -> 0.046825217
B31: EBIT | G31: =+Model!M26 -> 11273 | H31: =+Model!N26 -> 7972 | I31: =+Model!O26 -> 17155 | J31: =+Model!P26 -> 21001 | K31: =+Model!Q26 -> 22560 | L31: =+Model!R26 -> 18907 | M31: =M32*M25 -> 18585.61 | N31: =N32*N25 -> 20535.638 | O31: =O32*O25 -> 23053.752 | P31: =P32*P25 -> 25773.478 | Q31: =Q32*Q25 -> 28706.379 | R31: =R32*R25 -> 31864.617 | S31: =S32*S25 -> 32506.21 | T31: =T32*T25 -> 32241.807 | ... V31: =V32*V25 -> 31606.781
B32: % of Sales | G32: =G31/G25 -> 0.21004285 | H32: =H31/H25 -> 0.17854023 | I32: =I31/I25 -> 0.26714942 | J32: =J31/J25 -> 0.26521772 | K32: =K31/K25 -> 0.26185971 | L32: =L31/L25 -> 0.22326795 | M32: {=OFFSET(M32,$E$12,,)} -> 0.23 | N32: {=OFFSET(N32,$E$12,,)} -> 0.245 | O32: {=OFFSET(O32,$E$12,,)} -> 0.26 | P32: {=OFFSET(P32,$E$12,,)} -> 0.275 | Q32: {=OFFSET(Q32,$E$12,,)} -> 0.29 | R32: {=OFFSET(R32,$E$12,,)} -> 0.305 | S32: {=OFFSET(S32,$E$12,,)} -> 0.295 | T32: {=OFFSET(T32,$E$12,,)} -> 0.285 | ... V32: {=OFFSET(V32,$E$12,,)} -> 0.265
B33: Conservative Case | M33: =+M34-2% -> 0.21 | N33: =+N34-2% -> 0.225 | O33: =+O34-2% -> 0.24 | P33: =+P34-2% -> 0.255 | Q33: =+Q34-2% -> 0.27 | R33: =+R34-2% -> 0.285 | S33: =+S34-2% -> 0.275 | T33: =+T34-2% -> 0.265 | ... V33: =+V34-2% -> 0.245
B34: Base Case | M34: =+Model!S46 -> 0.23 | N34: =+Model!T46 -> 0.245 | O34: =+Model!U46 -> 0.26 | P34: =+Model!V46 -> 0.275 | Q34: =+Model!W46 -> 0.29 | R34: =+Model!X46 -> 0.305 | S34: =+Model!Y46 -> 0.295 | T34: =+Model!Z46 -> 0.285 | ... V34: =+Model!AB46 -> 0.265
B35: Optimisitic Case | M35: =+M34+2% -> 0.25 | N35: =+N34+2% -> 0.265 | O35: =+O34+2% -> 0.28 | P35: =+P34+2% -> 0.295 | Q35: =+Q34+2% -> 0.31 | R35: =+R34+2% -> 0.325 | S35: =+S34+2% -> 0.315 | T35: =+T34+2% -> 0.305 | ... V35: =+V34+2% -> 0.285
B37: Taxes | G37: =+Model!M31 -> 2932 | H37: =+Model!N31 -> 2409 | I37: =+Model!O31 -> 4510 | J37: =+Model!P31 -> 5362 | K37: =+Model!Q31 -> 5673 | L37: =+Model!R31 -> 5157 | M37: =M38*M31 -> 5018.1147 | N37: =N38*N31 -> 5955.335 | O37: =O38*O31 -> 6685.5882 | P37: =P38*P31 -> 7474.3085 | Q37: =Q38*Q31 -> 8324.85 | R37: =R38*R31 -> 9240.739 | S37: =S38*S31 -> 9426.801 | T37: =T38*T31 -> 9350.1242 | ... V37: =V38*V31 -> 9165.9666
B38: Tax Rate (%) | G38: =G37/G31 -> 0.26009048 | H38: =H37/H31 -> 0.30218264 | I38: =I37/I31 -> 0.26289711 | J38: =J37/J31 -> 0.25532118 | K38: =K37/K31 -> 0.25146277 | L38: =L37/L31 -> 0.27275612 | M38: 0.27 | N38: 0.29 | O38: 0.29 | P38: 0.29 | Q38: 0.29 | R38: 0.29 | S38: 0.29 | T38: 0.29 | U38: 0.29 | V38: 0.29
B40: Nopat | G40: =G31-G37 -> 8341 | H40: =H31-H37 -> 5563 | I40: =I31-I37 -> 12645 | J40: =J31-J37 -> 15639 | K40: =K31-K37 -> 16887 | L40: =L31-L37 -> 13750 | M40: =M31-M37 -> 13567.495 | N40: =N31-N37 -> 14580.303 | ... V40: =V31-V37 -> 22440.815
B42: D&A and other non-cash Expenses | G42: =+Model!M88+Model!M89 -> 5108 | H42: =+Model!N88+Model!N89 -> 6050 | I42: =+Model!O88+Model!O89 -> 5830 | J42: =+Model!P88+Model!P89 -> 6226 | K42: =+Model!Q88+Model!Q89 -> 7177 | L42: =+Model!R88+Model!R89 -> 7796 | M42: =M43*M25 -> 7757.472 | N42: =N43*N25 -> 8046.6173 | O42: =O43*O25 -> 8512.1547 | P42: =P43*P25 -> 8997.2867 | Q42: =Q43*Q25 -> 9502.8015 | R42: =R43*R25 -> 10029.519 | S42: =S43*S25 -> 10578.292 | T42: =T43*T25 -> 10860.398 | ... V42: =V43*V25 -> 11450.004
B43: % of Sales | G43: =G42/G25 -> 0.095174213 | H43: =H42/H25 -> 0.13549529 | I43: =I42/I25 -> 0.090788757 | J43: =J42/J25 -> 0.078626995 | K43: =K42/K25 -> 0.083305282 | L43: =L42/L25 -> 0.09206098 | M43: 0.096 | N43: 0.096 | O43: 0.096 | P43: 0.096 | Q43: 0.096 | R43: 0.096 | S43: 0.096 | T43: 0.096 | U43: 0.096 | V43: 0.096
B45: CapEx | G45: =+Model!M96 -> -3294 | H45: =+Model!N96 -> -2478 | I45: =+Model!O96 -> -2664 | J45: =+Model!P96 -> -4969 | K45: =+Model!Q96 -> -7478 | L45: =+Model!R96 -> -5531 | M45: =M46*M25 -> -5252.455 | N45: =N46*N25 -> -5448.2305 | O45: =O46*O25 -> -5763.4381 | P45: =P46*P25 -> -6091.9129 | Q45: =Q46*Q25 -> -6335.201 | R45: =R46*R25 -> -6581.8718 | S45: =S46*S25 -> -6831.8137 | T45: =T46*T25 -> -6900.8781 | ... V45: =V46*V25 -> -7036.9815
B46: % of Sales | G46: =G45/G25 -> -0.06137507 | H46: =H45/H25 -> -0.055497077 | I46: =I45/I25 -> -0.041485634 | J46: =J45/J25 -> -0.062752576 | K46: =K45/K25 -> -0.086799067 | L46: =L45/L25 -> -0.065314172 | M46: -0.065 | N46: -0.065 | O46: -0.065 | P46: -0.065 | Q46: =+P46+0.1% -> -0.064 | R46: =+Q46+0.1% -> -0.063 | S46: =+R46+0.1% -> -0.062 | T46: =+S46+0.1% -> -0.061 | U46: =+T46+0.1% -> -0.06 | V46: =+U46+0.1% -> -0.059
B48: Change in WC | G48: =+Model!M94 -> -1154 | H48: =+Model!N94 -> -367 | I48: =+Model!O94 -> 426 | J48: =+Model!P94 -> -3019 | K48: =+Model!Q94 -> -4577 | L48: =+Model!R94 -> -1925 | M48: =M49*M25 -> -1858.561 | N48: =N49*N25 -> -1927.8354 | O48: =O49*O25 -> -2039.3704 | P48: =P49*P25 -> -2155.5999 | Q48: =Q49*Q25 -> -2276.7128 | R48: =R49*R25 -> -2402.9056 | S48: =S49*S25 -> -2534.3825 | T48: =T49*T25 -> -2601.9704 | ... V48: =V49*V25 -> -2743.2301
B49: % of Sales | G49: =G48/G25 -> -0.02150177 | H49: =H48/H25 -> -0.0082193008 | I49: =I48/I25 -> 0.006633964 | J49: =J48/J25 -> -0.038126389 | K49: =K48/K25 -> -0.053126415 | L49: =L48/L25 -> -0.022731835 | M49: -0.023 | N49: -0.023 | O49: -0.023 | P49: -0.023 | Q49: -0.023 | R49: -0.023 | S49: -0.023 | T49: -0.023 | U49: -0.023 | V49: -0.023
B51: Unlevered Free Cashflow | G51: =G40+G42+G45+G48 -> 9001 | H51: =H40+H42+H45+H48 -> 8768 | I51: =I40+I42+I45+I48 -> 16237 | J51: =J40+J42+J45+J48 -> 13877 | K51: =K40+K42+K45+K48 -> 12009 | L51: =L40+L42+L45+L48 -> 14090 | M51: =M40+M42+M45+M48 -> 14213.951 | N51: =N40+N42+N45+N48 -> 15250.854 | ... V51: =V40+V42+V45+V48 -> 24110.607
B52: Present Value of unlevered FC | M52: =(M51/(1+$E$18)^M53)*M53 -> 7813.6051 | N52: =N51/(1+$E$18)^N53 -> 13312.005 | O52: =O51/(1+$E$18)^O53 -> 13675.631 | P52: =P51/(1+$E$18)^P53 -> 13994.816 | Q52: =Q51/(1+$E$18)^Q53 -> 14337.936 | R52: =R51/(1+$E$18)^R53 -> 14635.793 | S52: =S51/(1+$E$18)^S53 -> 13780.699 | T52: =T51/(1+$E$18)^T53 -> 12620.842 | U52: =U51/(1+$E$18)^U53 -> 11550.125 | V52: =V51/(1+$E$18)^V53 -> 10561.983
B53: Discount Period | M53: =YEARFRAC(E4,E5) -> 0.57777778 | N53: =M53+1 -> 1.5777778 | O53: =N53+1 -> 2.5777778 | P53: =O53+1 -> 3.5777778 | Q53: =P53+1 -> 4.5777778 | R53: =Q53+1 -> 5.5777778 | S53: =R53+1 -> 6.5777778 | T53: =S53+1 -> 7.5777778 | U53: =T53+1 -> 8.5777778 | V53: =U53+1 -> 9.5777778
B54: Sum of Present Value | V54: =SUM(M52:V52) -> 126283.43
...
