Workbook

Sheet Main
A1: Microsoft
A2: number in millions | G2: Price | H2: 455.3
G3: Shares | H3: 7425.5455 | I3: Q426
B4: SEC | G4: MC | H4: =H3*H2 -> 3380850.9
B5: IR | G5: Cash | H5: =20935+55908 -> 76843 | I5: Q426
G6: Debt | H6: =9277+31067 -> 40344 | I6: Q426
A7: x | B7: Businessmodel | G7: EV | H7: =H4-H5+H6 -> 3344351.9
B8: Segment | C8: %of Rev | D8: Products | E8: Notes
B9: Prodctivity & Business Process | C9: =Model!Y13/Model!$Y$18 -> 0.435783 | D9: Microsoft 365, Office etc
B10: Intellegent Cloud | C10: =Model!Y14/Model!$Y$18 -> 0.35681824 | D10: Cloud: Azur, AI etc | G10: CEO: Satya Nadella
B11: Personal Computing | C11: =Model!Y15/Model!$Y$18 -> 0.20739876 | D11: Windows, Surface | G11: Founded: 1975 Bill Gates
G12: Steve Ballmer CEO from 2000 to 2014
A15: x | B15: Notes:
B16: Bought LikedIn in 2016
B17: Products: Microsoft 365, LinkedIn, Dynamics 365, Microsoft AI -> Copilot, Office: Teams, Excel, Word etc
B18: Edge Browser
B19: Microsoft Cloud: Azure
B20: Personal Computing
B21: Windows 11
B22: Surface Product Family: Surface Laptop etc
B23: Xbox, Acquisition of Actvizison Blizzard: Game devolper

Sheet Model
A1: Main
C2: FQ123 | D2: FQ223 | E2: FQ323 | F2: FQ423 | G2: FQ124 | H2: FQ224 | I2: FQ324 | J2: FQ424 | K2: FQ125 | L2: FQ225 | M2: FQ325 | N2: FQ425 | O2: FQ126 | P2: FQ226 | Q2: FQ326 | R2: FQ426 | T2: FY19 | U2: FY20 | V2: FY21 | W2: FY22 | X2: FY23 | Y2: FY24 | Z2: FY25 | AA2: FY26
B3: Server & Cloud | C3: 18388 | D3: 19594 | E3: 20025 | F3: =X3-SUM(C3:E3) -> 7000 | G3: 22308 | H3: 23953 | I3: 24832 | J3: =+Y3-SUM(G3:I3) -> 8735 | K3: 22155 | L3: 23641 | M3: 24761 | N3: =+Z3-SUM(K3:M3) -> 27878 | O3: 28872 | P3: 30865 | Q3: 32592 | R3: =+AA3-SUM(O3:Q3) -> 37096 | T3: 32622 | U3: 41379 | V3: 52589 | W3: 67321 | X3: 65007 | Y3: 79828 | Z3: 98435 | AA3: 129425
B4: Office 365 | C4: 11577 | D4: 11867 | E4: 12468 | F4: =X4-SUM(C4:E4) -> 31037 | G4: 13140 | H4: 13477 | I4: 13911 | J4: =+Y4-SUM(G4:I4) -> 36441 | K4: 20449 | L4: 21117 | M4: 21883 | N4: =+Z4-SUM(K4:M4) -> 24318 | O4: 23966 | P4: 24524 | Q4: 25593 | R4: =+AA4-SUM(O4:Q4) -> 27914 | T4: 31769 | U4: 35316 | V4: 39872 | W4: 44862 | X4: 66949 | Y4: 76969 | Z4: 87767 | AA4: 101997
B5: XBOX | C5: 5313 | D5: 4758 | E5: 5328 | F5: =X5-SUM(C5:E5) -> 67 | G5: 5567 | H5: 7111 | I5: 5929 | J5: =+Y5-SUM(G5:I5) -> 2896 | K5: 5621 | L5: 6581 | M5: 5721 | N5: =+Z5-SUM(K5:M5) -> 5532 | O5: 5508 | P5: 5958 | Q5: 5341 | R5: =+AA5-SUM(O5:Q5) -> 4983 | T5: 11386 | U5: 11575 | V5: 15370 | W5: 16230 | X5: 15466 | Y5: 21503 | Z5: 23455 | AA5: 21790
B6: Windows | C6: 3610 | D6: 4808 | E6: 3607 | F6: =X6-SUM(C6:E6) -> 5122 | G6: 3919 | H6: 5262 | I6: 5451 | J6: =+Y6-SUM(G6:I6) -> 2394 | K6: 4329 | L6: 4587 | M6: 4311 | N6: =+Z6-SUM(K6:M6) -> 4087 | O6: 4714 | P6: 5082 | Q6: 4832 | R6: =+AA6-SUM(O6:Q6) -> 2456 | T6: 20395 | U6: 22294 | V6: 23227 | W6: 24761 | X6: 17147 | Y6: 17026 | Z6: 17314 | AA6: 17084
B7: LinkedIn | C7: 3628 | D7: 3833 | E7: 3659 | F7: =X7-SUM(C7:E7) -> 3869 | G7: 3913 | H7: 4195 | I7: 4013 | J7: =+Y7-SUM(G7:I7) -> 4251 | K7: 4292 | L7: 4512 | M7: 4144 | N7: =+Z7-SUM(K7:M7) -> 4864 | O7: 4551 | P7: 4479 | Q7: 4041 | R7: =+AA7-SUM(O7:Q7) -> 6746 | T7: 6754 | U7: 8077 | V7: 10289 | W7: 13816 | X7: 14989 | Y7: 16372 | Z7: 17812 | AA7: 19817
B8: Search & news ads | C8: 2913 | D8: 3209 | E8: 3036 | F8: =X8-SUM(C8:E8) -> 2967 | G8: 3053 | H8: 3220 | I8: 3134 | J8: =+Y8-SUM(G8:I8) -> 2899 | K8: 3225 | L8: 3558 | M8: 3504 | N8: =+Z8-SUM(K8:M8) -> 3591 | O8: 3697 | P8: 3812 | Q8: 3808 | R8: =+AA8-SUM(O8:Q8) -> 3859 | T8: 7628 | U8: 7740 | V8: 8528 | W8: 11591 | X8: 12125 | Y8: 12306 | Z8: 13878 | AA8: 15176
B9: Enterprise & Partner Services | C9: 1929 | D9: 1907 | E9: 2047 | F9: =X9-SUM(C9:E9) -> 2017 | G9: 1944 | H9: 1917 | I9: 1861 | J9: =+Y9-SUM(G9:I9) -> 1872 | K9: 1928 | L9: 1892 | M9: 1946 | N9: =+Z9-SUM(K9:M9) -> 1994 | O9: 2204 | P9: 2305 | Q9: 2297 | R9: =+AA9-SUM(O9:Q9) -> 2369 | T9: 6124 | U9: 6409 | V9: 6943 | W9: 7407 | X9: 7900 | Y9: 7594 | Z9: 7760 | AA9: 9175
B10: Dynamic Products & Cloud | C10: 1260 | D10: 1302 | E10: 1389 | F10: =X10-SUM(C10:E10) -> 1845 | G10: 1540 | H10: 1576 | I10: 1646 | J10: =+Y10-SUM(G10:I10) -> 2069 | K10: 1849 | L10: 1913 | M10: 1929 | N10: =+Z10-SUM(K10:M10) -> 2136 | O10: 2136 | P10: 2204 | Q10: 2292 | R10: =+AA10-SUM(O10:Q10) -> 2374 | T10: 0 | U10: 0 | V10: 0 | W10: 0 | X10: 5796 | Y10: 6831 | Z10: 7827 | AA10: 9006
B11: Devices | C11: 1448 | D11: 1430 | E11: 1282 | F11: =X11-SUM(C11:E11) -> 2257 | G11: 1125 | H11: 1298 | I11: 1067 | J11: =+Y11-SUM(G11:I11) -> 3158 | K11: 1727 | L11: 1821 | M11: 1821 | N11: =+Z11-SUM(K11:M11) -> 2035 | O11: 2022 | P11: 2038 | Q11: 2087 | R11: =+AA11-SUM(O11:Q11) -> 2113 | T11: 6095 | U11: 6457 | V11: 6791 | W11: 6991 | X11: 6417 | Y11: 6648 | Z11: 7404 | AA11: 8260
B12: Other | C12: 56 | D12: 39 | E12: 16 | F12: =X12-SUM(C12:E12) -> 8 | G12: 8 | H12: 11 | I12: 14 | J12: =+Y12-SUM(G12:I12) -> 12 | K12: 10 | L12: 10 | M12: 46 | N12: =+Z12-SUM(K12:M12) -> 6 | O12: 3 | P12: 6 | Q12: 3 | R12: =+AA12-SUM(O12:Q12) -> 97 | T12: 3070 | U12: 3768 | V12: 4479 | W12: 5291 | X12: 119 | Y12: 45 | Z12: 72 | AA12: 109
B13: Prodctivity & Business Process | C13: 16465 | D13: 17002 | E13: 17516 | F13: =X13-SUM(C13:E13) -> 43168 | G13: 18592 | H13: 19249 | I13: 19570 | J13: =+Y13-SUM(G13:I13) -> 49409 | K13: 28317 | L13: 29437 | M13: 29944 | N13: =+Z13-SUM(K13:M13) -> 33112 | O13: 33020 | P13: 34116 | Q13: 35013 | R13: =+AA13-SUM(O13:Q13) -> 37847 | T13: 41160 | U13: 46398 | V13: 53915 | W13: 63364 | X13: 94151 | Y13: 106820 | Z13: 120810 | AA13: 139996
B14: Intellegent Cloud | C14: 20325 | D14: 21508 | E14: 22081 | F14: =X14-SUM(C14:E14) -> 9030 | G14: 24259 | H14: 25880 | I14: 26708 | J14: =+Y14-SUM(G14:I14) -> 10617 | K14: 24092 | L14: 25544 | M14: 26751 | N14: =+Z14-SUM(K14:M14) -> 29878 | O14: 30897 | P14: 32907 | Q14: 34681 | R14: =+AA14-SUM(O14:Q14) -> 39306 | T14: 38985 | U14: 48366 | V14: 60080 | W14: 75251 | X14: 72944 | Y14: 87464 | Z14: 106265 | AA14: 137791
... B17: Services and Other | C17: 34381 | D17: 36230 | E17: 37269 | F17: =X17-SUM(C17:E17) -> 39336 | G17: 40982 | H17: 43079 | I17: 44778 | J17: =+Y17-SUM(G17:I17) -> 51510 | K17: 50313 | L17: 53413 | M17: 54747 | N17: =+Z17-SUM(K17:M17) -> 59305 | O17: 61751 | P17: 64822 | Q17: 67797 | R17: =+AA17-SUM(O17:Q17) -> 72773 | T17: 59774 | U17: 74974 | V17: 97014 | W17: 125538 | X17: 147216 | Y17: 180349 | Z17: 217778 | AA17: 267143
B18: Revenue | C18: =+C16+C17 -> 50122 | D18: =+D16+D17 -> 52747 | E18: =+E16+E17 -> 52857 | F18: =+F16+F17 -> 56189 | G18: =+G16+G17 -> 56517 | H18: =+H16+H17 -> 62020 | I18: =+I16+I17 -> 61858 | J18: =+J16+J17 -> 64727 | ... Q18: =+Q16+Q17 -> 82886 | R18: =+AA18-SUM(O18:Q18) -> 90007 | T18: =+T16+T17 -> 125843 | U18: =+U16+U17 -> 143015 | V18: =+V16+V17 -> 168088 | W18: =+W16+W17 -> 198270 | X18: =+X16+X17 -> 211915 | Y18: =+Y16+Y17 -> 245122 | Z18: =+Z16+Z17 -> 281724 | AA18: 331839
B19: COGS Products | C19: 4302 | D19: 5690 | E19: 3941 | F19: =X19-SUM(C19:E19) -> 3871 | G19: 3531 | H19: 5964 | I19: 4339 | J19: =+Y19-SUM(G19:I19) -> 1438 | K19: 3294 | L19: 3856 | M19: 3037 | N19: =+Z19-SUM(K19:M19) -> 3314 | O19: 2922 | P19: 3505 | Q19: 2733 | R19: =+AA19-SUM(O19:Q19) -> 2938 | T19: 16273 | U19: 16017 | V19: 18219 | W19: 19064 | X19: 17804 | Y19: 15272 | Z19: 13501 | AA19: 12098
B20: COGS Services | C20: 11150 | D20: 11798 | E20: 12187 | F20: =X20-SUM(C20:E20) -> 12924 | G20: 12771 | H20: 13659 | I20: 14166 | J20: =+Y20-SUM(G20:I20) -> 18246 | K20: 16805 | L20: 17943 | M20: 18882 | N20: =+Z20-SUM(K20:M20) -> 20700 | O20: 21121 | P20: 22473 | Q20: 24095 | R20: =+AA20-SUM(O20:Q20) -> 26587 | T20: 26637 | U20: 30061 | V20: 34013 | W20: 43586 | X20: 48059 | Y20: 58842 | Z20: 74330 | AA20: 94276
B21: Gross Profit | C21: =+C18-SUM(C19:C20) -> 34670 | D21: =+D18-SUM(D19:D20) -> 35259 | E21: =+E18-SUM(E19:E20) -> 36729 | F21: =+F18-SUM(F19:F20) -> 39394 | G21: =+G18-SUM(G19:G20) -> 40215 | H21: =+H18-SUM(H19:H20) -> 42397 | I21: =+I18-SUM(I19:I20) -> 43353 | J21: =+J18-SUM(J19:J20) -> 45043 | ... R21: =+R18-SUM(R19:R20) -> 60482 | T21: =+T18-SUM(T19:T20) -> 82933 | U21: =+U18-SUM(U19:U20) -> 96937 | V21: =+V18-SUM(V19:V20) -> 115856 | W21: =+W18-SUM(W19:W20) -> 135620 | X21: =+X18-SUM(X19:X20) -> 146052 | Y21: =+Y18-SUM(Y19:Y20) -> 171008 | Z21: =+Z18-SUM(Z19:Z20) -> 193893 | AA21: =+AA18-SUM(AA19:AA20) -> 225465
B22: R&D | C22: 6628 | D22: 6844 | E22: 6984 | F22: =X22-SUM(C22:E22) -> 6739 | G22: 6659 | H22: 7142 | I22: 7653 | J22: =+Y22-SUM(G22:I22) -> 8056 | K22: 7544 | L22: 7917 | M22: 8198 | N22: =+Z22-SUM(K22:M22) -> 8829 | O22: 8146 | P22: 8504 | Q22: 8915 | R22: =+AA22-SUM(O22:Q22) -> 9997 | T22: 16876 | U22: 19269 | V22: 20716 | W22: 24512 | X22: 27195 | Y22: 29510 | Z22: 32488 | AA22: 35562
B23: S&M | C23: 5126 | D23: 5679 | E23: 5750 | F23: =X23-SUM(C23:E23) -> 6204 | G23: 5187 | H23: 6246 | I23: 6207 | J23: =+Y23-SUM(G23:I23) -> 6816 | K23: 5717 | L23: 6440 | M23: 6212 | N23: =+Z23-SUM(K23:M23) -> 7285 | O23: 5717 | P23: 6584 | Q23: 6814 | R23: =+AA23-SUM(O23:Q23) -> 7595 | T23: 18213 | U23: 19598 | V23: 20117 | W23: 21825 | X23: 22759 | Y23: 24456 | Z23: 25654 | AA23: 26710
B24: G&A | C24: 1398 | D24: 2337 | E24: 1643 | F24: =X24-SUM(C24:E24) -> 2197 | G24: 1474 | H24: 1977 | I24: 1912 | J24: =+Y24-SUM(G24:I24) -> 2246 | K24: 1673 | L24: 1823 | M24: 1737 | N24: =+Z24-SUM(K24:M24) -> 1990 | O24: 1806 | P24: 1932 | Q24: 1931 | R24: =+AA24-SUM(O24:Q24) -> 2287 | T24: 4885 | U24: 5111 | V24: 5107 | W24: 5900 | X24: 7575 | Y24: 7609 | Z24: 7223 | AA24: 7956
B25: Operating Profit | C25: =+C21-SUM(C22:C24) -> 21518 | D25: =+D21-SUM(D22:D24) -> 20399 | E25: =+E21-SUM(E22:E24) -> 22352 | F25: =+F21-SUM(F22:F24) -> 24254 | G25: =+G21-SUM(G22:G24) -> 26895 | H25: =+H21-SUM(H22:H24) -> 27032 | I25: =+I21-SUM(I22:I24) -> 27581 | J25: =+J21-SUM(J22:J24) -> 27925 | ... R25: =+R21-SUM(R22:R24) -> 40603 | T25: =+T21-SUM(T22:T24) -> 42959 | U25: =+U21-SUM(U22:U24) -> 52959 | V25: =+V21-SUM(V22:V24) -> 69916 | W25: =+W21-SUM(W22:W24) -> 83383 | X25: =+X21-SUM(X22:X24) -> 88523 | Y25: =+Y21-SUM(Y22:Y24) -> 109433 | Z25: =+Z21-SUM(Z22:Z24) -> 128528 | AA25: =+AA21-SUM(AA22:AA24) -> 155237
B26: Other Income | C26: 54 | D26: -60 | E26: 321 | F26: =X26-SUM(C26:E26) -> 473 | G26: 389 | H26: -506 | I26: -854 | J26: =+Y26-SUM(G26:I26) -> -675 | K26: -283 | L26: -2288 | M26: -623 | N26: =+Z26-SUM(K26:M26) -> -1707 | O26: -3660 | P26: 9971 | Q26: 942 | R26: =+AA26-SUM(O26:Q26) -> 3444 | T26: 729 | U26: 77 | V26: 1186 | W26: 333 | X26: 788 | Y26: -1646 | Z26: -4901 | AA26: 10697
B27: Pretax Income | C27: =C25+C26 -> 21572 | D27: =D25+D26 -> 20339 | E27: =E25+E26 -> 22673 | F27: =F25+F26 -> 24727 | G27: =G25+G26 -> 27284 | H27: =H25+H26 -> 26526 | I27: =I25+I26 -> 26727 | J27: =J25+J26 -> 27250 | ... R27: =R25+R26 -> 44047 | T27: =T25+T26 -> 43688 | U27: =U25+U26 -> 53036 | V27: =V25+V26 -> 71102 | W27: =W25+W26 -> 83716 | X27: =X25+X26 -> 89311 | Y27: =Y25+Y26 -> 107787 | Z27: =Z25+Z26 -> 123627 | AA27: =AA25+AA26 -> 165934
B28: Tax Expense | C28: 4016 | D28: 3914 | E28: 4374 | F28: =X28-SUM(C28:E28) -> 4646 | G28: 4994 | H28: 4656 | I28: 4788 | J28: =+Y28-SUM(G28:I28) -> 5213 | K28: 5602 | L28: 5257 | M28: 5553 | N28: =+Z28-SUM(K28:M28) -> 5383 | O28: 6554 | P28: 9788 | Q28: 7562 | R28: =+AA28-SUM(O28:Q28) -> 8281 | T28: 4448 | U28: 8755 | V28: 9831 | W28: 10978 | X28: 16950 | Y28: 19651 | Z28: 21795 | AA28: 32185
B29: Net Income | C29: =+C27-C28 -> 17556 | D29: =+D27-D28 -> 16425 | E29: =+E27-E28 -> 18299 | F29: =+F27-F28 -> 20081 | G29: =+G27-G28 -> 22290 | H29: =+H27-H28 -> 21870 | I29: =+I27-I28 -> 21939 | J29: =+J27-J28 -> 22037 | ... R29: =+R27-R28 -> 35766 | T29: =+T27-T28 -> 39240 | U29: =+U27-U28 -> 44281 | V29: =+V27-V28 -> 61271 | W29: =+W27-W28 -> 72738 | X29: =+X27-X28 -> 72361 | Y29: =+Y27-Y28 -> 88136 | Z29: =+Z27-Z28 -> 101832 | AA29: =+AA27-AA28 -> 133749
B31: EPS | C31: =C29/C32 -> 2.354298 | D31: =D29/D32 -> 2.2044021 | E31: =E29/E32 -> 2.4592125 | F31: =F29/F32 -> 2.6968842 | G31: =G29/G32 -> 3.0004038 | H31: =H29/H32 -> 2.9426803 | I31: =I29/I32 -> 2.9523617 | J31: =J29/J32 -> 2.9655497 | ... R31: =R29/R32 -> 4.816321 | T31: =T29/T32 -> 5.1140362 | U31: =U29/U32 -> 5.8187911 | V31: =V29/V32 -> 8.1185902 | W31: =W29/W32 -> 9.7035752 | X31: =X29/X32 -> 9.7181037 | Y31: =Y29/Y32 -> 11.860584 | Z31: =Z29/Z32 -> 13.699987 | AA31: =AA29/AA32 -> 18.003634
B32: Shares | C32: 7457 | D32: 7451 | E32: 7441 | F32: =X32 -> 7446 | G32: 7429 | H32: 7432 | I32: 7431 | J32: =Y32 -> 7431 | K32: 7433 | L32: 7435 | M32: 7434 | N32: =+Z32 -> 7433 | O32: 7433 | P32: 7431 | Q32: 7426 | R32: 7426 | T32: 7673 | U32: 7610 | V32: 7547 | W32: 7496 | X32: 7446 | Y32: 7431 | Z32: 7433 | AA32: 7429
B34: Cloud Growth | G34: =+G14/C14-1 -> 0.19355474 | H34: =+H14/D14-1 -> 0.2032732 | I34: =+I14/E14-1 -> 0.20954667 | J34: =+J14/F14-1 -> 0.17574751 | K34: =+K14/G14-1 -> -0.006884043 | L34: =+L14/H14-1 -> -0.012982998 | M34: =+M14/I14-1 -> 0.0016100045 | N34: =+N14/J14-1 -> 1.814166 | ... Q34: =+Q14/M14-1 -> 0.29643752 | U34: =+U14/T14-1 -> 0.24063101 | V34: =+V14/U14-1 -> 0.24219493 | W34: =+W14/V14-1 -> 0.25251332 | X34: =+X14/W14-1 -> -0.0306574 | Y34: =+Y14/X14-1 -> 0.19905681 | Z34: =+Z14/Y14-1 -> 0.21495701 | AA34: =+AA14/Z14-1 -> 0.29667341
B35: Products YoY | G35: =G16/D16-1 -> -0.059453896 | H35: =H16/E16-1 -> 0.21510136 | I35: =I16/F16-1 -> 0.013469412 | J35: =J16/G16-1 -> -0.14921146 | K35: =K16/H16-1 -> -0.19370677 | L35: =L16/I16-1 -> -0.050409836 | M35: =M16/J16-1 -> 0.1590376 | N35: =N16/K16-1 -> 0.12205343 | ... Q35: =Q16/N16-1 -> -0.11945612 | U35: =U16/T16-1 -> 0.029847584 | V35: =V16/U16-1 -> 0.044576064 | W35: =W16/V16-1 -> 0.023327799 | X35: =X16/W16-1 -> -0.11044657 | Y35: =Y16/X16-1 -> 0.001143758 | Z35: =Z16/Y16-1 -> -0.012767666 | AA35: =AA16/Z16-1 -> 0.011728646
B36: Services YoY | G36: =G17/D17-1 -> 0.13116202 | H36: =H17/E17-1 -> 0.15589364 | I36: =I17/F17-1 -> 0.13834655 | J36: =J17/G17-1 -> 0.25689327 | K36: =K17/H17-1 -> 0.16792405 | L36: =L17/I17-1 -> 0.19284023 | M36: =M17/J17-1 -> 0.062842167 | N36: =N17/K17-1 -> 0.17872121 | ... Q36: =Q17/N17-1 -> 0.14319197 | U36: =U17/T17-1 -> 0.25429116 | V36: =V17/U17-1 -> 0.29396858 | W36: =W17/V17-1 -> 0.29401942 | X36: =X17/W17-1 -> 0.17268078 | Y36: =Y17/X17-1 -> 0.22506385 | Z36: =Z17/Y17-1 -> 0.2075365 | AA36: =AA17/Z17-1 -> 0.22667579
B37: Revenue YoY | G37: =G18/D18-1 -> 0.071473259 | H37: =H18/E18-1 -> 0.17335452 | I37: =I18/F18-1 -> 0.10089163 | J37: =J18/G18-1 -> 0.14526603 | K37: =K18/H18-1 -> 0.057481458 | L37: =L18/I18-1 -> 0.12567493 | M37: =M18/J18-1 -> 0.082484898 | N37: =N18/K18-1 -> 0.16552565 | ... Q37: =Q18/N18-1 -> 0.084313392 | U37: =U18/T18-1 -> 0.13645574 | V37: =V18/U18-1 -> 0.17531727 | W37: =W18/V18-1 -> 0.17956071 | X37: =X18/W18-1 -> 0.068820296 | Y37: =Y18/X18-1 -> 0.15669962 | Z37: =Z18/Y18-1 -> 0.14932156 | AA37: =AA18/Z18-1 -> 0.17788687
B38: GM Products | C38: =(C16-C19)/C16 -> 0.72670097 | D38: =(D16-D19)/D16 -> 0.65550645 | E38: =(E16-E19)/E16 -> 0.74717732 | F38: =(F16-F19)/F16 -> 0.77030796 | G38: =(G16-G19)/G16 -> 0.77270679 | H38: =(H16-H19)/H16 -> 0.6851275 | I38: =(I16-I19)/I16 -> 0.74596019 | J38: =(J16-J19)/J16 -> 0.89120073 | ... Q38: =(Q16-Q19)/Q16 -> 0.81887468 | T38: =(T16-T19)/T16 -> 0.75369689 | U38: =(U16-U19)/U16 -> 0.76459782 | V38: =(V16-V19)/V16 -> 0.74366154 | W38: =(W16-W19)/W16 -> 0.73788704 | X38: =(X16-X19)/X16 -> 0.724818 | Y38: =(Y16-Y19)/Y16 -> 0.76422275 | Z38: =(Z16-Z19)/Z16 -> 0.78886873 | AA38: =(AA16-AA19)/AA16 -> 0.81300235
B39: GM Services | C39: =(C17-C20)/C17 -> 0.67569297 | D39: =(D17-D20)/D17 -> 0.67435827 | E39: =(E17-E20)/E17 -> 0.67299901 | F39: =(F17-F20)/F17 -> 0.671446 | G39: =(G17-G20)/G17 -> 0.68837538 | H39: =(H17-H20)/H17 -> 0.68293136 | I39: =(I17-I20)/I17 -> 0.68363929 | J39: =(J17-J20)/J17 -> 0.64577752 | ... Q39: =(Q17-Q20)/Q17 -> 0.64460079 | T39: =(T17-T20)/T17 -> 0.55437147 | U39: =(U17-U20)/U17 -> 0.59904767 | V39: =(V17-V20)/V17 -> 0.64940112 | W39: =(W17-W20)/W17 -> 0.65280632 | X39: =(X17-X20)/X17 -> 0.67354771 | Y39: =(Y17-Y20)/Y17 -> 0.6737326 | Z39: =(Z17-Z20)/Z17 -> 0.65868912 | AA39: =(AA17-AA20)/AA17 -> 0.64709538
B40: Gross Margin | C40: =C21/C18 -> 0.69171222 | D40: =D21/D18 -> 0.66845508 | E40: =E21/E18 -> 0.69487485 | F40: =F21/F18 -> 0.70109808 | G40: =G21/G18 -> 0.71155582 | H40: =H21/H18 -> 0.68360206 | I40: =I21/I18 -> 0.7008471 | J40: =J21/J18 -> 0.69589198 | ... Q40: =Q21/Q18 -> 0.67632652 | T40: =T21/T18 -> 0.65901957 | U40: =U21/U18 -> 0.67781002 | V40: =V21/V18 -> 0.68925801 | W40: =W21/W18 -> 0.68401674 | X40: =X21/X18 -> 0.68920086 | Y40: =Y21/Y18 -> 0.69764444 | Z40: =Z21/Z18 -> 0.68823742 | AA40: =AA21/AA18 -> 0.67944093
B41: Operating Margin | C41: =C25/C18 -> 0.42931248 | D41: =D25/D18 -> 0.38673289 | E41: =E25/E18 -> 0.42287682 | F41: =F25/F18 -> 0.43165032 | G41: =G25/G18 -> 0.47587452 | H41: =H25/H18 -> 0.4358594 | I41: =I25/I18 -> 0.44587604 | J41: =J25/J18 -> 0.43142738 | ... Q41: =Q25/Q18 -> 0.46326279 | T41: =T25/T18 -> 0.3413698 | U41: =U25/U18 -> 0.37030381 | V41: =V25/V18 -> 0.41594879 | W41: =W25/W18 -> 0.42055278 | X41: =X25/X18 -> 0.41772881 | Y41: =Y25/Y18 -> 0.446443 | Z41: =Z25/Z18 -> 0.45621956 | AA41: =AA25/AA18 -> 0.46780818
B42: Tax Rate | C42: =C28/C27 -> 0.18616725 | D42: =D28/D27 -> 0.19243817 | E42: =E28/E27 -> 0.19291669 | F42: =F28/F27 -> 0.18789178 | G42: =G28/G27 -> 0.18303768 | H42: =H28/H27 -> 0.1755259 | I42: =I28/I27 -> 0.17914469 | J42: =J28/J27 -> 0.19130275 | ... Q42: =Q28/Q27 -> 0.19222166 | T42: =T28/T27 -> 0.10181285 | U42: =U28/U27 -> 0.16507655 | V42: =V28/V27 -> 0.13826615 | W42: =W28/W27 -> 0.13113383 | X42: =X28/X27 -> 0.18978625 | Y42: =Y28/Y27 -> 0.18231327 | Z42: =Z28/Z27 -> 0.17629644 | AA42: =AA28/AA27 -> 0.19396266
B44: Cash & Cash Equivalents | T44: 11356 | U44: 13576 | V44: 14224 | W44: 13931 | X44: 34704 | Y44: 18315 | Z44: 30242 | AA44: 20935
B45: Short-term Investments | T45: 122463 | U45: 122951 | V45: 116110 | W45: 90826 | X45: 76558 | Y45: 57228 | Z45: 64323 | AA45: 55908
...

Sheet Ratios
A1: Main
B2: Ratios | C2: FY18 | D2: FY19 | E2: FY20 | F2: FY21 | G2: FY22 | H2: FY23 | I2: FY24 | J2: FY25
B3: Efficency Ratios
B4: Return on Equity (ROE) | I4: =+Model!Y29/AVERAGE(Model!X75:Y75) -> 0.37133347 | N4: Net Income/Book Value of Equity
B5: Return on Assets (ROA) | N5: EBIT/Total Assets
B6: Return on Capital Employed (ROCE) | N6: EBIT/(Long Term Assets + Working Capital (Exclusive of cash)-Accounts Payables)
B7: Return on Capital Invested (ROIC) | N7: (EBIT-Tax Expenses)/(Book Value of Equity + Book Value of Debt - Book Value of Cash)
B8: Retention Rate | I8: =1-((-Model!Y101-Model!Y100)/Model!Y29) -> 0.55721839 | N8: 1 - Dividends/Net Income
B9: Expected Growth | I9: =+I8*I4 -> 0.20691384 | N9: Retention rate * ROE
B10: Reinvestment Rate | N10: Net CapEx + Change in WC / EBIT * (1-t)
B11: Expected Growth | N11: Reinvestment rate * ROIC
B14: Financial Stabilty Ratios
B15: EK-Quote | N15: Book Value of Equity/Total of Balance Sheet
B16: Gearing | N16: (Debt - Cash (Net Debt))/Book Value of Equity
B17: Interest Coverage Ratio | N17: EBIT/Interest Expenses
B18: Net Debt / EBITDA | N18: Net Debt/EBITDA
B19: Goodwill-Anteil | N19: Goodwill/Balance Sheet Total
B21: WC Managment Ratios
B22: Debitorenlaufzeit | N22: Accounts Receivables/Revenue*360
B23: Kreditorenlaufzeit | N23: Accounts Payable/Revenue*360
B24: Liquidität 1.Grades | N24: Cash and Cash Equivalents/Short term liabilites
B25: Liquidität 2.Grades | N25: (Cash and Cash Equivalents + Accounts Receivables) /Short term liabilities
B26: Liquidität 3.Grades | N26: Short term assets/short term liabilites
B27: Vorratsintensität | N27: Inventory/Balance Sheet Total
B28: Umschlaghäufigkeit der Vorräte | N28: Cogs/Inventory
B29: Lagedauer | N29: 360/Umschlaghäufigkeit der Vorräte
B30: Cash Conversion Cycle | N30: Cash Conversion Cycle = Debitorenlaufzeit + Lagedauer - Kreditorenlaufzeit
B32: Multiples
B33: Price
B34: Shares
B35: Market Cap
B36: Net Debt
B37: EV
B39: Equitymultiples
B40: P/E Ratio | N40: Share Price/EPS
B41: PEG Ratio | N41: P/E Ratio / Growth
B42: P/B Ratio | N42: Market Cap/Book Vakue of Equity
B43: Entitymultiples
B44: EV/EBITDA | N44: EV/EBITDA
B45: EV/EBIT | N45: EV/EBIT
...
