Workbook

Sheet Main
A1: Nike Inc
A2: numbers in mio USD
D3: Year Start: | E3: 37043 | H3: Price | I3: 44.05
B4: NKE | D4: Year End: | E4: 11444 | H4: Shares | I4: 1483.4987 | J4: FQ426
B5: SEC Filiings | D5: Credit Score | E5: A1 | H5: MC | I5: =I3*I4 -> 65348.118
B6: IR | H6: Cash | I6: =7563+1464 -> 9027 | J6: FQ426
H7: Debt | I7: =2000+5942 -> 7942 | J7: FQ426
A8: x | B8: Business Modek | H8: EV | I8: =I5+I7-I6 -> 64263.118
B9: Segments: | C9: %of Revenue | D9: Brands | E9: Customers | F9: Competitors
B10: Footwear | C10: 0.63 | D10: Nike, Jordan | E10: D2C, Wholesale | F10: New Balance, Puma, Asics, La Ning, Adidas, Anta | H10: EV/EBIT | I10: =+I8/Model!AB22 -> 16.924708
B11: Appereal | C11: 0.28 | D11: Nike, Jordan | E11: D2C, Wholesale | F11: Adidas, New Balance, Puma, Lulu Lemon, UA
B12: Equipment | C12: 0.04 | D12: Nike | E12: D2C, Wholesale | F12: Adidas, New Balance, Puma, Lulu Lemon, UA
B13: Converse | C13: 0.04 | D13: Converse | E13: D2C, Wholesale | F13: Adidas, New Balance, Puma
B14: Corporate and other | C14: 0.01 | E14: other | F14: other
B16: Largest seller of athletic footwear and appereal in the world

Sheet Model
A1: Main
C2: Q123 | D2: Q223 | E2: Q323 | F2: Q423 | G2: Q124 | H2: Q224 | I2: Q324 | J2: Q424 | K2: Q125 | L2: Q225 | M2: Q325 | N2: Q425 | O2: Q126 | P2: Q226 | Q2: Q326 | R2: Q426 | T2: FY18 | U2: FY19 | V2: FY20 | W2: FY21 | X2: FY22 | Y2: FY23 | Z2: FY24 | AA2: FY25 | AB2: FY26 | AC2: FY27 | AD2: FY28
B3: Nike Stores US | T3: 392 | U3: 384 | V3: 338 | W3: 325 | X3: 344 | Y3: 369 | Z3: 377 | AA3: 376 | AB3: 347
B4: Nike Stores International | T4: 790 | U4: 768 | V4: 758 | W4: 723 | X4: 702 | Y4: 663 | Z4: 668 | AA4: 658 | AB4: 641
B5: Total Stores | T5: =SUM(T3:T4) -> 1182 | U5: =SUM(U3:U4) -> 1152 | V5: =SUM(V3:V4) -> 1096 | W5: =SUM(W3:W4) -> 1048 | X5: =SUM(X3:X4) -> 1046 | Y5: =SUM(Y3:Y4) -> 1032 | Z5: =SUM(Z3:Z4) -> 1045 | AA5: =SUM(AA3:AA4) -> 1034 | AB5: =SUM(AB3:AB4) -> 988
B7: Nike Direct Revenue | T7: =10159+6765+3216+3829 -> 23969 | U7: =U16*U32 -> 26599.56 | V7: =V16*V32 -> 24311.95 | W7: =W16*W32 -> 27168.18 | X7: =X16*X32 -> 27091.8 | Y7: =Y16*Y32 -> 22535.48 | Z7: =Z16*Z32 -> 22599.28 | AA7: =18783+48 -> 18831 | AB7: 17720
B8: Wholesale Revenue | T8: =T16-T7 -> 12428 | U8: =U16*U33 -> 12517.44 | V8: =V16*V33 -> 13091.05 | W8: =W16*W33 -> 17369.82 | X8: =X16*X33 -> 19618.2 | Y8: =Y16*Y33 -> 28681.52 | Z8: =Z16*Z33 -> 28762.72 | AA8: 25883 | AB8: 27453
B9: Footwear | C9: 8114 | D9: 8504 | E9: 7970 | F9: =X9-SUM(C9:E9) -> 4555 | G9: 8421 | H9: 8607 | I9: 8162 | J9: 8237 | K9: 7462 | L9: 7655 | M9: 7208 | N9: 7185 | O9: 7410 | P9: 7659 | Q9: 7353 | R9: =+AB9-SUM(O9:Q9) -> 7103 | T9: 22268 | U9: 24222 | V9: 23305 | W9: 28021 | X9: 29143 | Y9: 33135 | Z9: =SUM(G9:J9) -> 33427 | AA9: =+SUM(K9:N9) -> 29510 | AB9: 29525
B10: Appereal | C10: 3434 | D10: 3794 | E10: 3381 | F10: =X10-SUM(C10:E10) -> 2958 | G10: 3388 | H10: 3774 | I10: 3290 | J10: 3323 | K10: 3032 | L10: 3738 | M10: 3193 | N10: 3002 | O10: 3313 | P10: 3906 | Q10: 3184 | R10: =+AB10-SUM(O10:Q10) -> 3046 | T10: 10733 | U10: 11550 | V10: 10953 | W10: 12865 | X10: 13567 | Y10: 13843 | Z10: =SUM(G10:J10) -> 13775 | AA10: =+SUM(K10:N10) -> 12965 | AB10: 13449
B11: Equipment | C11: 486 | D11: 408 | E11: 403 | F11: =X11-SUM(C11:E11) -> 327 | G11: 531 | H11: 479 | I11: 487 | J11: 578 | K11: 603 | L11: 544 | M11: 477 | N11: 567 | O11: 630 | P11: 550 | Q11: 468 | R11: =+AB11-SUM(O11:Q11) -> 551 | T11: 1396 | U11: 1404 | V11: 1280 | W11: 1382 | X11: 1624 | Y11: 1727 | Z11: =SUM(G11:J11) -> 2075 | AA11: =+SUM(K11:N11) -> 2191 | AB11: 2199
B12: Global Brand Divisions | C12: 14 | D12: 18 | E12: 12 | F12: =X12-SUM(C12:E12) -> 58 | G12: 13 | H12: 12 | I12: 9 | J12: 11 | K12: 14 | L12: 13 | M12: 12 | N12: 9 | O12: 9 | P12: 9 | Q12: 7 | R12: =+AB12-SUM(O12:Q12) -> 24 | T12: 88 | U12: 42 | V12: 30 | W12: 25 | X12: 102 | Y12: 58 | Z12: =SUM(G12:J12) -> 45 | AA12: =+SUM(K12:N12) -> 48 | AB12: 49
B13: Nike Brand Revenue | C13: =SUM(C9:C12) -> 12048 | D13: =SUM(D9:D12) -> 12724 | E13: =SUM(E9:E12) -> 11766 | F13: =SUM(F9:F12) -> 7898 | G13: =SUM(G9:G12) -> 12353 | H13: =SUM(H9:H12) -> 12872 | I13: =SUM(I9:I12) -> 11948 | J13: =SUM(J9:J12) -> 12149 | K13: =SUM(K9:K12) -> 11111 | L13: =+SUM(L9:L12) -> 11950 | M13: 10890 | N13: =+SUM(N9:N12) -> 10763 | O13: =+SUM(O9:O12) -> 11362 | P13: =+SUM(P9:P12) -> 12124 | Q13: 11012 | R13: =+AB13-SUM(O13:Q13) -> 10724 | T13: =+SUM(T9:T12) -> 34485 | U13: =+SUM(U9:U12) -> 37218 | V13: =+SUM(V9:V12) -> 35568 | W13: =+SUM(W9:W12) -> 42293 | X13: =+SUM(X9:X12) -> 44436 | Y13: =+SUM(Y9:Y12) -> 48763 | Z13: =+SUM(Z9:Z12) -> 49322 | AA13: =+SUM(AA9:AA12) -> 44714 | AB13: =+SUM(AB9:AB12) -> 45222
B14: Converse | C14: 643 | D14: 586 | E14: 612 | F14: =X14-SUM(C14:E14) -> 505 | G14: 588 | H14: 519 | I14: 495 | J14: 480 | K14: 501 | L14: 429 | M14: 405 | N14: 357 | O14: 366 | P14: 300 | Q14: 264 | R14: =+AB14-SUM(O14:Q14) -> 244 | T14: 1886 | U14: 1906 | V14: 1846 | W14: 2205 | X14: 2346 | Y14: 2427 | Z14: =SUM(G14:J14) -> 2082 | AA14: =+SUM(K14:N14) -> 1692 | AB14: 1174
B15: Corporate | C15: -4 | D15: 5 | E15: 12 | F15: =X15-SUM(C15:E15) -> -85 | G15: -2 | H15: -3 | I15: -14 | J15: -23 | K15: -23 | L15: -25 | M15: -26 | N15: -23 | O15: -8 | P15: 3 | Q15: 3 | R15: =+AB15-SUM(O15:Q15) -> 4 | T15: 26 | U15: -7 | V15: -11 | W15: 40 | X15: -72 | Y15: 27 | Z15: =SUM(G15:J15) -> -42 | AA15: =+SUM(K15:N15) -> -97 | AB15: 2
B16: Total Revenue | C16: 12687 | D16: 13315 | E16: 12390 | F16: =X16-SUM(C16:E16) -> 8318 | G16: 12939 | H16: 13388 | I16: 12429 | J16: 12606 | K16: 11589 | L16: 12354 | M16: 11269 | N16: 11097 | O16: 11720 | P16: 12427 | Q16: 11279 | R16: 10972 | T16: 36397 | U16: 39117 | V16: 37403 | W16: 44538 | X16: 46710 | Y16: 51217 | Z16: 51362 | AA16: 46309 | AB16: 46398
B17: COGS | C17: 7072 | D17: 7604 | E17: 7019 | F17: =X17-SUM(C17:E17) -> 3536 | G17: 7219 | H17: 7417 | I17: 6867 | J17: 6972 | K17: 6332 | L17: 6965 | M17: 6594 | N17: 6628 | O17: 6777 | P17: 7382 | Q17: 6749 | R17: 5579 | T17: 20441 | U17: 21643 | V17: 21162 | W17: 24576 | X17: 25231 | Y17: 28925 | Z17: =SUM(G17:J17) -> 28475 | AA17: =+SUM(K17:N17) -> 26519 | AB17: 26487
B18: Gross Profit | C18: =C16-C17 -> 5615 | D18: =D16-D17 -> 5711 | E18: =E16-E17 -> 5371 | F18: =F16-F17 -> 4782 | G18: =G16-G17 -> 5720 | H18: =H16-H17 -> 5971 | I18: =I16-I17 -> 5562 | J18: =J16-J17 -> 5634 | ... R18: =R16-R17 -> 5393 | T18: =T16-T17 -> 15956 | U18: =U16-U17 -> 17474 | V18: =V16-V17 -> 16241 | W18: =W16-W17 -> 19962 | X18: =X16-X17 -> 21479 | Y18: =Y16-Y17 -> 22292 | Z18: =Z16-Z17 -> 22887 | AA18: =AA16-AA17 -> 19790 | AB18: =AB16-AB17 -> 19911
B19: Demand Creation Expense | C19: 943 | D19: 1102 | E19: 923 | F19: =X19-SUM(C19:E19) -> 882 | G19: 1069 | H19: 1114 | I19: 1011 | J19: 1091 | K19: 1226 | L19: 1122 | M19: 1088 | N19: 1253 | O19: 1188 | P19: 1273 | Q19: 1090 | R19: 1203 | T19: 3577 | U19: 3753 | V19: 3592 | W19: 3114 | X19: 3850 | Y19: 4060 | Z19: =SUM(G19:J19) -> 4285 | AA19: =+SUM(K19:N19) -> 4689 | AB19: 4754
B20: Operating overhead Expense | C20: 2977 | D20: 3022 | E20: 3036 | F20: =X20-SUM(C20:E20) -> 1919 | G20: 3047 | H20: 3032 | I20: 3215 | J20: 2997 | K20: 2822 | L20: 2883 | M20: 2799 | N20: 2895 | O20: 2828 | P20: 2766 | Q20: 2887 | R20: 2879 | T20: 7934 | U20: 8949 | V20: 9534 | W20: 9911 | X20: 10954 | Y20: 12317 | Z20: =SUM(G20:J20) -> 12291 | AA20: =+SUM(K20:N20) -> 11399 | AB20: 11360
B21: OPEX | C21: =C19+C20 -> 3920 | D21: =D19+D20 -> 4124 | E21: =E19+E20 -> 3959 | F21: =F19+F20 -> 2801 | G21: =G19+G20 -> 4116 | H21: =H19+H20 -> 4146 | I21: =I19+I20 -> 4226 | J21: =J19+J20 -> 4088 | ... R21: =R19+R20 -> 4082 | T21: =T19+T20 -> 11511 | U21: =U19+U20 -> 12702 | V21: =V19+V20 -> 13126 | W21: =W19+W20 -> 13025 | X21: =X19+X20 -> 14804 | Y21: =Y19+Y20 -> 16377 | Z21: =Z19+Z20 -> 16576 | AA21: =AA19+AA20 -> 16088 | AB21: =AB19+AB20 -> 16114
B22: Operating Income | C22: =C18-C21 -> 1695 | D22: =D18-D21 -> 1587 | E22: =E18-E21 -> 1412 | F22: =F18-F21 -> 1981 | G22: =G18-G21 -> 1604 | H22: =H18-H21 -> 1825 | I22: =I18-I21 -> 1336 | J22: =J18-J21 -> 1546 | ... R22: =R18-R21 -> 1311 | T22: =T18-T21 -> 4445 | U22: =U18-U21 -> 4772 | V22: =V18-V21 -> 3115 | W22: =W18-W21 -> 6937 | X22: =X18-X21 -> 6675 | Y22: =Y18-Y21 -> 5915 | Z22: =Z18-Z21 -> 6311 | AA22: =AA18-AA21 -> 3702 | AB22: =AB18-AB21 -> 3797
B23: Interest Expense | C23: 13 | D23: 16 | E23: -7 | F23: =X23-SUM(C23:E23) -> 183 | G23: -34 | H23: -22 | I23: -52 | J23: -53 | K23: -43 | L23: -24 | M23: -18 | N23: -22 | O23: -18 | P23: -9 | Q23: -15 | R23: -8 | T23: 54 | U23: 49 | V23: 89 | W23: 262 | X23: 205 | Y23: -6 | Z23: =SUM(G23:J23) -> -161 | AA23: =+SUM(K23:N23) -> -107 | AB23: -50
B24: Other Income Expenses | C24: -146 | D24: -79 | E24: -58 | F24: =X24-SUM(C24:E24) -> 102 | G24: -10 | H24: -75 | I24: -16 | J24: -127 | K24: -55 | L24: -8 | M24: -38 | N24: 25 | O24: 23 | P24: 16 | Q24: -82 | R24: -10 | T24: 66 | U24: -78 | V24: 139 | W24: 14 | X24: -181 | Y24: -280 | Z24: =SUM(G24:J24) -> -228 | AA24: =+SUM(K24:N24) -> -76 | AB24: -53
B25: Pretax Income | C25: =C22-C23-C24 -> 1828 | D25: =D22-D23-D24 -> 1650 | E25: =E22-E23-E24 -> 1477 | F25: =F22-F23-F24 -> 1696 | G25: =G22-G23-G24 -> 1648 | H25: =H22-H23-H24 -> 1922 | I25: =I22-I23-I24 -> 1404 | J25: =J22-J23-J24 -> 1726 | ... R25: =R22-R23-R24 -> 1329 | T25: =T22-T23-T24 -> 4325 | U25: =U22-U23-U24 -> 4801 | V25: =V22-V23-V24 -> 2887 | W25: =W22-W23-W24 -> 6661 | X25: =X22-X23-X24 -> 6651 | Y25: =Y22-Y23-Y24 -> 6201 | Z25: =Z22-Z23-Z24 -> 6700 | AA25: =AA22-AA23-AA24 -> 3885 | AB25: =AB22-AB23-AB24 -> 3900
B26: Tax Expenses | C26: 360 | D26: 319 | E26: 237 | F26: =X26-SUM(C26:E26) -> -311 | G26: 198 | H26: 344 | I26: 232 | J26: 226 | K26: 256 | L26: 253 | M26: 50 | N26: 107 | O26: 195 | P26: 207 | Q26: 130 | R26: 260 | T26: 2392 | U26: 772 | V26: 348 | W26: 934 | X26: 605 | Y26: 1131 | Z26: =SUM(G26:J26) -> 1000 | AA26: =+SUM(K26:N26) -> 666 | AB26: 792
B27: Net Income | C27: =C25-C26 -> 1468 | D27: =D25-D26 -> 1331 | E27: =E25-E26 -> 1240 | F27: =F25-F26 -> 2007 | G27: =G25-G26 -> 1450 | H27: =H25-H26 -> 1578 | I27: =I25-I26 -> 1172 | J27: =J25-J26 -> 1500 | ... R27: =R25-R26 -> 1069 | T27: =T25-T26 -> 1933 | U27: =U25-U26 -> 4029 | V27: =V25-V26 -> 2539 | W27: =W25-W26 -> 5727 | X27: =X25-X26 -> 6046 | Y27: =Y25-Y26 -> 5070 | Z27: =Z25-Z26 -> 5700 | AA27: =AA25-AA26 -> 3219 | AB27: =AB25-AB26 -> 3108
B29: EPS | C29: =C27/C30 -> 0.92994376 | D29: =D27/D30 -> 0.84315746 | E29: =E27/E30 -> 0.78551108 | F29: =F27/F30 -> 1.2713877 | G29: =G27/G30 -> 0.95275008 | H29: =H27/H30 -> 1.0415002 | I29: =I27/I30 -> 0.77646747 | J29: =J27/J30 -> 0.99469496 | ... R29: =R27/R30 -> 0.72103062 | T29: 1.19 | U29: 2.55 | V29: 1.63 | W29: 3.64 | X29: 3.83 | Y29: 3.27 | Z29: =Z27/Z30 -> 3.7559304 | AA29: =AA27/AA30 -> 2.1679322 | AB29: =AB27/AB30 -> 2.1002838
B30: Shares | C30: =X30 -> 1578.5901 | D30: =X30 -> 1578.5901 | E30: =X30 -> 1578.5901 | F30: =X30 -> 1578.5901 | G30: 1521.9101 | H30: 1515.1221 | I30: 1509.4 | J30: 1508 | K30: 1497.7 | L30: 1486.8 | M30: 1478.1 | N30: 1476.7 | O30: 1476.6 | P30: 1479.5 | Q30: 1480.5 | R30: 1482.6 | T30: =T27/T29 -> 1624.3697 | U30: =U27/U29 -> 1580 | V30: =V27/V29 -> 1557.6687 | W30: =W27/W29 -> 1573.3516 | X30: =X27/X29 -> 1578.5901 | Y30: =Y27/Y29 -> 1550.4587 | Z30: 1517.6 | AA30: =+AVERAGE(K30:N30) -> 1484.825 | AB30: 1479.8
B32: Footwear Growth | G32: =G9/C9-1 -> 0.037835839 | H32: =H9/D9-1 -> 0.012111947 | I32: =I9/E9-1 -> 0.024090339 | J32: =J9/F9-1 -> 0.80834248 | K32: =K9/G9-1 -> -0.11388196 | L32: =L9/H9-1 -> -0.11060764 | M32: =M9/I9-1 -> -0.11688312 | N32: =N9/J9-1 -> -0.1277164 | ... R32: =R9/N9-1 -> -0.011412665 | T32: =T7/T16 -> 0.65854329 | U32: 0.68 | V32: 0.65 | W32: 0.61 | X32: 0.58 | Y32: 0.44 | Z32: 0.44 | AA32: 0.44 | AB32: 0.44
B33: Appereal Growth | G33: =G10/C10-1 -> -0.013395457 | H33: =H10/D10-1 -> -0.0052714813 | I33: =I10/E10-1 -> -0.026915114 | J33: =J10/F10-1 -> 0.12339419 | K33: =K10/G10-1 -> -0.10507674 | L33: =L10/H10-1 -> -0.0095389507 | M33: =M10/I10-1 -> -0.029483283 | N33: =N10/J10-1 -> -0.096599458 | ... R33: =R10/N10-1 -> 0.014656895 | T33: =T8/T16 -> 0.34145671 | U33: 0.32 | V33: 0.35 | W33: 0.39 | X33: 0.42 | Y33: 0.56 | Z33: 0.56 | AA33: 0.56 | AB33: 0.56
B34: Equipment Growth | G34: =G11/C11-1 -> 0.092592593 | H34: =H11/D11-1 -> 0.17401961 | I34: =I11/E11-1 -> 0.20843672 | J34: =J11/F11-1 -> 0.7675841 | K34: =K11/G11-1 -> 0.13559322 | L34: =L11/H11-1 -> 0.13569937 | M34: =M11/I11-1 -> -0.020533881 | N34: =N11/J11-1 -> -0.019031142 | ... R34: =R11/N11-1 -> -0.028218695 | T34: =T9/T16 -> 0.61180867 | U34: =U9/U16 -> 0.61921927 | V34: =V9/V16 -> 0.62307836 | W34: =W9/W16 -> 0.62914814 | X34: =X9/X16 -> 0.62391351 | Y34: =Y9/Y16 -> 0.64695316 | Z34: =Z9/Z16 -> 0.65081188 | AA34: =AA9/AA16 -> 0.63724114 | AB34: =AB9/AB16 -> 0.63634208
B35: Global Brands Growth | G35: =G12/C12-1 -> -0.071428571 | H35: =H12/D12-1 -> -0.33333333 | I35: =I12/E12-1 -> -0.25 | J35: =J12/F12-1 -> -0.81034483 | K35: =K12/G12-1 -> 0.076923077 | L35: =L12/H12-1 -> 0.083333333 | M35: =M12/I12-1 -> 0.33333333 | N35: =N12/J12-1 -> -0.18181818 | ... R35: =R12/N12-1 -> 1.6666667 | T35: =T10/T16 -> 0.29488694 | U35: =U10/U16 -> 0.29526804 | V35: =V10/V16 -> 0.29283747 | W35: =W10/W16 -> 0.28885446 | X35: =X10/X16 -> 0.29045172 | Y35: =Y10/Y16 -> 0.27028135 | Z35: =Z10/Z16 -> 0.26819438 | AA35: =AA10/AA16 -> 0.27996718 | AB35: =AB10/AB16 -> 0.28986163
B36: Nike Brands Growth | G36: =G13/C13-1 -> 0.025315405 | H36: =H13/D13-1 -> 0.011631562 | I36: =I13/E13-1 -> 0.015468298 | J36: =J13/F13-1 -> 0.53823753 | K36: =K13/G13-1 -> -0.10054238 | L36: =L13/H13-1 -> -0.071628341 | M36: =M13/I13-1 -> -0.088550385 | N36: =N13/J13-1 -> -0.11408346 | ... R36: =R13/N13-1 -> -0.003623525 | T36: =T11/T16 -> 0.038354809 | U36: =U11/U16 -> 0.035892323 | V36: =V11/V16 -> 0.034221854 | W36: =W11/W16 -> 0.031029683 | X36: =X11/X16 -> 0.034767716 | Y36: =Y11/Y16 -> 0.033719273 | Z36: =Z11/Z16 -> 0.040399517 | AA36: =AA11/AA16 -> 0.047312617 | AB36: =AB11/AB16 -> 0.047394284
B37: Converse Growth | G37: =G14/C14-1 -> -0.085536547 | H37: =H14/D14-1 -> -0.11433447 | I37: =I14/E14-1 -> -0.19117647 | J37: =J14/F14-1 -> -0.04950495 | K37: =K14/G14-1 -> -0.14795918 | L37: =L14/H14-1 -> -0.1734104 | M37: =M14/I14-1 -> -0.18181818 | N37: =N14/J14-1 -> -0.25625 | ... R37: =R14/N14-1 -> -0.31652661 | T37: =T14/T16 -> 0.051817457 | U37: =U14/U16 -> 0.048725618 | V37: =V14/V16 -> 0.04935433 | W37: =W14/W16 -> 0.049508285 | X37: =X14/X16 -> 0.050224791 | Y37: =Y14/Y16 -> 0.04738661 | Z37: =Z14/Z16 -> 0.040535805 | AA37: =AA14/AA16 -> 0.036537174 | AB37: =AB14/AB16 -> 0.025302815
B38: Revenue Growth | C38: n.a. | D38: n.a. | E38: n.a. | F38: n.a. | G38: =G16/D16-1 -> -0.028238828 | H38: =H16/D16-1 -> 0.0054825385 | I38: =I16/E16-1 -> 0.0031476998 | J38: =J16/F16-1 -> 0.51550854 | K38: =K16/G16-1 -> -0.10433573 | L38: =L16/H16-1 -> -0.077233343 | M38: =M16/I16-1 -> -0.093330115 | N38: =N16/J16-1 -> -0.1197049 | O38: =O16/K16-1 -> 0.011303823 | ... R38: =R16/N16-1 -> -0.011264306 | T38: n.a. | U38: =U16/T16-1 -> 0.074731434 | V38: =V16/U16-1 -> -0.043817266 | W38: =W16/V16-1 -> 0.1907601 | X38: =X16/W16-1 -> 0.048767345 | Y38: =Y16/X16-1 -> 0.096488975 | Z38: =Z16/Y16-1 -> 0.0028310912 | AA38: =AA16/Z16-1 -> -0.098380125 | AB38: =AB16/AA16-1 -> 0.0019218726
B39: Gross Margin | C39: =C18/C16 -> 0.44257902 | D39: =D18/D16 -> 0.42891476 | E39: =E18/E16 -> 0.43349475 | F39: =F18/F16 -> 0.57489781 | G39: =G18/G16 -> 0.44207435 | H39: =H18/H16 -> 0.44599641 | I39: =I18/I16 -> 0.44750181 | J39: =J18/J16 -> 0.44693003 | ... R39: =R18/R16 -> 0.49152388 | T39: =T18/T16 -> 0.43838778 | U39: =U18/U16 -> 0.44671115 | V39: =V18/V16 -> 0.43421651 | W39: =W18/W16 -> 0.44820154 | X39: =X18/X16 -> 0.45983729 | Y39: =Y18/Y16 -> 0.43524611 | Z39: =Z18/Z16 -> 0.44560181 | AA39: =AA18/AA16 -> 0.42734674 | AB39: =AB18/AB16 -> 0.42913488
B40: Operating Margin | C40: =C22/C16 -> 0.13360132 | D40: =D22/D16 -> 0.11918888 | E40: =E22/E16 -> 0.11396287 | F40: =F22/F16 -> 0.23815821 | G40: =G22/G16 -> 0.1239663 | H40: =H22/H16 -> 0.1363161 | I40: =I22/I16 -> 0.10749055 | J40: =J22/J16 -> 0.12264001 | ... R40: =R22/R16 -> 0.11948596 | T40: =T22/T16 -> 0.12212545 | U40: =U22/U16 -> 0.121993 | V40: =V22/V16 -> 0.08328209 | W40: =W22/W16 -> 0.15575464 | X40: =X22/X16 -> 0.14290302 | Y40: =Y22/Y16 -> 0.115489 | Z40: =Z22/Z16 -> 0.12287294 | AA40: =AA22/AA16 -> 0.079941264 | AB40: =AB22/AB16 -> 0.081835424
B41: Net Margin | C41: =C27/C16 -> 0.11570899 | D41: =D27/D16 -> 0.099962448 | E41: =E27/E16 -> 0.10008071 | F41: =F27/F16 -> 0.24128396 | G41: =G27/G16 -> 0.1120643 | H41: =H27/H16 -> 0.11786675 | I41: =I27/I16 -> 0.094295599 | J41: =J27/J16 -> 0.11899096 | ... R41: =R27/R16 -> 0.097429821 | T41: =T27/T16 -> 0.053108773 | U41: =U27/U16 -> 0.1029987 | V41: =V27/V16 -> 0.067882255 | W41: =W27/W16 -> 0.12858682 | X41: =X27/X16 -> 0.12943695 | Y41: =Y27/Y16 -> 0.09899057 | Z41: =Z27/Z16 -> 0.11097699 | AA41: =AA27/AA16 -> 0.069511326 | AB41: =AB27/AB16 -> 0.066985646
B42: Tax Rate | C42: =C26/C25 -> 0.19693654 | D42: =D26/D25 -> 0.19333333 | E42: =E26/E25 -> 0.16046039 | F42: =F26/F25 -> -0.18337264 | G42: =G26/G25 -> 0.12014563 | H42: =H26/H25 -> 0.17898023 | I42: =I26/I25 -> 0.16524217 | J42: =J26/J25 -> 0.13093859 | ... R42: =R26/R25 -> 0.19563582 | T42: =T26/T25 -> 0.55306358 | U42: =U26/U25 -> 0.16079983 | V42: =V26/V25 -> 0.12054035 | W42: =W26/W25 -> 0.14021919 | X42: =X26/X25 -> 0.090963765 | Y42: =Y26/Y25 -> 0.18238994 | Z42: 0.09 | AA42: 0.09 | AB42: 0.09
A45: x | B45: Balance Sheet
...

Sheet Ratios
A1: Main
C2: FY18 | D2: FY19 | E2: FY20 | F2: FY21 | G2: FY22 | H2: FY23 | I2: FY24 | J2: FY25 | L2: Average | M2: Median
A3: x | B3: Profitability
B4: ROE | C4: =Model!T27/Model!T83 -> 0.19700367 | D4: =Model!U27/Model!U83 -> 0.44568584 | E4: =Model!V27/Model!V83 -> 0.31520795 | F4: =Model!W27/Model!W83 -> 0.44857837 | G4: =Model!X27/Model!X83 -> 0.39565473 | H4: =Model!Y27/Model!Y83 -> 0.36203942 | I4: =Model!Z27/Model!Z83 -> 0.3950104 | L4: =AVERAGE(C4:I4) -> 0.3655972 | M4: =MEDIAN(C4:I4) -> 0.3950104
B5: ROCE | C5: =Model!T22/(Model!T58+SUM(Model!T48:T51)-Model!T65) -> 0.27767366 | D5: =Model!U22/(Model!U58+SUM(Model!U48:U51)-Model!U65) -> 0.28679608 | E5: =Model!V22/(Model!V58+SUM(Model!V48:V51)-Model!V65) -> 0.15014943 | F5: =Model!W22/(Model!W58+SUM(Model!W48:W51)-Model!W65) -> 0.27731361 | G5: =Model!X22/(Model!X58+SUM(Model!X48:X51)-Model!X65) -> 0.23512628 | H5: =Model!Y22/(Model!Y58+SUM(Model!Y48:Y51)-Model!Y65) -> 0.21723961 | I5: =Model!Z22/(Model!Z58+SUM(Model!Z48:Z51)-Model!Z65) -> 0.24847435 | L5: =AVERAGE(C5:I5) -> 0.24182472 | M5: =MEDIAN(C5:I5) -> 0.24847435
B6: ROIC | C6: =(Model!T27*(1-Model!T42))/(Model!T83+Model!T75-Model!T47) -> 0.047242746 | D6: =(Model!U27*(1-Model!U42))/(Model!U83+Model!U75-Model!U47) -> 0.17563438 | E6: =(Model!V27*(1-Model!V42))/(Model!V83+Model!V75-Model!V47) -> 0.097110031 | F6: =(Model!W27*(1-Model!W42))/(Model!W83+Model!W75-Model!W47) -> 0.17679669 | G6: =(Model!X27*(1-Model!X42))/(Model!X83+Model!X75-Model!X47) -> 0.17311976 | H6: =(Model!Y27*(1-Model!Y42))/(Model!Y83+Model!Y75-Model!Y47) -> 0.13776281 | I6: =(Model!Z27*(1-Model!Z42))/(Model!Z83+Model!Z75-Model!Z47) -> 0.18361062 | L6: =AVERAGE(C6:I6) -> 0.14161101 | M6: =MEDIAN(C6:I6) -> 0.17311976
B7: ROA | C7: =Model!T27/Model!T60 -> 0.085773873 | D7: =Model!U27/Model!U60 -> 0.16987815 | E7: =Model!V27/Model!V60 -> 0.081009508 | F7: =Model!W27/Model!W60 -> 0.15174881 | G7: =Model!X27/Model!X60 -> 0.14994668 | H7: =Model!Y27/Model!Y60 -> 0.13508833 | I7: =Model!Z27/Model!Z60 -> 0.14956704 | L7: =AVERAGE(C7:I7) -> 0.13185891 | M7: =MEDIAN(C7:I7) -> 0.14956704
B8: ROC | C8: =(Model!T27-Model!T23)/Model!T60 -> 0.083377707 | D8: =(Model!U27-Model!U23)/Model!U60 -> 0.16781212 | E8: =(Model!V27-Model!V23)/Model!V60 -> 0.078169868 | F8: =(Model!W27-Model!W23)/Model!W60 -> 0.14480657 | G8: =(Model!X27-Model!X23)/Model!X60 -> 0.14486248 | H8: =(Model!Y27-Model!Y23)/Model!Y60 -> 0.13524819 | I8: =(Model!Z27-Model!Z23)/Model!Z60 -> 0.15379166 | L8: =AVERAGE(C8:I8) -> 0.12972408 | M8: =MEDIAN(C8:I8) -> 0.14480657
B9: Retention Rate | C9: =1-(-Model!T112/Model!T27) -> 0.3569581 | D9: =1-(-Model!U112/Model!U27) -> 0.66939687 | E9: =1-(-Model!V112/Model!V27) -> 0.42812131 | F9: =1-(-Model!W112/Model!W27) -> 0.71398638 | G9: =1-(-Model!X112/Model!X27) -> 0.69616275 | H9: =1-(-Model!Y112/Model!Y27) -> 0.60315582 | I9: =1-(-Model!Z112/Model!Z27) -> 0.61947368 | L9: =AVERAGE(C9:I9) -> 0.58389356 | M9: =MEDIAN(C9:I9) -> 0.61947368
B10: Expected Growth | C10: =C9*C4 -> 0.070322055 | D10: =D9*D4 -> 0.29834071 | E10: =E9*E4 -> 0.13494724 | F10: =F9*F4 -> 0.32027884 | G10: =G9*G4 -> 0.27544009 | H10: =H9*H4 -> 0.21836618 | I10: =I9*I4 -> 0.24469854 | L10: =AVERAGE(C10:I10) -> 0.22319909 | M10: =MEDIAN(C10:I10) -> 0.24469854
B11: Reinvestment Rate | C11: =(-Model!T99-Model!T104)/(Model!T22*(1-Model!T42)) -> -0.22852744 | D11: =(-Model!U99-Model!U104)/(Model!U22*(1-Model!U42)) -> 0.13908785 | E11: =(-Model!V99-Model!V104)/(Model!V22*(1-Model!V42)) -> 0.85087998 | F11: =(-Model!W99-Model!W104)/(Model!W22*(1-Model!W42)) -> 0.10898178 | G11: =(-Model!X99-Model!X104)/(Model!X22*(1-Model!X42)) -> 0.39849588 | H11: =(-Model!Y99-Model!Y104)/(Model!Y22*(1-Model!Y42)) -> 0.30644125 | I11: =(-Model!Z99-Model!Z104)/(Model!Z22*(1-Model!Z42)) -> 0.016715973 | L11: =AVERAGE(C11:I11) -> 0.22743933 | M11: =MEDIAN(C11:I11) -> 0.13908785
B12: Expected Growth | C12: =C11*C6 -> -0.010796264 | D12: =D11*D6 -> 0.024428609 | E12: =E11*E6 -> 0.082628981 | F12: =F11*F6 -> 0.019267619 | G12: =G11*G6 -> 0.068987511 | H12: =H11*H6 -> 0.042216209 | I12: =I11*I6 -> 0.0030692302 | L12: =AVERAGE(C12:I12) -> 0.032828842 | M12: =MEDIAN(C12:I12) -> 0.024428609
A15: x | B15: Financial Stability
B16: % of Equity | C16: =Model!T83/Model!T85 -> 0.43539226 | D16: =Model!U83/Model!U85 -> 0.38116119 | E16: =Model!V83/Model!V85 -> 0.25700338 | F16: =Model!W83/Model!W85 -> 0.33828829 | G16: =Model!X83/Model!X85 -> 0.37898366 | H16: =Model!Y83/Model!Y85 -> 0.37313154 | I16: =Model!Z83/Model!Z85 -> 0.37864078 | L16: =AVERAGE(C16:I16) -> 0.36322873 | M16: =MEDIAN(C16:I16) -> 0.37864078
B17: Gearing | C17: =C33/Model!T83 -> -0.14624949 | D17: =D33/Model!U83 -> -0.13097345 | E17: =E33/Model!V83 -> 0.46964618 | F17: =F33/Model!W83 -> -0.088509438 | G17: =G33/Model!X83 -> -0.051698187 | H17: =H33/Model!Y83 -> 0.074550129 | I17: =I33/Model!Z83 -> -0.0074151074 | L17: =AVERAGE(C17:I17) -> 0.017050091 | M17: =MEDIAN(C17:I17) -> -0.051698187
B18: Net Debt/EBITDA | C18: =Ratios!C33/(Model!T22+Model!T89+Model!T92) -> -0.27495689 | D18: =Ratios!D33/(Model!U22+Model!U89+Model!U92) -> -0.21558631 | E18: =Ratios!E33/(Model!V22+Model!V89+Model!V92) -> 0.89348134 | F18: =Ratios!F33/(Model!W22+Model!W89+Model!W92) -> -0.14610809 | G18: =Ratios!G33/(Model!X22+Model!X89+Model!X92) -> -0.10512309 | H18: =Ratios!H33/(Model!Y22+Model!Y89+Model!Y92) -> 0.15411869 | I18: =I33/(Model!Z22+Model!Y89+Model!Y92) -> -0.014923291 | L18: =AVERAGE(C18:I18) -> 0.04155748 | M18: =MEDIAN(C18:I18) -> -0.10512309
B19: Reinvestment Need | C19: =-(Model!T104/Model!T89) -> 1.3761714 | D19: =-(Model!U104/Model!U89) -> 1.587234 | E19: =-(Model!V104/Model!V89) -> 1.5062413 | F19: =-(Model!W104/Model!W89) -> 0.93413978 | G19: =-(Model!X104/Model!X89) -> 1.0571827 | H19: =-(Model!Y104/Model!Y89) -> 1.3783784 | I19: =-(Model!Z104/Model!Z89) -> 1.0201005 | L19: =AVERAGE(C19:I19) -> 1.2656354 | M19: =MEDIAN(C19:I19) -> 1.3761714
B20: Net Debt/FCF | C20: =Ratios!C33/(Model!T22*(1-Model!T42))+Model!T89+Model!T92-Model!T99+Model!T104 -> -1736.7223 | D20: =Ratios!D33/(Model!U22*(1-Model!U42))+Model!U89+Model!U92-Model!U99+Model!U104 -> -961.29566 | E20: =Ratios!E33/(Model!V22*(1-Model!V42))+Model!V89+Model!V92-Model!V99+Model!V104 -> 1279.3809 | F20: =Ratios!F33/(Model!W22*(1-Model!W42))+Model!W89+Model!W92-Model!W99+Model!W104 -> 56.810539 | G20: =Ratios!G33/(Model!X22*(1-Model!X42))+Model!X89+Model!X92-Model!X99+Model!X104 -> 1741.8698 | H20: =Ratios!H33/(Model!Y22*(1-Model!Y42))+Model!Y89+Model!Y92-Model!Y99+Model!Y104 -> 403.21587 | I20: =Ratios!I33/(Model!Z22*(1-Model!Z42))+Model!Z89+Model!Z92-Model!Z99+Model!Z104 -> -684.01863 | L20: =AVERAGE(C20:I20) -> 14.177215 | M20: =MEDIAN(C20:I20) -> 56.810539
A23: x | B23: WC Metrics
B24: Debitors | C24: =Model!T49/Model!T9*360 -> 56.551105 | D24: =Model!U49/Model!U9*360 -> 63.492693 | E24: =Model!V49/Model!V9*360 -> 42.464707 | F24: =Model!W49/Model!W9*360 -> 57.338425 | G24: =Model!X49/Model!X9*360 -> 57.650894 | H24: =Model!Y49/Model!Y9*360 -> 44.881847 | I24: =Model!Z49/Model!Z9*360 -> 47.677626 | L24: =AVERAGE(C24:I24) -> 52.865328 | M24: =MEDIAN(C24:I24) -> 56.551105
B25: Creditors | C25: =Model!T65/Model!T9*360 -> 36.843902 | D25: =Model!U65/Model!U9*360 -> 38.820907 | E25: =Model!V65/Model!V9*360 -> 34.725595 | F25: =Model!W65/Model!W9*360 -> 36.43553 | G25: =Model!X65/Model!X9*360 -> 41.480973 | H25: =Model!Y65/Model!Y9*360 -> 31.094613 | I25: =Model!Z65/Model!Z9*360 -> 30.70452 | L25: =AVERAGE(C25:I25) -> 35.729434 | M25: =MEDIAN(C25:I25) -> 36.43553
B26: Inventory Intensity | C26: =Model!T50/Model!T60 -> 0.2334487 | D26: =Model!U50/Model!U60 -> 0.23704516 | E26: =Model!V50/Model!V60 -> 0.23505201 | F26: =Model!W50/Model!W60 -> 0.18161102 | G26: =Model!X50/Model!X60 -> 0.20882419 | H26: =Model!Y50/Model!Y60 -> 0.22525379 | I26: =Model!Z50/Model!Z60 -> 0.1972973 | L26: =AVERAGE(C26:I26) -> 0.21693317 | M26: =MEDIAN(C26:I26) -> 0.22525379
B27: Inventory Turnover | C27: =Model!T17/Model!T50 -> 3.885383 | D27: =Model!U17/Model!U50 -> 3.8496976 | E27: =Model!V17/Model!V50 -> 2.8725397 | F27: =Model!W17/Model!W50 -> 3.5856434 | G27: =Model!X17/Model!X50 -> 2.9965558 | H27: =Model!Y17/Model!Y50 -> 3.4214573 | I27: =Model!Z17/Model!Z50 -> 3.7870727 | L27: =AVERAGE(C27:I27) -> 3.4854785 | M27: =AVERAGE(D27:J27) -> 3.4188278
B28: Storage Period | C28: =360/C27 -> 92.654958 | D28: =360/D27 -> 93.513838 | E28: =360/E27 -> 125.32464 | F28: =360/F27 -> 100.40039 | G28: =360/G27 -> 120.13793 | H28: =360/H27 -> 105.21832 | I28: =360/I27 -> 95.060228 | L28: =AVERAGE(C28:I28) -> 104.61576 | M28: =AVERAGE(D28:J28) -> 106.60922
B29: Cash Conversion Cycle | C29: =C28+C24-C25 -> 112.36216 | D29: =D28+D24-D25 -> 118.18562 | E29: =E28+E24-E25 -> 133.06375 | F29: =F28+F24-F25 -> 121.30328 | G29: =G28+G24-G25 -> 136.30785 | H29: =H28+H24-H25 -> 119.00556 | I29: =I28+I24-I25 -> 112.03333 | L29: =AVERAGE(C29:I29) -> 121.75165 | M29: =AVERAGE(D29:J29) -> 123.31657
B31: Multiples
B32: MC | C32: =74.3*Model!T30 -> 120690.67 | D32: =83.13*Model!U30 -> 131345.4 | E32: =95.17*Model!V30 -> 148243.33 | F32: =131.94*Model!W30 -> 207588.02 | G32: =110.44*Model!X30 -> 174339.49 | H32: =106.83*Model!Y30 -> 165635.5 | I32: =Main!I5 -> 65348.118
B33: Net Debt | C33: =Model!T63+Model!T64+Model!T70+Model!T71-Model!T47-Model!T48 -> -1435 | D33: =Model!U63+Model!U64+Model!U70+Model!U71-Model!U47-Model!U48 -> -1184 | E33: =Model!V63+Model!V64+Model!V70+Model!V71-Model!V47-Model!V48 -> 3783 | F33: =Model!W63+Model!W64+Model!W70+Model!W71-Model!W47-Model!W48 -> -1130 | G33: =Model!X63+Model!X64+Model!X70+Model!X71-Model!X47-Model!X48 -> -790 | H33: =Model!Y63+Model!Y64+Model!Y70+Model!Y71-Model!Y47-Model!Y48 -> 1044 | I33: =Model!Z63+Model!Z64+Model!Z70+Model!Z71-Model!Z47-Model!Z48 -> -107
B34: EV | C34: =C32+C33 -> 119255.67 | D34: =D32+D33 -> 130161.4 | E34: =E32+E33 -> 152026.33 | F34: =F32+F33 -> 206458.02 | G34: =G32+G33 -> 173549.49 | H34: =H32+H33 -> 166679.5 | I34: =I32+I33 -> 65241.118
B35: Equity:
B36: P/E | C36: =C32/Model!T27 -> 62.436975 | D36: =D32/Model!U27 -> 32.6 | E36: =E32/Model!V27 -> 58.386503 | F36: =F32/Model!W27 -> 36.247253 | G36: =G32/Model!X27 -> 28.835509 | H36: =H32/Model!Y27 -> 32.669725 | I36: =I32/Model!Z27 -> 11.464582 | L36: =AVERAGE(C36:I36) -> 37.520078 | M36: =AVERAGE(D36:J36) -> 33.367262
B37: PEG | C37: n.a. | D37: =D36/((Model!U27/Model!T27-1)*100) -> 0.3006479 | E37: =E36/((Model!V27/Model!U27-1)*100) -> -1.5787867 | F37: =F36/((Model!W27/Model!V27-1)*100) -> 0.28868185 | G37: =G36/((Model!X27/Model!W27-1)*100) -> 5.1768326 | H37: =H36/((Model!Y27/Model!X27-1)*100) -> -2.0237823 | I37: =I36/((Model!Z27/Model!Y27-1)*100) -> 0.92262589 | L37: =AVERAGE(C37:I37) -> 0.51436987 | M37: =AVERAGE(D37:J37) -> 0.51436987
B38: P/B | C38: =Ratios!C32/Model!T83 -> 12.300313 | D38: =Ratios!D32/Model!U83 -> 14.529358 | E38: =Ratios!E32/Model!V83 -> 18.40389 | F38: =Ratios!F32/Model!W83 -> 16.259733 | G38: =Ratios!G32/Model!X83 -> 11.408906 | H38: =Ratios!H32/Model!Y83 -> 11.827728 | I38: =Ratios!I32/Model!Z83 -> 4.5286291 | L38: =AVERAGE(C38:I38) -> 12.751223 | M38: =AVERAGE(D38:J38) -> 12.826374
B39: P/TB | C39: =C32/(Model!T83-Model!T55-Model!T56) -> 12.876419 | D39: =D32/(Model!U83-Model!U55-Model!U56) -> 15.267395 | E39: =E32/(Model!V83-Model!V55-Model!V56) -> 19.614095 | F39: =F32/(Model!W83-Model!W55-Model!W56) -> 16.937665 | G39: =G32/(Model!X83-Model!X55-Model!X56) -> 11.850961 | H39: =H32/(Model!Y83-Model!Y55-Model!Y56) -> 12.315823 | I39: =I32/(Model!Z83-Model!Z55-Model!Z56) -> 4.6908419 | L39: =AVERAGE(C39:I39) -> 13.364743 | M39: =AVERAGE(D39:J39) -> 13.44613
B40: P/CF | C40: =C32/Model!T100 -> 24.357351 | D40: =D32/Model!U100 -> 22.250618 | E40: =E32/Model!V100 -> 59.655264 | F40: =F32/Model!W100 -> 31.183418 | G40: =G32/Model!X100 -> 33.604373 | H40: =H32/Model!Y100 -> 28.357388 | I40: =I32/Model!Z100 -> 8.7963545 | L40: =AVERAGE(C40:I40) -> 29.743538 | M40: =AVERAGE(D40:J40) -> 30.641236
B41: P/Sales | C41: =C32/Model!T16 -> 3.3159511 | D41: =D32/Model!U16 -> 3.3577575 | E41: =E32/Model!V16 -> 3.9634075 | F41: =F32/Model!W16 -> 4.6609191 | G41: =G32/Model!X16 -> 3.7323804 | H41: =H32/Model!Y16 -> 3.2339947 | I41: =I32/Model!Z16 -> 1.2723048 | L41: =AVERAGE(C41:I41) -> 3.3623879 | M41: =AVERAGE(D41:J41) -> 3.3701273
B42: Entity:
B43: EV/Sales | C43: =C34/Model!T16 -> 3.2765248 | D43: =D34/Model!U16 -> 3.3274893 | E43: =E34/Model!V16 -> 4.0645491 | F43: =F34/Model!W16 -> 4.6355475 | G43: =G34/Model!X16 -> 3.7154675 | H43: =H34/Model!Y16 -> 3.2543785 | I43: =I34/Model!Z16 -> 1.2702215 | L43: =AVERAGE(C43:I43) -> 3.3634541 | M43: =AVERAGE(D43:J43) -> 3.3779423
B44: EV/EBIT | C44: =C34/Model!T22 -> 26.829173 | D44: =D34/Model!U22 -> 27.276069 | E44: =E34/Model!V22 -> 48.804601 | F44: =F34/Model!W22 -> 29.761859 | G44: =G34/Model!X22 -> 25.999923 | H44: =H34/Model!Y22 -> 28.179122 | I44: =I34/Model!Z22 -> 10.337683 | L44: =AVERAGE(C44:I44) -> 28.169776 | M44: =AVERAGE(D44:J44) -> 28.393209
B45: EV/EBITDA | C45: =Ratios!C34/(Model!T22+Model!T89+Model!T92) -> 22.850292 | D45: =Ratios!D34/(Model!U22+Model!U89+Model!U92) -> 23.700182 | E45: =Ratios!E34/(Model!V22+Model!V89+Model!V92) -> 35.906077 | F45: =Ratios!F34/(Model!W22+Model!W89+Model!W92) -> 26.694856 | G45: =Ratios!G34/(Model!X22+Model!X89+Model!X92) -> 23.093744 | H45: =Ratios!H34/(Model!Y22+Model!Y89+Model!Y92) -> 24.605773 | I45: =Ratios!I34/(Model!Z22+Model!Y89+Model!Y92) -> 9.0991796 | L45: =AVERAGE(C45:I45) -> 23.707158 | M45: =AVERAGE(D45:J45) -> 23.849969
...

Sheet DCF
A1: Main | B1: DCF
B3: Ticker | E3: NKE | G3: Share Price | J3: =Main!I3 -> 44.05
B4: Date | E4: 45519 | G4: Fair Share Price | J4: =V60 -> 69.732016
B5: End of FY | E5: 45808 | G5: Implied Upside | J5: =J4/J3-1 -> 0.58301967
A7: x | B7: Assumptions
B9: Switches | G9: Conservative Case | L9: Base Case | Q9: Optimistic Case
B10: Assuptions | G10: Assuptions | I10: Year | J10: Metic | L10: Assuptions | N10: Year | O10: Metic | Q10: Assuptions | S10: Year | T10: Metic
B11: Revenue | E11: 2 | G11: Revenue | L11: Revenue | Q11: Revenue
B12: EBIT | E12: 2
B13: WACC | E13: 2 | G13: EBIT | L13: EBIT | O13: 0.035 | Q13: EBIT
B14: TGR | E14: 2
B16: Valuation
B17: WACC | E17: =CHOOSE(E13,J17,O17,T17) -> 0.09 | G17: WACC | L17: WACC | O17: 0.09 | Q17: WACC
B18: TGR | E18: =CHOOSE(E14,J18,O18,T18) -> 0.02 | G18: TGR | L18: TGR | O18: 0.02 | Q18: TGR
A22: x | B22: Model | G22: 19 | H22: =G22+1 -> 20 | I22: =H22+1 -> 21 | J22: =I22+1 -> 22 | K22: =J22+1 -> 23 | L22: =K22+1 -> 24 | M22: =L22+1 -> 25 | N22: =M22+1 -> 26 | O22: =N22+1 -> 27 | ... V22: =U22+1 -> 34
B23: Revenue | G23: =Model!U16 -> 39117 | H23: =Model!V16 -> 37403 | I23: =Model!W16 -> 44538 | J23: =Model!X16 -> 46710 | K23: =Model!Y16 -> 51217 | L23: =Model!Z16 -> 51362 | M23: =L23*(1+M24) -> 45712.18 | N23: =M23*(1+N24) -> 45255.058 | O23: =N23*(1+O24) -> 46612.71 | P23: =O23*(1+P24) -> 48477.218 | Q23: =P23*(1+Q24) -> 50901.079 | R23: =Q23*(1+R24) -> 53446.133 | S23: =R23*(1+S24) -> 56118.44 | T23: =S23*(1+T24) -> 58250.941 | ... V23: =U23*(1+V24) -> 62279.343
B24: Growth (%) | H24: =H23/G23-1 -> -0.043817266 | I24: =I23/H23-1 -> 0.1907601 | J24: =J23/I23-1 -> 0.048767345 | K24: =K23/J23-1 -> 0.096488975 | L24: =L23/K23-1 -> 0.0028310912 | M24: {=OFFSET(M24,$E$11,,)} -> -0.11 | N24: {=OFFSET(N24,$E$11,,)} -> -0.01 | O24: {=OFFSET(O24,$E$11,,)} -> 0.03 | P24: {=OFFSET(P24,$E$11,,)} -> 0.04 | Q24: {=OFFSET(Q24,$E$11,,)} -> 0.05 | R24: {=OFFSET(R24,$E$11,,)} -> 0.05 | S24: {=OFFSET(S24,$E$11,,)} -> 0.05 | T24: {=OFFSET(T24,$E$11,,)} -> 0.038 | ... V24: {=OFFSET(V24,$E$11,,)} -> 0.034
B25: Conservative Case
B26: Base Case | M26: -0.11 | N26: -0.01 | O26: 0.03 | P26: 0.04 | Q26: 0.05 | R26: 0.05 | S26: 0.05 | T26: 0.038 | U26: 0.034 | V26: =U26*(1+$O$11) -> 0.034
B27: Optimisitic Case
B29: EBIT | G29: =Model!U22 -> 4772 | H29: =Model!V22 -> 3115 | I29: =Model!W22 -> 6937 | J29: =Model!X22 -> 6675 | K29: =Model!Y22 -> 5915 | L29: =Model!Z22 -> 6311 | M29: =M30*M23 -> 5485.4616 | N29: =N30*N23 -> 5620.6782 | O29: =O30*O23 -> 5991.924 | P29: =P30*P23 -> 6449.707 | Q29: =Q30*Q23 -> 7009.2191 | R29: =R30*R23 -> 7617.2689 | S29: =S30*S23 -> 8278.0669 | T29: =T30*T23 -> 8893.3757 | ... V29: =V30*V23 -> 9964.6948
B30: % of Sales | G30: =G29/G23 -> 0.121993 | H30: =H29/H23 -> 0.08328209 | I30: =I29/I23 -> 0.15575464 | J30: =J29/J23 -> 0.14290302 | K30: =K29/K23 -> 0.115489 | L30: =L29/L23 -> 0.12287294 | M30: {=OFFSET(M30,$E$12,,)} -> 0.12 | N30: {=OFFSET(N30,$E$12,,)} -> 0.1242 | O30: {=OFFSET(O30,$E$12,,)} -> 0.128547 | P30: {=OFFSET(P30,$E$12,,)} -> 0.13304614 | Q30: {=OFFSET(Q30,$E$12,,)} -> 0.13770276 | R30: {=OFFSET(R30,$E$12,,)} -> 0.14252236 | S30: {=OFFSET(S30,$E$12,,)} -> 0.14751064 | T30: {=OFFSET(T30,$E$12,,)} -> 0.15267351 | ... V30: {=OFFSET(V30,$E$12,,)} -> 0.16
B31: Conservative Case
B32: Base Case | M32: 0.12 | N32: =M32*(1+$O$13) -> 0.1242 | O32: =N32*(1+$O$13) -> 0.128547 | P32: =O32*(1+$O$13) -> 0.13304614 | Q32: =P32*(1+$O$13) -> 0.13770276 | R32: =Q32*(1+$O$13) -> 0.14252236 | S32: =R32*(1+$O$13) -> 0.14751064 | T32: =S32*(1+$O$13) -> 0.15267351 | U32: =T32*(1+$O$13) -> 0.15801708 | V32: 0.16
B33: Optimisitic Case
B35: Taxes | G35: =Model!T26 -> 2392 | H35: =Model!U26 -> 772 | I35: =Model!V26 -> 348 | J35: =Model!W26 -> 934 | K35: =Model!X26 -> 605 | L35: =Model!Y26 -> 1131 | M35: =M36*M29 -> 987.38309 | N35: =N36*N29 -> 981.37042 | O35: =O36*O29 -> 1014.8042 | P35: =P36*P29 -> 1059.5652 | Q35: =Q36*Q29 -> 1116.938 | R35: =R36*R29 -> 1177.4174 | S35: =S36*S29 -> 1241.1716 | T35: =T36*T29 -> 1293.4251 | ... V35: =V36*V29 -> 1395.0573
B36: Tax Rate (%) | G36: =G35/G29 -> 0.50125733 | H36: =H35/H29 -> 0.24783307 | I36: =I35/I29 -> 0.050165778 | J36: =J35/J29 -> 0.13992509 | K36: =K35/K29 -> 0.10228233 | L36: =L35/L29 -> 0.1792109 | M36: 0.18 | N36: =M36*(1-3%) -> 0.1746 | O36: =N36*(1-3%) -> 0.169362 | P36: =O36*(1-3%) -> 0.16428114 | Q36: =P36*(1-3%) -> 0.15935271 | R36: =Q36*(1-3%) -> 0.15457212 | S36: =R36*(1-3%) -> 0.14993496 | T36: =S36*(1-3%) -> 0.14543691 | U36: =T36*(1-3%) -> 0.1410738 | V36: 0.14
B38: Nopat | G38: =G29-G35 -> 2380 | H38: =H29-H35 -> 2343 | I38: =I29-I35 -> 6589 | J38: =J29-J35 -> 5741 | K38: =K29-K35 -> 5310 | L38: =L29-L35 -> 5180 | M38: =M29-M35 -> 4498.0785 | N38: =N29-N35 -> 4639.3078 | ... V38: =V29-V35 -> 8569.6375
B40: D&A | G40: =Model!T89 -> 747 | H40: =Model!U89 -> 705 | I40: =Model!V89 -> 721 | J40: =Model!W89 -> 744 | K40: =Model!X89 -> 717 | L40: =Model!Y89 -> 703 | M40: =M41*M23 -> 685.6827 | N40: =N41*N23 -> 678.82587 | O40: =O41*O23 -> 699.19065 | P40: =P41*P23 -> 727.15828 | Q40: =Q41*Q23 -> 763.51619 | R40: =R41*R23 -> 801.692 | S40: =S41*S23 -> 841.7766 | T40: =T41*T23 -> 873.76411 | ... V40: =V41*V23 -> 934.19014
B41: % of Sales | G41: =G40/G23 -> 0.019096556 | H41: =H40/H23 -> 0.018848755 | I41: =I40/I23 -> 0.016188423 | J41: =J40/J23 -> 0.015928067 | K41: =K40/K23 -> 0.013999258 | L41: =L40/L23 -> 0.013687162 | M41: 0.015 | N41: 0.015 | O41: 0.015 | P41: 0.015 | Q41: 0.015 | R41: 0.015 | S41: 0.015 | T41: 0.015 | U41: 0.015 | V41: 0.015
B43: CapEx | G43: =Model!T104 -> -1028 | H43: =Model!U104 -> -1119 | I43: =Model!V104 -> -1086 | J43: =Model!W104 -> -695 | K43: =Model!X104 -> -758 | L43: =Model!Y104 -> -969 | M43: =M44*M23 -> -1005.668 | N43: =N44*N23 -> -995.61128 | O43: =O44*O23 -> -1025.4796 | P43: =P44*P23 -> -1066.4988 | Q43: =Q44*Q23 -> -1119.8237 | R43: =R44*R23 -> -1175.8149 | S43: =S44*S23 -> -1234.6057 | T43: =T44*T23 -> -1281.5207 | ... V43: =V44*V23 -> -1370.1455
B44: % of Sales | G44: =G43/G23 -> -0.026280134 | H44: =H43/H23 -> -0.029917386 | I44: =I43/I23 -> -0.024383672 | J44: =J43/J23 -> -0.014879041 | K44: =K43/K23 -> -0.014799774 | L44: =L43/L23 -> -0.018866088 | M44: -0.022 | N44: -0.022 | O44: -0.022 | P44: -0.022 | Q44: -0.022 | R44: -0.022 | S44: -0.022 | T44: -0.022 | U44: -0.022 | V44: -0.022
B46: Change in WC | G46: =Model!U99 -> 562 | H46: =Model!V99 -> -1245 | I46: =Model!W99 -> 45 | J46: =Model!X99 -> -1660 | K46: =Model!Y99 -> -513 | L46: =Model!Z99 -> 716 | M46: =M47*M23 -> -365.69744 | N46: =N47*N23 -> -362.04047 | O46: =O47*O23 -> -372.90168 | P46: =P47*P23 -> -387.81775 | Q46: =Q47*Q23 -> -407.20863 | R46: =R47*R23 -> -427.56907 | S46: =S47*S23 -> -448.94752 | T46: =T47*T23 -> -466.00752 | ... V46: =V47*V23 -> -498.23474
B47: % of Sales | G47: =G46/G23 -> 0.014367155 | H47: =H46/H23 -> -0.0332861 | I47: =I46/I23 -> 0.0010103732 | J47: =J46/J23 -> -0.035538429 | K47: =K46/K23 -> -0.010016206 | L47: =L46/L23 -> 0.013940267 | M47: -0.008 | N47: -0.008 | O47: -0.008 | P47: -0.008 | Q47: -0.008 | R47: -0.008 | S47: -0.008 | T47: -0.008 | U47: -0.008 | V47: -0.008
B49: Unlevered Free Cashflow | G49: =G38+G40+G43+G46 -> 2661 | H49: =H38+H40+H43+H46 -> 684 | I49: =I38+I40+I43+I46 -> 6269 | J49: =J38+J40+J43+J46 -> 4130 | K49: =K38+K40+K43+K46 -> 4756 | L49: =L38+L40+L43+L46 -> 5630 | M49: =M38+M40+M43+M46 -> 3812.3958 | N49: =N38+N40+N43+N46 -> 3960.4819 | ... V49: =V38+V40+V43+V46 -> 7635.4474
B50: Present Value of unlevered FC | M50: =(M49/(1+$D$15)^M51)*M51 -> 3028.7367 | N50: =N49/(1+$D$15)^N51 -> 3960.4819 | O50: =O49/(1+$D$15)^O51 -> 4277.9291 | P50: =P49/(1+$D$15)^P51 -> 4662.9835 | Q50: =Q49/(1+$D$15)^Q51 -> 5128.7649 | R50: =R49/(1+$D$15)^R51 -> 5638.1594 | S50: =S49/(1+$D$15)^S51 -> 6195.1187 | T50: =T49/(1+$D$15)^T51 -> 6726.1865 | U50: =U49/(1+$D$15)^U51 -> 7271.4453 | V50: =V49/(1+$D$15)^V51 -> 7635.4474
B51: Discount Period | M51: =YEARFRAC(E4,E5) -> 0.79444444 | N51: =M51+1 -> 1.7944444 | O51: =N51+1 -> 2.7944444 | P51: =O51+1 -> 3.7944444 | Q51: =P51+1 -> 4.7944444 | R51: =Q51+1 -> 5.7944444 | S51: =R51+1 -> 6.7944444 | T51: =S51+1 -> 7.7944444 | U51: =T51+1 -> 8.7944444 | V51: =U51+1 -> 9.7944444
B52: Sum of Present Value | V52: =SUM(M50:V50) -> 54525.253
B53: Terminal Value | V53: =(V49*(1+E18))/(E17-E18) -> 111259.38
B54: Present Value of TV | V54: =V53/(1+E17)^V51 -> 47837.103
...

Sheet CoC
A1: Main
B3: Cost of Capital
A4: x | B4: Cost of Equity (CAPM)
B5: Riskfree Rate
B6: Expected Inflation | F6: =+(1+F7)/(1+1.667%)-1 -> 0.02241632 | H6: =(1+Nominal Rate)/(1+Real Rate)-1
B7: Average Real Interest Rate | F7: 0.03946 | H7: = Average Interest Rate of the Past
B8: Riskfree Rate | F8: =F6+F7 -> 0.06187632 | H8: =Goverment Bond or Expected Inflation + Average Real Interest Rate
A10: x | B10: Adjustments for Industry/Company Risk
B11: Raw Beta | F11: =+_xlfn.COVARIANCE.P(J51:J303,D51:D303)/_xlfn.VAR.P(D51:D303) -> 0.52893228 | H11: =Raw beta slope of regression line aginst total market -> Ri= alpha + beta*Rm + standard error
B12: Debt to Value Ratio | H12: Value of Debt/Enterpries Value
B13: Unlevered Beta | H13: = Raw Beta* Debt-to-Equity Ratio (Book Value)
B14: Unlevered Industry Beta | H14: =Median of Peer Group
B15: Levered Industry Beta | F15: =+F11 -> 0.52893228 | H15: =Unlevered Industry Beta * Market Value of Debt to Market Value of Equity
A17: x | B17: Expected Equity Risk Premium
B18: Estimated Future Market Return | F18: 0.11 | H18: = 1/P/E * (1.g/ROE) + g , g = real growth in GDP, P/E => P/E ratio for S&P500 or MSCI World Index, ROE = Average ROE in S&P500 or MSCI World
B19: Riskfree Rate | F19: =+F8 -> 0.06187632
B20: Expected Equity Risk Premium | F20: =F18-F19 -> 0.04812368
A22: x | B22: Cost of Equity (CAPM) | F22: =F8+F15*F20 -> 0.087330488 | H22: => ER(i)=rf+beta(i)*(Er(m)-rf)
A25: x | B25: Cost of Debt
B26: Yield to Maturity on Trading Bonds | F26: 0.03625 | H26: => Price = Coupon/(1+YTM)+Coupon(1+YTM)^2 + … + (Face Value + Coupon)/(1+YTM)^n => solve for YTM
B27: or
B28: Riskfree Rate
B29: Credit Default Spread
B30: Country Rsik Premium
A32: x | B32: Cost of Debt | F32: =+F26 -> 0.03625
A34: x | B34: Capital Structure
B35: Market Value of Debt | F35: =+Main!I7 -> 7942
B36: Market Value of Equity | F36: =+Main!I5 -> 65348.118
B37: Total Enterprise Value | F37: =F35+F36 -> 73290.118
B39: Marginal Tax Rate | F39: 0.21
A41: x | B41: WACC | F41: =(F32*(F35/F37)*(1-F39))+((F36/F37)*F22) -> 0.080970289 | H41: => WACC = (D/D+E)*kd * (1-t) + (E/D+E) * ke
B48: SPX IDX | H48: NKE EQ
B49: Date | C49: Price | D49: Change | H49: Date | I49: Price | J49: Change
B50: 45397 | C50: 5061.82 | H50: 45397 | I50: 87.4382
B51: 45398 | C51: 5051.41 | D51: =+C51/C50-1 -> -0.0020565725 | H51: 45398 | I51: 87.2124 | J51: =+I51/I50-1 -> -0.0025823953
B52: 45399 | C52: 5022.21 | D52: =+C52/C51-1 -> -0.0057805642 | H52: 45399 | I52: 88.3511 | J52: =+I52/I51-1 -> 0.01305663
B53: 45400 | C53: 5011.12 | D53: =+C53/C52-1 -> -0.0022081912 | H53: 45400 | I53: 89.3328 | J53: =+I53/I52-1 -> 0.01111135
B54: 45401 | C54: 4967.23 | D54: =+C54/C53-1 -> -0.008758521 | H54: 45401 | I54: 87.3695 | J54: =+I54/I53-1 -> -0.02197737
B55: 45404 | C55: 5010.6 | D55: =+C55/C54-1 -> 0.0087312244 | H55: 45404 | I55: 90.3145 | J55: =+I55/I54-1 -> 0.033707415
B56: 45405 | C56: 5070.55 | D56: =+C56/C55-1 -> 0.011964635 | H56: 45405 | I56: 90.3145 | J56: =+I56/I55-1 -> 0
...
