Workbook

Sheet Main
A1: Philipp Morris
A2: numbers in mio USD
D3: IR | J3: Price | K3: 182.31
B4: Business Model | J4: Shares | K4: 1556.6796 | L4: Q425
B5: Segment | C5: % of Revenue | D5: Brands | E5: Markets | F5: Competitors | J5: MC | K5: =K4*K3 -> 283798.25
B6: Cigarettes | C6: 0.63 | D6: Malboro, Parliament, Chesterfield, L&M, PM, Local Brands | E6: 175 | J6: Cash | K6: 4872 | L6: Q425
B7: Smoke-Free: | C7: 0.36 | D7: IQOS, Zynn | E7: 84 | J7: Debt | K7: =168+3533+45134 -> 48835 | L7: Q425
B8: heat-not-burn | D8: IQOS HEETS | J8: EV | K8: =K5-K6+K7 -> 327761.25
B9: vapors | D9: IQOS
B10: oral nicotine | D10: ZYN
B11: Wellnes/Health | C11: 0.01
B13: established 1847
B14: 12,5 b invested since 2008 for smoke-free products
B15: In 2022 acquistion of Swedish Match AB -> Leader for orinal nicotine (snus)
B16: Subsidary of Altria Group (MO)
B17: Till 2008 intgrated in Phil Morris International -> Spin Off
B18: PM is responsible solely for International Markets and Altria Group for US Market
B19: https://web.quartr.com/search/all?articleId=bb65609e-1f13-4724-88ed-673487c6a60b&documentType=article

Sheet Model
A1: Main
C2: Q123 | D2: Q223 | E2: Q323 | F2: Q423 | G2: Q124 | H2: Q224 | I2: Q324 | J2: Q424 | K2: Q125 | L2: Q225 | M2: Q325 | N2: Q425 | P2: FY18 | Q2: FY19 | R2: FY20 | S2: FY21 | T2: FY22 | U2: FY23 | V2: FY24 | W2: FY25
B3: TM excl. China and US | C3: 614.2 | D3: 647.2 | E3: 553.1 | F3: =+U3-SUM(C3:E3) -> 765.4 | G3: 618.8 | H3: 657.2 | I3: 568.1 | J3: =+V3-SUM(G3:I3) -> 773.9 | K3: 615.2 | L3: 654.5 | M3: 668.5 | P3: =P9*(1/P4)+(P10*(P5/1)) -> 2773.3773 | Q3: 2705 | R3: 2561 | S3: 2620 | T3: 2621.5 | U3: 2579.9 | V3: 2618 | W3: 2587
B4: Cigarrete Market-Share | C4: 0.227 | D4: 0.234 | E4: 0.237 | F4: =+U4 -> 0.237 | G4: 0.228 | H4: 0.232 | I4: 0.236 | J4: =+V4 -> 0.235 | K4: 0.23 | L4: 0.234 | M4: 0.237 | P4: =26.7/100 -> 0.267 | Q4: =26.2/100 -> 0.262 | R4: 0.249 | S4: 0.237 | T4: 0.236 | U4: 0.237 | V4: 0.235 | W4: 0.234
B5: Smokefree Market-Share | C5: 0.045 | D5: 0.046 | E5: 0.046 | F5: =+U5 -> 0.047 | G5: 0.051 | H5: 51 | I5: 0.052 | J5: =+V5 -> 0.052 | K5: 0.057 | L5: 0.057 | M5: 0.058 | P5: =1.6/100 -> 0.016 | Q5: =2.2/100 -> 0.022 | R5: =+R6-R4 -> 0.027 | S5: =3.5/100 -> 0.035 | T5: =4.1/100 -> 0.041 | U5: =4.7/100 -> 0.047 | V5: 0.052 | W5: 0.058
B6: Total Market Share | C6: 0.272 | D6: 0.279 | E6: 0.283 | F6: =+U6 -> 0.281 | G6: 0.279 | H6: 0.283 | I6: 0.287 | J6: =+V6 -> 0.287 | K6: 0.286 | L6: 0.292 | M6: 0.295 | P6: =+P4+P5 -> 0.283 | Q6: =+Q4+Q5 -> 0.284 | R6: 0.276 | S6: 0.272 | T6: 0.277 | U6: 0.281 | V6: 0.287 | W6: 0.253
B8: PMI Shimpment Volume
B9: Cigarettes | C9: 143.708 | D9: 157.01 | E9: 161.137 | F9: =+U9-SUM(C9:E9) -> 151.045 | G9: 143.191 | H9: 157.618 | I9: 163.238 | J9: =+V9-SUM(G9:I9) -> 152.78 | K9: 144.753 | L9: 155.248 | M9: 157.94 | P9: 740.315 | Q9: 706.709 | R9: 628.518 | S9: 624.875 | T9: 621.9 | U9: 612.9 | V9: 616.827 | W9: 607.4
B10: Heated Tobacco | C10: 27.396 | D10: 31.424 | E10: 32.471 | F10: =+U10-SUM(C10:E10) -> 34.009 | G10: 33.134 | H10: 35.544 | I10: 35.347 | J10: =+V10-SUM(G10:I10) -> 33.718 | K10: 37.089 | L10: 38.81 | M10: 40.836 | P10: 41.372 | Q10: 59.652 | R10: 76.111 | S10: 94.976 | T10: 109.2 | U10: 125.3 | V10: 137.743 | W10: 155.1
B11: Total (in billion units) | C11: =C9+C10 -> 171.104 | D11: =D9+D10 -> 188.434 | E11: =E9+E10 -> 193.608 | F11: =F9+F10 -> 185.054 | G11: =G9+G10 -> 176.325 | H11: =H9+H10 -> 193.162 | I11: =I9+I10 -> 198.585 | J11: =J9+J10 -> 186.498 | ... N11: =N9+N10 -> 0 | P11: =P9+P10 -> 781.687 | Q11: =Q9+Q10 -> 766.361 | R11: =R9+R10 -> 704.629 | S11: =S9+S10 -> 719.851 | T11: =T9+T10 -> 731.1 | U11: =U9+U10 -> 738.2 | V11: =V9+V10 -> 754.57 | W11: =W9+W10 -> 762.5
B13: Nicotine Pouches | C13: 81.3 | D13: 99.5 | E13: 114.6 | F13: =+U13-SUM(C13:E13) -> 125.7 | G13: 145.7 | H13: 149.9 | I13: 164.5 | J13: =+V13-SUM(G13:I13) -> 183.9 | K13: 223.4 | L13: 214.7 | M13: 224.6 | P13: 0 | Q13: 0 | R13: 0 | S13: 1.1 | T13: 42.5 | U13: 421.1 | V13: 644 | W13: 879.6
B14: Snus | C14: 55.6 | D14: 62.6 | E14: 60.3 | F14: =+U14-SUM(C14:E14) -> 61.9 | G14: 61.4 | H14: 58.8 | I14: 61.3 | J14: =+V14-SUM(G14:I14) -> 58.1 | K14: 60.2 | L14: 59.6 | M14: 56.2 | P14: 0 | Q14: 0 | R14: 0 | S14: 6.2 | T14: 54.8 | U14: 240.4 | V14: 239.6 | W14: 227.9
B15: Moist Snuff | C15: 35.2 | D15: 34.1 | E15: 33.2 | F15: =+U15-SUM(C15:E15) -> 31.2 | G15: 34.4 | H15: 34.2 | I15: 34.1 | J15: =+V15-SUM(G15:I15) -> 31.9 | K15: 33.6 | L15: 33.4 | M15: 31.6 | P15: 0 | Q15: 0 | R15: 0 | S15: 0 | T15: 16 | U15: 133.7 | V15: 134.6 | W15: 129.8
B16: Other Oral Products | C16: 1.3 | D16: 1.2 | E16: 0.9 | F16: =+U16-SUM(C16:E16) -> 0.8 | G16: 1 | H16: 1 | I16: 0.7 | J16: =+V16-SUM(G16:I16) -> 0.7 | K16: 0.6 | L16: 0.7 | M16: 0.8 | P16: 0 | Q16: 0 | R16: 0 | S16: 0 | T16: 0 | U16: 4.2 | V16: 3.4 | W16: 2.6
B17: Total Oral Products (in million cans) | C17: =+SUM(C13:C16) -> 173.4 | D17: =+SUM(D13:D16) -> 197.4 | E17: =+SUM(E13:E16) -> 209 | F17: =+SUM(F13:F16) -> 219.6 | G17: =+SUM(G13:G16) -> 242.5 | H17: =+SUM(H13:H16) -> 243.9 | I17: =+SUM(I13:I16) -> 260.6 | J17: =+SUM(J13:J16) -> 274.6 | ... L17: =+SUM(L13:L16) -> 308.4 | M17: =M15+M16 -> 32.4 | N17: =N15+N16 -> 0 | P17: 0 | Q17: 0 | R17: 0 | S17: =+SUM(S13:S16) -> 7.3 | T17: =+SUM(T13:T16) -> 113.3 | U17: =+SUM(U13:U16) -> 799.4 | V17: =+SUM(V13:V16) -> 1021.6 | W17: =+SUM(W13:W16) -> 1239.9
B19: Europe | C19: 3068 | D19: 3574 | E19: 3823 | F19: =+U19-SUM(C19:E19) -> 3766 | G19: 3455 | H19: 3895 | I19: 4197 | J19: =+V19-SUM(G19:I19) -> 3810 | K19: 3560 | L19: 4234 | M19: 4719 | P19: =9298+2921 -> 12219 | Q19: =9817+3282 -> 13099 | R19: =10792+3378 -> 14170 | S19: 13155 | T19: 12972 | U19: 14231 | V19: 15357 | W19: 17111
B20: SSEA, CIS & MEA | C20: 2477 | D20: 2668 | E20: 2777 | F20: =+U20-SUM(C20:E20) -> 2707 | G20: 2658 | H20: 2771 | I20: 2964 | J20: =+V20-SUM(G20:I20) -> 2868 | K20: 2743 | L20: 2926 | M20: 3273 | P20: =4114+4656 -> 8770 | Q20: =4042+5094 -> 9136 | R20: =3088+4396 -> 7484 | S20: 9858 | T20: 10467 | U20: 10629 | V20: 11261 | W20: 12051
B21: EA, AU, PMI GTR | C21: 1520 | D21: 1680 | E21: 1571 | F21: =+U21-SUM(C21:E21) -> 1430 | G21: 1684 | H21: 1673 | I21: 1602 | J21: =+V21-SUM(G21:I21) -> 1434 | K21: 1731 | L21: 1708 | M21: 1768 | P21: 5580 | Q21: 5364 | R21: 5329 | S21: 6448 | T21: 5936 | U21: 6201 | V21: 6393 | W21: 6632
B22: Americas | C22: 868 | D22: 969 | E22: 895 | F22: =+U22-SUM(C22:E22) -> 1075 | G22: 996 | H22: 1129 | I22: 1148 | J22: =+V22-SUM(G22:I22) -> 1261 | K22: 1267 | L22: 1272 | M22: 1085 | P22: 3056 | Q22: 2206 | R22: 1701 | S22: 1843 | T22: 2116 | U22: 3807 | V22: 4534 | W22: 4854
B23: Combustible Tabacco | C23: 5223 | D23: 5790 | E23: 5832 | F23: =+U23-SUM(C23:E23) -> 5489 | G23: 5407 | H23: 5858 | I23: 6134 | J23: =+V23-SUM(G23:I23) -> 5819 | K23: 5406 | L23: 5979 | M23: 6400 | P23: 25529 | Q23: 24218 | R23: 21867 | S23: 22067 | T23: 21572 | U23: 22334 | V23: 23218 | W23: 23794
B24: Smoke-Free | C24: 2710 | D24: 3101 | E24: 3234 | F24: =+U24-SUM(C24:E24) -> 3489 | G24: =3386-90 -> 3296 | H24: 3530 | I24: 3701 | J24: =+V24-SUM(G24:I24) -> 3800 | K24: =3895-51 -> 3844 | L24: =4161-57 -> 4104 | M24: =4445-57 -> 4388 | P24: 4096 | Q24: 5587 | R24: 6827 | S24: 9237 | T24: 9919 | U24: 12534 | V24: 14327 | W24: =16854-238 -> 16616
B25: Wellnes/Health | C25: 86 | D25: 76 | E25: 75 | F25: =+U25-SUM(C25:E25) -> 69 | G25: 90 | H25: 80 | I25: 76 | J25: =+V25-SUM(G25:I25) -> 87 | K25: 51 | L25: 57 | M25: 57 | P25: 0 | Q25: 0 | R25: 0 | S25: 101 | T25: 271 | U25: 306 | V25: 333 | W25: 238
B26: Revenue | C26: 8019 | D26: 8967 | E26: 9141 | F26: =+U26-SUM(C26:E26) -> 9047 | G26: 8793 | H26: 9468 | I26: 9911 | J26: =+V26-SUM(G26:I26) -> 9706 | K26: 9301 | L26: 10140 | M26: 10845 | P26: 29625 | Q26: 29805 | R26: 28694 | S26: 31405 | T26: =SUM(T23:T25) -> 31762 | U26: =SUM(U23:U25) -> 35174 | V26: =SUM(V23:V25) -> 37878 | W26: 40648
B27: COGS | C27: 3038 | D27: 3228 | E27: 3165 | F27: =+U27-SUM(C27:E27) -> 3462 | G27: 3195 | H27: 3345 | I27: 3366 | J27: =+V27-SUM(G27:I27) -> 3423 | K27: 3040 | L27: 3279 | M27: 3487 | P27: 10758 | Q27: 10513 | R27: 9569 | S27: 10030 | T27: 11402 | U27: 12893 | V27: 13329 | W27: 13366
B28: Gross Profit | C28: =C26-C27 -> 4981 | D28: =D26-D27 -> 5739 | E28: =E26-E27 -> 5976 | F28: =F26-F27 -> 5585 | G28: =G26-G27 -> 5598 | H28: =H26-H27 -> 6123 | I28: =I26-I27 -> 6545 | J28: =J26-J27 -> 6283 | ... M28: =M26-M27 -> 7358 | P28: =P26-P27 -> 18867 | Q28: =Q26-Q27 -> 19292 | R28: =R26-R27 -> 19125 | S28: =S26-S27 -> 21375 | T28: =T26-T27 -> 20360 | U28: =U26-U27 -> 22281 | V28: =V26-V27 -> 24549 | W28: =W26-W27 -> 27282
B29: SGA | C29: 2250 | D29: 2508 | E29: 2606 | F29: =+U29-SUM(C29:E29) -> 2696 | G29: 2553 | H29: 2679 | I29: 2891 | J29: =+V29-SUM(G29:I29) -> 3024 | K29: 2717 | L29: 3108 | M29: 3095 | P29: =7408+82 -> 7490 | Q29: =8695+66 -> 8761 | R29: =7384+73 -> 7457 | S29: 8400 | T29: 8114 | U29: 10060 | V29: 11147 | W29: 12349
B30: Other Income | C30: 0 | D30: -665 | E30: 0 | F30: 0 | G30: 0 | H30: 0 | I30: 0 | J30: =+V30-SUM(G30:I30) -> 0 | K30: 0 | L30: -41 | M30: 0 | P30: 0 | Q30: 0 | R30: 0 | S30: 0 | T30: 0 | U30: -665 | V30: 0 | W30: -41
B31: Operating Profit | C31: =C28-C29+C30 -> 2731 | D31: =D28-D29+D30 -> 2566 | E31: =E28-E29+E30 -> 3370 | F31: =F28-F29+F30 -> 2889 | G31: =G28-G29+G30 -> 3045 | H31: =H28-H29+H30 -> 3444 | I31: =I28-I29+I30 -> 3654 | J31: =J28-J29+J30 -> 3259 | ... M31: =M28-M29+M30 -> 4263 | P31: =P28-P29+P30 -> 11377 | Q31: =Q28-Q29+Q30 -> 10531 | R31: =R28-R29+R30 -> 11668 | S31: =S28-S29+S30 -> 12975 | T31: =T28-T29+T30 -> 12246 | U31: =U28-U29+U30 -> 11556 | V31: =V28-V29+V30 -> 13402 | W31: =W28-W29+W30 -> 14892
B32: Interest Expense | C32: 230 | D32: 297 | E32: 261 | F32: =+U32-SUM(C32:E32) -> 273 | G32: 299 | H32: 329 | I32: 189 | J32: =+V32-SUM(G32:I32) -> 326 | K32: 241 | L32: 277 | M32: 230 | P32: 665 | Q32: 570 | R32: 618 | S32: 628 | T32: 588 | U32: 1061 | V32: 1143 | W32: 966
B33: Pension Expenses | C33: 22 | D33: 6 | E33: 8 | F33: =+U33-SUM(C33:E33) -> 9 | G33: 15 | H33: 14 | I33: 15 | J33: =+V33-SUM(G33:I33) -> 16 | K33: 12 | L33: 11 | M33: 14 | P33: 41 | Q33: 89 | R33: 97 | S33: 115 | T33: 24 | U33: 45 | V33: 60 | W33: 46
B34: Pretax Income | C34: =C31-C32-C33 -> 2479 | D34: =D31-D32-D33 -> 2263 | E34: =E31-E32-E33 -> 3101 | F34: =F31-F32-F33 -> 2607 | G34: =G31-G32-G33 -> 2731 | H34: =H31-H32-H33 -> 3101 | I34: =I31-I32-I33 -> 3450 | J34: =J31-J32-J33 -> 2917 | ... M34: =M31-M32-M33 -> 4019 | P34: =P31-P32-P33 -> 10671 | Q34: =Q31-Q32-Q33 -> 9872 | R34: =R31-R32-R33 -> 10953 | S34: =S31-S32-S33 -> 12232 | T34: =T31-T32-T33 -> 11634 | U34: =U31-U32-U33 -> 10450 | V34: =V31-V32-V33 -> 12199 | W34: =W31-W32-W33 -> 13880
B35: Income Tax Expense | C35: 428 | D35: 560 | E35: 1031 | F35: =+U35-SUM(C35:E35) -> 320 | G35: 676 | H35: 734 | I35: 735 | J35: =+V35-SUM(G35:I35) -> 872 | K35: 659 | L35: 652 | M35: 751 | P35: 2445 | Q35: 2293 | R35: 2377 | S35: 2671 | T35: 2244 | U35: 2339 | V35: 3017 | W35: 2737
B36: Equity Investment Loss & other | C36: -51 | D36: 21 | E36: -101 | F36: =+U36-SUM(C36:E36) -> -26 | G36: -191 | H36: -161 | I36: -500 | J36: =+V36-SUM(G36:I36) -> 2531 | K36: -205 | L36: -376 | M36: -345 | P36: -60 | Q36: -149 | R36: -16 | S36: -149 | T36: -137 | U36: -157 | V36: =-637+2316 -> 1679 | W36: -705
B37: Net Income | C37: =C34-C35-C36 -> 2102 | D37: =D34-D35-D36 -> 1682 | E37: =E34-E35-E36 -> 2171 | F37: =F34-F35-F36 -> 2313 | G37: =G34-G35-G36 -> 2246 | H37: =H34-H35-H36 -> 2528 | I37: =I34-I35-I36 -> 3215 | J37: =J34-J35-J36 -> -486 | ... M37: =M34-M35-M36 -> 3613 | P37: =P34-P35-P36 -> 8286 | Q37: =Q34-Q35-Q36 -> 7728 | R37: =R34-R35-R36 -> 8592 | S37: =S34-S35-S36 -> 9710 | T37: =T34-T35-T36 -> 9527 | U37: =U34-U35-U36 -> 8268 | V37: =V34-V35-V36 -> 7503 | W37: =W34-W35-W36 -> 11848
B38: Minorities | C38: 107 | D38: 144 | E38: 117 | F38: =+U38-SUM(C38:E38) -> 87 | G38: 98 | H38: 122 | I38: 133 | J38: =+V38-SUM(G38:I38) -> 93 | K38: 147 | L38: 109 | M38: 135 | P38: 375 | Q38: 543 | R38: 536 | S38: 601 | T38: 479 | U38: 455 | V38: 446 | W38: 500
B39: Net Income to Firm | C39: =C37-C38 -> 1995 | D39: =D37-D38 -> 1538 | E39: =E37-E38 -> 2054 | F39: =F37-F38 -> 2226 | G39: =G37-G38 -> 2148 | H39: =H37-H38 -> 2406 | I39: =I37-I38 -> 3082 | J39: =J37-J38 -> -579 | ... M39: =M37-M38 -> 3478 | P39: =P37-P38 -> 7911 | Q39: =Q37-Q38 -> 7185 | R39: =R37-R38 -> 8056 | S39: =S37-S38 -> 9109 | T39: =T37-T38 -> 9048 | U39: =U37-U38 -> 7813 | V39: =V37-V38 -> 7057 | W39: =W37-W38 -> 11348
B41: EPS | C41: 1.28 | D41: 1.01 | E41: 1.32 | F41: =+U41-SUM(C41:E41) -> 1.4241495 | G41: 1.38 | H41: 1.54 | I41: 1.98 | J41: =+J39/J42 -> -0.37258687 | K41: =+K39/K42 -> 1.7287918 | L41: =+L39/L42 -> 1.9530848 | M41: =+M39/M42 -> 0.30096919 | P41: =+P39/P42 -> 5.0874598 | Q41: =+Q39/Q42 -> 4.6176093 | R41: =+R39/R42 -> 5.1707317 | S41: =+S39/S42 -> 5.842848 | T41: =+T39/T42 -> 5.8374194 | U41: =+U39/U42 -> 5.0341495 | V41: =+V39/V42 -> 4.541184 | W41: =+W39/W42 -> 7.283697
B42: Shares | C42: =C39/C41 -> 1558.5938 | D42: =D39/D41 -> 1522.7723 | E42: =E39/E41 -> 1556.0606 | F42: =F39/F41 -> 1563.0382 | G42: =G39/G41 -> 1556.5217 | H42: =H39/H41 -> 1562.3377 | I42: =I39/I41 -> 1556.5657 | J42: 1554 | K42: 1556 | L42: 1556 | M42: 11556 | P42: 1555 | Q42: 1556 | R42: 1558 | S42: 1559 | T42: 1550 | U42: 1552 | V42: 1554 | W42: 1558
B44: Combustible Tabacco | G44: =G23/C23-1 -> 0.035228796 | H44: =H23/D23-1 -> 0.011744387 | I44: =I23/E23-1 -> 0.051783265 | J44: =J23/F23-1 -> 0.06012024 | K44: =K23/G23-1 -> -0.00018494544 | L44: =L23/H23-1 -> 0.020655514 | M44: =M23/I23-1 -> 0.043364852 | N44: =N23/J23-1 -> -1 | Q44: =Q23/P23-1 -> -0.051353363 | R44: =R23/Q23-1 -> -0.097076555 | S44: =S23/R23-1 -> 0.009146202 | T44: =T23/S23-1 -> -0.022431685 | U44: =U23/T23-1 -> 0.035323568 | V44: =V23/U23-1 -> 0.039580908 | W44: =W23/V23-1 -> 0.024808338
B45: Smoke-Free | G45: =G24/C24-1 -> 0.21623616 | H45: =H24/D24-1 -> 0.13834247 | I45: =I24/E24-1 -> 0.14440322 | J45: =J24/F24-1 -> 0.089137289 | K45: =K24/G24-1 -> 0.16626214 | L45: =L24/H24-1 -> 0.16260623 | M45: =M24/I24-1 -> 0.18562551 | N45: =N24/J24-1 -> -1 | Q45: =Q24/P24-1 -> 0.36401367 | R45: =R24/Q24-1 -> 0.2219438 | S45: =S24/R24-1 -> 0.35301011 | T45: =T24/S24-1 -> 0.073833496 | U45: =U24/T24-1 -> 0.26363545 | V45: =V24/U24-1 -> 0.1430509 | W45: =W24/V24-1 -> 0.15976827
...

Sheet Ratios
B2: Ratios | C2: 18 | D2: =C2+1 -> 19 | E2: =D2+1 -> 20 | F2: =E2+1 -> 21 | G2: =F2+1 -> 22 | H2: =G2+1 -> 23 | I2: =H2+1 -> 24 | K2: Average | L2: Median | N2: Descripition
B3: Etragskennzahlen
B4: Eigenkapitalrendite (ROE) | C4: =Model!P39/Model!P103 -> -0.73666077 | D4: =Model!Q39/Model!Q103 -> -0.74851547 | E4: =Model!R39/Model!R103 -> -0.75778384 | F4: =Model!S39/Model!S103 -> -1.109771 | G4: =Model!T39/Model!T103 -> -1.4336872 | H4: =Model!U39/Model!U103 -> -0.82712259 | I4: =Model!V39/Model!V103 -> -0.71499493 | N4: Net Income / Equity
B5: Return on Capital Employed (ROCE) | N5: EBIT/(Long Term Assets + Working Capital (Exclusive of cash)-Accounts Payables)
B6: Return on Capital Invested (ROIC) | C6: =(Model!P31*(1-Model!P50))/(Model!P103+Model!P79+Model!P89+Model!P78-Model!P54) -> 0.60790443 | D6: =(Model!Q31*(1-Model!Q50))/(Model!Q103+Model!Q79+Model!Q89+Model!Q78-Model!Q54) -> 0.55433199 | E6: =(Model!R31*(1-Model!R50))/(Model!R103+Model!R79+Model!R89+Model!R78-Model!R54) -> 0.67051978 | F6: =(Model!S31*(1-Model!S50))/(Model!S103+Model!S79+Model!S89+Model!S78-Model!S54) -> 0.67155061 | G6: =(Model!T31*(1-Model!T50))/(Model!T103+Model!T79+Model!T89+Model!T78-Model!T54) -> 0.29412158 | H6: =(Model!U31*(1-Model!U50))/(Model!U103+Model!U79+Model!U89+Model!U78-Model!U54) -> 0.25335272 | I6: =(Model!V31*(1-Model!V50))/(Model!V103+Model!V79+Model!V89+Model!V78-Model!V54) -> 0.31913315 | N6: (EBIT-Tax Expenses)/(Book Value of Equity + Book Value of Debt - Book Value of Cash)
B7: Retention Rate | N7: 1 - Dividends/Net Income
B8: Expected Growth | N8: Retention rate * ROE
B9: Reinvestment Rate | N9: Net CapEx + Change in WC / EBIT * (1-t)
B10: Expected Growth | N10: Reinvestment rate * ROIC
A13: x | B13: Kennzahlen zur finanziellen Stabilität
B14: EK-Quote | N14: Book Value of Equity/Total of Balance Sheet
B15: Gearing | N15: (Debt - Cash (Net Debt))/Book Value of Equity
B16: Interest Coverage Ratio | N16: EBIT/Interest Expense
B17: Net Debt / EBITDA | N17: Net Debt/EBITDA
B18: Goodwill-Anteil | N18: Goodwill/Balance Sheet Total
A20: x | B20: Kennzahlen WC Management
B21: Debitorenlaufzeit | N21: Accounts Receivables/Revenue*360
B22: Kreditorenlaufzeit | N22: Accounts Payable/Revenue*360
B23: Umschlaghäufigkeit der Vorräte | N23: Cogs/Inventory
B24: Lagedauer | N24: 360/Umschlaghäufigkeit der Vorräte
B25: Cash Conversion | N25: Cash Conversion Cycle = Debitorenlaufzeit + Lagedauer - Kreditorenlaufzeit
A27: x | B27: Bewertungskennzahlen
B28: Equitymultiplikatoren:
B29: Market Cap
B30: EV
B31: P/E Ratio | N31: Share Price/EPS
B32: PEG Ratio | N32: P/E Ratio / Growth
B33: P/B Ratio | N33: Market Cap/Book Vakue of Equity
B34: Entitymultipliaktoren
B35: EV/EBITDA | N35: EV/EBITDA
B36: EV/EBIT | N36: EV/EBIT
B37: EV/FCF | N37: EV/FCF
B38: EV/Sales | N38: EV/Revenue

Sheet DCF
B2: Phil Morris DCF
B4: Ticker | E4: PM | G4: Share Price | J4: =Main!K3 -> 182.31
B5: Date | E5: 45504 | G5: Fair Share Price | J5: =V61 -> 148.23643
B6: End of FY | E6: 45657 | G6: Implied Upside | J6: =J5/J4-1 -> -0.18689907
A8: x | B8: Assumptions
B10: Switches | G10: Conservative Case | L10: Base Case | Q10: Optimistic Case
B11: Assuptions | G11: Assuptions | I11: Year | J11: Metic | L11: Assuptions | N11: Year | O11: Metic | Q11: Assuptions | S11: Year | T11: Metic
B12: Revenue | E12: 2 | G12: Revenue | L12: Revenue | Q12: Revenue
B13: EBIT | E13: 2
B14: WACC | E14: 2 | G14: EBIT | L14: EBIT | Q14: EBIT
B15: TGR | E15: 2
B17: Valuation
B18: WACC | E18: 0.07 | G18: WACC | L18: WACC | O18: 0.07 | Q18: WACC
B19: TGR | E19: =CHOOSE(E15,J19,O19,T19) -> 0.015 | G19: TGR | L19: TGR | O19: 0.015 | Q19: TGR
A23: x | B23: Model | G23: 18 | H23: =G23+1 -> 19 | I23: =H23+1 -> 20 | J23: =I23+1 -> 21 | K23: =J23+1 -> 22 | L23: =K23+1 -> 23 | M23: =L23+1 -> 24 | N23: =M23+1 -> 25 | O23: =N23+1 -> 26 | ... V23: =U23+1 -> 33
B24: Revenue | G24: =Model!P26 -> 29625 | H24: =Model!Q26 -> 29805 | I24: =Model!R26 -> 28694 | J24: =Model!S26 -> 31405 | K24: =Model!T26 -> 31762 | L24: =Model!U26 -> 35174 | M24: =L24*(1+M25) -> 36580.96 | N24: =M24*(1+N25) -> 38044.198 | O24: =N24*(1+O25) -> 39565.966 | P24: =O24*(1+P25) -> 41148.605 | Q24: =P24*(1+Q25) -> 42794.549 | R24: =Q24*(1+R25) -> 44506.331 | S24: =R24*(1+S25) -> 46286.584 | T24: =S24*(1+T25) -> 48138.048 | ... V24: =U24*(1+V25) -> 52066.112
B25: Growth (%) | H25: =H24/G24-1 -> 0.0060759494 | I25: =I24/H24-1 -> -0.037275625 | J25: =J24/I24-1 -> 0.094479682 | K25: =K24/J24-1 -> 0.011367617 | L25: =L24/K24-1 -> 0.10742397 | M25: {=OFFSET(M25,$E$12,,)} -> 0.04 | N25: {=OFFSET(N25,$E$12,,)} -> 0.04 | O25: {=OFFSET(O25,$E$12,,)} -> 0.04 | P25: {=OFFSET(P25,$E$12,,)} -> 0.04 | Q25: {=OFFSET(Q25,$E$12,,)} -> 0.04 | R25: {=OFFSET(R25,$E$12,,)} -> 0.04 | S25: {=OFFSET(S25,$E$12,,)} -> 0.04 | T25: {=OFFSET(T25,$E$12,,)} -> 0.04 | ... V25: {=OFFSET(V25,$E$12,,)} -> 0.04
B26: Conservative Case
B27: Base Case | M27: 0.04 | N27: 0.04 | O27: 0.04 | P27: 0.04 | Q27: 0.04 | R27: 0.04 | S27: 0.04 | T27: 0.04 | U27: 0.04 | V27: 0.04
B28: Optimisitic Case
B30: EBIT | G30: =Model!P31 -> 11377 | H30: =Model!Q31 -> 10531 | I30: =Model!R31 -> 11668 | J30: =Model!S31 -> 12975 | K30: =Model!T31 -> 12246 | L30: =Model!U31 -> 11556 | M30: =M31*M24 -> 13900.765 | N30: =N31*N24 -> 14456.795 | O30: =O31*O24 -> 15035.067 | P30: =P31*P24 -> 15636.47 | Q30: =Q31*Q24 -> 16261.929 | R30: =R31*R24 -> 16912.406 | S30: =S31*S24 -> 17588.902 | T30: =T31*T24 -> 18292.458 | ... V30: =V31*V24 -> 19785.123
B31: % of Sales | G31: =G30/G24 -> 0.38403376 | H31: =H30/H24 -> 0.35332998 | I31: =I30/I24 -> 0.40663553 | J31: =J30/J24 -> 0.41315077 | K31: =K30/K24 -> 0.38555507 | L31: =L30/L24 -> 0.32853812 | M31: {=OFFSET(M31,$E$13,,)} -> 0.38 | N31: {=OFFSET(N31,$E$13,,)} -> 0.38 | O31: {=OFFSET(O31,$E$13,,)} -> 0.38 | P31: {=OFFSET(P31,$E$13,,)} -> 0.38 | Q31: {=OFFSET(Q31,$E$13,,)} -> 0.38 | R31: {=OFFSET(R31,$E$13,,)} -> 0.38 | S31: {=OFFSET(S31,$E$13,,)} -> 0.38 | T31: {=OFFSET(T31,$E$13,,)} -> 0.38 | ... V31: {=OFFSET(V31,$E$13,,)} -> 0.38
B32: Conservative Case
B33: Base Case | M33: 0.38 | N33: 0.38 | O33: 0.38 | P33: 0.38 | Q33: 0.38 | R33: 0.38 | S33: 0.38 | T33: 0.38 | U33: 0.38 | V33: 0.38
B34: Optimisitic Case
B36: Taxes | G36: =Model!P35 -> 2445 | H36: =Model!Q35 -> 2293 | I36: =Model!R35 -> 2377 | J36: =Model!S35 -> 2671 | K36: =Model!T35 -> 2244 | L36: =Model!U35 -> 2339 | M36: =M37*M30 -> 2780.153 | N36: =N37*N30 -> 2891.3591 | O36: =O37*O30 -> 3007.0134 | P36: =P37*P30 -> 3127.294 | Q36: =Q37*Q30 -> 3252.3857 | R36: =R37*R30 -> 3382.4812 | S36: =S37*S30 -> 3517.7804 | T36: =T37*T30 -> 3658.4916 | ... V36: =V37*V30 -> 3957.0245
B37: Tax Rate (%) | G37: =G36/G30 -> 0.21490727 | H37: =H36/H30 -> 0.21773811 | I37: =I36/I30 -> 0.20371957 | J37: =J36/J30 -> 0.20585742 | K37: =K36/K30 -> 0.18324351 | L37: =L36/L30 -> 0.20240568 | M37: 0.2 | N37: 0.2 | O37: 0.2 | P37: 0.2 | Q37: 0.2 | R37: 0.2 | S37: 0.2 | T37: 0.2 | U37: 0.2 | V37: 0.2
B39: Nopat | G39: =G30-G36 -> 8932 | H39: =H30-H36 -> 8238 | I39: =I30-I36 -> 9291 | J39: =J30-J36 -> 10304 | K39: =K30-K36 -> 10002 | L39: =L30-L36 -> 9217 | M39: =M30-M36 -> 11120.612 | N39: =N30-N36 -> 11565.436 | ... V39: =V30-V36 -> 15828.098
B41: D&A | G41: =Model!P110 -> 989 | H41: =Model!Q110 -> 964 | I41: =Model!R110 -> 981 | J41: =Model!S110 -> 998 | K41: =Model!T110 -> 1077 | L41: =Model!U110 -> 1398 | M41: =M42*M24 -> 1243.7526 | N41: =N42*N24 -> 1293.5027 | O41: =O42*O24 -> 1345.2429 | P41: =P42*P24 -> 1399.0526 | Q41: =Q42*Q24 -> 1455.0147 | R41: =R42*R24 -> 1513.2153 | S41: =S42*S24 -> 1573.7439 | T41: =T42*T24 -> 1636.6936 | ... V41: =V42*V24 -> 1770.2478
B42: % of Sales | G42: =G41/G24 -> 0.033383966 | H42: =H41/H24 -> 0.032343567 | I42: =I41/I24 -> 0.034188332 | J42: =J41/J24 -> 0.031778379 | K42: =K41/K24 -> 0.033908444 | L42: =L41/L24 -> 0.039745266 | M42: 0.034 | N42: 0.034 | O42: 0.034 | P42: 0.034 | Q42: 0.034 | R42: 0.034 | S42: 0.034 | T42: 0.034 | U42: 0.034 | V42: 0.034
B44: CapEx | G44: =-Model!P124 -> 1436 | H44: =-Model!Q124 -> 852 | I44: =-Model!R124 -> 602 | J44: =-Model!S124 -> 748 | K44: =-Model!T124 -> 1077 | L44: =-Model!U124 -> 1321 | M44: =M45*M24 -> 1390.0765 | N44: =N45*N24 -> 1445.6795 | O44: =O45*O24 -> 1503.5067 | P44: =P45*P24 -> 1563.647 | Q44: =Q45*Q24 -> 1626.1929 | R44: =R45*R24 -> 1691.2406 | S44: =S45*S24 -> 1758.8902 | T44: =T45*T24 -> 1829.2458 | ... V44: =V45*V24 -> 1978.5123
B45: % of Sales | G45: =G44/G24 -> 0.048472574 | H45: =H44/H24 -> 0.028585808 | I45: =I44/I24 -> 0.020979996 | J45: =J44/J24 -> 0.023817863 | K45: =K44/K24 -> 0.033908444 | L45: =L44/L24 -> 0.037556149 | M45: 0.038 | N45: 0.038 | O45: 0.038 | P45: 0.038 | Q45: 0.038 | R45: 0.038 | S45: 0.038 | T45: 0.038 | U45: 0.038 | V45: 0.038
B47: Change in WC | G47: =Model!P122 -> 306 | H47: =Model!Q122 -> 1168 | I47: =Model!R122 -> 396 | J47: =Model!S122 -> 1298 | K47: =Model!T122 -> 414 | L47: =Model!U122 -> -842 | M47: =M48*M24 -> -365.8096 | N47: =N48*N24 -> -380.44198 | O47: =O48*O24 -> -395.65966 | P47: =P48*P24 -> -411.48605 | Q47: =Q48*Q24 -> -427.94549 | R47: =R48*R24 -> -445.06331 | S47: =S48*S24 -> -462.86584 | T47: =T48*T24 -> -481.38048 | ... V47: =V48*V24 -> -520.66112
B48: % of Sales | G48: =G47/G24 -> 0.010329114 | H48: =H47/H24 -> 0.039188056 | I48: =I47/I24 -> 0.013800795 | J48: =J47/J24 -> 0.041330998 | K48: =K47/K24 -> 0.013034444 | L48: =L47/L24 -> -0.023938136 | M48: -0.01 | N48: -0.01 | O48: -0.01 | P48: -0.01 | Q48: -0.01 | R48: -0.01 | S48: -0.01 | T48: -0.01 | U48: -0.01 | V48: -0.01
B50: Unlevered Free Cashflow | G50: =G39+G41-G44+G47 -> 8791 | H50: =H39+H41-H44+H47 -> 9518 | I50: =I39+I41-I44+I47 -> 10066 | J50: =J39+J41-J44+J47 -> 11852 | K50: =K39+K41-K44+K47 -> 10416 | L50: =L39+L41-L44+L47 -> 8452 | M50: =M39+M41-M44+M47 -> 10608.478 | N50: =N39+N41-N44+N47 -> 11032.818 | ... V50: =V39+V41-V44+V47 -> 15099.173
B51: Present Value of unlevered FC | M51: =M50/(1+$D$16)^M52 -> 10608.478 | N51: =N50/(1+$D$16)^N52 -> 11032.818 | O51: =O50/(1+$D$16)^O52 -> 11474.13 | P51: =P50/(1+$D$16)^P52 -> 11933.095 | Q51: =Q50/(1+$D$16)^Q52 -> 12410.419 | R51: =R50/(1+$D$16)^R52 -> 12906.836 | S51: =S50/(1+$D$16)^S52 -> 13423.109 | T51: =T50/(1+$D$16)^T52 -> 13960.034 | ... V51: =V50/(1+$D$16)^V52 -> 15099.173
B52: Discount Period | M52: =YEARFRAC(E5,E6) -> 0.41666667 | N52: =M52+1 -> 1.4166667 | O52: =N52+1 -> 2.4166667 | P52: =O52+1 -> 3.4166667 | Q52: =P52+1 -> 4.4166667 | R52: =Q52+1 -> 5.4166667 | S52: =R52+1 -> 6.4166667 | T52: =S52+1 -> 7.4166667 | U52: =T52+1 -> 8.4166667 | V52: =U52+1 -> 9.4166667
B53: Sum of Present Value | V53: =SUM(M51:V51) -> 127366.53
B54: Terminal Value | V54: =(V50*(1+E19))/(E18-E19) -> 278648.37
B55: Present Value of TV | V55: =V54/(1+E18)^V52 -> 147353.1
...
