Workbook

Sheet Main
A1: Paypal Holding Inc
A2: numbers in mio USD | H2: Price | I2: 58.7
H3: Shares | I3: 887 | J3: Q226
B4: PYPL | H4: MC | I4: =+I3*I2 -> 52066.9
B5: IR | H5: Cash | I5: =8306+2950 -> 11256 | J5: Q226
H6: Debt | I6: =10895+2505 -> 13400 | J6: Q226
B7: Notes | H7: EV | I7: =+I4-I5+I6 -> 54210.9
B8: PayPal Everywhere, Enhanced chekckout, Fastlane
B9: Partnerships: adyen, prime, fiserv, global payment, shopify | H9: Founded: | I9: 1998 | J9: Founders: Peter Thiel, Max Levchin, Ken Howery, Luke Nosek, Yu Pan
B10: Paypal, Venmo | K10: 2000: merger with X.com by Elon Musk, 2002 aquired by Ebay for 1,5 billion USD, 2015 spin-off
B11: Businessmodel:
B12: payment solutions | J12: Management
B13: Revenue -> primarily: charging feesfrom merchants for completing transactions, | J13: CEO: | K13: Enrique Lores
B14: typical fee: 2,99% in the US, currency conversion fees, instant transfer; | J14: CPO: | K14: Isable Cruz
B15: value added services: partnerships, interest & fees credit products etc. | J15: CFO: | K15: Jamie Miller | M15: Interim CEO
B16: growth drivers: win checkout, scale omni and venmo, | J16: CTO: | K16: Srini Venkatesan
B17: drive psp profitability, scale next-gen growth vectors (crypto, agentic commerce)
B18: Launch of Paypal virtual credit card in Germany -> banking license in Luxembourg | J18: Q425: | K18: Alex Chriss (CEO 2023 - 2025)
B19: Paypal stable coin PYUSD = 1 USD -> aims to yield 3.7%
B20: MarketCap PYUSD: | D20: 770
B21: MarketCap Thether: | D21: 128000
B22: Deal with OpenAi
B23: Paypal potential candidate for Takeover (https://finance.yahoo.com/news/paypal-faces-takeover-talk-ai-221058219.html?guccounter=1&guce_referrer=aHR0cHM6Ly93d3cuZ29vZ2xlLmNvbS8&guce_referrer_sig=AQAAADvebTLk8diE1pdvprcTUyH1RRbW6aRvjvFzRUYfnIHXBL10fNG_DM_aensxTpeyxmAAKZUak8aw5PPdMSyGeC0dHMxttNiuqbya5St_2_xzQtHpAIH16cXnDjrJkyVOak4uLBUTq69Zy3mgw1wX8oVw4F7_zIewFOntMvGyy4vD)
B24: Q1 26: Turnaround plan: cut 20% of workforce
B27: Competitors: Visa, Mastercard

Sheet Model
A1: Main
C2: Q123 | D2: Q223 | E2: Q323 | F2: Q423 | G2: Q124 | H2: Q224 | I2: Q324 | J2: Q424 | K2: Q125 | L2: Q225 | M2: Q325 | N2: Q425 | O2: Q126 | P2: Q226 | Q2: Q326 | R2: Q426 | T2: FY16 | U2: FY17 | V2: FY18 | W2: FY19 | X2: FY20 | Y2: FY21 | Z2: FY22 | AA2: FY23 | AB2: FY24 | AC2: FY25
B3: Global GDP | T3: 62542663 | U3: 62542663 | V3: 62542663 | W3: 62542663 | X3: 62542663 | Y3: 62542663 | Z3: 62542663 | AA3: 62542663 | AB3: =+AA3*(1+2%) -> 63793516 | AC3: =+AB3*(1+2%) -> 65069386
B4: Service GDP | T4: 40027304 | U4: 40027304 | V4: 40027304 | W4: 40027304 | X4: 40421323 | Y4: 40965444 | Z4: 39777133 | AA4: 38526280 | AB4: 39296806 | AC4: =+AB4*(1+2%) -> 40082742
B5: % of PayPal Payment Volume | T5: =+T12/T4 -> 0.008992062 | U5: =+U12/U4 -> 0.011396696 | V5: =+V12/V4 -> 0.014450611 | W5: =+W12/W4 -> 0.017785984 | X5: =+X12/X4 -> 0.023157629 | Y5: =+Y12/Y4 -> 0.030412926 | Z5: =+Z12/Z4 -> 0.034117893 | AA5: =+AA12/AA4 -> 0.039676268 | ... AC5: =+AC12/AC4 -> 0.044756893
B7: Active Accounts | C7: 433 | D7: 431 | E7: 428 | F7: 426 | G7: 427 | H7: 429 | I7: 432 | J7: 434 | K7: 436 | L7: 438 | M7: 438 | N7: 439 | O7: 439 | P7: 439 | T7: 199 | U7: 229 | V7: 267 | W7: 305 | X7: 377 | Y7: 426 | Z7: 435 | AA7: 426 | AB7: 434 | AC7: =+N7 -> 439
B8: Number of transaction | C8: 5835 | D8: 6074 | E8: 6275 | F8: 6798 | G8: 6505 | H8: 6580 | I8: 6631 | J8: 6619 | K8: 6045 | L8: 6226 | M8: 6331 | N8: 6754 | O8: 6475 | P8: 6750 | T8: 6295 | U8: 7769 | V8: 9871 | W8: 12361 | X8: 15423 | Y8: 19348 | Z8: 22349 | AA8: 24981 | AB8: 26334 | AC8: =+SUM(K8:N8) -> 25356
B9: Average Transaction Amount | C9: =+C12/C8 -> 60.755441 | D9: =+D12/D8 -> 61.991768 | E9: =+E12/E8 -> 61.78502 | F9: =+F12/F8 -> 60.287143 | G9: =+G12/G8 -> 62.08455 | H9: =+H12/H8 -> 63.345593 | I9: =+I12/I8 -> 63.737144 | J9: =+J12/J8 -> 66.148361 | K9: =+K12/K8 -> 69.017039 | L9: 58.3 | M9: =+M12/M8 -> 72.356342 | N9: =+N12/N8 -> 70.348682 | O9: =+O12/O8 -> 71.653282 | P9: =+P12/P8 -> 72.06637 | T9: =+T12/T8 -> 57.176807 | U9: =+U12/U8 -> 58.717853 | V9: =+V12/V8 -> 58.597812 | W9: =+W12/W8 -> 57.59445 | X9: =+X12/X8 -> 60.692602 | Y9: =+Y12/Y8 -> 64.393167 | Z9: =+Z12/Z8 -> 60.723612 | AA9: =+AA12/AA8 -> 61.189664 | ... AC9: =+AC12/AC8 -> 70.751656
B10: Transaction Amount per User | C10: =+C12/C7 -> 818.72517 | D10: =+D12/D7 -> 873.63805 | E10: =+E12/E7 -> 905.84346 | F10: =+F12/F7 -> 962.04695 | G10: =+G12/G7 -> 945.80796 | H10: =+H12/H7 -> 971.59441 | I10: =+I12/I7 -> 978.33565 | J10: =+J12/J7 -> 1008.8387 | ... P10: =+P12/P7 -> 1108.082 | T10: =+T12/T7 -> 1808.6834 | U10: =+U12/U7 -> 1992.048 | V10: =+V12/V7 -> 2166.3633 | W10: =+W12/W7 -> 2334.1803 | X10: =+X12/X7 -> 2482.9231 | Y10: =+Y12/Y7 -> 2924.5986 | Z10: =+Z12/Z7 -> 3119.7977 | AA10: =+AA12/AA7 -> 3588.2136 | ... AC10: =+AC12/AC7 -> 4086.5125
B11: ATPU | C11: =+C8/C7 -> 13.475751 | D11: =+D8/D7 -> 14.092807 | E11: =+E8/E7 -> 14.661215 | F11: =+F8/F7 -> 15.957746 | G11: =+G8/G7 -> 15.234192 | H11: =+H8/H7 -> 15.337995 | I11: =+I8/I7 -> 15.349537 | J11: =+J8/J7 -> 15.251152 | ... P11: =+P8/P7 -> 15.375854 | T11: =+T8/T7 -> 31.633166 | U11: =+U8/U7 -> 33.925764 | V11: =+V8/V7 -> 36.970037 | W11: =+W8/W7 -> 40.527869 | X11: =+X8/X7 -> 40.909814 | Y11: =+Y8/Y7 -> 45.41784 | Z11: =+Z8/Z7 -> 51.377011 | AA11: =+AA8/AA7 -> 58.640845 | ... AC11: =+AC8/AC7 -> 57.758542
B12: Total Payment Volume | C12: 354508 | D12: 376538 | E12: 387701 | F12: 409832 | G12: 403860 | H12: 416814 | I12: 422641 | J12: 437836 | K12: 417208 | L12: 443547 | M12: 458088 | N12: 475135 | O12: 463955 | P12: 486448 | T12: 359928 | U12: 456179 | V12: 578419 | W12: 711925 | X12: 936062 | Y12: 1245879 | Z12: 1357112 | AA12: 1528579 | AB12: 1681150 | AC12: 1793979
B13: Fee in % | C13: =+C19/C12 -> 0.019858508 | D13: =+D19/D12 -> 0.019352628 | E13: =+E19/E12 -> 0.019133301 | F13: =+F19/F12 -> 0.019583634 | G13: =+G19/G12 -> 0.019063537 | H13: =+H19/H12 -> 0.018917311 | I13: =+I19/I12 -> 0.018566585 | J13: =+J19/J12 -> 0.019107611 | ... P13: =+P19/P12 -> 0.017847745 | T13: =+T19/T12 -> 0.030122691 | U13: =+U19/U12 -> 0.028703645 | V13: =+V19/V12 -> 0.02671247 | W13: =+W19/W12 -> 0.024963304 | X13: =+X19/X12 -> 0.022919422 | Y13: =+Y19/Y12 -> 0.020363936 | Z13: =+Z19/Z12 -> 0.020276882 | AA13: =+AA19/AA12 -> 0.019476259 | ... AC13: =+AC19/AC12 -> 0.01849074
B15: US Revenue | C15: 4147 | D15: 4210 | E15: 4257 | F15: 4639 | G15: 4467 | H15: 4550 | I15: 4518 | J15: 4732 | K15: 4463 | L15: 4709 | M15: 4753 | N15: 4943 | O15: 4882 | P15: 5048 | T15: 5760 | U15: 7084 | V15: 8324 | W15: 9417 | X15: 11013 | Y15: 13712 | Z15: 15087 | AA15: 17253 | AB15: 18267 | AC15: =+SUM(K15:N15) -> 18868
B16: International Revenue | C16: 2893 | D16: 3077 | E16: 3161 | F16: 3387 | G16: 3232 | H16: 3355 | I16: 3329 | J16: 3614 | K16: 3328 | L16: 3579 | M16: 3664 | N16: 3733 | O16: 3471 | P16: 3634 | T16: =1257+3825 -> 5082 | U16: =1402+4608 -> 6010 | V16: =1568+5469 -> 7037 | W16: =1872+6483 -> 8355 | X16: =2340+8101 -> 10441 | Y16: =2340+9319 -> 11659 | Z16: 11711 | AA16: 12518 | AB16: 13530 | AC16: =+SUM(K16:N16) -> 14304
B17: Transaction Revenue | C17: 6364 | D17: 7034 | E17: 6654 | F17: 7283 | G17: 7034 | H17: 7153 | I17: 7067 | J17: 7588 | K17: 7016 | L17: 7441 | M17: 7522 | N17: 7819 | O17: 7501 | P17: 7832 | T17: 9585 | U17: 11501 | V17: 13709 | W17: 16099 | X17: 19918 | Y17: 23402 | Z17: 25206 | AA17: 26857 | AB17: 28842 | AC17: =+SUM(K17:N17) -> 29798
B18: Other Services | C18: 676 | D18: 665 | E18: 764 | F18: 743 | G18: 665 | H18: 732 | I18: 780 | J18: 778 | K18: 775 | L18: 847 | M18: 895 | N18: 857 | O18: 852 | P18: 850 | T18: 1257 | U18: 1593 | V18: 1742 | W18: 1673 | X18: 1536 | Y18: 1969 | Z18: 2312 | AA18: 2914 | AB18: 2955 | AC18: =+SUM(K18:N18) -> 3374
B19: Revenue | C19: 7040 | D19: 7287 | E19: 7418 | F19: 8026 | G19: 7699 | H19: 7885 | I19: 7847 | J19: 8366 | K19: 7791 | L19: 8288 | M19: 8417 | N19: 8676 | O19: 8353 | P19: 8682 | T19: 10842 | U19: 13094 | V19: 15451 | W19: 17772 | X19: 21454 | Y19: 25371 | Z19: 27518 | AA19: 29771 | AB19: 31797 | AC19: 33172
B20: Transaction Expense | C20: 3283 | D20: 3541 | E20: 3603 | F20: 3958 | G20: 3917 | H20: 3942 | I20: 3841 | J20: 3997 | K20: 3704 | L20: 3968 | M20: 4063 | N20: 4252 | O20: 4165 | P20: 4385 | T20: =3346+724 -> 4070 | U20: =4419+805 -> 5224 | V20: =5581+776 -> 6357 | W20: 6790 | X20: 7934 | Y20: 10315 | Z20: 12173 | AA20: 14385 | AB20: 15697 | AC20: 15987
B21: Transaction & Credit losses | C21: 442 | D21: 398 | E21: 446 | F21: 396 | G21: 321 | H21: 335 | I21: 352 | J21: 434 | K21: 371 | L21: 476 | M21: 483 | N21: 390 | O21: 378 | P21: 397 | T21: 1088 | U21: 1011 | V21: 1274 | W21: 1380 | X21: 1741 | Y21: 1060 | Z21: 1572 | AA21: 1682 | AB21: 1442 | AC21: 1720
B22: Gross Profit | C22: =+C19-SUM(C20:C21) -> 3315 | D22: =+D19-SUM(D20:D21) -> 3348 | E22: =+E19-SUM(E20:E21) -> 3369 | F22: =+F19-SUM(F20:F21) -> 3672 | G22: =+G19-SUM(G20:G21) -> 3461 | H22: =+H19-SUM(H20:H21) -> 3608 | I22: =+I19-SUM(I20:I21) -> 3654 | J22: =+J19-SUM(J20:J21) -> 3935 | ... P22: =+P19-SUM(P20:P21) -> 3900 | T22: =+T19-SUM(T20:T21) -> 5684 | U22: =+U19-SUM(U20:U21) -> 6859 | V22: =+V19-SUM(V20:V21) -> 7820 | W22: =+W19-SUM(W20:W21) -> 9602 | X22: =+X19-SUM(X20:X21) -> 11779 | Y22: =+Y19-SUM(Y20:Y21) -> 13996 | Z22: =+Z19-SUM(Z20:Z21) -> 13773 | AA22: =+AA19-SUM(AA20:AA21) -> 13704 | ... AC22: =+AC19-SUM(AC20:AC21) -> 15465
B23: Customer Support | C23: 488 | D23: 492 | E23: 474 | F23: 465 | G23: 454 | H23: 436 | I23: 427 | J23: 451 | K23: 398 | L23: 413 | M23: 447 | N23: 446 | O23: 446 | P23: 462 | T23: 1267 | U23: 1364 | V23: 1482 | W23: 1615 | X23: 1778 | Y23: 2075 | Z23: 2120 | AA23: 1919 | AB23: 1768 | AC23: 1704
B24: S&M | C24: 436 | D24: 465 | E24: 442 | F24: 466 | G24: 421 | H24: 446 | I24: 508 | J24: 626 | K24: 488 | L24: 583 | M24: 521 | N24: 691 | O24: 518 | P24: 546 | T24: 969 | U24: 1128 | V24: 1313 | W24: 1401 | X24: 1861 | Y24: 2445 | Z24: 2257 | AA24: 1809 | AB24: 2001 | AC24: 2283
B25: Technology & Development | C25: 721 | D25: 743 | E25: 739 | F25: 770 | G25: 742 | H25: 718 | I25: 746 | J25: 773 | K25: 731 | L25: 767 | M25: 801 | N25: 804 | O25: 793 | P25: 849 | T25: 834 | U25: 953 | V25: 1071 | W25: 2085 | X25: 2642 | Y25: 3038 | Z25: 3253 | AA25: 2973 | AB25: 2979 | AC25: 3103
B26: G&A | C26: 507 | D26: 491 | E26: 507 | F26: 554 | G26: 464 | H26: 570 | I26: 519 | J26: 594 | K26: 503 | L26: 461 | M26: 513 | N26: 502 | O26: 491 | P26: 503 | T26: 1028 | U26: 1155 | V26: 1451 | W26: 1711 | X26: 2070 | Y26: 2114 | Z26: 2099 | AA26: 2059 | AB26: 2147 | AC26: 1979
B27: Restructuring | C27: 164 | D27: 24 | E27: 39 | F27: -311 | G27: 212 | H27: 113 | I27: 63 | J27: 50 | K27: 66 | L27: 116 | M27: 69 | N27: 80 | O27: 74 | P27: 113 | T27: 0 | U27: 132 | V27: 309 | W27: 71 | X27: 139 | Y27: 62 | Z27: 207 | AA27: -84 | AB27: 438 | AC27: 331
B28: Operating Income | C28: =+C22-SUM(C23:C27) -> 999 | D28: =+D22-SUM(D23:D27) -> 1133 | E28: =+E22-SUM(E23:E27) -> 1168 | F28: =+F22-SUM(F23:F27) -> 1728 | G28: =+G22-SUM(G23:G27) -> 1168 | H28: =+H22-SUM(H23:H27) -> 1325 | I28: =+I22-SUM(I23:I27) -> 1391 | J28: =+J22-SUM(J23:J27) -> 1441 | ... P28: =+P22-SUM(P23:P27) -> 1427 | T28: =+T22-SUM(T23:T27) -> 1586 | U28: =+U22-SUM(U23:U27) -> 2127 | V28: =+V22-SUM(V23:V27) -> 2194 | W28: =+W22-SUM(W23:W27) -> 2719 | X28: =+X22-SUM(X23:X27) -> 3289 | Y28: =+Y22-SUM(Y23:Y27) -> 4262 | Z28: =+Z22-SUM(Z23:Z27) -> 3837 | AA28: =+AA22-SUM(AA23:AA27) -> 5028 | ... AC28: =+AC22-SUM(AC23:AC27) -> 6065
B29: Other Income | C29: 75 | D29: 170 | E29: 73 | F29: 65 | G29: 41 | H29: 74 | I29: -80 | J29: -31 | K29: 73 | L29: 25 | M29: 13 | N29: 116 | O29: -95 | P29: -117 | T29: 45 | U29: 73 | V29: 182 | W29: 279 | X29: 1776 | Y29: -163 | Z29: -471 | AA29: 383 | AB29: 4 | AC29: 227
B30: Pretax Income | C30: =+C28+C29 -> 1074 | D30: =+D28+D29 -> 1303 | E30: =+E28+E29 -> 1241 | F30: =+F28+F29 -> 1793 | G30: =+G28+G29 -> 1209 | H30: =+H28+H29 -> 1399 | I30: =+I28+I29 -> 1311 | J30: =+J28+J29 -> 1410 | ... P30: =+P28+P29 -> 1310 | T30: =+T28+T29 -> 1631 | U30: =+U28+U29 -> 2200 | V30: =+V28+V29 -> 2376 | W30: =+W28+W29 -> 2998 | X30: =+X28+X29 -> 5065 | Y30: =+Y28+Y29 -> 4099 | Z30: =+Z28+Z29 -> 3366 | AA30: =+AA28+AA29 -> 5411 | ... AC30: =+AC28+AC29 -> 6292
B31: Tax Expense | C31: 279 | D31: 274 | E31: 221 | F31: 391 | G31: 321 | H31: 271 | I31: 301 | J31: 289 | K31: 316 | L31: 269 | M31: 285 | N31: 190 | O31: 280 | P31: 206 | T31: 230 | U31: 405 | V31: 319 | W31: 539 | X31: 863 | Y31: -70 | Z31: 947 | AA31: 1165 | AB31: 1182 | AC31: 1059
B32: Net Income | C32: =+C30-C31 -> 795 | D32: =+D30-D31 -> 1029 | E32: =+E30-E31 -> 1020 | F32: =+F30-F31 -> 1402 | G32: =+G30-G31 -> 888 | H32: =+H30-H31 -> 1128 | I32: =+I30-I31 -> 1010 | J32: =+J30-J31 -> 1121 | ... P32: =+P30-P31 -> 1104 | T32: =+T30-T31 -> 1401 | U32: =+U30-U31 -> 1795 | V32: =+V30-V31 -> 2057 | W32: =+W30-W31 -> 2459 | X32: =+X30-X31 -> 4202 | Y32: =+Y30-Y31 -> 4169 | Z32: =+Z30-Z31 -> 2419 | AA32: =+AA30-AA31 -> 4246 | ... AC32: =+AC30-AC31 -> 5233
B34: EPS | C34: =+C32/C35 -> 0.70416298 | D34: =+D32/D35 -> 0.92619262 | E34: =+E32/E35 -> 0.93235832 | F34: =+F32/F35 -> 1.3017642 | G34: =+G32/G35 -> 0.83458647 | H34: =+H32/H35 -> 1 | I34: =+I32/I35 -> 0.99507389 | J34: =+J32/J35 -> 1.1243731 | ... P34: =+P32/P35 -> 1.2446449 | T34: =+T32/T35 -> 1.1578512 | U34: =+U32/U35 -> 1.4921031 | V34: =+V32/V35 -> 1.7373311 | W34: =+W32/W35 -> 2.0945486 | X34: =+X32/X35 -> 3.5822677 | Y34: =+Y32/Y35 -> 3.5511073 | Z34: =+Z32/Z35 -> 2.0889465 | AA34: =+AA32/AA35 -> 3.8355917 | ... AC34: =+AC32/AC35 -> 5.4567258
B35: Shares | C35: 1129 | D35: 1111 | E35: 1094 | F35: 1077 | G35: 1064 | H35: 1128 | I35: 1015 | J35: 997 | K35: 986 | L35: 969 | M35: 950 | N35: 931 | O35: 913 | P35: 887 | T35: 1210 | U35: 1203 | V35: 1184 | W35: 1174 | X35: 1173 | Y35: 1174 | Z35: 1158 | AA35: 1107 | AB35: 1029 | AC35: 959
B37: User Growth | G37: =+G7/C7-1 -> -0.013856813 | H37: =+H7/D7-1 -> -0.0046403712 | I37: =+I7/E7-1 -> 0.0093457944 | J37: =+J7/F7-1 -> 0.018779343 | K37: =+K7/G7-1 -> 0.021077283 | L37: =+L7/H7-1 -> 0.020979021 | M37: =+M7/I7-1 -> 0.013888889 | N37: =+N7/J7-1 -> 0.011520737 | ... P37: =+P7/L7-1 -> 0.002283105 | U37: =+U7/T7-1 -> 0.15075377 | V37: =+V7/U7-1 -> 0.16593886 | W37: =+W7/V7-1 -> 0.1423221 | X37: =+X7/W7-1 -> 0.23606557 | Y37: =+Y7/X7-1 -> 0.12997347 | Z37: =+Z7/Y7-1 -> 0.021126761 | AA37: =+AA7/Z7-1 -> -0.020689655 | AB37: =+AB7/AA7-1 -> 0.018779343 | AC37: =+AC7/AB7-1 -> 0.011520737
B38: Transaction Growth | G38: =+G8/C8-1 -> 0.11482434 | H38: =+H8/D8-1 -> 0.083305894 | I38: =+I8/E8-1 -> 0.056733068 | J38: =+J8/F8-1 -> -0.026331274 | K38: =+K8/G8-1 -> -0.070714835 | L38: =+L8/H8-1 -> -0.053799392 | M38: =+M8/I8-1 -> -0.045242045 | N38: =+N8/J8-1 -> 0.02039583 | ... P38: =+P8/L8-1 -> 0.084163187 | U38: =+U8/T8-1 -> 0.23415409 | V38: =+V8/U8-1 -> 0.27056249 | W38: =+W8/V8-1 -> 0.25225408 | X38: =+X8/W8-1 -> 0.24771459 | Y38: =+Y8/X8-1 -> 0.25449005 | Z38: =+Z8/Y8-1 -> 0.15510647 | AA38: =+AA8/Z8-1 -> 0.11776813 | AB38: =+AB8/AA8-1 -> 0.054161162 | AC38: =+AC8/AB8-1 -> -0.0371383
B39: Payment Volume Growth | G39: =+G12/C12-1 -> 0.13921266 | H39: =+H12/D12-1 -> 0.10696397 | I39: =+I12/E12-1 -> 0.090120995 | J39: =+J12/F12-1 -> 0.068330438 | K39: =+K12/G12-1 -> 0.033051057 | L39: =+L12/H12-1 -> 0.064136521 | M39: =+M12/I12-1 -> 0.083870235 | N39: =+N12/J12-1 -> 0.085189432 | ... P39: =+P12/L12-1 -> 0.096722557 | U39: =+U12/T12-1 -> 0.26741737 | V39: =+V12/U12-1 -> 0.26796499 | W39: =+W12/V12-1 -> 0.23081192 | X39: =+X12/W12-1 -> 0.31483232 | Y39: =+Y12/X12-1 -> 0.33097914 | Z39: =+Z12/Y12-1 -> 0.089280741 | AA39: =+AA12/Z12-1 -> 0.12634698 | AB39: =+AB12/AA12-1 -> 0.099812309 | AC39: =+AC12/AB12-1 -> 0.067114178
B40: Transaction Rev Growth | G40: =+G17/C17-1 -> 0.1052797 | H40: =+H17/D17-1 -> 0.016917828 | I40: =+I17/E17-1 -> 0.062067929 | J40: =+J17/F17-1 -> 0.041878347 | K40: =+K17/G17-1 -> -0.0025589991 | L40: =+L17/H17-1 -> 0.040262827 | M40: =+M17/I17-1 -> 0.064383755 | N40: =+N17/J17-1 -> 0.030442804 | ... P40: =+P17/L17-1 -> 0.052546701 | U40: =+U17/T17-1 -> 0.19989567 | V40: =+V17/U17-1 -> 0.19198331 | W40: =+W17/V17-1 -> 0.17433803 | X40: =+X17/W17-1 -> 0.2372197 | Y40: =+Y17/X17-1 -> 0.17491716 | Z40: =+Z17/Y17-1 -> 0.077087428 | AA40: =+AA17/Z17-1 -> 0.065500278 | AB40: =+AB17/AA17-1 -> 0.073909968 | AC40: =+AC17/AB17-1 -> 0.033146106
B41: Other Services Growth | G41: =+G18/C18-1 -> -0.016272189 | H41: =+H18/D18-1 -> 0.10075188 | I41: =+I18/E18-1 -> 0.020942408 | J41: =+J18/F18-1 -> 0.047106326 | K41: =+K18/G18-1 -> 0.16541353 | L41: =+L18/H18-1 -> 0.15710383 | M41: =+M18/I18-1 -> 0.1474359 | N41: =+N18/J18-1 -> 0.10154242 | ... P41: =+P18/L18-1 -> 0.0035419126 | U41: =+U18/T18-1 -> 0.2673031 | V41: =+V18/U18-1 -> 0.093534212 | W41: =+W18/V18-1 -> -0.039609644 | X41: =+X18/W18-1 -> -0.081888822 | Y41: =+Y18/X18-1 -> 0.28190104 | Z41: =+Z18/Y18-1 -> 0.1742001 | AA41: =+AA18/Z18-1 -> 0.26038062 | AB41: =+AB18/AA18-1 -> 0.014070007 | AC41: =+AC18/AB18-1 -> 0.14179357
B42: Revenue Growth | G42: =+G19/C19-1 -> 0.093607955 | H42: =+H19/D19-1 -> 0.082063949 | I42: =+I19/E19-1 -> 0.0578323 | J42: =+J19/F19-1 -> 0.042362322 | K42: =+K19/G19-1 -> 0.011949604 | L42: =+L19/H19-1 -> 0.051109702 | M42: =+M19/I19-1 -> 0.072639225 | N42: =+N19/J19-1 -> 0.037054745 | ... P42: =+P19/L19-1 -> 0.04753861 | U42: =+U19/T19-1 -> 0.20771075 | V42: =+V19/U19-1 -> 0.18000611 | W42: =+W19/V19-1 -> 0.15021681 | X42: =+X19/W19-1 -> 0.20717983 | Y42: =+Y19/X19-1 -> 0.18257668 | Z42: =+Z19/Y19-1 -> 0.084624177 | AA42: =+AA19/Z19-1 -> 0.081873683 | AB42: =+AB19/AA19-1 -> 0.068052803 | AC42: =+AC19/AB19-1 -> 0.043243073
B43: Gross Margin | C43: =+C22/C19 -> 0.47088068 | D43: =+D22/D19 -> 0.45944833 | E43: =+E22/E19 -> 0.45416554 | F43: =+F22/F19 -> 0.45751308 | G43: =+G22/G19 -> 0.4495389 | H43: =+H22/H19 -> 0.45757768 | I43: =+I22/I19 -> 0.46565566 | J43: =+J22/J19 -> 0.4703562 | ... P43: =+P22/P19 -> 0.44920525 | T43: =+T22/T19 -> 0.52425752 | U43: =+U22/U19 -> 0.52382771 | V43: =+V22/V19 -> 0.50611611 | W43: =+W22/W19 -> 0.54028809 | X43: =+X22/X19 -> 0.54903514 | Y43: =+Y22/Y19 -> 0.55165346 | Z43: =+Z22/Z19 -> 0.50050876 | AA43: =+AA22/AA19 -> 0.46031373 | ... AC43: =+AC22/AC19 -> 0.46620644
B44: Operating Margin | C44: =+C28/C19 -> 0.14190341 | D44: =+D28/D19 -> 0.15548237 | E44: =+E28/E19 -> 0.15745484 | F44: =+F28/F19 -> 0.21530027 | G44: =+G28/G19 -> 0.15170801 | H44: =+H28/H19 -> 0.16804058 | I44: =+I28/I19 -> 0.1772652 | J44: =+J28/J19 -> 0.1722448 | ... P44: =+P28/P19 -> 0.16436305 | T44: =+T28/T19 -> 0.14628297 | U44: =+U28/U19 -> 0.16244081 | V44: =+V28/V19 -> 0.14199728 | W44: =+W28/W19 -> 0.15299347 | X44: =+X28/X19 -> 0.15330475 | Y44: =+Y28/Y19 -> 0.16798707 | Z44: =+Z28/Z19 -> 0.13943601 | AA44: =+AA28/AA19 -> 0.16888919 | ... AC44: =+AC28/AC19 -> 0.18283492
...

Sheet KPIs
A1: Main
B2: Ratios | C2: 18 | D2: =+C2+1 -> 19 | E2: =+D2+1 -> 20 | F2: =+E2+1 -> 21 | G2: =+F2+1 -> 22 | H2: =+G2+1 -> 23 | I2: =+H2+1 -> 24 | J2: =+I2+1 -> 25
B3: Price
B4: Shares o/s
B5: Market Cap
B6: Net Debt
B7: EV
A9: x | B9: Value Driver
B10: Capital Emloyed | L10: =Long Term Assets + Working Capital (Exclusive of cash)-Accounts Payables
B11: Invested Capital | L11: =Net Working Capital + PP&E + Other Net Operating Assets (net of Liabilties) + (Intangibles)
B12: Invested Capital (exl. Intangibles)
B13: Total Funds Invested | L13: Invested Capital + Non-Operating Assets
B14: NOPAT | L14: EBITA * (1-Marginal Tax Rate)
B15: Net Investment | L15: =Invested Capital (t+1)-Invested Capital (t)
B16: FCF | L16: =NOPAT + non-cash Expenses - Investments in Invested Capital
B17: Investment Rate | L17: =Net Investment/NOPAT
B18: Economic Profit | L18: =Invested Capital *(ROIC-WACC)
A20: x | B20: Efficency-Ratios
B21: Capital Turnover | L21: =Revenue/Equity
B22: Return on Equity (ROE) | L22: =Net Income/Book Value of Equity
B23: Return on Capital Employed (ROCE) | L23: =EBIT/Capital Employed
B24: Return on Capital Invested (ROIC) | L24: =NOPAT/Invested Capital
B25: ROIC without Intangibles | L25: =NOPAT/(Invested Capital exclusive of Intangibles)
B26: Decomposed ROIC | L26: = ROIC = (1-operating cash tax)* (EBITA/Revenues) * (Revenue/Invested Capital)
B28: Retention Rate | L28: =1 - Dividends/Net Income
B29: Reinvestment Rate | L29: =Net CapEx + Change in WC / EBIT * (1-t)
B30: Epected Growth in Net Income | L30: =ROE * Retention Rate
B31: Expected Growth in NOPAT | L31: =ROIC * Reinvestment Rate
A33: x | B33: Finacial Stability Ratios
B34: Equity/Debt Ratio | L34: =Book Value of Equtiy/Book Value of Debt
B35: Gearing | L35: =(Debt - Cash (Net Debt))/Book Value of Equity
B36: Interest Coverage Ratio | L36: =EBIT/Interest Expenses
B37: Net Debt / EBITDA | L37: =Net Debt/EBITDA
B38: Cash Burn Rate | L38: =Book Value of Equity/Absolute value of Loss
A40: x | B40: WC-Managment Ratios
B41: Debitor-Duration | L41: =Accounts Receivables/Revenue*360
B42: Creditor-Duration | L42: =Accounts Payable/Revenue*360
B43: Inventory Intensity | L43: =Inventory/Balance Sheet Total
B44: Invetory Turnover | L44: =Cogs/Inventory
B45: Storage-Duration | L45: =360/Inventory Turnover
...

Sheet CoC
A1: Main
B3: Cost of Capital
A4: x | B4: Cost of Equity (CAPM)
B5: Riskfree Rate
B6: Expected Inflation | H6: =(1+Nominal Rate)/(1+Real Rate)-1
B7: Average Real Interest Rate | H7: = Average Interest Rate of the Past
B8: Riskfree Rate | F8: =F6+F7 -> 0 | H8: =Goverment Bond or Expected Inflation + Average Real Interest Rate
A10: x | B10: Adjustments for Industry/Company Risk
B11: Raw Beta | H11: =Raw beta slope of regression line aginst total market -> Ri= alpha + beta*Rm + standard error
B12: Debt to Value Ratio | H12: Value of Debt/Enterpries Value
B13: Unlevered Beta | H13: = Raw Beta* Debt-to-Equity Ratio (Book Value)
B14: Unlevered Industry Beta | H14: =Median of Peer Group
B15: Levered Industry Beta | H15: =Unlevered Industry Beta * Market Value of Debt to Market Value of Equity
A17: x | B17: Expected Equity Risk Premium
B18: Estimated Future Market Return | H18: = 1/P/E * (1.g/ROE) + g , g = real growth in GDP, P/E => P/E ratio for S&P500 or MSCI World Index, ROE = Average ROE in S&P500 or MSCI World
B19: Riskfree Rate
B20: Expected Equity Risk Premium | F20: =F18-F19 -> 0
A22: x | B22: Cost of Equity (CAPM) | F22: =F8+F15*F20 -> 0 | H22: => ER(i)=rf+beta(i)*(Er(m)-rf)
A25: x | B25: Cost of Debt
B26: Yield to Maturity on Trading Bonds | H26: => Price = Coupon/(1+YTM)+Coupon(1+YTM)^2 + … + (Face Value + Coupon)/(1+YTM)^n => solve for YTM
B27: or
B28: Riskfree Rate
B29: Credit Default Spread
B30: Country Rsik Premium
A32: x | B32: Cost of Debt | F32: =F28+F29+F30 -> 0
A34: x | B34: Capital Structure
B35: Market Value of Debt
B36: Market Value of Equity
B37: Total Enterprise Value | F37: =F35+F36 -> 0
B39: Marginal Tax Rate
A41: x | B41: WACC | F41: =(F32*(F35/F37)*(1-F39))+((F36/F38)*F22) -> #DIV/0! | H41: => WACC = (D/D+E)*kd * (1-t) + (E/D+E) * ke
I47: =SLOPE(H48:H52,K48:K52) -> #DIV/0!
H48: Change

Sheet DCF
A1: Main | B1: PayPal DCF
B3: Ticker | E3: PYPL | G3: Share Price | J3: =+Main!I2 -> 58.7 | L3: Share Price | O3: =+J3 -> 58.7
B4: Date | E4: =+TODAY() -> 46231 | G4: Fair Share Price | J4: =V62 -> 90.720142 | L4: Scneario DCF Price | O4: =+J15+O15+T15 -> 0
B5: End of FY | E5: 46022 | G5: Implied Upside | J5: =J4/J3-1 -> 0.54548793 | L5: Implied Upside | O5: =O4/O3-1 -> -1
A7: x | B7: Assumptions
B9: Switches | G9: Conservative Case | L9: Base Case | Q9: Optimistic Case
B10: Assuptions | G10: Assuptions | I10: Year | J10: Metic | L10: Assuptions | N10: Year | O10: Metic | Q10: Assuptions | S10: Year | T10: Metic
B11: Revenue | E11: 2 | G11: Revenue | L11: Revenue | Q11: Revenue
B12: EBIT | E12: 2 | G12: EBIT | L12: EBIT | Q12: EBIT
B13: WACC | E13: 2 | G13: Implied Share Price
B14: TGR | E14: 2 | G14: Probability | L14: Probability | Q14: Probability
B15: ROIC | E15: 2 | G15: Implied Share Price * p | L15: Implied Share Price * p | Q15: Implied Share Price * p
B17: Valuation
B18: WACC | E18: =CHOOSE(E13,J18,O18,T18) -> 0.09 | G18: WACC | J18: 0.11 | L18: WACC | O18: 0.09 | Q18: WACC | T18: 0.07
B19: TGR | E19: =CHOOSE(E14,J19,O19,T19) -> 0.025 | G19: TGR | J19: 0.015 | L19: TGR | O19: 0.025 | Q19: TGR | T19: 0.035
B20: RONIC | E20: =CHOOSE(E15,J20,O20,T20) -> 0.1 | G20: RONIC | J20: 0.09 | L20: RONIC | O20: 0.1 | Q20: RONIC | T20: 0.11
A24: x | B24: Model | G24: 19 | H24: =G24+1 -> 20 | I24: =H24+1 -> 21 | J24: =I24+1 -> 22 | K24: =J24+1 -> 23 | L24: =K24+1 -> 24 | M24: =L24+1 -> 25 | N24: =M24+1 -> 26 | O24: =N24+1 -> 27 | ... V24: =U24+1 -> 34
B25: Revenue | G25: =+Model!W19 -> 17772 | H25: =+Model!X19 -> 21454 | I25: =+Model!Y19 -> 25371 | J25: =+Model!Z19 -> 27518 | K25: =+Model!AA19 -> 29771 | L25: =+Model!AB19 -> 31797 | M25: =L25*(1+M26) -> 34022.79 | N25: =M25*(1+N26) -> 36285.306 | O25: =N25*(1+O26) -> 38577.63 | P25: =O25*(1+P26) -> 40892.914 | Q25: =P25*(1+Q26) -> 43224.442 | R25: =Q25*(1+R26) -> 45565.679 | S25: =R25*(1+S26) -> 47910.327 | T25: =S25*(1+T26) -> 50252.356 | ... V25: =U25*(1+V26) -> 54906.01
B26: Growth (%) | H26: =H25/G25-1 -> 0.20717983 | I26: =I25/H25-1 -> 0.18257668 | J26: =J25/I25-1 -> 0.084624177 | K26: =K25/J25-1 -> 0.081873683 | L26: =L25/K25-1 -> 0.068052803 | M26: {=OFFSET(M26,$E$11,,)} -> 0.07 | N26: {=OFFSET(N26,$E$11,,)} -> 0.0665 | O26: {=OFFSET(O26,$E$11,,)} -> 0.063175 | P26: {=OFFSET(P26,$E$11,,)} -> 0.06001625 | Q26: {=OFFSET(Q26,$E$11,,)} -> 0.057015437 | R26: {=OFFSET(R26,$E$11,,)} -> 0.054164666 | S26: {=OFFSET(S26,$E$11,,)} -> 0.051456432 | T26: {=OFFSET(T26,$E$11,,)} -> 0.048883611 | ... V26: {=OFFSET(V26,$E$11,,)} -> 0.044117459
B27: Conservative Case | M27: =+M28-2% -> 0.05 | N27: =+N28-2% -> 0.0465 | O27: =+O28-2% -> 0.043175 | P27: =+P28-2% -> 0.04001625 | Q27: =+Q28-2% -> 0.037015437 | R27: =+R28-2% -> 0.034164666 | S27: =+S28-2% -> 0.031456432 | T27: =+T28-2% -> 0.028883611 | ... V27: =+V28-2% -> 0.024117459
B28: Base Case | M28: 0.07 | N28: =+M28*(1-5%) -> 0.0665 | O28: =+N28*(1-5%) -> 0.063175 | P28: =+O28*(1-5%) -> 0.06001625 | Q28: =+P28*(1-5%) -> 0.057015437 | R28: =+Q28*(1-5%) -> 0.054164666 | S28: =+R28*(1-5%) -> 0.051456432 | T28: =+S28*(1-5%) -> 0.048883611 | U28: =+T28*(1-5%) -> 0.04643943 | V28: =+U28*(1-5%) -> 0.044117459
B29: Optimisitic Case | M29: =+M28+2% -> 0.09 | N29: =+N28+2% -> 0.0865 | O29: =+O28+2% -> 0.083175 | P29: =+P28+2% -> 0.08001625 | Q29: =+Q28+2% -> 0.077015437 | R29: =+R28+2% -> 0.074164666 | S29: =+S28+2% -> 0.071456432 | T29: =+T28+2% -> 0.068883611 | ... V29: =+V28+2% -> 0.064117459
B31: EBIT | G31: =+Model!W28 -> 2719 | H31: =+Model!X28 -> 3289 | I31: =+Model!Y28 -> 4262 | J31: =+Model!Z28 -> 3837 | K31: =+Model!AA28 -> 5028 | L31: =+Model!AB28 -> 5325 | M31: =M32*M25 -> 5783.8743 | N31: =N32*N25 -> 6476.927 | O31: =O32*O25 -> 7230.4122 | P31: =P32*P25 -> 8047.5722 | Q31: =Q32*Q25 -> 8644.8884 | R31: =R32*R25 -> 9113.1358 | S31: =S32*S25 -> 9582.0653 | T31: =T32*T25 -> 10050.471 | ... V31: =V32*V25 -> 10981.202
B32: % of Sales | G32: =G31/G25 -> 0.15299347 | H32: =H31/H25 -> 0.15330475 | I32: =I31/I25 -> 0.16798707 | J32: =J31/J25 -> 0.13943601 | K32: =K31/K25 -> 0.16888919 | L32: =L31/L25 -> 0.16746863 | M32: {=OFFSET(M32,$E$12,,)} -> 0.17 | N32: {=OFFSET(N32,$E$12,,)} -> 0.1785 | O32: {=OFFSET(O32,$E$12,,)} -> 0.187425 | P32: {=OFFSET(P32,$E$12,,)} -> 0.19679625 | Q32: {=OFFSET(Q32,$E$12,,)} -> 0.2 | R32: {=OFFSET(R32,$E$12,,)} -> 0.2 | S32: {=OFFSET(S32,$E$12,,)} -> 0.2 | T32: {=OFFSET(T32,$E$12,,)} -> 0.2 | ... V32: {=OFFSET(V32,$E$12,,)} -> 0.2
B33: Conservative Case | M33: =+M34-2% -> 0.15 | N33: =+N34-2% -> 0.1585 | O33: =+O34-2% -> 0.167425 | P33: =+P34-2% -> 0.17679625 | Q33: =+Q34-2% -> 0.18 | R33: =+R34-2% -> 0.18 | S33: =+S34-2% -> 0.18 | T33: =+T34-2% -> 0.18 | ... V33: =+V34-2% -> 0.18
B34: Base Case | M34: 0.17 | N34: =+M34*(1+5%) -> 0.1785 | O34: =+N34*(1+5%) -> 0.187425 | P34: =+O34*(1+5%) -> 0.19679625 | Q34: 0.2 | R34: 0.2 | S34: 0.2 | T34: 0.2 | U34: 0.2 | V34: 0.2
B35: Optimisitic Case | M35: =+M34+2% -> 0.19 | N35: =+N34+2% -> 0.1985 | O35: =+O34+2% -> 0.207425 | P35: =+P34+2% -> 0.21679625 | Q35: =+Q34+2% -> 0.22 | R35: =+R34+2% -> 0.22 | S35: =+S34+2% -> 0.22 | T35: =+T34+2% -> 0.22 | ... V35: =+V34+2% -> 0.22
B37: Taxes | G37: =+Model!W31 -> 539 | H37: =+Model!X31 -> 863 | I37: =+Model!Y31 -> -70 | J37: =+Model!Z31 -> 947 | K37: =+Model!AA31 -> 1165 | L37: =+Model!AB31 -> 1182 | M37: =M38*M31 -> 1272.4523 | N37: =N38*N31 -> 1424.9239 | O37: =O38*O31 -> 1590.6907 | P37: =P38*P31 -> 1770.4659 | Q37: =Q38*Q31 -> 1901.8754 | R37: =R38*R31 -> 2004.8899 | S37: =S38*S31 -> 2108.0544 | T37: =T38*T31 -> 2211.1037 | ... V37: =V38*V31 -> 2415.8644
B38: Tax Rate (%) | G38: =G37/G31 -> 0.19823465 | H38: =H37/H31 -> 0.26238978 | I38: =I37/I31 -> -0.016424214 | J38: =J37/J31 -> 0.2468074 | K38: =K37/K31 -> 0.23170247 | L38: =L37/L31 -> 0.22197183 | M38: 0.22 | N38: 0.22 | O38: 0.22 | P38: 0.22 | Q38: 0.22 | R38: 0.22 | S38: 0.22 | T38: 0.22 | U38: 0.22 | V38: 0.22
B40: Nopat | G40: =G31-G37 -> 2180 | H40: =H31-H37 -> 2426 | I40: =I31-I37 -> 4332 | J40: =J31-J37 -> 2890 | K40: =K31-K37 -> 3863 | L40: =L31-L37 -> 4143 | M40: =M31-M37 -> 4511.422 | N40: =N31-N37 -> 5052.0031 | ... V40: =V31-V37 -> 8565.3375
B42: D&A and other non-cash Expenses | G42: =+Model!W76 -> 912 | H42: =+Model!X76 -> 1189 | I42: =+Model!Y76 -> 1265 | J42: =+Model!Z76 -> 1317 | K42: =+Model!AA76 -> 1072 | L42: =+Model!AB76 -> 1032 | M42: =M43*M25 -> 1360.9116 | N42: =N43*N25 -> 1451.4122 | O42: =O43*O25 -> 1543.1052 | P42: =P43*P25 -> 1635.7166 | Q42: =Q43*Q25 -> 1728.9777 | R42: =R43*R25 -> 1822.6272 | S42: =S43*S25 -> 1916.4131 | T42: =T43*T25 -> 2010.0943 | ... V42: =V43*V25 -> 2196.2404
B43: % of Sales | G43: =G42/G25 -> 0.051316678 | H43: =H42/H25 -> 0.055420901 | I43: =I42/I25 -> 0.049860076 | J43: =J42/J25 -> 0.047859583 | K43: =K42/K25 -> 0.036008196 | L43: =L42/L25 -> 0.032455892 | M43: 0.04 | N43: 0.04 | O43: 0.04 | P43: 0.04 | Q43: 0.04 | R43: 0.04 | S43: 0.04 | T43: 0.04 | U43: 0.04 | V43: 0.04
B45: CapEx | G45: =+Model!W92 -> -704 | H45: =+Model!X92 -> -866 | I45: =+Model!Y92 -> -908 | J45: =+Model!Z92 -> -706 | K45: =+Model!AA92 -> -623 | L45: =+Model!AB92 -> -683 | M45: =M46*M25 -> -1020.6837 | N45: =N46*N25 -> -1088.5592 | O45: =O46*O25 -> -1157.3289 | P45: =P46*P25 -> -1226.7874 | Q45: =Q46*Q25 -> -1296.7333 | R45: =R46*R25 -> -1366.9704 | S45: =S46*S25 -> -1437.3098 | T45: =T46*T25 -> -1507.5707 | ... V45: =V46*V25 -> -1647.1803
B46: % of Sales | G46: =G45/G25 -> -0.039612874 | H46: =H45/H25 -> -0.040365433 | I46: =I45/I25 -> -0.035788893 | J46: =J45/J25 -> -0.025655934 | K46: =K45/K25 -> -0.020926405 | L46: =L45/L25 -> -0.021480014 | M46: -0.03 | N46: -0.03 | O46: -0.03 | P46: -0.03 | Q46: -0.03 | R46: -0.03 | S46: -0.03 | T46: -0.03 | U46: -0.03 | V46: -0.03
B48: Change in WC | G48: =+Model!W90 -> -1075 | H48: =+Model!X90 -> -952 | I48: =+Model!Y90 -> -1102 | J48: =+Model!Z90 -> -454 | K48: =+Model!AA90 -> -1314 | L48: =+Model!AB90 -> -558 | M48: =M49*M25 -> -680.4558 | N48: =N49*N25 -> -725.70611 | O48: =O49*O25 -> -771.55259 | P48: =P49*P25 -> -817.85829 | Q48: =Q49*Q25 -> -864.48884 | R48: =R49*R25 -> -911.31358 | S48: =S49*S25 -> -958.20653 | T48: =T49*T25 -> -1005.0471 | ... V48: =V49*V25 -> -1098.1202
B49: % of Sales | G49: =G48/G25 -> -0.060488409 | H49: =H48/H25 -> -0.04437401 | I49: =I48/I25 -> -0.043435418 | J49: =J48/J25 -> -0.016498292 | K49: =K48/K25 -> -0.044136912 | L49: =L48/L25 -> -0.017548825 | M49: -0.02 | N49: -0.02 | O49: -0.02 | P49: -0.02 | Q49: -0.02 | R49: -0.02 | S49: -0.02 | T49: -0.02 | U49: -0.02 | V49: -0.02
B51: Unlevered Free Cashflow | G51: =G40+G42+G45+G48 -> 1313 | H51: =H40+H42+H45+H48 -> 1797 | I51: =I40+I42+I45+I48 -> 3587 | J51: =J40+J42+J45+J48 -> 3047 | K51: =K40+K42+K45+K48 -> 2998 | L51: =L40+L42+L45+L48 -> 3934 | M51: =M40+M42+M45+M48 -> 4171.1941 | N51: =N40+N42+N45+N48 -> 4689.15 | ... V51: =V40+V42+V45+V48 -> 8016.2774
B52: Present Value of unlevered FC | M52: =(M51/(1+$E$18)^M53)*M53 -> 2292.9629 | N52: =N51/(1+$E$18)^N53 -> 4093.0159 | O52: =O51/(1+$E$18)^O53 -> 4207.3472 | P52: =P51/(1+$E$18)^P53 -> 4311.2134 | Q52: =Q51/(1+$E$18)^Q53 -> 4253.5551 | R52: =R51/(1+$E$18)^R53 -> 4113.7133 | S52: =S51/(1+$E$18)^S53 -> 3968.2479 | T52: =T51/(1+$E$18)^T53 -> 3818.5598 | U52: =U51/(1+$E$18)^U53 -> 3665.9556 | V52: =V51/(1+$E$18)^V53 -> 3511.6406
B53: Discount Period | M53: =YEARFRAC(E4,E5) -> 0.57777778 | N53: =M53+1 -> 1.5777778 | O53: =N53+1 -> 2.5777778 | P53: =O53+1 -> 3.5777778 | Q53: =P53+1 -> 4.5777778 | R53: =Q53+1 -> 5.5777778 | S53: =R53+1 -> 6.5777778 | T53: =S53+1 -> 7.5777778 | U53: =T53+1 -> 8.5777778 | V53: =U53+1 -> 9.5777778
B54: Sum of Present Value | V54: =SUM(M52:V52) -> 38236.212
...
