Workbook

Sheet Main
A1: Ralph Lauren
A2: numbers in mio USD | G2: Price | H2: 389.9
G3: Shares | H3: =37.700963+21.881276 -> 59.582239 | I3: Q127
B4: IR | G4: MC | H4: =H3*H2 -> 23231.115
B5: SEC | G5: Cash | H5: =1719+222.6 -> 1941.6 | I5: Q127
B6: FY | C6: April 1 to March 30 | G6: Debt | H6: 1308.1 | I6: Q127
G7: EV | H7: =H4+H5-H6 -> 23864.615
J9: Management
J10: Ralph Lauren | K10: 84, Founder, Executive Chairman and Chief Creative Officer
J11: Patrice Louvet | K11: 59, CEO and President since 2017, before he was at Procter&Gamble
A12: x | B12: Notes | J12: Jane Hamilton Nielsen | K12: 60, Chief Financial Officer since 2016 and Chief Operating Officer sine 2019, before she was at Coach Inc, and Pepsi
B13: Credit Score | C13: A3 | J13: David Lauren | K13: 52, Chief Branding and Innovation Officer since 2022, was a strategic advisor and vice chairman before
J14: Halide Alagöz | K14: 52, Chief Product Officer since 2021, she was at H&M corp before
A15: x | B15: Businessmodel
B16: Founded 1967 by Ralph Lauren RL Corp is a global leader in marketing, desing and distribution of luxury lifestyle products like appereal, footwear & accessoires, home, hospitalitiy and fragrances
A18: x | B18: Brands and Products
B19: Appereal: | C19: collection of men, women and children clothing which are sold under brand names like Ralph Lauren Collection, Ralph Lauren Purple Labe (luxury line), Double Rl,
C20: Polo Ralph Lauren, Lauren Ralph Lauren, Polo Golf Ralph Lauren, Ralph Lauren Golf, RLX Ralph Lauren, Ralph Lauren Children, Chaps and other
B22: Footwear & Accessoires: | C22: include products for men, women, children: casual shoes, boat shoes, dress shoes, sneakers, sandals, eyewaer, watches, fashion jewelry, scarves, hats, gloves umbrellas and leather goods
C23: Sold under: Ralph Lauren Collection, RL Purple Label, Double RL, Polo RL, Lauren RL, Polo RL Children, Chaps
B25: Fragrances: | C25: Fragrances for men, women: women fragrances -> RL Collection, Woman by RL, Romance Collection, Ralph Collection, Polo Eath for man and woman (sustainable)
C26: Man fragrances: Ralphs Club, Purple Label, Polo Blue, Polo Red, Polo Green, Polo Black, Polo 67, Polo Safari, Polo Sport, Big Pony Men
B28: Home: | C28: Sold under Ralph Lauren, Polo, Lauren by RL and Chaps -> include furniture, bed and bath, lighting, floor decoration etc
B30: Hospitality | C30: "Culinar Art": Several Bars and Resuranst across the globe like The Polo Bar in NY, RL Resturant in Chicago, The Bar at Ralph Lauren Milan, Ralphs Bar in Chengdu China etc.
A32: x | B32: Distribution
B34: Noth America | C34: 44% of sales, retail and wholesale business in the US and Canada, Retail: RL Stores, Outlet Stores, Concession based stores in store, ecommerce sites
C35: Wholesale is focused on sales on department stores, third party digital and licensee partners
B37: Europe | C37: 30% of sales, Retail in Europe: RL Stores, Outlet Stores, Concession based stores in store, ecommerce sites
C38: Wholesale is focused on sales on department stores, third party digital and licensee partners vaires from country to country
B40: Asia | C40: 24% of sales, retail and wholesale in Asia, Australia, New Zeeland, Retail; RL Stores, Outlet Stores, Concession based stores in store, ecommerce sites and third party ecommerce sites
C41: Wholesale is focused on sales on department stores, third party digital and licensee partners
B43: Non operating segments | C43: 2% of sales -> lincenses
B45: Retail | C45: D2C through 564 retail stores and 699 stores in store (total of 4,2 million and 0,7 million square feet), e commerce sites and thrid party digital partners
B47: RL Stores | C47: 50 in America, 44 in Europe, 138 in Asia -> Total 232 , opened 34 in FY24, closed 11 in FY24
B50: Outlet Stores | C50: 180 in America, 59 in Europe, 93 in Asia, Total 332, opened 5 in FY24 and losed 17 in FY24
B52: Shop within Shop | C52: 1 in America, 27 in Europe, 671 in Asia, Total 699,
B54: Ecommerce | C54: https://www.ralphlauren.de
B56: Whole Sale
A61: x

Sheet Model
A1: Main
C2: Q124 | D2: Q224 | E2: Q324 | F2: Q424 | G2: Q125 | H2: Q225 | I2: Q325 | J2: Q425 | K2: Q126 | L2: Q226 | M2: Q326 | N2: Q426 | O2: Q127 | P2: Q227 | Q2: Q327 | R2: Q427 | T2: FY19 | U2: FY20 | V2: FY21 | W2: FY22 | X2: FY23 | Y2: FY24 | Z2: FY25 | AA2: FY26
B3: North America Stores | G3: 228 | H3: 228 | K3: 225 | L3: 225 | M3: 225 | N3: =53+166 -> 219 | O3: 220 | Y3: 239 | Z3: 223 | AA3: =53+166 -> 219
B4: Europe Stores | G4: 103 | H4: 104 | K4: 106 | L4: 108 | M4: 112 | N4: =57+54 -> 111 | O4: 111 | Y4: 103 | Z4: 104 | AA4: =57+54 -> 111
B5: Asia Stores | G5: 234 | H5: 238 | K5: 238 | L5: 249 | M5: 263 | N5: =87+177 -> 264 | O5: 269 | Y5: 231 | Z5: 237 | AA5: =87+177 -> 264
B6: RL Stores | G6: =+SUM(G3:G5) -> 565 | H6: =+SUM(H3:H5) -> 570 | K6: =+SUM(K3:K5) -> 569 | L6: =+SUM(L3:L5) -> 582 | M6: =+SUM(M3:M5) -> 600 | N6: 287 | O6: =+SUM(O3:O5) -> 600 | Y6: 232 | Z6: 252 | AA6: 287
B7: Outlets | G7: 697 | H7: 0 | K7: 0 | L7: 0 | M7: 0 | N7: 307 | O7: 0 | Y7: 332 | Z7: 312 | AA7: 307
B8: Total Stores | C8: =+C6+C7 -> 0 | D8: =+D6+D7 -> 0 | E8: =+E6+E7 -> 0 | F8: =+F6+F7 -> 0 | G8: =+G6+G7 -> 1262 | H8: =+H6+H7 -> 570 | I8: =+I6+I7 -> 0 | J8: =+J6+J7 -> 0 | ... O8: =+O6+O7 -> 600 | X8: =+X6+X7 -> 0 | Y8: =+Y6+Y7 -> 564 | Z8: =+Z6+Z7 -> 564 | AA8: =+AA6+AA7 -> 594
B9: Concessions | H9: 682 | K9: 665 | L9: 667 | M9: 663 | N9: 644 | O9: 623 | Y9: 699 | Z9: 671 | AA9: 644
B10: Licensed Partner Stores | H10: =+H8+H9 -> 1252 | K10: =+K8+K9 -> 1234 | L10: =+L8+L9 -> 1249 | M10: =+M8+M9 -> 1263 | N10: n.a. | O10: n.a. | Y10: 100 | Z10: 116 | AA10: n.a.
B12: North America Revenue | E12: 933.3 | F12: 667.7 | G12: 608.2 | H12: 739.5 | I12: 997.7 | J12: 704.7 | K12: 656.2 | L12: 832.4 | M12: 1078.3 | N12: =+AA12-SUM(K12:M12) -> 762.7 | O12: 740.3 | Y12: 2905.5 | Z12: 3050.1 | AA12: 3329.6
B13: Europe Revenue | E13: 521.5 | F13: 469.2 | G13: 479.1 | H13: 565.9 | I13: 604.4 | J13: 525.5 | K13: 554.5 | L13: 688.3 | M13: 676.5 | N13: =+AA13-SUM(K13:M13) -> 619.6 | O13: 594.4 | Y13: 1968 | Z13: 2174.9 | AA13: 2538.9
B14: Asia Revenue | E14: 446.4 | F14: 394.3 | G14: 390.9 | H14: 380.2 | I14: 506.7 | J14: 431.6 | K14: 474 | L14: 445.6 | M14: 620.3 | N14: =+AA14-SUM(K14:M14) -> 563.6 | O14: 589.3 | Y14: 1566.6 | Z14: 1709.4 | AA14: 2103.5
B15: Other Revenue | E15: 32.8 | F15: 36.7 | G15: 34 | H15: 40.4 | I15: 34.7 | J15: 35.5 | K15: 34.4 | L15: 44.4 | M15: 30.9 | N15: =+AA15-SUM(K15:M15) -> 32.8 | O15: 35.8 | Y15: 146.3 | Z15: 144.6 | AA15: 142.5
B16: Retail | E16: 1415.8 | F16: 951.1 | G16: 1032.6 | H16: 1096.4 | I16: 1581.8 | J16: 1509.3 | K16: 1201.2 | L16: 1264.5 | M16: 1581.8 | N16: =+AA16-SUM(K16:M16) -> 1485.1 | O16: 1201.2 | T16: 3747.8 | U16: 3740.9 | V16: 2779.8 | W16: 3941.5 | X16: 4053.1 | Y16: 4351 | Z16: 4770.1 | AA16: 5532.6
B17: Wholesale | E17: 485.4 | F17: 580.1 | G17: 445.6 | H17: 589.2 | I17: 527 | J17: 602.5 | K17: 483.5 | L17: 701.8 | M17: 527 | N17: =+AA17-SUM(K17:M17) -> 727.1 | O17: 483.5 | T17: 2392.5 | U17: 2250.8 | V17: 1498.6 | W17: 2127.3 | X17: 2233.3 | Y17: 2134.1 | Z17: 2164.3 | AA17: 2439.4
B18: Licensing | E18: 32.8 | F18: 36.7 | G18: 34 | H18: 40.4 | I18: 34.7 | J18: 35.5 | K18: 34.4 | L18: 44.4 | M18: 34.7 | N18: =+AA18-SUM(K18:M18) -> 29 | O18: 34.4 | T18: 172.7 | U18: 168.1 | V18: 122.4 | W18: 149.7 | X18: 157.2 | Y18: 146.3 | Z18: 144.6 | AA18: 142.5
B19: Revenue | E19: 1934 | F19: 1567.9 | G19: 1512.2 | H19: 1726 | I19: 2143.5 | J19: 1697.3 | K19: 1719.1 | L19: 2010.7 | M19: 2406 | N19: =+AA19-SUM(K19:M19) -> 1978.7 | O19: 1959.8 | T19: 6313 | U19: 6159.8 | V19: 4400.8 | W19: 6218.5 | X19: 6443.6 | Y19: 6631.4 | Z19: 7079 | AA19: 8114.5
B20: COGS | E20: 648 | F20: 524.2 | G20: 446.4 | H20: 570.3 | I20: 677.4 | J20: 532 | K20: 476.8 | L20: 644.3 | M20: 724.3 | N20: =+AA20-SUM(K20:M20) -> 599.9 | O20: 515.6 | T20: 2427 | U20: 2506.5 | V20: 1539.4 | W20: 2071 | X20: 2277.8 | Y20: 2199.6 | Z20: 2226.1 | AA20: 2445.3
B21: Gross Profit | C21: =+C19-C20 -> 0 | D21: =+D19-D20 -> 0 | E21: =+E19-E20 -> 1286 | F21: =+F19-F20 -> 1043.7 | G21: =+G19-G20 -> 1065.8 | H21: =+H19-H20 -> 1155.7 | I21: =+I19-I20 -> 1466.1 | J21: =+J19-J20 -> 1165.3 | ... O21: =+O19-O20 -> 1444.2 | T21: =T19-T20 -> 3886 | U21: =U19-U20 -> 3653.3 | V21: =V19-V20 -> 2861.4 | W21: =W19-W20 -> 4147.5 | X21: =X19-X20 -> 4165.8 | Y21: =Y19-Y20 -> 4431.8 | Z21: =Z19-Z20 -> 4852.9 | AA21: =AA19-AA20 -> 5669.2
B22: SGA | E22: 967.6 | F22: 906.6 | G22: 849.9 | H22: 958.4 | I22: 1064.2 | J22: 990.5 | K22: 949.4 | L22: 1083.4 | M22: 1178.6 | N22: =+AA22-SUM(K22:M22) -> 1160.5 | O22: 1077 | T22: 3168.3 | U22: 3237.5 | V22: 2638.5 | W22: 3305.6 | X22: 3408.9 | Y22: 3600.5 | Z22: 3863 | AA22: 4371.9
B23: Impairment of Assets | E23: 0 | F23: 0 | G23: 0 | H23: 0 | I23: 0 | J23: 0.8 | K23: 0 | L23: 0 | M23: 0 | N23: =+AA23-SUM(K23:M23) -> 0 | O23: 0 | T23: 25.8 | U23: 31.6 | V23: 96 | W23: 21.3 | X23: 9.7 | Y23: 0 | Z23: 0.8 | AA23: 0
B24: Restructruing and other | E24: 0.7 | F24: 29.3 | G24: 7.4 | H24: 18.4 | I24: 12.2 | J24: 19 | K24: 19.3 | L24: 37.3 | M24: 31.8 | N24: =+AA24-SUM(K24:M24) -> 29.7 | O24: 24.8 | T24: 130.1 | U24: 67.2 | V24: 170.5 | W24: 22.2 | X24: 43 | Y24: 74.9 | Z24: 57 | AA24: 118.1
B25: Total OpEx | C25: =SUM(C22:C24) -> 0 | D25: =SUM(D22:D24) -> 0 | E25: =SUM(E22:E24) -> 968.3 | F25: =SUM(F22:F24) -> 935.9 | G25: =SUM(G22:G24) -> 857.3 | H25: =SUM(H22:H24) -> 976.8 | I25: =SUM(I22:I24) -> 1076.4 | J25: =SUM(J22:J24) -> 1010.3 | ... O25: =SUM(O22:O24) -> 1101.8 | T25: =SUM(T22:T24) -> 3324.2 | U25: =SUM(U22:U24) -> 3336.3 | V25: =SUM(V22:V24) -> 2905 | W25: =SUM(W22:W24) -> 3349.1 | X25: =SUM(X22:X24) -> 3461.6 | Y25: =SUM(Y22:Y24) -> 3675.4 | Z25: =SUM(Z22:Z24) -> 3920.8 | AA25: =SUM(AA22:AA24) -> 4490
B26: Operating Profit | C26: =C21-C25 -> 0 | D26: =D21-D25 -> 0 | E26: =E21-E25 -> 317.7 | F26: =F21-F25 -> 107.8 | G26: =G21-G25 -> 208.5 | H26: =H21-H25 -> 178.9 | I26: =I21-I25 -> 389.7 | J26: =J21-J25 -> 155 | K26: 273.6 | L26: 245.7 | M26: =+M21-M25 -> 471.3 | N26: =+N21-N25 -> 188.6 | O26: =+O21-O25 -> 342.4 | T26: =T21-T25 -> 561.8 | U26: =U21-U25 -> 317 | V26: =V21-V25 -> -43.6 | W26: =W21-W25 -> 798.4 | X26: =X21-X25 -> 704.2 | Y26: =Y21-Y25 -> 756.4 | Z26: =Z21-Z25 -> 932.1 | AA26: =AA21-AA25 -> 1179.2
B27: Interest Expense | E27: 10.6 | F27: 11.6 | G27: 10.9 | H27: 11.4 | I27: 11.6 | J27: 10.2 | K27: 11.5 | L27: 15.9 | M27: 13.3 | N27: =+AA27-SUM(K27:M27) -> 13.5 | O27: 13 | T27: 20.7 | U27: 17.6 | V27: 48.5 | W27: 54 | X27: 40.4 | Y27: 42.2 | Z27: 44.1 | AA27: 54.2
B28: Interest Income | E28: 20.7 | F28: 20.8 | G28: 20.1 | H28: 17.9 | I28: 17.8 | J28: 18.2 | K28: 14.8 | L28: 14.6 | M28: 11.9 | N28: =+AA28-SUM(K28:M28) -> 12.4 | O28: 11.6 | T28: 40.8 | U28: 34.4 | V28: 9.7 | W28: 5.5 | X28: 32.2 | Y28: 73 | Z28: 74 | AA28: 53.7
B29: Other Income | E29: 2 | F29: -5.5 | G29: -1.1 | H29: 2.7 | I29: -12.2 | J29: -0.7 | K29: 1.1 | L29: -1.6 | M29: -6.1 | N29: =+AA29-SUM(K29:M29) -> 5.6 | O29: 1.2 | T29: 0.6 | U29: -7.4 | V29: 7.6 | W29: 4.7 | X29: -4.1 | Y29: -9.8 | Z29: -11.3 | AA29: -1
B30: Pre Tax Income | C30: =C26-C27+C28+C29 -> 0 | D30: =D26-D27+D28+D29 -> 0 | E30: =E26-E27+E28+E29 -> 329.8 | F30: =F26-F27+F28+F29 -> 111.5 | G30: =G26-G27+G28+G29 -> 216.6 | H30: =H26-H27+H28+H29 -> 188.1 | I30: =I26-I27+I28+I29 -> 383.7 | J30: =J26-J27+J28+J29 -> 162.3 | ... O30: =O26-O27+O28+O29 -> 342.2 | T30: =T26-T27+T28+T29 -> 582.5 | U30: =U26-U27+U28+U29 -> 326.4 | V30: =V26-V27+V28+V29 -> -74.8 | W30: =W26-W27+W28+W29 -> 754.6 | X30: =X26-X27+X28+X29 -> 691.9 | Y30: =Y26-Y27+Y28+Y29 -> 777.4 | Z30: =Z26-Z27+Z28+Z29 -> 950.7 | AA30: =AA26-AA27+AA28+AA29 -> 1177.7
B31: Tax Expenses | E31: 53.2 | F31: 20.8 | G31: 48 | H31: 40.2 | I31: 86.3 | J31: 33.3 | K31: 57.6 | L31: 35.3 | M31: 102.2 | N31: =+AA31-SUM(K31:M31) -> 41.5 | O31: 80 | T31: 151.6 | U31: -57.9 | V31: 46.3 | W31: 154.5 | X31: 169.2 | Y31: 131.1 | Z31: 207.8 | AA31: 236.6
B32: Net Income | C32: =C30-C31 -> 0 | D32: =D30-D31 -> 0 | E32: =E30-E31 -> 276.6 | F32: =F30-F31 -> 90.7 | G32: =G30-G31 -> 168.6 | H32: =H30-H31 -> 147.9 | I32: =I30-I31 -> 297.4 | J32: =J30-J31 -> 129 | ... O32: =O30-O31 -> 262.2 | T32: =T30-T31 -> 430.9 | U32: =U30-U31 -> 384.3 | V32: =V30-V31 -> -121.1 | W32: =W30-W31 -> 600.1 | X32: =X30-X31 -> 522.7 | Y32: =Y30-Y31 -> 646.3 | Z32: =Z30-Z31 -> 742.9 | AA32: =AA30-AA31 -> 941.1
B34: EPS | C34: =+C32/C35 -> #DIV/0! | D34: =+D32/D35 -> #DIV/0! | E34: =+E32/E35 -> 4.2553846 | F34: =+F32/F35 -> #DIV/0! | G34: =+G32/G35 -> 2.6677215 | H34: =+H32/H35 -> 2.3626198 | I34: =+I32/I35 -> 4.7584 | J34: =+J32/J35 -> #DIV/0! | ... O34: =+O32/O35 -> 4.3627288 | T34: =T32/T35 -> 5.5191936 | U34: =U32/U35 -> 5.2892357 | V34: =V32/V35 -> -1.6559325 | W34: =W32/W35 -> 8.5636818 | X34: =X32/X35 -> 7.9918659 | Y34: =Y32/Y35 -> 10.669545 | Z34: =Z32/Z35 -> 11.867412 | AA34: =AA32/AA35 -> 15.427869
B35: Number of Shares | E35: 65 | G35: 63.2 | H35: 62.6 | I35: 62.5 | K35: 61 | L35: 61.1 | M35: 61.1 | N35: 61.1 | O35: 60.1 | T35: =52.192+25.881 -> 78.073 | U35: =47.777+24.88^1 -> 72.657 | V35: =48.25+24.881 -> 73.131 | W35: =45.194+24.881 -> 70.075 | X35: =40.523+24.881 -> 65.404 | Y35: 60.574282 | Z35: 62.6 | AA35: 61
B37: Store Growth | X37: =+X8/W8-1 -> #DIV/0! | Y37: =+Y8/X8-1 -> #DIV/0! | Z37: =+Z8/Y8-1 -> 0 | AA37: =+AA8/Z8-1 -> 0.053191489
B38: North America Growth | C38: n.a. | D38: n.a. | E38: n.a. | F38: n.a. | G38: =+G12/C12-1 -> #DIV/0! | H38: =+H12/D12-1 -> #DIV/0! | I38: =+I12/E12-1 -> 0.069002464 | J38: =+J12/F12-1 -> 0.055414108 | K38: =+K12/G12-1 -> 0.078921407 | L38: =+L12/H12-1 -> 0.12562542 | M38: =+M12/I12-1 -> 0.080785807 | N38: =+N12/J12-1 -> 0.082304527 | O38: =+O12/K12-1 -> 0.12816215 | T38: n.a. | U38: =U12/T12-1 -> #DIV/0! | V38: =V12/U12-1 -> #DIV/0! | W38: =W12/V12-1 -> #DIV/0! | X38: =X12/W12-1 -> #DIV/0! | Y38: =Y12/X12-1 -> #DIV/0! | Z38: =Z12/Y12-1 -> 0.049767682 | AA38: =AA12/Z12-1 -> 0.09163634
B39: Europe Growth | C39: n.a. | D39: n.a. | E39: n.a. | F39: n.a. | G39: =+G13/C13-1 -> #DIV/0! | H39: =+H13/D13-1 -> #DIV/0! | I39: =+I13/E13-1 -> 0.15896453 | J39: =+J13/F13-1 -> 0.11999147 | K39: =+K13/G13-1 -> 0.15737842 | L39: =+L13/H13-1 -> 0.21629263 | M39: =+M13/I13-1 -> 0.11929186 | N39: =+N13/J13-1 -> 0.17906755 | O39: =+O13/K13-1 -> 0.071956718 | T39: n.a. | U39: =U13/T13-1 -> #DIV/0! | V39: =V13/U13-1 -> #DIV/0! | W39: =W13/V13-1 -> #DIV/0! | X39: =X13/W13-1 -> #DIV/0! | Y39: =Y13/X13-1 -> #DIV/0! | Z39: =Z13/Y13-1 -> 0.10513211 | AA39: =AA13/Z13-1 -> 0.16736402
B40: Asia Growth | C40: n.a. | D40: n.a. | E40: n.a. | F40: n.a. | G40: =+G14/C14-1 -> #DIV/0! | H40: =+H14/D14-1 -> #DIV/0! | I40: =+I14/E14-1 -> 0.13508065 | J40: =+J14/F14-1 -> 0.094598022 | K40: =+K14/G14-1 -> 0.21258634 | L40: =+L14/H14-1 -> 0.17201473 | M40: =+M14/I14-1 -> 0.22419578 | N40: =+N14/J14-1 -> 0.30583874 | O40: =+O14/K14-1 -> 0.24324895 | T40: n.a. | U40: =U14/T14-1 -> #DIV/0! | V40: =V14/U14-1 -> #DIV/0! | W40: =W14/V14-1 -> #DIV/0! | X40: =X14/W14-1 -> #DIV/0! | Y40: =Y14/X14-1 -> #DIV/0! | Z40: =Z14/Y14-1 -> 0.091152815 | AA40: =AA14/Z14-1 -> 0.23054873
B41: Other Growth | C41: n.a. | D41: n.a. | E41: n.a. | F41: n.a. | G41: =+G15/C15-1 -> #DIV/0! | H41: =+H15/D15-1 -> #DIV/0! | I41: =+I15/E15-1 -> 0.057926829 | J41: =+J15/F15-1 -> -0.032697548 | K41: =+K15/G15-1 -> 0.011764706 | L41: =+L15/H15-1 -> 0.099009901 | M41: =+M15/I15-1 -> -0.10951009 | N41: =+N15/J15-1 -> -0.076056338 | O41: =+O15/K15-1 -> 0.040697674 | T41: n.a. | U41: =U15/T15-1 -> #DIV/0! | V41: =V15/U15-1 -> #DIV/0! | W41: =W15/V15-1 -> #DIV/0! | X41: =X15/W15-1 -> #DIV/0! | Y41: =Y15/X15-1 -> #DIV/0! | Z41: =Z15/Y15-1 -> -0.011619959 | AA41: =AA15/Z15-1 -> -0.014522822
B42: Retail Growth | C42: n.a. | D42: n.a. | E42: n.a. | F42: n.a. | G42: =+G16/C16-1 -> #DIV/0! | H42: =+H16/D16-1 -> #DIV/0! | I42: =+I16/E16-1 -> 0.1172482 | J42: =+J16/F16-1 -> 0.58689938 | K42: =+K16/G16-1 -> 0.16327716 | L42: =+L16/H16-1 -> 0.15331996 | M42: =+M16/I16-1 -> 0 | N42: =+N16/J16-1 -> -0.016033923 | O42: =+O16/K16-1 -> 0 | T42: n.a. | U42: =U16/T16-1 -> -0.0018410801 | V42: =V16/U16-1 -> -0.25691678 | W42: =W16/V16-1 -> 0.41790776 | X42: =X16/W16-1 -> 0.028314094 | Y42: =Y16/X16-1 -> 0.073499297 | Z42: =Z16/Y16-1 -> 0.096322684 | AA42: =AA16/Z16-1 -> 0.1598499
B43: Wholesale Growth | C43: n.a. | D43: n.a. | E43: n.a. | F43: n.a. | G43: =+G17/C17-1 -> #DIV/0! | H43: =+H17/D17-1 -> #DIV/0! | I43: =+I17/E17-1 -> 0.085702513 | J43: =+J17/F17-1 -> 0.038614032 | K43: =+K17/G17-1 -> 0.08505386 | L43: =+L17/H17-1 -> 0.19110659 | M43: =+M17/I17-1 -> 0 | N43: =+N17/J17-1 -> 0.20680498 | O43: =+O17/K17-1 -> 0 | T43: n.a. | U43: =U17/T17-1 -> -0.05922675 | V43: =V17/U17-1 -> -0.33419229 | W43: =W17/V17-1 -> 0.41952489 | X43: =X17/W17-1 -> 0.049828421 | Y43: =Y17/X17-1 -> -0.044418573 | Z43: =Z17/Y17-1 -> 0.014151164 | AA43: =AA17/Z17-1 -> 0.12710807
...

Sheet Ratios
A1: Main
B2: Ratios | D2: FY19 | E2: FY20 | F2: FY21 | G2: FY22 | H2: FY23 | I2: FY24 | J2: FY25 | K2: FY26 | M2: Average | N2: Median | P2: Beschreibung
B3: Etragskennzahlen
B4: Eigenkapitalrendite (ROE) | D4: =Model!T32/Model!T81 -> 0.13108421 | E4: =Model!U32/Model!U81 -> 0.14269801 | F4: =Model!V32/Model!V81 -> -0.046498234 | G4: =Model!W32/Model!W81 -> 0.23663249 | H4: =Model!X32/Model!X81 -> 0.21505863 | I4: =Model!Y32/Model!Y81 -> 0.26376362 | J4: =Model!Z32/Model!Z81 -> 0.28700019 | K4: =Model!AA32/Model!AA81 -> 0.33120997 | M4: =AVERAGE(G4:I4,D4) -> 0.21163474 | N4: =MEDIAN(G4:I4,D4:E4) -> 0.21505863 | P4: Net Income/Book Value of Equity
B5: Umsatzrendite | D5: =Model!T32/Model!T19 -> 0.06825598 | E5: =Model!U32/Model!U19 -> 0.062388389 | F5: =Model!V32/Model!V19 -> -0.027517724 | G5: =Model!W32/Model!W19 -> 0.096502372 | H5: =Model!X32/Model!X19 -> 0.08111925 | I5: =Model!Y32/Model!Y19 -> 0.097460566 | J5: =Model!Z32/Model!Z19 -> 0.1049442 | K5: =Model!AA32/Model!AA19 -> 0.11597757 | M5: =AVERAGE(G5:I5,D5) -> 0.085834542 | N5: =MEDIAN(G5:I5,D5:E5) -> 0.08111925 | P5: Net Income/Revenue
B6: EBIT-Marge | D6: =Model!T26/Model!T19 -> 0.088990971 | E6: =Model!U26/Model!U19 -> 0.05146271 | F6: =Model!V26/Model!V19 -> -0.0099072896 | G6: =Model!W26/Model!W19 -> 0.12839109 | H6: =Model!X26/Model!X19 -> 0.10928673 | I6: =Model!Y26/Model!Y19 -> 0.1140634 | J6: =Model!Z26/Model!Z19 -> 0.13167114 | K6: =Model!AA26/Model!AA19 -> 0.14532011 | M6: =AVERAGE(G6:I6,D6) -> 0.11018305 | N6: =MEDIAN(G6:I6,D6:E6) -> 0.10928673 | P6: EBIT/Revenue
B7: EBITDA-Marge | D7: =(Model!T26+Model!T86)/Model!T19 -> 0.13354982 | E7: =(Model!U26+Model!U86)/Model!U19 -> 0.09521413 | F7: =(Model!V26+Model!V86)/Model!V19 -> 0.046355208 | G7: =(Model!W26+Model!W86)/Model!W19 -> 0.16532926 | H7: =(Model!X26+Model!X86)/Model!X19 -> 0.14350674 | I7: =(Model!Y26+Model!Y86)/Model!Y19 -> 0.14859607 | J7: =(Model!Z26+Model!Z86)/Model!Z19 -> 0.16269247 | K7: =(Model!AA26+Model!AA86)/Model!AA19 -> 0.17403414 | M7: =AVERAGE(G7:I7,D7) -> 0.14774547 | N7: =MEDIAN(G7:I7,D7:E7) -> 0.14350674 | P7: EBITDA/Revenue
B8: Kapitalumschlag | D8: =Model!T19/Model!T66 -> 1.0622939 | E8: =Model!U19/Model!U66 -> 0.846138 | F8: =Model!V19/Model!V66 -> 0.55794612 | G8: =Model!W19/Model!W66 -> 0.80501508 | H8: =Model!X19/Model!X66 -> 0.94905369 | I8: =Model!Y19/Model!Y66 -> 1.0043619 | J8: =Model!Z19/Model!Z66 -> 1.0044982 | K8: =Model!AA19/Model!AA66 -> 1.0484527 | M8: =AVERAGE(G8:I8,D8) -> 0.95518114 | N8: =AVERAGE(H8:L8,E8) -> 0.9705009 | P8: Revenue/Total Liabilties and Equity
B9: Return on Capital | D9: =(Model!T32+Model!T27)/Model!T66 -> 0.075991115 | E9: =(Model!U32+Model!U27)/Model!U66 -> 0.055206802 | F9: =(Model!V32+Model!V27)/Model!V66 -> -0.0092044374 | G9: =(Model!W32+Model!W27)/Model!W66 -> 0.084676428 | H9: =(Model!X32+Model!X27)/Model!X66 -> 0.082936888 | I9: =(Model!Y32+Model!Y27)/Model!Y66 -> 0.1042771 | J9: =(Model!Z32+Model!Z27)/Model!Z66 -> 0.11167397 | K9: =(Model!AA32+Model!AA27)/Model!AA66 -> 0.12860004 | M9: =AVERAGE(G9:I9,D9) -> 0.086970383 | N9: =MEDIAN(G9:I9,D9:E9) -> 0.082936888 | P9: (Net Income+Interest paid on debt)/Total Liabilies and Equity
B10: Return on Assets | D10: =Model!T26/Model!T66 -> 0.094534563 | E10: =Model!U26/Model!U66 -> 0.043544554 | F10: =Model!V26/Model!V66 -> -0.0055277338 | G10: =Model!W26/Model!W66 -> 0.10335676 | H10: =Model!X26/Model!X66 -> 0.10371898 | I10: =Model!Y26/Model!Y66 -> 0.11456093 | J10: =Model!Z26/Model!Z66 -> 0.13226342 | K10: =Model!AA26/Model!AA66 -> 0.15236126 | M10: =AVERAGE(G10:I10,D10) -> 0.10404281 | N10: =MEDIAN(G10:I10,D10:E10) -> 0.10335676 | P10: EBIT/Total Assets
B11: Return on Capital Employed (ROCE) | D11: =Model!T26/(Model!T65+SUM(Model!T53:T57)-Model!T68) -> 0.10895198 | E11: =Model!U26/(Model!U65+SUM(Model!U53:U57)-Model!U68) -> 0.058565965 | F11: =Model!V26/(Model!V65+SUM(Model!V53:V57)-Model!V68) -> -0.0088034568 | G11: =Model!W26/(Model!W65+SUM(Model!W53:W57)-Model!W68) -> 0.14751857 | H11: =Model!X26/(Model!X65+SUM(Model!X53:X57)-Model!X68) -> 0.14404942 | I11: =Model!Y26/(Model!Y65+SUM(Model!Y53:Y57)-Model!Y68) -> 0.16414218 | J11: =Model!Z26/(Model!Z65+SUM(Model!Z53:Z57)-Model!Z68) -> 0.19879287 | K11: =Model!AA26/(Model!AA65+SUM(Model!AA53:AA57)-Model!AA68) -> 0.22163331 | M11: =AVERAGE(G11:I11,D11) -> 0.14116554 | N11: =MEDIAN(G11:I11,D11:E11) -> 0.14404942 | P11: EBIT/(Long Term Assets + Working Capital (Exclusive of cash)-Accounts Payables)
B12: Return on Capital Invested (ROIC) | D12: =(Model!T26*(1-Model!T49))/(Model!T80+Model!T81-Model!T52) -> 0.067954267 | E12: =(Model!U26*(1-Model!U49))/(Model!U80+Model!U81-Model!U52) -> 0.064450984 | F12: =(Model!V26*(1-Model!V49))/(Model!V80+Model!V81-Model!V52) -> -0.011353401 | G12: =(Model!W26*(1-Model!W49))/(Model!W80+Model!W81-Model!W52) -> 0.10115277 | H12: =(Model!X26*(1-Model!X49))/(Model!X80+Model!X81-Model!X52) -> 0.090537955 | I12: =(Model!Y26*(1-Model!Y49))/(Model!Y80+Model!Y81-Model!Y52) -> 0.12204812 | J12: =(Model!Z26*(1-Model!Z49))/(Model!Z80+Model!Z81-Model!Z52) -> 0.1310057 | K12: =(Model!AA26*(1-Model!AA49))/(Model!AA80+Model!AA81-Model!AA52) -> 0.15347992 | M12: =AVERAGE(G12:I12,D12) -> 0.095423278 | N12: =MEDIAN(G12:I12,D12:E12) -> 0.090537955 | P12: (EBIT-Tax Expenses)/(Book Value of Equity + Book Value of Debt - Book Value of Cash)
B13: Umsatzverdienstrate | D13: =Model!T101/Model!T19 -> 0.1241565 | E13: =Model!U101/Model!U19 -> 0.12250398 | F13: =Model!V101/Model!V19 -> 0.086552445 | G13: =Model!W101/Model!W19 -> 0.11512423 | H13: =Model!X101/Model!X19 -> 0.06378422 | I13: =Model!Y101/Model!Y19 -> 0.16130832 | J13: =Model!Z101/Model!Z19 -> 0.1744738 | K13: =Model!AA101/Model!AA19 -> 0.1422392 | M13: =AVERAGE(G13:I13,D13) -> 0.11609332 | N13: =MEDIAN(G13:I13,D13:E13) -> 0.12250398 | P13: Operativer Cahsflow/Revenue
B14: Retention Rate | D14: =1-(Model!T113/Model!T114) -> 0.62057302 | E14: =1-(Model!U113/Model!U114) -> 0.70653425 | F14: =1-(Model!V113/Model!V114) -> -0.32095491 | G14: =1-(Model!W113/Model!W114) -> 0.6954933 | H14: =1-(Model!X113/Model!X114) -> 0.59414654 | I14: =1-(Model!Y113/Model!Y114) -> 0.56726707 | J14: =1-(Model!Z113/Model!Z114) -> 0.58182574 | K14: =1-(Model!AA113/Model!AA114) -> 0.65293363 | M14: =AVERAGE(G14:I14,D14) -> 0.61936998 | N14: =MEDIAN(G14:I14,D14:E14) -> 0.62057302 | P14: 1 - Dividends/Net Income
B15: Expected Growth | D15: =D14*D4 -> 0.081347321 | E15: =E14*E4 -> 0.10082103 | F15: =F14*F4 -> 0.014923836 | G15: =G14*G4 -> 0.16457631 | H15: =H14*H4 -> 0.12777634 | I15: =I14*I4 -> 0.14962442 | J15: =J14*J4 -> 0.1669841 | K15: =K14*K4 -> 0.21625813 | M15: =AVERAGE(G15:I15,D15) -> 0.1308311 | N15: =MEDIAN(G15:I15,D15:E15) -> 0.12777634 | P15: Retention rate * ROE
B16: Reinvestment Rate | D16: =(-Model!T102+SUM(Model!T94:T100))/(Model!T26*(1-Model!T49)) -> 0.35123224 | E16: =(-Model!U102+SUM(Model!U94:U100))/(Model!U26*(1-Model!U49)) -> 0.94363328 | F16: =(-Model!V102+SUM(Model!V94:V100))/(Model!V26*(1-Model!V49)) -> -3.0479747 | G16: =(-Model!W102+SUM(Model!W94:W100))/(Model!W26*(1-Model!W49)) -> -0.0045543005 | H16: =(-Model!X102+SUM(Model!X94:X100))/(Model!X26*(1-Model!X49)) -> -0.4348577 | I16: =(-Model!Y102+SUM(Model!Y94:Y100))/(Model!Y26*(1-Model!Y49)) -> 0.46403901 | J16: =(-Model!Z102+SUM(Model!Z94:Z100))/(Model!Z26*(1-Model!Z49)) -> 0.62274904 | K16: =(-Model!AA102+SUM(Model!AA94:AA100))/(Model!AA26*(1-Model!AA49)) -> 0.2829826 | M16: =AVERAGE(G16:I16,D16) -> 0.093964812 | N16: =MEDIAN(G16:I16,D16:E16) -> 0.35123224 | P16: Net CapEx + Change in WC / EBIT * (1-t)
B17: Expected Growth | D17: =D16*D12 -> 0.023867729 | E17: =E16*E12 -> 0.060818093 | F17: =F16*F12 -> 0.034604879 | G17: =G16*G12 -> -0.0004606801 | H17: =H16*H12 -> -0.039371127 | I17: =I16*I12 -> 0.05663509 | J17: =J16*J12 -> 0.081583672 | K17: =K16*K12 -> 0.043432148 | M17: =AVERAGE(G17:I17,D17) -> 0.010167753 | N17: =MEDIAN(G17:I17,D17:E17) -> 0.023867729 | P17: Reinvestment rate * ROIC
B20: Kennzahlen zur finanziellen Stabilität
B21: EK-Quote | D21: =Model!T81/Model!T82 -> 0.55313993 | E21: =Model!U81/Model!U82 -> 0.3699364 | F21: =Model!V81/Model!V82 -> 0.33019334 | G21: =Model!W81/Model!W82 -> 0.32829754 | H21: =Model!X81/Model!X82 -> 0.35797923 | I21: =Model!Y81/Model!Y82 -> 0.37111138 | J21: =Model!Z81/Model!Z82 -> 0.36730379 | K21: =Model!AA81/Model!AA82 -> 0.36712966 | M21: =AVERAGE(G21:I21,D21) -> 0.40263202 | N21: =MEDIAN(G21:I21,D21:E21) -> 0.3699364 | P21: Book Value of Equity/Total of Balance Sheet
B22: Gearing | D22: =(Model!T67+Model!T73+Model!T74+Model!T75-Model!T52-Model!T53)/Model!T81 -> -0.39498661 | E22: =(Model!U67+Model!U73+Model!U74+Model!U75-Model!U52-Model!U53)/Model!U81 -> 0.23133192 | F22: =(Model!V67+Model!V73+Model!V74+Model!V75-Model!V52-Model!V53)/Model!V81 -> 0.057940409 | G22: =(Model!W67+Model!W73+Model!W74+Model!W75-Model!W52-Model!W53)/Model!W81 -> 0.20177445 | H22: =(Model!X67+Model!X73+Model!X74+Model!X75-Model!X52-Model!X53)/Model!X81 -> 0.42345196 | I22: =(Model!Y67+Model!Y73+Model!Y74+Model!Y75-Model!Y52-Model!Y53)/Model!Y81 -> 0.25605028 | J22: =(Model!Z67+Model!Z73+Model!Z74+Model!Z75-Model!Z52-Model!Z53)/Model!Z81 -> 0.13100251 | K22: =(Model!AA67+Model!AA73+Model!AA74+Model!AA75-Model!AA52-Model!AA53)/Model!AA81 -> 0.2505807 | M22: =AVERAGE(G22:I22,D22) -> 0.12157252 | N22: =MEDIAN(G22:I22,D22:E22) -> 0.23133192 | P22: (Debt - Cash (Net Debt))/Book Value of Equity
B23: Dynamischer Verschuldungsgrad | D23: =(Model!T67+Model!T73+Model!T74+Model!T75-Model!T52-Model!T53)/(Model!T26*(1-Model!T49)+Model!T86+Model!T102+SUM(Model!T94:T100)) -> -3.4354066 | E23: =(Model!U67+Model!U73+Model!U74+Model!U75-Model!U52-Model!U53)/(Model!U26*(1-Model!U49)+Model!U86+Model!U102+SUM(Model!U94:U100)) -> 1.4228281 | F23: =(Model!V67+Model!V73+Model!V74+Model!V75-Model!V52-Model!V53)/(Model!V26*(1-Model!V49)+Model!V86+Model!V102+SUM(Model!V94:V100)) -> 0.97085211 | G23: =(Model!W67+Model!W73+Model!W74+Model!W75-Model!W52-Model!W53)/(Model!W26*(1-Model!W49)+Model!W86+Model!W102+SUM(Model!W94:W100)) -> 1.0527805 | H23: =(Model!X67+Model!X73+Model!X74+Model!X75-Model!X52-Model!X53)/(Model!X26*(1-Model!X49)+Model!X86+Model!X102+SUM(Model!X94:X100)) -> 18.833346 | I23: =(Model!Y67+Model!Y73+Model!Y74+Model!Y75-Model!Y52-Model!Y53)/(Model!Y26*(1-Model!Y49)+Model!Y86+Model!Y102+SUM(Model!Y94:Y100)) -> 0.80213095 | J23: =(Model!Z67+Model!Z73+Model!Z74+Model!Z75-Model!Z52-Model!Z53)/(Model!Z26*(1-Model!Z49)+Model!Z86+Model!Z102+SUM(Model!Z94:Z100)) -> 0.38680109 | K23: =(Model!AA67+Model!AA73+Model!AA74+Model!AA75-Model!AA52-Model!AA53)/(Model!AA26*(1-Model!AA49)+Model!AA86+Model!AA102+SUM(Model!AA94:AA100)) -> 1.2961013 | M23: =AVERAGE(G23:I23,D23) -> 4.3132126 | N23: =MEDIAN(G23:I23,D23:E23) -> 1.0527805 | P23: Net Debt/Free Cashflow
B24: Net Debt / EBITDA | D24: =(Model!T67+Model!T73+Model!T74+Model!T75-Model!T52-Model!T53)/(Model!T26+Model!T86) -> -1.5400308 | E24: =(Model!U67+Model!U73+Model!U74+Model!U75-Model!U52-Model!U53)/(Model!U26+Model!U86) -> 1.0622336 | F24: =(Model!V67+Model!V73+Model!V74+Model!V75-Model!V52-Model!V53)/(Model!V26+Model!V86) -> 0.73970588 | G24: =(Model!W67+Model!W73+Model!W74+Model!W75-Model!W52-Model!W53)/(Model!W26+Model!W86) -> 0.49771423 | H24: =(Model!X67+Model!X73+Model!X74+Model!X75-Model!X52-Model!X53)/(Model!X26+Model!X86) -> 1.1130096 | I24: =(Model!Y67+Model!Y73+Model!Y74+Model!Y75-Model!Y52-Model!Y53)/(Model!Y26+Model!Y86) -> 0.63669576 | J24: =(Model!Z67+Model!Z73+Model!Z74+Model!Z75-Model!Z52-Model!Z53)/(Model!Z26+Model!Z86) -> 0.29443431 | K24: =(Model!AA67+Model!AA73+Model!AA74+Model!AA75-Model!AA52-Model!AA53)/(Model!AA26+Model!AA86) -> 0.50417788 | M24: =AVERAGE(G24:I24,D24) -> 0.17684719 | N24: =MEDIAN(G24:I24,D24:E24) -> 0.63669576 | P24: Net Debt/EBITDA
B25: Sachinvestitionsquote | D25: =(-Model!T102/Model!T101) -> 0.25223271 | E25: =(-Model!U102/Model!U101) -> 0.35820302 | F25: =(-Model!V102/Model!V101) -> 0.28301391 | G25: =(-Model!W102/Model!W101) -> 0.23313312 | H25: =(-Model!X102/Model!X101) -> 0.52919708 | I25: =(-Model!Y102/Model!Y101) -> 0.15406189 | J25: =(-Model!Z102/Model!Z101) -> 0.17504655 | K25: =(-Model!AA102/Model!AA101) -> 0.35357824 | M25: =AVERAGE(G25:I25,D25) -> 0.2921562 | N25: =MEDIAN(G25:I25,D25:E25) -> 0.25223271 | P25: CapEx/CFFO
B26: Anlageabnutzungsgrad | D26: n.a. | E26: n.a. | F26: n.a. | G26: n.a. | H26: n.a. | I26: n.a. | J26: n.a. | K26: n.a. | M26: n.a. | N26: n.a. | P26: Accumlated Depreciation/Cost of fixed Assets
B27: Wachstumsquote | D27: =-Model!T102/Model!T86 -> 0.70280839 | E27: =-Model!U102/Model!U86 -> 1.0029685 | F27: =-Model!V102/Model!V86 -> 0.43537964 | G27: =-Model!W102/Model!W86 -> 0.72659991 | H27: =-Model!X102/Model!X86 -> 0.98639456 | I27: =-Model!Y102/Model!Y86 -> 0.71965066 | J27: =-Model!Z102/Model!Z86 -> 0.9845173 | K27: =-Model!AA102/Model!AA86 -> 1.7515021 | M27: =AVERAGE(G27:I27,D27) -> 0.78386338 | N27: =MEDIAN(G27:I27,D27:E27) -> 0.72659991 | P27: CapeX/Depreciation
B28: Cash Burn Rate | D28: positiv | E28: positiv | F28: =(Model!V81/-Model!V26) -> 59.733945 | G28: positiv | H28: positiv | I28: positiv | J28: positiv | K28: positiv | M28: positiv | N28: positiv | P28: Book Value of Equity/Absolute value of Loss
B29: Umlaufintensität | D29: =Model!T58/Model!T66 -> 0.60490005 | E29: =Model!U58/Model!U66 -> 0.46363274 | F29: =Model!V58/Model!V66 -> 0.53350238 | G29: =Model!W58/Model!W66 -> 0.54595 | H29: =Model!X58/Model!X66 -> 0.48959423 | I29: =Model!Y58/Model!Y66 -> 0.50886015 | J29: =Model!Z58/Model!Z66 -> 0.53778043 | K29: =Model!AA58/Model!AA66 -> 0.50225467 | M29: =AVERAGE(G29:I29,D29) -> 0.53732611 | N29: =MEDIAN(G29:I29,D29:E29) -> 0.50886015 | P29: Short term Assets/Total Assets
B30: Anlageintensität | D30: =1-D29 -> 0.39509995 | E30: =1-E29 -> 0.53636726 | F30: =1-F29 -> 0.46649762 | G30: =1-G29 -> 0.45405 | H30: =1-H29 -> 0.51040577 | I30: =1-I29 -> 0.49113985 | J30: =1-J29 -> 0.46221957 | K30: =1-K29 -> 0.49774533 | M30: =AVERAGE(G30:I30,D30) -> 0.46267389 | N30: =MEDIAN(G30:I30,D30:E30) -> 0.49113985 | P30: Long term Assets/Total Assets
B31: Anlagedeckungsgrad I | D31: =Model!T81/Model!T65 -> 1.4 | E31: =Model!U81/Model!U65 -> 0.68970728 | F31: =Model!V81/Model!V65 -> 0.70781356 | G31: =Model!W81/Model!W65 -> 0.72304271 | H31: =Model!X81/Model!X65 -> 0.70136204 | I31: =Model!Y81/Model!Y65 -> 0.75561243 | J31: =Model!Z81/Model!Z65 -> 0.79465218 | K31: =Model!AA81/Model!AA65 -> 0.73758534 | M31: =AVERAGE(G31:I31,D31) -> 0.89500429 | N31: =MEDIAN(G31:I31,D31:E31) -> 0.72304271 | P31: Book Value of Equity/Long term Assets
B32: Anlagedeckungsgrad II | D32: =(Model!T81+Model!T73)/Model!T81 -> 1.2096313 | E32: =(Model!U81+Model!U73)/Model!U81 -> 1.147191 | F32: =(Model!V81+Model!V73)/Model!V81 -> 1.6269774 | G32: =(Model!W81+Model!W73)/Model!W81 -> 1.4481467 | H32: =(Model!X81+Model!X73)/Model!X81 -> 1.4684221 | I32: =(Model!Y81+Model!Y73)/Model!Y81 -> 1.4654532 | J32: =(Model!Z81+Model!Z73)/Model!Z81 -> 1.2870002 | K32: =(Model!AA81+Model!AA73)/Model!AA81 -> 1.4360175 | M32: =AVERAGE(G32:I32,D32) -> 1.3979133 | N32: =MEDIAN(G32:I32,D32:E32) -> 1.4481467 | P32: Book Value of Equity + Long Term Borrowings/Long Term Assets
B33: Goodwill-Anteil | D33: =Model!T62/Model!T66 -> 0.15474187 | E33: =Model!U62/Model!U66 -> 0.12575722 | F33: =Model!V62/Model!V66 -> 0.11849128 | G33: =Model!W62/Model!W66 -> 0.11763564 | H33: =Model!X62/Model!X66 -> 0.13239561 | I33: =Model!Y62/Model!Y66 -> 0.13450762 | J33: =Model!Z62/Model!Z66 -> 0.12607665 | K33: =Model!AA62/Model!AA66 -> 0.11682925 | M33: =AVERAGE(G33:I33,D33) -> 0.13482018 | N33: =MEDIAN(G33:I33,D33:E33) -> 0.13239561 | P33: Goodwill/Balance Sheet Total
B35: Kennzahlen WC Management
B36: Debitorenlaufzeit | D36: =Model!T54/Model!T19*360 -> 22.701727 | E36: =Model!U54/Model!U19*360 -> 16.194682 | F36: =Model!V54/Model!V19*360 -> 36.934194 | G36: =Model!W54/Model!W19*360 -> 23.469325 | H36: =Model!X54/Model!X19*360 -> 25.012726 | I36: =Model!Y54/Model!Y19*360 -> 24.239226 | J36: =Model!Z54/Model!Z19*360 -> 23.367707 | K36: =Model!AA54/Model!AA19*360 -> 21.814283 | M36: =AVERAGE(G36:I36,D36) -> 23.855751 | N36: =MEDIAN(G36:I36,D36:E36) -> 23.469325 | P36: Accounts Receivables/Revenue*360
B37: Kreditorenlaufzeit | D37: =Model!T68/Model!T19*360 -> 11.536195 | E37: =Model!U68/Model!U19*360 -> 14.423845 | F37: =Model!V68/Model!V19*360 -> 29.113797 | G37: =Model!W68/Model!W19*360 -> 25.976039 | H37: =Model!X68/Model!X19*360 -> 20.761065 | I37: =Model!Y68/Model!Y19*360 -> 18.034201 | J37: =Model!Z68/Model!Z19*360 -> 22.172623 | K37: =Model!AA68/Model!AA19*360 -> 19.121326 | M37: =AVERAGE(G37:I37,D37) -> 19.076875 | N37: =MEDIAN(G37:I37,D37:E37) -> 18.034201 | P37: Accounts Payable/Revenue*360
B38: Liquidität 1.Grades | D38: =Model!T52/Model!T72 -> 0.48670944 | E38: =Model!U52/Model!U72 -> 0.77456979 | F38: =Model!V52/Model!V72 -> 1.6273347 | G38: =Model!W52/Model!W72 -> 0.82626236 | H38: =Model!X52/Model!X72 -> 1.0239705 | I38: =Model!Y52/Model!Y72 -> 1.1329062 | J38: =Model!Z52/Model!Z72 -> 0.90101701 | K38: =Model!AA52/Model!AA72 -> 1.0884205 | M38: =AVERAGE(G38:I38,D38) -> 0.86746214 | N38: =MEDIAN(G38:I38,D38:E38) -> 0.82626236 | P38: Cash and Cash Equivalents/Short term liabilites
B39: Liquidität 2.Grades | D39: =(Model!T52+Model!T54)/Model!T72 -> 0.8184318 | E39: =(Model!U52+Model!U54)/Model!U72 -> 0.90702677 | F39: =(Model!V52+Model!V54)/Model!V72 -> 1.9122287 | G39: =(Model!W52+Model!W54)/Model!W72 -> 1.0059848 | H39: =(Model!X52+Model!X54)/Model!X72 -> 1.3237362 | I39: =(Model!Y52+Model!Y54)/Model!Y72 -> 1.4372274 | J39: =(Model!Z52+Model!Z54)/Model!Z72 -> 1.1163706 | K39: =(Model!AA52+Model!AA54)/Model!AA72 -> 1.3576239 | M39: =AVERAGE(G39:I39,D39) -> 1.146345 | N39: =MEDIAN(G39:I39,D39:E39) -> 1.0059848 | P39: (Cash and Cash Equivalents + Accounts Receivables) /Short term liabilities
B40: Liquidität 3.Grades | D40: =Model!T58/Model!T72 -> 2.995417 | E40: =Model!U58/Model!U72 -> 1.6133843 | F40: =Model!V58/Model!V72 -> 2.6552246 | G40: =Model!W58/Model!W72 -> 1.8696192 | H40: =Model!X58/Model!X72 -> 2.2257114 | I40: =Model!Y58/Model!Y72 -> 2.28994 | J40: =Model!Z58/Model!Z72 -> 1.7762103 | K40: =Model!AA58/Model!AA72 -> 2.1282234 | M40: =AVERAGE(G40:I40,D40) -> 2.3451719 | N40: =MEDIAN(G40:I40,D40:E40) -> 2.2257114 | P40: Short term assets/short term liabilites
B41: Vorratsintensität | D41: =Model!T55/Model!T66 -> 0.1376119 | E41: =Model!U55/Model!U66 -> 0.10112776 | F41: =Model!V55/Model!V66 -> 0.096228209 | G41: =Model!W55/Model!W66 -> 0.12651624 | H41: =Model!X55/Model!X66 -> 0.15778776 | I41: =Model!Y55/Model!Y66 -> 0.13664314 | J41: =Model!Z55/Model!Z66 -> 0.13474664 | K41: =Model!AA55/Model!AA66 -> 0.13105498 | M41: =AVERAGE(G41:I41,D41) -> 0.13963976 | N41: =MEDIAN(G41:I41,D41:E41) -> 0.13664314 | P41: Inventory/Balance Sheet Total
B42: Umschlaghäufigkeit der Vorräte | D42: =Model!T20/Model!T55 -> 2.9677183 | E42: =Model!U20/Model!U55 -> 3.4046455 | F42: =Model!V20/Model!V55 -> 2.028195 | G42: =Model!W20/Model!W55 -> 2.1191037 | H42: =Model!X20/Model!X55 -> 2.1262018 | I42: =Model!Y20/Model!Y55 -> 2.4380403 | J42: =Model!Z20/Model!Z55 -> 2.3442502 | K42: =Model!AA20/Model!AA55 -> 2.4108252 | M42: =AVERAGE(G42:I42,D42) -> 2.412766 | N42: =MEDIAN(G42:I42,D42:E42) -> 2.4380403 | P42: Cogs/Inventory
B43: Lagedauer | D43: =360/D42 -> 121.30532 | E43: =360/E42 -> 105.73788 | F43: =360/F42 -> 177.49773 | G43: =360/G42 -> 169.88315 | H43: =360/H42 -> 169.31601 | I43: =360/I42 -> 147.65957 | J43: =360/J42 -> 153.56723 | K43: =360/K42 -> 149.32646 | M43: =AVERAGE(G43:I43,D43) -> 152.04101 | N43: =MEDIAN(G43:I43,D43:E43) -> 147.65957 | P43: 360/Umschlaghäufigkeit der Vorräte
...
