Workbook

Sheet Main
A1: Hermès
A2: in Mio EUR | J2: Price | K2: 1553
J3: Shares | K3: 104.79324 | L3: Q226
B4: IR | J4: MC | K4: =K2*K3 -> 162743.9
B5: RMS | J5: Cash | K5: 12310 | L5: Q226
J6: Debt | K6: =1+4 -> 5 | L6: Q226
B7: Segment | C7: % of Rev | D7: Costumers | E7: Competitors | J7: EV | K7: =K4-K5+K6 -> 150438.9
B8: Leather Goods and Saddlery | C8: 0.42843817
B9: Ready to Wear and Accesoires | C9: 0.28811301 | J9: Employee Count: | L9: 23242
B10: Silk and Textiles | C10: 0.058102345 | J10: Founded | K10: 1837
B11: Other Hermes Sectors | C11: 0.12886461
B12: Perfume and Beauty | C12: 0.034514925 | J12: Managment: | O12: Design Senior Executive:
B13: Watches | C13: 0.041044776 | J13: Executive Chairman | L13: Henri-Louis Bauer | O13: Silk and Textiles | Q13: Alix Coindreau
B14: Other Prodcuts | C14: 0.020922175 | J14: Chairwoman | L14: Agnès de Villers | O14: Watches | Q14: Laurent Dordet
J15: CEO | L15: Axel Dumas | O15: Ready to Wear W | Q15: Cielo Dunbavand
B16: Notes | J16: CFO | L16: Eric du Halgouet | O16: Shoes | Q16: Julien Faurie
B17: Iconic Models: Birkin bag(Starting price: 8.850), Kelly Bag (Starting price: 8.450) | J17: Artistiv EVP | L17: Pierre-Alexis Dumas | O17: Leather Goods | Q17: Ly Lallier
B18: FY24: 2.300 new jobs (1.300 in France) | J18: CCO | L18: Charlotte David | O18: Ready to Wear M | Q18: Véronique Nichanian
J19: CSDO | L19: Floarian Craen | O19: Home | Q19: Anne-Sarah Panhard
J20: CSAO | L20: Olivier Fournier | O20: Accessoires | Q20: Élodie Potdevin
J21: CISO | L21: Wilfried Guerrand | O21: Jewellery | Q21: Ambre Pulcini
B22: History: | J22: CHRO | L22: Sharon MacBeath
B23: Founded 1837 by Thierry Hermés -> leather goods for european royals | J23: CMDO | L23: Guillame de Seynes
B24: Emile Maurice son of Thierry Hermés -> 3 daughters: married into three families: Guerrand, Puech, Dumas
B25: Assuming leadership in 1978 Jean-Louis Dumas transformed th company in a global luxury brand
B26: In 2011 the Dumas family prevented a takeover by LVMH by pooling their shares: over 50 descendants pooled their shares into a holding -> 52% of voting shares
B27: Every heir of Hermés began their career as in apprentice in production
B28: 2003 -> silk and textiles was the most important, now today leather goods
B29: Since 2014 Axel Dumas -> CEO in the 6. Generation
B43: https://quartr.com/insights/business-philosophy/hermes-two-centuries-of-craftsmanship-and-excellence

Sheet Model
A1: Main
C2: H123 | D2: H223 | E2: H124 | F2: H224 | G2: H125 | H2: H225 | I2: H126 | J2: H226 | L2: FY18 | M2: FY19 | N2: FY20 | O2: FY21 | P2: FY22 | Q2: FY23 | R2: FY24 | S2: FY25
B3: France | E3: 680 | F3: =+R3-E3 -> 767 | G3: 740 | H3: =+S3-G3 -> 835 | I3: 753 | L3: 802.2 | M3: 867.3 | N3: 619.6 | O3: 838 | P3: 1064 | Q3: 1274 | R3: 1447 | S3: 1575
B4: Europe | E4: 970 | F4: =+R4-E4 -> 1177 | G4: 1088 | H4: =+S4-G4 -> 1274 | I4: 1165 | L4: 1106.5 | M4: 1201.9 | N4: 953.4 | O4: 1393 | P4: 1536 | Q4: 1818 | R4: 2147 | S4: 2362
B5: Japan | E5: 693 | F5: =+R5-E5 -> 744 | G5: 815 | H5: =+S5-G5 -> 776 | I5: 798 | L5: 748.3 | M5: 846 | N5: 833.9 | O5: 877 | P5: 1101 | Q5: 1269 | R5: 1437 | S5: 1591
B6: Asia Pacific | E6: 3521 | F6: =+R6-E6 -> 3127 | G6: 3574 | H6: =+S6-G6 -> 3128 | I6: 3533 | L6: 2142.4 | M6: 2589.6 | N6: 2915.4 | O6: 4251 | P6: 5556 | Q6: 6273 | R6: 6648 | S6: 6702
B7: America | E7: 1329 | F7: =+R7-E7 -> 1536 | G7: 1455 | H7: =+S7-G7 -> 1620 | I7: 1585 | L7: 1058.6 | M7: 1240.7 | N7: 959 | O7: 1458 | P7: 2138 | Q7: 2592 | R7: 2865 | S7: 3075
B8: Other (middle east) | E8: 311 | F8: =+R8-E8 -> 316 | G8: 362 | H8: =+S8-G8 -> 335 | I8: 330 | L8: 108.1 | M8: 120 | N8: 108.2 | O8: 156 | P8: 207 | Q8: 299 | R8: 627 | S8: 697
B9: Leather Goods and Saddlery | C9: 2780 | D9: =Q9-C9 -> 2767 | E9: 3215 | F9: =+R9-E9 -> 3242 | G9: 3578 | H9: =+S9-G9 -> 3492 | I9: 3761 | L9: 2976 | M9: 3414 | N9: 3209 | O9: 4091 | P9: 4963 | Q9: 5547 | R9: 6457 | S9: 7070
B10: Ready to Wear and Accesoires | C10: 1922 | D10: =Q10-C10 -> 1957 | E10: 2162 | F10: =+R10-E10 -> 2243 | G10: 2255 | H10: =+S10-G10 -> 2270 | I10: 2198 | L10: 1310 | M10: 1574 | N10: 1409 | O10: 2219 | P10: 3152 | Q10: 3879 | R10: 4405 | S10: 4525
B11: Silk and Textiles | C11: 444 | D11: =Q11-C11 -> 488 | E11: 436 | F11: =+R11-E11 -> 514 | G11: 447 | H11: =+S11-G11 -> 517 | I11: 469 | L11: 537 | M11: 592 | N11: 452 | O11: 669 | P11: 842 | Q11: 932 | R11: 950 | S11: 964
B12: Other Hermes Sectors | C12: 836 | D12: =Q12-C12 -> 817 | E12: 967 | F12: =+R12-E12 -> 942 | G12: 1056 | H12: =+S12-G12 -> 999 | I12: 1065 | L12: 425 | M12: 525 | N12: 643 | O12: 1001 | P12: 1371 | Q12: 1653 | R12: 1909 | S12: 2055
B13: Perfume and Beauty | C13: 249 | D13: =Q13-C13 -> 243 | E13: 259 | F13: =+R13-E13 -> 276 | G13: 248 | H13: =+S13-G13 -> 241 | I13: 233 | L13: 312 | M13: 326 | N13: 263 | O13: 385 | P13: 448 | Q13: 492 | R13: 535 | S13: 489
B14: Watches | C14: 317 | D14: =Q14-C14 -> 294 | E14: 308 | F14: =+R14-E14 -> 269 | G14: 281 | H14: =+S14-G14 -> 268 | I14: 269 | L14: 169 | M14: 193 | N14: 196 | O14: 337 | P14: 519 | Q14: 611 | R14: 577 | S14: 549
B15: Other Prodcuts | C15: 150 | D15: =Q15-C15 -> 163 | E15: 157 | F15: =+R15-E15 -> 180 | G15: 168 | H15: =+S15-G15 -> 181 | I15: 168 | L15: 238 | M15: 258 | N15: 218 | O15: 279 | P15: 306 | Q15: 313 | R15: 337 | S15: 349
B16: Revenues | C16: =SUM(C9:C15) -> 6698 | D16: =SUM(D9:D15) -> 6729 | E16: =SUM(E9:E15) -> 7504 | F16: =SUM(F9:F15) -> 7666 | G16: 8034 | H16: =+S16-G16 -> 7968 | I16: 8163 | L16: 5966.1 | M16: 6883.4 | N16: 6389 | O16: 8982 | P16: 11602 | Q16: 13427 | R16: 15170 | S16: 16002
B17: COGS | C17: 1863 | D17: =Q17-C17 -> 1856 | E17: 2206 | F17: =+R17-E17 -> 2305 | G17: 2356 | H17: =+S17-G17 -> 2267 | I17: 2356 | L17: 1791.8 | M17: 2124.9 | N17: 2013 | O17: 2580 | P17: 3389 | Q17: 3719 | R17: 4511 | S17: 4623
B18: Gross Profit | C18: =C16-C17 -> 4835 | D18: =D16-D17 -> 4873 | E18: =E16-E17 -> 5298 | F18: =F16-F17 -> 5361 | G18: =G16-G17 -> 5678 | H18: =H16-H17 -> 5701 | I18: =I16-I17 -> 5807 | L18: =L16-L17 -> 4174.3 | M18: =M16-M17 -> 4758.5 | N18: =N16-N17 -> 4376 | O18: =O16-O17 -> 6402 | P18: =P16-P17 -> 8213 | Q18: =Q16-Q17 -> 9708 | R18: =R16-R17 -> 10659 | S18: =S16-S17 -> 11379
B19: SGA | C19: 1485 | D19: =Q19-C19 -> 1684 | E19: 1682 | F19: =+R19-E19 -> 1887 | G19: 1832 | H19: =+S19-G19 -> 1872 | I19: 1899 | L19: 1562.3 | M19: 1815.7 | N19: 1699 | O19: 2137 | P19: 2680 | Q19: 3169 | R19: 3569 | S19: 3704
B20: Other Income and Expenses | C20: 403 | D20: =Q20-C20 -> 486 | E20: 467 | F20: =+R20-E20 -> 475 | G20: 519 | H20: =+S20-G20 -> 587 | I20: 558 | L20: 536.7 | M20: 604 | N20: 696 | O20: 734 | P20: 836 | Q20: 889 | R20: 942 | S20: 1106
B21: Recurring Operating Income | C21: =C18-C19-C20 -> 2947 | D21: =D18-D19-D20 -> 2703 | E21: =E18-E19-E20 -> 3149 | F21: =F18-F19-F20 -> 2999 | G21: =G18-G19-G20 -> 3327 | H21: =H18-H19-H20 -> 3242 | I21: =+I18-I19-I20 -> 3350 | L21: =L18-L19-L20 -> 2075.3 | M21: =M18-M19-M20 -> 2338.8 | N21: =N18-N19-N20 -> 1981 | O21: =O18-O19-O20-1 -> 3530 | P21: =P18-P19-P20 -> 4697 | Q21: =Q18-Q19-Q20 -> 5650 | R21: =R18-R19-R20 -> 6148 | S21: =S18-S19-S20 -> 6569
B22: Other non-occuring expenses | C22: 0 | D22: =Q22-C22 -> 0 | E22: 0 | F22: =+R22-E22 -> 0 | G22: 0 | H22: =+S22-G22 -> 0 | I22: 0 | L22: 52.7 | M22: 0 | N22: 91 | O22: 0 | P22: 0 | Q22: 0 | R22: 0 | S22: 0
B23: Operating Profit | C23: =C21+C22 -> 2947 | D23: =D21+D22 -> 2703 | E23: =E21+E22 -> 3149 | F23: =F21+F22 -> 2999 | G23: =G21+G22 -> 3327 | H23: =H21+H22 -> 3242 | I23: =I21+I22 -> 3350 | L23: =L21+L22 -> 2128 | M23: =M21+M22+0.1 -> 2338.9 | N23: =N21+N22+1 -> 2073 | O23: =O21+O22 -> 3530 | P23: =P21+P22 -> 4697 | Q23: =Q21+Q22 -> 5650 | R23: =R21+R22 -> 6148 | S23: =S21+S22 -> 6569
B24: Net Financial Income | C24: 75 | D24: =Q24-C24 -> 115 | E24: 141 | F24: =+R24-E24 -> 142 | G24: 148 | H24: =+S24-G24 -> 59 | I24: 90 | L24: -61.8 | M24: -68.6 | N24: -86 | O24: -96 | P24: -62 | Q24: 190 | R24: 283 | S24: 207
B25: Pretax Profit | C25: =C23+C24 -> 3022 | D25: =D23+D24 -> 2818 | E25: =E23+E24 -> 3290 | F25: =F23+F24 -> 3141 | G25: =G23+G24 -> 3475 | H25: =H23+H24 -> 3301 | I25: =I23+I24 -> 3440 | L25: =L23+L24 -> 2066.2 | M25: =M23+M24 -> 2270.3 | N25: =N23+N24 -> 1987 | O25: =O23+O24 -> 3434 | P25: =P23+P24 -> 4635 | Q25: =Q23+Q24 -> 5840 | R25: =R23+R24 -> 6431 | S25: =S23+S24 -> 6776
B26: Tax Expense | C26: 831 | D26: =Q26-C26 -> 792 | E26: 927 | F26: =+R26-E26 -> 918 | G26: 1230 | H26: =+S26-G26 -> 1033 | I26: 1217 | L26: 672.2 | M26: 751 | N26: 613 | O26: 1015 | P26: 1305 | Q26: 1623 | R26: 1845 | S26: 2263
B27: Net Icome from Associates | C27: 43 | D27: =Q27-C27 -> 62 | E27: 16 | F27: =+R27-E27 -> 28 | G27: 26 | H27: =+S27-G27 -> 21 | I27: 23 | L27: 16.6 | M27: 15.9 | N27: 16 | O27: 34 | P27: 50 | Q27: 105 | R27: 44 | S27: 47
B28: Net Income | C28: =C25-C26+C27 -> 2234 | D28: =D25-D26+D27 -> 2088 | E28: =E25-E26+E27 -> 2379 | F28: =F25-F26+F27 -> 2251 | G28: =G25-G26+G27 -> 2271 | H28: =H25-H26+H27 -> 2289 | I28: =I25-I26+I27 -> 2246 | L28: =L25-L26+L27 -> 1410.6 | M28: =M25-M26+M27+0.1 -> 1535.3 | N28: =N25-N26+N27 -> 1390 | O28: =O25-O26+O27+1 -> 2454 | P28: =P25-P26+P27 -> 3380 | Q28: =Q25-Q26+Q27 -> 4322 | R28: =R25-R26+R27 -> 4630 | S28: =S25-S26+S27 -> 4560
B29: Non-Controlling Interest | C29: -8 | D29: =Q29-C29 -> -3 | E29: -10 | F29: =+R29-E29 -> -18 | G29: -25 | H29: =+S29-G29 -> -11 | I29: -9 | L29: -5.1 | M29: -7 | N29: -4 | O29: -8 | P29: -13 | Q29: -11 | R29: -28 | S29: -36
B30: Income attributable to Owners | C30: =C28+C29 -> 2226 | D30: =D28+D29 -> 2085 | E30: =E28+E29 -> 2369 | F30: =F28+F29 -> 2233 | G30: =G28+G29 -> 2246 | H30: =H28+H29 -> 2278 | I30: =I28+I29 -> 2237 | L30: =L28+L29 -> 1405.5 | M30: =M28+M29-0.1 -> 1528.2 | N30: =N28+N29-1 -> 1385 | O30: =O28+O29-1 -> 2445 | P30: =P28+P29 -> 3367 | Q30: =Q28+Q29 -> 4311 | R30: =R28+R29 -> 4602 | S30: =S28+S29 -> 4524
B32: EPS | C32: =+C30/C33 -> 21.271293 | D32: =+D30/D33 -> 19.92392 | E32: =+E30/E33 -> 22.637778 | F32: =+F30/F33 -> 21.338184 | G32: =+G30/G33 -> 21.423903 | H32: =+H30/H33 -> 21.57822 | I32: =+I30/I33 -> 21.346797 | L32: =+L30/L33 -> 13.484183 | M32: =+M30/M33 -> 14.661351 | N32: =+N30/N33 -> 13.262374 | O32: =+O30/O33 -> 23.369549 | P32: =+P30/P33 -> 32.20015 | Q32: =+Q30/Q33 -> 41.195214 | R32: =+R30/R33 -> 43.975963 | S32: =+S30/S33 -> 42.853322
B33: Shares | C33: 104.64808 | D33: 104.64808 | E33: 104.64808 | F33: 104.64808 | G33: 104.83617 | H33: 105.56941 | I33: 104.79324 | L33: 104.23323 | M33: 104.23323 | N33: 104.43077 | O33: 104.62333 | P33: 104.56473 | Q33: 104.64808 | R33: 104.64808 | S33: 105.56941
B35: France Growth | E35: =+E3/C3-1 -> #DIV/0! | F35: =+F3/D3-1 -> #DIV/0! | G35: =+G3/E3-1 -> 0.088235294 | H35: =+H3/F3-1 -> 0.088657106 | I35: =+I3/G3-1 -> 0.017567568 | M35: =M3/L3-1 -> 0.081151832 | N35: =N3/M3-1 -> -0.28559899 | O35: =O3/N3-1 -> 0.35248547 | P35: =P3/O3-1 -> 0.26968974 | Q35: =Q3/P3-1 -> 0.19736842 | R35: =R3/Q3-1 -> 0.13579278 | S35: =S3/R3-1 -> 0.08845888
B36: Europe Growth | E36: =+E4/C4-1 -> #DIV/0! | F36: =+F4/D4-1 -> #DIV/0! | G36: =+G4/E4-1 -> 0.12164948 | H36: =+H4/F4-1 -> 0.082412914 | I36: =+I4/G4-1 -> 0.070772059 | M36: =M4/L4-1 -> 0.086217804 | N36: =N4/M4-1 -> -0.20675597 | O36: =O4/N4-1 -> 0.46108664 | P36: =P4/O4-1 -> 0.10265614 | Q36: =Q4/P4-1 -> 0.18359375 | R36: =R4/Q4-1 -> 0.1809681 | S36: =S4/R4-1 -> 0.10013973
B37: Japan Growth | E37: =+E5/C5-1 -> #DIV/0! | F37: =+F5/D5-1 -> #DIV/0! | G37: =+G5/E5-1 -> 0.17604618 | H37: =+H5/F5-1 -> 0.043010753 | I37: =+I5/G5-1 -> -0.020858896 | M37: =M5/L5-1 -> 0.13056261 | N37: =N5/M5-1 -> -0.0143026 | O37: =O5/N5-1 -> 0.051684854 | P37: =P5/O5-1 -> 0.25541619 | Q37: =Q5/P5-1 -> 0.15258856 | R37: =R5/Q5-1 -> 0.13238771 | S37: =S5/R5-1 -> 0.10716771
B38: Asia Pacific Growth | E38: =+E6/C6-1 -> #DIV/0! | F38: =+F6/D6-1 -> #DIV/0! | G38: =+G6/E6-1 -> 0.015052542 | H38: =+H6/F6-1 -> 0.00031979533 | I38: =+I6/G6-1 -> -0.01147174 | M38: =M6/L6-1 -> 0.20873786 | N38: =N6/M6-1 -> 0.12581094 | O38: =O6/N6-1 -> 0.45811895 | P38: =P6/O6-1 -> 0.30698659 | Q38: =Q6/P6-1 -> 0.12904968 | R38: =R6/Q6-1 -> 0.05978001 | S38: =S6/R6-1 -> 0.0081227437
B39: America Growth | E39: =+E7/C7-1 -> #DIV/0! | F39: =+F7/D7-1 -> #DIV/0! | G39: =+G7/E7-1 -> 0.094808126 | H39: =+H7/F7-1 -> 0.0546875 | I39: =+I7/G7-1 -> 0.089347079 | M39: =M7/L7-1 -> 0.17201965 | N39: =N7/M7-1 -> -0.22704925 | O39: =O7/N7-1 -> 0.52033368 | P39: =P7/O7-1 -> 0.46639232 | Q39: =Q7/P7-1 -> 0.21234799 | R39: =R7/Q7-1 -> 0.10532407 | S39: =S7/R7-1 -> 0.073298429
B40: Other Growth | E40: =+E8/C8-1 -> #DIV/0! | F40: =+F8/D8-1 -> #DIV/0! | G40: =+G8/E8-1 -> 0.16398714 | H40: =+H8/F8-1 -> 0.060126582 | I40: =+I8/G8-1 -> -0.08839779 | M40: =M8/L8-1 -> 0.11008326 | N40: =N8/M8-1 -> -0.098333333 | O40: =O8/N8-1 -> 0.44177449 | P40: =P8/O8-1 -> 0.32692308 | Q40: =Q8/P8-1 -> 0.44444444 | R40: =R8/Q8-1 -> 1.09699 | S40: =S8/R8-1 -> 0.11164274
B41: Leather Goods and Saddlery | E41: =E9/C9-1 -> 0.15647482 | F41: =F9/D9-1 -> 0.17166606 | G41: =G9/E9-1 -> 0.11290824 | H41: =H9/F9-1 -> 0.077112893 | I41: =I9/G9-1 -> 0.051145892 | J41: =J9/H9-1 -> -1 | M41: =M9/L9-1 -> 0.14717742 | N41: =N9/M9-1 -> -0.060046866 | O41: =O9/N9-1 -> 0.27485198 | P41: =P9/O9-1 -> 0.21315082 | Q41: =Q9/P9-1 -> 0.11767076 | R41: =R9/Q9-1 -> 0.16405264 | S41: =S9/R9-1 -> 0.094935729
B42: Ready to Wear and Accesoires | E42: =E10/C10-1 -> 0.12486993 | F42: =F10/D10-1 -> 0.14614205 | G42: =G10/E10-1 -> 0.043015726 | H42: =H10/F10-1 -> 0.01203745 | I42: =I10/G10-1 -> -0.025277162 | J42: =J10/H10-1 -> -1 | M42: =M10/L10-1 -> 0.20152672 | N42: =N10/M10-1 -> -0.10482846 | O42: =O10/N10-1 -> 0.5748758 | P42: =P10/O10-1 -> 0.42045967 | Q42: =Q10/P10-1 -> 0.23064721 | R42: =R10/Q10-1 -> 0.13560196 | S42: =S10/R10-1 -> 0.027241771
...

Sheet Quarters
A1: Main
C2: Q124 | D2: Q224 | E2: Q324 | F2: Q424 | G2: Q125 | H2: Q225 | I2: Q325 | J2: Q425 | K2: Q126 | L2: Q226 | M2: Q326 | N2: Q426
B3: France Revenue | C3: 312 | D3: =+Model!E3-Quarters!C3 -> 368 | E3: 365 | G3: 357 | H3: =+Model!G3-Quarters!G3 -> 383 | I3: 403 | K3: 347 | L3: =+Model!I3-Quarters!K3 -> 406
B4: Europe Revenue | C4: 444 | D4: =+Model!E4-Quarters!C4 -> 526 | E4: 584 | G4: 501 | H4: =+Model!G4-Quarters!G4 -> 587 | I4: 633 | K4: 538 | L4: =+Model!I4-Quarters!K4 -> 627
B5: Japan Revenue | C5: 357 | D5: =+Model!E5-Quarters!C5 -> 336 | E5: 360 | G5: 421 | H5: =+Model!G5-Quarters!G5 -> 394 | I5: 389 | K5: 404 | L5: =+Model!I5-Quarters!K5 -> 394
B6: APAC Revenue | C6: 1920 | D6: =+Model!E6-Quarters!C6 -> 1601 | E6: 1584 | G6: 1971 | H6: =+Model!G6-Quarters!G6 -> 1603 | I6: 1589 | K6: 1881 | L6: =+Model!I6-Quarters!K6 -> 1652
B7: Americas Revenue | C7: 614 | D7: =+Model!E7-Quarters!C7 -> 715 | E7: 666 | G7: 695 | H7: =+Model!G7-Quarters!G7 -> 760 | I7: 714 | K7: 739 | L7: =+Model!I7-Quarters!K7 -> 846
B8: Other (Middle East) | C8: 158 | D8: =+Model!E8-Quarters!C8 -> 153 | E8: 145 | G8: 185 | H8: =+Model!G8-Quarters!G8 -> 177 | I8: 154 | K8: 160 | L8: =+Model!I8-Quarters!K8 -> 170
B9: Leather Goods & Saddlery | C9: 1628 | D9: =+Model!E9-Quarters!C9 -> 1587 | E9: 1573 | G9: 1813 | H9: =+Model!G9-Quarters!G9 -> 1765 | I9: 1700 | K9: 1849 | L9: =+Model!I9-Quarters!K9 -> 1912
B10: Ready-to-Wear & Accessoires | C10: 1061 | D10: =+Model!E10-Quarters!C10 -> 1101 | E10: 1134 | G10: 1149 | H10: =+Model!G10-Quarters!G10 -> 1106 | I10: 1157 | K10: 1076 | L10: =+Model!I10-Quarters!K10 -> 1122
B11: Silk and Textiles | C11: 242 | D11: =+Model!E11-Quarters!C11 -> 194 | E11: 210 | G11: 256 | H11: =+Model!G11-Quarters!G11 -> 191 | I11: 209 | K11: 257 | L11: =+Model!I11-Quarters!K11 -> 212
B12: Others | C12: 505 | D12: =+Model!E12-Quarters!C12 -> 462 | E12: 455 | G12: 544 | H12: =+Model!G12-Quarters!G12 -> 512 | I12: 484 | K12: 540 | L12: =+Model!I12-Quarters!K12 -> 525
B13: Perfume & Beauty | C13: 130 | D13: =+Model!E13-Quarters!C13 -> 129 | E13: 129 | G13: 129 | H13: =+Model!G13-Quarters!G13 -> 119 | I13: 118 | K13: 127 | L13: =+Model!I13-Quarters!K13 -> 106
B14: Watches | C14: 166 | D14: =+Model!E14-Quarters!C14 -> 142 | E14: 126 | G14: 151 | H14: =+Model!G14-Quarters!G14 -> 130 | I14: 131 | K14: 135 | L14: =+Model!I14-Quarters!K14 -> 134
B15: Other products | C15: 74 | D15: =+Model!E15-Quarters!C15 -> 83 | E15: 76 | G15: 87 | H15: =+Model!G15-Quarters!G15 -> 81 | I15: 82 | K15: 86 | L15: =+Model!I15-Quarters!K15 -> 82
B16: Total Revenue | C16: =+SUM(C9:C15) -> 3806 | D16: =+SUM(D9:D15) -> 3698 | E16: 3704 | F16: =+SUM(F9:F15) -> 0 | G16: =+SUM(G9:G15) -> 4129 | H16: =+Model!G16-Quarters!G16 -> 3905 | I16: 3881 | K16: 4070 | L16: =+Model!I16-Quarters!K16 -> 4093
B18: France Growth | G18: =+G3/C3-1 -> 0.14423077 | H18: =+H3/D3-1 -> 0.04076087 | I18: =+I3/E3-1 -> 0.10410959 | J18: =+J3/F3-1 -> #DIV/0! | K18: =+K3/G3-1 -> -0.028011204 | L18: =+L3/H3-1 -> 0.060052219
B19: Europe Growth | G19: =+G4/C4-1 -> 0.12837838 | H19: =+H4/D4-1 -> 0.11596958 | I19: =+I4/E4-1 -> 0.08390411 | J19: =+J4/F4-1 -> #DIV/0! | K19: =+K4/G4-1 -> 0.073852295 | L19: =+L4/H4-1 -> 0.068143101
B20: Japan Growth | G20: =+G5/C5-1 -> 0.17927171 | H20: =+H5/D5-1 -> 0.17261905 | I20: =+I5/E5-1 -> 0.080555556 | J20: =+J5/F5-1 -> #DIV/0! | K20: =+K5/G5-1 -> -0.040380048 | L20: =+L5/H5-1 -> 0
B21: APAC Growth | G21: =+G6/C6-1 -> 0.0265625 | H21: =+H6/D6-1 -> 0.0012492192 | I21: =+I6/E6-1 -> 0.0031565657 | J21: =+J6/F6-1 -> #DIV/0! | K21: =+K6/G6-1 -> -0.0456621 | L21: =+L6/H6-1 -> 0.030567686
B22: Americas Growth | G22: =+G7/C7-1 -> 0.13192182 | H22: =+H7/D7-1 -> 0.062937063 | I22: =+I7/E7-1 -> 0.072072072 | J22: =+J7/F7-1 -> #DIV/0! | K22: =+K7/G7-1 -> 0.063309353 | L22: =+L7/H7-1 -> 0.11315789
B23: Middle East Growth | G23: =+G8/C8-1 -> 0.17088608 | H23: =+H8/D8-1 -> 0.15686275 | I23: =+I8/E8-1 -> 0.062068966 | J23: =+J8/F8-1 -> #DIV/0! | K23: =+K8/G8-1 -> -0.13513514 | L23: =+L8/H8-1 -> -0.039548023
B24: Leather Goods Growth | G24: =+G9/C9-1 -> 0.11363636 | H24: =+H9/D9-1 -> 0.11216131 | I24: =+I9/E9-1 -> 0.080737444 | J24: =+J9/F9-1 -> #DIV/0! | K24: =+K9/G9-1 -> 0.019856591 | L24: =+L9/H9-1 -> 0.083286119
B25: Ready to Wear Growth | G25: =+G10/C10-1 -> 0.082940622 | H25: =+H10/D10-1 -> 0.0045413261 | I25: =+I10/E10-1 -> 0.020282187 | J25: =+J10/F10-1 -> #DIV/0! | K25: =+K10/G10-1 -> -0.063533507 | L25: =+L10/H10-1 -> 0.014466546
B26: Silk & Textiles Growth | G26: =+G11/C11-1 -> 0.05785124 | H26: =+H11/D11-1 -> -0.015463918 | I26: =+I11/E11-1 -> -0.0047619048 | J26: =+J11/F11-1 -> #DIV/0! | K26: =+K11/G11-1 -> 0.00390625 | L26: =+L11/H11-1 -> 0.10994764
B27: Others Growth | G27: =+G12/C12-1 -> 0.077227723 | H27: =+H12/D12-1 -> 0.10822511 | I27: =+I12/E12-1 -> 0.063736264 | J27: =+J12/F12-1 -> #DIV/0! | K27: =+K12/G12-1 -> -0.0073529412 | L27: =+L12/H12-1 -> 0.025390625
B28: Beauty Growth | G28: =+G13/C13-1 -> -0.0076923077 | H28: =+H13/D13-1 -> -0.07751938 | I28: =+I13/E13-1 -> -0.085271318 | J28: =+J13/F13-1 -> #DIV/0! | K28: =+K13/G13-1 -> -0.015503876 | L28: =+L13/H13-1 -> -0.1092437
B29: Watches Growth | G29: =+G14/C14-1 -> -0.090361446 | H29: =+H14/D14-1 -> -0.084507042 | I29: =+I14/E14-1 -> 0.03968254 | J29: =+J14/F14-1 -> #DIV/0! | K29: =+K14/G14-1 -> -0.10596026 | L29: =+L14/H14-1 -> 0.030769231
... B31: Revenue Growth | G31: =+G16/C16-1 -> 0.084866001 | H31: =+H16/D16-1 -> 0.055976203 | I31: =+I16/E16-1 -> 0.047786177 | J31: =+J16/F16-1 -> #DIV/0! | K31: =+K16/G16-1 -> -0.014289174 | L31: =+L16/H16-1 -> 0.048143406

Sheet Ratios
A1: Main
B2: Ratios | C2: 18 | D2: =+C2+1 -> 19 | E2: =+D2+1 -> 20 | F2: =+E2+1 -> 21 | G2: =+F2+1 -> 22 | H2: =+G2+1 -> 23 | I2: =+H2+1 -> 24 | J2: =+I2+1 -> 25
B3: Price | C3: 477.6 | D3: 671 | E3: 884.4 | F3: 1542 | G3: 1473 | H3: 1897.4 | I3: 2237 | J3: 2146
B4: Shares o/s | C4: =+Model!L33 -> 104.23323 | D4: =+Model!M33 -> 104.23323 | E4: =+Model!N33 -> 104.43077 | F4: =+Model!O33 -> 104.62333 | G4: =+Model!P33 -> 104.56473 | H4: =+Model!Q33 -> 104.64808 | I4: =+Model!R33 -> 104.64808 | J4: =+Model!S33 -> 105.56941
B5: Market Cap | C5: =+C3*C4 -> 49781.792 | D5: =+D3*D4 -> 69940.499 | E5: =+E3*E4 -> 92358.575 | F5: =+F3*F4 -> 161329.17 | G5: =+G3*G4 -> 154023.85 | H5: =+H3*H4 -> 198559.27 | I5: =+I3*I4 -> 234097.75 | J5: =+J3*J4 -> 226551.96
B6: Net Debt | C6: =+Model!L84+Model!L91-Model!L70 -> -3429.1 | D6: =+Model!M84+Model!M91-Model!M70 -> -4334.1 | E6: =+Model!N84+Model!N91-Model!N70 -> -4690 | F6: =+Model!O84+Model!O91-Model!O70 -> -6671 | G6: =+Model!P84+Model!P91-Model!P70 -> -9188 | H6: =+Model!Q84+Model!Q91-Model!Q70 -> -10574 | I6: =+Model!R84+Model!R91-Model!R70 -> -11581 | J6: =+Model!S84+Model!S91-Model!S70 -> -12205
B7: EV | C7: =+C5+C6 -> 46352.692 | D7: =+D5+D6 -> 65606.399 | E7: =+E5+E6 -> 87668.575 | F7: =+F5+F6 -> 154658.17 | G7: =+G5+G6 -> 144835.85 | H7: =+H5+H6 -> 187985.27 | I7: =+I5+I6 -> 222516.75 | J7: =+J5+J6 -> 214346.96
A9: x | B9: Value Driver
B10: Capital Emloyed | C10: =+Model!L64+Model!L66+Model!L67+Model!L68+Model!L69-Model!L95 -> 3642.2 | D10: =+Model!M64+Model!M66+Model!M67+Model!M68+Model!M69-Model!M95 -> 3883.8 | E10: =+Model!N64+Model!N66+Model!N67+Model!N68+Model!N69-Model!N95 -> 4579 | F10: =+Model!O64+Model!O66+Model!O67+Model!O68+Model!O69-Model!O95 -> 5168 | G10: =+Model!P64+Model!P66+Model!P67+Model!P68+Model!P69-Model!P95 -> 5680 | H10: =+Model!Q64+Model!Q66+Model!Q67+Model!Q68+Model!Q69-Model!Q95 -> 6529 | I10: =+Model!R64+Model!R66+Model!R67+Model!R68+Model!R69-Model!R95 -> 7811 | J10: =+Model!S64+Model!S66+Model!S67+Model!S68+Model!S69-Model!S95 -> 8805 | L10: =Long Term Assets + Working Capital (Exclusive of cash)-Accounts Payables
B11: Invested Capital | C11: =+Model!L54+Model!L55+Model!L57+Model!L58+Model!L62+Model!L65+Model!L66+Model!L67+Model!L68+Model!L69-Model!L95 -> 3171.9 | D11: =+Model!M54+Model!M55+Model!M57+Model!M58+Model!M62+Model!M65+Model!M66+Model!M67+Model!M68+Model!M69-Model!M95 -> 3556.8 | E11: =+Model!N54+Model!N55+Model!N57+Model!N58+Model!N62+Model!N65+Model!N66+Model!N67+Model!N68+Model!N69-Model!N95 -> 3925 | F11: =+Model!O54+Model!O55+Model!O57+Model!O58+Model!O62+Model!O65+Model!O66+Model!O67+Model!O68+Model!O69-Model!O95 -> 4351 | G11: =+Model!P54+Model!P55+Model!P57+Model!P58+Model!P62+Model!P65+Model!P66+Model!P67+Model!P68+Model!P69-Model!P95 -> 4610 | H11: =+Model!Q54+Model!Q55+Model!Q57+Model!Q58+Model!Q62+Model!Q65+Model!Q66+Model!Q67+Model!Q68+Model!Q69-Model!Q95 -> 5779 | I11: =+Model!R54+Model!R55+Model!R57+Model!R58+Model!R62+Model!R65+Model!R66+Model!R67+Model!R68+Model!R69-Model!R95 -> 7375 | J11: =+Model!S54+Model!S55+Model!S57+Model!S58+Model!S62+Model!S65+Model!S66+Model!S67+Model!S68+Model!S69-Model!S95 -> 7779 | L11: =Net Working Capital + PP&E + Other Net Operating Assets (net of Liabilties) + (Intangibles)
B12: Invested Capital (exl. Intangibles)
B13: Total Funds Invested | L13: Invested Capital + Non-Operating Assets
B14: NOPAT | L14: EBITA * (1-Marginal Tax Rate)
B15: Net Investment | L15: =Invested Capital (t+1)-Invested Capital (t)
B16: FCF | L16: =NOPAT + non-cash Expenses - Investments in Invested Capital
B17: Investment Rate | L17: =Net Investment/NOPAT
B18: Economic Profit | L18: =Invested Capital *(ROIC-WACC)
A20: x | B20: Efficency-Ratios
B21: Capital Turnover | L21: =Revenue/Total Assets
B22: Return on Equity (ROE) | C22: =Model!L28/Model!L82 -> 0.25765795 | D22: =Model!M28/Model!M82 -> 0.23347375 | E22: =Model!N28/Model!N82 -> 0.18804113 | F22: =Model!O28/Model!O82 -> 0.26070328 | G22: =Model!P28/Model!P82 -> 0.27133339 | H22: =Model!Q28/Model!Q82 -> 0.2842486 | I22: =Model!R28/Model!R82 -> 0.26710511 | J22: =Model!S28/Model!S82 -> 0.24193548 | L22: =Net Income/Book Value of Equity
B23: Return on Capital Employed (ROCE) | C23: =+Model!L23/Ratios!C10 -> 0.58426226 | D23: =+Model!M23/Ratios!D10 -> 0.60221948 | E23: =+Model!N23/Ratios!E10 -> 0.45271893 | F23: =+Model!O23/Ratios!F10 -> 0.68304954 | G23: =+Model!P23/Ratios!G10 -> 0.82693662 | H23: =+Model!Q23/Ratios!H10 -> 0.86536989 | I23: =+Model!R23/Ratios!I10 -> 0.78709512 | J23: =+Model!S23/Ratios!J10 -> 0.74605338 | L23: =EBIT/Capital Employed
B24: Return on Capital Invested (ROIC) | C24: =+Model!L23*(1-Model!L52)/Ratios!C11 -> 0.45262918 | D24: =+Model!M23*(1-Model!M52)/Ratios!D11 -> 0.44006061 | E24: =+Model!N23*(1-Model!N52)/Ratios!E11 -> 0.36521492 | F24: =+Model!O23*(1-Model!O52)/Ratios!F11 -> 0.57150653 | G24: =+Model!P23*(1-Model!P52)/Ratios!G11 -> 0.73200514 | H24: =+Model!Q23*(1-Model!Q52)/Ratios!H11 -> 0.70597042 | I24: =+Model!R23*(1-Model!R52)/Ratios!I11 -> 0.59446649 | J24: =+Model!S23*(1-Model!S52)/Ratios!J11 -> 0.56242864 | L24: =NOPAT/Invested Capital
B25: ROIC without Intangibles | L25: =NOPAT/(Invested Capital exclusive of Intangibles)
B26: Decomposed ROIC | L26: = ROIC = (1-operating cash tax)* (EBITA/Revenues) * (Revenue/Invested Capital)
B27: Return on Assets (ROA) | C27: =+Model!L21/Model!L72 -> 0.24267122 | D27: =+Model!M21/Model!M72 -> 0.23669669 | E27: =+Model!N21/Model!N72 -> 0.17929224 | F27: =+Model!O21/Model!O72 -> 0.25491046 | G27: =+Model!P21/Model!P72 -> 0.26899948 | H27: =+Model!Q21/Model!Q72 -> 0.27631064 | I27: =+Model!R21/Model!R72 -> 0.26635474 | J27: =+Model!S21/Model!S72 -> 0.2700958
B29: Retention Rate | L29: =1 - Dividends/Net Income
B30: Reinvestment Rate | L30: =Net CapEx + Change in WC / EBIT * (1-t)
B31: Epected Growth in Net Income | L31: =ROE * Retention Rate
B32: Expected Growth in NOPAT | L32: =ROIC * Reinvestment Rate
A34: x | B34: Finacial Stability Ratios
B35: Equity/Debt Ratio | L35: =Book Value of Equtiy/Book Value of Debt
B36: Gearing | L36: =(Debt - Cash (Net Debt))/Book Value of Equity
B37: Interest Coverage Ratio | L37: =EBIT/Interest Expenses
B38: Net Debt / EBITDA | L38: =Net Debt/EBITDA
B39: Cash Burn Rate | L39: =Book Value of Equity/Absolute value of Loss
A41: x | B41: WC-Managment Ratios
B42: Debitor-Duration | L42: =Accounts Receivables/Revenue*360
B43: Creditor-Duration | L43: =Accounts Payable/Revenue*360
B44: Inventory Intensity | L44: =Inventory/Balance Sheet Total
B45: Invetory Turnover | L45: =Cogs/Inventory
...

Sheet DCF
A1: Main | B1: Hermés DCF
B3: Ticker | E3: =+Main!K2 -> 1553 | G3: Share Price | L3: Share Price | O3: =+J3 -> 0
B4: Date | E4: =+TODAY() -> 46232 | G4: Fair Share Price | J4: =V62 -> #DIV/0! | L4: Scneario DCF Price | O4: =+J15+O15+T15 -> 0
B5: End of FY | E5: 46022 | G5: Implied Upside | J5: =J4/J3-1 -> #DIV/0! | L5: Implied Upside | O5: =O4/O3-1 -> #DIV/0!
A7: x | B7: Assumptions
B9: Switches | G9: Conservative Case | L9: Base Case | Q9: Optimistic Case
B10: Assuptions | G10: Assuptions | I10: Year | J10: Metic | L10: Assuptions | N10: Year | O10: Metic | Q10: Assuptions | S10: Year | T10: Metic
B11: Revenue | E11: 2 | G11: Revenue | L11: Revenue | Q11: Revenue
B12: EBIT | E12: 2 | G12: EBIT | L12: EBIT | Q12: EBIT
B13: WACC | E13: 2 | G13: Implied Share Price
B14: TGR | E14: 2 | G14: Probability | L14: Probability | Q14: Probability
B15: ROIC | E15: 2 | G15: Implied Share Price * p | L15: Implied Share Price * p | Q15: Implied Share Price * p
B17: Valuation
B18: WACC | E18: =CHOOSE(E13,J18,O18,T18) -> 0 | G18: WACC | L18: WACC | Q18: WACC
B19: TGR | E19: =CHOOSE(E14,J19,O19,T19) -> 0 | G19: TGR | L19: TGR | Q19: TGR
B20: RONIC | E20: =CHOOSE(E15,J20,O20,T20) -> 0 | G20: RONIC | L20: RONIC | Q20: RONIC
A24: x | B24: Model | G24: 19 | H24: =G24+1 -> 20 | I24: =H24+1 -> 21 | J24: =I24+1 -> 22 | K24: =J24+1 -> 23 | L24: =K24+1 -> 24 | M24: =L24+1 -> 25 | N24: =M24+1 -> 26 | O24: =N24+1 -> 27 | ... V24: =U24+1 -> 34
B25: Revenue | G25: =+Model!M16 -> 6883.4 | H25: =+Model!N16 -> 6389 | I25: =+Model!O16 -> 8982 | J25: =+Model!P16 -> 11602 | K25: =+Model!Q16 -> 13427 | L25: =+Model!R16 -> 15170 | M25: =L25*(1+M26) -> 15170 | N25: =M25*(1+N26) -> 15170 | O25: =N25*(1+O26) -> 15170 | P25: =O25*(1+P26) -> 15170 | Q25: =P25*(1+Q26) -> 15170 | R25: =Q25*(1+R26) -> 15170 | S25: =R25*(1+S26) -> 15170 | T25: =S25*(1+T26) -> 15170 | ... V25: =U25*(1+V26) -> 15170
B26: Growth (%) | H26: =H25/G25-1 -> -0.07182497 | I26: =I25/H25-1 -> 0.40585381 | J26: =J25/I25-1 -> 0.2916945 | K26: =K25/J25-1 -> 0.15730047 | L26: =L25/K25-1 -> 0.12981306 | M26: {=OFFSET(M26,$E$11,,)} -> 0 | N26: {=OFFSET(N26,$E$11,,)} -> 0 | O26: {=OFFSET(O26,$E$11,,)} -> 0 | P26: {=OFFSET(P26,$E$11,,)} -> 0 | Q26: {=OFFSET(Q26,$E$11,,)} -> 0 | R26: {=OFFSET(R26,$E$11,,)} -> 0 | S26: {=OFFSET(S26,$E$11,,)} -> 0 | T26: {=OFFSET(T26,$E$11,,)} -> 0 | ... V26: {=OFFSET(V26,$E$11,,)} -> 0
B27: Conservative Case
B28: Base Case
B29: Optimisitic Case
B31: EBIT | G31: =+Model!M23 -> 2338.9 | H31: =+Model!N23 -> 2073 | I31: =+Model!O23 -> 3530 | J31: =+Model!P23 -> 4697 | K31: =+Model!Q23 -> 5650 | L31: =+Model!R23 -> 6148 | M31: =M32*M25 -> 0 | N31: =N32*N25 -> 0 | O31: =O32*O25 -> 0 | P31: =P32*P25 -> 0 | Q31: =Q32*Q25 -> 0 | R31: =R32*R25 -> 0 | S31: =S32*S25 -> 0 | T31: =T32*T25 -> 0 | ... V31: =V32*V25 -> 0
B32: % of Sales | G32: =G31/G25 -> 0.33978848 | H32: =H31/H25 -> 0.32446392 | I32: =I31/I25 -> 0.39300824 | J32: =J31/J25 -> 0.40484399 | K32: =K31/K25 -> 0.42079392 | L32: =L31/L25 -> 0.40527357 | M32: {=OFFSET(M32,$E$12,,)} -> 0 | N32: {=OFFSET(N32,$E$12,,)} -> 0 | O32: {=OFFSET(O32,$E$12,,)} -> 0 | P32: {=OFFSET(P32,$E$12,,)} -> 0 | Q32: {=OFFSET(Q32,$E$12,,)} -> 0 | R32: {=OFFSET(R32,$E$12,,)} -> 0 | S32: {=OFFSET(S32,$E$12,,)} -> 0 | T32: {=OFFSET(T32,$E$12,,)} -> 0 | ... V32: {=OFFSET(V32,$E$12,,)} -> 0
B33: Conservative Case
B34: Base Case
B35: Optimisitic Case
B37: Taxes | G37: =+Model!M26 -> 751 | H37: =+Model!N26 -> 613 | I37: =+Model!O26 -> 1015 | J37: =+Model!P26 -> 1305 | K37: =+Model!Q26 -> 1623 | L37: =+Model!R26 -> 1845 | M37: =M38*M31 -> 0 | N37: =N38*N31 -> 0 | O37: =O38*O31 -> 0 | P37: =P38*P31 -> 0 | Q37: =Q38*Q31 -> 0 | R37: =R38*R31 -> 0 | S37: =S38*S31 -> 0 | T37: =T38*T31 -> 0 | ... V37: =V38*V31 -> 0
B38: Tax Rate (%) | G38: =G37/G31 -> 0.32109111 | H38: =H37/H31 -> 0.29570671 | I38: =I37/I31 -> 0.28753541 | J38: =J37/J31 -> 0.27783692 | K38: =K37/K31 -> 0.28725664 | L38: =L37/L31 -> 0.30009759
B40: Nopat | G40: =G31-G37 -> 1587.9 | H40: =H31-H37 -> 1460 | I40: =I31-I37 -> 2515 | J40: =J31-J37 -> 3392 | K40: =K31-K37 -> 4027 | L40: =L31-L37 -> 4303 | M40: =M31-M37 -> 0 | N40: =N31-N37 -> 0 | ... V40: =V31-V37 -> 0
B42: D&A and other non-cash Expenses | G42: =+Model!M104 -> 447.7 | H42: =+Model!N104 -> 514 | I42: =+Model!O104 -> 563 | J42: =+Model!P104 -> 730 | K42: =+Model!Q104 -> 772 | L42: =+Model!R104 -> 844 | M42: =M43*M25 -> 0 | N42: =N43*N25 -> 0 | O42: =O43*O25 -> 0 | P42: =P43*P25 -> 0 | Q42: =Q43*Q25 -> 0 | R42: =R43*R25 -> 0 | S42: =S43*S25 -> 0 | T42: =T43*T25 -> 0 | ... V42: =V43*V25 -> 0
B43: % of Sales | G43: =G42/G25 -> 0.065040532 | H43: =H42/H25 -> 0.080450775 | I43: =I42/I25 -> 0.062680917 | J43: =J42/J25 -> 0.062920186 | K43: =K42/K25 -> 0.05749609 | L43: =L42/L25 -> 0.055636124
B45: CapEx | G45: =+Model!M116 -> -478 | H45: =+Model!N116 -> -448 | I45: =+Model!O116 -> -532 | J45: =+Model!P116 -> -518 | K45: =+Model!Q116 -> -859 | L45: =+Model!R116 -> -1067 | M45: =M46*M25 -> 0 | N45: =N46*N25 -> 0 | O45: =O46*O25 -> 0 | P45: =P46*P25 -> 0 | Q45: =Q46*Q25 -> 0 | R45: =R46*R25 -> 0 | S45: =S46*S25 -> 0 | T45: =T46*T25 -> 0 | ... V45: =V46*V25 -> 0
B46: % of Sales | G46: =G45/G25 -> -0.069442427 | H46: =H45/H25 -> -0.07012052 | I46: =I45/I25 -> -0.05922957 | J46: =J45/J25 -> -0.044647475 | K46: =K45/K25 -> -0.063975572 | L46: =L45/L25 -> -0.07033619
B48: Change in WC | G48: =+Model!M114 -> 23.9 | H48: =+Model!N114 -> -350 | I48: =+Model!O114 -> 346 | J48: =+Model!P114 -> 73 | K48: =+Model!Q114 -> -794 | L48: =+Model!R114 -> -239 | M48: =M49*M25 -> 0 | N48: =N49*N25 -> 0 | O48: =O49*O25 -> 0 | P48: =P49*P25 -> 0 | Q48: =Q49*Q25 -> 0 | R48: =R49*R25 -> 0 | S48: =S49*S25 -> 0 | T48: =T49*T25 -> 0 | ... V48: =V49*V25 -> 0
B49: % of Sales | G49: =G48/G25 -> 0.0034721213 | H49: =H48/H25 -> -0.054781656 | I49: =I48/I25 -> 0.038521487 | J49: =J48/J25 -> 0.0062920186 | K49: =K48/K25 -> -0.05913458 | L49: =L48/L25 -> -0.015754779
B51: Unlevered Free Cashflow | G51: =G40+G42+G45+G48 -> 1581.5 | H51: =H40+H42+H45+H48 -> 1176 | I51: =I40+I42+I45+I48 -> 2892 | J51: =J40+J42+J45+J48 -> 3677 | K51: =K40+K42+K45+K48 -> 3146 | L51: =L40+L42+L45+L48 -> 3841 | M51: =M40+M42+M45+M48 -> 0 | N51: =N40+N42+N45+N48 -> 0 | ... V51: =V40+V42+V45+V48 -> 0
B52: Present Value of unlevered FC | M52: =(M51/(1+$E$18)^M53)*M53 -> 0 | N52: =N51/(1+$E$18)^N53 -> 0 | O52: =O51/(1+$E$18)^O53 -> 0 | P52: =P51/(1+$E$18)^P53 -> 0 | Q52: =Q51/(1+$E$18)^Q53 -> 0 | R52: =R51/(1+$E$18)^R53 -> 0 | S52: =S51/(1+$E$18)^S53 -> 0 | T52: =T51/(1+$E$18)^T53 -> 0 | U52: =U51/(1+$E$18)^U53 -> 0 | V52: =V51/(1+$E$18)^V53 -> 0
B53: Discount Period | M53: =YEARFRAC(E4,E5) -> 0.58055556 | N53: =M53+1 -> 1.5805556 | O53: =N53+1 -> 2.5805556 | P53: =O53+1 -> 3.5805556 | Q53: =P53+1 -> 4.5805556 | R53: =Q53+1 -> 5.5805556 | S53: =R53+1 -> 6.5805556 | T53: =S53+1 -> 7.5805556 | U53: =T53+1 -> 8.5805556 | V53: =U53+1 -> 9.5805556
B54: Sum of Present Value | V54: =SUM(M52:V52) -> 0
...
