Workbook

Sheet Main
A1: Scandivian Tobacco
A2: numbers in mio DKK | I2: Price | J2: 71.6
I3: Shares | J3: 78.62 | K3: Q226
B4: IR | I4: MC | J4: =+J2*J3 -> 5629.192
B5: STG.CO | I5: Cash | J5: 61.6 | K5: Q226
I6: Debt | J6: =3690.9+1251 -> 4941.9 | K6: Q226
B7: Sgments | D7: Brands | I7: EV | J7: =+J4-J5+J6 -> 10509.492
B8: Handmade cigars | D8: Cao, Cohiba, La Gloria Cubana, Petit, etc.
B9: Machine-rolled cigars | D9: Balmoral,Cubero, La Paz, Panter, etc.
B10: Next Gen Prod | D10: XQS, Ström, Ace, Grit | I10: HQ: Denmark, Genftote
B11: Other | D11: Smoking and Pipe Tobacco, Accessoires | I11: CEO: Niels Frederiksen
B13: Notes | I13: Employee Count (2024)
B14: IPO 2016 | I14: 10219
B15: Key Brands Europe: La Paz, Panter, Meharis, Signature
B16: Key Brands North America: Tiedemanns, Cao, Cohiba, Macunado | I16: Founded 1750
B17: Captain Black, Punch
B18: North America Online & Retail Brands: diesel, Mark Twain, Ave Maria
B19: History
B20: Merged in 2010 with Swedish Match Cigars
B22: FY25 Guidance: 9.1 - 9.2 billion DKK, 19,5%-20,5% OM, FCF: 0,8-1 bil
B35: Value Chain

Sheet Model
A1: Main
C2: Q124 | D2: Q224 | E2: Q324 | F2: Q424 | G2: Q125 | H2: Q225 | I2: Q325 | J2: Q425 | K2: Q126 | L2: Q226 | M2: Q326 | N2: Q426 | P2: FY17 | Q2: FY18 | R2: FY19 | S2: FY20 | T2: FY21 | U2: FY22 | V2: FY23 | W2: FY24 | X2: FY25
B3: Americas | G3: 618.7 | H3: 780 | K3: 575 | L3: 793 | P3: 2933.4 | Q3: 3443.2 | R3: 3639.9 | S3: 4138.8 | T3: 4328.2 | U3: 4715.3 | V3: 4745.8 | W3: 4911.9 | X3: 4538.1
B4: Europe | G4: 687.3 | H4: 730 | K4: 630 | L4: 746 | P4: 2843.5 | Q4: 2726.5 | R4: 2589.7 | S4: 3462.8 | T4: 3445.4 | U4: 3418.2 | V4: 3459.6 | W4: 3756.2 | X4: 3933.6
B5: RoW | G5: 667.7 | H5: 851 | K5: 655 | L5: 795 | P5: 686 | Q5: 547.8 | R5: 489.4 | S5: 404.3 | T5: 459.1 | U5: 628.7 | V5: 525.5 | W5: 534 | X5: 564
B6: Handmade cigars | G6: 672.6 | K6: 660.2 | L6: 876 | P6: 1920.7 | Q6: 2375.7 | R6: 2562.5 | S6: 2878.7 | T6: 3035 | U6: 3302.2 | V6: 3235.9 | W6: 3299.5 | X6: 3164.1
B7: Machine-rolled cigars | G7: 1011.2 | K7: 956.2 | L7: 1138 | P7: 2491.5 | Q7: 2366.7 | R7: 2223.1 | S7: 2894.8 | T7: 2918.8 | U7: 3009.8 | V7: 4294.5 | W7: 4431.2 | X7: 4541.5
B8: Next Gen Prod | G8: 79.7 | K8: 64 | L8: 115 | P8: =544.3+597.9 -> 1142.2 | Q8: =478.2+561.6 -> 1039.8 | R8: 1005.4 | S8: 1144.2 | T8: 1206.2 | U8: 1279.5 | V8: 193.3 | W8: 420.9 | X8: 428.2
B9: Other | G9: 210.2 | K9: 178.8 | L9: 205 | P9: 909.1 | Q9: 935.3 | R9: 928 | S9: 1088.2 | T9: 1072.6 | U9: 1170.7 | V9: 1007.2 | W9: 1050.5 | X9: 902
B10: Revenue | C10: 1948.3 | D10: 2365.8 | E10: 2430.5 | F10: =+W10-SUM(C10:E10) -> 2457.5 | G10: 1973.7 | H10: 2361.4 | I10: 2357.3 | J10: =+X10-SUM(G10:I10) -> 2343.3 | K10: 1859.2 | L10: 2334 | P10: 6463.5 | Q10: 6717.5 | R10: 6719 | S10: 8005.9 | T10: 8232.7 | U10: 8762.2 | V10: 8730.9 | W10: 9202.1 | X10: 9035.7
B11: COGS | C11: 1067.1 | D11: 1256.6 | E11: 1304.5 | F11: =+W11-SUM(C11:E11) -> 1295.4 | G11: 1107 | H11: 1298 | I11: 1307.1 | J11: =+X11-SUM(G11:I11) -> 1322.4 | K11: 1035.4 | L11: 1279 | P11: 3368.2 | Q11: 3516.6 | R11: 3576.5 | S11: 4293.7 | T11: 4119.6 | U11: 4454.9 | V11: 4526.8 | W11: 4923.6 | X11: 5034.5
B12: Gross Profit | C12: =+C10-C11 -> 881.2 | D12: =+D10-D11 -> 1109.2 | E12: =+E10-E11 -> 1126 | F12: =+F10-F11 -> 1162.1 | G12: =+G10-G11 -> 866.7 | H12: =+H10-H11 -> 1063.4 | I12: =+I10-I11 -> 1050.2 | J12: =+J10-J11 -> 1020.9 | ... L12: =+L10-L11 -> 1055 | P12: =+P10-P11 -> 3095.3 | Q12: =+Q10-Q11 -> 3200.9 | R12: =+R10-R11 -> 3142.5 | S12: =+S10-S11 -> 3712.2 | T12: =+T10-T11 -> 4113.1 | U12: =+U10-U11 -> 4307.3 | V12: =+V10-V11 -> 4204.1 | W12: =+W10-W11 -> 4278.5 | X12: =+X10-X11 -> 4001.2
B13: External Costs | C13: 295.7 | D13: 288.7 | E13: 293.8 | F13: =+W13-SUM(C13:E13) -> 312.6 | G13: 285.9 | H13: 277 | I13: 317.6 | J13: =+X13-SUM(G13:I13) -> 363.7 | K13: 232 | L13: 248 | P13: 1141.5 | Q13: 1206.5 | R13: 898.3 | S13: 1007.9 | T13: 1052.9 | U13: 1126.4 | V13: 1142.6 | W13: 1190.8 | X13: 1244.2
B14: Staff | C14: 254.3 | D14: 255.8 | E14: 272.9 | F14: =+W14-SUM(C14:E14) -> 274.2 | G14: 274.9 | H14: 294.2 | I14: 232.9 | J14: =+X14-SUM(G14:I14) -> 221.3 | K14: 302.4 | L14: 340.3 | P14: 735.5 | Q14: 905.7 | R14: 737.1 | S14: 878.4 | T14: 858.4 | U14: 910.9 | V14: 968 | W14: 1057.2 | X14: 1023.3
B15: Other Income | C15: 3.6 | D15: 15.8 | E15: 8.4 | F15: =+W15-SUM(C15:E15) -> 20.7 | G15: 11.1 | H15: 6.9 | I15: 18.9 | J15: =+X15-SUM(G15:I15) -> 20.4 | K15: 30.6 | L15: 48.6 | P15: 13.4 | Q15: 0 | R15: 5.9 | S15: 0 | T15: 31 | U15: 0 | V15: 12.2 | W15: 48.5 | X15: 57.3
B16: D&A | C16: =53.1+43.9+29.8 -> 126.8 | D16: =54.1+44.2+52.8 -> 151.1 | E16: =68.9+48.9+48.8 -> 166.6 | F16: =+W16-SUM(C16:E16) -> 254.3 | G16: =63+48.3+69.8 -> 181.1 | H16: =61.4+49+34.7 -> 145.1 | I16: =61.2+50.1+41.3 -> 152.6 | J16: =+X16-SUM(G16:I16) -> 170 | K16: =63.3+64+75.6 -> 202.9 | L16: =65.5+61.9+59.8 -> 187.2 | P16: =148.2+170.5 -> 318.7 | Q16: =127.1+224.1 -> 351.2 | R16: =215.1+187.3+133.4 -> 535.8 | S16: =238.1+167+435.2 -> 840.3 | T16: =202.7+161.2+54.7 -> 418.6 | U16: =183.8+168.5-35.3 -> 317 | V16: =201+174+92.4 -> 467.4 | W16: =236.3+183.5+279 -> 698.8 | X16: =252.1+197+199.7 -> 648.8
B17: Operating Income | C17: =+C12-SUM(C13:C14,C16)+C15 -> 208 | D17: =+D12-SUM(D13:D14,D16)+D15 -> 429.4 | E17: =+E12-SUM(E13:E14,E16)+E15 -> 401.1 | F17: =+F12-SUM(F13:F14,F16)+F15 -> 341.7 | G17: =+G12-SUM(G13:G14,G16)+G15 -> 135.9 | H17: =+H12-SUM(H13:H14,H16)+H15 -> 354 | I17: =+I12-SUM(I13:I14,I16)+I15 -> 366 | J17: =+J12-SUM(J13:J14,J16)+J15 -> 286.3 | ... L17: =+L12-SUM(L13:L14,L16)+L15 -> 328.1 | P17: =+P12-SUM(P13:P14,P16)+P15 -> 913 | Q17: =+Q12-SUM(Q13:Q14,Q16)+Q15 -> 737.5 | R17: =+R12-SUM(R13:R14,R16)+R15 -> 977.2 | S17: =+S12-SUM(S13:S14,S16)+S15 -> 985.6 | T17: =+T12-SUM(T13:T14,T16)+T15 -> 1814.2 | U17: =+U12-SUM(U13:U14,U16)+U15 -> 1953 | V17: =+V12-SUM(V13:V14,V16)+V15 -> 1638.3 | W17: =+W12-SUM(W13:W14,W16)+W15 -> 1380.2 | X17: =+X12-SUM(X13:X14,X16)+X15 -> 1142.2
B18: Income from subsidees | C18: 5.1 | D18: 8.3 | E18: 7.5 | F18: =+W18-SUM(C18:E18) -> 4.5 | G18: 3.9 | H18: 7.8 | I18: 6.7 | J18: =+X18-SUM(G18:I18) -> 4.8 | K18: 4.9 | L18: 6.6 | P18: 16.1 | Q18: 16.7 | R18: 16.7 | S18: 18.7 | T18: 31.5 | U18: 40.4 | V18: 29.4 | W18: 25.4 | X18: 23.2
B19: Financial Income | C19: 15 | D19: 16 | E19: 52.8 | F19: =+W19-SUM(C19:E19) -> 46.4 | G19: 16.1 | H19: 18.9 | I19: 8.5 | J19: =+X19-SUM(G19:I19) -> 27.8 | K19: 27.3 | L19: 31.6 | P19: 23.5 | Q19: 55 | R19: 46.6 | S19: 81.1 | T19: 75 | U19: 197.3 | V19: 184.6 | W19: 130.2 | X19: 71.3
B20: Financial Costs | C20: 69.2 | D20: 68.6 | E20: 78.4 | F20: =+W20-SUM(C20:E20) -> 100.3 | G20: 89 | H20: 85.9 | I20: 86.1 | J20: =+X20-SUM(G20:I20) -> 97.9 | K20: 93 | L20: 84.5 | P20: 100.9 | Q20: 92.4 | R20: 91.9 | S20: 134 | T20: 152.2 | U20: 334.2 | V20: 361.5 | W20: 316.5 | X20: 358.9
B21: Pretax Income | C21: =+C17+C18+C19-C20 -> 158.9 | D21: =+D17+D18+D19-D20 -> 385.1 | E21: =+E17+E18+E19-E20 -> 383 | F21: =+F17+F18+F19-F20 -> 292.3 | G21: =+G17+G18+G19-G20 -> 66.9 | H21: =+H17+H18+H19-H20 -> 294.8 | I21: =+I17+I18+I19-I20 -> 295.1 | J21: =+J17+J18+J19-J20 -> 221 | ... L21: =+L17+L18+L19-L20 -> 281.8 | P21: =+P17+P18+P19-P20 -> 851.7 | Q21: =+Q17+Q18+Q19-Q20 -> 716.8 | R21: =+R17+R18+R19-R20 -> 948.6 | S21: =+S17+S18+S19-S20 -> 951.4 | T21: =+T17+T18+T19-T20 -> 1768.5 | U21: =+U17+U18+U19-U20 -> 1856.5 | V21: =+V17+V18+V19-V20 -> 1490.8 | W21: =+W17+W18+W19-W20 -> 1219.3 | X21: =+X17+X18+X19-X20 -> 877.8
B22: Tax Expense | C22: 34.1 | D22: 88.3 | E22: 85.9 | F22: =+W22-SUM(C22:E22) -> 71.3 | G22: 15.4 | H22: 67.8 | I22: 67.8 | J22: =+X22-SUM(G22:I22) -> 57.4 | K22: 12.9 | L22: 64.9 | P22: 140.1 | Q22: 51.3 | R22: 200.9 | S22: 273.5 | T22: 377.9 | U22: 380.2 | V22: 308.4 | W22: 279.6 | X22: 208.4
B23: Net Income | C23: =+C21-C22 -> 124.8 | D23: =+D21-D22 -> 296.8 | E23: =+E21-E22 -> 297.1 | F23: =+F21-F22 -> 221 | G23: =+G21-G22 -> 51.5 | H23: =+H21-H22 -> 227 | I23: =+I21-I22 -> 227.3 | J23: =+J21-J22 -> 163.6 | ... L23: =+L21-L22 -> 216.9 | P23: =+P21-P22 -> 711.6 | Q23: =+Q21-Q22 -> 665.5 | R23: =+R21-R22 -> 747.7 | S23: =+S21-S22 -> 677.9 | T23: =+T21-T22 -> 1390.6 | U23: =+U21-U22 -> 1476.3 | V23: =+V21-V22 -> 1182.4 | W23: =+W21-W22 -> 939.7 | X23: =+X21-X22 -> 669.4
B25: EPS | C25: =+C23/C26 -> 1.4618205 | D25: =+D23/D26 -> 3.5185053 | E25: =+E23/E26 -> 3.5759421 | F25: =+F23/F26 -> 2.6898079 | G25: =+G23/G26 -> 0.65323 | H25: =+H23/H26 -> 2.8787014 | I25: =+I23/I26 -> 2.881775 | J25: =+J23/J26 -> 2.074168 | ... L25: =+L23/L26 -> 2.75884 | P25: =+P23/P26 -> 7.116 | Q25: =+Q23/Q26 -> 6.6681362 | R25: =+R23/R26 -> 7.4814889 | S25: =+S23/S26 -> 6.8021955 | T25: =+T23/T26 -> 14.532496 | U25: =+U23/U26 -> 16.249684 | V25: =+V23/V26 -> 13.642867 | W25: =+W23/W26 -> 11.437161 | X25: =+X23/X26 -> 8.501289
B26: Shares | C26: 85.373 | D26: 84.354 | E26: 83.083 | F26: =+W26 -> 82.162 | G26: 78.839 | H26: 78.855 | I26: 78.875 | J26: 78.875 | K26: 78.875 | L26: 78.62 | P26: =+KPI!C4 -> 100 | Q26: =+KPI!D4 -> 99.803 | R26: =+KPI!E4 -> 99.94 | S26: =+KPI!F4 -> 99.659 | T26: 95.689 | U26: 90.851 | V26: 86.668 | W26: 82.162 | X26: 78.741
B28: Handmade cigars growth | Q28: =+Q6/P6-1 -> 0.2368928 | R28: =+R6/Q6-1 -> 0.078629457 | S28: =+S6/R6-1 -> 0.12339512 | T28: =+T6/S6-1 -> 0.054295342 | U28: =+U6/T6-1 -> 0.088039539 | V28: =+V6/U6-1 -> -0.020077524 | W28: =+W6/V6-1 -> 0.019654501 | X28: =+X6/W6-1 -> -0.041036521
B29: Machine-rolled growth | Q29: =+Q7/P7-1 -> -0.050090307 | R29: =+R7/Q7-1 -> -0.060675202 | S29: =+S7/R7-1 -> 0.30214565 | T29: =+T7/S7-1 -> 0.0082907282 | U29: =+U7/T7-1 -> 0.031177196 | V29: =+V7/U7-1 -> 0.42683899 | W29: =+W7/V7-1 -> 0.031831412 | X29: =+X7/W7-1 -> 0.024891677
B30: Net Gen Growth | Q30: =+Q8/P8-1 -> -0.08965155 | R30: =+R8/Q8-1 -> -0.033083285 | S30: =+S8/R8-1 -> 0.13805451 | T30: =+T8/S8-1 -> 0.054186331 | U30: =+U8/T8-1 -> 0.060769358 | V30: =+V8/U8-1 -> -0.84892536 | W30: =+W8/V8-1 -> 1.1774444 | X30: =+X8/W8-1 -> 0.017343787
B31: Other Growth | Q31: =+Q9/P9-1 -> 0.028819712 | R31: =+R9/Q9-1 -> -0.0078049824 | S31: =+S9/R9-1 -> 0.17262931 | T31: =+T9/S9-1 -> -0.0143356 | U31: =+U9/T9-1 -> 0.091460004 | V31: =+V9/U9-1 -> -0.13966003 | W31: =+W9/V9-1 -> 0.042990469 | X31: =+X9/W9-1 -> -0.14136126
B32: Revenue Growth | G32: =+G10/C10-1 -> 0.013037007 | H32: =+H10/D10-1 -> -0.001859836 | I32: =+I10/E10-1 -> -0.03011726 | J32: =+J10/F10-1 -> -0.04646999 | K32: =+K10/G10-1 -> -0.058012869 | L32: =+L10/H10-1 -> -0.011603286 | M32: =+M10/I10-1 -> -1 | N32: =+N10/J10-1 -> -1 | Q32: =+Q10/P10-1 -> 0.039297594 | R32: =+R10/Q10-1 -> 0.00022329736 | S32: =+S10/R10-1 -> 0.19153148 | T32: =+T10/S10-1 -> 0.028329107 | U32: =+U10/T10-1 -> 0.064316688 | V32: =+V10/U10-1 -> -0.0035721622 | W32: =+W10/V10-1 -> 0.053969236 | X32: =+X10/W10-1 -> -0.018082829
B33: Gross Margin | C33: =+C12/C10 -> 0.45229174 | D33: =+D12/D10 -> 0.46884775 | E33: =+E12/E10 -> 0.46327916 | F33: =+F12/F10 -> 0.47287894 | G33: =+G12/G10 -> 0.43912449 | H33: =+H12/H10 -> 0.45032608 | I33: =+I12/I10 -> 0.44550969 | J33: =+J12/J10 -> 0.43566765 | ... N33: =+N12/N10 -> #DIV/0! | Q33: =+Q12/Q10 -> 0.47650167 | R33: =+R12/R10 -> 0.46770353 | S33: =+S12/S10 -> 0.46368303 | T33: =+T12/T10 -> 0.49960523 | U33: =+U12/U10 -> 0.49157746 | V33: =+V12/V10 -> 0.48151966 | W33: =+W12/W10 -> 0.46494822 | X33: =+X12/X10 -> 0.44282125
B34: Operating Margin | C34: =+C17/C10 -> 0.10675974 | D34: =+D17/D10 -> 0.18150309 | E34: =+E17/E10 -> 0.16502777 | F34: =+F17/F10 -> 0.13904374 | G34: =+G17/G10 -> 0.068855449 | H34: =+H17/H10 -> 0.14991107 | I34: =+I17/I10 -> 0.15526238 | J34: =+J17/J10 -> 0.12217812 | ... N34: =+N17/N10 -> #DIV/0! | Q34: =+Q17/Q10 -> 0.10978787 | R34: =+R17/R10 -> 0.14543831 | S34: =+S17/S10 -> 0.12310921 | T34: =+T17/T10 -> 0.22036513 | U34: =+U17/U10 -> 0.22288923 | V34: =+V17/V10 -> 0.18764389 | W34: =+W17/W10 -> 0.1499875 | X34: =+X17/X10 -> 0.12640969
B35: Tax Rate | C35: =+C22/C21 -> 0.21460038 | D35: =+D22/D21 -> 0.22929109 | E35: =+E22/E21 -> 0.22428198 | F35: =+F22/F21 -> 0.24392747 | G35: =+G22/G21 -> 0.23019432 | H35: =+H22/H21 -> 0.22998643 | I35: =+I22/I21 -> 0.22975263 | J35: =+J22/J21 -> 0.25972851 | ... N35: =+N22/N21 -> #DIV/0! | Q35: =+Q22/Q21 -> 0.07156808 | R35: =+R22/R21 -> 0.21178579 | S35: =+S22/S21 -> 0.2874711 | T35: =+T22/T21 -> 0.21368391 | U35: =+U22/U21 -> 0.20479397 | V35: =+V22/V21 -> 0.2068688 | W35: =+W22/W21 -> 0.2293119 | X35: =+X22/X21 -> 0.23741171
B37: Goodwill | P37: 4255.8 | Q37: 4561.8 | R37: 4629.8 | S37: 4895.1 | T37: 5142.5 | U37: 5331.5 | V37: 5235.6 | W37: 5409.9 | X37: 5071.8
B38: Trademarks | P38: 3013.9 | Q38: 2922.6 | R38: 2840.2 | S38: 3067.5 | T38: 3044.6 | U38: 2987.6 | V38: 3226.1 | W38: 3224.1 | X38: 3003
B39: IT Software | P39: 99.4 | Q39: 75.9 | R39: 45.7 | S39: 77.9 | T39: 33.7 | U39: 50.5 | V39: 74.4 | W39: 65.3 | X39: 179.7
B40: Other Intangibles | P40: 181.9 | Q40: 308.8 | R40: 281.1 | S40: 239.2 | T40: 218.9 | U40: 195.1 | V40: 404 | W40: 400 | X40: 345.2
B41: Intangivles under Construction | P41: 0 | Q41: 0 | R41: 0 | S41: 0 | T41: 54.7 | U41: 125.4 | V41: 183.1 | W41: 215.5 | X41: 97
B42: PP&E | P42: 1217.3 | Q42: 1219.5 | R42: 1098.2 | S42: 1200.8 | T42: 1261.1 | U42: 1425.4 | V42: 1475.1 | W42: 1664.2 | X42: 1538.5
B43: Leases | P43: 127.7 | Q43: 143.7 | R43: 225.5 | S43: 204.7 | T43: 187.2 | U43: 314.2 | V43: 284.6 | W43: 402.3 | X43: 368.9
...

Sheet KPI
A1: Main
C2: FY17 | D2: FY18 | E2: FY19 | F2: FY20 | G2: FY21 | H2: FY22 | I2: FY23 | J2: FY24
B3: Share Price (EoY) | C3: 120 | D3: 78.45 | E3: 81.25 | F3: 104.1 | G3: 137.3 | H3: 122.1 | I3: 117.3 | J3: 95.3
B4: Shares outstanding | C4: 100 | D4: 99.803 | E4: 99.94 | F4: 99.659 | G4: 95.689 | H4: 90.851 | I4: 86.668 | J4: 82.162
B5: MC | C5: =+C3*C4 -> 12000 | D5: =+D3*D4 -> 7829.5454 | E5: =+E3*E4 -> 8120.125 | F5: =+F3*F4 -> 10374.502 | G5: =+G3*G4 -> 13138.1 | H5: =+H3*H4 -> 11092.907 | I5: =+I3*I4 -> 10166.156 | J5: =+J3*J4 -> 7830.0386
B6: Cash | C6: =+Model!P52 -> 605.2 | D6: =+Model!Q52 -> 310.8 | E6: =+Model!R52 -> 897.5 | F6: =+Model!S52 -> 117 | G6: =+Model!T52 -> 173.6 | H6: =+Model!U52 -> 22.2 | I6: =+Model!V52 -> 99.6 | J6: =+Model!W52 -> 160.1
B7: Debt | C7: =+Model!P57+Model!P64 -> 2606.3 | D7: =+Model!Q57+Model!Q64 -> 2658.1 | E7: =+Model!R57+Model!R64 -> 2682.1 | F7: =+Model!S57+Model!S64 -> 2843.5 | G7: =+Model!T57+Model!T64 -> 2918 | H7: =+Model!U57+Model!U64 -> 3101.1 | I7: =+Model!V57+Model!V64 -> 3656.7 | J7: =+Model!W57+Model!W64 -> 4958.4
B8: EV | C8: =+C5-C6+C7 -> 14001.1 | D8: =+D5-D6+D7 -> 10176.845 | E8: =+E5-E6+E7 -> 9904.725 | F8: =+F5-F6+F7 -> 13101.002 | G8: =+G5-G6+G7 -> 15882.5 | H8: =+H5-H6+H7 -> 14171.807 | I8: =+I5-I6+I7 -> 13723.256 | J8: =+J5-J6+J7 -> 12628.339
B10: Invested Capital
B11: Total Funds Invested
B12: Capital Employed
B14: ROE | C14: =+Model!P23/Model!P56 -> 0.08423096 | D14: =+Model!Q23/Model!Q56 -> 0.075468917 | E14: =+Model!R23/Model!R56 -> 0.082140464 | F14: =+Model!S23/Model!S56 -> 0.080969387 | G14: =+Model!T23/Model!T56 -> 0.1550659 | H14: =+Model!U23/Model!U56 -> 0.15803503 | I14: =+Model!V23/Model!V56 -> 0.1253339 | J14: =+Model!W23/Model!W56 -> 0.10195291
B15: ROA
B16: ROIC
B17: ROCE

Sheet DCF
A1: Main | B1: DCF
B3: Ticker | E3: STG-CO | G3: Share Price | J3: =+Main!J2 -> 71.6 | L3: Share Price | O3: =+J3 -> 71.6
B4: Date | E4: =+TODAY() -> 46260 | G4: Fair Share Price | J4: =V62 -> 108.99871 | L4: Scneario DCF Price | O4: =+J15+O15+T15 -> 0
B5: End of FY | E5: 46022 | G5: Implied Upside | J5: =J4/J3-1 -> 0.5223283 | L5: Implied Upside | O5: =O4/O3-1 -> -1
A7: x | B7: Assumptions
B9: Switches | G9: Conservative Case | L9: Base Case | Q9: Optimistic Case
B10: Assuptions | G10: Assuptions | I10: Year | J10: Metic | L10: Assuptions | N10: Year | O10: Metic | Q10: Assuptions | S10: Year | T10: Metic
B11: Revenue | E11: 2 | G11: Revenue | L11: Revenue | Q11: Revenue
B12: EBIT | E12: 2 | G12: EBIT | L12: EBIT | Q12: EBIT
B13: WACC | E13: 2 | G13: Implied Share Price
B14: TGR | E14: 2 | G14: Probability | L14: Probability | Q14: Probability
B15: ROIC | E15: 2 | G15: Implied Share Price * p | L15: Implied Share Price * p | Q15: Implied Share Price * p
B17: Valuation
B18: WACC | E18: =CHOOSE(E13,J18,O18,T18) -> 0.09 | G18: WACC | J18: 0.1 | L18: WACC | O18: 0.09 | Q18: WACC | T18: 0.08
B19: TGR | E19: =CHOOSE(E14,J19,O19,T19) -> 0.01 | G19: TGR | J19: 0.005 | L19: TGR | O19: 0.01 | Q19: TGR | T19: 0.015
B20: RONIC | E20: =CHOOSE(E15,J20,O20,T20) -> 0.11 | G20: RONIC | J20: 0.1 | L20: RONIC | O20: 0.11 | Q20: RONIC | T20: 0.12
A24: x | B24: Model | G24: 20 | H24: =G24+1 -> 21 | I24: =H24+1 -> 22 | J24: =I24+1 -> 23 | K24: =J24+1 -> 24 | L24: =K24+1 -> 25 | M24: =L24+1 -> 26 | N24: =M24+1 -> 27 | O24: =N24+1 -> 28 | ... V24: =U24+1 -> 35
B25: Revenue | G25: =+Model!R10 -> 6719 | H25: =+Model!S10 -> 8005.9 | I25: =+Model!T10 -> 8232.7 | J25: =+Model!U10 -> 8762.2 | K25: =+Model!V10 -> 8730.9 | L25: =+Model!W10 -> 9202.1 | M25: =L25*(1+M26) -> 9294.121 | N25: =M25*(1+N26) -> 9387.0622 | O25: =N25*(1+O26) -> 9480.9328 | P25: =O25*(1+P26) -> 9575.7422 | Q25: =P25*(1+Q26) -> 9671.4996 | R25: =Q25*(1+R26) -> 9768.2146 | S25: =R25*(1+S26) -> 9865.8967 | T25: =S25*(1+T26) -> 9964.5557 | ... V25: =U25*(1+V26) -> 10164.843
B26: Growth (%) | H26: =H25/G25-1 -> 0.19153148 | I26: =I25/H25-1 -> 0.028329107 | J26: =J25/I25-1 -> 0.064316688 | K26: =K25/J25-1 -> -0.0035721622 | L26: =L25/K25-1 -> 0.053969236 | M26: {=OFFSET(M26,$E$11,,)} -> 0.01 | N26: {=OFFSET(N26,$E$11,,)} -> 0.01 | O26: {=OFFSET(O26,$E$11,,)} -> 0.01 | P26: {=OFFSET(P26,$E$11,,)} -> 0.01 | Q26: {=OFFSET(Q26,$E$11,,)} -> 0.01 | R26: {=OFFSET(R26,$E$11,,)} -> 0.01 | S26: {=OFFSET(S26,$E$11,,)} -> 0.01 | T26: {=OFFSET(T26,$E$11,,)} -> 0.01 | ... V26: {=OFFSET(V26,$E$11,,)} -> 0.01
B27: Conservative Case | M27: -0.01 | N27: -0.01 | O27: -0.01 | P27: -0.01 | Q27: -0.01 | R27: -0.01 | S27: -0.01 | T27: -0.01 | U27: -0.01 | V27: -0.01
B28: Base Case | M28: 0.01 | N28: 0.01 | O28: 0.01 | P28: 0.01 | Q28: 0.01 | R28: 0.01 | S28: 0.01 | T28: 0.01 | U28: 0.01 | V28: 0.01
B29: Optimisitic Case | M29: 0.03 | N29: 0.03 | O29: 0.03 | P29: 0.03 | Q29: 0.03 | R29: 0.03 | S29: 0.03 | T29: 0.03 | U29: 0.03 | V29: 0.03
B31: EBIT | G31: =+Model!R17 -> 977.2 | H31: =+Model!S17 -> 985.6 | I31: =+Model!T17 -> 1814.2 | J31: =+Model!U17 -> 1953 | K31: =+Model!V17 -> 1638.3 | L31: =+Model!W17 -> 1380.2 | M31: =M32*M25 -> 1394.1182 | N31: =N32*N25 -> 1408.0593 | O31: =O32*O25 -> 1422.1399 | P31: =P32*P25 -> 1436.3613 | Q31: =Q32*Q25 -> 1450.7249 | R31: =R32*R25 -> 1465.2322 | S31: =S32*S25 -> 1479.8845 | T31: =T32*T25 -> 1494.6834 | ... V31: =V32*V25 -> 1524.7265
B32: % of Sales | G32: =G31/G25 -> 0.14543831 | H32: =H31/H25 -> 0.12310921 | I32: =I31/I25 -> 0.22036513 | J32: =J31/J25 -> 0.22288923 | K32: =K31/K25 -> 0.18764389 | L32: =L31/L25 -> 0.1499875 | M32: {=OFFSET(M32,$E$12,,)} -> 0.15 | N32: {=OFFSET(N32,$E$12,,)} -> 0.15 | O32: {=OFFSET(O32,$E$12,,)} -> 0.15 | P32: {=OFFSET(P32,$E$12,,)} -> 0.15 | Q32: {=OFFSET(Q32,$E$12,,)} -> 0.15 | R32: {=OFFSET(R32,$E$12,,)} -> 0.15 | S32: {=OFFSET(S32,$E$12,,)} -> 0.15 | T32: {=OFFSET(T32,$E$12,,)} -> 0.15 | ... V32: {=OFFSET(V32,$E$12,,)} -> 0.15
B33: Conservative Case | M33: 0.13 | N33: 0.13 | O33: 0.13 | P33: 0.13 | Q33: 0.13 | R33: 0.13 | S33: 0.13 | T33: 0.13 | U33: 0.13 | V33: 0.13
B34: Base Case | M34: 0.15 | N34: 0.15 | O34: 0.15 | P34: 0.15 | Q34: 0.15 | R34: 0.15 | S34: 0.15 | T34: 0.15 | U34: 0.15 | V34: 0.15
B35: Optimisitic Case | M35: 0.18 | N35: 0.18 | O35: 0.18 | P35: 0.18 | Q35: 0.18 | R35: 0.18 | S35: 0.18 | T35: 0.18 | U35: 0.18 | V35: 0.18
B37: Taxes | G37: =+Model!R22 -> 200.9 | H37: =+Model!S22 -> 273.5 | I37: =+Model!T22 -> 377.9 | J37: =+Model!U22 -> 380.2 | K37: =+Model!V22 -> 308.4 | L37: =+Model!W22 -> 279.6 | M37: =M38*M31 -> 278.82363 | N37: =N38*N31 -> 281.61187 | O37: =O38*O31 -> 284.42798 | P37: =P38*P31 -> 287.27226 | Q37: =Q38*Q31 -> 290.14499 | R37: =R38*R31 -> 293.04644 | S37: =S38*S31 -> 295.9769 | T37: =T38*T31 -> 298.93667 | ... V37: =V38*V31 -> 304.9453
B38: Tax Rate (%) | G38: =G37/G31 -> 0.20558739 | H38: =H37/H31 -> 0.27749594 | I38: =I37/I31 -> 0.20830118 | J38: =J37/J31 -> 0.19467486 | K38: =K37/K31 -> 0.18824391 | L38: =L37/L31 -> 0.20257934 | M38: 0.2 | N38: 0.2 | O38: 0.2 | P38: 0.2 | Q38: 0.2 | R38: 0.2 | S38: 0.2 | T38: 0.2 | U38: 0.2 | V38: 0.2
B40: Nopat | G40: =G31-G37 -> 776.3 | H40: =H31-H37 -> 712.1 | I40: =I31-I37 -> 1436.3 | J40: =J31-J37 -> 1572.8 | K40: =K31-K37 -> 1329.9 | L40: =L31-L37 -> 1100.6 | M40: =M31-M37 -> 1115.2945 | N40: =N31-N37 -> 1126.4475 | ... V40: =V31-V37 -> 1219.7812
B42: D&A and other non-cash Expenses | K42: =+Model!V75 -> 375 | L42: =+Model!W75 -> 419.8 | M42: =M43*M25 -> 408.94132 | N42: =N43*N25 -> 413.03074 | O42: =O43*O25 -> 417.16104 | P42: =P43*P25 -> 421.33266 | Q42: =Q43*Q25 -> 425.54598 | R42: =R43*R25 -> 429.80144 | S42: =S43*S25 -> 434.09946 | T42: =T43*T25 -> 438.44045 | ... V42: =V43*V25 -> 447.2531
B43: % of Sales | G43: =G42/G25 -> 0 | H43: =H42/H25 -> 0 | I43: =I42/I25 -> 0 | J43: =J42/J25 -> 0 | K43: =K42/K25 -> 0.042950899 | L43: =L42/L25 -> 0.045620022 | M43: 0.044 | N43: 0.044 | O43: 0.044 | P43: 0.044 | Q43: 0.044 | R43: 0.044 | S43: 0.044 | T43: 0.044 | U43: 0.044 | V43: 0.044
B45: CapEx | K45: =+Model!V84+Model!V85 -> -308.4 | L45: =+Model!W84+Model!W85 -> -264.3 | M45: =M46*M25 -> -306.70599 | N45: =N46*N25 -> -309.77305 | O45: =O46*O25 -> -312.87078 | P45: =P46*P25 -> -315.99949 | Q45: =Q46*Q25 -> -319.15949 | R45: =R46*R25 -> -322.35108 | S45: =S46*S25 -> -325.57459 | T45: =T46*T25 -> -328.83034 | ... V45: =V46*V25 -> -335.43983
B46: % of Sales | G46: =G45/G25 -> 0 | H46: =H45/H25 -> 0 | I46: =I45/I25 -> 0 | J46: =J45/J25 -> 0 | K46: =K45/K25 -> -0.035322819 | L46: =L45/L25 -> -0.028721705 | M46: -0.033 | N46: -0.033 | O46: -0.033 | P46: -0.033 | Q46: -0.033 | R46: -0.033 | S46: -0.033 | T46: -0.033 | U46: -0.033 | V46: -0.033
B48: Change in WC | K48: =+Model!V77 -> -36.7 | L48: =+Model!W77 -> -138.4 | M48: =M49*M25 -> -92.94121 | N48: =N49*N25 -> -93.870622 | O48: =O49*O25 -> -94.809328 | P48: =P49*P25 -> -95.757422 | Q48: =Q49*Q25 -> -96.714996 | R48: =R49*R25 -> -97.682146 | S48: =S49*S25 -> -98.658967 | T48: =T49*T25 -> -99.645557 | ... V48: =V49*V25 -> -101.64843
B49: % of Sales | G49: =G48/G25 -> 0 | H49: =H48/H25 -> 0 | I49: =I48/I25 -> 0 | J49: =J48/J25 -> 0 | K49: =K48/K25 -> -0.0042034613 | L49: =L48/L25 -> -0.015040045 | M49: -0.01 | N49: -0.01 | O49: -0.01 | P49: -0.01 | Q49: -0.01 | R49: -0.01 | S49: -0.01 | T49: -0.01 | U49: -0.01 | V49: -0.01
B51: Unlevered Free Cashflow | G51: =G40+G42+G45+G48 -> 776.3 | H51: =H40+H42+H45+H48 -> 712.1 | I51: =I40+I42+I45+I48 -> 1436.3 | J51: =J40+J42+J45+J48 -> 1572.8 | K51: =K40+K42+K45+K48 -> 1359.8 | L51: =L40+L42+L45+L48 -> 1117.7 | M51: =M40+M42+M45+M48 -> 1124.5886 | N51: =N40+N42+N45+N48 -> 1135.8345 | ... V51: =V40+V42+V45+V48 -> 1229.946
B52: Present Value of unlevered FC | M52: =(M51/(1+$E$18)^M53)*M53 -> 696.73567 | N52: =N51/(1+$E$18)^N53 -> 984.8122 | O52: =O51/(1+$E$18)^O53 -> 912.5324 | P52: =P51/(1+$E$18)^P53 -> 845.55755 | Q52: =Q51/(1+$E$18)^Q53 -> 783.49828 | R52: =R51/(1+$E$18)^R53 -> 725.99382 | S52: =S51/(1+$E$18)^S53 -> 672.70987 | T52: =T51/(1+$E$18)^T53 -> 623.33667 | U52: =U51/(1+$E$18)^U53 -> 577.58719 | V52: =V51/(1+$E$18)^V53 -> 535.19547
B53: Discount Period | M53: =YEARFRAC(E4,E5) -> 0.65555556 | N53: =M53+1 -> 1.6555556 | O53: =N53+1 -> 2.6555556 | P53: =O53+1 -> 3.6555556 | Q53: =P53+1 -> 4.6555556 | R53: =Q53+1 -> 5.6555556 | S53: =R53+1 -> 6.6555556 | T53: =S53+1 -> 7.6555556 | U53: =T53+1 -> 8.6555556 | V53: =U53+1 -> 9.6555556
B54: Sum of Present Value | V54: =SUM(M52:V52) -> 7357.9591
...
