Workbook

Sheet Main
A1: TJX Companies
A2: numbers in mio USD
H3: Price | I3: 141.19
B4: TJX | H4: Shares | I4: 1117 | J4: Q227
B5: IR | H5: MC | I5: =I4*I3 -> 157709.23
H6: Cash | I6: 6004 | J6: Q227
B7: Business Model | H7: Debt | I7: =1000+1871 -> 2871 | J7: Q227
B8: Segment | C8: Products | D8: Stores | E8: Competiton | H8: EV | I8: =I5-I6+I7 -> 154576.23
B9: MarMaxx | C9: TJ Maxx, Marshalls Chains ->off price retailer | D9: 2516
B10: Sierra | C10: Off Price retailer -> outdoor appereal etc. | D10: incl. In MarMaxx
B11: HomeGoods | C11: Off Price Retailer -> Home Fashions | D11: 919
B12: TJX Canada | C12: Winners, Home Sense, Marshalls in Canada | D12: 312
B13: TJX International | C13: TK Maxx, Homesense in Europe and Australia | D13: 644
C16: Segments | D16: % of Revenue
C17: Clothing and Footwear | D17: 47
C18: Accessoires incl. Jewelery | D18: 18
C19: Home Fashion | D19: 35
C20: USA | D20: 79
C21: Canada | D21: 9
C22: Europe | D22: 12
C23: Australia | D23: 1
B26: Notes
B27: In Q225 360 Mio USD Investment in Brands for Less (Discount in Saudi-Arabia)

Sheet Model
A1: Main
C2: Q124 | D2: Q224 | E2: Q324 | F2: Q424 | G2: Q125 | H2: Q225 | I2: Q325 | J2: Q425 | K2: Q126 | L2: Q226 | M2: Q326 | N2: Q426 | O2: Q127 | P2: Q227 | Q2: Q327 | R2: Q427 | T2: FY19 | U2: FY20 | V2: FY21 | W2: FY22 | X2: FY23 | Y2: FY24 | Z2: FY25 | AA2: FY26 | AB2: FY27 | AC2: FY28 | AD2: FY29 | AE2: FY30 | AF2: FY31 | AG2: FY32 | AH2: FY33 | AI2: FY34
A3: x | B3: Stores
B4: MarMaxx Number of Stores | C4: 2574 | D4: 2578 | E4: 2603 | F4: 2516 | G4: 2620 | H4: =1326+1204+101 -> 2631 | I4: =1331+1219+109 -> 2659 | J4: =1319+1197+94+55 -> 2665 | K4: =1338+1234 -> 2572 | L4: =1340+1234 -> 2574 | M4: =1346+1248 -> 2594 | N4: =1348+1255+111 -> 2714 | O4: =1354+1265 -> 2619 | P4: =1359+1267 -> 2626 | T4: 2343 | U4: 2403 | V4: 2402 | W4: 2432 | X4: 2482 | Y4: 2516 | Z4: =1319+1197+94+55 -> 2665 | AA4: =1348+1255+111 -> 2714 | AB4: =AA4*1.03 -> 2795.42 | AC4: =AB4*1.03 -> 2879.2826 | AD4: =AC4*1.03 -> 2965.6611 | AE4: =AD4*1.02855 -> 3050.3307 | AF4: =AE4 -> 3050.3307 | AG4: =AF4 -> 3050.3307 | AH4: =AG4 -> 3050.3307 | AI4: =AH4 -> 3050.3307 | AJ4: 3000
B5: HomeGoods Number of Stores | C5: 950 | D5: 956 | E5: 968 | F5: 974 | G5: 981 | H5: =930+62 -> 992 | I5: =941+67 -> 1008 | J5: =919+158+79 -> 1156 | K5: =950+123+75 -> 1148 | L5: =952+127+76 -> 1155 | M5: =958+141+77 -> 1176 | N5: =963+145+79 -> 1187 | O5: =969+153+84 -> 1206 | P5: =973+156+86 -> 1215 | T5: 765 | U5: 841 | V5: 855 | W5: 889 | X5: 940 | Y5: 974 | Z5: =919+158+79 -> 1156 | AA5: =963+145+79 -> 1187 | AB5: =AA5*1.055 -> 1252.285 | AC5: =AB5*1.055 -> 1321.1607 | AD5: =AC5*1.055 -> 1393.8245 | AE5: =AD5*1.055 -> 1470.4849 | AF5: =AE5*1.055 -> 1551.3615 | AG5: =AF5*1.055 -> 1636.6864 | AH5: =AG5*1.0035 -> 1642.4148 | AI5: =AH5 -> 1642.4148 | AJ5: 1500
B6: TJX Canada Number of Stores | C6: 556 | D6: 559 | E6: 565 | F6: 566 | G6: 567 | H6: =304+160+108 -> 572 | I6: =307+160+109 -> 576 | J6: =302+106 -> 408 | K6: =310+161+110 -> 581 | L6: =311+161+110 -> 582 | M6: =315+162+111 -> 588 | N6: =316+162 -> 478 | O6: =319+162+112 -> 593 | P6: =320+162+112 -> 594 | T6: 484 | U6: 513 | V6: 525 | W6: 546 | X6: 554 | Y6: 566 | Z6: =302+106 -> 408 | AA6: =316+162 -> 478 | AB6: =AA6*1.02 -> 487.56 | AC6: =AB6*1.02 -> 497.3112 | AD6: =AC6*1.02 -> 507.25742 | AE6: =AD6*1.02 -> 517.40257 | AF6: =AE6*1.0198 -> 527.64714 | AG6: =AF6 -> 527.64714 | AH6: =AG6 -> 527.64714 | AI6: =AH6 -> 527.64714 | AJ6: 650
B7: TJX International Number of Stores | C7: 785 | D7: 791 | E7: 798 | F7: 803 | G7: 804 | H7: =645+77+84 -> 806 | I7: =653+77+84 -> 814 | J7: =644+79 -> 723 | K7: =662+74+84 -> 820 | L7: =664+74+85 -> 823 | M7: =672+74+87 -> 833 | N7: =673+74+88 -> 835 | O7: =679+74+91 -> 844 | P7: =685+74+91 -> 850 | T7: 679 | U7: 726 | V7: 742 | W7: 763 | X7: 781 | Y7: 803 | Z7: =644+79 -> 723 | AA7: =673+74+88 -> 835 | AB7: =AA7*1.05 -> 876.75 | AC7: =AB7*1.05 -> 920.5875 | AD7: =AC7*1.05 -> 966.61688 | AE7: =AD7*1.05 -> 1014.9477 | AF7: =AE7*1.0454 -> 1061.0263 | AG7: =AF7 -> 1061.0263 | AH7: =AG7 -> 1061.0263 | AI7: =AH7 -> 1061.0263 | AJ7: 1125
B8: TJX Total Stores | C8: =+SUM(C4:C7) -> 4865 | D8: =+SUM(D4:D7) -> 4884 | E8: =+SUM(E4:E7) -> 4934 | F8: =+SUM(F4:F7) -> 4859 | G8: =+SUM(G4:G7) -> 4972 | H8: =+SUM(H4:H7) -> 5001 | I8: =+SUM(I4:I7) -> 5057 | J8: =+SUM(J4:J7) -> 4952 | ... P8: =+SUM(P4:P7) -> 5285 | T8: =+SUM(T4:T7) -> 4271 | U8: =+SUM(U4:U7) -> 4483 | V8: =+SUM(V4:V7) -> 4524 | W8: =+SUM(W4:W7) -> 4630 | X8: =+SUM(X4:X7) -> 4757 | Y8: =+SUM(Y4:Y7) -> 4859 | Z8: =+SUM(Z4:Z7) -> 4952 | AA8: =+SUM(AA4:AA7) -> 5214 | ... AJ8: =+SUM(AJ4:AJ7) -> 6275
B9: MarMaxx Revenue per Store | C9: =C15/C4 -> 2.8616939 | D9: =D15/D4 -> 3.0655547 | E9: =E15/E4 -> 3.1144833 | F9: =F15/F4 -> 3.9892687 | G9: =G15/G4 -> 2.9580153 | H9: =H15/H4 -> 3.2098062 | I9: =I15/I4 -> 3.1733734 | J9: =J15/J4 -> 3.7414634 | ... P9: =P15/P4 -> 3.4687738 | T9: =T15/T4 -> 10.268032 | U9: =U15/U4 -> 10.6804 | V9: =V15/V4 -> 8.061199 | W9: =W15/W4 -> 12.122944 | X9: =X15/X4 -> 12.306608 | Y9: =Y15/Y4 -> 13.280207 | Z9: =Y9*1.05 -> 13.944217 | AA9: =Z9*1.05 -> 14.641428 | AB9: =AA9*1.05 -> 15.373499 | AC9: =AB9*1.05 -> 16.142174 | AD9: =AC9*1.05 -> 16.949283 | AE9: =AD9*1.05 -> 17.796747 | AF9: =AE9*1.05 -> 18.686584 | AG9: =AF9*1.05 -> 19.620914 | ... AI9: =AH9*1.05 -> 21.632057 | AJ9: =AI9 -> 21.632057
B10: HomeGoods Revenue per Store | C10: =C16/C5 -> 2.0694737 | D10: =D16/D5 -> 2.1035565 | E10: =E16/E5 -> 2.2809917 | F10: =F16/F5 -> 2.8798768 | G10: =G16/G5 -> 2.1192661 | H10: =H16/H5 -> 2.1179435 | I10: =I16/I5 -> 2.3363095 | J10: =J16/J5 -> 2.466263 | ... P10: =P16/P5 -> 2.0633745 | T10: =T16/T5 -> 7.5652288 | U10: =U16/U5 -> 7.5576694 | V10: =V16/V5 -> 7.1298246 | W10: =W16/W5 -> 10.11811 | X10: =X16/X5 -> 8.7914894 | Y10: =Y16/Y5 -> 9.2299795 | Z10: =Y10*1.02 -> 9.4145791 | AA10: =Z10*1.02 -> 9.6028706 | AB10: =AA10*1.02 -> 9.794928 | AC10: =AB10*1.02 -> 9.9908266 | AD10: =AC10*1.02 -> 10.190643 | AE10: =AD10*1.02 -> 10.394456 | AF10: =AE10*1.02 -> 10.602345 | AG10: =AF10*1.02 -> 10.814392 | ... AI10: =AH10*1.02 -> 11.251293 | AJ10: =AI10 -> 11.251293
B11: TJX Canada Revenue per Store | C11: =C17/C6 -> 1.8669065 | D11: =D17/D6 -> 2.1878354 | E11: =E17/E6 -> 2.3309735 | F11: =F17/F6 -> 2.5936396 | G11: =G17/G6 -> 1.962963 | H11: =H17/H6 -> 2.1748252 | I11: =I17/I6 -> 2.3993056 | J11: =J17/J6 -> 3.5539216 | ... P11: =P17/P6 -> 2.4747475 | T11: =T17/T6 -> 7.9954545 | U11: =U17/U6 -> 7.8576998 | V11: =V17/V6 -> 5.4019048 | W11: =W17/W6 -> 7.9542125 | X11: =X17/X6 -> 8.866426 | Y11: =Y17/Y6 -> 8.9151943 | Z11: =Y11*1.01 -> 9.0043463 | AA11: =Z11*1.01 -> 9.0943898 | AB11: =AA11*1.01 -> 9.1853337 | AC11: =AB11*1.01 -> 9.277187 | AD11: =AC11*1.01 -> 9.3699589 | AE11: =AD11*1.01 -> 9.4636584 | AF11: =AE11*1.01 -> 9.558295 | AG11: =AF11*1.01 -> 9.653878 | ... AI11: =AH11*1.01 -> 9.8479209 | AJ11: =AI11 -> 9.8479209
B12: TJX International Revenue per Store | C12: =C18/C7 -> 1.9579618 | D12: =D18/D7 -> 2.0493047 | E12: =E18/E7 -> 2.0463659 | F12: =F18/F7 -> 2.4620174 | G12: =G18/G7 -> 1.9116915 | H12: =H18/H7 -> 2.0818859 | I12: =I18/I7 -> 2.3194103 | J12: =J18/J7 -> 2.8741355 | ... P12: =P18/P7 -> 2.4635294 | T12: =T18/T7 -> 7.7434462 | U12: =U18/U7 -> 7.8030303 | V12: =V18/V7 -> 5.1778976 | W12: =W18/W7 -> 7.508519 | X12: =X18/X7 -> 7.9577465 | Y12: =Y18/Y7 -> 8.4283935 | Z12: =Y12*1.02 -> 8.5969614 | AA12: =Z12*1.02 -> 8.7689006 | AB12: =AA12*1.02 -> 8.9442786 | AC12: =AB12*1.02 -> 9.1231642 | AD12: =AC12*1.02 -> 9.3056275 | AE12: =AD12*1.02 -> 9.49174 | AF12: =AE12*1.02 -> 9.6815748 | AG12: =AF12*1.02 -> 9.8752063 | ... AI12: =AH12*1.02 -> 10.274165 | AJ12: =AI12 -> 10.274165
A14: x | B14: Income Statement
B15: MarMaxx Revenue | C15: 7366 | D15: 7903 | E15: 8107 | F15: =Y15-SUM(C15:E15) -> 10037 | G15: 7750 | H15: 8445 | I15: 8438 | J15: 9971 | K15: 8052 | L15: 8841 | M15: 9037 | N15: =+AA15-SUM(K15:M15) -> 10655 | O15: 8650 | P15: 9109 | T15: 24058 | U15: 25665 | V15: 19363 | W15: 29483 | X15: 30545 | Y15: 33413 | Z15: 34604 | AA15: 36585 | AB15: =AB4*AB9 -> 42975.387 | AC15: =AC4*AC9 -> 46477.881 | AD15: =AD4*AD9 -> 50265.829 | AE15: =AE4*AE9 -> 54285.964 | AF15: =AF4*AF9 -> 57000.262 | AG15: =AG4*AG9 -> 59850.275 | AH15: =AH4*AH9 -> 62842.789 | AI15: =AI4*AI9 -> 65984.929
B16: HomeGoods Revenue | C16: 1966 | D16: 2011 | E16: 2208 | F16: =Y16-SUM(C16:E16) -> 2805 | G16: 2079 | H16: 2101 | I16: 2355 | J16: 2851 | K16: 2254 | L16: 2286 | M16: 2539 | N16: =+AA16-SUM(K16:M16) -> 3093 | O16: 2506 | P16: 2507 | T16: 5787.4 | U16: 6356 | V16: 6096 | W16: 8995 | X16: 8264 | Y16: 8990 | Z16: 9386 | AA16: 10172 | AB16: =AB5*AB10 -> 12266.041 | AC16: =AC5*AC10 -> 13199.487 | AD16: =AD5*AD10 -> 14203.968 | AE16: =AE5*AE10 -> 15284.89 | AF16: =AF5*AF10 -> 16448.07 | AG16: =AG5*AG10 -> 17699.768 | AH16: =AH5*AH10 -> 18116.952 | AI16: =AI5*AI10 -> 18479.291
B17: TJX Canada Revenue | C17: 1038 | D17: 1223 | E17: 1317 | F17: =Y17-SUM(C17:E17) -> 1468 | G17: 1113 | H17: 1244 | I17: 1382 | J17: 1450 | K17: 1144 | L17: 1381 | M17: 1492 | N17: =+AA17-SUM(K17:M17) -> 1612 | O17: 1285 | P17: 1470 | T17: 3869.8 | U17: 4031 | V17: 2836 | W17: 4343 | X17: 4912 | Y17: 5046 | Z17: 5189 | AA17: 5629 | AB17: =AB6*AB11 -> 4478.4013 | AC17: =AC6*AC11 -> 4613.649 | AD17: =AD6*AD11 -> 4752.9812 | AE17: =AE6*AE11 -> 4896.5212 | AF17: =AF6*AF11 -> 5043.4071 | AG17: =AG6*AG11 -> 5093.8411 | AH17: =AH6*AH11 -> 5144.7796 | AI17: =AI6*AI11 -> 5196.2273
B18: TJX International Revenue | C18: 1537 | D18: 1621 | E18: 1633 | F18: =Y18-SUM(C18:E18) -> 1977 | G18: 1537 | H18: 1678 | I18: 1888 | J18: 2078 | K18: 1661 | L18: 1893 | M18: 2049 | N18: =+AA18-SUM(K18:M18) -> 2383 | O18: 1882 | P18: 2094 | T18: 5257.8 | U18: 5665 | V18: 3842 | W18: 5729 | X18: 6215 | Y18: 6768 | Z18: 7181 | AA18: 7986 | AB18: =AB7*AB12 -> 7841.8963 | AC18: =AC7*AC12 -> 8398.6709 | AD18: =AD7*AD12 -> 8994.9766 | AE18: =AE7*AE12 -> 9633.6199 | AF18: =AF7*AF12 -> 10272.406 | AG18: =AG7*AG12 -> 10477.854 | AH18: =AH7*AH12 -> 10687.411 | AI18: =AI7*AI12 -> 10901.159
B19: Revenue | C19: 11783 | D19: 12758 | E19: 13265 | F19: =Y19-SUM(C19:E19) -> 16411 | G19: 12479 | H19: =SUM(H15:H18) -> 13468 | I19: =SUM(I15:I18) -> 14063 | J19: 16350 | K19: 13111 | L19: 14401 | M19: 15117 | N19: =+AA19-SUM(K19:M19) -> 17743 | O19: 14323 | P19: 15180 | T19: 38972.934 | U19: =SUM(U15:U18) -> 41717 | V19: =SUM(V15:V18) -> 32137 | W19: =SUM(W15:W18) -> 48550 | X19: =SUM(X15:X18) -> 49936 | Y19: =SUM(Y15:Y18) -> 54217 | Z19: =SUM(Z15:Z18) -> 56360 | AA19: 60372 | AB19: =SUM(AB15:AB18) -> 67561.726 | AC19: =SUM(AC15:AC18) -> 72689.689 | AD19: =SUM(AD15:AD18) -> 78217.755 | AE19: =SUM(AE15:AE18) -> 84100.995 | AF19: =SUM(AF15:AF18) -> 88764.146 | AG19: =SUM(AG15:AG18) -> 93121.739 | AH19: =SUM(AH15:AH18) -> 96791.932 | AI19: =SUM(AI15:AI18) -> 100561.61
B20: COGS | C20: 8374 | D20: 8910 | E20: 9139 | F20: =Y20-SUM(C20:E20) -> 11528 | G20: 8739 | H20: 9380 | I20: 9622 | J20: 11371 | K20: 9246 | L20: 9976 | M20: 10190 | N20: =+AA20-SUM(K20:M20) -> 12267 | O20: 9843 | P20: 10108 | T20: 27831.177 | U20: 29845.78 | V20: 24533.815 | W20: 34714 | X20: 36149 | Y20: 37951 | Z20: 39112 | AA20: 41679
B21: Gross Profit | C21: =C19-C20 -> 3409 | D21: =D19-D20 -> 3848 | E21: =E19-E20 -> 4126 | F21: =F19-F20 -> 4883 | G21: =G19-G20 -> 3740 | H21: =H19-H20 -> 4088 | I21: =I19-I20 -> 4441 | J21: =J19-J20 -> 4979 | ... P21: =P19-P20 -> 5072 | T21: =T19-T20 -> 11141.757 | U21: =U19-U20 -> 11871.22 | V21: =V19-V20 -> 7603.185 | W21: =W19-W20 -> 13836 | X21: =X19-X20 -> 13787 | Y21: =Y19-Y20 -> 16266 | Z21: =Z19-Z20 -> 17248 | AA21: =AA19-AA20 -> 18693
B22: SGA | C22: 2238 | D22: 2559 | E22: 2578 | F22: =Y22-SUM(C22:E22) -> 3094 | G22: 2400 | H22: 2666 | I22: 2748 | J22: 3132 | K22: 2549 | L22: 2805 | M22: 3039 | N22: =+AA22-SUM(K22:M22) -> 3122 | O22: 2794 | P22: 3085 | T22: 6923.564 | U22: 7454.988 | V22: 7020.917 | W22: 9081 | X22: 8927 | Y22: 10469 | Z22: 10946 | AA22: 11515
B23: Operating Profit | C23: =C21-C22 -> 1171 | D23: =D21-D22 -> 1289 | E23: =E21-E22 -> 1548 | F23: =F21-F22 -> 1789 | G23: =G21-G22 -> 1340 | H23: =H21-H22 -> 1422 | I23: =I21-I22 -> 1693 | J23: =J21-J22 -> 1847 | ... P23: =P21-P22 -> 1987 | T23: =T21-T22 -> 4218.193 | U23: =U21-U22 -> 4416.232 | V23: =V21-V22 -> 582.268 | W23: =W21-W22 -> 4755 | X23: =X21-X22 -> 4860 | Y23: =Y21-Y22 -> 5797 | Z23: =Z21-Z22 -> 6302 | AA23: =AA21-AA22 -> 7178
B24: Other Income | C24: 0 | D24: 0 | E24: 0 | F24: 0 | G24: 0 | H24: 0 | I24: 0 | J24: 0 | K24: 0 | L24: 0 | M24: 0 | N24: =+AA24-SUM(K24:M24) -> 0 | O24: 0 | P24: 0 | T24: -36.112 | U24: 0 | V24: -312.233 | W24: -242 | X24: -218 | Y24: 0 | Z24: 0 | AA24: 0
B25: Interest Expense | C25: 37 | D25: 38 | E25: 41 | F25: =Y25-SUM(C25:E25) -> 54 | G25: 50 | H25: 46 | I25: 43 | J25: 42 | K25: 30 | L25: 27 | M25: 28 | N25: =+AA25-SUM(K25:M25) -> 36 | O25: 35 | P25: 31 | T25: -8.86 | U25: -10.026 | V25: -180.734 | W25: -115 | X25: -6 | Y25: 170 | Z25: 181 | AA25: 121
B26: Income before Taxes | C26: =C23+C25 -> 1208 | D26: =D23+D25 -> 1327 | E26: =E23+E25 -> 1589 | F26: =F23+F25 -> 1843 | G26: =G23+G25 -> 1390 | H26: =H23+H25 -> 1468 | I26: =I23+I25 -> 1736 | J26: =J23+J25 -> 1889 | ... P26: =P23+P25 -> 2018 | T26: =T23+T24+T25 -> 4173.221 | U26: =U23+U24+U25 -> 4406.206 | V26: =V23+V24+V25 -> 89.301 | W26: =W23+W24+W25 -> 4398 | X26: =X23+X24+X25 -> 4636 | Y26: =Y23+Y24+Y25 -> 5967 | Z26: =Z23+Z24+Z25 -> 6483 | AA26: =AA23+AA24+AA25 -> 7299
B27: Income Tax Expense | C27: 317 | D27: 338 | E27: 398 | F27: =Y27-SUM(C27:E27) -> 440 | G27: 320 | H27: 369 | I27: 439 | J27: 491 | K27: 310 | L27: 404 | M27: 474 | N27: =+AA27-SUM(K27:M27) -> 617 | O27: 389 | P27: 498 | T27: 1113.413 | U27: 1133.99 | V27: -1.207 | W27: 1115 | X27: 1138 | Y27: 1493 | Z27: 1619 | AA27: 1805
B28: Net Income | C28: =C26-C27 -> 891 | D28: =D26-D27 -> 989 | E28: =E26-E27 -> 1191 | F28: =F26-F27 -> 1403 | G28: =G26-G27 -> 1070 | H28: =H26-H27 -> 1099 | I28: =I26-I27 -> 1297 | J28: =J26-J27 -> 1398 | ... P28: =P26-P27 -> 1520 | T28: =T26-T27 -> 3059.808 | U28: =U26-U27 -> 3272.216 | V28: =V26-V27 -> 90.508 | W28: =W26-W27 -> 3283 | X28: =X26-X27 -> 3498 | Y28: =Y26-Y27 -> 4474 | Z28: =Z26-Z27 -> 4864 | AA28: =AA26-AA27 -> 5494
B30: EPS | C30: =+C28/C31 -> 0.78502203 | D30: =+D28/D31 -> 0.86149826 | E30: =+E28/E31 -> 1.0410839 | F30: =+F28/F31 -> 1.2242583 | G30: =+G28/G31 -> 0.94522968 | H30: =+H28/H31 -> 0.96066434 | I30: =+I28/I31 -> 1.1508429 | J30: =+J28/J31 -> 1.228471 | ... P30: =+P28/P31 -> 1.3607878 | T30: =T28/T31 -> 2.4652948 | U30: =U28/U31 -> 2.7084226 | V30: =V28/V31 -> 0.075427922 | W30: =W28/W31 -> 2.7358333 | X30: =X28/X31 -> 3 | Y30: =Y28/Y31 -> 3.904014 | Z30: =Z28/Z31 -> 4.2591944 | AA30: =AA28/AA31 -> 4.9317774
B31: Shares | C31: 1135 | D31: 1148 | E31: 1144 | F31: 1146 | G31: 1132 | H31: 1144 | I31: 1127 | J31: 1138 | K31: 1132 | L31: 1128 | M31: 1126 | N31: 1126 | O31: 1120 | P31: 1117 | T31: 1241.153 | U31: 1208.163 | V31: 1199.927 | W31: 1200 | X31: 1166 | Y31: 1146 | Z31: 1142 | AA31: 1114
A33: x | B33: Metrics
B34: MarMaxx Store Growth | G34: =G4/C4-1 -> 0.017871018 | H34: =H4/D4-1 -> 0.020558573 | I34: =I4/E4-1 -> 0.021513638 | J34: =J4/F4-1 -> 0.059220986 | K34: =K4/G4-1 -> -0.018320611 | L34: =L4/H4-1 -> -0.021664766 | M34: =M4/I4-1 -> -0.02444528 | N34: =N4/J4-1 -> 0.018386492 | ... P34: =P4/L4-1 -> 0.02020202 | U34: =U4/T4-1 -> 0.025608195 | V34: =V4/U4-1 -> -0.00041614648 | W34: =W4/V4-1 -> 0.012489592 | X34: =X4/W4-1 -> 0.020559211 | Y34: =Y4/X4-1 -> 0.01369863 | Z34: =Z4/Y4-1 -> 0.059220986 | AA34: =AA4/Z4-1 -> 0.018386492 | AB34: =AB4/AA4-1 -> 0.03 | ... AI34: =AI4/AH4-1 -> 0
B35: HomeGoods Store Growth | G35: =G5/C5-1 -> 0.032631579 | H35: =H5/D5-1 -> 0.037656904 | I35: =I5/E5-1 -> 0.041322314 | J35: =J5/F5-1 -> 0.18685832 | K35: =K5/G5-1 -> 0.17023445 | L35: =L5/H5-1 -> 0.16431452 | M35: =M5/I5-1 -> 0.16666667 | N35: =N5/J5-1 -> 0.026816609 | ... P35: =P5/L5-1 -> 0.051948052 | U35: =U5/T5-1 -> 0.099346405 | V35: =V5/U5-1 -> 0.016646849 | W35: =W5/V5-1 -> 0.039766082 | X35: =X5/W5-1 -> 0.057367829 | Y35: =Y5/X5-1 -> 0.036170213 | Z35: =Z5/Y5-1 -> 0.18685832 | AA35: =AA5/Z5-1 -> 0.026816609 | AB35: =AB5/AA5-1 -> 0.055 | ... AI35: =AI5/AH5-1 -> 0
B36: TJX Canada Store Growth | G36: =G6/C6-1 -> 0.019784173 | H36: =H6/D6-1 -> 0.023255814 | I36: =I6/E6-1 -> 0.019469027 | J36: =J6/F6-1 -> -0.27915194 | K36: =K6/G6-1 -> 0.024691358 | L36: =L6/H6-1 -> 0.017482517 | M36: =M6/I6-1 -> 0.020833333 | N36: =N6/J6-1 -> 0.17156863 | ... P36: =P6/L6-1 -> 0.020618557 | U36: =U6/T6-1 -> 0.059917355 | V36: =V6/U6-1 -> 0.023391813 | W36: =W6/V6-1 -> 0.04 | X36: =X6/W6-1 -> 0.014652015 | Y36: =Y6/X6-1 -> 0.02166065 | Z36: =Z6/Y6-1 -> -0.27915194 | AA36: =AA6/Z6-1 -> 0.17156863 | AB36: =AB6/AA6-1 -> 0.02 | ... AI36: =AI6/AH6-1 -> 0
B37: TJX International Store Growth | G37: =G7/C7-1 -> 0.024203822 | H37: =H7/D7-1 -> 0.018963338 | I37: =I7/E7-1 -> 0.020050125 | J37: =J7/F7-1 -> -0.099626401 | K37: =K7/G7-1 -> 0.019900498 | L37: =L7/H7-1 -> 0.021091811 | M37: =M7/I7-1 -> 0.023341523 | N37: =N7/J7-1 -> 0.1549101 | ... P37: =P7/L7-1 -> 0.032806804 | U37: =U7/T7-1 -> 0.06921944 | V37: =V7/U7-1 -> 0.022038567 | W37: =W7/V7-1 -> 0.028301887 | X37: =X7/W7-1 -> 0.023591088 | Y37: =Y7/X7-1 -> 0.028169014 | Z37: =Z7/Y7-1 -> -0.099626401 | AA37: =AA7/Z7-1 -> 0.1549101 | AB37: =AB7/AA7-1 -> 0.05 | ... AI37: =AI7/AH7-1 -> 0
B38: Revenue Groth | G38: =G19/C19-1 -> 0.059068149 | H38: =H19/D19-1 -> 0.055651356 | I38: =I19/E19-1 -> 0.060158311 | J38: =J19/F19-1 -> -0.0037170191 | K38: =K19/G19-1 -> 0.050645084 | L38: =L19/H19-1 -> 0.069275319 | M38: =M19/I19-1 -> 0.074948446 | N38: =N19/J19-1 -> 0.085198777 | ... P38: =P19/L19-1 -> 0.054093466 | U38: =U19/T19-1 -> 0.070409531 | V38: =V19/U19-1 -> -0.22964259 | W38: =W19/V19-1 -> 0.51071973 | X38: =X19/W19-1 -> 0.028547889 | Y38: =Y19/X19-1 -> 0.085729734 | Z38: =Z19/Y19-1 -> 0.039526348 | AA38: =AA19/Z19-1 -> 0.071185238 | AB38: =AB19/AA19-1 -> 0.11909041 | ... AI38: =AI19/AH19-1 -> 0.038946165
B39: Gross Margin | C39: =C21/C19 -> 0.28931511 | D39: =D21/D19 -> 0.30161467 | E39: =E21/E19 -> 0.3110441 | F39: =F21/F19 -> 0.29754433 | G39: =G21/G19 -> 0.2997035 | H39: =H21/H19 -> 0.3035343 | I39: =I21/I19 -> 0.31579322 | J39: =J21/J19 -> 0.30452599 | ... P39: =P21/P19 -> 0.33412385 | T39: =T21/T19 -> 0.28588448 | U39: =U21/U19 -> 0.28456552 | V39: =V21/V19 -> 0.23658664 | W39: =W21/W19 -> 0.28498455 | X39: =X21/X19 -> 0.2760934 | Y39: =Y21/Y19 -> 0.3000166 | Z39: =Z21/Z19 -> 0.30603265 | AA39: =AA21/AA19 -> 0.30963029
B40: Operating Margin | C40: =C23/C19 -> 0.099380463 | D40: =D23/D19 -> 0.10103464 | E40: =E23/E19 -> 0.11669808 | F40: =F23/F19 -> 0.10901225 | G40: =G23/G19 -> 0.1073804 | H40: =H23/H19 -> 0.10558361 | I40: =I23/I19 -> 0.12038683 | J40: =J23/J19 -> 0.11296636 | ... P40: =P23/P19 -> 0.13089592 | T40: =T23/T19 -> 0.10823391 | U40: =U23/U19 -> 0.10586169 | V40: =V23/V19 -> 0.018118306 | W40: =W23/W19 -> 0.097940268 | X40: =X23/X19 -> 0.097324575 | Y40: =Y23/Y19 -> 0.10692218 | Z40: =Z23/Z19 -> 0.11181689 | AA40: =AA23/AA19 -> 0.11889618
B41: Net Margin | C41: =C28/C19 -> 0.075617415 | D41: =D28/D19 -> 0.077519987 | E41: =E28/E19 -> 0.089785149 | F41: =F28/F19 -> 0.085491439 | G41: =G28/G19 -> 0.08574405 | H41: =H28/H19 -> 0.081600832 | I41: =I28/I19 -> 0.092227832 | J41: =J28/J19 -> 0.085504587 | ... P41: =P28/P19 -> 0.10013175 | T41: =T28/T19 -> 0.078511102 | U41: =U28/U19 -> 0.07843843 | V41: =V28/V19 -> 0.0028163176 | W41: =W28/W19 -> 0.067621009 | X41: =X28/X19 -> 0.070049664 | Y41: =Y28/Y19 -> 0.082520243 | Z41: =Z28/Z19 -> 0.086302342 | AA41: =AA28/AA19 -> 0.091002451
B42: Tax Rate | C42: =C27/C26 -> 0.26241722 | D42: =D27/D26 -> 0.25470987 | E42: =E27/E26 -> 0.25047199 | F42: =F27/F26 -> 0.23874118 | G42: =G27/G26 -> 0.23021583 | H42: =H27/H26 -> 0.2513624 | I42: =I27/I26 -> 0.25288018 | J42: =J27/J26 -> 0.25992589 | ... P42: =P27/P26 -> 0.24677899 | T42: =T27/T26 -> 0.26679943 | U42: =U27/U26 -> 0.257362 | V42: =V27/V26 -> -0.013516086 | W42: =W27/W26 -> 0.25352433 | X42: =X27/X26 -> 0.24547023 | Y42: =Y27/Y26 -> 0.25020949 | Z42: =Z27/Z26 -> 0.24973006 | AA42: =AA27/AA26 -> 0.24729415
A45: x | B45: Balance Sheet
...

Sheet Ratios
A1: Main
B2: Ratios | C2: FY19 | D2: FY20 | E2: FY21 | F2: FY22 | G2: FY23 | H2: FY24 | I2: FY25 | K2: Average
A3: x | B3: Efficiency
B4: ROE | C4: =Model!T28/Model!T78 -> 0.60606987 | D4: =Model!U28/Model!U78 -> 0.55011758 | E4: =Model!V28/Model!V78 -> 0.015517384 | F4: =Model!W28/Model!W78 -> 0.54689395 | G4: =Model!X28/Model!X78 -> 0.54965431 | H4: =Model!Y28/Model!Y78 -> 0.61270885 | K4: =AVERAGE(F4:H4,C4:D4) -> 0.57308891
B5: ROA | C5: =Model!T23/Model!T58 -> 0.29444258 | D5: =Model!U23/Model!U58 -> 0.1829046 | E5: =Model!V23/Model!V58 -> 0.018896483 | F5: =Model!W23/Model!W58 -> 0.16706804 | G5: =Model!X23/Model!X58 -> 0.17143462 | H5: =Model!Y23/Model!Y58 -> 0.19487679 | K5: =AVERAGE(F5:H5,C5:D5) -> 0.20214533
B6: ROCE | C6: =Model!T23/(Model!T57+Model!T47+Model!T48+Model!T49+Model!T50-Model!T60) -> 0.48755897 | D6: =Model!U23/(Model!U57+Model!U47+Model!U48+Model!U49+Model!U50-Model!U60) -> 0.24190984 | E6: =Model!V23/(Model!V57+Model!V47+Model!V48+Model!V49+Model!V50-Model!V60) -> 0.037515825 | F6: =Model!W23/(Model!W57+Model!W47+Model!W48+Model!W49+Model!W50-Model!W60) -> 0.26759687 | G6: =Model!X23/(Model!X57+Model!X47+Model!X48+Model!X49+Model!X50-Model!X60) -> 0.25474368 | H6: =Model!Y23/(Model!Y57+Model!Y47+Model!Y48+Model!Y49+Model!Y50-Model!Y60) -> 0.28577767 | K6: =AVERAGE(F6:H6,C6:D6) -> 0.30751741
B7: ROIC | C7: =(Model!T23*(1-Model!T42))/(Model!T78+Model!T69+Model!T68+Model!T66+Model!T62+Model!T63-Model!T46) -> 0.55166819 | D7: =(Model!U23*(1-Model!U42))/(Model!U78+Model!U69+Model!U68+Model!U66+Model!U62+Model!U63-Model!U46) -> 0.21796044 | E7: =(Model!V23*(1-Model!V42))/(Model!V78+Model!V69+Model!V68+Model!V66+Model!V62+Model!V63-Model!V46) -> 0.049464889 | F7: =(Model!W23*(1-Model!W42))/(Model!W78+Model!W69+Model!W68+Model!W66+Model!W62+Model!W63-Model!W46) -> 0.26690038 | G7: =(Model!X23*(1-Model!X42))/(Model!X78+Model!X69+Model!X68+Model!X66+Model!X62+Model!X63-Model!X46) -> 0.2520285 | H7: =(Model!Y23*(1-Model!Y42))/(Model!Y78+Model!Y69+Model!Y68+Model!Y66+Model!Y62+Model!Y63-Model!Y46) -> 0.28655957 | K7: =AVERAGE(F7:H7,C7:D7) -> 0.31502342
B9: Retention Rate | C9: =(Model!T28+Model!T113+Model!T111)/Model!T28 -> -0.088170565 | D9: =(Model!U28+Model!U113+Model!U111)/Model!U28 -> 0.19823325 | E9: =(Model!V28+Model!V113+Model!V111)/Model!V28 -> -4.3007027 | F9: =(Model!W28+Model!W113+Model!W111)/Model!W28 -> -0.04416692 | G9: =(Model!X28+Model!X113+Model!X111)/Model!X28 -> -0.027444254 | H9: =(Model!Y28+Model!Y113+Model!Y111)/Model!Y28 -> 0.1130979 | K9: =AVERAGE(F9:H9,C9:D9) -> 0.030309881
B10: Expected Growth NI | C10: =C9*C6 -> -0.04298835 | D10: =D9*D6 -> 0.047954573 | E10: =E9*E6 -> -0.16134441 | F10: =F9*F6 -> -0.01181893 | G10: =G9*G6 -> -0.0069912503 | H10: =H9*H6 -> 0.032320854 | K10: =AVERAGE(F10:H10,C10:D10) -> 0.0036953793
B11: Reinvestment Rate | C11: =(-Model!T104-Model!T102)/(Model!T23*(1-Model!T42)) -> 0.31844183 | D11: =(-Model!U104-Model!U102)/(Model!U23*(1-Model!U42)) -> 0.43627976 | E11: =(-Model!V104-Model!V102)/(Model!V23*(1-Model!V42)) -> -4.7595377 | F11: =(-Model!W104-Model!W102)/(Model!W23*(1-Model!W42)) -> 0.71418674 | G11: =(-Model!X104-Model!X102)/(Model!X23*(1-Model!X42)) -> 0.59585254 | H11: =(-Model!Y104-Model!Y102)/(Model!Y23*(1-Model!Y42)) -> 0.30299993 | K11: =AVERAGE(F11:H11,C11:D11) -> 0.47355216
B12: Expected Growth OI | C12: =C11*C7 -> 0.17567423 | D12: =D11*D7 -> 0.095091729 | E12: =E11*E7 -> -0.23543 | F12: =F11*F7 -> 0.19061671 | G12: =G11*G7 -> 0.15017182 | H12: =H11*H7 -> 0.086827532 | K12: =AVERAGE(F12:H12,C12:D12) -> 0.1396764
A14: x | B14: Financial Stability
B15: Gearing | C15: =C31/Model!T78 -> 0.11045207 | D15: =D31/Model!U78 -> 1.5296761 | E15: =E31/Model!V78 -> 1.0454463 | F15: =F31/Model!W78 -> 1.2153851 | G15: =G31/Model!X78 -> 1.2862979 | H15: =H31/Model!Y78 -> 1.0772391
B16: Net Debt/EBITDA | C16: =C31/(Model!T23+Model!T85) -> 0.11068794 | D16: =D31/(Model!U23+Model!U85) -> 1.7221118 | E16: =E31/(Model!V23+Model!V85) -> 4.1965925 | F16: =F31/(Model!W23+Model!W85) -> 1.2975186 | G16: =G31/(Model!X23+Model!X85) -> 1.4243953 | H16: =H31/(Model!Y23+Model!Y85) -> 1.1634374
B17: Interest Coverage
A19: x | B19: WC Management
B20: Creditors | C20: =Model!T47/Model!T19*360 -> 3.1988169 | D20: =Model!U47/Model!U19*360 -> 3.3332685 | E20: =Model!V47/Model!V19*360 -> 5.1656981 | F20: =Model!W47/Model!W19*360 -> 3.8381932 | G20: =Model!X47/Model!X19*360 -> 4.0587953 | H20: =Model!Y47/Model!Y19*360 -> 3.5125514 | K20: =AVERAGE(C20:H20) -> 3.8512206
B21: Debitors | C21: =Model!T60/Model!T19*360 -> 24.424424 | D21: =Model!U60/Model!U19*360 -> 23.063032 | E21: =Model!V60/Model!V19*360 -> 54.031892 | F21: =Model!W60/Model!W19*360 -> 33.111302 | G21: =Model!X60/Model!X19*360 -> 27.35181 | H21: =Model!Y60/Model!Y19*360 -> 25.643617 | K21: =AVERAGE(C21:H21) -> 31.271013
B22: Inventority Intensity | C22: =Model!T48/Model!T58 -> 0.3196303 | D22: =Model!U48/Model!U58 -> 0.2018054 | E22: =Model!V48/Model!V58 -> 0.14076262 | F22: =Model!W48/Model!W58 -> 0.20946127 | G22: =Model!X48/Model!X58 -> 0.20526297 | H22: =Model!Y48/Model!Y58 -> 0.20052442 | K22: =AVERAGE(C22:H22) -> 0.21290783
B23: Inventority Turnover | C23: =Model!T20/Model!T48 -> 6.0779595 | D23: =Model!U20/Model!U48 -> 6.1252368 | E23: =Model!V20/Model!V48 -> 5.656344 | F23: =Model!W20/Model!W48 -> 5.8229598 | G23: =Model!X20/Model!X48 -> 6.2122358 | H23: =Model!Y20/Model!Y48 -> 6.36228 | K23: =AVERAGE(C23:H23) -> 6.042836
B24: Storage Duration | C24: =360/C23 -> 59.230405 | D24: =360/D23 -> 58.773238 | E24: =360/E23 -> 63.645352 | F24: =360/F23 -> 61.824229 | G24: =360/G23 -> 57.950151 | H24: =360/H23 -> 56.583489 | K24: =AVERAGE(C24:H24) -> 59.66781
B25: Cash Conversion Cycle | C25: =C20+C24-C21 -> 38.004797 | D25: =D20+D24-D21 -> 39.043474 | E25: =E20+E24-E21 -> 14.779157 | F25: =F20+F24-F21 -> 32.55112 | G25: =G20+G24-G21 -> 34.657136 | H25: =H20+H24-H21 -> 34.452423 | K25: =AVERAGE(C25:H25) -> 32.248018
A27: x | B27: Multiples
B28: Price | C28: 44.6 | D28: 61.06 | E28: 66.81 | F28: 75.5 | G28: 79 | H28: 97.6
B29: Shares | C29: =Model!T31 -> 1241.153 | D29: =Model!U31 -> 1208.163 | E29: =Model!V31 -> 1199.927 | F29: =Model!W31 -> 1200 | G29: =Model!X31 -> 1166 | H29: =Model!Y31 -> 1146
B30: MC | C30: =C29*C28 -> 55355.424 | D30: =D29*D28 -> 73770.433 | E30: =E29*E28 -> 80167.123 | F30: =F29*F28 -> 90600 | G30: =G29*G28 -> 92114 | H30: =H29*H28 -> 111849.6
B31: Net Debt | C31: =Model!T69+Model!T68+Model!T66+Model!T62+Model!T63-Model!T46 -> 557.629 | D31: =Model!U69+Model!U68+Model!U66+Model!U62+Model!U63-Model!U46 -> 9098.838 | E31: =Model!V69+Model!V68+Model!V66+Model!V62+Model!V63-Model!V46 -> 6097.758 | F31: =Model!W69+Model!W68+Model!W66+Model!W62+Model!W63-Model!W46 -> 7295.947 | G31: =Model!X69+Model!X68+Model!X66+Model!X62+Model!X63-Model!X46 -> 8186 | H31: =Model!Y69+Model!Y68+Model!Y66+Model!Y62+Model!Y63-Model!Y46 -> 7866
B32: EV | C32: =C30+C31 -> 55913.053 | D32: =D30+D31 -> 82869.271 | E32: =E30+E31 -> 86264.881 | F32: =F30+F31 -> 97895.947 | G32: =G30+G31 -> 100300 | H32: =H30+H31 -> 119715.6
B33: Equity Multiples
B34: P/E | C34: =C30/Model!T28 -> 18.091143 | D34: =D30/Model!U28 -> 22.544488 | E34: =E30/Model!V28 -> 885.74626 | F34: =F30/Model!W28 -> 27.59671 | G34: =G30/Model!X28 -> 26.333333 | H34: =H30/Model!Y28 -> 24.999911 | K34: =AVERAGE(F34:H34,C34:D34) -> 23.913117
B35: PEG-Ratio | D35: =D34/((Model!U28/Model!T28-1)*100) -> 3.2476085 | E35: =E34/((Model!V28/Model!U28-1)*100) -> -9.1094252 | F35: =F34/((Model!W28/Model!V28-1)*100) -> 0.007823741 | G35: =G34/((Model!X28/Model!W28-1)*100) -> 4.0210388 | H35: =H34/((Model!Y28/Model!X28-1)*100) -> 0.89600089 | K35: =AVERAGE(F35:H35,D35) -> 2.043118
B36: P/B | C36: =C30/Model!T78 -> 10.964497 | D36: =D30/Model!U78 -> 12.402119 | E36: =E30/Model!V78 -> 13.744465 | F36: =F30/Model!W78 -> 15.092474 | G36: =G30/Model!X78 -> 14.47423 | H36: =H30/Model!Y78 -> 15.317666 | K36: =AVERAGE(F36:H36,C36:D36) -> 13.650197
B37: Entity Multiples
B38: EV/Sales | C38: =Ratios!C32/Model!T19 -> 1.4346637 | D38: =Ratios!D32/Model!U19 -> 1.9864629 | E38: =Ratios!E32/Model!V19 -> 2.6842854 | F38: =Ratios!F32/Model!W19 -> 2.0163944 | G38: =Ratios!G32/Model!X19 -> 2.008571 | H38: =Ratios!H32/Model!Y19 -> 2.2080823 | K38: =AVERAGE(F38:H38,C38:D38) -> 1.9308348
B39: EV/EBITDA | C39: =C32/(Model!T23+Model!T85) -> 11.098599 | D39: =D32/(Model!U23+Model!U85) -> 15.684437 | E39: =E32/(Model!V23+Model!V85) -> 59.369124 | F39: =F32/(Model!W23+Model!W85) -> 17.409914 | G39: =G32/(Model!X23+Model!X85) -> 17.452584 | H39: =H32/(Model!Y23+Model!Y85) -> 17.706789 | K39: =AVERAGE(F39:H39,C39:D39) -> 15.870464
B40: EV/EBIT | C40: =C32/Model!T23 -> 13.255214 | D40: =D32/Model!U23 -> 18.7647 | E40: =E32/Model!V23 -> 148.15322 | F40: =F32/Model!W23 -> 20.588001 | G40: =G32/Model!X23 -> 20.63786 | H40: =H32/Model!Y23 -> 20.651302 | K40: =AVERAGE(F40:H40,C40:D40) -> 18.779416
A42: x | B42: WACC
B43: Riskfree Rate | J43: 0.04277
B44: Country Default Risk | J44: 0
B45: Default Spread | J45: 0.0092
...

Sheet DCF
A1: Main
A3: x | B3: Switches | K3: Assumptions
B4: Revenue | D4: 2 | F4: D&A | H4: 2 | K4: Conservative Case | O4: Base Case | S4: Optimistic Case
B5: EBIT | D5: 2 | F5: CapEX | H5: 2 | K5: WACC | M5: =Q5+1% -> 0.092449686 | O5: WACC | Q5: =Ratios!J53 -> 0.082449686 | S5: WACC | U5: =Q5-1% -> 0.072449686
B6: Taxes | D6: 2 | F6: WC | H6: 2 | K6: TGR | M6: =Q6-0.5% -> 0.02 | O6: TGR | Q6: 0.025 | S6: TGR | U6: =Q6+0.5% -> 0.03
B7: WACC | D7: 2 | F7: TGR | H7: 2
B9: WACC | D9: =CHOOSE(D7,M5,Q5,U5) -> 0.082449686 | F9: Share Price | H9: =Main!I3 -> 141.19
B10: TGR | D10: =CHOOSE(H7,M6,Q6,U6) -> 0.025 | F10: Fair Share Price | H10: =V67 -> 95.964498 | K10: Fair Share Price | M10: 42.6 | O10: Fair Share Price | Q10: 91.8 | S10: Fair Share Price | U10: 194.18
F11: Implied Upside | H11: =H10/H9-1 -> -0.32031661 | K11: Implied Upside | M11: =M10/H9-1 -> -0.69827891 | O11: Implied Upside | Q11: =Q10/H9-1 -> -0.34981231 | S11: Implied Upside | U11: =U10/H9-1 -> 0.37530987
G15: h | H15: h | I15: h | J15: h | K15: h | L15: h | M15: p | N15: p | O15: p | P15: p | Q15: p | R15: p | S15: p | T15: p | U15: p | V15: p
A16: x | B16: Model | G16: FY19 | H16: FY20 | I16: FY21 | J16: FY22 | K16: FY23 | L16: FY24 | M16: FY25 | N16: FY26 | O16: FY27 | P16: FY28 | Q16: FY29 | R16: FY30 | S16: FY31 | T16: FY32 | U16: FY33 | V16: FY33
B18: Revenue | G18: =Model!T19 -> 38972.934 | H18: =Model!U19 -> 41717 | I18: =Model!V19 -> 32137 | J18: =Model!W19 -> 48550 | K18: =Model!X19 -> 49936 | L18: =Model!Y19 -> 54217 | M18: =L18*(1+M19) -> 56360 | N18: =M18*(1+N19) -> 60372 | O18: =N18*(1+O19) -> 67561.726 | P18: =O18*(1+P19) -> 72689.689 | Q18: =P18*(1+Q19) -> 78217.755 | R18: =Q18*(1+R19) -> 84100.995 | S18: =R18*(1+S19) -> 88764.146 | T18: =S18*(1+T19) -> 93121.739 | ... V18: =U18*(1+V19) -> 100561.61
B19: Growth (%) | H19: =H18/G18-1 -> 0.070409531 | I19: =I18/H18-1 -> -0.22964259 | J19: =J18/I18-1 -> 0.51071973 | K19: =K18/J18-1 -> 0.028547889 | L19: =L18/K18-1 -> 0.085729734 | M19: {=OFFSET(M19,$D$4,,)} -> 0.039526348 | N19: {=OFFSET(N19,$D$4,,)} -> 0.071185238 | O19: {=OFFSET(O19,$D$4,,)} -> 0.11909041 | P19: {=OFFSET(P19,$D$4,,)} -> 0.075900402 | Q19: {=OFFSET(Q19,$D$4,,)} -> 0.076050211 | R19: {=OFFSET(R19,$D$4,,)} -> 0.075216179 | S19: {=OFFSET(S19,$D$4,,)} -> 0.055447028 | T19: {=OFFSET(T19,$D$4,,)} -> 0.04909182 | ... V19: {=OFFSET(V19,$D$4,,)} -> 0.038946165
B20: Conservative Case | M20: =M21-1% -> 0.029526348 | N20: =N21-1% -> 0.061185238 | O20: =O21-1% -> 0.10909041 | P20: =P21-1% -> 0.065900402 | Q20: =Q21-1% -> 0.066050211 | R20: =R21-1% -> 0.065216179 | S20: =S21-1% -> 0.045447028 | T20: =T21-1% -> 0.03909182 | ... V20: =V21-1% -> 0.028946165
B21: Base Case | M21: =Model!Z38 -> 0.039526348 | N21: =Model!AA38 -> 0.071185238 | O21: =Model!AB38 -> 0.11909041 | P21: =Model!AC38 -> 0.075900402 | Q21: =Model!AD38 -> 0.076050211 | R21: =Model!AE38 -> 0.075216179 | S21: =Model!AF38 -> 0.055447028 | T21: =Model!AG38 -> 0.04909182 | ... V21: =Model!AI38 -> 0.038946165
B22: Optimisitic Case | M22: =M21+2% -> 0.059526348 | N22: =N21+2% -> 0.091185238 | O22: =O21+2% -> 0.13909041 | P22: =P21+2% -> 0.095900402 | Q22: =Q21+2% -> 0.096050211 | R22: =R21+2% -> 0.095216179 | S22: =S21+2% -> 0.075447028 | T22: =T21+2% -> 0.06909182 | ... V22: =V21+2% -> 0.058946165
B24: EBIT | G24: =Model!T23 -> 4218.193 | H24: =Model!U23 -> 4416.232 | I24: =Model!V23 -> 582.268 | J24: =Model!W23 -> 4755 | K24: =Model!X23 -> 4860 | L24: =Model!Y23 -> 5797 | M24: =M25*M18 -> 6199.6 | N24: =N25*N18 -> 6791.85 | O24: =O25*O18 -> 7769.5985 | P24: =P25*P18 -> 8541.0384 | Q24: =Q25*Q18 -> 9386.1306 | R24: =R25*R18 -> 10302.372 | S24: =S25*S18 -> 11095.518 | T24: =T25*T18 -> 11873.022 | ... V24: =V25*V18 -> 13073.009
B25: % of Sales | G25: =G24/G18 -> 0.10823391 | H25: =H24/H18 -> 0.10586169 | I25: =I24/I18 -> 0.018118306 | J25: =J24/J18 -> 0.097940268 | K25: =K24/K18 -> 0.097324575 | L25: =L24/L18 -> 0.10692218 | M25: {=OFFSET(M25,$D$5,,)} -> 0.11 | N25: {=OFFSET(N25,$D$5,,)} -> 0.1125 | O25: {=OFFSET(O25,$D$5,,)} -> 0.115 | P25: {=OFFSET(P25,$D$5,,)} -> 0.1175 | Q25: {=OFFSET(Q25,$D$5,,)} -> 0.12 | R25: {=OFFSET(R25,$D$5,,)} -> 0.1225 | S25: {=OFFSET(S25,$D$5,,)} -> 0.125 | T25: {=OFFSET(T25,$D$5,,)} -> 0.1275 | ... V25: {=OFFSET(V25,$D$5,,)} -> 0.13
B26: Conservative Case | M26: =M27-1% -> 0.1 | N26: =N27-1% -> 0.1025 | O26: =O27-1% -> 0.105 | P26: =P27-1% -> 0.1075 | Q26: =Q27-1% -> 0.11 | R26: =R27-1% -> 0.1125 | S26: =S27-1% -> 0.115 | T26: =T27-1% -> 0.1175 | ... V26: =V27-1% -> 0.12
B27: Base Case | M27: 0.11 | N27: 0.1125 | O27: 0.115 | P27: 0.1175 | Q27: 0.12 | R27: 0.1225 | S27: 0.125 | T27: 0.1275 | U27: 0.13 | V27: 0.13
B28: Optimisitic Case | M28: =M27+1% -> 0.12 | N28: =N27+1% -> 0.1225 | O28: =O27+1% -> 0.125 | P28: =P27+1% -> 0.1275 | Q28: =Q27+1% -> 0.13 | R28: =R27+1% -> 0.1325 | S28: =S27+1% -> 0.135 | T28: =T27+1% -> 0.1375 | ... V28: =V27+1% -> 0.14
B30: Taxes | G30: =Model!T27 -> 1113.413 | H30: =Model!U27 -> 1133.99 | I30: =Model!V27 -> -1.207 | J30: =Model!W27 -> 1115 | K30: =Model!X27 -> 1138 | L30: =Model!Y27 -> 1493 | M30: =M31*M24 -> 1611.896 | N30: =N31*N24 -> 1765.881 | O30: =O31*O24 -> 2020.0956 | P30: =P31*P24 -> 2220.67 | Q30: =Q31*Q24 -> 2440.3939 | R30: =R31*R24 -> 2678.6167 | S30: =S31*S24 -> 2884.8347 | T30: =T31*T24 -> 3086.9856 | ... V30: =V31*V24 -> 2614.6018
B31: Tax Rate (%) | G31: =G30/G24 -> 0.26395497 | H31: =H30/H24 -> 0.25677772 | I31: =I30/I24 -> -0.0020729286 | J31: =J30/J24 -> 0.23449001 | K31: =K30/K24 -> 0.23415638 | L31: =L30/L24 -> 0.25754701 | M31: {=OFFSET(M31,$D$6,,)} -> 0.26 | N31: {=OFFSET(N31,$D$6,,)} -> 0.26 | O31: {=OFFSET(O31,$D$6,,)} -> 0.26 | P31: {=OFFSET(P31,$D$6,,)} -> 0.26 | Q31: {=OFFSET(Q31,$D$6,,)} -> 0.26 | R31: {=OFFSET(R31,$D$6,,)} -> 0.26 | S31: {=OFFSET(S31,$D$6,,)} -> 0.26 | T31: {=OFFSET(T31,$D$6,,)} -> 0.26 | ... V31: {=OFFSET(V31,$D$6,,)} -> 0.2
B32: Conservative Case | M32: =M33+2% -> 0.28 | N32: =N33+2% -> 0.28 | O32: 0.15 | P32: 0.17 | Q32: 0.19 | R32: 0.2 | S32: 0.2 | T32: 0.2 | U32: 0.2 | V32: 0.2
B33: Base Case | M33: 0.26 | N33: 0.26 | O33: 0.26 | P33: 0.26 | Q33: 0.26 | R33: 0.26 | S33: 0.26 | T33: 0.26 | U33: 0.2 | V33: 0.2
B34: Optimisitic Case | M34: =M33-2% -> 0.24 | N34: =N33-2% -> 0.24 | O34: =O33-2% -> 0.24 | P34: =P33-2% -> 0.24 | Q34: =Q33-2% -> 0.24 | R34: =R33-2% -> 0.24 | S34: =S33-2% -> 0.24 | T34: =T33-2% -> 0.24 | U34: 0.2 | V34: 0.2
B36: Nopat | G36: =G24-G30 -> 3104.78 | H36: =H24-H30 -> 3282.242 | I36: =I24-I30 -> 583.475 | J36: =J24-J30 -> 3640 | K36: =K24-K30 -> 3722 | L36: =L24-L30 -> 4304 | M36: =M24-M30 -> 4587.704 | N36: =N24-N30 -> 5025.969 | ... V36: =V24-V30 -> 10458.407
B38: D&A | G38: =Model!T85 -> 819.655 | H38: =Model!U85 -> 867.303 | I38: =Model!V85 -> 870.758 | J38: =Model!W85 -> 868 | K38: =Model!X85 -> 887 | L38: =Model!Y85 -> 964 | M38: =M39*M18 -> 1014.48 | N38: =N39*N18 -> 1064.9621 | O38: =O39*O18 -> 1167.9531 | P38: =P39*P18 -> 1231.4692 | Q38: =Q39*Q18 -> 1298.6202 | R38: =R39*R18 -> 1368.3715 | S38: =S39*S18 -> 1415.3588 | T38: =T39*T18 -> 1455.1445 | ... V38: =V39*V18 -> 1509.1743
B39: % of Sales | G39: =G38/G18 -> 0.021031391 | H39: =H38/H18 -> 0.020790157 | I39: =I38/I18 -> 0.027095186 | J39: =J38/J18 -> 0.017878476 | K39: =K38/K18 -> 0.017762736 | L39: =L38/L18 -> 0.017780401 | M39: {=OFFSET(M39,$H$4,,)} -> 0.018 | N39: {=OFFSET(N39,$H$4,,)} -> 0.01764 | O39: {=OFFSET(O39,$H$4,,)} -> 0.0172872 | P39: {=OFFSET(P39,$H$4,,)} -> 0.016941456 | Q39: {=OFFSET(Q39,$H$4,,)} -> 0.016602627 | R39: {=OFFSET(R39,$H$4,,)} -> 0.016270574 | S39: {=OFFSET(S39,$H$4,,)} -> 0.015945163 | T39: {=OFFSET(T39,$H$4,,)} -> 0.01562626 | ... V39: {=OFFSET(V39,$H$4,,)} -> 0.01500746
B40: Conservative Case | M40: =M41-0.2% -> 0.016 | N40: =N41-0.2% -> 0.01564 | O40: =O41-0.2% -> 0.0152872 | P40: =P41-0.2% -> 0.014941456 | Q40: =Q41-0.2% -> 0.014602627 | R40: =R41-0.2% -> 0.014270574 | S40: =S41-0.2% -> 0.013945163 | T40: =T41-0.2% -> 0.01362626 | ... V40: =V41-0.2% -> 0.01300746
B41: Base Case | M41: 0.018 | N41: =M41*0.98 -> 0.01764 | O41: =N41*0.98 -> 0.0172872 | P41: =O41*0.98 -> 0.016941456 | Q41: =P41*0.98 -> 0.016602627 | R41: =Q41*0.98 -> 0.016270574 | S41: =R41*0.98 -> 0.015945163 | T41: =S41*0.98 -> 0.01562626 | U41: =T41*0.98 -> 0.015313734 | V41: =U41*0.98 -> 0.01500746
B42: Optimisitic Case | M42: =M41+0.2% -> 0.02 | N42: =N41+0.2% -> 0.01964 | O42: =O41+0.2% -> 0.0192872 | P42: =P41+0.2% -> 0.018941456 | Q42: =Q41+0.2% -> 0.018602627 | R42: =R41+0.2% -> 0.018270574 | S42: =S41+0.2% -> 0.017945163 | T42: =T41+0.2% -> 0.01762626 | ... V42: =V41+0.2% -> 0.01700746
B44: CapEx | G44: =-Model!T104 -> 1125.139 | H44: =-Model!U104 -> 1223.116 | I44: =-Model!V104 -> 568.021 | J44: =-Model!W104 -> 1045 | K44: =-Model!X104 -> 1457 | L44: =-Model!Y104 -> 1722 | M44: =M45*M18 -> 1803.52 | N44: =N45*N18 -> 1893.2659 | O44: =O45*O18 -> 2076.361 | P44: =P45*P18 -> 2189.2785 | Q44: =Q45*Q18 -> 2308.6581 | R44: =R45*R18 -> 2432.6604 | S44: =S45*S18 -> 2516.1933 | T44: =T45*T18 -> 2586.9235 | ... V44: =V45*V18 -> 2682.9765
B45: % of Sales | G45: =G44/G18 -> 0.028869754 | H45: =H44/H18 -> 0.029319366 | I45: =I44/I18 -> 0.017674985 | J45: =J44/J18 -> 0.021524202 | K45: =K44/K18 -> 0.029177347 | L45: =L44/L18 -> 0.031761256 | M45: {=OFFSET(M45,$H$5,,)} -> 0.032 | N45: {=OFFSET(N45,$H$5,,)} -> 0.03136 | O45: {=OFFSET(O45,$H$5,,)} -> 0.0307328 | P45: {=OFFSET(P45,$H$5,,)} -> 0.030118144 | Q45: {=OFFSET(Q45,$H$5,,)} -> 0.029515781 | R45: {=OFFSET(R45,$H$5,,)} -> 0.028925465 | S45: {=OFFSET(S45,$H$5,,)} -> 0.028346956 | T45: {=OFFSET(T45,$H$5,,)} -> 0.027780017 | ... V45: {=OFFSET(V45,$H$5,,)} -> 0.026679928
B46: Conservative Case | M46: =M47+0.5% -> 0.037 | N46: =N47+0.5% -> 0.03636 | O46: =O47+0.5% -> 0.0357328 | P46: =P47+0.5% -> 0.035118144 | Q46: =Q47+0.5% -> 0.034515781 | R46: =R47+0.5% -> 0.033925465 | S46: =S47+0.5% -> 0.033346956 | T46: =T47+0.5% -> 0.032780017 | ... V46: =V47+0.5% -> 0.031679928
B47: Base Case | M47: 0.032 | N47: =M47*0.98 -> 0.03136 | O47: =N47*0.98 -> 0.0307328 | P47: =O47*0.98 -> 0.030118144 | Q47: =P47*0.98 -> 0.029515781 | R47: =Q47*0.98 -> 0.028925465 | S47: =R47*0.98 -> 0.028346956 | T47: =S47*0.98 -> 0.027780017 | U47: =T47*0.98 -> 0.027224417 | V47: =U47*0.98 -> 0.026679928
B48: Optimisitic Case | M48: =M47-0.5% -> 0.027 | N48: =N47-0.5% -> 0.02636 | O48: =O47-0.5% -> 0.0257328 | P48: =P47-0.5% -> 0.025118144 | Q48: =Q47-0.5% -> 0.024515781 | R48: =R47-0.5% -> 0.023925465 | S48: =S47-0.5% -> 0.023346956 | T48: =T47-0.5% -> 0.022780017 | ... V48: =V47-0.5% -> 0.021679928
B50: Change in WC | G50: =Model!T102 -> 140.268 | H50: =Model!U102 -> -207.734 | I50: =Model!V102 -> 3376.805 | J50: =Model!W102 -> -1490 | K50: =Model!X102 -> -728 | L50: =Model!Y102 -> 405 | M50: =M51*M18 -> -441.62768 | N50: =N51*N18 -> -482.976 | O50: =O51*O18 -> -540.49381 | P50: =P51*P18 -> -581.51751 | Q50: =Q51*Q18 -> -625.74204 | R50: =R51*R18 -> -672.80796 | S50: =S51*S18 -> -710.11316 | T50: =T51*T18 -> -744.97391 | ... V50: =V51*V18 -> -804.49285
B51: % of Sales | G51: =G50/G18 -> 0.0035991132 | H51: =H50/H18 -> -0.0049796006 | I51: =I50/I18 -> 0.1050753 | J51: =J50/J18 -> -0.03069001 | K51: =K50/K18 -> -0.014578661 | L51: =L50/L18 -> 0.0074699817 | M51: {=OFFSET(M51,$H$6,,)} -> -0.0078358353 | N51: {=OFFSET(N51,$H$6,,)} -> -0.008 | O51: {=OFFSET(O51,$H$6,,)} -> -0.008 | P51: {=OFFSET(P51,$H$6,,)} -> -0.008 | Q51: {=OFFSET(Q51,$H$6,,)} -> -0.008 | R51: {=OFFSET(R51,$H$6,,)} -> -0.008 | S51: {=OFFSET(S51,$H$6,,)} -> -0.008 | T51: {=OFFSET(T51,$H$6,,)} -> -0.008 | ... V51: {=OFFSET(V51,$H$6,,)} -> -0.008
B52: Conservative Case | M52: =M53-0.5% -> -0.012835835 | N52: -0.02 | O52: -0.02 | P52: -0.02 | Q52: -0.02 | R52: -0.02 | S52: -0.02 | T52: -0.02 | U52: -0.02 | V52: -0.02
...
