Workbook

Sheet Main
A1: Virtu Financial
A2: numbers in mio USD | G2: Price | H2: 59.96
G3: Shares | H3: =84.577655+8.194847+60.09174 -> 152.86424 | I3: Q225
B4: IR | G4: MC | H4: =+H2*H3 -> 9165.74
B5: VIRT | G5: Cash | H5: 752.101 | I5: Q225
G6: Debt | H6: =251.754+1743.171 -> 1994.925 | I6: Q225
B7: Segments | C7: % of Rev | D7: Services | E7: Competitors | G7: EV | H7: =+H4-H5+H6 -> 10408.564
B8: Market Making | C8: 0.82491654 | D8: market making in every asset class | E8: Jane Street, Citadel
B9: Execution Services | C9: 0.16829361 | D9: Trading services and analytics | G9: Founded | H9: 2008 | I9: by Vincent Viola and Douglas Cifu
B10: Corporate | C10: 0.0067898442 | D10: Corporate
B12: Notes | G12: Management
B13: IPO 2015 | G13: CEO | H13: Aaron Simons
B14: 2017 Acquisition of KCG holdings for 1.4 billion USD | G14: CFO | H14: Cindy Lee
B15: 2019 Acquisition of ITG for 1billion USD
B17: Market making
B18: 25.000 OTC securities
B20: Biggest Risk
B21: performance will suffer if markets stabilize -> profits extremly from volatility
B22: https://finance.yahoo.com/news/virtu-financial-virt-down-4-153019856.html

Sheet Model
A1: Main
C2: Q124 | D2: Q224 | E2: Q324 | F2: Q424 | G2: Q125 | H2: Q225 | I2: Q325 | J2: Q425 | L2: FY16 | M2: FY17 | N2: FY18 | O2: FY19 | P2: FY20 | Q2: FY21 | R2: FY22 | S2: FY23 | T2: FY24
B3: Market Making | C3: 521.998 | D3: 569.783 | G3: 691.172 | H3: 786.593 | L3: 691.884 | M3: 836.707 | N3: 1384.475 | O3: 1028.094 | P3: 2593.342 | Q3: 2203.046 | R3: 1812.839 | S3: 1843.523 | T3: 2374.096
B4: Execution Services | C4: 117.788 | D4: 127.059 | G4: 141.008 | H4: 214.488 | L4: 92.14 | M4: 99.135 | N4: 496.333 | O4: 491.736 | P4: 650.143 | Q4: 600.215 | R4: 514.241 | S4: 446.542 | T4: 507.23
B5: Corporate | C5: 4.043 | D5: -3.857 | G5: 5.689 | H5: -1.508 | L5: 0.36 | M5: 10.352 | N5: -2.09 | O5: -2.338 | P5: -4.154 | Q5: 8.224 | R5: 37.732 | S5: 3.308 | T5: -4.377
B6: Trading Income | C6: 408.095 | D6: 426.395 | G6: 589.983 | H6: 652.796 | L6: 665.465 | M6: 766.027 | N6: 1266.682 | O6: 912.316 | P6: 2493.248 | Q6: 2105.194 | R6: 1628.898 | S6: 1301.344 | T6: 1822.437
B7: Interests and Dividends | C7: 105.992 | D7: 107.066 | G7: 109.053 | H7: 128.406 | L7: 26.419 | M7: 50.407 | N7: 87.508 | O7: 108.778 | P7: 62.119 | Q7: 75.384 | R7: 159.12 | S7: 462.566 | T7: 462.07
B8: Commissions and services | C8: 118.611 | D8: 126.101 | G8: 151.307 | H8: 153.859 | L8: 10.352 | M8: 116.503 | N8: 184.339 | O8: 498.544 | P8: 600.51 | Q8: 614.489 | R8: 529.845 | S8: 455.598 | T8: 516.783
B9: Other | C9: 10.141 | D9: 33.423 | G9: -12.474 | H9: 64.512 | L9: 0.036 | M9: 95.045 | N9: 340.189 | O9: -2.146 | P9: 83.454 | Q9: 16.418 | R9: 46.949 | S9: 73.865 | T9: 75.659
B10: Revenue | C10: =+SUM(C6:C9) -> 642.839 | D10: =+SUM(D6:D9) -> 692.985 | E10: =+SUM(E6:E9) -> 0 | F10: =+SUM(F6:F9) -> 0 | G10: =+SUM(G6:G9) -> 837.869 | H10: 999.573 | L10: =+SUM(L6:L9) -> 702.272 | M10: =+SUM(M6:M9) -> 1027.982 | N10: =+SUM(N6:N9) -> 1878.718 | O10: =+SUM(O6:O9) -> 1517.492 | P10: =+SUM(P6:P9) -> 3239.331 | Q10: =+SUM(Q6:Q9) -> 2811.485 | R10: =+SUM(R6:R9) -> 2364.812 | S10: =+SUM(S6:S9) -> 2293.373 | T10: =+SUM(T6:T9) -> 2876.949
B11: Brokerager, exchange, payment for order flow | C11: 139.799 | D11: 150.787 | G11: 221.875 | H11: 202.125 | L11: 221.214 | M11: =256.926+27.727 -> 284.653 | N11: =301.779+74.645 -> 376.424 | O11: 386.888 | P11: 758.843 | Q11: 745.434 | R11: 619.168 | S11: 508.358 | T11: 674.426
B12: Interest and Dividend Expense | C12: 126.028 | D12: 123.693 | G12: 131.328 | H12: 165.213 | L12: 56.557 | M12: 91.993 | N12: 141.814 | O12: 158.039 | P12: 125.649 | Q12: 139.704 | R12: 231.06 | S12: 500.467 | T12: 529.177
B13: Gross Profit | C13: =+C10-SUM(C11:C12) -> 377.012 | D13: =+D10-SUM(D11:D12) -> 418.505 | E13: =+E10-SUM(E11:E12) -> 0 | F13: =+F10-SUM(F11:F12) -> 0 | G13: =+G10-SUM(G11:G12) -> 484.666 | H13: =+H10-SUM(H11:H12) -> 632.235 | L13: =+L10-SUM(L11:L12) -> 424.501 | M13: =+M10-SUM(M11:M12) -> 651.336 | N13: =+N10-SUM(N11:N12) -> 1360.48 | O13: =+O10-SUM(O11:O12) -> 972.565 | P13: =+P10-SUM(P11:P12) -> 2354.839 | Q13: =+Q10-SUM(Q11:Q12) -> 1926.347 | R13: =+R10-SUM(R11:R12) -> 1514.584 | S13: =+S10-SUM(S11:S12) -> 1284.548 | T13: =+T10-SUM(T11:T12) -> 1673.346
B14: Communication and data processing | C14: 58.182 | D14: 59.327 | G14: 59.803 | H14: 61.435 | L14: 71.001 | M14: 131.506 | N14: 176.12 | O14: 209.393 | P14: 213.75 | Q14: 211.988 | R14: 219.505 | S14: 230.76 | T14: 236.446
B15: Employee compensation | C15: 100.823 | D15: 105.716 | G15: 119.356 | H15: 136.181 | L15: 85.295 | M15: 177.489 | N15: 215.556 | O15: 383.713 | P15: 393.536 | Q15: 376.282 | R15: 390.947 | S15: 394.039 | T15: 434.823
B16: Operations and administrative | C16: 22.346 | D16: 22.061 | G16: 22.136 | H16: 25.895 | L16: 23.358 | M16: 61.466 | N16: 64.749 | O16: 103.642 | P16: 94.558 | Q16: 88.149 | R16: 86.069 | S16: 98.972 | T16: 97.002
B17: D&A | C17: =16.076+14.687 -> 30.763 | D17: =16.078+12.153 -> 28.231 | G17: =15.932+11.783 -> 27.715 | H17: =15.618+11.783 -> 27.401 | L17: =29.703+0.211 -> 29.914 | M17: =47.327+15.447 -> 62.774 | N17: =61.154+26.123 -> 87.277 | O17: =65.644+70.595 -> 136.239 | P17: =66.741+74.254 -> 140.995 | Q17: =67.816+69.668 -> 137.484 | R17: =66.377+64.837 -> 131.214 | S17: =63.306+63.96 -> 127.266 | T17: =65.816+50.471 -> 116.287
B18: Transaction, advisor fees & other | C18: =0.135+0.017 -> 0.152 | D18: =0.016+0.06 -> 0.076 | G18: =0.338+0.01 -> 0.348 | H18: =0.011+0.059 -> 0.07 | L18: =-0.319+1.755 -> 1.436 | M18: =3.671+25.27+0.657+0.772 -> 30.37 | N18: =23.357+2.02+0.024+11.487 -> 36.888 | O18: =66.452+26.117 -> 92.569 | P18: =9.608+2.941 -> 12.549 | Q18: =28.138+0.843 -> 28.981 | R18: =6.982+1.124 -> 8.106 | S18: =0.445+0.314 -> 0.759 | T18: =0.313+16.224 -> 16.537
B19: Operating Income | C19: =+C13-SUM(C14:C18) -> 164.746 | D19: =+D13-SUM(D14:D18) -> 203.094 | E19: =+E13-SUM(E14:E18) -> 0 | F19: =+F13-SUM(F14:F18) -> 0 | G19: =+G13-SUM(G14:G18) -> 255.308 | H19: =+H13-SUM(H14:H18) -> 381.253 | L19: =+L13-SUM(L14:L18) -> 213.497 | M19: =+M13-SUM(M14:M18) -> 187.731 | N19: =+N13-SUM(N14:N18) -> 779.89 | O19: =+O13-SUM(O14:O18) -> 47.009 | P19: =+P13-SUM(P14:P18) -> 1499.451 | Q19: =+Q13-SUM(Q14:Q18) -> 1083.463 | R19: =+R13-SUM(R14:R18) -> 678.743 | S19: =+S13-SUM(S14:S18) -> 432.752 | T19: =+T13-SUM(T14:T18) -> 772.251
B20: Cost of debt | C20: 1.694 | D20: 24.279 | G20: 1.681 | H20: 1.682 | L20: 5.579 | M20: 10.46 | N20: 11.727 | O20: 41.132 | P20: 28.879 | Q20: 6.59 | R20: 29.91 | S20: 8.317 | T20: 29.479
B21: Interest on long term debt | C21: 23.232 | D21: 23.43 | G21: 29.891 | H21: 32.551 | L21: 28.327 | M21: 64.107 | N21: 71.8 | O21: 121.859 | P21: 87.735 | Q21: 79.969 | R21: 92.035 | S21: 99.294 | T21: 97.802
B22: Pretax Income | C22: =+C19-C20-C21 -> 139.82 | D22: =+D19-D20-D21 -> 155.385 | E22: =+E19-E20-E21 -> 0 | F22: =+F19-F20-F21 -> 0 | G22: =+G19-G20-G21 -> 223.736 | H22: =+H19-H20-H21 -> 347.02 | L22: =+L19-L20-L21 -> 179.591 | M22: =+M19-M20-M21 -> 113.164 | N22: =+N19-N20-N21 -> 696.363 | O22: =+O19-O20-O21 -> -115.982 | P22: =+P19-P20-P21 -> 1382.837 | Q22: =+Q19-Q20-Q21 -> 996.904 | R22: =+R19-R20-R21 -> 556.798 | S22: =+S19-S20-S21 -> 325.141 | T22: =+T19-T20-T21 -> 644.97
B23: Tax Expense | C23: 28.512 | D23: 27.268 | G23: 34.101 | H23: 54.044 | L23: 21.251 | M23: 94.266 | N23: 76.171 | O23: -12.277 | P23: 261.924 | Q23: 169.67 | R23: 88.466 | S23: 61.21 | T23: 110.435
B24: Minority Interest | C24: 55.491 | D24: 61.531 | G24: 89.985 | H24: 141.789 | L24: 125.36 | M24: 15.959 | N24: 330.751 | O24: -45.11 | P24: 471.716 | Q24: 350.356 | R24: 203.306 | S24: 121.885 | T24: 258.12
B25: Net Income | C25: =+C22-SUM(C23:C24) -> 55.817 | D25: =+D22-SUM(D23:D24) -> 66.586 | E25: =+E22-SUM(E23:E24) -> 0 | F25: =+F22-SUM(F23:F24) -> 0 | G25: =+G22-SUM(G23:G24) -> 99.65 | H25: =+H22-SUM(H23:H24) -> 151.187 | L25: =+L22-L23-L24 -> 32.98 | M25: =+M22-M23-M24 -> 2.939 | N25: =+N22-N23-N24 -> 289.441 | O25: =+O22-O23-O24 -> -58.595 | P25: =+P22-P23-P24 -> 649.197 | Q25: =+Q22-Q23-Q24 -> 476.878 | R25: =+R22-R23-R24 -> 265.026 | S25: =+S22-S23-S24 -> 142.046 | T25: =+T22-T23-T24 -> 276.415
B27: EPS | C27: =+C25/C28 -> 0.62716349 | D27: =+D25/D28 -> 0.75547609 | E27: =+E25/E28 -> #DIV/0! | F27: =+F25/F28 -> #DIV/0! | G27: =+G25/G28 -> 1.1630348 | H27: =+H25/H28 -> 1.7684733 | L27: =+L25/L28 -> 0.85575471 | M27: =+M25/M28 -> 0.046964526 | N27: =+N25/N28 -> 2.869281 | O27: =+O25/O28 -> -0.51436074 | P27: =+P25/P28 -> 5.3347355 | Q27: =+Q25/Q28 -> 4.0640862 | R27: =+R25/R28 -> 2.5483326 | S27: =+S25/S28 -> 1.4955963 | T27: =+T25/T28 -> 3.1596727
B28: Shares | C28: 88.999122 | D28: 88.137799 | G28: 85.681015 | H28: 85.490121 | L28: 38.539081 | M28: 62.579147 | N28: 100.87579 | O28: 113.9181 | P28: 121.69244 | Q28: 117.33954 | R28: 103.99977 | S28: 94.976165 | T28: 87.482162
B30: Market Making Growth | G30: =+G3/C3-1 -> 0.32408936 | H30: =+H3/D3-1 -> 0.38051328 | M30: =+M3/L3-1 -> 0.20931688 | N30: =+N3/M3-1 -> 0.65467123 | O30: =+O3/N3-1 -> -0.25741238 | P30: =+P3/O3-1 -> 1.5224756 | Q30: =+Q3/P3-1 -> -0.15049924 | R30: =+R3/Q3-1 -> -0.17712159 | S30: =+S3/R3-1 -> 0.016925938 | T30: =+T3/S3-1 -> 0.28780384
B31: Execution Services Growth | G31: =+G4/C4-1 -> 0.19713383 | H31: =+H4/D4-1 -> 0.68809766 | M31: =+M4/L4-1 -> 0.075917083 | N31: =+N4/M4-1 -> 4.0066374 | O31: =+O4/N4-1 -> -0.009261927 | P31: =+P4/O4-1 -> 0.3221383 | Q31: =+Q4/P4-1 -> -0.076795413 | R31: =+R4/Q4-1 -> -0.14323867 | S31: =+S4/R4-1 -> -0.13164839 | T31: =+T4/S4-1 -> 0.13590659
B32: Trading Income Growth | G32: =+G6/C6-1 -> 0.44570014 | H32: =+H6/D6-1 -> 0.53096542 | M32: =+M6/L6-1 -> 0.15111539 | N32: =+N6/M6-1 -> 0.65357357 | O32: =+O6/N6-1 -> -0.27975925 | P32: =+P6/O6-1 -> 1.7328776 | Q32: =+Q6/P6-1 -> -0.15564196 | R32: =+R6/Q6-1 -> -0.22624803 | S32: =+S6/R6-1 -> -0.20108933 | T32: =+T6/S6-1 -> 0.40042679
B33: Interest/Dividends Growth | G33: =+G7/C7-1 -> 0.028879538 | H33: =+H7/D7-1 -> 0.19931631 | M33: =+M7/L7-1 -> 0.90798289 | N33: =+N7/M7-1 -> 0.73602873 | O33: =+O7/N7-1 -> 0.24306349 | P33: =+P7/O7-1 -> -0.42893784 | Q33: =+Q7/P7-1 -> 0.21354175 | R33: =+R7/Q7-1 -> 1.1107927 | S33: =+S7/R7-1 -> 1.9070261 | T33: =+T7/S7-1 -> -0.0010722794
B34: Commission Growth | G34: =+G8/C8-1 -> 0.2756574 | H34: =+H8/D8-1 -> 0.22012514 | M34: =+M8/L8-1 -> 10.254154 | N34: =+N8/M8-1 -> 0.58226827 | O34: =+O8/N8-1 -> 1.7044955 | P34: =+P8/O8-1 -> 0.20452758 | Q34: =+Q8/P8-1 -> 0.023278547 | R34: =+R8/Q8-1 -> -0.13774697 | S34: =+S8/R8-1 -> -0.14012966 | T34: =+T8/S8-1 -> 0.13429602
B35: Revenue Growth | G35: =+G10/C10-1 -> 0.30338856 | H35: =+H10/D10-1 -> 0.4424165 | M35: =+M10/L10-1 -> 0.46379466 | N35: =+N10/M10-1 -> 0.82757869 | O35: =+O10/N10-1 -> -0.1922726 | P35: =+P10/O10-1 -> 1.134661 | Q35: =+Q10/P10-1 -> -0.13207851 | R35: =+R10/Q10-1 -> -0.1588744 | S35: =+S10/R10-1 -> -0.030209167 | T35: =+T10/S10-1 -> 0.25446188
B36: Gross Margin | C36: =+C13/C10 -> 0.58647966 | D36: =+D13/D10 -> 0.60391639 | E36: =+E13/E10 -> #DIV/0! | F36: =+F13/F10 -> #DIV/0! | G36: =+G13/G10 -> 0.57845081 | H36: =+H13/H10 -> 0.63250508 | M36: =+M13/M10 -> 0.63360643 | N36: =+N13/N10 -> 0.72415339 | O36: =+O13/O10 -> 0.64090288 | P36: =+P13/P10 -> 0.72695226 | Q36: =+Q13/Q10 -> 0.68517065 | R36: =+R13/R10 -> 0.64046698 | S36: =+S13/S10 -> 0.56011299 | T36: =+T13/T10 -> 0.58163909
B37: Operating Margin | C37: =+C19/C10 -> 0.25627879 | D37: =+D19/D10 -> 0.29307128 | E37: =+E19/E10 -> #DIV/0! | F37: =+F19/F10 -> #DIV/0! | G37: =+G19/G10 -> 0.30471112 | H37: =+H19/H10 -> 0.38141586 | M37: =+M19/M10 -> 0.1826209 | N37: =+N19/N10 -> 0.41511818 | O37: =+O19/O10 -> 0.030978088 | P37: =+P19/P10 -> 0.4628891 | Q37: =+Q19/Q10 -> 0.38537036 | R37: =+R19/R10 -> 0.28701774 | S37: =+S19/S10 -> 0.18869674 | T37: =+T19/T10 -> 0.26842707
B38: Tax Rate | C38: =+C23/C22 -> 0.20391932 | D38: =+D23/D22 -> 0.17548669 | E38: =+E23/E22 -> #DIV/0! | F38: =+F23/F22 -> #DIV/0! | G38: =+G23/G22 -> 0.15241624 | H38: =+H23/H22 -> 0.15573742 | M38: =+M23/M22 -> 0.83300343 | N38: =+N23/N22 -> 0.10938404 | O38: =+O23/O22 -> 0.10585263 | P38: =+P23/P22 -> 0.18941061 | Q38: =+Q23/Q22 -> 0.17019693 | R38: =+R23/R22 -> 0.15888347 | S38: =+S23/S22 -> 0.18825679 | T38: =+T23/T22 -> 0.17122502
B40: Cash & Cash Equivalents | P40: 889.559 | Q40: 1071.463 | R40: 981.58 | S40: 820.436 | T40: 872.513
B41: Restricted Cash | P41: 117.446 | Q41: 49.49 | R41: 56.662 | S41: 35.024 | T41: 41.478
B42: Securrities Borrowed | P42: 1425.016 | Q42: 1349.322 | R42: 1187.674 | S42: 1722.44 | T42: 2294.529
B43: Securrities purchased to resell | P43: 22.866 | Q43: 119.453 | R43: 336.999 | S43: 1512.114 | T43: 983.941
...

Sheet Ratios
A1: Main
B2: Ratios | C2: 18 | D2: =+C2+1 -> 19 | E2: =+D2+1 -> 20 | F2: =+E2+1 -> 21 | G2: =+F2+1 -> 22 | H2: =+G2+1 -> 23 | I2: =+H2+1 -> 24 | J2: =+I2+1 -> 25
B3: Price | C3: 19.71 | D3: 12.84 | E3: 21.11 | F3: 25.04 | G3: 18.4 | H3: 19.25 | I3: 35.23
B4: Shares o/s | C4: =107.329814+13.509886+60.09174 -> 180.93144 | D4: =119.921738+12.162851+60.0974 -> 192.18199 | E4: =122.186196+10.135182+60.09174 -> 192.41312 | F4: =108.77295+9.053155+60.09174 -> 177.91784 | G4: =97.877807+8.856531+60.09174 -> 166.82608 | H4: =89.415191+8.607998+60.09174 -> 158.11493 | I4: =86.618617+8.194847+60.09174 -> 154.9052
B5: Market Cap | C5: =+C3*C4 -> 3566.1587 | D5: =+D3*D4 -> 2467.6167 | E5: =+E3*E4 -> 4061.8409 | F5: =+F3*F4 -> 4455.0628 | G5: =+G3*G4 -> 3069.5998 | H5: =+H3*H4 -> 3043.7124 | I5: =+I3*I4 -> 5457.3103
B6: Net Debt | C6: =+Model!N57+Model!N67-Model!N40 -> 0 | D6: =+Model!O57+Model!O67-Model!O40 -> 0 | E6: =+Model!P57+Model!P67-Model!P40 -> -509.533 | F6: =+Model!Q57+Model!Q67-Model!Q40 -> -731.208 | G6: =+Model!R57+Model!R67-Model!R40 -> -981.58 | H6: =+Model!S57+Model!S67-Model!S40 -> 906.769 | I6: =+Model!T57+Model!T67-Model!T40 -> 906.495
B7: EV | C7: =+C5+C6 -> 3566.1587 | D7: =+D5+D6 -> 2467.6167 | E7: =+E5+E6 -> 3552.3079 | F7: =+F5+F6 -> 3723.8548 | G7: =+G5+G6 -> 2088.0198 | H7: =+H5+H6 -> 3950.4814 | I7: =+I5+I6 -> 6363.8053
A9: x | B9: Value Driver
B10: Capital Emloyed | E10: =+Model!P49+Model!P51+Model!P52+Model!P42+Model!P43+Model!P44+Model!P45+Model!P46+Model!P47-Model!P58-Model!P59-Model!P60-Model!P64 -> 5893.175 | F10: =+Model!Q49+Model!Q51+Model!Q52+Model!Q42+Model!Q43+Model!Q44+Model!Q45+Model!Q46+Model!Q47-Model!Q58-Model!Q59-Model!Q60-Model!Q64 -> 6295.902 | G10: =+Model!R49+Model!R51+Model!R52+Model!R42+Model!R43+Model!R44+Model!R45+Model!R46+Model!R47-Model!R58-Model!R59-Model!R60-Model!R64 -> 8906.84 | H10: =+Model!S49+Model!S51+Model!S52+Model!S42+Model!S43+Model!S44+Model!S45+Model!S46+Model!S47-Model!S58-Model!S59-Model!S60-Model!S64 -> 8199.5 | I10: =+Model!T49+Model!T51+Model!T52+Model!T42+Model!T43+Model!T44+Model!T45+Model!T46+Model!T47-Model!T58-Model!T59-Model!T60-Model!T64 -> 8594.973 | L10: =Long Term Assets + Working Capital (Exclusive of cash)-Accounts Payables
B11: Invested Capital | E11: =+Model!P41+Model!P42+Model!P43+Model!P44+Model!P45+Model!P46+Model!P47+Model!P49+Model!P54-Model!P58-Model!P59-Model!P60-Model!P61-Model!P63-Model!P64-Model!P68+Model!P52+Model!P51 -> 4299.097 | F11: =+Model!Q41+Model!Q42+Model!Q43+Model!Q44+Model!Q45+Model!Q46+Model!Q47+Model!Q49+Model!Q54-Model!Q58-Model!Q59-Model!Q60-Model!Q61-Model!Q63-Model!Q64-Model!Q68+Model!Q52+Model!Q51 -> 4717.285 | G11: =+Model!R41+Model!R42+Model!R43+Model!R44+Model!R45+Model!R46+Model!R47+Model!R49+Model!R54-Model!R58-Model!R59-Model!R60-Model!R61-Model!R63-Model!R64-Model!R68+Model!R52+Model!R51 -> 9267.418 | H11: =+Model!S41+Model!S42+Model!S43+Model!S44+Model!S45+Model!S46+Model!S47+Model!S49+Model!S54-Model!S58-Model!S59-Model!S60-Model!S61-Model!S63-Model!S64-Model!S68+Model!S52+Model!S51 -> 8298.535 | I11: =+Model!T41+Model!T42+Model!T43+Model!T44+Model!T45+Model!T46+Model!T47+Model!T49+Model!T54-Model!T58-Model!T59-Model!T60-Model!T61-Model!T63-Model!T64-Model!T68+Model!T52+Model!T51 -> 8754.576 | L11: =Net Working Capital + PP&E + Other Net Operating Assets (net of Liabilties) + (Intangibles)
B12: Invested Capital (exl. Intangibles) | E12: =+Model!P41+Model!P42+Model!P43+Model!P44+Model!P45+Model!P46+Model!P47+Model!P49+Model!P54-Model!P58-Model!P59-Model!P60-Model!P61-Model!P63-Model!P64-Model!P68 -> 2695.672 | F12: =+Model!Q41+Model!Q42+Model!Q43+Model!Q44+Model!Q45+Model!Q46+Model!Q47+Model!Q49+Model!Q54-Model!Q58-Model!Q59-Model!Q60-Model!Q61-Model!Q63-Model!Q64-Model!Q68 -> 3182.027 | G12: =+Model!R41+Model!R42+Model!R43+Model!R44+Model!R45+Model!R46+Model!R47+Model!R49+Model!R54-Model!R58-Model!R59-Model!R60-Model!R61-Model!R63-Model!R64-Model!R68 -> 7797.012 | H12: =+Model!S41+Model!S42+Model!S43+Model!S44+Model!S45+Model!S46+Model!S47+Model!S49+Model!S54-Model!S58-Model!S59-Model!S60-Model!S61-Model!S63-Model!S64-Model!S68 -> 6892.089 | I12: =+Model!T41+Model!T42+Model!T43+Model!T44+Model!T45+Model!T46+Model!T47+Model!T49+Model!T54-Model!T58-Model!T59-Model!T60-Model!T61-Model!T63-Model!T64-Model!T68 -> 7402.462
B13: Total Funds Invested | E13: =+E11+Model!P40+Model!P41-Model!P57-Model!P67 -> 4926.076 | F13: =+F11+Model!Q40+Model!Q41-Model!Q57-Model!Q67 -> 5497.983 | G13: =+G11+Model!R40+Model!R41-Model!R57-Model!R67 -> 10305.66 | H13: =+H11+Model!S40+Model!S41-Model!S57-Model!S67 -> 7426.79 | I13: =+I11+Model!T40+Model!T41-Model!T57-Model!T67 -> 7889.559 | L13: Invested Capital + Non-Operating Assets
B14: NOPAT | E14: =+Model!P19*(1-Model!P38) -> 1215.4391 | F14: =+Model!Q19*(1-Model!Q38) -> 899.06092 | G14: =+Model!R19*(1-Model!R38) -> 570.90195 | H14: =+Model!S19*(1-Model!S38) -> 351.2835 | I14: =+Model!T19*(1-Model!T38) -> 640.02231 | L14: EBITA * (1-Marginal Tax Rate)
B15: Net Investment | L15: =Invested Capital (t+1)-Invested Capital (t)
B16: FCF | L16: =NOPAT + non-cash Expenses - Investments in Invested Capital
B17: Investment Rate | L17: =Net Investment/NOPAT
B18: Economic Profit | L18: =Invested Capital *(ROIC-WACC)
A20: x | B20: Efficency-Ratios
B21: Capital Turnover | L21: =Revenue/Equity
B22: Return on Equity (ROE) | L22: =Net Income/Book Value of Equity
B23: Return on Capital Employed (ROCE) | L23: =EBIT/Capital Employed
B24: Return on Capital Invested (ROIC) | C24: =+C14/C11 -> #DIV/0! | D24: =+D14/D11 -> #DIV/0! | E24: =+E14/E11 -> 0.28271962 | F24: =+F14/F11 -> 0.19058864 | G24: =+G14/G11 -> 0.06160313 | H24: =+H14/H11 -> 0.042330785 | I24: =+I14/I11 -> 0.073107174 | L24: =NOPAT/Invested Capital
B25: ROIC without Intangibles | C25: =+C14/C12 -> #DIV/0! | D25: =+D14/D12 -> #DIV/0! | E25: =+E14/E12 -> 0.45088537 | F25: =+F14/F12 -> 0.28254346 | G25: =+G14/G12 -> 0.073220607 | H25: =+H14/H12 -> 0.050969089 | I25: =+I14/I12 -> 0.086460735 | L25: =NOPAT/(Invested Capital exclusive of Intangibles)
B26: Decomposed ROIC | L26: = ROIC = (1-operating cash tax)* (EBITA/Revenues) * (Revenue/Invested Capital)
B28: Retention Rate | L28: =1 - Dividends/Net Income
B29: Reinvestment Rate | L29: =Net CapEx + Change in WC / EBIT * (1-t)
B30: Epected Growth in Net Income | L30: =ROE * Retention Rate
B31: Expected Growth in NOPAT | L31: =ROIC * Reinvestment Rate
A33: x | B33: Finacial Stability Ratios
B34: Equity/Debt Ratio | L34: =Book Value of Equtiy/Book Value of Debt
B35: Gearing | L35: =(Debt - Cash (Net Debt))/Book Value of Equity
B36: Interest Coverage Ratio | L36: =EBIT/Interest Expenses
B37: Net Debt / EBITDA | L37: =Net Debt/EBITDA
B38: Cash Burn Rate | L38: =Book Value of Equity/Absolute value of Loss
A40: x | B40: WC-Managment Ratios
B41: Debitor-Duration | L41: =Accounts Receivables/Revenue*360
B42: Creditor-Duration | L42: =Accounts Payable/Revenue*360
B43: Inventory Intensity | L43: =Inventory/Balance Sheet Total
B44: Invetory Turnover | L44: =Cogs/Inventory
B45: Storage-Duration | L45: =360/Inventory Turnover
...

Sheet CoC
A1: Main
B3: Cost of Capital
A4: x | B4: Cost of Equity (CAPM)
B5: Riskfree Rate
B6: Expected Inflation | H6: =(1+Nominal Rate)/(1+Real Rate)-1
B7: Average Real Interest Rate | H7: = Average Interest Rate of the Past
B8: Riskfree Rate | F8: =F6+F7 -> 0 | H8: =Goverment Bond or Expected Inflation + Average Real Interest Rate
A10: x | B10: Adjustments for Industry/Company Risk
B11: Raw Beta | H11: =Raw beta slope of regression line aginst total market -> Ri= alpha + beta*Rm + standard error
B12: Debt to Value Ratio | H12: Value of Debt/Enterpries Value
B13: Unlevered Beta | H13: = Raw Beta* Debt-to-Equity Ratio (Book Value)
B14: Unlevered Industry Beta | H14: =Median of Peer Group
B15: Levered Industry Beta | H15: =Unlevered Industry Beta * Market Value of Debt to Market Value of Equity
A17: x | B17: Expected Equity Risk Premium
B18: Estimated Future Market Return | H18: = 1/P/E * (1.g/ROE) + g , g = real growth in GDP, P/E => P/E ratio for S&P500 or MSCI World Index, ROE = Average ROE in S&P500 or MSCI World
B19: Riskfree Rate
B20: Expected Equity Risk Premium | F20: =F18-F19 -> 0
A22: x | B22: Cost of Equity (CAPM) | F22: =F8+F15*F20 -> 0 | H22: => ER(i)=rf+beta(i)*(Er(m)-rf)
A25: x | B25: Cost of Debt
B26: Yield to Maturity on Trading Bonds | H26: => Price = Coupon/(1+YTM)+Coupon(1+YTM)^2 + … + (Face Value + Coupon)/(1+YTM)^n => solve for YTM
B27: or
B28: Riskfree Rate
B29: Credit Default Spread
B30: Country Rsik Premium
A32: x | B32: Cost of Debt | F32: =F28+F29+F30 -> 0
A34: x | B34: Capital Structure
B35: Market Value of Debt
B36: Market Value of Equity
B37: Total Enterprise Value | F37: =F35+F36 -> 0
B39: Marginal Tax Rate
A41: x | B41: WACC | F41: =(F32*(F35/F37)*(1-F39))+((F36/F38)*F22) -> #DIV/0! | H41: => WACC = (D/D+E)*kd * (1-t) + (E/D+E) * ke
I47: =SLOPE(H48:H52,K48:K52) -> #DIV/0!
H48: Change

Sheet DCF
A1: Main | B1: DCF
B3: Ticker | E3: VIRT | G3: Share Price | J3: =+Main!H2 -> 59.96 | L3: Share Price | O3: =+J3 -> 59.96
B4: Date | E4: =+TODAY() -> 46227 | G4: Fair Share Price | J4: =V62 -> 58.626233 | L4: Scneario DCF Price | O4: =+J15+O15+T15 -> 0
B5: End of FY | E5: 46022 | G5: Implied Upside | J5: =J4/J3-1 -> -0.022244279 | L5: Implied Upside | O5: =O4/O3-1 -> -1
A7: x | B7: Assumptions
B9: Switches | G9: Conservative Case | L9: Base Case | Q9: Optimistic Case
B10: Assumptions | G10: Assumptions | I10: Year | J10: Metic | L10: Assumptions | N10: Year | O10: Metic | Q10: Assumptions | S10: Year | T10: Metic
B11: Revenue | E11: 1 | G11: Revenue | L11: Revenue | Q11: Revenue
B12: EBIT | E12: 1 | G12: EBIT | L12: EBIT | Q12: EBIT
B13: WACC | E13: 1 | G13: Implied Share Price
B14: TGR | E14: 1 | G14: Probability | L14: Probability | Q14: Probability
B15: ROIC | E15: 1 | G15: Implied Share Price * p | L15: Implied Share Price * p | Q15: Implied Share Price * p
B17: Valuation
B18: WACC | E18: =CHOOSE(E13,J18,O18,T18) -> 0.1 | G18: WACC | J18: 0.1 | L18: WACC | O18: 0.09 | Q18: WACC
B19: TGR | E19: =CHOOSE(E14,J19,O19,T19) -> 0.025 | G19: TGR | J19: 0.025 | L19: TGR | O19: 0.03 | Q19: TGR
B20: RONIC | E20: =CHOOSE(E15,J20,O20,T20) -> 0.11 | G20: RONIC | J20: 0.11 | L20: RONIC | O20: 0.12 | Q20: RONIC
A24: x | B24: Model | G24: 19 | H24: =G24+1 -> 20 | I24: =H24+1 -> 21 | J24: =I24+1 -> 22 | K24: =J24+1 -> 23 | L24: =K24+1 -> 24 | M24: =L24+1 -> 25 | N24: =M24+1 -> 26 | O24: =N24+1 -> 27 | ... V24: =U24+1 -> 34
B25: Revenue | G25: =+Model!O10 -> 1517.492 | H25: =+Model!P10 -> 3239.331 | I25: =+Model!Q10 -> 2811.485 | J25: =+Model!R10 -> 2364.812 | K25: =+Model!S10 -> 2293.373 | L25: =+Model!T10 -> 2876.949 | M25: =L25*(1+M26) -> 3020.7965 | N25: =M25*(1+N26) -> 3171.8363 | O25: =N25*(1+O26) -> 3330.4281 | P25: =O25*(1+P26) -> 3496.9495 | Q25: =P25*(1+Q26) -> 3671.797 | R25: =Q25*(1+R26) -> 3855.3868 | S25: =R25*(1+S26) -> 4048.1562 | T25: =S25*(1+T26) -> 4250.564 | ... V25: =U25*(1+V26) -> 4686.2468
B26: Growth (%) | H26: =H25/G25-1 -> 1.134661 | I26: =I25/H25-1 -> -0.13207851 | J26: =J25/I25-1 -> -0.1588744 | K26: =K25/J25-1 -> -0.030209167 | L26: =L25/K25-1 -> 0.25446188 | M26: {=OFFSET(M26,$E$11,,)} -> 0.05 | N26: {=OFFSET(N26,$E$11,,)} -> 0.05 | O26: {=OFFSET(O26,$E$11,,)} -> 0.05 | P26: {=OFFSET(P26,$E$11,,)} -> 0.05 | Q26: {=OFFSET(Q26,$E$11,,)} -> 0.05 | R26: {=OFFSET(R26,$E$11,,)} -> 0.05 | S26: {=OFFSET(S26,$E$11,,)} -> 0.05 | T26: {=OFFSET(T26,$E$11,,)} -> 0.05 | ... V26: {=OFFSET(V26,$E$11,,)} -> 0.05
B27: Conservative Case | M27: 0.05 | N27: 0.05 | O27: 0.05 | P27: 0.05 | Q27: 0.05 | R27: 0.05 | S27: 0.05 | T27: 0.05 | U27: 0.05 | V27: 0.05
B28: Base Case | M28: 0.44 | N28: -0.1 | O28: 0.1 | P28: 0.1 | Q28: 0.1 | R28: 0.1 | S28: 0.1 | T28: 0.1 | U28: 0.1 | V28: 0.1
B29: Optimisitic Case
B31: EBIT | G31: =+Model!O19 -> 47.009 | H31: =+Model!P19 -> 1499.451 | I31: =+Model!Q19 -> 1083.463 | J31: =+Model!R19 -> 678.743 | K31: =+Model!S19 -> 432.752 | L31: =+Model!T19 -> 772.251 | M31: =M32*M25 -> 876.03097 | N31: =N32*N25 -> 919.83252 | O31: =O32*O25 -> 965.82414 | P31: =P32*P25 -> 1014.1154 | Q31: =Q32*Q25 -> 1064.8211 | R31: =R32*R25 -> 1118.0622 | S31: =S32*S25 -> 1173.9653 | T31: =T32*T25 -> 1232.6635 | ... V31: =V32*V25 -> 1359.0116
B32: % of Sales | G32: =G31/G25 -> 0.030978088 | H32: =H31/H25 -> 0.4628891 | I32: =I31/I25 -> 0.38537036 | J32: =J31/J25 -> 0.28701774 | K32: =K31/K25 -> 0.18869674 | L32: =L31/L25 -> 0.26842707 | M32: {=OFFSET(M32,$E$12,,)} -> 0.29 | N32: {=OFFSET(N32,$E$12,,)} -> 0.29 | O32: {=OFFSET(O32,$E$12,,)} -> 0.29 | P32: {=OFFSET(P32,$E$12,,)} -> 0.29 | Q32: {=OFFSET(Q32,$E$12,,)} -> 0.29 | R32: {=OFFSET(R32,$E$12,,)} -> 0.29 | S32: {=OFFSET(S32,$E$12,,)} -> 0.29 | T32: {=OFFSET(T32,$E$12,,)} -> 0.29 | ... V32: {=OFFSET(V32,$E$12,,)} -> 0.29
B33: Conservative Case | M33: 0.29 | N33: 0.29 | O33: 0.29 | P33: 0.29 | Q33: 0.29 | R33: 0.29 | S33: 0.29 | T33: 0.29 | U33: 0.29 | V33: 0.29
B34: Base Case | M34: 0.35 | N34: 0.3 | O34: 0.3 | P34: 0.3 | Q34: 0.3 | R34: 0.3 | S34: 0.3 | T34: 0.3 | U34: 0.3 | V34: 0.3
B35: Optimisitic Case
B37: Taxes | G37: =+Model!O23 -> -12.277 | H37: =+Model!P23 -> 261.924 | I37: =+Model!Q23 -> 169.67 | J37: =+Model!R23 -> 88.466 | K37: =+Model!S23 -> 61.21 | L37: =+Model!T23 -> 110.435 | M37: =M38*M31 -> 131.40465 | N37: =N38*N31 -> 142.57404 | O37: =O38*O31 -> 154.53186 | P37: =P38*P31 -> 167.32903 | Q37: =Q38*Q31 -> 181.01959 | R37: =R38*R31 -> 195.66088 | S37: =S38*S31 -> 211.31375 | T37: =T38*T31 -> 228.04276 | ... V37: =V38*V31 -> 271.80231
B38: Tax Rate (%) | G38: =G37/G31 -> -0.26116276 | H38: =H37/H31 -> 0.17467993 | I38: =I37/I31 -> 0.15659972 | J38: =J37/J31 -> 0.13033799 | K38: =K37/K31 -> 0.1414436 | L38: =L37/L31 -> 0.14300402 | M38: 0.15 | N38: 0.155 | O38: 0.16 | P38: 0.165 | Q38: 0.17 | R38: 0.175 | S38: 0.18 | T38: 0.185 | U38: 0.19 | V38: 0.2
B40: Nopat | G40: =G31-G37 -> 59.286 | H40: =H31-H37 -> 1237.527 | I40: =I31-I37 -> 913.793 | J40: =J31-J37 -> 590.277 | K40: =K31-K37 -> 371.542 | L40: =L31-L37 -> 661.816 | M40: =M31-M37 -> 744.62632 | N40: =N31-N37 -> 777.25848 | ... V40: =V31-V37 -> 1087.2093
B42: D&A and other non-cash Expenses | G42: =+Model!O75 -> 147.869 | H42: =+Model!P75 -> 167.143 | I42: =+Model!Q75 -> 144.423 | J42: =+Model!R75 -> 138.133 | K42: =+Model!S75 -> 138.654 | L42: =+Model!T75 -> 123.148 | M42: =M43*M25 -> 160.10221 | N42: =N43*N25 -> 168.10732 | O42: =O43*O25 -> 176.51269 | P42: =P43*P25 -> 185.33832 | Q42: =Q43*Q25 -> 194.60524 | R42: =R43*R25 -> 204.3355 | S42: =S43*S25 -> 214.55228 | T42: =T43*T25 -> 225.27989 | ... V42: =V43*V25 -> 248.37108
B43: % of Sales | G43: =G42/G25 -> 0.097443018 | H43: =H42/H25 -> 0.051598 | I43: =I42/I25 -> 0.051368938 | J43: =J42/J25 -> 0.058411831 | K43: =K42/K25 -> 0.060458547 | L43: =L42/L25 -> 0.042805069 | M43: 0.053 | N43: 0.053 | O43: 0.053 | P43: 0.053 | Q43: 0.053 | R43: 0.053 | S43: 0.053 | T43: 0.053 | U43: 0.053 | V43: 0.053
B45: CapEx | G45: =+Model!O83+Model!O84+Model!O85 -> -899.643 | H45: =+Model!P83+Model!P84+Model!P85 -> -2.559 | I45: =+Model!Q83+Model!Q84+Model!Q85 -> -87.349 | J45: =+Model!R83+Model!R84+Model!R85 -> -29.53 | K45: =+Model!S83+Model!S84+Model!S85 -> -94.484 | L45: =+Model!T83+Model!T84+Model!T85 -> -61.847 | M45: =M46*M25 -> -63.436725 | N45: =N46*N25 -> -66.608562 | O45: =O46*O25 -> -69.93899 | P45: =P46*P25 -> -73.435939 | Q45: =Q46*Q25 -> -77.107736 | R45: =R46*R25 -> -80.963123 | S45: =S46*S25 -> -85.011279 | T45: =T46*T25 -> -89.261843 | ... V45: =V46*V25 -> -98.411182
B46: % of Sales | G46: =G45/G25 -> -0.59284859 | H46: =H45/H25 -> -0.00078997793 | I46: =I45/I25 -> -0.031068635 | J46: =J45/J25 -> -0.012487251 | K46: =K45/K25 -> -0.041198706 | L46: =L45/L25 -> -0.021497427 | M46: -0.021 | N46: -0.021 | O46: -0.021 | P46: -0.021 | Q46: -0.021 | R46: -0.021 | S46: -0.021 | T46: -0.021 | U46: -0.021 | V46: -0.021
B48: Change in WC | G48: =+Model!O81 -> -12.66 | H48: =+Model!P81 -> -265.196 | I48: =+Model!Q81 -> 86.37 | J48: =+Model!R81 -> -3.828 | K48: =+Model!S81 -> 17.442 | L48: =+Model!T81 -> -140.056 | M48: =M49*M25 -> -60.415929 | N48: =N49*N25 -> -63.436725 | O48: =O49*O25 -> -66.608562 | P48: =P49*P25 -> -69.93899 | Q48: =Q49*Q25 -> -73.435939 | R48: =R49*R25 -> -77.107736 | S48: =S49*S25 -> -80.963123 | T48: =T49*T25 -> -85.011279 | ... V48: =V49*V25 -> -93.724935
B49: % of Sales | G49: =G48/G25 -> -0.0083427128 | H49: =H48/H25 -> -0.081867521 | I49: =I48/I25 -> 0.03072042 | J49: =J48/J25 -> -0.0016187333 | K49: =K48/K25 -> 0.0076053917 | L49: =L48/L25 -> -0.048682128 | M49: -0.02 | N49: -0.02 | O49: -0.02 | P49: -0.02 | Q49: -0.02 | R49: -0.02 | S49: -0.02 | T49: -0.02 | U49: -0.02 | V49: -0.02
B51: Unlevered Free Cashflow | G51: =G40+G42+G45+G48 -> -705.148 | H51: =H40+H42+H45+H48 -> 1136.915 | I51: =I40+I42+I45+I48 -> 1057.237 | J51: =J40+J42+J45+J48 -> 695.052 | K51: =K40+K42+K45+K48 -> 433.154 | L51: =L40+L42+L45+L48 -> 583.061 | M51: =M40+M42+M45+M48 -> 780.87588 | N51: =N40+N42+N45+N48 -> 815.32051 | ... V51: =V40+V42+V45+V48 -> 1143.4442
B52: Present Value of unlevered FC | M52: =(M51/(1+$E$18)^M53)*M53 -> 419.23142 | N52: =N51/(1+$E$18)^N53 -> 702.23073 | O52: =O51/(1+$E$18)^O53 -> 666.52997 | P52: =P51/(1+$E$18)^P53 -> 632.62385 | Q52: =Q51/(1+$E$18)^Q53 -> 600.42298 | R52: =R51/(1+$E$18)^R53 -> 569.84238 | S52: =S51/(1+$E$18)^S53 -> 540.8013 | T52: =T51/(1+$E$18)^T53 -> 513.22295 | U52: =U51/(1+$E$18)^U53 -> 487.03437 | V52: =V51/(1+$E$18)^V53 -> 459.43593
B53: Discount Period | M53: =YEARFRAC(E4,E5) -> 0.56666667 | N53: =M53+1 -> 1.5666667 | O53: =N53+1 -> 2.5666667 | P53: =O53+1 -> 3.5666667 | Q53: =P53+1 -> 4.5666667 | R53: =Q53+1 -> 5.5666667 | S53: =R53+1 -> 6.5666667 | T53: =S53+1 -> 7.5666667 | U53: =T53+1 -> 8.5666667 | V53: =U53+1 -> 9.5666667
B54: Sum of Present Value | V54: =SUM(M52:V52) -> 5591.3759
...
